Workbook

Sheet Read me
B2: Argentina — GDP and demand-side activity pack
B3: INDEC national accounts, base 2004. Data through 2026-Q1; EMAE through May-2026.
B5: What's in here
B6: Data Constant | C6: INDEC quarterly volumes at 2004 prices, ORIGINAL (not seasonally adjusted). Blue = source. Includes an identity check column that must read zero.
B7: Data SA | C7: The seasonally adjusted volume series. INDEC does not publish SA inventories or SA statistical discrepancy, so those are backed out here as the residual.
B8: Data Nominal | C8: Current-price series, plus the quarterly USD conversion at the Com. "A" 3500 rate.
B9: Quarterly | C9: The read: GDP q/q seasonally adjusted, the annualised version of it, and y/y — with each demand component's y/y beside them.
B10: Contributions | C10: The tab you asked for. Demand-side contributions to growth in percentage points, quarterly y/y and annual. Contributions sum exactly to GDP growth, which is only true if the statistical discrepancy is carried explicitly — see the note on that tab.
B11: Annual | C11: Full-year levels and growth: real, nominal in pesos, nominal in USD, and the implied deflator.
B12: EMAE | C12: The monthly GDP proxy, and the quarter-to-date nowcast it implies for the quarter INDEC has not yet published.
B13: Forecast | C13: Bull / base / bear quarterly paths to Q4-2027 with the assumptions behind each, benchmarked to the BCRA REM and the IMF.
B15: Two things that will bite you if you don't know them
B16: Annual rates | C16: INDEC's quarterly national accounts are published at ANNUAL RATES. A year's level is the AVERAGE of its four quarters, never the sum. Every annual figure in this pack uses AVERAGEIFS for that reason. The Data tabs also carry a true-quarterly column (level / 4) for anything that needs a genuine quarterly flow — the USD conversion uses it.
B17: Statistical discrepancy | C17: INDEC only began publishing 'discrepancia estadistica' as its own line in Q1-2024. Before that it sat inside 'variacion de existencias'. So a 2024 y/y comparison that splits the two lines is comparing a carved-out series against one that still contains it. Every contribution calculation here therefore uses the COMBINED 'inventories + statistical discrepancy' line, which is continuous across the break. The split is shown separately as a memo from 2024 only.
B19: Source | C19: INDEC, Cuentas nacionales, oferta y demanda globales, base 2004, retrieved from the official series API at apis.datos.gob.ar (constant prices family 4.2, seasonally adjusted 3.2, current prices 4.4, EMAE 143.3). Exchange rate: BCRA Comunicacion "A" 3500 wholesale reference rate, series 175.1_DR_REFE500_0_0_25, monthly average of daily fixings.
B20: Validation | C20: Annual real growth computed here reproduces the published series for every year 2005-2025 to two decimal places (max deviation 0.11pp, at 2025). Nominal GDP for 2025 reproduces INDEC's published 850,239,798 million pesos exactly. GDP in USD for 2024 and 2025 lands within 0.2% of the IMF WEO figures of US$637.2bn and US$681.5bn, which is an independent check on the FX series and the annual-rate convention at the same time.
B21: Known vintage gaps | C21: The published q/q SA prints for 2025 (+1.0 / -0.1 / +0.6 / +0.6) do not reproduce from the current API vintage, which gives +0.77 / +0.30 / +0.12 / +1.16. Seasonal adjustment is re-estimated at every release and redistributes growth across quarters while holding the annual total; the annual totals do match. If you need to tie to a specific published print, you need that release's vintage, not the live series.
B22: 2019 identity | C22: Q3 and Q4 2019 are the only quarters where the demand components do not sum exactly to GDP (residual 135 and 891 on ~671,000, i.e. 0.13%). That is unallocated discrepancy in INDEC's own data for a period before the discrepancy line existed, not a transcription error.

Sheet Data Constant
B2: INDEC national accounts — constant 2004 prices, original (NSA)
B3: Millions of pesos at 2004 prices, at ANNUAL RATES. Blue = INDEC source value. Black = formula.
B5: Quarter | C5: Year | D5: Q | E5: GDP | F5: Private consumption | G5: Public consumption | H5: Gross fixed capital form. | I5: Change in inventories | J5: Statistical discrepancy | K5: Exports G&S | L5: Imports G&S | M5: Inventories + discrepancy | N5: Identity check | O5: True quarterly level | P5: GDP y/y
B6: 2004-Q1 | C6: 2004 | D6: 1 | E6: 460369.44 | F6: 305237.17 | G6: 49687.342 | H6: 71794.434 | I6: 3949.8213 | K6: 102774.2 | L6: 73073.435 | M6: =N(I6)+N(J6) -> 3949.8213 | N6: =F6+G6+H6+M6+K6-L6-E6 -> 0.096645969 | O6: =E6/4 -> 115092.36
B7: 2004-Q2 | C7: 2004 | D7: 2 | E7: 514395.68 | F7: 338800 | G7: 52072.278 | H7: 81995.48 | I7: 2071.9331 | K7: 119462.28 | L7: 80006.307 | M7: =N(I7)+N(J7) -> 2071.9331 | N7: =F7+G7+H7+M7+K7-L7-E7 -> -0.018493548 | O7: =E7/4 -> 128598.92
B8: 2004-Q3 | C8: 2004 | D8: 3 | E8: 481151.98 | F8: 310440.57 | G8: 53720.816 | H8: 79254.314 | I8: 3533.1507 | K8: 119619.17 | L8: 85416.073 | M8: =N(I8)+N(J8) -> 3533.1507 | N8: =F8+G8+H8+M8+K8-L8-E8 -> -0.026313035 | O8: =E8/4 -> 120287.99
B9: 2004-Q4 | C9: 2004 | D9: 4 | E9: 484543.68 | F9: 293849.79 | G9: 60194.718 | H9: 75368.48 | I9: 22607.904 | K9: 120898.05 | L9: 88375.322 | M9: =N(I9)+N(J9) -> 22607.904 | N9: =F9+G9+H9+M9+K9-L9-E9 -> -0.051839386 | O9: =E9/4 -> 121135.92
B10: 2005-Q1 | C10: 2005 | D10: 1 | E10: 493602.53 | F10: 319799.76 | G10: 54179.355 | H10: 80672.435 | I10: 4668.8284 | K10: 119186.93 | L10: 84904.777 | M10: =N(I10)+N(J10) -> 4668.8284 | N10: =F10+G10+H10+M10+K10-L10-E10 -> 0 | O10: =E10/4 -> 123400.63 | P10: =E10/E6-1 -> 0.072187868
B11: 2005-Q2 | C11: 2005 | D11: 2 | E11: 581668.25 | F11: 385778.07 | G11: 58212.172 | H11: 94508.359 | I11: 2240.3024 | K11: 138217.55 | L11: 97288.203 | M11: =N(I11)+N(J11) -> 2240.3024 | N11: =F11+G11+H11+M11+K11-L11-E11 -> 0 | O11: =E11/4 -> 145417.06 | P11: =E11/E7-1 -> 0.13077981
B12: 2005-Q3 | C12: 2005 | D12: 3 | E12: 514697.79 | F12: 323831.37 | G12: 58977.839 | H12: 89948.604 | I12: 3352.1803 | K12: 135432.69 | L12: 96844.893 | M12: =N(I12)+N(J12) -> 3352.1803 | N12: =F12+G12+H12+M12+K12-L12-E12 -> 0 | O12: =E12/4 -> 128674.45 | P12: =E12/E8-1 -> 0.069719779
B13: 2005-Q4 | C13: 2005 | D13: 4 | E13: 522255.2 | F13: 311201.94 | G13: 65561.513 | H13: 92100.023 | I13: 23477.469 | K13: 129550.82 | L13: 99636.558 | M13: =N(I13)+N(J13) -> 23477.469 | N13: =F13+G13+H13+M13+K13-L13-E13 -> 0 | O13: =E13/4 -> 130563.8 | P13: =E13/E9-1 -> 0.077828945
B14: 2006-Q1 | C14: 2006 | D14: 1 | E14: 532348.21 | F14: 354888.12 | G14: 56878.88 | H14: 93836.573 | I14: -2443.212 | K14: 125801.74 | L14: 96613.892 | M14: =N(I14)+N(J14) -> -2443.212 | N14: =F14+G14+H14+M14+K14-L14-E14 -> 0 | O14: =E14/4 -> 133087.05 | P14: =E14/E10-1 -> 0.078495711
B15: 2006-Q2 | C15: 2006 | D15: 2 | E15: 614076.39 | F15: 412814.67 | G15: 60002.963 | H15: 105355.81 | I15: -3784.5828 | K15: 141431.39 | L15: 101743.86 | M15: =N(I15)+N(J15) -> -3784.5828 | N15: =F15+G15+H15+M15+K15-L15-E15 -> 0 | O15: =E15/4 -> 153519.1 | P15: =E15/E11-1 -> 0.055715853
B16: 2006-Q3 | C16: 2006 | D16: 3 | E16: 562978.97 | F16: 372993.09 | G16: 60840.091 | H16: 106228.6 | I16: -6513.3054 | K16: 139275.06 | L16: 109844.58 | M16: =N(I16)+N(J16) -> -6513.3054 | N16: =F16+G16+H16+M16+K16-L16-E16 -> 0 | O16: =E16/4 -> 140744.74 | P16: =E16/E12-1 -> 0.093804903
B17: 2006-Q4 | C17: 2006 | D17: 4 | E17: 572794.05 | F17: 346795.75 | G17: 68028.752 | H17: 103509.59 | I17: 21624.583 | K17: 144930.85 | L17: 112095.48 | M17: =N(I17)+N(J17) -> 21624.583 | N17: =F17+G17+H17+M17+K17-L17-E17 -> 0 | O17: =E17/4 -> 143198.51 | P17: =E17/E13-1 -> 0.096770404
B18: 2007-Q1 | C18: 2007 | D18: 1 | E18: 576846.89 | F18: 394546.92 | G18: 61224.205 | H18: 111459.5 | I18: -8102.4942 | K18: 129994.29 | L18: 112275.54 | M18: =N(I18)+N(J18) -> -8102.4942 | N18: =F18+G18+H18+M18+K18-L18-E18 -> 0 | O18: =E18/4 -> 144211.72 | P18: =E18/E14-1 -> 0.083589411
B19: 2007-Q2 | C19: 2007 | D19: 2 | E19: 674620.56 | F19: 444046.11 | G19: 65259.864 | H19: 125373.06 | I19: 5766.3413 | K19: 151852.51 | L19: 117677.33 | M19: =N(I19)+N(J19) -> 5766.3413 | N19: =F19+G19+H19+M19+K19-L19-E19 -> 0 | O19: =E19/4 -> 168655.14 | P19: =E19/E15-1 -> 0.098593874
B20: 2007-Q3 | C20: 2007 | D20: 3 | E20: 610425.69 | F20: 403183.04 | G20: 65411.563 | H20: 128893.7 | I20: -4834.0395 | K20: 153959.99 | L20: 136188.56 | M20: =N(I20)+N(J20) -> -4834.0395 | N20: =F20+G20+H20+M20+K20-L20-E20 -> 0 | O20: =E20/4 -> 152606.42 | P20: =E20/E16-1 -> 0.084277977
B21: 2007-Q4 | C21: 2007 | D21: 4 | E21: 625876.87 | F21: 384630.08 | G21: 73096.788 | H21: 126843.7 | I21: 17356.141 | K21: 160654.22 | L21: 136704.06 | M21: =N(I21)+N(J21) -> 17356.141 | N21: =F21+G21+H21+M21+K21-L21-E21 -> 0 | O21: =E21/4 -> 156469.22 | P21: =E21/E17-1 -> 0.092673486
... B85: 2023-Q4 | C85: 2023 | D85: 4 | E85: 700543.2 | F85: 480687.41 | G85: 99272.705 | H85: 137053.09 | I85: 30180.388 | K85: 136117.33 | L85: 182767.72 | M85: =N(I85)+N(J85) -> 30180.388 | N85: =F85+G85+H85+M85+K85-L85-E85 -> 0 | O85: =E85/4 -> 175135.8 | P85: =E85/E81-1 -> -0.017113185
B86: 2024-Q1 | C86: 2024 | D86: 1 | E86: 668219.63 | F86: 508286.75 | G86: 93290.784 | H86: 107772.24 | I86: -29378.771 | J86: 4554.4696 | K86: 147382.29 | L86: 163688.13 | M86: =N(I86)+N(J86) -> -24824.302 | N86: =F86+G86+H86+M86+K86-L86-E86 -> 0 | O86: =E86/4 -> 167054.91 | P86: =E86/E82-1 -> -0.05083657
B87: 2024-Q2 | C87: 2024 | D87: 2 | E87: 729909.37 | F87: 538393.96 | G87: 98261.488 | H87: 111250.68 | I87: -9485.3139 | J87: -8671.4112 | K87: 164179.76 | L87: 164019.8 | M87: =N(I87)+N(J87) -> -18156.725 | N87: =F87+G87+H87+M87+K87-L87-E87 -> 0 | O87: =E87/4 -> 182477.34 | P87: =E87/E83-1 -> -0.011134976
B88: 2024-Q3 | C88: 2024 | D88: 3 | E88: 714299.22 | F88: 490119.31 | G88: 95614.376 | H88: 134999.68 | I88: 16624.836 | J88: -14763.567 | K88: 172087.52 | L88: 180382.93 | M88: =N(I88)+N(J88) -> 1861.2691 | N88: =F88+G88+H88+M88+K88-L88-E88 -> 0 | O88: =E88/4 -> 178574.8 | P88: =E88/E84-1 -> -0.01955005
B89: 2024-Q4 | C89: 2024 | D89: 4 | E89: 719523.32 | F89: 504095.17 | G89: 101219.34 | H89: 139618.48 | I89: 26848.363 | J89: -25287.855 | K89: 172594.56 | L89: 199564.73 | M89: =N(I89)+N(J89) -> 1560.5084 | N89: =F89+G89+H89+M89+K89-L89-E89 -> 0 | O89: =E89/4 -> 179880.83 | P89: =E89/E85-1 -> 0.027093436
B90: 2025-Q1 | C90: 2025 | D90: 1 | E90: 709095.12 | F90: 566590.76 | G90: 91687.793 | H90: 141620.55 | I90: -19277.671 | J90: 1704.7551 | K90: 156881.31 | L90: 230112.38 | M90: =N(I90)+N(J90) -> -17572.916 | N90: =F90+G90+H90+M90+K90-L90-E90 -> 0 | O90: =E90/4 -> 177273.78 | P90: =E90/E86-1 -> 0.061170747
B91: 2025-Q2 | C91: 2025 | D91: 2 | E91: 777482.56 | F91: 601163.87 | G91: 99731.984 | H91: 147249.23 | I91: -1008.5525 | J91: -11455.469 | K91: 169976.52 | L91: 228175.02 | M91: =N(I91)+N(J91) -> -12464.021 | N91: =F91+G91+H91+M91+K91-L91-E91 -> 0 | O91: =E91/4 -> 194370.64 | P91: =E91/E87-1 -> 0.065176841
B92: 2025-Q3 | C92: 2025 | D92: 3 | E92: 737135.07 | F92: 522534.77 | G92: 96837.224 | H92: 148829.51 | I92: 19392.457 | J92: -14355.754 | K92: 189756.07 | L92: 225859.21 | M92: =N(I92)+N(J92) -> 5036.7038 | N92: =F92+G92+H92+M92+K92-L92-E92 -> 0 | O92: =E92/4 -> 184283.77 | P92: =E92/E88-1 -> 0.031969585
B93: 2025-Q4 | C93: 2025 | D93: 4 | E93: 735202.11 | F93: 525445.78 | G93: 101592.27 | H93: 135974 | I93: 17703.807 | J93: -16770.731 | K93: 192971.24 | L93: 221714.27 | M93: =N(I93)+N(J93) -> 933.07651 | N93: =F93+G93+H93+M93+K93-L93-E93 -> 0 | O93: =E93/4 -> 183800.53 | P93: =E93/E89-1 -> 0.021790516
B94: 2026-Q1 | C94: 2026 | D94: 1 | E94: 725600.24 | F94: 582154.8 | G94: 90857.061 | H94: 125135.44 | I94: -32028.81 | J94: 131.66151 | K94: 172306.88 | L94: 212956.78 | M94: =N(I94)+N(J94) -> -31897.148 | N94: =F94+G94+H94+M94+K94-L94-E94 -> 0 | O94: =E94/4 -> 181400.06 | P94: =E94/E90-1 -> 0.023276313
B96: Identity check = components - GDP. Zero everywhere except Q3/Q4 2019 (INDEC unallocated discrepancy).
B97: Statistical discrepancy is only published from Q1-2024; blank before. Column M combines it with inventories so the series is continuous — use M, not I and J separately, for any growth calculation.

Sheet Data SA
B2: Constant 2004 prices — seasonally adjusted
B3: INDEC publishes SA series for GDP and the five main components only. Inventories + discrepancy is the residual.
B5: Quarter | C5: Year | D5: Q | E5: GDP SA | F5: Private consumption | G5: Public consumption | H5: Gross fixed capital form. | I5: Exports G&S | J5: Imports G&S | K5: Inventories + discrep. (resid.) | L5: GDP q/q | M5: GDP q/q annualised | N5: GDP y/y
B6: 2004-Q1 | C6: 2004 | D6: 1 | E6: 475539.4 | F6: 301225.67 | G6: 52621.016 | H6: 74514.13 | I6: 110907.83 | J6: 76725.676 | K6: =E6-F6-G6-H6-I6+J6 -> 12996.432
B7: 2004-Q2 | C7: 2004 | D7: 2 | E7: 470354.12 | F7: 305241.66 | G7: 52878.311 | H7: 76863.936 | I7: 114545.41 | J7: 80629.076 | K7: =E7-F7-G7-H7-I7+J7 -> 1453.8775 | L7: =E7/E6-1 -> -0.010904004 | M7: =(E7/E6)^4-1 -> -0.042907802
B8: 2004-Q3 | C8: 2004 | D8: 3 | E8: 493797.38 | F8: 317312.25 | G8: 54459.556 | H8: 77795.468 | I8: 117308.34 | J8: 82343.691 | K8: =E8-F8-G8-H8-I8+J8 -> 9265.4531 | L8: =E8/E7-1 -> 0.049841721 | M8: =(E8/E7)^4-1 -> 0.2147735
B9: 2004-Q4 | C9: 2004 | D9: 4 | E9: 500769.88 | F9: 324547.96 | G9: 55716.272 | H9: 79239.174 | I9: 119992.12 | J9: 87172.694 | K9: =E9-F9-G9-H9-I9+J9 -> 8447.0499 | L9: =E9/E8-1 -> 0.014120167 | M9: =(E9/E8)^4-1 -> 0.057688243
B10: 2005-Q1 | C10: 2005 | D10: 1 | E10: 515285.82 | F10: 321702.45 | G10: 57525.338 | H10: 85169.008 | I10: 128987.94 | J10: 89020.985 | K10: =E10-F10-G10-H10-I10+J10 -> 10922.077 | L10: =E10/E9-1 -> 0.028987252 | M10: =(E10/E9)^4-1 -> 0.12108871 | N10: =E10/E6-1 -> 0.083581758
B11: 2005-Q2 | C11: 2005 | D11: 2 | E11: 526591.97 | F11: 343081.08 | G11: 58978.537 | H11: 88011.75 | I11: 132423.53 | J11: 98373.376 | K11: =E11-F11-G11-H11-I11+J11 -> 2470.4523 | L11: =E11/E10-1 -> 0.02194151 | M11: =(E11/E10)^4-1 -> 0.090697106 | N11: =E11/E7-1 -> 0.11956492
B12: 2005-Q3 | C12: 2005 | D12: 3 | E12: 530024.97 | F12: 331929.02 | G12: 59809.009 | H12: 88220.828 | I12: 132582.35 | J12: 93046.384 | K12: =E12-F12-G12-H12-I12+J12 -> 10530.138 | L12: =E12/E11-1 -> 0.0065192746 | M12: =(E12/E11)^4-1 -> 0.026333214 | N12: =E12/E8-1 -> 0.073365296
B13: 2005-Q4 | C13: 2005 | D13: 4 | E13: 540321.01 | F13: 343898.59 | G13: 60617.996 | H13: 95827.835 | I13: 128394.16 | J13: 98233.686 | K13: =E13-F13-G13-H13-I13+J13 -> 9816.1132 | L13: =E13/E12-1 -> 0.019425572 | M13: =(E13/E12)^4-1 -> 0.079995867 | N13: =E13/E9-1 -> 0.078980644
B14: 2006-Q1 | C14: 2006 | D14: 1 | E14: 554468.16 | F14: 353365.27 | G14: 60522.471 | H14: 97461.46 | I14: 136759.03 | J14: 101242.5 | K14: =E14-F14-G14-H14-I14+J14 -> 7602.434 | L14: =E14/E13-1 -> 0.026182871 | M14: =(E14/E13)^4-1 -> 0.10891701 | N14: =E14/E10-1 -> 0.076040011
B15: 2006-Q2 | C15: 2006 | D15: 2 | E15: 561434.68 | F15: 372603.09 | G15: 60728.019 | H15: 100733.36 | I15: 135072.85 | J15: 103482.74 | K15: =E15-F15-G15-H15-I15+J15 -> -4219.893 | L15: =E15/E14-1 -> 0.012564321 | M15: =(E15/E14)^4-1 -> 0.051212414 | N15: =E15/E11-1 -> 0.066166422
B16: 2006-Q3 | C16: 2006 | D16: 3 | E16: 576815.72 | F16: 380887.27 | G16: 61643.491 | H16: 103916.74 | I16: 136282.97 | J16: 104959.45 | K16: =E16-F16-G16-H16-I16+J16 -> -955.29674 | L16: =E16/E15-1 -> 0.027395962 | M16: =(E16/E15)^4-1 -> 0.11416989 | N16: =E16/E12-1 -> 0.088280278
B17: 2006-Q4 | C17: 2006 | D17: 4 | E17: 589479.06 | F17: 380636.01 | G17: 62856.704 | H17: 106819.02 | I17: 143324.2 | J17: 110613.11 | K17: =E17-F17-G17-H17-I17+J17 -> 6456.2381 | L17: =E17/E16-1 -> 0.021953866 | M17: =(E17/E16)^4-1 -> 0.090749854 | N17: =E17/E13-1 -> 0.09097934
B18: 2007-Q1 | C18: 2007 | D18: 1 | E18: 603416.48 | F18: 391504.94 | G18: 65393.617 | H18: 116275.43 | I18: 142842.16 | J18: 117928.92 | K18: =E18-F18-G18-H18-I18+J18 -> 5329.2527 | L18: =E18/E17-1 -> 0.023643632 | M18: =(E18/E17)^4-1 -> 0.097981838 | N18: =E18/E14-1 -> 0.088279766
B19: 2007-Q2 | C19: 2007 | D19: 2 | E19: 616299.39 | F19: 403493.07 | G19: 65952.731 | H19: 121499.76 | I19: 144117.98 | J19: 120824.15 | K19: =E19-F19-G19-H19-I19+J19 -> 2060.0007 | L19: =E19/E18-1 -> 0.021349949 | M19: =(E19/E18)^4-1 -> 0.088173854 | N19: =E19/E15-1 -> 0.097722349
B20: 2007-Q3 | C20: 2007 | D20: 3 | E20: 624352.59 | F20: 412119.43 | G20: 66180.533 | H20: 125645.15 | I20: 150536.22 | J20: 129423.55 | K20: =E20-F20-G20-H20-I20+J20 -> -705.1901 | L20: =E20/E19-1 -> 0.013067018 | M20: =(E20/E19)^4-1 -> 0.05330151 | N20: =E20/E16-1 -> 0.082412573
B21: 2007-Q4 | C21: 2007 | D21: 4 | E21: 643701.55 | F21: 419288.71 | G21: 67465.539 | H21: 129149.62 | I21: 158964.67 | J21: 134668.87 | K21: =E21-F21-G21-H21-I21+J21 -> 3501.8855 | L21: =E21/E20-1 -> 0.030990435 | M21: =(E21/E20)^4-1 -> 0.12984416 | N21: =E21/E17-1 -> 0.091983745
... B94: 2026-Q1 | C94: 2026 | D94: 1 | E94: 752727.87 | F94: 565983.81 | G94: 95533.095 | H94: 133170.09 | I94: 184748.03 | J94: 217099.66 | K94: =E94-F94-G94-H94-I94+J94 -> -9607.4932 | L94: =E94/E93-1 -> 0.0074514741 | M94: =(E94/E93)^4-1 -> 0.030140701 | N94: =E94/E90-1 -> 0.023467571
B96: Seasonal factors are re-estimated at every INDEC release, so the q/q path is revised routinely even when the annual total is not. INDEC benchmarks each SA series to its NSA annual total: the two agree here to within 0.001 in every full year, which is what makes the annual figures on the Forecast tab valid.

Sheet Data Nominal
B2: Current prices, and the conversion to US dollars
B3: Millions of current pesos at annual rates. USD uses the true quarterly flow (level / 4) at the period-average Com. "A" 3500 rate.
B5: Quarter | C5: Year | D5: Q | E5: GDP | F5: Private consumption | G5: Public consumption | H5: Gross fixed capital form. | I5: Change in inventories | J5: Statistical discrepancy | K5: Exports G&S | L5: Imports G&S | M5: Inventories + discrepancy | N5: Identity check | O5: GDP, true quarterly (ARS mn) | P5: ARS/USD avg | Q5: GDP, quarterly (USD mn) | R5: 4q rolling GDP (USD mn) | S5: Deflator y/y
B6: 2004-Q1 | C6: 2004 | D6: 1 | E6: 439195.87 | F6: 291921.51 | G6: 47170.596 | H6: 65561.353 | I6: 3841.4185 | K6: 100001.76 | L6: 69300.987 | M6: =N(I6)+N(J6) -> 3841.4185 | N6: =F6+G6+H6+M6+K6-L6-E6 -> -0.21849341 | O6: =E6/4 -> 109798.97 | P6: 2.9091973 | Q6: =O6/P6 -> 37742.014
B7: 2004-Q2 | C7: 2004 | D7: 2 | E7: 509498.66 | F7: 334394.66 | G7: 50275.444 | H7: 80070.028 | I7: 2127.3567 | K7: 120749.9 | L7: 78118.806 | M7: =N(I7)+N(J7) -> 2127.3567 | N7: =F7+G7+H7+M7+K7-L7-E7 -> -0.084098251 | O7: =E7/4 -> 127374.67 | P7: 2.905115 | Q7: =O7/P7 -> 43844.965
B8: 2004-Q3 | C8: 2004 | D8: 3 | E8: 488462.38 | F8: 314867.08 | G8: 54912.188 | H8: 82294.818 | I8: 3464.2002 | K8: 120599.67 | L8: 87675.425 | M8: =N(I8)+N(J8) -> 3464.2002 | N8: =F8+G8+H8+M8+K8-L8-E8 -> 0.14972504 | O8: =E8/4 -> 122115.6 | P8: 2.9892973 | Q8: =O8/P8 -> 40850.937
B9: 2004-Q4 | C9: 2004 | D9: 4 | E9: 503303.87 | F9: 307144.29 | G9: 63316.925 | H9: 80486.509 | I9: 22729.834 | K9: 121402.38 | L9: 91775.918 | M9: =N(I9)+N(J9) -> 22729.834 | N9: =F9+G9+H9+M9+K9-L9-E9 -> 0.15286662 | O9: =E9/4 -> 125825.97 | P9: 2.9651946 | Q9: =O9/P9 -> 42434.303 | R9: =SUM(Q6:Q9) -> 164872.22
B10: 2005-Q1 | C10: 2005 | D10: 1 | E10: 510703.43 | F10: 329383.74 | G10: 60446.018 | H10: 88292.809 | I10: 4284.7309 | K10: 116402.46 | L10: 88106.331 | M10: =N(I10)+N(J10) -> 4284.7309 | N10: =F10+G10+H10+M10+K10-L10-E10 -> -3.2050884e-06 | O10: =E10/4 -> 127675.86 | P10: 2.9294382 | Q10: =O10/P10 -> 43583.734 | R10: =SUM(Q7:Q10) -> 170713.94 | S10: =(E10/'Data Constant'!E10)/(E6/'Data Constant'!E6)-1 -> 0.084525183
B11: 2005-Q2 | C11: 2005 | D11: 2 | E11: 605771.78 | F11: 400294.01 | G11: 66443.387 | H11: 104017.94 | I11: -613.93896 | K11: 138861.52 | L11: 103231.14 | M11: =N(I11)+N(J11) -> -613.93896 | N11: =F11+G11+H11+M11+K11-L11-E11 -> -2.0670705e-06 | O11: =E11/4 -> 151442.94 | P11: 2.8919299 | Q11: =O11/P11 -> 52367.432 | R11: =SUM(Q8:Q11) -> 179236.41 | S11: =(E11/'Data Constant'!E11)/(E7/'Data Constant'!E7)-1 -> 0.051448344
B12: 2005-Q3 | C12: 2005 | D12: 3 | E12: 590219.56 | F12: 370307.89 | G12: 71261.082 | H12: 103532.81 | I12: 5402.5476 | K12: 142090.96 | L12: 102375.72 | M12: =N(I12)+N(J12) -> 5402.5476 | N12: =F12+G12+H12+M12+K12-L12-E12 -> 3.9518345e-06 | O12: =E12/4 -> 147554.89 | P12: 2.8897859 | Q12: =O12/P12 -> 51060.838 | R12: =SUM(Q9:Q12) -> 189446.31 | S12: =(E12/'Data Constant'!E12)/(E8/'Data Constant'!E8)-1 -> 0.12956818
B13: 2005-Q4 | C13: 2005 | D13: 4 | E13: 623457.93 | F13: 368695.45 | G13: 84773.42 | H13: 108464.66 | I13: 26743.839 | K13: 144309.48 | L13: 109528.91 | M13: =N(I13)+N(J13) -> 26743.839 | N13: =F13+G13+H13+M13+K13-L13-E13 -> -2.4546171e-06 | O13: =E13/4 -> 155864.48 | P13: 2.9817643 | Q13: =O13/P13 -> 52272.57 | R13: =SUM(Q10:Q13) -> 199284.57 | S13: =(E13/'Data Constant'!E13)/(E9/'Data Constant'!E9)-1 -> 0.14928316
B14: 2006-Q1 | C14: 2006 | D14: 1 | E14: 643562.38 | F14: 420680.07 | G14: 77417.349 | H14: 116110.67 | I14: -2667.7756 | K14: 143494.78 | L14: 111472.72 | M14: =N(I14)+N(J14) -> -2667.7756 | N14: =F14+G14+H14+M14+K14-L14-E14 -> -2.7706847e-08 | O14: =E14/4 -> 160890.59 | P14: 3.0632684 | Q14: =O14/P14 -> 52522.526 | R14: =SUM(Q11:Q14) -> 208223.37 | S14: =(E14/'Data Constant'!E14)/(E10/'Data Constant'!E10)-1 -> 0.16843203
B15: 2006-Q2 | C15: 2006 | D15: 2 | E15: 727989.19 | F15: 472564.97 | G15: 85196.548 | H15: 130833.71 | I15: -6080.1451 | K15: 165070.51 | L15: 119596.41 | M15: =N(I15)+N(J15) -> -6080.1451 | N15: =F15+G15+H15+M15+K15-L15-E15 -> -1.4579855e-06 | O15: =E15/4 -> 181997.3 | P15: 3.0677281 | Q15: =O15/P15 -> 59326.411 | R15: =SUM(Q12:Q15) -> 215182.35 | S15: =(E15/'Data Constant'!E15)/(E11/'Data Constant'!E11)-1 -> 0.13833175
B16: 2006-Q3 | C16: 2006 | D16: 3 | E16: 729299.5 | F16: 469727 | G16: 88513.651 | H16: 139597.74 | I16: -5690.0446 | K16: 169541.64 | L16: 132390.49 | M16: =N(I16)+N(J16) -> -5690.0446 | N16: =F16+G16+H16+M16+K16-L16-E16 -> 8.7544322e-08 | O16: =E16/4 -> 182324.87 | P16: 3.0867335 | Q16: =O16/P16 -> 59067.254 | R16: =SUM(Q13:Q16) -> 223188.76 | S16: =(E16/'Data Constant'!E16)/(E12/'Data Constant'!E12)-1 -> 0.12967223
B17: 2006-Q4 | C17: 2006 | D17: 4 | E17: 762766.02 | F17: 448843.87 | G17: 104803.32 | H17: 138392.87 | I17: 24440.595 | K17: 181289.42 | L17: 135004.05 | M17: =N(I17)+N(J17) -> 24440.595 | N17: =F17+G17+H17+M17+K17-L17-E17 -> 3.6571873e-06 | O17: =E17/4 -> 190691.51 | P17: 3.0781369 | Q17: =O17/P17 -> 61950.301 | R17: =SUM(Q14:Q17) -> 232866.49 | S17: =(E17/'Data Constant'!E17)/(E13/'Data Constant'!E13)-1 -> 0.11549715
B18: 2007-Q1 | C18: 2007 | D18: 1 | E18: 774387.79 | F18: 506621.03 | G18: 97650.677 | H18: 148228.49 | I18: -7455.1385 | K18: 168496.92 | L18: 139154.19 | M18: =N(I18)+N(J18) -> -7455.1385 | N18: =F18+G18+H18+M18+K18-L18-E18 -> -1.1895318e-06 | O18: =E18/4 -> 193596.95 | P18: 3.0960215 | Q18: =O18/P18 -> 62530.88 | R18: =SUM(Q15:Q18) -> 242874.85 | S18: =(E18/'Data Constant'!E18)/(E14/'Data Constant'!E14)-1 -> 0.11046045
B19: 2007-Q2 | C19: 2007 | D19: 2 | E19: 904350.39 | F19: 576216.9 | G19: 111138.65 | H19: 170803.78 | I19: 2515.5409 | K19: 193068.36 | L19: 149392.84 | M19: =N(I19)+N(J19) -> 2515.5409 | N19: =F19+G19+H19+M19+K19-L19-E19 -> 2.9227231e-06 | O19: =E19/4 -> 226087.6 | P19: 3.0836592 | Q19: =O19/P19 -> 73317.957 | R19: =SUM(Q16:Q19) -> 256866.39 | S19: =(E19/'Data Constant'!E19)/(E15/'Data Constant'!E15)-1 -> 0.13077091
B20: 2007-Q3 | C20: 2007 | D20: 3 | E20: 914103.97 | F20: 589438.23 | G20: 118300.44 | H20: 189101.61 | I20: -6912.9367 | K20: 207489.64 | L20: 183313.02 | M20: =N(I20)+N(J20) -> -6912.9367 | N20: =F20+G20+H20+M20+K20-L20-E20 -> -9.1188122e-07 | O20: =E20/4 -> 228525.99 | P20: 3.1368523 | Q20: =O20/P20 -> 72852.009 | R20: =SUM(Q17:Q20) -> 270651.15 | S20: =(E20/'Data Constant'!E20)/(E16/'Data Constant'!E16)-1 -> 0.1559766
B21: 2007-Q4 | C21: 2007 | D21: 4 | E21: 995078.55 | F21: 571294.89 | G21: 138956.88 | H21: 192087.56 | I21: 32771.333 | K21: 244066.59 | L21: 184098.7 | M21: =N(I21)+N(J21) -> 32771.333 | N21: =F21+G21+H21+M21+K21-L21-E21 -> 7.7567529e-07 | O21: =E21/4 -> 248769.64 | P21: 3.1455868 | Q21: =O21/P21 -> 79085.289 | R21: =SUM(Q18:Q21) -> 287786.14 | S21: =(E21/'Data Constant'!E21)/(E17/'Data Constant'!E17)-1 -> 0.19392108
... B85: 2023-Q4 | C85: 2023 | D85: 4 | E85: 2.8487957e+08 | F85: 1.8436116e+08 | G85: 46145723 | H85: 50737504 | I85: 2333685.8 | K85: 35985967 | L85: 34684472 | M85: =N(I85)+N(J85) -> 2333685.8 | N85: =F85+G85+H85+M85+K85-L85-E85 -> 0 | O85: =E85/4 -> 71219893 | P85: 445.74917 | Q85: =O85/P85 -> 159775.72 | R85: =SUM(Q82:Q85) -> 658221.5 | S85: =(E85/'Data Constant'!E85)/(E81/'Data Constant'!E81)-1 -> 1.7774516
B86: 2024-Q1 | C86: 2024 | D86: 1 | E86: 4.3184098e+08 | F86: 2.9835049e+08 | G86: 61774368 | H86: 66584081 | I86: -19971376 | J86: 12700162 | K86: 71982618 | L86: 59579367 | M86: =N(I86)+N(J86) -> -7271213.9 | N86: =F86+G86+H86+M86+K86-L86-E86 -> 0 | O86: =E86/4 -> 1.0796024e+08 | P86: 834.30949 | Q86: =O86/P86 -> 129400.71 | R86: =SUM(Q83:Q86) -> 628706.17 | S86: =(E86/'Data Constant'!E86)/(E82/'Data Constant'!E82)-1 -> 2.7213077
B87: 2024-Q2 | C87: 2024 | D87: 2 | E87: 5.5953591e+08 | F87: 3.625485e+08 | G87: 85765973 | H87: 85957513 | I87: -12235825 | J87: 16144117 | K87: 87131369 | L87: 65775727 | M87: =N(I87)+N(J87) -> 3908291.3 | N87: =F87+G87+H87+M87+K87-L87-E87 -> 0 | O87: =E87/4 -> 1.3988398e+08 | P87: 885.91306 | Q87: =O87/P87 -> 157898.09 | R87: =SUM(Q84:Q87) -> 613850.92 | S87: =(E87/'Data Constant'!E87)/(E83/'Data Constant'!E83)-1 -> 2.5334429
B88: 2024-Q3 | C88: 2024 | D88: 3 | E88: 6.3763992e+08 | F88: 4.3172497e+08 | G88: 92583552 | H88: 1.1143253e+08 | I88: 14657669 | J88: -26823577 | K88: 95222015 | L88: 81157250 | M88: =N(I88)+N(J88) -> -12165907 | N88: =F88+G88+H88+M88+K88-L88-E88 -> 0 | O88: =E88/4 -> 1.5940998e+08 | P88: 942.93608 | Q88: =O88/P88 -> 169057.04 | R88: =SUM(Q85:Q88) -> 616131.55 | S88: =(E88/'Data Constant'!E88)/(E84/'Data Constant'!E84)-1 -> 2.1191025
B89: 2024-Q4 | C89: 2024 | D89: 4 | E89: 7.0849124e+08 | F89: 4.8216091e+08 | G89: 1.1458156e+08 | H89: 1.1576641e+08 | I89: 13466114 | J89: -33169071 | K89: 1.0134628e+08 | L89: 85660970 | M89: =N(I89)+N(J89) -> -19702957 | N89: =F89+G89+H89+M89+K89-L89-E89 -> 0 | O89: =E89/4 -> 1.7712281e+08 | P89: 1001.606 | Q89: =O89/P89 -> 176838.81 | R89: =SUM(Q86:Q89) -> 633194.65 | S89: =(E89/'Data Constant'!E89)/(E85/'Data Constant'!E85)-1 -> 1.4213815
B90: 2025-Q1 | C90: 2025 | D90: 1 | E90: 7.2969821e+08 | F90: 5.6216349e+08 | G90: 1.0944933e+08 | H90: 1.1837647e+08 | I90: -19091786 | J90: -30485212 | K90: 98604532 | L90: 1.0931862e+08 | M90: =N(I90)+N(J90) -> -49576998 | N90: =F90+G90+H90+M90+K90-L90-E90 -> 0 | O90: =E90/4 -> 1.8242455e+08 | P90: 1056.5512 | Q90: =O90/P90 -> 172660.4 | R90: =SUM(Q87:Q90) -> 676454.34 | S90: =(E90/'Data Constant'!E90)/(E86/'Data Constant'!E86)-1 -> 0.59233398
B91: 2025-Q2 | C91: 2025 | D91: 2 | E91: 8.3544789e+08 | F91: 5.8020272e+08 | G91: 1.2990302e+08 | H91: 1.4155428e+08 | I91: -11454688 | J91: -5639568.6 | K91: 1.1625281e+08 | L91: 1.1537067e+08 | M91: =N(I91)+N(J91) -> -17094256 | N91: =F91+G91+H91+M91+K91-L91-E91 -> 0 | O91: =E91/4 -> 2.0886197e+08 | P91: 1151.5877 | Q91: =O91/P91 -> 181368.7 | R91: =SUM(Q88:Q91) -> 699924.95 | S91: =(E91/'Data Constant'!E91)/(E87/'Data Constant'!E87)-1 -> 0.40174717
B92: 2025-Q3 | C92: 2025 | D92: 3 | E92: 8.8800091e+08 | F92: 6.0988824e+08 | G92: 1.3003556e+08 | H92: 1.5591246e+08 | I92: 25988419 | J92: -42889894 | K92: 1.5035567e+08 | L92: 1.4128955e+08 | M92: =N(I92)+N(J92) -> -16901475 | N92: =F92+G92+H92+M92+K92-L92-E92 -> 0 | O92: =E92/4 -> 2.2200023e+08 | P92: 1332.0883 | Q92: =O92/P92 -> 166655.79 | R92: =SUM(Q89:Q92) -> 697523.7 | S92: =(E92/'Data Constant'!E92)/(E88/'Data Constant'!E88)-1 -> 0.34949419
B93: 2025-Q4 | C93: 2025 | D93: 4 | E93: 9.4781217e+08 | F93: 6.5659212e+08 | G93: 1.5262036e+08 | H93: 1.4701702e+08 | I93: 10545583 | J93: -44063479 | K93: 1.6301235e+08 | L93: 1.3791177e+08 | M93: =N(I93)+N(J93) -> -33517896 | N93: =F93+G93+H93+M93+K93-L93-E93 -> 0 | O93: =E93/4 -> 2.3695304e+08 | P93: 1437.8635 | Q93: =O93/P93 -> 164795.23 | R93: =SUM(Q90:Q93) -> 685480.12 | S93: =(E93/'Data Constant'!E93)/(E89/'Data Constant'!E89)-1 -> 0.3092601
B94: 2026-Q1 | C94: 2026 | D94: 1 | E94: 9.7387578e+08 | F94: 7.6329695e+08 | G94: 1.4362093e+08 | H94: 1.3943705e+08 | I94: -38191101 | J94: -47332935 | K94: 1.5325311e+08 | L94: 1.4020822e+08 | M94: =N(I94)+N(J94) -> -85524036 | N94: =F94+G94+H94+M94+K94-L94-E94 -> 0 | O94: =E94/4 -> 2.4346895e+08 | P94: 1418.1367 | Q94: =O94/P94 -> 171682.28 | R94: =SUM(Q91:Q94) -> 684502 | S94: =(E94/'Data Constant'!E94)/(E90/'Data Constant'!E90)-1 -> 0.30426957
B96: Exchange rate: BCRA Comunicacion "A" 3500 wholesale reference rate, monthly average of daily fixings, averaged to the quarter. Source series 175.1_DR_REFE500_0_0_25 on apis.datos.gob.ar.
B97: USD GDP is a period-average conversion, the same convention the IMF WEO uses. At an official rate inside a managed band this flatters the dollar level relative to a market-clearing rate — read levels with that in mind; the ratios on the balance-of-payments pack are less sensitive to it than the levels are.

Sheet Quarterly
B2: Quarterly read — growth rates
B3: Green = pulled from the Data tabs. q/q is seasonally adjusted; y/y uses the original series.
B5: Quarter | C5: Year | D5: GDP q/q SA | E5: GDP q/q annualised | F5: GDP y/y SA | G5: GDP y/y NSA | H5: Private cons. y/y | I5: Public cons. y/y | J5: GFCF y/y | K5: Exports y/y | L5: Imports y/y
B6: 2004-Q1 | C6: 2004 | D6: ='Data SA'!L6 -> 0 | E6: ='Data SA'!M6 -> 0 | F6: ='Data SA'!N6 -> 0 | G6: ='Data Constant'!P6 -> 0
B7: 2004-Q2 | C7: 2004 | D7: ='Data SA'!L7 -> -0.010904004 | E7: ='Data SA'!M7 -> -0.042907802 | F7: ='Data SA'!N7 -> 0 | G7: ='Data Constant'!P7 -> 0
B8: 2004-Q3 | C8: 2004 | D8: ='Data SA'!L8 -> 0.049841721 | E8: ='Data SA'!M8 -> 0.2147735 | F8: ='Data SA'!N8 -> 0 | G8: ='Data Constant'!P8 -> 0
B9: 2004-Q4 | C9: 2004 | D9: ='Data SA'!L9 -> 0.014120167 | E9: ='Data SA'!M9 -> 0.057688243 | F9: ='Data SA'!N9 -> 0 | G9: ='Data Constant'!P9 -> 0
B10: 2005-Q1 | C10: 2005 | D10: ='Data SA'!L10 -> 0.028987252 | E10: ='Data SA'!M10 -> 0.12108871 | F10: ='Data SA'!N10 -> 0.083581758 | G10: ='Data Constant'!P10 -> 0.072187868 | H10: ='Data Constant'!F10/'Data Constant'!F6-1 -> 0.047709094 | I10: ='Data Constant'!G10/'Data Constant'!G6-1 -> 0.090405586 | J10: ='Data Constant'!H10/'Data Constant'!H6-1 -> 0.12365862 | K10: ='Data Constant'!K10/'Data Constant'!K6-1 -> 0.15969692 | L10: ='Data Constant'!L10/'Data Constant'!L6-1 -> 0.16191031
B11: 2005-Q2 | C11: 2005 | D11: ='Data SA'!L11 -> 0.02194151 | E11: ='Data SA'!M11 -> 0.090697106 | F11: ='Data SA'!N11 -> 0.11956492 | G11: ='Data Constant'!P11 -> 0.13077981 | H11: ='Data Constant'!F11/'Data Constant'!F7-1 -> 0.13866018 | I11: ='Data Constant'!G11/'Data Constant'!G7-1 -> 0.11791099 | J11: ='Data Constant'!H11/'Data Constant'!H7-1 -> 0.15260449 | K11: ='Data Constant'!K11/'Data Constant'!K7-1 -> 0.15699743 | L11: ='Data Constant'!L11/'Data Constant'!L7-1 -> 0.21600667
B12: 2005-Q3 | C12: 2005 | D12: ='Data SA'!L12 -> 0.0065192746 | E12: ='Data SA'!M12 -> 0.026333214 | F12: ='Data SA'!N12 -> 0.073365296 | G12: ='Data Constant'!P12 -> 0.069719779 | H12: ='Data Constant'!F12/'Data Constant'!F8-1 -> 0.043134798 | I12: ='Data Constant'!G12/'Data Constant'!G8-1 -> 0.097858212 | J12: ='Data Constant'!H12/'Data Constant'!H8-1 -> 0.13493638 | K12: ='Data Constant'!K12/'Data Constant'!K8-1 -> 0.13219889 | L12: ='Data Constant'!L12/'Data Constant'!L8-1 -> 0.13380176
B13: 2005-Q4 | C13: 2005 | D13: ='Data SA'!L13 -> 0.019425572 | E13: ='Data SA'!M13 -> 0.079995867 | F13: ='Data SA'!N13 -> 0.078980644 | G13: ='Data Constant'!P13 -> 0.077828945 | H13: ='Data Constant'!F13/'Data Constant'!F9-1 -> 0.059051058 | I13: ='Data Constant'!G13/'Data Constant'!G9-1 -> 0.089157232 | J13: ='Data Constant'!H13/'Data Constant'!H9-1 -> 0.22199655 | K13: ='Data Constant'!K13/'Data Constant'!K9-1 -> 0.071570785 | L13: ='Data Constant'!L13/'Data Constant'!L9-1 -> 0.12742512
B14: 2006-Q1 | C14: 2006 | D14: ='Data SA'!L14 -> 0.026182871 | E14: ='Data SA'!M14 -> 0.10891701 | F14: ='Data SA'!N14 -> 0.076040011 | G14: ='Data Constant'!P14 -> 0.078495711 | H14: ='Data Constant'!F14/'Data Constant'!F10-1 -> 0.10971977 | I14: ='Data Constant'!G14/'Data Constant'!G10-1 -> 0.049825697 | J14: ='Data Constant'!H14/'Data Constant'!H10-1 -> 0.16318013 | K14: ='Data Constant'!K14/'Data Constant'!K10-1 -> 0.055499511 | L14: ='Data Constant'!L14/'Data Constant'!L10-1 -> 0.13790878
B15: 2006-Q2 | C15: 2006 | D15: ='Data SA'!L15 -> 0.012564321 | E15: ='Data SA'!M15 -> 0.051212414 | F15: ='Data SA'!N15 -> 0.066166422 | G15: ='Data Constant'!P15 -> 0.055715853 | H15: ='Data Constant'!F15/'Data Constant'!F11-1 -> 0.070083285 | I15: ='Data Constant'!G15/'Data Constant'!G11-1 -> 0.030763164 | J15: ='Data Constant'!H15/'Data Constant'!H11-1 -> 0.11477772 | K15: ='Data Constant'!K15/'Data Constant'!K11-1 -> 0.02325209 | L15: ='Data Constant'!L15/'Data Constant'!L11-1 -> 0.045798548
B16: 2006-Q3 | C16: 2006 | D16: ='Data SA'!L16 -> 0.027395962 | E16: ='Data SA'!M16 -> 0.11416989 | F16: ='Data SA'!N16 -> 0.088280278 | G16: ='Data Constant'!P16 -> 0.093804903 | H16: ='Data Constant'!F16/'Data Constant'!F12-1 -> 0.15181274 | I16: ='Data Constant'!G16/'Data Constant'!G12-1 -> 0.031575456 | J16: ='Data Constant'!H16/'Data Constant'!H12-1 -> 0.18099223 | K16: ='Data Constant'!K16/'Data Constant'!K12-1 -> 0.028371044 | L16: ='Data Constant'!L16/'Data Constant'!L12-1 -> 0.134232
B17: 2006-Q4 | C17: 2006 | D17: ='Data SA'!L17 -> 0.021953866 | E17: ='Data SA'!M17 -> 0.090749854 | F17: ='Data SA'!N17 -> 0.09097934 | G17: ='Data Constant'!P17 -> 0.096770404 | H17: ='Data Constant'!F17/'Data Constant'!F13-1 -> 0.11437531 | I17: ='Data Constant'!G17/'Data Constant'!G13-1 -> 0.037632438 | J17: ='Data Constant'!H17/'Data Constant'!H13-1 -> 0.12388233 | K17: ='Data Constant'!K17/'Data Constant'!K13-1 -> 0.1187181 | L17: ='Data Constant'!L17/'Data Constant'!L13-1 -> 0.12504364
B18: 2007-Q1 | C18: 2007 | D18: ='Data SA'!L18 -> 0.023643632 | E18: ='Data SA'!M18 -> 0.097981838 | F18: ='Data SA'!N18 -> 0.088279766 | G18: ='Data Constant'!P18 -> 0.083589411 | H18: ='Data Constant'!F18/'Data Constant'!F14-1 -> 0.11175016 | I18: ='Data Constant'!G18/'Data Constant'!G14-1 -> 0.076396109 | J18: ='Data Constant'!H18/'Data Constant'!H14-1 -> 0.18780446 | K18: ='Data Constant'!K18/'Data Constant'!K14-1 -> 0.033326645 | L18: ='Data Constant'!L18/'Data Constant'!L14-1 -> 0.16210556
B19: 2007-Q2 | C19: 2007 | D19: ='Data SA'!L19 -> 0.021349949 | E19: ='Data SA'!M19 -> 0.088173854 | F19: ='Data SA'!N19 -> 0.097722349 | G19: ='Data Constant'!P19 -> 0.098593874 | H19: ='Data Constant'!F19/'Data Constant'!F15-1 -> 0.075654882 | I19: ='Data Constant'!G19/'Data Constant'!G15-1 -> 0.087610696 | J19: ='Data Constant'!H19/'Data Constant'!H15-1 -> 0.18999659 | K19: ='Data Constant'!K19/'Data Constant'!K15-1 -> 0.073683213 | L19: ='Data Constant'!L19/'Data Constant'!L15-1 -> 0.15660369
B20: 2007-Q3 | C20: 2007 | D20: ='Data SA'!L20 -> 0.013067018 | E20: ='Data SA'!M20 -> 0.05330151 | F20: ='Data SA'!N20 -> 0.082412573 | G20: ='Data Constant'!P20 -> 0.084277977 | H20: ='Data Constant'!F20/'Data Constant'!F16-1 -> 0.080939687 | I20: ='Data Constant'!G20/'Data Constant'!G16-1 -> 0.075139135 | J20: ='Data Constant'!H20/'Data Constant'!H16-1 -> 0.21336157 | K20: ='Data Constant'!K20/'Data Constant'!K16-1 -> 0.10543835 | L20: ='Data Constant'!L20/'Data Constant'!L16-1 -> 0.23982965
B21: 2007-Q4 | C21: 2007 | D21: ='Data SA'!L21 -> 0.030990435 | E21: ='Data SA'!M21 -> 0.12984416 | F21: ='Data SA'!N21 -> 0.091983745 | G21: ='Data Constant'!P21 -> 0.092673486 | H21: ='Data Constant'!F21/'Data Constant'!F17-1 -> 0.10909685 | I21: ='Data Constant'!G21/'Data Constant'!G17-1 -> 0.074498446 | J21: ='Data Constant'!H21/'Data Constant'!H17-1 -> 0.22542946 | K21: ='Data Constant'!K21/'Data Constant'!K17-1 -> 0.1084888 | L21: ='Data Constant'!L21/'Data Constant'!L17-1 -> 0.21953235
... B94: 2026-Q1 | C94: 2026 | D94: ='Data SA'!L94 -> 0.0074514741 | E94: ='Data SA'!M94 -> 0.030140701 | F94: ='Data SA'!N94 -> 0.023467571 | G94: ='Data Constant'!P94 -> 0.023276313 | H94: ='Data Constant'!F94/'Data Constant'!F90-1 -> 0.027469628 | I94: ='Data Constant'!G94/'Data Constant'!G90-1 -> -0.0090604362 | J94: ='Data Constant'!H94/'Data Constant'!H90-1 -> -0.11640338 | K94: ='Data Constant'!K94/'Data Constant'!K90-1 -> 0.098326332 | L94: ='Data Constant'!L94/'Data Constant'!L90-1 -> -0.07455311

Sheet Annual
B2: Annual — levels and growth
B3: A year's level is the AVERAGE of its four quarters, because INDEC publishes quarterly data at annual rates.
B5: Year | C5: GDP (2004 ARS mn) | D5: Private consumption | E5: Public consumption | F5: GFCF | G5: Inventories + discrepancy | H5: Exports | I5: Imports | J5: Real GDP growth | K5: Nominal GDP (ARS mn) | L5: Nominal GDP (USD bn) | M5: Deflator y/y | N5: Nominal growth | O5: GFCF % of GDP | P5: Priv. cons. % of GDP
B6: 2004 | C6: =AVERAGEIFS('Data Constant'!$E$6:$E$94,'Data Constant'!$C$6:$C$94,$B6) -> 485115.2 | D6: =AVERAGEIFS('Data Constant'!$F$6:$F$94,'Data Constant'!$C$6:$C$94,$B6) -> 312081.89 | E6: =AVERAGEIFS('Data Constant'!$G$6:$G$94,'Data Constant'!$C$6:$C$94,$B6) -> 53918.789 | F6: =AVERAGEIFS('Data Constant'!$H$6:$H$94,'Data Constant'!$C$6:$C$94,$B6) -> 77103.177 | G6: =AVERAGEIFS('Data Constant'!$M$6:$M$94,'Data Constant'!$C$6:$C$94,$B6) -> 8040.7022 | H6: =AVERAGEIFS('Data Constant'!$K$6:$K$94,'Data Constant'!$C$6:$C$94,$B6) -> 115688.43 | I6: =AVERAGEIFS('Data Constant'!$L$6:$L$94,'Data Constant'!$C$6:$C$94,$B6) -> 81717.784 | K6: =AVERAGEIFS('Data Nominal'!$E$6:$E$94,'Data Nominal'!$C$6:$C$94,$B6) -> 485115.19 | L6: =SUMIFS('Data Nominal'!$Q$6:$Q$94,'Data Nominal'!$C$6:$C$94,$B6)/1000 -> 164.87222 | O6: =AVERAGEIFS('Data Nominal'!$H$6:$H$94,'Data Nominal'!$C$6:$C$94,$B6)/K6 -> 0.15893787 | P6: =AVERAGEIFS('Data Nominal'!$F$6:$F$94,'Data Nominal'!$C$6:$C$94,$B6)/K6 -> 0.64331501
B7: 2005 | C7: =AVERAGEIFS('Data Constant'!$E$6:$E$94,'Data Constant'!$C$6:$C$94,$B7) -> 528055.94 | D7: =AVERAGEIFS('Data Constant'!$F$6:$F$94,'Data Constant'!$C$6:$C$94,$B7) -> 335152.78 | E7: =AVERAGEIFS('Data Constant'!$G$6:$G$94,'Data Constant'!$C$6:$C$94,$B7) -> 59232.72 | F7: =AVERAGEIFS('Data Constant'!$H$6:$H$94,'Data Constant'!$C$6:$C$94,$B7) -> 89307.355 | G7: =AVERAGEIFS('Data Constant'!$M$6:$M$94,'Data Constant'!$C$6:$C$94,$B7) -> 8434.695 | H7: =AVERAGEIFS('Data Constant'!$K$6:$K$94,'Data Constant'!$C$6:$C$94,$B7) -> 130597 | I7: =AVERAGEIFS('Data Constant'!$L$6:$L$94,'Data Constant'!$C$6:$C$94,$B7) -> 94668.608 | J7: =C7/C6-1 -> 0.088516599 | K7: =AVERAGEIFS('Data Nominal'!$E$6:$E$94,'Data Nominal'!$C$6:$C$94,$B7) -> 582538.17 | L7: =SUMIFS('Data Nominal'!$Q$6:$Q$94,'Data Nominal'!$C$6:$C$94,$B7)/1000 -> 199.28457 | M7: =(K7/C7)/(K6/C6)-1 -> 0.10317511 | N7: =K7/K6-1 -> 0.20082442 | O7: =AVERAGEIFS('Data Nominal'!$H$6:$H$94,'Data Nominal'!$C$6:$C$94,$B7)/K7 -> 0.17351147 | P7: =AVERAGEIFS('Data Nominal'!$F$6:$F$94,'Data Nominal'!$C$6:$C$94,$B7)/K7 -> 0.63029392
B8: 2006 | C8: =AVERAGEIFS('Data Constant'!$E$6:$E$94,'Data Constant'!$C$6:$C$94,$B8) -> 570549.4 | D8: =AVERAGEIFS('Data Constant'!$F$6:$F$94,'Data Constant'!$C$6:$C$94,$B8) -> 371872.91 | E8: =AVERAGEIFS('Data Constant'!$G$6:$G$94,'Data Constant'!$C$6:$C$94,$B8) -> 61437.671 | F8: =AVERAGEIFS('Data Constant'!$H$6:$H$94,'Data Constant'!$C$6:$C$94,$B8) -> 102232.64 | G8: =AVERAGEIFS('Data Constant'!$M$6:$M$94,'Data Constant'!$C$6:$C$94,$B8) -> 2220.8706 | H8: =AVERAGEIFS('Data Constant'!$K$6:$K$94,'Data Constant'!$C$6:$C$94,$B8) -> 137859.76 | I8: =AVERAGEIFS('Data Constant'!$L$6:$L$94,'Data Constant'!$C$6:$C$94,$B8) -> 105074.45 | J8: =C8/C7-1 -> 0.080471515 | K8: =AVERAGEIFS('Data Nominal'!$E$6:$E$94,'Data Nominal'!$C$6:$C$94,$B8) -> 715904.27 | L8: =SUMIFS('Data Nominal'!$Q$6:$Q$94,'Data Nominal'!$C$6:$C$94,$B8)/1000 -> 232.86649 | M8: =(K8/C8)/(K7/C7)-1 -> 0.13741052 | N8: =K8/K7-1 -> 0.22893967 | O8: =AVERAGEIFS('Data Nominal'!$H$6:$H$94,'Data Nominal'!$C$6:$C$94,$B8)/K8 -> 0.18331187 | P8: =AVERAGEIFS('Data Nominal'!$F$6:$F$94,'Data Nominal'!$C$6:$C$94,$B8)/K8 -> 0.63270188
B9: 2007 | C9: =AVERAGEIFS('Data Constant'!$E$6:$E$94,'Data Constant'!$C$6:$C$94,$B9) -> 621942.5 | D9: =AVERAGEIFS('Data Constant'!$F$6:$F$94,'Data Constant'!$C$6:$C$94,$B9) -> 406601.54 | E9: =AVERAGEIFS('Data Constant'!$G$6:$G$94,'Data Constant'!$C$6:$C$94,$B9) -> 66248.105 | F9: =AVERAGEIFS('Data Constant'!$H$6:$H$94,'Data Constant'!$C$6:$C$94,$B9) -> 123142.49 | G9: =AVERAGEIFS('Data Constant'!$M$6:$M$94,'Data Constant'!$C$6:$C$94,$B9) -> 2546.4872 | H9: =AVERAGEIFS('Data Constant'!$K$6:$K$94,'Data Constant'!$C$6:$C$94,$B9) -> 149115.25 | I9: =AVERAGEIFS('Data Constant'!$L$6:$L$94,'Data Constant'!$C$6:$C$94,$B9) -> 125711.37 | J9: =C9/C8-1 -> 0.090076509 | K9: =AVERAGEIFS('Data Nominal'!$E$6:$E$94,'Data Nominal'!$C$6:$C$94,$B9) -> 896980.17 | L9: =SUMIFS('Data Nominal'!$Q$6:$Q$94,'Data Nominal'!$C$6:$C$94,$B9)/1000 -> 287.78614 | M9: =(K9/C9)/(K8/C8)-1 -> 0.14939925 | N9: =K9/K8-1 -> 0.25293312 | O9: =AVERAGEIFS('Data Nominal'!$H$6:$H$94,'Data Nominal'!$C$6:$C$94,$B9)/K9 -> 0.19516079 | P9: =AVERAGEIFS('Data Nominal'!$F$6:$F$94,'Data Nominal'!$C$6:$C$94,$B9)/K9 -> 0.62531233
B10: 2008 | C10: =AVERAGEIFS('Data Constant'!$E$6:$E$94,'Data Constant'!$C$6:$C$94,$B10) -> 647176.16 | D10: =AVERAGEIFS('Data Constant'!$F$6:$F$94,'Data Constant'!$C$6:$C$94,$B10) -> 436058.39 | E10: =AVERAGEIFS('Data Constant'!$G$6:$G$94,'Data Constant'!$C$6:$C$94,$B10) -> 69570.5 | F10: =AVERAGEIFS('Data Constant'!$H$6:$H$94,'Data Constant'!$C$6:$C$94,$B10) -> 133850.26 | G10: =AVERAGEIFS('Data Constant'!$M$6:$M$94,'Data Constant'!$C$6:$C$94,$B10) -> 239.06665 | H10: =AVERAGEIFS('Data Constant'!$K$6:$K$94,'Data Constant'!$C$6:$C$94,$B10) -> 150218.52 | I10: =AVERAGEIFS('Data Constant'!$L$6:$L$94,'Data Constant'!$C$6:$C$94,$B10) -> 142760.58 | J10: =C10/C9-1 -> 0.040572331 | K10: =AVERAGEIFS('Data Nominal'!$E$6:$E$94,'Data Nominal'!$C$6:$C$94,$B10) -> 1149646.1 | L10: =SUMIFS('Data Nominal'!$Q$6:$Q$94,'Data Nominal'!$C$6:$C$94,$B10)/1000 -> 363.87837 | M10: =(K10/C10)/(K9/C9)-1 -> 0.23171165 | N10: =K10/K9-1 -> 0.28168506 | O10: =AVERAGEIFS('Data Nominal'!$H$6:$H$94,'Data Nominal'!$C$6:$C$94,$B10)/K10 -> 0.19010161 | P10: =AVERAGEIFS('Data Nominal'!$F$6:$F$94,'Data Nominal'!$C$6:$C$94,$B10)/K10 -> 0.63074583
B11: 2009 | C11: =AVERAGEIFS('Data Constant'!$E$6:$E$94,'Data Constant'!$C$6:$C$94,$B11) -> 608872.88 | D11: =AVERAGEIFS('Data Constant'!$F$6:$F$94,'Data Constant'!$C$6:$C$94,$B11) -> 412521.48 | E11: =AVERAGEIFS('Data Constant'!$G$6:$G$94,'Data Constant'!$C$6:$C$94,$B11) -> 73490.278 | F11: =AVERAGEIFS('Data Constant'!$H$6:$H$94,'Data Constant'!$C$6:$C$94,$B11) -> 103636.44 | G11: =AVERAGEIFS('Data Constant'!$M$6:$M$94,'Data Constant'!$C$6:$C$94,$B11) -> -483.58938 | H11: =AVERAGEIFS('Data Constant'!$K$6:$K$94,'Data Constant'!$C$6:$C$94,$B11) -> 136177.44 | I11: =AVERAGEIFS('Data Constant'!$L$6:$L$94,'Data Constant'!$C$6:$C$94,$B11) -> 116469.17 | J11: =C11/C10-1 -> -0.059185251 | K11: =AVERAGEIFS('Data Nominal'!$E$6:$E$94,'Data Nominal'!$C$6:$C$94,$B11) -> 1247929.3 | L11: =SUMIFS('Data Nominal'!$Q$6:$Q$94,'Data Nominal'!$C$6:$C$94,$B11)/1000 -> 334.28174 | M11: =(K11/C11)/(K10/C10)-1 -> 0.15377649 | N11: =K11/K10-1 -> 0.085489943 | O11: =AVERAGEIFS('Data Nominal'!$H$6:$H$94,'Data Nominal'!$C$6:$C$94,$B11)/K11 -> 0.15581753 | P11: =AVERAGEIFS('Data Nominal'!$F$6:$F$94,'Data Nominal'!$C$6:$C$94,$B11)/K11 -> 0.62978148
B12: 2010 | C12: =AVERAGEIFS('Data Constant'!$E$6:$E$94,'Data Constant'!$C$6:$C$94,$B12) -> 670523.68 | D12: =AVERAGEIFS('Data Constant'!$F$6:$F$94,'Data Constant'!$C$6:$C$94,$B12) -> 458675.17 | E12: =AVERAGEIFS('Data Constant'!$G$6:$G$94,'Data Constant'!$C$6:$C$94,$B12) -> 77497.097 | F12: =AVERAGEIFS('Data Constant'!$H$6:$H$94,'Data Constant'!$C$6:$C$94,$B12) -> 130845.76 | G12: =AVERAGEIFS('Data Constant'!$M$6:$M$94,'Data Constant'!$C$6:$C$94,$B12) -> 5875.2206 | H12: =AVERAGEIFS('Data Constant'!$K$6:$K$94,'Data Constant'!$C$6:$C$94,$B12) -> 155101.9 | I12: =AVERAGEIFS('Data Constant'!$L$6:$L$94,'Data Constant'!$C$6:$C$94,$B12) -> 157471.46 | J12: =C12/C11-1 -> 0.10125398 | K12: =AVERAGEIFS('Data Nominal'!$E$6:$E$94,'Data Nominal'!$C$6:$C$94,$B12) -> 1661720.9 | L12: =SUMIFS('Data Nominal'!$Q$6:$Q$94,'Data Nominal'!$C$6:$C$94,$B12)/1000 -> 424.3448 | M12: =(K12/C12)/(K11/C11)-1 -> 0.20915124 | N12: =K12/K11-1 -> 0.33158262 | O12: =AVERAGEIFS('Data Nominal'!$H$6:$H$94,'Data Nominal'!$C$6:$C$94,$B12)/K12 -> 0.16641466 | P12: =AVERAGEIFS('Data Nominal'!$F$6:$F$94,'Data Nominal'!$C$6:$C$94,$B12)/K12 -> 0.64234115
B13: 2011 | C13: =AVERAGEIFS('Data Constant'!$E$6:$E$94,'Data Constant'!$C$6:$C$94,$B13) -> 710781.6 | D13: =AVERAGEIFS('Data Constant'!$F$6:$F$94,'Data Constant'!$C$6:$C$94,$B13) -> 501647.15 | E13: =AVERAGEIFS('Data Constant'!$G$6:$G$94,'Data Constant'!$C$6:$C$94,$B13) -> 81034.77 | F13: =AVERAGEIFS('Data Constant'!$H$6:$H$94,'Data Constant'!$C$6:$C$94,$B13) -> 153584.09 | G13: =AVERAGEIFS('Data Constant'!$M$6:$M$94,'Data Constant'!$C$6:$C$94,$B13) -> 5139.0456 | H13: =AVERAGEIFS('Data Constant'!$K$6:$K$94,'Data Constant'!$C$6:$C$94,$B13) -> 161536.79 | I13: =AVERAGEIFS('Data Constant'!$L$6:$L$94,'Data Constant'!$C$6:$C$94,$B13) -> 192160.24 | J13: =C13/C12-1 -> 0.060039517 | K13: =AVERAGEIFS('Data Nominal'!$E$6:$E$94,'Data Nominal'!$C$6:$C$94,$B13) -> 2179024.1 | L13: =SUMIFS('Data Nominal'!$Q$6:$Q$94,'Data Nominal'!$C$6:$C$94,$B13)/1000 -> 527.11469 | M13: =(K13/C13)/(K12/C12)-1 -> 0.23703472 | N13: =K13/K12-1 -> 0.31130569 | O13: =AVERAGEIFS('Data Nominal'!$H$6:$H$94,'Data Nominal'!$C$6:$C$94,$B13)/K13 -> 0.17248285 | P13: =AVERAGEIFS('Data Nominal'!$F$6:$F$94,'Data Nominal'!$C$6:$C$94,$B13)/K13 -> 0.64220321
B14: 2012 | C14: =AVERAGEIFS('Data Constant'!$E$6:$E$94,'Data Constant'!$C$6:$C$94,$B14) -> 703485.99 | D14: =AVERAGEIFS('Data Constant'!$F$6:$F$94,'Data Constant'!$C$6:$C$94,$B14) -> 507216.85 | E14: =AVERAGEIFS('Data Constant'!$G$6:$G$94,'Data Constant'!$C$6:$C$94,$B14) -> 83473.346 | F14: =AVERAGEIFS('Data Constant'!$H$6:$H$94,'Data Constant'!$C$6:$C$94,$B14) -> 142717.7 | G14: =AVERAGEIFS('Data Constant'!$M$6:$M$94,'Data Constant'!$C$6:$C$94,$B14) -> -1747.8602 | H14: =AVERAGEIFS('Data Constant'!$K$6:$K$94,'Data Constant'!$C$6:$C$94,$B14) -> 154900.35 | I14: =AVERAGEIFS('Data Constant'!$L$6:$L$94,'Data Constant'!$C$6:$C$94,$B14) -> 183074.4 | J14: =C14/C13-1 -> -0.010264205 | K14: =AVERAGEIFS('Data Nominal'!$E$6:$E$94,'Data Nominal'!$C$6:$C$94,$B14) -> 2637913.8 | L14: =SUMIFS('Data Nominal'!$Q$6:$Q$94,'Data Nominal'!$C$6:$C$94,$B14)/1000 -> 579.08165 | M14: =(K14/C14)/(K13/C13)-1 -> 0.22314881 | N14: =K14/K13-1 -> 0.21059416 | O14: =AVERAGEIFS('Data Nominal'!$H$6:$H$94,'Data Nominal'!$C$6:$C$94,$B14)/K14 -> 0.15857525 | P14: =AVERAGEIFS('Data Nominal'!$F$6:$F$94,'Data Nominal'!$C$6:$C$94,$B14)/K14 -> 0.64903399
B15: 2013 | C15: =AVERAGEIFS('Data Constant'!$E$6:$E$94,'Data Constant'!$C$6:$C$94,$B15) -> 720407.11 | D15: =AVERAGEIFS('Data Constant'!$F$6:$F$94,'Data Constant'!$C$6:$C$94,$B15) -> 525674.53 | E15: =AVERAGEIFS('Data Constant'!$G$6:$G$94,'Data Constant'!$C$6:$C$94,$B15) -> 87916.288 | F15: =AVERAGEIFS('Data Constant'!$H$6:$H$94,'Data Constant'!$C$6:$C$94,$B15) -> 146056.57 | G15: =AVERAGEIFS('Data Constant'!$M$6:$M$94,'Data Constant'!$C$6:$C$94,$B15) -> 1495.1918 | H15: =AVERAGEIFS('Data Constant'!$K$6:$K$94,'Data Constant'!$C$6:$C$94,$B15) -> 149447.49 | I15: =AVERAGEIFS('Data Constant'!$L$6:$L$94,'Data Constant'!$C$6:$C$94,$B15) -> 190182.96 | J15: =C15/C14-1 -> 0.024053238 | K15: =AVERAGEIFS('Data Nominal'!$E$6:$E$94,'Data Nominal'!$C$6:$C$94,$B15) -> 3348308.5 | L15: =SUMIFS('Data Nominal'!$Q$6:$Q$94,'Data Nominal'!$C$6:$C$94,$B15)/1000 -> 611.1477 | M15: =(K15/C15)/(K14/C14)-1 -> 0.23948798 | N15: =K15/K14-1 -> 0.26930168 | O15: =AVERAGEIFS('Data Nominal'!$H$6:$H$94,'Data Nominal'!$C$6:$C$94,$B15)/K15 -> 0.16289511 | P15: =AVERAGEIFS('Data Nominal'!$F$6:$F$94,'Data Nominal'!$C$6:$C$94,$B15)/K15 -> 0.65987566
B16: 2014 | C16: =AVERAGEIFS('Data Constant'!$E$6:$E$94,'Data Constant'!$C$6:$C$94,$B16) -> 702306.05 | D16: =AVERAGEIFS('Data Constant'!$F$6:$F$94,'Data Constant'!$C$6:$C$94,$B16) -> 502764.44 | E16: =AVERAGEIFS('Data Constant'!$G$6:$G$94,'Data Constant'!$C$6:$C$94,$B16) -> 90505.449 | F16: =AVERAGEIFS('Data Constant'!$H$6:$H$94,'Data Constant'!$C$6:$C$94,$B16) -> 136189.65 | G16: =AVERAGEIFS('Data Constant'!$M$6:$M$94,'Data Constant'!$C$6:$C$94,$B16) -> 2179.1837 | H16: =AVERAGEIFS('Data Constant'!$K$6:$K$94,'Data Constant'!$C$6:$C$94,$B16) -> 139017.3 | I16: =AVERAGEIFS('Data Constant'!$L$6:$L$94,'Data Constant'!$C$6:$C$94,$B16) -> 168349.97 | J16: =C16/C15-1 -> -0.025126153 | K16: =AVERAGEIFS('Data Nominal'!$E$6:$E$94,'Data Nominal'!$C$6:$C$94,$B16) -> 4579086.4 | L16: =SUMIFS('Data Nominal'!$Q$6:$Q$94,'Data Nominal'!$C$6:$C$94,$B16)/1000 -> 562.8465 | M16: =(K16/C16)/(K15/C15)-1 -> 0.40282972 | N16: =K16/K15-1 -> 0.367582 | O16: =AVERAGEIFS('Data Nominal'!$H$6:$H$94,'Data Nominal'!$C$6:$C$94,$B16)/K16 -> 0.15979954 | P16: =AVERAGEIFS('Data Nominal'!$F$6:$F$94,'Data Nominal'!$C$6:$C$94,$B16)/K16 -> 0.6538308
B17: 2015 | C17: =AVERAGEIFS('Data Constant'!$E$6:$E$94,'Data Constant'!$C$6:$C$94,$B17) -> 721487.15 | D17: =AVERAGEIFS('Data Constant'!$F$6:$F$94,'Data Constant'!$C$6:$C$94,$B17) -> 521146.49 | E17: =AVERAGEIFS('Data Constant'!$G$6:$G$94,'Data Constant'!$C$6:$C$94,$B17) -> 96791.963 | F17: =AVERAGEIFS('Data Constant'!$H$6:$H$94,'Data Constant'!$C$6:$C$94,$B17) -> 140905.22 | G17: =AVERAGEIFS('Data Constant'!$M$6:$M$94,'Data Constant'!$C$6:$C$94,$B17) -> 3768.6757 | H17: =AVERAGEIFS('Data Constant'!$K$6:$K$94,'Data Constant'!$C$6:$C$94,$B17) -> 135156.27 | I17: =AVERAGEIFS('Data Constant'!$L$6:$L$94,'Data Constant'!$C$6:$C$94,$B17) -> 176281.47 | J17: =C17/C16-1 -> 0.027311598 | K17: =AVERAGEIFS('Data Nominal'!$E$6:$E$94,'Data Nominal'!$C$6:$C$94,$B17) -> 5954510.9 | L17: =SUMIFS('Data Nominal'!$Q$6:$Q$94,'Data Nominal'!$C$6:$C$94,$B17)/1000 -> 642.06007 | M17: =(K17/C17)/(K16/C16)-1 -> 0.26579992 | N17: =K17/K16-1 -> 0.30037093 | O17: =AVERAGEIFS('Data Nominal'!$H$6:$H$94,'Data Nominal'!$C$6:$C$94,$B17)/K17 -> 0.15564745 | P17: =AVERAGEIFS('Data Nominal'!$F$6:$F$94,'Data Nominal'!$C$6:$C$94,$B17)/K17 -> 0.65905837
B18: 2016 | C18: =AVERAGEIFS('Data Constant'!$E$6:$E$94,'Data Constant'!$C$6:$C$94,$B18) -> 706477.85 | D18: =AVERAGEIFS('Data Constant'!$F$6:$F$94,'Data Constant'!$C$6:$C$94,$B18) -> 517080.14 | E18: =AVERAGEIFS('Data Constant'!$G$6:$G$94,'Data Constant'!$C$6:$C$94,$B18) -> 96284.41 | F18: =AVERAGEIFS('Data Constant'!$H$6:$H$94,'Data Constant'!$C$6:$C$94,$B18) -> 132763.06 | G18: =AVERAGEIFS('Data Constant'!$M$6:$M$94,'Data Constant'!$C$6:$C$94,$B18) -> 4555.6305 | H18: =AVERAGEIFS('Data Constant'!$K$6:$K$94,'Data Constant'!$C$6:$C$94,$B18) -> 142343.01 | I18: =AVERAGEIFS('Data Constant'!$L$6:$L$94,'Data Constant'!$C$6:$C$94,$B18) -> 186548.39 | J18: =C18/C17-1 -> -0.020803278 | K18: =AVERAGEIFS('Data Nominal'!$E$6:$E$94,'Data Nominal'!$C$6:$C$94,$B18) -> 8228159.6 | L18: =SUMIFS('Data Nominal'!$Q$6:$Q$94,'Data Nominal'!$C$6:$C$94,$B18)/1000 -> 556.84722 | M18: =(K18/C18)/(K17/C17)-1 -> 0.4111938 | N18: =K18/K17-1 -> 0.38183634 | O18: =AVERAGEIFS('Data Nominal'!$H$6:$H$94,'Data Nominal'!$C$6:$C$94,$B18)/K18 -> 0.14272363 | P18: =AVERAGEIFS('Data Nominal'!$F$6:$F$94,'Data Nominal'!$C$6:$C$94,$B18)/K18 -> 0.65721891
... B27: 2025 | C27: =AVERAGEIFS('Data Constant'!$E$6:$E$94,'Data Constant'!$C$6:$C$94,$B27) -> 739728.71 | D27: =AVERAGEIFS('Data Constant'!$F$6:$F$94,'Data Constant'!$C$6:$C$94,$B27) -> 553933.8 | E27: =AVERAGEIFS('Data Constant'!$G$6:$G$94,'Data Constant'!$C$6:$C$94,$B27) -> 97462.319 | F27: =AVERAGEIFS('Data Constant'!$H$6:$H$94,'Data Constant'!$C$6:$C$94,$B27) -> 143418.32 | G27: =AVERAGEIFS('Data Constant'!$M$6:$M$94,'Data Constant'!$C$6:$C$94,$B27) -> -6016.7892 | H27: =AVERAGEIFS('Data Constant'!$K$6:$K$94,'Data Constant'!$C$6:$C$94,$B27) -> 177396.29 | I27: =AVERAGEIFS('Data Constant'!$L$6:$L$94,'Data Constant'!$C$6:$C$94,$B27) -> 226465.22 | J27: =C27/C26-1 -> 0.044832446 | K27: =AVERAGEIFS('Data Nominal'!$E$6:$E$94,'Data Nominal'!$C$6:$C$94,$B27) -> 8.502398e+08 | L27: =SUMIFS('Data Nominal'!$Q$6:$Q$94,'Data Nominal'!$C$6:$C$94,$B27)/1000 -> 685.48012 | M27: =(K27/C27)/(K26/C26)-1 -> 0.39252069 | N27: =K27/K26-1 -> 0.4549508 | O27: =AVERAGEIFS('Data Nominal'!$H$6:$H$94,'Data Nominal'!$C$6:$C$94,$B27)/K27 -> 0.16550044 | P27: =AVERAGEIFS('Data Nominal'!$F$6:$F$94,'Data Nominal'!$C$6:$C$94,$B27)/K27 -> 0.70828447
B29: Full calendar years only (2004-2025). 2026 is incomplete and is handled on the Forecast tab, not here.
B30: Real growth here reproduces the published annual series to two decimals for every year; nominal 2025 reproduces INDEC's 850,239,798 million pesos exactly; USD GDP for 2024 and 2025 lands within 0.2% of IMF WEO.

Sheet Contributions
B2: Demand-side contributions to GDP growth
B3: Percentage points. Contributions sum exactly to GDP growth — which requires carrying the statistical discrepancy explicitly. Imports enter with a negative sign.
B4: Contribution of component i = (level_i this period - level_i a year earlier) / GDP a year earlier. The inventories line is inventories PLUS statistical discrepancy, because INDEC only split them out in 2024 and a split series would break the y/y comparison in that year.
B6: 1. Quarterly, year-on-year (original series)
B7: Quarter | C7: GDP y/y | D7: Private consumption | E7: Public consumption | F7: GFCF | G7: Inventories + discrepancy | H7: Exports | I7: Imports | J7: Sum of contributions | K7: Check (sum - GDP) | L7: memo: discrep. alone
B8: ='Data Constant'!B10 -> 2005-Q1 | C8: =('Data Constant'!E10/'Data Constant'!E6-1)*100 -> 7.2187868 | D8: =('Data Constant'!F10-'Data Constant'!F6)/'Data Constant'!$E6*100 -> 3.1632397 | E8: =('Data Constant'!G10-'Data Constant'!G6)/'Data Constant'!$E6*100 -> 0.97574097 | F8: =('Data Constant'!H10-'Data Constant'!H6)/'Data Constant'!$E6*100 -> 1.9284514 | G8: =('Data Constant'!M10-'Data Constant'!M6)/'Data Constant'!$E6*100 -> 0.15618046 | H8: =('Data Constant'!K10-'Data Constant'!K6)/'Data Constant'!$E6*100 -> 3.5651202 | I8: =-('Data Constant'!L10-'Data Constant'!L6)/'Data Constant'!$E6*100 -> -2.569967 | J8: =SUM(D8:I8) -> 7.2187658 | K8: =J8-C8 -> -2.0993133e-05 | L8: =IF(OR('Data Constant'!J10="",'Data Constant'!J6=""),"",('Data Constant'!J10-'Data Constant'!J6)/'Data Constant'!$E6*100)
B9: ='Data Constant'!B11 -> 2005-Q2 | C9: =('Data Constant'!E11/'Data Constant'!E7-1)*100 -> 13.077981 | D9: =('Data Constant'!F11-'Data Constant'!F7)/'Data Constant'!$E7*100 -> 9.132672 | E9: =('Data Constant'!G11-'Data Constant'!G7)/'Data Constant'!$E7*100 -> 1.1936131 | F9: =('Data Constant'!H11-'Data Constant'!H7)/'Data Constant'!$E7*100 -> 2.4325395 | G9: =('Data Constant'!M11-'Data Constant'!M7)/'Data Constant'!$E7*100 -> 0.032731467 | H9: =('Data Constant'!K11-'Data Constant'!K7)/'Data Constant'!$E7*100 -> 3.6460785 | I9: =-('Data Constant'!L11-'Data Constant'!L7)/'Data Constant'!$E7*100 -> -3.3596503 | J9: =SUM(D9:I9) -> 13.077984 | K9: =J9-C9 -> 3.5951988e-06 | L9: =IF(OR('Data Constant'!J11="",'Data Constant'!J7=""),"",('Data Constant'!J11-'Data Constant'!J7)/'Data Constant'!$E7*100)
B10: ='Data Constant'!B12 -> 2005-Q3 | C10: =('Data Constant'!E12/'Data Constant'!E8-1)*100 -> 6.9719779 | D10: =('Data Constant'!F12-'Data Constant'!F8)/'Data Constant'!$E8*100 -> 2.783069 | E10: =('Data Constant'!G12-'Data Constant'!G8)/'Data Constant'!$E8*100 -> 1.092591 | F10: =('Data Constant'!H12-'Data Constant'!H8)/'Data Constant'!$E8*100 -> 2.2226429 | G10: =('Data Constant'!M12-'Data Constant'!M8)/'Data Constant'!$E8*100 -> -0.037611895 | H10: =('Data Constant'!K12-'Data Constant'!K8)/'Data Constant'!$E8*100 -> 3.286596 | I10: =-('Data Constant'!L12-'Data Constant'!L8)/'Data Constant'!$E8*100 -> -2.3753036 | J10: =SUM(D10:I10) -> 6.9719833 | K10: =J10-C10 -> 5.4687574e-06 | L10: =IF(OR('Data Constant'!J12="",'Data Constant'!J8=""),"",('Data Constant'!J12-'Data Constant'!J8)/'Data Constant'!$E8*100)
B11: ='Data Constant'!B13 -> 2005-Q4 | C11: =('Data Constant'!E13/'Data Constant'!E9-1)*100 -> 7.7828945 | D11: =('Data Constant'!F13-'Data Constant'!F9)/'Data Constant'!$E9*100 -> 3.5811304 | E11: =('Data Constant'!G13-'Data Constant'!G9)/'Data Constant'!$E9*100 -> 1.1075977 | F11: =('Data Constant'!H13-'Data Constant'!H9)/'Data Constant'!$E9*100 -> 3.4530515 | G11: =('Data Constant'!M13-'Data Constant'!M9)/'Data Constant'!$E9*100 -> 0.17946061 | H11: =('Data Constant'!K13-'Data Constant'!K9)/'Data Constant'!$E9*100 -> 1.7857561 | I11: =-('Data Constant'!L13-'Data Constant'!L9)/'Data Constant'!$E9*100 -> -2.3240911 | J11: =SUM(D11:I11) -> 7.7829052 | K11: =J11-C11 -> 1.0698599e-05 | L11: =IF(OR('Data Constant'!J13="",'Data Constant'!J9=""),"",('Data Constant'!J13-'Data Constant'!J9)/'Data Constant'!$E9*100)
B12: ='Data Constant'!B14 -> 2006-Q1 | C12: =('Data Constant'!E14/'Data Constant'!E10-1)*100 -> 7.8495711 | D12: =('Data Constant'!F14-'Data Constant'!F10)/'Data Constant'!$E10*100 -> 7.1086259 | E12: =('Data Constant'!G14-'Data Constant'!G10)/'Data Constant'!$E10*100 -> 0.54690241 | F12: =('Data Constant'!H14-'Data Constant'!H10)/'Data Constant'!$E10*100 -> 2.6669512 | G12: =('Data Constant'!M14-'Data Constant'!M10)/'Data Constant'!$E10*100 -> -1.4408436 | H12: =('Data Constant'!K14-'Data Constant'!K10)/'Data Constant'!$E10*100 -> 1.3401098 | I12: =-('Data Constant'!L14-'Data Constant'!L10)/'Data Constant'!$E10*100 -> -2.3721747 | J12: =SUM(D12:I12) -> 7.8495711 | K12: =J12-C12 -> 0 | L12: =IF(OR('Data Constant'!J14="",'Data Constant'!J10=""),"",('Data Constant'!J14-'Data Constant'!J10)/'Data Constant'!$E10*100)
B13: ='Data Constant'!B15 -> 2006-Q2 | C13: =('Data Constant'!E15/'Data Constant'!E11-1)*100 -> 5.5715853 | D13: =('Data Constant'!F15-'Data Constant'!F11)/'Data Constant'!$E11*100 -> 4.6481125 | E13: =('Data Constant'!G15-'Data Constant'!G11)/'Data Constant'!$E11*100 -> 0.30787147 | F13: =('Data Constant'!H15-'Data Constant'!H11)/'Data Constant'!$E11*100 -> 1.8648868 | G13: =('Data Constant'!M15-'Data Constant'!M11)/'Data Constant'!$E11*100 -> -1.0357941 | H13: =('Data Constant'!K15-'Data Constant'!K11)/'Data Constant'!$E11*100 -> 0.55252231 | I13: =-('Data Constant'!L15-'Data Constant'!L11)/'Data Constant'!$E11*100 -> -0.76601369 | J13: =SUM(D13:I13) -> 5.5715853 | K13: =J13-C13 -> 0 | L13: =IF(OR('Data Constant'!J15="",'Data Constant'!J11=""),"",('Data Constant'!J15-'Data Constant'!J11)/'Data Constant'!$E11*100)
B14: ='Data Constant'!B16 -> 2006-Q3 | C14: =('Data Constant'!E16/'Data Constant'!E12-1)*100 -> 9.3804903 | D14: =('Data Constant'!F16-'Data Constant'!F12)/'Data Constant'!$E12*100 -> 9.5515716 | E14: =('Data Constant'!G16-'Data Constant'!G12)/'Data Constant'!$E12*100 -> 0.36181468 | F14: =('Data Constant'!H16-'Data Constant'!H12)/'Data Constant'!$E12*100 -> 3.1630208 | G14: =('Data Constant'!M16-'Data Constant'!M12)/'Data Constant'!$E12*100 -> -1.9167531 | H14: =('Data Constant'!K16-'Data Constant'!K12)/'Data Constant'!$E12*100 -> 0.74652874 | I14: =-('Data Constant'!L16-'Data Constant'!L12)/'Data Constant'!$E12*100 -> -2.5256925 | J14: =SUM(D14:I14) -> 9.3804903 | K14: =J14-C14 -> 5.6843419e-14 | L14: =IF(OR('Data Constant'!J16="",'Data Constant'!J12=""),"",('Data Constant'!J16-'Data Constant'!J12)/'Data Constant'!$E12*100)
