Workbook
Name Forecast_Base27: Forecast!$D$46

Sheet Read me
B2: Argentina inflation — the Milei disinflation and the road to October 2027
B3: Thematic pack. INDEC data through 2026-08. Built 30-Sep-2026.
B5: THE QUESTION
C6: What did Milei inherit, what did his people change, what has been accomplished, and where is CPI when voters choose on 24 October 2027.
B8: THE FOUR FINDINGS
B9: 1. Not hyperinflation | C9: Argentina did NOT reach hyperinflation and on the price metric was not close. Dec-2023 printed 25.5% m/m — 51% of Cagan's 50%/month threshold, annualising to 1,427% against the 12,875% the threshold implies. The 1989 peak was 197% m/m, 7.7x higher. The danger sat in the BALANCE SHEET, not the CPI: remunerated liabilities at 2.92x base money, a quasi-fiscal deficit of 10.5% of GDP, net reserves at minus USD 11.2bn, and base money collapsed to 3.1% of GDP. Say the honest thing, then pivot to the overhang — that is where the argument is.
B10: 2. The anchor was withdrawn | C10: On 1-Jan-2026 the FX band's edges stopped crawling at a fixed +/-1%/month and began indexing to the last reported monthly CPI (t-2 lag). That converted the band from a NOMINAL ANCHOR into an INDEXATION MECHANISM. It is the single most important policy change of 2026 and the structural reason inflation now converges TO the crawl rather than below it.
B11: 3. Disinflation is understated | C11: Regulated prices have risen 61% RELATIVE to core since Dec-2023. Core inflation Jan-Aug 2026 (19.8%) is running BELOW the same window of 2025 (20.8%), while headline (21.3%) runs ABOVE 2025 (19.5%). The entire difference is regulados (28.5% vs 20.0%). Underlying disinflation is better than the headline shows; the headline is held up by a deliberate, ongoing relative-price correction.
B12: 4. Inflation is no longer the vote | C12: Approval has moved INVERSELY to the disinflation. ICG fell from 2.86 (Dec-2023) to 1.94 (Sep-2026), a 32% decline, while inflation fell from 25.5% m/m to 1.67% m/m. What approval tracks is REAL INCOME. Across nine presidential elections, 'the incumbent wins iff real wages rose' is right 8 of 9 times; 'iff inflation is below 20%' is right 6 of 9. And inflation has already been displaced as the most-named problem — 20.8% in Jun-2026, down from 44% in May-2024, at 33.5% measured inflation.
B14: TABS
B15: Sources | C15: Every primary document behind every number, plus the explicit list of series that could NOT be sourced. Read the gaps list before publishing anything from this pack.
B16: CPI Data | C16: INDEC national CPI: headline, nucleo, regulados, estacionales as index levels (blue) with m/m, 3m annualised, 6m annualised, y/y and YTD all calculated in-sheet.
B17: Seasonality | C17: Month x year matrix of m/m by calendar year, for headline and core, plus scale-free seasonal factors.
B18: Momentum | C18: 3m and 6m annualised against y/y. The annualised measures turn roughly nine months before the y/y does.
B19: Components | C19: Nucleo vs regulados vs estacionales, and the relative price shift index (Dec-2023 = 100) that quantifies the tariff catch-up.
B20: Inheritance | C20: The monetary financing of the deficit 2019-2023: adelantos transitorios and utilidades, the indirect channels that circumvented the IMF ceiling, letras intransferibles, the LELIQ/pases stock, the quasi-fiscal deficit, money demand collapse and reserves.
B21: Hyperinflation | C21: Distance to Cagan, computed in-sheet: annualised rates, doubling times, and the balance-sheet markers that were the real risk.
B22: Real Rates | C22: Nominal reference rate -> TEM -> real ex-post against realised CPI and real ex-ante against REM expectations. Note there is NO continuous policy rate series: the instrument was abolished on 9-Jun-2025.
B23: Expectations | C23: REM drift by round, household expectations, the LECAP/BONCAP curve and the CER breakevens. The ordering government 18.0% < REM 20.0% < market ~24.6% for 2027 is the note's cleanest single finding.
B24: Models | C24: SIX independent models of where CPI lands in the 3-6 months before the vote, converging into one comparison table. This is the analytical core of the pack.
B25: Forecast | C25: The bull/base/bear monthly paths to Dec-2027 with the assumptions behind each, probability-weighted, benchmarked to the REM and the Budget.
B26: Approval Model | C26: The transparent logistic scoring device mapping inflation level, inflation direction and real wages to an incumbent win probability, with a sensitivity grid. NINE observations and three parameters — a device for organising priors, not a forecast.
... B28: Elections | C28: The eleven-election record: pre-vote inflation, momentum, real wage direction and outcome.
B30: CONVENTIONS
B31: Blue cells | C31: Hardcoded inputs from a cited source. Every one is traceable on the Sources tab.
B32: Black cells | C32: Calculated in-sheet. Change a blue cell and every black cell downstream updates.
B33: Red cells | C33: Derived parameters — computed from the data by a stated method rather than read from a source. There are only a handful and each carries a cell comment with its derivation.
B34: Yellow rows | C34: Empty forecast months on the CPI Data tab. Paste a new INDEC print in and the whole workbook updates.
B35: Pink cells | C35: Reconstructed values, not published ones. See the caveat below.
B37: !! Jul & Aug-2026 caveat | C37: The July-2026 and August-2026 index LEVELS are RECONSTRUCTED, not pulled from the INDEC API, which could not be reached. They were solved from the published press releases, each of which pins every series with three independent figures — the m/m, the change vs December-2025 and the y/y. For every series those three constraints intersect in a band narrower than 0.07% of the level, and the midpoint is what is entered. Every percentage this workbook DISPLAYS therefore matches the published print to INDEC's own decimal. Treat the two index levels as accurate to about +/-0.035%.
B38: Validation gate | C38: Compounded monthly rates reproduce INDEC's published Dec/Dec prints exactly: 2019 53.8%, 2020 36.1%, 2021 50.9%, 2022 94.8%, 2023 211.4%, 2024 117.8%, 2025 31.5%. The August-2026 print also reconciles across all four series: headline 1.7 / 21.3 / 33.5, nucleo 1.8 / 19.8 / 31.9, regulados 2.2 / 28.5 / 43.7, estacionales -0.9 / 16.8 / 24.0.
B40: WHAT THIS PACK DOES NOT DO
B41: No filled gaps | C41: Where a series could not be sourced it is left empty with the source identifier recorded, per standing practice. The Sources tab lists fourteen such gaps. Several are closable only with an interactive session or a Bloomberg pull — the BCRA statistical files, the UTDT history file and the REM XLSX are all behind blocks that a headless run cannot pass.
B42: No merged definitions | C42: Monetary financing as % of GDP mixes two definitions across years (IMF includes valuation-gain transfers; BCRA does not). They are labelled separately and never plotted on one line. The same discipline applies to net reserves, where four estimates use four incompatible methodologies.
B43: No misery index | C43: Inflation and the labour variable are kept separate. An equal-weighted sum is numerically dominated by the inflation term in an economy where inflation moved from 25% m/m to 1.7% m/m while unemployment moved inside a 6-8% band — it would be an inflation index with noise added.

Sheet Sources
B2: Sources and gaps
B3: Primary documents first. Where a figure rests on press reporting of official data it says so.
B5: Series | C5: Source | D5: Document / identifier | E5: Note
B6: CPI | C6: INDEC, Indice de precios al consumidor nacional, base dic-2016=100 | D6: apis.datos.gob.ar series 148.3_INIVELNAL_DICI_M_26, _INUCLEONAL_DICI_M_19, _IREGULANAL_DICI_M_22, _IESTACINAL_DICI_M_25 | E6: Primary. Jul/Aug-2026 levels reconstructed from the press release - see Read me.
B7: CPI validation | C7: INDEC, informes de prensa IPC | D7: Monthly press releases | E7: Compounded m/m reproduces published Dec/Dec: 2019 53.8, 2020 36.1, 2021 50.9, 2022 94.8, 2023 211.4, 2024 117.8, 2025 31.5.
B8: Monetary financing | C8: BCRA, Informe Monetario Mensual, December editions | D8: Bol1219, Bol1220, Bol1221, Bol1222, informe-monetario-mensual-dic-2023 | E8: Factores de variacion de la base monetaria.
B9: Monetary financing % GDP | C9: IMF Country Report 25/3 (Ex-Post Evaluation of the 2022 EFF) para.6 p.12, para.31 p.33; IMF CR 22/92 Box 2 p.35 | D9: CR 25/3; CR 22/92 | E9: MIXED DEFINITION vs BCRA - see Read me.
B10: Quasi-fiscal / net credit | C10: IMF Country Report 25/3, Ex-Post Evaluation, para.31 p.33 | D10: CR 25/3 | E10: Quasi-fiscal 3.3 / 5.2 / 10.5% GDP 2021-23; BCRA net credit to government 24.6% GDP end-2023.
B11: Remunerated liabilities | C11: BCRA, Informe al Congreso 2023, pp.15-17; IMM Nov-2023 and Dec-2023 | D11: Informecongreso2023 | E11: Note: the Informe p.17 mistypes the stock by a factor of 10 - cite the IMM.
B12: Letras intransferibles | C12: Decreto DNU 1599/2005; Resolucion Conjunta 1/2006 y 4/2006; BCRA balance sheet 23-Dec-2023 | D12: argentina.gob.ar/normativa norma-112207, norma-112815 | E12: Stock read from the balance sheet by Romano Group via Infobae 5-Jan-2024.
B13: Carta Organica limits | C13: Carta Organica del BCRA, Arts. 19, 20, 38, as amended by Leyes 25.562 and 26.739 | D13: InfoLeg norma 66194 | E13: Art.38 profit-transfer channel has NO quantitative ceiling.
B14: Hyperinflation benchmark | C14: Cagan via Fischer, Sahay & Vegh, 'Modern Hyper- and High Inflations', NBER WP 8930, p.2 | D14: NBER WP 8930 | E14: 50% per month.
B15: Hyperinflation comparators | C15: Hanke & Krus, 'The Hyperinflation Table', Cato Institute | D15: Cato | E15: Venezuela absent from the version retrieved - NOT SOURCED.
B16: Fiscal outturns | C16: MECON / Secretaria de Hacienda releases; IMF Art.IV 2026 | D16: IMF CR 2026/105 | E16: 2025 overall EXCLUDES zero-coupon interest recorded below the line - not like-for-like with 2023.
... B30: EXCLUDED | C30: teleSUR | D30: - | E30: Excluded as unreliable per standing research policy. Not used anywhere in this workbook.
B33: Series requested but NOT sourced — do not fill without new primary data
B34: Series | C34: Why, and the route to closing it
B35: Adelantos transitorios + utilidades, 2003-2018 | C35: No multi-year table in BCRA Informe al Congreso 2019 or CEPAL chapters. Route: BCRA Balance Semanal / Cuentas Analiticas historical files.
B36: Adelantos and utilidades separately by year | C36: BCRA publishes them as a single combined line in the factores de variacion.
B37: Letras intransferibles stock by year | C37: Only the 23-Dec-2023 point and administration-level totals, both press readings of the balance sheet. Route: BCRA audited Estados Contables annexes.
B38: Seigniorage / inflation tax, % GDP, any year | C38: Not published by BCRA; not tabulated in the IMF documents reviewed. Computing it from dBM/GDP would be a modelled proxy - declined.
B39: 1989-90 monthly INDEC CPI | C39: Only the Hanke-Krus peak (Jul-1989, 197% m/m). Spanish Wikipedia is unusable: cites Trading Economics and conflates m/m with annualised.
B40: Regulated vs headline cumulative 2019-2023 | C40: NOT COMPUTABLE from INDEC national - the regulados sub-index begins Jan-2022.
B41: Real ex-ante rate before Mar-2026 | C41: Requires the REM next-month expected CPI per round; the REM PDF summary tables would not machine-read in any round attempted.
B42: TAMAR and BADLAR before Oct-2025 | C42: Largest quantitative gap in the rates section. Route: BCRA Boletin Estadistico.
B43: UTDT ICG and ICC monthly history 2001-2023 | C43: utdt.edu:443 refused by the egress proxy; download path robots-disallowed. This is what a true empirical inflation-band mapping needs.
B44: REM 2027 median, Aug-2026 round | C44: Not in the PDF's readable text and absent from all press coverage found. The Jul-2026 round's 20.0% is carried forward.
B45: Discrete 2027 / 2028 market breakevens | C45: Needs the CER and fixed-rate curves priced simultaneously off BYMA/MAE or Bloomberg.
... B48: Buenos Aires province share of the national roll | C48: argentina.gob.ar Observatorio Electoral returned 403. ~37-38% is approximate - verify before publishing.

Sheet CPI Data
B2: INDEC IPC nacional — index levels and every derived rate
B3: Blue = published index level. Black = formula. Paste a new print into the yellow row and the workbook updates.
B5: Month | C5: Year | D5: M# | E5: Nivel General (index) | F5: Nucleo (index) | G5: Regulados (index) | H5: Estacionales (index) | I5: m/m Nivel Gen. | J5: m/m Nucleo | K5: m/m Regulados | L5: m/m Estacion. | M5: y/y Nivel Gen. | N5: y/y Nucleo | O5: y/y Regulados | P5: 3m ann. Nivel Gen. | Q5: 3m ann. Nucleo | R5: 6m ann. Nivel Gen. | S5: YTD Nivel Gen. | T5: Reg less core m/m (pp) | U5: Reg/core Dec-23=100
B6: 2018-12 | C6: 2018 | D6: 12 | E6: 184.2552 | F6: 178.9326 | T6: =IF(OR(K6="",J6=""),"",(K6-J6)*100) | U6: =IF(OR(G6="",F6=""),"",(G6/INDEX($G:$G,MATCH("2023-12",$B:$B,0)))/(F6/INDEX($F:$F,MATCH("2023-12",$B:$B,0)))*100)
B7: 2019-01 | C7: 2019 | D7: 1 | E7: 189.6101 | F7: 184.3056 | I7: =IF(OR(E7="",E6=""),"",E7/E6-1) | J7: =IF(OR(F7="",F6=""),"",F7/F6-1) | K7: =IF(OR(G7="",G6=""),"",G7/G6-1) | L7: =IF(OR(H7="",H6=""),"",H7/H6-1) | S7: =IF(E7="","",IFERROR(E7/INDEX($E:$E,MATCH(C7-1&"-12",$B:$B,0))-1,"")) | T7: =IF(OR(K7="",J7=""),"",(K7-J7)*100) | U7: =IF(OR(G7="",F7=""),"",(G7/INDEX($G:$G,MATCH("2023-12",$B:$B,0)))/(F7/INDEX($F:$F,MATCH("2023-12",$B:$B,0)))*100)
B8: 2019-02 | C8: 2019 | D8: 2 | E8: 196.7501 | F8: 191.4115 | I8: =IF(OR(E8="",E7=""),"",E8/E7-1) | J8: =IF(OR(F8="",F7=""),"",F8/F7-1) | K8: =IF(OR(G8="",G7=""),"",G8/G7-1) | L8: =IF(OR(H8="",H7=""),"",H8/H7-1) | S8: =IF(E8="","",IFERROR(E8/INDEX($E:$E,MATCH(C8-1&"-12",$B:$B,0))-1,"")) | T8: =IF(OR(K8="",J8=""),"",(K8-J8)*100) | U8: =IF(OR(G8="",F8=""),"",(G8/INDEX($G:$G,MATCH("2023-12",$B:$B,0)))/(F8/INDEX($F:$F,MATCH("2023-12",$B:$B,0)))*100)
B9: 2019-03 | C9: 2019 | D9: 3 | E9: 205.9571 | F9: 200.1771 | I9: =IF(OR(E9="",E8=""),"",E9/E8-1) | J9: =IF(OR(F9="",F8=""),"",F9/F8-1) | K9: =IF(OR(G9="",G8=""),"",G9/G8-1) | L9: =IF(OR(H9="",H8=""),"",H9/H8-1) | P9: =IF(OR(E9="",E6=""),"",(E9/E6)^4-1) | Q9: =IF(OR(F9="",F6=""),"",(F9/F6)^4-1) | S9: =IF(E9="","",IFERROR(E9/INDEX($E:$E,MATCH(C9-1&"-12",$B:$B,0))-1,"")) | T9: =IF(OR(K9="",J9=""),"",(K9-J9)*100) | U9: =IF(OR(G9="",F9=""),"",(G9/INDEX($G:$G,MATCH("2023-12",$B:$B,0)))/(F9/INDEX($F:$F,MATCH("2023-12",$B:$B,0)))*100)
B10: 2019-04 | C10: 2019 | D10: 4 | E10: 212.95964 | F10: 207.7179 | I10: =IF(OR(E10="",E9=""),"",E10/E9-1) | J10: =IF(OR(F10="",F9=""),"",F10/F9-1) | K10: =IF(OR(G10="",G9=""),"",G10/G9-1) | L10: =IF(OR(H10="",H9=""),"",H10/H9-1) | P10: =IF(OR(E10="",E7=""),"",(E10/E7)^4-1) | Q10: =IF(OR(F10="",F7=""),"",(F10/F7)^4-1) | S10: =IF(E10="","",IFERROR(E10/INDEX($E:$E,MATCH(C10-1&"-12",$B:$B,0))-1,"")) | T10: =IF(OR(K10="",J10=""),"",(K10-J10)*100) | U10: =IF(OR(G10="",F10=""),"",(G10/INDEX($G:$G,MATCH("2023-12",$B:$B,0)))/(F10/INDEX($F:$F,MATCH("2023-12",$B:$B,0)))*100)
B11: 2019-05 | C11: 2019 | D11: 5 | E11: 219.5691 | F11: 214.3182 | I11: =IF(OR(E11="",E10=""),"",E11/E10-1) | J11: =IF(OR(F11="",F10=""),"",F11/F10-1) | K11: =IF(OR(G11="",G10=""),"",G11/G10-1) | L11: =IF(OR(H11="",H10=""),"",H11/H10-1) | P11: =IF(OR(E11="",E8=""),"",(E11/E8)^4-1) | Q11: =IF(OR(F11="",F8=""),"",(F11/F8)^4-1) | S11: =IF(E11="","",IFERROR(E11/INDEX($E:$E,MATCH(C11-1&"-12",$B:$B,0))-1,"")) | T11: =IF(OR(K11="",J11=""),"",(K11-J11)*100) | U11: =IF(OR(G11="",F11=""),"",(G11/INDEX($G:$G,MATCH("2023-12",$B:$B,0)))/(F11/INDEX($F:$F,MATCH("2023-12",$B:$B,0)))*100)
B12: 2019-06 | C12: 2019 | D12: 6 | E12: 225.537 | F12: 220.1725 | I12: =IF(OR(E12="",E11=""),"",E12/E11-1) | J12: =IF(OR(F12="",F11=""),"",F12/F11-1) | K12: =IF(OR(G12="",G11=""),"",G12/G11-1) | L12: =IF(OR(H12="",H11=""),"",H12/H11-1) | P12: =IF(OR(E12="",E9=""),"",(E12/E9)^4-1) | Q12: =IF(OR(F12="",F9=""),"",(F12/F9)^4-1) | R12: =IF(OR(E12="",E6=""),"",(E12/E6)^2-1) | S12: =IF(E12="","",IFERROR(E12/INDEX($E:$E,MATCH(C12-1&"-12",$B:$B,0))-1,"")) | T12: =IF(OR(K12="",J12=""),"",(K12-J12)*100) | U12: =IF(OR(G12="",F12=""),"",(G12/INDEX($G:$G,MATCH("2023-12",$B:$B,0)))/(F12/INDEX($F:$F,MATCH("2023-12",$B:$B,0)))*100)
B13: 2019-07 | C13: 2019 | D13: 7 | E13: 230.494 | F13: 224.9011 | I13: =IF(OR(E13="",E12=""),"",E13/E12-1) | J13: =IF(OR(F13="",F12=""),"",F13/F12-1) | K13: =IF(OR(G13="",G12=""),"",G13/G12-1) | L13: =IF(OR(H13="",H12=""),"",H13/H12-1) | P13: =IF(OR(E13="",E10=""),"",(E13/E10)^4-1) | Q13: =IF(OR(F13="",F10=""),"",(F13/F10)^4-1) | R13: =IF(OR(E13="",E7=""),"",(E13/E7)^2-1) | S13: =IF(E13="","",IFERROR(E13/INDEX($E:$E,MATCH(C13-1&"-12",$B:$B,0))-1,"")) | T13: =IF(OR(K13="",J13=""),"",(K13-J13)*100) | U13: =IF(OR(G13="",F13=""),"",(G13/INDEX($G:$G,MATCH("2023-12",$B:$B,0)))/(F13/INDEX($F:$F,MATCH("2023-12",$B:$B,0)))*100)
B14: 2019-08 | C14: 2019 | D14: 8 | E14: 239.6077 | F14: 235.3317 | I14: =IF(OR(E14="",E13=""),"",E14/E13-1) | J14: =IF(OR(F14="",F13=""),"",F14/F13-1) | K14: =IF(OR(G14="",G13=""),"",G14/G13-1) | L14: =IF(OR(H14="",H13=""),"",H14/H13-1) | P14: =IF(OR(E14="",E11=""),"",(E14/E11)^4-1) | Q14: =IF(OR(F14="",F11=""),"",(F14/F11)^4-1) | R14: =IF(OR(E14="",E8=""),"",(E14/E8)^2-1) | S14: =IF(E14="","",IFERROR(E14/INDEX($E:$E,MATCH(C14-1&"-12",$B:$B,0))-1,"")) | T14: =IF(OR(K14="",J14=""),"",(K14-J14)*100) | U14: =IF(OR(G14="",F14=""),"",(G14/INDEX($G:$G,MATCH("2023-12",$B:$B,0)))/(F14/INDEX($F:$F,MATCH("2023-12",$B:$B,0)))*100)
B15: 2019-09 | C15: 2019 | D15: 9 | E15: 253.7102 | F15: 250.4818 | I15: =IF(OR(E15="",E14=""),"",E15/E14-1) | J15: =IF(OR(F15="",F14=""),"",F15/F14-1) | K15: =IF(OR(G15="",G14=""),"",G15/G14-1) | L15: =IF(OR(H15="",H14=""),"",H15/H14-1) | P15: =IF(OR(E15="",E12=""),"",(E15/E12)^4-1) | Q15: =IF(OR(F15="",F12=""),"",(F15/F12)^4-1) | R15: =IF(OR(E15="",E9=""),"",(E15/E9)^2-1) | S15: =IF(E15="","",IFERROR(E15/INDEX($E:$E,MATCH(C15-1&"-12",$B:$B,0))-1,"")) | T15: =IF(OR(K15="",J15=""),"",(K15-J15)*100) | U15: =IF(OR(G15="",F15=""),"",(G15/INDEX($G:$G,MATCH("2023-12",$B:$B,0)))/(F15/INDEX($F:$F,MATCH("2023-12",$B:$B,0)))*100)
B16: 2019-10 | C16: 2019 | D16: 10 | E16: 262.0661 | F16: 260.0118 | I16: =IF(OR(E16="",E15=""),"",E16/E15-1) | J16: =IF(OR(F16="",F15=""),"",F16/F15-1) | K16: =IF(OR(G16="",G15=""),"",G16/G15-1) | L16: =IF(OR(H16="",H15=""),"",H16/H15-1) | P16: =IF(OR(E16="",E13=""),"",(E16/E13)^4-1) | Q16: =IF(OR(F16="",F13=""),"",(F16/F13)^4-1) | R16: =IF(OR(E16="",E10=""),"",(E16/E10)^2-1) | S16: =IF(E16="","",IFERROR(E16/INDEX($E:$E,MATCH(C16-1&"-12",$B:$B,0))-1,"")) | T16: =IF(OR(K16="",J16=""),"",(K16-J16)*100) | U16: =IF(OR(G16="",F16=""),"",(G16/INDEX($G:$G,MATCH("2023-12",$B:$B,0)))/(F16/INDEX($F:$F,MATCH("2023-12",$B:$B,0)))*100)
B17: 2019-11 | C17: 2019 | D17: 11 | E17: 273.2158 | F17: 270.3554 | I17: =IF(OR(E17="",E16=""),"",E17/E16-1) | J17: =IF(OR(F17="",F16=""),"",F17/F16-1) | K17: =IF(OR(G17="",G16=""),"",G17/G16-1) | L17: =IF(OR(H17="",H16=""),"",H17/H16-1) | P17: =IF(OR(E17="",E14=""),"",(E17/E14)^4-1) | Q17: =IF(OR(F17="",F14=""),"",(F17/F14)^4-1) | R17: =IF(OR(E17="",E11=""),"",(E17/E11)^2-1) | S17: =IF(E17="","",IFERROR(E17/INDEX($E:$E,MATCH(C17-1&"-12",$B:$B,0))-1,"")) | T17: =IF(OR(K17="",J17=""),"",(K17-J17)*100) | U17: =IF(OR(G17="",F17=""),"",(G17/INDEX($G:$G,MATCH("2023-12",$B:$B,0)))/(F17/INDEX($F:$F,MATCH("2023-12",$B:$B,0)))*100)
B18: 2019-12 | C18: 2019 | D18: 12 | E18: 283.4442 | F18: 280.3107 | I18: =IF(OR(E18="",E17=""),"",E18/E17-1) | J18: =IF(OR(F18="",F17=""),"",F18/F17-1) | K18: =IF(OR(G18="",G17=""),"",G18/G17-1) | L18: =IF(OR(H18="",H17=""),"",H18/H17-1) | M18: =IF(OR(E18="",E6=""),"",E18/E6-1) | N18: =IF(OR(F18="",F6=""),"",F18/F6-1) | O18: =IF(OR(G18="",G6=""),"",G18/G6-1) | P18: =IF(OR(E18="",E15=""),"",(E18/E15)^4-1) | Q18: =IF(OR(F18="",F15=""),"",(F18/F15)^4-1) | R18: =IF(OR(E18="",E12=""),"",(E18/E12)^2-1) | S18: =IF(E18="","",IFERROR(E18/INDEX($E:$E,MATCH(C18-1&"-12",$B:$B,0))-1,"")) | T18: =IF(OR(K18="",J18=""),"",(K18-J18)*100) | U18: =IF(OR(G18="",F18=""),"",(G18/INDEX($G:$G,MATCH("2023-12",$B:$B,0)))/(F18/INDEX($F:$F,MATCH("2023-12",$B:$B,0)))*100)
B19: 2020-01 | C19: 2020 | D19: 1 | E19: 289.8299 | F19: 287.1529 | I19: =IF(OR(E19="",E18=""),"",E19/E18-1) | J19: =IF(OR(F19="",F18=""),"",F19/F18-1) | K19: =IF(OR(G19="",G18=""),"",G19/G18-1) | L19: =IF(OR(H19="",H18=""),"",H19/H18-1) | M19: =IF(OR(E19="",E7=""),"",E19/E7-1) | N19: =IF(OR(F19="",F7=""),"",F19/F7-1) | O19: =IF(OR(G19="",G7=""),"",G19/G7-1) | P19: =IF(OR(E19="",E16=""),"",(E19/E16)^4-1) | Q19: =IF(OR(F19="",F16=""),"",(F19/F16)^4-1) | R19: =IF(OR(E19="",E13=""),"",(E19/E13)^2-1) | S19: =IF(E19="","",IFERROR(E19/INDEX($E:$E,MATCH(C19-1&"-12",$B:$B,0))-1,"")) | T19: =IF(OR(K19="",J19=""),"",(K19-J19)*100) | U19: =IF(OR(G19="",F19=""),"",(G19/INDEX($G:$G,MATCH("2023-12",$B:$B,0)))/(F19/INDEX($F:$F,MATCH("2023-12",$B:$B,0)))*100)
B20: 2020-02 | C20: 2020 | D20: 2 | E20: 295.666 | F20: 293.9922 | I20: =IF(OR(E20="",E19=""),"",E20/E19-1) | J20: =IF(OR(F20="",F19=""),"",F20/F19-1) | K20: =IF(OR(G20="",G19=""),"",G20/G19-1) | L20: =IF(OR(H20="",H19=""),"",H20/H19-1) | M20: =IF(OR(E20="",E8=""),"",E20/E8-1) | N20: =IF(OR(F20="",F8=""),"",F20/F8-1) | O20: =IF(OR(G20="",G8=""),"",G20/G8-1) | P20: =IF(OR(E20="",E17=""),"",(E20/E17)^4-1) | Q20: =IF(OR(F20="",F17=""),"",(F20/F17)^4-1) | R20: =IF(OR(E20="",E14=""),"",(E20/E14)^2-1) | S20: =IF(E20="","",IFERROR(E20/INDEX($E:$E,MATCH(C20-1&"-12",$B:$B,0))-1,"")) | T20: =IF(OR(K20="",J20=""),"",(K20-J20)*100) | U20: =IF(OR(G20="",F20=""),"",(G20/INDEX($G:$G,MATCH("2023-12",$B:$B,0)))/(F20/INDEX($F:$F,MATCH("2023-12",$B:$B,0)))*100)
B21: 2020-03 | C21: 2020 | D21: 3 | E21: 305.5515 | F21: 303.1665 | I21: =IF(OR(E21="",E20=""),"",E21/E20-1) | J21: =IF(OR(F21="",F20=""),"",F21/F20-1) | K21: =IF(OR(G21="",G20=""),"",G21/G20-1) | L21: =IF(OR(H21="",H20=""),"",H21/H20-1) | M21: =IF(OR(E21="",E9=""),"",E21/E9-1) | N21: =IF(OR(F21="",F9=""),"",F21/F9-1) | O21: =IF(OR(G21="",G9=""),"",G21/G9-1) | P21: =IF(OR(E21="",E18=""),"",(E21/E18)^4-1) | Q21: =IF(OR(F21="",F18=""),"",(F21/F18)^4-1) | R21: =IF(OR(E21="",E15=""),"",(E21/E15)^2-1) | S21: =IF(E21="","",IFERROR(E21/INDEX($E:$E,MATCH(C21-1&"-12",$B:$B,0))-1,"")) | T21: =IF(OR(K21="",J21=""),"",(K21-J21)*100) | U21: =IF(OR(G21="",F21=""),"",(G21/INDEX($G:$G,MATCH("2023-12",$B:$B,0)))/(F21/INDEX($F:$F,MATCH("2023-12",$B:$B,0)))*100)
B22: 2020-04 | C22: 2020 | D22: 4 | E22: 310.1243 | F22: 308.3681 | I22: =IF(OR(E22="",E21=""),"",E22/E21-1) | J22: =IF(OR(F22="",F21=""),"",F22/F21-1) | K22: =IF(OR(G22="",G21=""),"",G22/G21-1) | L22: =IF(OR(H22="",H21=""),"",H22/H21-1) | M22: =IF(OR(E22="",E10=""),"",E22/E10-1) | N22: =IF(OR(F22="",F10=""),"",F22/F10-1) | O22: =IF(OR(G22="",G10=""),"",G22/G10-1) | P22: =IF(OR(E22="",E19=""),"",(E22/E19)^4-1) | Q22: =IF(OR(F22="",F19=""),"",(F22/F19)^4-1) | R22: =IF(OR(E22="",E16=""),"",(E22/E16)^2-1) | S22: =IF(E22="","",IFERROR(E22/INDEX($E:$E,MATCH(C22-1&"-12",$B:$B,0))-1,"")) | T22: =IF(OR(K22="",J22=""),"",(K22-J22)*100) | U22: =IF(OR(G22="",F22=""),"",(G22/INDEX($G:$G,MATCH("2023-12",$B:$B,0)))/(F22/INDEX($F:$F,MATCH("2023-12",$B:$B,0)))*100)
B23: 2020-05 | C23: 2020 | D23: 5 | E23: 314.9087 | F23: 313.3195 | I23: =IF(OR(E23="",E22=""),"",E23/E22-1) | J23: =IF(OR(F23="",F22=""),"",F23/F22-1) | K23: =IF(OR(G23="",G22=""),"",G23/G22-1) | L23: =IF(OR(H23="",H22=""),"",H23/H22-1) | M23: =IF(OR(E23="",E11=""),"",E23/E11-1) | N23: =IF(OR(F23="",F11=""),"",F23/F11-1) | O23: =IF(OR(G23="",G11=""),"",G23/G11-1) | P23: =IF(OR(E23="",E20=""),"",(E23/E20)^4-1) | Q23: =IF(OR(F23="",F20=""),"",(F23/F20)^4-1) | R23: =IF(OR(E23="",E17=""),"",(E23/E17)^2-1) | S23: =IF(E23="","",IFERROR(E23/INDEX($E:$E,MATCH(C23-1&"-12",$B:$B,0))-1,"")) | T23: =IF(OR(K23="",J23=""),"",(K23-J23)*100) | U23: =IF(OR(G23="",F23=""),"",(G23/INDEX($G:$G,MATCH("2023-12",$B:$B,0)))/(F23/INDEX($F:$F,MATCH("2023-12",$B:$B,0)))*100)
B24: 2020-06 | C24: 2020 | D24: 6 | E24: 321.9738 | F24: 320.5733 | I24: =IF(OR(E24="",E23=""),"",E24/E23-1) | J24: =IF(OR(F24="",F23=""),"",F24/F23-1) | K24: =IF(OR(G24="",G23=""),"",G24/G23-1) | L24: =IF(OR(H24="",H23=""),"",H24/H23-1) | M24: =IF(OR(E24="",E12=""),"",E24/E12-1) | N24: =IF(OR(F24="",F12=""),"",F24/F12-1) | O24: =IF(OR(G24="",G12=""),"",G24/G12-1) | P24: =IF(OR(E24="",E21=""),"",(E24/E21)^4-1) | Q24: =IF(OR(F24="",F21=""),"",(F24/F21)^4-1) | R24: =IF(OR(E24="",E18=""),"",(E24/E18)^2-1) | S24: =IF(E24="","",IFERROR(E24/INDEX($E:$E,MATCH(C24-1&"-12",$B:$B,0))-1,"")) | T24: =IF(OR(K24="",J24=""),"",(K24-J24)*100) | U24: =IF(OR(G24="",F24=""),"",(G24/INDEX($G:$G,MATCH("2023-12",$B:$B,0)))/(F24/INDEX($F:$F,MATCH("2023-12",$B:$B,0)))*100)
B25: 2020-07 | C25: 2020 | D25: 7 | E25: 328.2014 | F25: 328.6943 | I25: =IF(OR(E25="",E24=""),"",E25/E24-1) | J25: =IF(OR(F25="",F24=""),"",F25/F24-1) | K25: =IF(OR(G25="",G24=""),"",G25/G24-1) | L25: =IF(OR(H25="",H24=""),"",H25/H24-1) | M25: =IF(OR(E25="",E13=""),"",E25/E13-1) | N25: =IF(OR(F25="",F13=""),"",F25/F13-1) | O25: =IF(OR(G25="",G13=""),"",G25/G13-1) | P25: =IF(OR(E25="",E22=""),"",(E25/E22)^4-1) | Q25: =IF(OR(F25="",F22=""),"",(F25/F22)^4-1) | R25: =IF(OR(E25="",E19=""),"",(E25/E19)^2-1) | S25: =IF(E25="","",IFERROR(E25/INDEX($E:$E,MATCH(C25-1&"-12",$B:$B,0))-1,"")) | T25: =IF(OR(K25="",J25=""),"",(K25-J25)*100) | U25: =IF(OR(G25="",F25=""),"",(G25/INDEX($G:$G,MATCH("2023-12",$B:$B,0)))/(F25/INDEX($F:$F,MATCH("2023-12",$B:$B,0)))*100)
B26: 2020-08 | C26: 2020 | D26: 8 | E26: 337.0632 | F26: 338.6645 | I26: =IF(OR(E26="",E25=""),"",E26/E25-1) | J26: =IF(OR(F26="",F25=""),"",F26/F25-1) | K26: =IF(OR(G26="",G25=""),"",G26/G25-1) | L26: =IF(OR(H26="",H25=""),"",H26/H25-1) | M26: =IF(OR(E26="",E14=""),"",E26/E14-1) | N26: =IF(OR(F26="",F14=""),"",F26/F14-1) | O26: =IF(OR(G26="",G14=""),"",G26/G14-1) | P26: =IF(OR(E26="",E23=""),"",(E26/E23)^4-1) | Q26: =IF(OR(F26="",F23=""),"",(F26/F23)^4-1) | R26: =IF(OR(E26="",E20=""),"",(E26/E20)^2-1) | S26: =IF(E26="","",IFERROR(E26/INDEX($E:$E,MATCH(C26-1&"-12",$B:$B,0))-1,"")) | T26: =IF(OR(K26="",J26=""),"",(K26-J26)*100) | U26: =IF(OR(G26="",F26=""),"",(G26/INDEX($G:$G,MATCH("2023-12",$B:$B,0)))/(F26/INDEX($F:$F,MATCH("2023-12",$B:$B,0)))*100)
B27: 2020-09 | C27: 2020 | D27: 9 | E27: 346.6207 | F27: 346.511 | I27: =IF(OR(E27="",E26=""),"",E27/E26-1) | J27: =IF(OR(F27="",F26=""),"",F27/F26-1) | K27: =IF(OR(G27="",G26=""),"",G27/G26-1) | L27: =IF(OR(H27="",H26=""),"",H27/H26-1) | M27: =IF(OR(E27="",E15=""),"",E27/E15-1) | N27: =IF(OR(F27="",F15=""),"",F27/F15-1) | O27: =IF(OR(G27="",G15=""),"",G27/G15-1) | P27: =IF(OR(E27="",E24=""),"",(E27/E24)^4-1) | Q27: =IF(OR(F27="",F24=""),"",(F27/F24)^4-1) | R27: =IF(OR(E27="",E21=""),"",(E27/E21)^2-1) | S27: =IF(E27="","",IFERROR(E27/INDEX($E:$E,MATCH(C27-1&"-12",$B:$B,0))-1,"")) | T27: =IF(OR(K27="",J27=""),"",(K27-J27)*100) | U27: =IF(OR(G27="",F27=""),"",(G27/INDEX($G:$G,MATCH("2023-12",$B:$B,0)))/(F27/INDEX($F:$F,MATCH("2023-12",$B:$B,0)))*100)
B28: 2020-10 | C28: 2020 | D28: 10 | E28: 359.657 | F28: 358.4989 | I28: =IF(OR(E28="",E27=""),"",E28/E27-1) | J28: =IF(OR(F28="",F27=""),"",F28/F27-1) | K28: =IF(OR(G28="",G27=""),"",G28/G27-1) | L28: =IF(OR(H28="",H27=""),"",H28/H27-1) | M28: =IF(OR(E28="",E16=""),"",E28/E16-1) | N28: =IF(OR(F28="",F16=""),"",F28/F16-1) | O28: =IF(OR(G28="",G16=""),"",G28/G16-1) | P28: =IF(OR(E28="",E25=""),"",(E28/E25)^4-1) | Q28: =IF(OR(F28="",F25=""),"",(F28/F25)^4-1) | R28: =IF(OR(E28="",E22=""),"",(E28/E22)^2-1) | S28: =IF(E28="","",IFERROR(E28/INDEX($E:$E,MATCH(C28-1&"-12",$B:$B,0))-1,"")) | T28: =IF(OR(K28="",J28=""),"",(K28-J28)*100) | U28: =IF(OR(G28="",F28=""),"",(G28/INDEX($G:$G,MATCH("2023-12",$B:$B,0)))/(F28/INDEX($F:$F,MATCH("2023-12",$B:$B,0)))*100)
B29: 2020-11 | C29: 2020 | D29: 11 | E29: 371.0211 | F29: 372.6154 | I29: =IF(OR(E29="",E28=""),"",E29/E28-1) | J29: =IF(OR(F29="",F28=""),"",F29/F28-1) | K29: =IF(OR(G29="",G28=""),"",G29/G28-1) | L29: =IF(OR(H29="",H28=""),"",H29/H28-1) | M29: =IF(OR(E29="",E17=""),"",E29/E17-1) | N29: =IF(OR(F29="",F17=""),"",F29/F17-1) | O29: =IF(OR(G29="",G17=""),"",G29/G17-1) | P29: =IF(OR(E29="",E26=""),"",(E29/E26)^4-1) | Q29: =IF(OR(F29="",F26=""),"",(F29/F26)^4-1) | R29: =IF(OR(E29="",E23=""),"",(E29/E23)^2-1) | S29: =IF(E29="","",IFERROR(E29/INDEX($E:$E,MATCH(C29-1&"-12",$B:$B,0))-1,"")) | T29: =IF(OR(K29="",J29=""),"",(K29-J29)*100) | U29: =IF(OR(G29="",F29=""),"",(G29/INDEX($G:$G,MATCH("2023-12",$B:$B,0)))/(F29/INDEX($F:$F,MATCH("2023-12",$B:$B,0)))*100)
... B42: 2021-12 | C42: 2021 | D42: 12 | E42: 582.4575 | F42: 605.1759 | I42: =IF(OR(E42="",E41=""),"",E42/E41-1) | J42: =IF(OR(F42="",F41=""),"",F42/F41-1) | K42: =IF(OR(G42="",G41=""),"",G42/G41-1) | L42: =IF(OR(H42="",H41=""),"",H42/H41-1) | M42: =IF(OR(E42="",E30=""),"",E42/E30-1) | N42: =IF(OR(F42="",F30=""),"",F42/F30-1) | O42: =IF(OR(G42="",G30=""),"",G42/G30-1) | P42: =IF(OR(E42="",E39=""),"",(E42/E39)^4-1) | Q42: =IF(OR(F42="",F39=""),"",(F42/F39)^4-1) | R42: =IF(OR(E42="",E36=""),"",(E42/E36)^2-1) | S42: =IF(E42="","",IFERROR(E42/INDEX($E:$E,MATCH(C42-1&"-12",$B:$B,0))-1,"")) | T42: =IF(OR(K42="",J42=""),"",(K42-J42)*100) | U42: =IF(OR(G42="",F42=""),"",(G42/INDEX($G:$G,MATCH("2023-12",$B:$B,0)))/(F42/INDEX($F:$F,MATCH("2023-12",$B:$B,0)))*100)
B43: 2022-01 | C43: 2022 | D43: 1 | E43: 605.0317 | F43: 625.1594 | G43: 512.3766 | H43: 658.2543 | I43: =IF(OR(E43="",E42=""),"",E43/E42-1) | J43: =IF(OR(F43="",F42=""),"",F43/F42-1) | K43: =IF(OR(G43="",G42=""),"",G43/G42-1) | L43: =IF(OR(H43="",H42=""),"",H43/H42-1) | M43: =IF(OR(E43="",E31=""),"",E43/E31-1) | N43: =IF(OR(F43="",F31=""),"",F43/F31-1) | O43: =IF(OR(G43="",G31=""),"",G43/G31-1) | P43: =IF(OR(E43="",E40=""),"",(E43/E40)^4-1) | Q43: =IF(OR(F43="",F40=""),"",(F43/F40)^4-1) | R43: =IF(OR(E43="",E37=""),"",(E43/E37)^2-1) | S43: =IF(E43="","",IFERROR(E43/INDEX($E:$E,MATCH(C43-1&"-12",$B:$B,0))-1,"")) | T43: =IF(OR(K43="",J43=""),"",(K43-J43)*100) | U43: =IF(OR(G43="",F43=""),"",(G43/INDEX($G:$G,MATCH("2023-12",$B:$B,0)))/(F43/INDEX($F:$F,MATCH("2023-12",$B:$B,0)))*100)
B44: 2022-02 | C44: 2022 | D44: 2 | E44: 633.4341 | F44: 652.9838 | G44: 528.2683 | H44: 713.7013 | I44: =IF(OR(E44="",E43=""),"",E44/E43-1) | J44: =IF(OR(F44="",F43=""),"",F44/F43-1) | K44: =IF(OR(G44="",G43=""),"",G44/G43-1) | L44: =IF(OR(H44="",H43=""),"",H44/H43-1) | M44: =IF(OR(E44="",E32=""),"",E44/E32-1) | N44: =IF(OR(F44="",F32=""),"",F44/F32-1) | O44: =IF(OR(G44="",G32=""),"",G44/G32-1) | P44: =IF(OR(E44="",E41=""),"",(E44/E41)^4-1) | Q44: =IF(OR(F44="",F41=""),"",(F44/F41)^4-1) | R44: =IF(OR(E44="",E38=""),"",(E44/E38)^2-1) | S44: =IF(E44="","",IFERROR(E44/INDEX($E:$E,MATCH(C44-1&"-12",$B:$B,0))-1,"")) | T44: =IF(OR(K44="",J44=""),"",(K44-J44)*100) | U44: =IF(OR(G44="",F44=""),"",(G44/INDEX($G:$G,MATCH("2023-12",$B:$B,0)))/(F44/INDEX($F:$F,MATCH("2023-12",$B:$B,0)))*100)
B45: 2022-03 | C45: 2022 | D45: 3 | E45: 676.0566 | F45: 694.7515 | G45: 572.7992 | H45: 757.8963 | I45: =IF(OR(E45="",E44=""),"",E45/E44-1) | J45: =IF(OR(F45="",F44=""),"",F45/F44-1) | K45: =IF(OR(G45="",G44=""),"",G45/G44-1) | L45: =IF(OR(H45="",H44=""),"",H45/H44-1) | M45: =IF(OR(E45="",E33=""),"",E45/E33-1) | N45: =IF(OR(F45="",F33=""),"",F45/F33-1) | O45: =IF(OR(G45="",G33=""),"",G45/G33-1) | P45: =IF(OR(E45="",E42=""),"",(E45/E42)^4-1) | Q45: =IF(OR(F45="",F42=""),"",(F45/F42)^4-1) | R45: =IF(OR(E45="",E39=""),"",(E45/E39)^2-1) | S45: =IF(E45="","",IFERROR(E45/INDEX($E:$E,MATCH(C45-1&"-12",$B:$B,0))-1,"")) | T45: =IF(OR(K45="",J45=""),"",(K45-J45)*100) | U45: =IF(OR(G45="",F45=""),"",(G45/INDEX($G:$G,MATCH("2023-12",$B:$B,0)))/(F45/INDEX($F:$F,MATCH("2023-12",$B:$B,0)))*100)
B46: 2022-04 | C46: 2022 | D46: 4 | E46: 716.9399 | F46: 741.3622 | G46: 595.2223 | H46: 799.0308 | I46: =IF(OR(E46="",E45=""),"",E46/E45-1) | J46: =IF(OR(F46="",F45=""),"",F46/F45-1) | K46: =IF(OR(G46="",G45=""),"",G46/G45-1) | L46: =IF(OR(H46="",H45=""),"",H46/H45-1) | M46: =IF(OR(E46="",E34=""),"",E46/E34-1) | N46: =IF(OR(F46="",F34=""),"",F46/F34-1) | O46: =IF(OR(G46="",G34=""),"",G46/G34-1) | P46: =IF(OR(E46="",E43=""),"",(E46/E43)^4-1) | Q46: =IF(OR(F46="",F43=""),"",(F46/F43)^4-1) | R46: =IF(OR(E46="",E40=""),"",(E46/E40)^2-1) | S46: =IF(E46="","",IFERROR(E46/INDEX($E:$E,MATCH(C46-1&"-12",$B:$B,0))-1,"")) | T46: =IF(OR(K46="",J46=""),"",(K46-J46)*100) | U46: =IF(OR(G46="",F46=""),"",(G46/INDEX($G:$G,MATCH("2023-12",$B:$B,0)))/(F46/INDEX($F:$F,MATCH("2023-12",$B:$B,0)))*100)
B47: 2022-05 | C47: 2022 | D47: 5 | E47: 753.147 | F47: 779.9267 | G47: 629.0029 | H47: 825.8088 | I47: =IF(OR(E47="",E46=""),"",E47/E46-1) | J47: =IF(OR(F47="",F46=""),"",F47/F46-1) | K47: =IF(OR(G47="",G46=""),"",G47/G46-1) | L47: =IF(OR(H47="",H46=""),"",H47/H46-1) | M47: =IF(OR(E47="",E35=""),"",E47/E35-1) | N47: =IF(OR(F47="",F35=""),"",F47/F35-1) | O47: =IF(OR(G47="",G35=""),"",G47/G35-1) | P47: =IF(OR(E47="",E44=""),"",(E47/E44)^4-1) | Q47: =IF(OR(F47="",F44=""),"",(F47/F44)^4-1) | R47: =IF(OR(E47="",E41=""),"",(E47/E41)^2-1) | S47: =IF(E47="","",IFERROR(E47/INDEX($E:$E,MATCH(C47-1&"-12",$B:$B,0))-1,"")) | T47: =IF(OR(K47="",J47=""),"",(K47-J47)*100) | U47: =IF(OR(G47="",F47=""),"",(G47/INDEX($G:$G,MATCH("2023-12",$B:$B,0)))/(F47/INDEX($F:$F,MATCH("2023-12",$B:$B,0)))*100)
B48: 2022-06 | C48: 2022 | D48: 6 | E48: 793.0278 | F48: 819.5734 | G48: 662.0938 | H48: 880.3186 | I48: =IF(OR(E48="",E47=""),"",E48/E47-1) | J48: =IF(OR(F48="",F47=""),"",F48/F47-1) | K48: =IF(OR(G48="",G47=""),"",G48/G47-1) | L48: =IF(OR(H48="",H47=""),"",H48/H47-1) | M48: =IF(OR(E48="",E36=""),"",E48/E36-1) | N48: =IF(OR(F48="",F36=""),"",F48/F36-1) | O48: =IF(OR(G48="",G36=""),"",G48/G36-1) | P48: =IF(OR(E48="",E45=""),"",(E48/E45)^4-1) | Q48: =IF(OR(F48="",F45=""),"",(F48/F45)^4-1) | R48: =IF(OR(E48="",E42=""),"",(E48/E42)^2-1) | S48: =IF(E48="","",IFERROR(E48/INDEX($E:$E,MATCH(C48-1&"-12",$B:$B,0))-1,"")) | T48: =IF(OR(K48="",J48=""),"",(K48-J48)*100) | U48: =IF(OR(G48="",F48=""),"",(G48/INDEX($G:$G,MATCH("2023-12",$B:$B,0)))/(F48/INDEX($F:$F,MATCH("2023-12",$B:$B,0)))*100)
B49: 2022-07 | C49: 2022 | D49: 7 | E49: 851.761 | F49: 879.6383 | G49: 694.6115 | H49: 979.7957 | I49: =IF(OR(E49="",E48=""),"",E49/E48-1) | J49: =IF(OR(F49="",F48=""),"",F49/F48-1) | K49: =IF(OR(G49="",G48=""),"",G49/G48-1) | L49: =IF(OR(H49="",H48=""),"",H49/H48-1) | M49: =IF(OR(E49="",E37=""),"",E49/E37-1) | N49: =IF(OR(F49="",F37=""),"",F49/F37-1) | O49: =IF(OR(G49="",G37=""),"",G49/G37-1) | P49: =IF(OR(E49="",E46=""),"",(E49/E46)^4-1) | Q49: =IF(OR(F49="",F46=""),"",(F49/F46)^4-1) | R49: =IF(OR(E49="",E43=""),"",(E49/E43)^2-1) | S49: =IF(E49="","",IFERROR(E49/INDEX($E:$E,MATCH(C49-1&"-12",$B:$B,0))-1,"")) | T49: =IF(OR(K49="",J49=""),"",(K49-J49)*100) | U49: =IF(OR(G49="",F49=""),"",(G49/INDEX($G:$G,MATCH("2023-12",$B:$B,0)))/(F49/INDEX($F:$F,MATCH("2023-12",$B:$B,0)))*100)
B50: 2022-08 | C50: 2022 | D50: 8 | E50: 911.1316 | F50: 939.4677 | G50: 738.3105 | H50: 1064.731 | I50: =IF(OR(E50="",E49=""),"",E50/E49-1) | J50: =IF(OR(F50="",F49=""),"",F50/F49-1) | K50: =IF(OR(G50="",G49=""),"",G50/G49-1) | L50: =IF(OR(H50="",H49=""),"",H50/H49-1) | M50: =IF(OR(E50="",E38=""),"",E50/E38-1) | N50: =IF(OR(F50="",F38=""),"",F50/F38-1) | O50: =IF(OR(G50="",G38=""),"",G50/G38-1) | P50: =IF(OR(E50="",E47=""),"",(E50/E47)^4-1) | Q50: =IF(OR(F50="",F47=""),"",(F50/F47)^4-1) | R50: =IF(OR(E50="",E44=""),"",(E50/E44)^2-1) | S50: =IF(E50="","",IFERROR(E50/INDEX($E:$E,MATCH(C50-1&"-12",$B:$B,0))-1,"")) | T50: =IF(OR(K50="",J50=""),"",(K50-J50)*100) | U50: =IF(OR(G50="",F50=""),"",(G50/INDEX($G:$G,MATCH("2023-12",$B:$B,0)))/(F50/INDEX($F:$F,MATCH("2023-12",$B:$B,0)))*100)
B51: 2022-09 | C51: 2022 | D51: 9 | E51: 967.3076 | F51: 991.2585 | G51: 771.8891 | H51: 1189.6609 | I51: =IF(OR(E51="",E50=""),"",E51/E50-1) | J51: =IF(OR(F51="",F50=""),"",F51/F50-1) | K51: =IF(OR(G51="",G50=""),"",G51/G50-1) | L51: =IF(OR(H51="",H50=""),"",H51/H50-1) | M51: =IF(OR(E51="",E39=""),"",E51/E39-1) | N51: =IF(OR(F51="",F39=""),"",F51/F39-1) | O51: =IF(OR(G51="",G39=""),"",G51/G39-1) | P51: =IF(OR(E51="",E48=""),"",(E51/E48)^4-1) | Q51: =IF(OR(F51="",F48=""),"",(F51/F48)^4-1) | R51: =IF(OR(E51="",E45=""),"",(E51/E45)^2-1) | S51: =IF(E51="","",IFERROR(E51/INDEX($E:$E,MATCH(C51-1&"-12",$B:$B,0))-1,"")) | T51: =IF(OR(K51="",J51=""),"",(K51-J51)*100) | U51: =IF(OR(G51="",F51=""),"",(G51/INDEX($G:$G,MATCH("2023-12",$B:$B,0)))/(F51/INDEX($F:$F,MATCH("2023-12",$B:$B,0)))*100)
B52: 2022-10 | C52: 2022 | D52: 10 | E52: 1028.706 | F52: 1046.265 | G52: 829.1011 | H52: 1297.2889 | I52: =IF(OR(E52="",E51=""),"",E52/E51-1) | J52: =IF(OR(F52="",F51=""),"",F52/F51-1) | K52: =IF(OR(G52="",G51=""),"",G52/G51-1) | L52: =IF(OR(H52="",H51=""),"",H52/H51-1) | M52: =IF(OR(E52="",E40=""),"",E52/E40-1) | N52: =IF(OR(F52="",F40=""),"",F52/F40-1) | O52: =IF(OR(G52="",G40=""),"",G52/G40-1) | P52: =IF(OR(E52="",E49=""),"",(E52/E49)^4-1) | Q52: =IF(OR(F52="",F49=""),"",(F52/F49)^4-1) | R52: =IF(OR(E52="",E46=""),"",(E52/E46)^2-1) | S52: =IF(E52="","",IFERROR(E52/INDEX($E:$E,MATCH(C52-1&"-12",$B:$B,0))-1,"")) | T52: =IF(OR(K52="",J52=""),"",(K52-J52)*100) | U52: =IF(OR(G52="",F52=""),"",(G52/INDEX($G:$G,MATCH("2023-12",$B:$B,0)))/(F52/INDEX($F:$F,MATCH("2023-12",$B:$B,0)))*100)
B53: 2022-11 | C53: 2022 | D53: 11 | E53: 1079.2787 | F53: 1096.024 | G53: 880.7676 | H53: 1350.5167 | I53: =IF(OR(E53="",E52=""),"",E53/E52-1) | J53: =IF(OR(F53="",F52=""),"",F53/F52-1) | K53: =IF(OR(G53="",G52=""),"",G53/G52-1) | L53: =IF(OR(H53="",H52=""),"",H53/H52-1) | M53: =IF(OR(E53="",E41=""),"",E53/E41-1) | N53: =IF(OR(F53="",F41=""),"",F53/F41-1) | O53: =IF(OR(G53="",G41=""),"",G53/G41-1) | P53: =IF(OR(E53="",E50=""),"",(E53/E50)^4-1) | Q53: =IF(OR(F53="",F50=""),"",(F53/F50)^4-1) | R53: =IF(OR(E53="",E47=""),"",(E53/E47)^2-1) | S53: =IF(E53="","",IFERROR(E53/INDEX($E:$E,MATCH(C53-1&"-12",$B:$B,0))-1,"")) | T53: =IF(OR(K53="",J53=""),"",(K53-J53)*100) | U53: =IF(OR(G53="",F53=""),"",(G53/INDEX($G:$G,MATCH("2023-12",$B:$B,0)))/(F53/INDEX($F:$F,MATCH("2023-12",$B:$B,0)))*100)
B54: 2022-12 | C54: 2022 | D54: 12 | E54: 1134.5875 | F54: 1153.5771 | G54: 925.7853 | H54: 1413.2059 | I54: =IF(OR(E54="",E53=""),"",E54/E53-1) | J54: =IF(OR(F54="",F53=""),"",F54/F53-1) | K54: =IF(OR(G54="",G53=""),"",G54/G53-1) | L54: =IF(OR(H54="",H53=""),"",H54/H53-1) | M54: =IF(OR(E54="",E42=""),"",E54/E42-1) | N54: =IF(OR(F54="",F42=""),"",F54/F42-1) | O54: =IF(OR(G54="",G42=""),"",G54/G42-1) | P54: =IF(OR(E54="",E51=""),"",(E54/E51)^4-1) | Q54: =IF(OR(F54="",F51=""),"",(F54/F51)^4-1) | R54: =IF(OR(E54="",E48=""),"",(E54/E48)^2-1) | S54: =IF(E54="","",IFERROR(E54/INDEX($E:$E,MATCH(C54-1&"-12",$B:$B,0))-1,"")) | T54: =IF(OR(K54="",J54=""),"",(K54-J54)*100) | U54: =IF(OR(G54="",F54=""),"",(G54/INDEX($G:$G,MATCH("2023-12",$B:$B,0)))/(F54/INDEX($F:$F,MATCH("2023-12",$B:$B,0)))*100)
...

Sheet Seasonality Headline
B2: Seasonality — IPC Nivel General (headline): month-on-month % by calendar year
B3: One line per calendar year. Recent years darker; 2026 in UBS red.
B5: Month | C5: 2019 | D5: 2020 | E5: 2021 | F5: 2022 | G5: 2023 | H5: 2024 | I5: 2025 | J5: 2026
B6: Jan | C6: =IF(COUNTIFS('CPI Data'!$C$6:$C$114,C$5,'CPI Data'!$D$6:$D$114,1,'CPI Data'!$E$6:$E$114,">0")=0,"",SUMIFS('CPI Data'!$I$6:$I$114,'CPI Data'!$C$6:$C$114,C$5,'CPI Data'!$D$6:$D$114,1)) | D6: =IF(COUNTIFS('CPI Data'!$C$6:$C$114,D$5,'CPI Data'!$D$6:$D$114,1,'CPI Data'!$E$6:$E$114,">0")=0,"",SUMIFS('CPI Data'!$I$6:$I$114,'CPI Data'!$C$6:$C$114,D$5,'CPI Data'!$D$6:$D$114,1)) | E6: =IF(COUNTIFS('CPI Data'!$C$6:$C$114,E$5,'CPI Data'!$D$6:$D$114,1,'CPI Data'!$E$6:$E$114,">0")=0,"",SUMIFS('CPI Data'!$I$6:$I$114,'CPI Data'!$C$6:$C$114,E$5,'CPI Data'!$D$6:$D$114,1)) | F6: =IF(COUNTIFS('CPI Data'!$C$6:$C$114,F$5,'CPI Data'!$D$6:$D$114,1,'CPI Data'!$E$6:$E$114,">0")=0,"",SUMIFS('CPI Data'!$I$6:$I$114,'CPI Data'!$C$6:$C$114,F$5,'CPI Data'!$D$6:$D$114,1)) | G6: =IF(COUNTIFS('CPI Data'!$C$6:$C$114,G$5,'CPI Data'!$D$6:$D$114,1,'CPI Data'!$E$6:$E$114,">0")=0,"",SUMIFS('CPI Data'!$I$6:$I$114,'CPI Data'!$C$6:$C$114,G$5,'CPI Data'!$D$6:$D$114,1)) | H6: =IF(COUNTIFS('CPI Data'!$C$6:$C$114,H$5,'CPI Data'!$D$6:$D$114,1,'CPI Data'!$E$6:$E$114,">0")=0,"",SUMIFS('CPI Data'!$I$6:$I$114,'CPI Data'!$C$6:$C$114,H$5,'CPI Data'!$D$6:$D$114,1)) | I6: =IF(COUNTIFS('CPI Data'!$C$6:$C$114,I$5,'CPI Data'!$D$6:$D$114,1,'CPI Data'!$E$6:$E$114,">0")=0,"",SUMIFS('CPI Data'!$I$6:$I$114,'CPI Data'!$C$6:$C$114,I$5,'CPI Data'!$D$6:$D$114,1)) | J6: =IF(COUNTIFS('CPI Data'!$C$6:$C$114,J$5,'CPI Data'!$D$6:$D$114,1,'CPI Data'!$E$6:$E$114,">0")=0,"",SUMIFS('CPI Data'!$I$6:$I$114,'CPI Data'!$C$6:$C$114,J$5,'CPI Data'!$D$6:$D$114,1))
B7: Feb | C7: =IF(COUNTIFS('CPI Data'!$C$6:$C$114,C$5,'CPI Data'!$D$6:$D$114,2,'CPI Data'!$E$6:$E$114,">0")=0,"",SUMIFS('CPI Data'!$I$6:$I$114,'CPI Data'!$C$6:$C$114,C$5,'CPI Data'!$D$6:$D$114,2)) | D7: =IF(COUNTIFS('CPI Data'!$C$6:$C$114,D$5,'CPI Data'!$D$6:$D$114,2,'CPI Data'!$E$6:$E$114,">0")=0,"",SUMIFS('CPI Data'!$I$6:$I$114,'CPI Data'!$C$6:$C$114,D$5,'CPI Data'!$D$6:$D$114,2)) | E7: =IF(COUNTIFS('CPI Data'!$C$6:$C$114,E$5,'CPI Data'!$D$6:$D$114,2,'CPI Data'!$E$6:$E$114,">0")=0,"",SUMIFS('CPI Data'!$I$6:$I$114,'CPI Data'!$C$6:$C$114,E$5,'CPI Data'!$D$6:$D$114,2)) | F7: =IF(COUNTIFS('CPI Data'!$C$6:$C$114,F$5,'CPI Data'!$D$6:$D$114,2,'CPI Data'!$E$6:$E$114,">0")=0,"",SUMIFS('CPI Data'!$I$6:$I$114,'CPI Data'!$C$6:$C$114,F$5,'CPI Data'!$D$6:$D$114,2)) | G7: =IF(COUNTIFS('CPI Data'!$C$6:$C$114,G$5,'CPI Data'!$D$6:$D$114,2,'CPI Data'!$E$6:$E$114,">0")=0,"",SUMIFS('CPI Data'!$I$6:$I$114,'CPI Data'!$C$6:$C$114,G$5,'CPI Data'!$D$6:$D$114,2)) | H7: =IF(COUNTIFS('CPI Data'!$C$6:$C$114,H$5,'CPI Data'!$D$6:$D$114,2,'CPI Data'!$E$6:$E$114,">0")=0,"",SUMIFS('CPI Data'!$I$6:$I$114,'CPI Data'!$C$6:$C$114,H$5,'CPI Data'!$D$6:$D$114,2)) | I7: =IF(COUNTIFS('CPI Data'!$C$6:$C$114,I$5,'CPI Data'!$D$6:$D$114,2,'CPI Data'!$E$6:$E$114,">0")=0,"",SUMIFS('CPI Data'!$I$6:$I$114,'CPI Data'!$C$6:$C$114,I$5,'CPI Data'!$D$6:$D$114,2)) | J7: =IF(COUNTIFS('CPI Data'!$C$6:$C$114,J$5,'CPI Data'!$D$6:$D$114,2,'CPI Data'!$E$6:$E$114,">0")=0,"",SUMIFS('CPI Data'!$I$6:$I$114,'CPI Data'!$C$6:$C$114,J$5,'CPI Data'!$D$6:$D$114,2))
B8: Mar | C8: =IF(COUNTIFS('CPI Data'!$C$6:$C$114,C$5,'CPI Data'!$D$6:$D$114,3,'CPI Data'!$E$6:$E$114,">0")=0,"",SUMIFS('CPI Data'!$I$6:$I$114,'CPI Data'!$C$6:$C$114,C$5,'CPI Data'!$D$6:$D$114,3)) | D8: =IF(COUNTIFS('CPI Data'!$C$6:$C$114,D$5,'CPI Data'!$D$6:$D$114,3,'CPI Data'!$E$6:$E$114,">0")=0,"",SUMIFS('CPI Data'!$I$6:$I$114,'CPI Data'!$C$6:$C$114,D$5,'CPI Data'!$D$6:$D$114,3)) | E8: =IF(COUNTIFS('CPI Data'!$C$6:$C$114,E$5,'CPI Data'!$D$6:$D$114,3,'CPI Data'!$E$6:$E$114,">0")=0,"",SUMIFS('CPI Data'!$I$6:$I$114,'CPI Data'!$C$6:$C$114,E$5,'CPI Data'!$D$6:$D$114,3)) | F8: =IF(COUNTIFS('CPI Data'!$C$6:$C$114,F$5,'CPI Data'!$D$6:$D$114,3,'CPI Data'!$E$6:$E$114,">0")=0,"",SUMIFS('CPI Data'!$I$6:$I$114,'CPI Data'!$C$6:$C$114,F$5,'CPI Data'!$D$6:$D$114,3)) | G8: =IF(COUNTIFS('CPI Data'!$C$6:$C$114,G$5,'CPI Data'!$D$6:$D$114,3,'CPI Data'!$E$6:$E$114,">0")=0,"",SUMIFS('CPI Data'!$I$6:$I$114,'CPI Data'!$C$6:$C$114,G$5,'CPI Data'!$D$6:$D$114,3)) | H8: =IF(COUNTIFS('CPI Data'!$C$6:$C$114,H$5,'CPI Data'!$D$6:$D$114,3,'CPI Data'!$E$6:$E$114,">0")=0,"",SUMIFS('CPI Data'!$I$6:$I$114,'CPI Data'!$C$6:$C$114,H$5,'CPI Data'!$D$6:$D$114,3)) | I8: =IF(COUNTIFS('CPI Data'!$C$6:$C$114,I$5,'CPI Data'!$D$6:$D$114,3,'CPI Data'!$E$6:$E$114,">0")=0,"",SUMIFS('CPI Data'!$I$6:$I$114,'CPI Data'!$C$6:$C$114,I$5,'CPI Data'!$D$6:$D$114,3)) | J8: =IF(COUNTIFS('CPI Data'!$C$6:$C$114,J$5,'CPI Data'!$D$6:$D$114,3,'CPI Data'!$E$6:$E$114,">0")=0,"",SUMIFS('CPI Data'!$I$6:$I$114,'CPI Data'!$C$6:$C$114,J$5,'CPI Data'!$D$6:$D$114,3))
B9: Apr | C9: =IF(COUNTIFS('CPI Data'!$C$6:$C$114,C$5,'CPI Data'!$D$6:$D$114,4,'CPI Data'!$E$6:$E$114,">0")=0,"",SUMIFS('CPI Data'!$I$6:$I$114,'CPI Data'!$C$6:$C$114,C$5,'CPI Data'!$D$6:$D$114,4)) | D9: =IF(COUNTIFS('CPI Data'!$C$6:$C$114,D$5,'CPI Data'!$D$6:$D$114,4,'CPI Data'!$E$6:$E$114,">0")=0,"",SUMIFS('CPI Data'!$I$6:$I$114,'CPI Data'!$C$6:$C$114,D$5,'CPI Data'!$D$6:$D$114,4)) | E9: =IF(COUNTIFS('CPI Data'!$C$6:$C$114,E$5,'CPI Data'!$D$6:$D$114,4,'CPI Data'!$E$6:$E$114,">0")=0,"",SUMIFS('CPI Data'!$I$6:$I$114,'CPI Data'!$C$6:$C$114,E$5,'CPI Data'!$D$6:$D$114,4)) | F9: =IF(COUNTIFS('CPI Data'!$C$6:$C$114,F$5,'CPI Data'!$D$6:$D$114,4,'CPI Data'!$E$6:$E$114,">0")=0,"",SUMIFS('CPI Data'!$I$6:$I$114,'CPI Data'!$C$6:$C$114,F$5,'CPI Data'!$D$6:$D$114,4)) | G9: =IF(COUNTIFS('CPI Data'!$C$6:$C$114,G$5,'CPI Data'!$D$6:$D$114,4,'CPI Data'!$E$6:$E$114,">0")=0,"",SUMIFS('CPI Data'!$I$6:$I$114,'CPI Data'!$C$6:$C$114,G$5,'CPI Data'!$D$6:$D$114,4)) | H9: =IF(COUNTIFS('CPI Data'!$C$6:$C$114,H$5,'CPI Data'!$D$6:$D$114,4,'CPI Data'!$E$6:$E$114,">0")=0,"",SUMIFS('CPI Data'!$I$6:$I$114,'CPI Data'!$C$6:$C$114,H$5,'CPI Data'!$D$6:$D$114,4)) | I9: =IF(COUNTIFS('CPI Data'!$C$6:$C$114,I$5,'CPI Data'!$D$6:$D$114,4,'CPI Data'!$E$6:$E$114,">0")=0,"",SUMIFS('CPI Data'!$I$6:$I$114,'CPI Data'!$C$6:$C$114,I$5,'CPI Data'!$D$6:$D$114,4)) | J9: =IF(COUNTIFS('CPI Data'!$C$6:$C$114,J$5,'CPI Data'!$D$6:$D$114,4,'CPI Data'!$E$6:$E$114,">0")=0,"",SUMIFS('CPI Data'!$I$6:$I$114,'CPI Data'!$C$6:$C$114,J$5,'CPI Data'!$D$6:$D$114,4))
B10: May | C10: =IF(COUNTIFS('CPI Data'!$C$6:$C$114,C$5,'CPI Data'!$D$6:$D$114,5,'CPI Data'!$E$6:$E$114,">0")=0,"",SUMIFS('CPI Data'!$I$6:$I$114,'CPI Data'!$C$6:$C$114,C$5,'CPI Data'!$D$6:$D$114,5)) | D10: =IF(COUNTIFS('CPI Data'!$C$6:$C$114,D$5,'CPI Data'!$D$6:$D$114,5,'CPI Data'!$E$6:$E$114,">0")=0,"",SUMIFS('CPI Data'!$I$6:$I$114,'CPI Data'!$C$6:$C$114,D$5,'CPI Data'!$D$6:$D$114,5)) | E10: =IF(COUNTIFS('CPI Data'!$C$6:$C$114,E$5,'CPI Data'!$D$6:$D$114,5,'CPI Data'!$E$6:$E$114,">0")=0,"",SUMIFS('CPI Data'!$I$6:$I$114,'CPI Data'!$C$6:$C$114,E$5,'CPI Data'!$D$6:$D$114,5)) | F10: =IF(COUNTIFS('CPI Data'!$C$6:$C$114,F$5,'CPI Data'!$D$6:$D$114,5,'CPI Data'!$E$6:$E$114,">0")=0,"",SUMIFS('CPI Data'!$I$6:$I$114,'CPI Data'!$C$6:$C$114,F$5,'CPI Data'!$D$6:$D$114,5)) | G10: =IF(COUNTIFS('CPI Data'!$C$6:$C$114,G$5,'CPI Data'!$D$6:$D$114,5,'CPI Data'!$E$6:$E$114,">0")=0,"",SUMIFS('CPI Data'!$I$6:$I$114,'CPI Data'!$C$6:$C$114,G$5,'CPI Data'!$D$6:$D$114,5)) | H10: =IF(COUNTIFS('CPI Data'!$C$6:$C$114,H$5,'CPI Data'!$D$6:$D$114,5,'CPI Data'!$E$6:$E$114,">0")=0,"",SUMIFS('CPI Data'!$I$6:$I$114,'CPI Data'!$C$6:$C$114,H$5,'CPI Data'!$D$6:$D$114,5)) | I10: =IF(COUNTIFS('CPI Data'!$C$6:$C$114,I$5,'CPI Data'!$D$6:$D$114,5,'CPI Data'!$E$6:$E$114,">0")=0,"",SUMIFS('CPI Data'!$I$6:$I$114,'CPI Data'!$C$6:$C$114,I$5,'CPI Data'!$D$6:$D$114,5)) | J10: =IF(COUNTIFS('CPI Data'!$C$6:$C$114,J$5,'CPI Data'!$D$6:$D$114,5,'CPI Data'!$E$6:$E$114,">0")=0,"",SUMIFS('CPI Data'!$I$6:$I$114,'CPI Data'!$C$6:$C$114,J$5,'CPI Data'!$D$6:$D$114,5))
B11: Jun | C11: =IF(COUNTIFS('CPI Data'!$C$6:$C$114,C$5,'CPI Data'!$D$6:$D$114,6,'CPI Data'!$E$6:$E$114,">0")=0,"",SUMIFS('CPI Data'!$I$6:$I$114,'CPI Data'!$C$6:$C$114,C$5,'CPI Data'!$D$6:$D$114,6)) | D11: =IF(COUNTIFS('CPI Data'!$C$6:$C$114,D$5,'CPI Data'!$D$6:$D$114,6,'CPI Data'!$E$6:$E$114,">0")=0,"",SUMIFS('CPI Data'!$I$6:$I$114,'CPI Data'!$C$6:$C$114,D$5,'CPI Data'!$D$6:$D$114,6)) | E11: =IF(COUNTIFS('CPI Data'!$C$6:$C$114,E$5,'CPI Data'!$D$6:$D$114,6,'CPI Data'!$E$6:$E$114,">0")=0,"",SUMIFS('CPI Data'!$I$6:$I$114,'CPI Data'!$C$6:$C$114,E$5,'CPI Data'!$D$6:$D$114,6)) | F11: =IF(COUNTIFS('CPI Data'!$C$6:$C$114,F$5,'CPI Data'!$D$6:$D$114,6,'CPI Data'!$E$6:$E$114,">0")=0,"",SUMIFS('CPI Data'!$I$6:$I$114,'CPI Data'!$C$6:$C$114,F$5,'CPI Data'!$D$6:$D$114,6)) | G11: =IF(COUNTIFS('CPI Data'!$C$6:$C$114,G$5,'CPI Data'!$D$6:$D$114,6,'CPI Data'!$E$6:$E$114,">0")=0,"",SUMIFS('CPI Data'!$I$6:$I$114,'CPI Data'!$C$6:$C$114,G$5,'CPI Data'!$D$6:$D$114,6)) | H11: =IF(COUNTIFS('CPI Data'!$C$6:$C$114,H$5,'CPI Data'!$D$6:$D$114,6,'CPI Data'!$E$6:$E$114,">0")=0,"",SUMIFS('CPI Data'!$I$6:$I$114,'CPI Data'!$C$6:$C$114,H$5,'CPI Data'!$D$6:$D$114,6)) | I11: =IF(COUNTIFS('CPI Data'!$C$6:$C$114,I$5,'CPI Data'!$D$6:$D$114,6,'CPI Data'!$E$6:$E$114,">0")=0,"",SUMIFS('CPI Data'!$I$6:$I$114,'CPI Data'!$C$6:$C$114,I$5,'CPI Data'!$D$6:$D$114,6)) | J11: =IF(COUNTIFS('CPI Data'!$C$6:$C$114,J$5,'CPI Data'!$D$6:$D$114,6,'CPI Data'!$E$6:$E$114,">0")=0,"",SUMIFS('CPI Data'!$I$6:$I$114,'CPI Data'!$C$6:$C$114,J$5,'CPI Data'!$D$6:$D$114,6))
B12: Jul | C12: =IF(COUNTIFS('CPI Data'!$C$6:$C$114,C$5,'CPI Data'!$D$6:$D$114,7,'CPI Data'!$E$6:$E$114,">0")=0,"",SUMIFS('CPI Data'!$I$6:$I$114,'CPI Data'!$C$6:$C$114,C$5,'CPI Data'!$D$6:$D$114,7)) | D12: =IF(COUNTIFS('CPI Data'!$C$6:$C$114,D$5,'CPI Data'!$D$6:$D$114,7,'CPI Data'!$E$6:$E$114,">0")=0,"",SUMIFS('CPI Data'!$I$6:$I$114,'CPI Data'!$C$6:$C$114,D$5,'CPI Data'!$D$6:$D$114,7)) | E12: =IF(COUNTIFS('CPI Data'!$C$6:$C$114,E$5,'CPI Data'!$D$6:$D$114,7,'CPI Data'!$E$6:$E$114,">0")=0,"",SUMIFS('CPI Data'!$I$6:$I$114,'CPI Data'!$C$6:$C$114,E$5,'CPI Data'!$D$6:$D$114,7)) | F12: =IF(COUNTIFS('CPI Data'!$C$6:$C$114,F$5,'CPI Data'!$D$6:$D$114,7,'CPI Data'!$E$6:$E$114,">0")=0,"",SUMIFS('CPI Data'!$I$6:$I$114,'CPI Data'!$C$6:$C$114,F$5,'CPI Data'!$D$6:$D$114,7)) | G12: =IF(COUNTIFS('CPI Data'!$C$6:$C$114,G$5,'CPI Data'!$D$6:$D$114,7,'CPI Data'!$E$6:$E$114,">0")=0,"",SUMIFS('CPI Data'!$I$6:$I$114,'CPI Data'!$C$6:$C$114,G$5,'CPI Data'!$D$6:$D$114,7)) | H12: =IF(COUNTIFS('CPI Data'!$C$6:$C$114,H$5,'CPI Data'!$D$6:$D$114,7,'CPI Data'!$E$6:$E$114,">0")=0,"",SUMIFS('CPI Data'!$I$6:$I$114,'CPI Data'!$C$6:$C$114,H$5,'CPI Data'!$D$6:$D$114,7)) | I12: =IF(COUNTIFS('CPI Data'!$C$6:$C$114,I$5,'CPI Data'!$D$6:$D$114,7,'CPI Data'!$E$6:$E$114,">0")=0,"",SUMIFS('CPI Data'!$I$6:$I$114,'CPI Data'!$C$6:$C$114,I$5,'CPI Data'!$D$6:$D$114,7)) | J12: =IF(COUNTIFS('CPI Data'!$C$6:$C$114,J$5,'CPI Data'!$D$6:$D$114,7,'CPI Data'!$E$6:$E$114,">0")=0,"",SUMIFS('CPI Data'!$I$6:$I$114,'CPI Data'!$C$6:$C$114,J$5,'CPI Data'!$D$6:$D$114,7))
B13: Aug | C13: =IF(COUNTIFS('CPI Data'!$C$6:$C$114,C$5,'CPI Data'!$D$6:$D$114,8,'CPI Data'!$E$6:$E$114,">0")=0,"",SUMIFS('CPI Data'!$I$6:$I$114,'CPI Data'!$C$6:$C$114,C$5,'CPI Data'!$D$6:$D$114,8)) | D13: =IF(COUNTIFS('CPI Data'!$C$6:$C$114,D$5,'CPI Data'!$D$6:$D$114,8,'CPI Data'!$E$6:$E$114,">0")=0,"",SUMIFS('CPI Data'!$I$6:$I$114,'CPI Data'!$C$6:$C$114,D$5,'CPI Data'!$D$6:$D$114,8)) | E13: =IF(COUNTIFS('CPI Data'!$C$6:$C$114,E$5,'CPI Data'!$D$6:$D$114,8,'CPI Data'!$E$6:$E$114,">0")=0,"",SUMIFS('CPI Data'!$I$6:$I$114,'CPI Data'!$C$6:$C$114,E$5,'CPI Data'!$D$6:$D$114,8)) | F13: =IF(COUNTIFS('CPI Data'!$C$6:$C$114,F$5,'CPI Data'!$D$6:$D$114,8,'CPI Data'!$E$6:$E$114,">0")=0,"",SUMIFS('CPI Data'!$I$6:$I$114,'CPI Data'!$C$6:$C$114,F$5,'CPI Data'!$D$6:$D$114,8)) | G13: =IF(COUNTIFS('CPI Data'!$C$6:$C$114,G$5,'CPI Data'!$D$6:$D$114,8,'CPI Data'!$E$6:$E$114,">0")=0,"",SUMIFS('CPI Data'!$I$6:$I$114,'CPI Data'!$C$6:$C$114,G$5,'CPI Data'!$D$6:$D$114,8)) | H13: =IF(COUNTIFS('CPI Data'!$C$6:$C$114,H$5,'CPI Data'!$D$6:$D$114,8,'CPI Data'!$E$6:$E$114,">0")=0,"",SUMIFS('CPI Data'!$I$6:$I$114,'CPI Data'!$C$6:$C$114,H$5,'CPI Data'!$D$6:$D$114,8)) | I13: =IF(COUNTIFS('CPI Data'!$C$6:$C$114,I$5,'CPI Data'!$D$6:$D$114,8,'CPI Data'!$E$6:$E$114,">0")=0,"",SUMIFS('CPI Data'!$I$6:$I$114,'CPI Data'!$C$6:$C$114,I$5,'CPI Data'!$D$6:$D$114,8)) | J13: =IF(COUNTIFS('CPI Data'!$C$6:$C$114,J$5,'CPI Data'!$D$6:$D$114,8,'CPI Data'!$E$6:$E$114,">0")=0,"",SUMIFS('CPI Data'!$I$6:$I$114,'CPI Data'!$C$6:$C$114,J$5,'CPI Data'!$D$6:$D$114,8))
B14: Sep | C14: =IF(COUNTIFS('CPI Data'!$C$6:$C$114,C$5,'CPI Data'!$D$6:$D$114,9,'CPI Data'!$E$6:$E$114,">0")=0,"",SUMIFS('CPI Data'!$I$6:$I$114,'CPI Data'!$C$6:$C$114,C$5,'CPI Data'!$D$6:$D$114,9)) | D14: =IF(COUNTIFS('CPI Data'!$C$6:$C$114,D$5,'CPI Data'!$D$6:$D$114,9,'CPI Data'!$E$6:$E$114,">0")=0,"",SUMIFS('CPI Data'!$I$6:$I$114,'CPI Data'!$C$6:$C$114,D$5,'CPI Data'!$D$6:$D$114,9)) | E14: =IF(COUNTIFS('CPI Data'!$C$6:$C$114,E$5,'CPI Data'!$D$6:$D$114,9,'CPI Data'!$E$6:$E$114,">0")=0,"",SUMIFS('CPI Data'!$I$6:$I$114,'CPI Data'!$C$6:$C$114,E$5,'CPI Data'!$D$6:$D$114,9)) | F14: =IF(COUNTIFS('CPI Data'!$C$6:$C$114,F$5,'CPI Data'!$D$6:$D$114,9,'CPI Data'!$E$6:$E$114,">0")=0,"",SUMIFS('CPI Data'!$I$6:$I$114,'CPI Data'!$C$6:$C$114,F$5,'CPI Data'!$D$6:$D$114,9)) | G14: =IF(COUNTIFS('CPI Data'!$C$6:$C$114,G$5,'CPI Data'!$D$6:$D$114,9,'CPI Data'!$E$6:$E$114,">0")=0,"",SUMIFS('CPI Data'!$I$6:$I$114,'CPI Data'!$C$6:$C$114,G$5,'CPI Data'!$D$6:$D$114,9)) | H14: =IF(COUNTIFS('CPI Data'!$C$6:$C$114,H$5,'CPI Data'!$D$6:$D$114,9,'CPI Data'!$E$6:$E$114,">0")=0,"",SUMIFS('CPI Data'!$I$6:$I$114,'CPI Data'!$C$6:$C$114,H$5,'CPI Data'!$D$6:$D$114,9)) | I14: =IF(COUNTIFS('CPI Data'!$C$6:$C$114,I$5,'CPI Data'!$D$6:$D$114,9,'CPI Data'!$E$6:$E$114,">0")=0,"",SUMIFS('CPI Data'!$I$6:$I$114,'CPI Data'!$C$6:$C$114,I$5,'CPI Data'!$D$6:$D$114,9)) | J14: =IF(COUNTIFS('CPI Data'!$C$6:$C$114,J$5,'CPI Data'!$D$6:$D$114,9,'CPI Data'!$E$6:$E$114,">0")=0,"",SUMIFS('CPI Data'!$I$6:$I$114,'CPI Data'!$C$6:$C$114,J$5,'CPI Data'!$D$6:$D$114,9))
B15: Oct | C15: =IF(COUNTIFS('CPI Data'!$C$6:$C$114,C$5,'CPI Data'!$D$6:$D$114,10,'CPI Data'!$E$6:$E$114,">0")=0,"",SUMIFS('CPI Data'!$I$6:$I$114,'CPI Data'!$C$6:$C$114,C$5,'CPI Data'!$D$6:$D$114,10)) | D15: =IF(COUNTIFS('CPI Data'!$C$6:$C$114,D$5,'CPI Data'!$D$6:$D$114,10,'CPI Data'!$E$6:$E$114,">0")=0,"",SUMIFS('CPI Data'!$I$6:$I$114,'CPI Data'!$C$6:$C$114,D$5,'CPI Data'!$D$6:$D$114,10)) | E15: =IF(COUNTIFS('CPI Data'!$C$6:$C$114,E$5,'CPI Data'!$D$6:$D$114,10,'CPI Data'!$E$6:$E$114,">0")=0,"",SUMIFS('CPI Data'!$I$6:$I$114,'CPI Data'!$C$6:$C$114,E$5,'CPI Data'!$D$6:$D$114,10)) | F15: =IF(COUNTIFS('CPI Data'!$C$6:$C$114,F$5,'CPI Data'!$D$6:$D$114,10,'CPI Data'!$E$6:$E$114,">0")=0,"",SUMIFS('CPI Data'!$I$6:$I$114,'CPI Data'!$C$6:$C$114,F$5,'CPI Data'!$D$6:$D$114,10)) | G15: =IF(COUNTIFS('CPI Data'!$C$6:$C$114,G$5,'CPI Data'!$D$6:$D$114,10,'CPI Data'!$E$6:$E$114,">0")=0,"",SUMIFS('CPI Data'!$I$6:$I$114,'CPI Data'!$C$6:$C$114,G$5,'CPI Data'!$D$6:$D$114,10)) | H15: =IF(COUNTIFS('CPI Data'!$C$6:$C$114,H$5,'CPI Data'!$D$6:$D$114,10,'CPI Data'!$E$6:$E$114,">0")=0,"",SUMIFS('CPI Data'!$I$6:$I$114,'CPI Data'!$C$6:$C$114,H$5,'CPI Data'!$D$6:$D$114,10)) | I15: =IF(COUNTIFS('CPI Data'!$C$6:$C$114,I$5,'CPI Data'!$D$6:$D$114,10,'CPI Data'!$E$6:$E$114,">0")=0,"",SUMIFS('CPI Data'!$I$6:$I$114,'CPI Data'!$C$6:$C$114,I$5,'CPI Data'!$D$6:$D$114,10)) | J15: =IF(COUNTIFS('CPI Data'!$C$6:$C$114,J$5,'CPI Data'!$D$6:$D$114,10,'CPI Data'!$E$6:$E$114,">0")=0,"",SUMIFS('CPI Data'!$I$6:$I$114,'CPI Data'!$C$6:$C$114,J$5,'CPI Data'!$D$6:$D$114,10))
B16: Nov | C16: =IF(COUNTIFS('CPI Data'!$C$6:$C$114,C$5,'CPI Data'!$D$6:$D$114,11,'CPI Data'!$E$6:$E$114,">0")=0,"",SUMIFS('CPI Data'!$I$6:$I$114,'CPI Data'!$C$6:$C$114,C$5,'CPI Data'!$D$6:$D$114,11)) | D16: =IF(COUNTIFS('CPI Data'!$C$6:$C$114,D$5,'CPI Data'!$D$6:$D$114,11,'CPI Data'!$E$6:$E$114,">0")=0,"",SUMIFS('CPI Data'!$I$6:$I$114,'CPI Data'!$C$6:$C$114,D$5,'CPI Data'!$D$6:$D$114,11)) | E16: =IF(COUNTIFS('CPI Data'!$C$6:$C$114,E$5,'CPI Data'!$D$6:$D$114,11,'CPI Data'!$E$6:$E$114,">0")=0,"",SUMIFS('CPI Data'!$I$6:$I$114,'CPI Data'!$C$6:$C$114,E$5,'CPI Data'!$D$6:$D$114,11)) | F16: =IF(COUNTIFS('CPI Data'!$C$6:$C$114,F$5,'CPI Data'!$D$6:$D$114,11,'CPI Data'!$E$6:$E$114,">0")=0,"",SUMIFS('CPI Data'!$I$6:$I$114,'CPI Data'!$C$6:$C$114,F$5,'CPI Data'!$D$6:$D$114,11)) | G16: =IF(COUNTIFS('CPI Data'!$C$6:$C$114,G$5,'CPI Data'!$D$6:$D$114,11,'CPI Data'!$E$6:$E$114,">0")=0,"",SUMIFS('CPI Data'!$I$6:$I$114,'CPI Data'!$C$6:$C$114,G$5,'CPI Data'!$D$6:$D$114,11)) | H16: =IF(COUNTIFS('CPI Data'!$C$6:$C$114,H$5,'CPI Data'!$D$6:$D$114,11,'CPI Data'!$E$6:$E$114,">0")=0,"",SUMIFS('CPI Data'!$I$6:$I$114,'CPI Data'!$C$6:$C$114,H$5,'CPI Data'!$D$6:$D$114,11)) | I16: =IF(COUNTIFS('CPI Data'!$C$6:$C$114,I$5,'CPI Data'!$D$6:$D$114,11,'CPI Data'!$E$6:$E$114,">0")=0,"",SUMIFS('CPI Data'!$I$6:$I$114,'CPI Data'!$C$6:$C$114,I$5,'CPI Data'!$D$6:$D$114,11)) | J16: =IF(COUNTIFS('CPI Data'!$C$6:$C$114,J$5,'CPI Data'!$D$6:$D$114,11,'CPI Data'!$E$6:$E$114,">0")=0,"",SUMIFS('CPI Data'!$I$6:$I$114,'CPI Data'!$C$6:$C$114,J$5,'CPI Data'!$D$6:$D$114,11))
B17: Dec | C17: =IF(COUNTIFS('CPI Data'!$C$6:$C$114,C$5,'CPI Data'!$D$6:$D$114,12,'CPI Data'!$E$6:$E$114,">0")=0,"",SUMIFS('CPI Data'!$I$6:$I$114,'CPI Data'!$C$6:$C$114,C$5,'CPI Data'!$D$6:$D$114,12)) | D17: =IF(COUNTIFS('CPI Data'!$C$6:$C$114,D$5,'CPI Data'!$D$6:$D$114,12,'CPI Data'!$E$6:$E$114,">0")=0,"",SUMIFS('CPI Data'!$I$6:$I$114,'CPI Data'!$C$6:$C$114,D$5,'CPI Data'!$D$6:$D$114,12)) | E17: =IF(COUNTIFS('CPI Data'!$C$6:$C$114,E$5,'CPI Data'!$D$6:$D$114,12,'CPI Data'!$E$6:$E$114,">0")=0,"",SUMIFS('CPI Data'!$I$6:$I$114,'CPI Data'!$C$6:$C$114,E$5,'CPI Data'!$D$6:$D$114,12)) | F17: =IF(COUNTIFS('CPI Data'!$C$6:$C$114,F$5,'CPI Data'!$D$6:$D$114,12,'CPI Data'!$E$6:$E$114,">0")=0,"",SUMIFS('CPI Data'!$I$6:$I$114,'CPI Data'!$C$6:$C$114,F$5,'CPI Data'!$D$6:$D$114,12)) | G17: =IF(COUNTIFS('CPI Data'!$C$6:$C$114,G$5,'CPI Data'!$D$6:$D$114,12,'CPI Data'!$E$6:$E$114,">0")=0,"",SUMIFS('CPI Data'!$I$6:$I$114,'CPI Data'!$C$6:$C$114,G$5,'CPI Data'!$D$6:$D$114,12)) | H17: =IF(COUNTIFS('CPI Data'!$C$6:$C$114,H$5,'CPI Data'!$D$6:$D$114,12,'CPI Data'!$E$6:$E$114,">0")=0,"",SUMIFS('CPI Data'!$I$6:$I$114,'CPI Data'!$C$6:$C$114,H$5,'CPI Data'!$D$6:$D$114,12)) | I17: =IF(COUNTIFS('CPI Data'!$C$6:$C$114,I$5,'CPI Data'!$D$6:$D$114,12,'CPI Data'!$E$6:$E$114,">0")=0,"",SUMIFS('CPI Data'!$I$6:$I$114,'CPI Data'!$C$6:$C$114,I$5,'CPI Data'!$D$6:$D$114,12)) | J17: =IF(COUNTIFS('CPI Data'!$C$6:$C$114,J$5,'CPI Data'!$D$6:$D$114,12,'CPI Data'!$E$6:$E$114,">0")=0,"",SUMIFS('CPI Data'!$I$6:$I$114,'CPI Data'!$C$6:$C$114,J$5,'CPI Data'!$D$6:$D$114,12))
B19: Dec/Dec* | C19: =IFERROR(INDEX('CPI Data'!$E:$E,MATCH("2019-12",'CPI Data'!$B:$B,0))/INDEX('CPI Data'!$E:$E,MATCH("2018-12",'CPI Data'!$B:$B,0))-1,"") | D19: =IFERROR(INDEX('CPI Data'!$E:$E,MATCH("2020-12",'CPI Data'!$B:$B,0))/INDEX('CPI Data'!$E:$E,MATCH("2019-12",'CPI Data'!$B:$B,0))-1,"") | E19: =IFERROR(INDEX('CPI Data'!$E:$E,MATCH("2021-12",'CPI Data'!$B:$B,0))/INDEX('CPI Data'!$E:$E,MATCH("2020-12",'CPI Data'!$B:$B,0))-1,"") | F19: =IFERROR(INDEX('CPI Data'!$E:$E,MATCH("2022-12",'CPI Data'!$B:$B,0))/INDEX('CPI Data'!$E:$E,MATCH("2021-12",'CPI Data'!$B:$B,0))-1,"") | G19: =IFERROR(INDEX('CPI Data'!$E:$E,MATCH("2023-12",'CPI Data'!$B:$B,0))/INDEX('CPI Data'!$E:$E,MATCH("2022-12",'CPI Data'!$B:$B,0))-1,"") | H19: =IFERROR(INDEX('CPI Data'!$E:$E,MATCH("2024-12",'CPI Data'!$B:$B,0))/INDEX('CPI Data'!$E:$E,MATCH("2023-12",'CPI Data'!$B:$B,0))-1,"") | I19: =IFERROR(INDEX('CPI Data'!$E:$E,MATCH("2025-12",'CPI Data'!$B:$B,0))/INDEX('CPI Data'!$E:$E,MATCH("2024-12",'CPI Data'!$B:$B,0))-1,"") | J19: =IFERROR(INDEX('CPI Data'!$E:$E,MATCH("2026-08",'CPI Data'!$B:$B,0))/INDEX('CPI Data'!$E:$E,MATCH("2025-12",'CPI Data'!$B:$B,0))-1,"")
B20: Avg month | C20: =IFERROR(AVERAGE(C6:C17),"") | D20: =IFERROR(AVERAGE(D6:D17),"") | E20: =IFERROR(AVERAGE(E6:E17),"") | F20: =IFERROR(AVERAGE(F6:F17),"") | G20: =IFERROR(AVERAGE(G6:G17),"") | H20: =IFERROR(AVERAGE(H6:H17),"") | I20: =IFERROR(AVERAGE(I6:I17),"") | J20: =IFERROR(AVERAGE(J6:J17),"")
B21: * the 2026 column is year-to-date through 2026-08, not a full year.

Sheet Seasonality Core
B2: Seasonality — IPC Nucleo (core): month-on-month % by calendar year
B3: Core strips out regulated tariffs and seasonal items — the cleanest read on underlying momentum.
B5: Month | C5: 2019 | D5: 2020 | E5: 2021 | F5: 2022 | G5: 2023 | H5: 2024 | I5: 2025 | J5: 2026
