Workbook

Sheet Tabelle1
D1: EMAE | E1: Agri. | F1: Fishing | G1: Mining | H1: Mfg. | I1: Utilities | J1: Const. | K1: Trade | L1: Hotels | M1: Transport | N1: Finance | O1: Real Estate | P1: Public Admin. | Q1: Education | R1: Health | S1: Other Services
B2: 10401 !M NA_ | C2: .excel_last | D2: S213GVI@EMERGELA | E2: N213GAFI@EMERGELA | F2: N213GFFI@EMERGELA | G2: N213GQI@EMERGELA | H2: N213GMI@EMERGELA | I2: N213GEI@EMERGELA | J2: N213GCOI@EMERGELA | K2: N213GWRI@EMERGELA | L2: N213GHI@EMERGELA | M2: N213GTSI@EMERGELA | N2: N213GFMI@EMERGELA | O2: N213GPRI@EMERGELA | P2: N213GGI@EMERGELA | Q2: N213GDI@EMERGELA | R2: N213GHSI@EMERGELA | S2: N213GSOI@EMERGELA
B3: .DESC | D3: Argentina: Economic Activity Indicator (SA, 2004=100) | E3: Argentina: Economic Act: Agr, Livestock, Hunting & Forestry (NSA, 2004=100) | F3: Argentina: Economic Activity: Fishing (NSA, 2004=100) | G3: Argentina: Economic Activity: Mining & Quarrying(NSA, 2004=100) | H3: Argentina: Economic Activity: Manufacturing (NSA, 2004=100) | I3: Argentina: Economic Activity: Electricity, Gas & Water (NSA, 2004=100) | J3: Argentina: Economic Activity: Construction (NSA, 2004=100) | K3: Argentina: Economic Act: Wholesale & Retail Trade and Repairs (NSA, 2004=100) | L3: Argentina: Economic Activity: Hotel & Restaurants (NSA, 2004=100) | M3: Argentina: Economic Activity: Transportation & Communications (NSA, 2004=100) | N3: Argentina: Economic Activity: Financial Intermediation (NSA, 2004=100) | O3: Argentina: Econ Act: Real Estate, Business & Rental Activities (NSA, 2004=100) | P3: Argentina: Econ Act: Public Admin & Defense, SocSec Plans (NSA, 2004=100) | Q3: Argentina: Economic Activity: Education (NSA, 2004=100) | R3: Argentina: Economic Activity: Social & Health Services (NSA, 2004=100) | S3: Argentina: EconAct: Other Community, Social & Personal Srvc Act (NSA, 2004=100)
B4: .SOURCE | D4: INDEC | E4: INDEC | F4: INDEC | G4: INDEC | H4: INDEC | I4: INDEC | J4: INDEC | K4: INDEC | L4: INDEC | M4: INDEC | N4: INDEC | O4: INDEC | P4: INDEC | Q4: INDEC | R4: INDEC | S4: INDEC
B5: .DTLM | D5: Jul-22-2026 15:06 | E5: Jul-22-2026 15:06 | F5: Jul-22-2026 15:06 | G5: Jul-22-2026 15:06 | H5: Jul-22-2026 15:06 | I5: Jul-22-2026 15:06 | J5: Jul-22-2026 15:06 | K5: Jul-22-2026 15:06 | L5: Jul-22-2026 15:06 | M5: Jul-22-2026 15:06 | N5: Jul-22-2026 15:06 | O5: Jul-22-2026 15:06 | P5: Jul-22-2026 15:06 | Q5: Jul-22-2026 15:06 | R5: Jul-22-2026 15:06 | S5: Jul-22-2026 15:06
B6: .DATA_TYPE | D6: INDEX | E6: INDEX | F6: INDEX | G6: INDEX | H6: INDEX | I6: INDEX | J6: INDEX | K6: INDEX | L6: INDEX | M6: INDEX | N6: INDEX | O6: INDEX | P6: INDEX | Q6: INDEX | R6: INDEX | S6: INDEX
B7: .MAG | D7: 0 | E7: 0 | F7: 0 | G7: 0 | H7: 0 | I7: 0 | J7: 0 | K7: 0 | L7: 0 | M7: 0 | N7: 0 | O7: 0 | P7: 0 | Q7: 0 | R7: 0 | S7: 0
B8: 0401 | C8: 38017 | D8: 98.33957 | E8: 65.99535 | F8: 42.54787 | G8: 100.7045 | H8: 91.45461 | I8: 99.91798 | J8: 95.93805 | K8: 92.06534 | L8: 108.41168 | M8: 95.50673 | N8: 103.89026 | O8: 91.41838 | P8: 97.26127 | Q8: 95.6277 | R8: 94.19839 | S8: 97.00618
B9: 0402 | C9: 38046 | D9: 98.07072 | E9: 64.9266 | F9: 62.44077 | G9: 95.41419 | H9: 89.42485 | I9: 92.89344 | J9: 98.85339 | K9: 91.46472 | L9: 103.44826 | M9: 90.73641 | N9: 96.48146 | O9: 94.04698 | P9: 97.88228 | Q9: 96.08425 | R9: 90.31346 | S9: 96.83613
B10: 0403 | C10: 38077 | D10: 97.66795 | E10: 110.66656 | F10: 174.08465 | G10: 100.25104 | H10: 101.42643 | I10: 103.77021 | J10: 103.12453 | K10: 109.12778 | L10: 101.06184 | M10: 97.17581 | N10: 98.30457 | O10: 99.64872 | P10: 97.71846 | Q10: 96.3803 | R10: 98.08149 | S10: 96.15504
B11: 0404 | C11: 38107 | D11: 95.23678 | E11: 150.06592 | F11: 153.87764 | G11: 96.69755 | H11: 98.43731 | I11: 97.00985 | J11: 95.81549 | K11: 99.42014 | L11: 93.243 | M11: 99.70693 | N11: 95.3159 | O11: 97.60226 | P11: 98.40554 | Q11: 97.71187 | R11: 102.18435 | S11: 98.08314
B12: 0405 | C12: 38138 | D12: 96.95127 | E12: 209.38808 | F12: 132.35766 | G12: 104.10053 | H12: 100.35314 | I12: 102.47183 | J12: 97.99457 | K12: 100.53274 | L12: 90.98526 | M12: 105.55244 | N12: 97.00467 | O12: 99.80349 | P12: 99.20852 | Q12: 99.13689 | R12: 102.76126 | S12: 98.05435
B13: 0406 | C13: 38168 | D13: 98.68356 | E13: 144.66132 | F13: 158.95986 | G13: 100.67785 | H13: 100.66693 | I13: 101.91112 | J13: 99.15678 | K13: 104.34202 | L13: 90.55608 | M13: 101.67565 | N13: 97.31215 | O13: 101.71298 | P13: 100.4454 | Q13: 102.20951 | R13: 104.26446 | S13: 99.76658
B14: 0407 | C14: 38199 | D14: 100.8411 | E14: 94.86246 | F14: 77.40334 | G14: 100.80174 | H14: 102.50853 | I14: 105.41654 | J14: 98.906 | K14: 100.82722 | L14: 99.05112 | M14: 99.8302 | N14: 99.01951 | O14: 100.85959 | P14: 100.16519 | Q14: 100.50009 | R14: 101.84397 | S14: 108.7301
B15: 0408 | C15: 38230 | D15: 102.17769 | E15: 64.86116 | F15: 99.29888 | G15: 102.27351 | H15: 101.01094 | I15: 103.97781 | J15: 102.03281 | K15: 99.55237 | L15: 98.1705 | M15: 99.2237 | N15: 101.18031 | O15: 101.57448 | P15: 100.67623 | Q15: 101.39315 | R15: 104.49316 | S15: 100.45682
B16: 0409 | C16: 38260 | D16: 102.35036 | E16: 60.7499 | F16: 68.15818 | G16: 100.58408 | H16: 102.56272 | I16: 97.65632 | J16: 106.81513 | K16: 99.96032 | L16: 100.05105 | M16: 98.89115 | N16: 100.80853 | O16: 103.00434 | P16: 101.52659 | Q16: 101.80328 | R16: 104.69994 | S16: 99.92452
B17: 0410 | C17: 38291 | D17: 103.12368 | E17: 62.66926 | F17: 84.44642 | G17: 101.39273 | H17: 105.90569 | I17: 96.18753 | J17: 97.84211 | K17: 101.16296 | L17: 102.93943 | M17: 101.57252 | N17: 102.0793 | O17: 100.69115 | P17: 101.68981 | Q17: 102.21213 | R17: 100.22067 | S17: 101.16164
B18: 0411 | C18: 38321 | D18: 103.57877 | E18: 78.41525 | F18: 70.43561 | G18: 96.38347 | H18: 104.37511 | I18: 95.06963 | J18: 101.65557 | K18: 102.41598 | L18: 106.49311 | M18: 104.54272 | N18: 102.96217 | O18: 103.28028 | P18: 102.03612 | Q18: 102.50137 | R18: 99.69656 | S18: 100.02634
B19: 0412 | C19: 38352 | D19: 102.97856 | E19: 92.73814 | F19: 75.98912 | G19: 100.71881 | H19: 101.87374 | I19: 103.71775 | J19: 101.86557 | K19: 99.12842 | L19: 105.58867 | M19: 105.58575 | N19: 105.64116 | O19: 106.35733 | P19: 102.9846 | Q19: 104.43946 | R19: 97.24229 | S19: 103.79916
... B276: 2605 | C276: 46173 | D276: 153.62027 | E276: 297.66329 | F276: 102.84501 | G276: 144.59675 | H276: 114.35306 | I276: 158.63625 | J276: 124.37794 | K276: 153.91377 | L276: 157.15323 | M276: 197.26347 | N276: 179.16448 | O276: 159.78965 | P276: 158.5742 | Q276: 171.81406 | R276: 198.56366 | S276: 116.71788

Sheet Weights & Assumptions
A1: Weights, Sector Mapping and Forecast Assumptions
A2: Blue cells are inputs you can overwrite. Everything downstream is formula-driven and will recalculate.
A4: 1 | Sector weights and bucket mapping
A5: Sector | B5: Bucket | C5: Weight (%) | D5: INDEC 2004 prior (%) | E5: Deviation (pp) | F5: Weight within bucket | G5: Contribution check
A6: Agri. | B6: Primary | C6: 8.2873 | D6: 8.7 | E6: =C6-D6*100/SUM($D$6:$D$20) -> -0.71891118 | F6: =C6/SUMIF($B$6:$B$20,B6,$C$6:$C$20) -> 0.98774746 | G6: =C6/SUM($C$6:$C$20) -> 0.082872834
A7: Fishing | B7: Primary | C7: 0.1028 | D7: 0.4 | E7: =C7-D7*100/SUM($D$6:$D$20) -> -0.31127867 | F7: =C7/SUMIF($B$6:$B$20,B7,$C$6:$C$20) -> 0.012252536 | G7: =C7/SUM($C$6:$C$20) -> 0.0010279979
A8: Mining | B8: Industrial | C8: 3.175 | D8: 4 | E8: =C8-D8*100/SUM($D$6:$D$20) -> -0.96578675 | F8: =C8/SUMIF($B$6:$B$20,B8,$C$6:$C$20) -> 0.11939771 | G8: =C8/SUM($C$6:$C$20) -> 0.031749937
A9: Mfg. | B9: Industrial | C9: 17.8771 | D9: 17.5 | E9: =C9-D9*100/SUM($D$6:$D$20) -> -0.23884203 | F9: =C9/SUMIF($B$6:$B$20,B9,$C$6:$C$20) -> 0.67227867 | G9: =C9/SUM($C$6:$C$20) -> 0.17877064
A10: Utilities | B10: Services | C10: 1.8434 | D10: 2 | E10: =C10-D10*100/SUM($D$6:$D$20) -> -0.22699337 | F10: =C10/SUMIF($B$6:$B$20,B10,$C$6:$C$20) -> 0.028352018 | G10: =C10/SUM($C$6:$C$20) -> 0.018433963
A11: Const. | B11: Industrial | C11: 5.5397 | D11: 5.3 | E11: =C11-D11*100/SUM($D$6:$D$20) -> 0.053157557 | F11: =C11/SUMIF($B$6:$B$20,B11,$C$6:$C$20) -> 0.20832362 | G11: =C11/SUM($C$6:$C$20) -> 0.055396889
A12: Trade | B12: Services | C12: 13.2283 | D12: 12.4 | E12: =C12-D12*100/SUM($D$6:$D$20) -> 0.39186108 | F12: =C12/SUMIF($B$6:$B$20,B12,$C$6:$C$20) -> 0.20345503 | G12: =C12/SUM($C$6:$C$20) -> 0.13228274
A13: Hotels | B13: Services | C13: 3.0404 | D13: 2.7 | E13: =C13-D13*100/SUM($D$6:$D$20) -> 0.24536894 | F13: =C13/SUMIF($B$6:$B$20,B13,$C$6:$C$20) -> 0.046762219 | G13: =C13/SUM($C$6:$C$20) -> 0.030403939
A14: Transport | B14: Services | C14: 9.4699 | D14: 8.3 | E14: =C14-D14*100/SUM($D$6:$D$20) -> 0.87776749 | F14: =C14/SUMIF($B$6:$B$20,B14,$C$6:$C$20) -> 0.14564976 | G14: =C14/SUM($C$6:$C$20) -> 0.094698811
A15: Finance | B15: Services | C15: 4.9519 | D15: 4 | E15: =C15-D15*100/SUM($D$6:$D$20) -> 0.81111325 | F15: =C15/SUMIF($B$6:$B$20,B15,$C$6:$C$20) -> 0.076161634 | G15: =C15/SUM($C$6:$C$20) -> 0.049518901
A16: Real Estate | B16: Services | C16: 13.2728 | D16: 12.9 | E16: =C16-D16*100/SUM($D$6:$D$20) -> -0.081237267 | F16: =C16/SUMIF($B$6:$B$20,B16,$C$6:$C$20) -> 0.20413945 | G16: =C16/SUM($C$6:$C$20) -> 0.13272773
A17: Public Admin. | B17: Services | C17: 6.1054 | D17: 6 | E17: =C17-D17*100/SUM($D$6:$D$20) -> -0.10578012 | F17: =C17/SUMIF($B$6:$B$20,B17,$C$6:$C$20) -> 0.093902794 | G17: =C17/SUM($C$6:$C$20) -> 0.061053878
... A20: Other Services | B20: Services | C20: 3.5611 | D20: 3.6 | E20: =C20-D20*100/SUM($D$6:$D$20) -> -0.16560807 | F20: =C20/SUMIF($B$6:$B$20,B20,$C$6:$C$20) -> 0.054770734 | G20: =C20/SUM($C$6:$C$20) -> 0.035610929
A21: Total | C21: =SUM(C6:C20) -> 100.0002 | D21: =SUM(D6:D20) -> 96.6 | G21: =SUM(G6:G20) -> 1
A23: 2 | Bucket weights (derived)
A24: Bucket | B24: Weight (%) | C24: Share of EMAE
A25: Primary | B25: =SUMIF($B$6:$B$20,A25,$C$6:$C$20) -> 8.3901 | C25: =B25/SUM($B$25:$B$27) -> 0.083900832
A26: Industrial | B26: =SUMIF($B$6:$B$20,A26,$C$6:$C$20) -> 26.5918 | C26: =B26/SUM($B$25:$B$27) -> 0.26591747
A27: Services | B27: =SUMIF($B$6:$B$20,A27,$C$6:$C$20) -> 65.0183 | C27: =B27/SUM($B$25:$B$27) -> 0.6501817
A28: Total | B28: =SUM(B25:B27) -> 100.0002
A30: 3 | Forecast assumptions — average m/m growth of each sub-index, SA (%)
A31: The forecast is built bottom-up: these three pairs of assumptions drive the sub-index level paths, which aggregate to EMAE using the bucket weights above. Change a cell and every forecast number moves.
A32: Sub-index | B32: May-26 to Dec-26 (% m/m) | C32: 2027 (% m/m) | D32: Implied ann. pace 2026H2 | E32: Implied ann. pace 2027 | F32: Trailing 6m actual (% m/m)
A33: Primary | B33: 0.1 | C33: 0.25 | D33: =((1+B33/100)^12-1)*100 -> 1.206622 | E33: =((1+C33/100)^12-1)*100 -> 3.0415957 | F33: 2.62
A34: Industrial | B34: 0.15 | C34: 0.35 | D34: =((1+B34/100)^12-1)*100 -> 1.8149245 | E34: =((1+C34/100)^12-1)*100 -> 4.2818007 | F34: 0
A35: Services | B35: 0.15 | C35: 0.3 | D35: =((1+B35/100)^12-1)*100 -> 1.8149245 | E35: =((1+C35/100)^12-1)*100 -> 3.659998 | F35: 0.03
A38: 4 | Weight estimation diagnostics
A39: Method | B39: Constrained least squares of the 15 seasonally-adjusted sector indices on the published SA EMAE, shrunk toward the INDEC 2004 value-added shares.
A40: Why shrinkage | B40: Every series is rebased to 2004=100, so EMAE is exactly a convex combination of the sectors and the weights are the 2004 value-added shares. But the services block is highly collinear: the unpenalised fit pins Education, Utilities, Public Admin and Other Services at zero and pushes Trade to 22.9%. Shrinkage restores economically sensible weights at almost no cost in fit.
A41: Shrinkage parameter | B41: lambda = 5.0
A42: R-squared | B42: 0.98958
A43: Residual std. dev. (index pts) | B43: 1.469
A44: Max abs. residual (index pts) | B44: 4.301
A45: Bucket weights: stability | B45: Primary 8-10%, Industrial 26-27%, Services 63-65% across the entire shrinkage range. The bucket split is well identified even though individual sector weights are not.
A46: Override | B46: If you have INDEC's official EMAE base-2004 weights, paste them into column C. Nothing else needs changing.

Sheet X11 Reference
A1: Static X-11 Benchmark
A2: One-off seasonal adjustment computed offline with a full X-11-style routine. Frozen values, kept only as a benchmark for the live in-sheet factors. Nothing downstream depends on this sheet.
A6: Date | B6: Agri. | C6: Fishing | D6: Mining | E6: Mfg. | F6: Utilities | G6: Const. | H6: Trade | I6: Hotels | J6: Transport | K6: Finance | L6: Real Estate | M6: Public Admin. | N6: Education | O6: Health | P6: Other Services
A7: 38017 | B7: 122.29655 | C7: 120.21122 | D7: 99.535438 | E7: 95.81535 | F7: 97.308176 | G7: 96.577477 | H7: 97.979626 | I7: 95.579602 | J7: 96.389149 | K7: 98.779296 | L7: 96.182671 | M7: 97.505233 | N7: 96.74534 | O7: 97.417586 | P7: 95.35565
A8: 38046 | B8: 115.81236 | C8: 87.445869 | D8: 101.41784 | E8: 96.976622 | F8: 98.858384 | G8: 96.992826 | H8: 98.207697 | I8: 96.466881 | J8: 97.06902 | K8: 97.805568 | L8: 96.906771 | M8: 97.963489 | N8: 97.33128 | O8: 97.916659 | P8: 98.126777
A9: 38077 | B9: 100.7906 | C9: 108.54386 | D9: 99.754717 | E9: 97.557282 | F9: 101.62633 | G9: 97.766438 | H9: 99.037171 | I9: 96.995971 | J9: 97.125243 | K9: 97.763415 | L9: 98.182217 | M9: 98.126239 | N9: 97.400252 | O9: 98.022085 | P9: 98.595348
A10: 38107 | B10: 90.244558 | C10: 103.80445 | D10: 99.13117 | E10: 97.177344 | F10: 100.5615 | G10: 98.034028 | H10: 98.050647 | I10: 97.48835 | J10: 97.54146 | K10: 97.146005 | L10: 97.861236 | M10: 98.9659 | N10: 98.61292 | O10: 100.31625 | P10: 98.69831
A11: 38138 | B11: 85.140239 | C11: 78.751344 | D11: 100.26006 | E11: 98.233277 | F11: 100.17702 | G11: 98.627322 | H11: 97.842738 | I11: 98.952839 | J11: 97.639471 | K11: 97.336068 | L11: 98.405466 | M11: 99.22246 | N11: 99.022886 | O11: 99.587195 | P11: 99.046811
A12: 38168 | B12: 84.794334 | C12: 103.31534 | D12: 100.25824 | E12: 99.765487 | F12: 100.19932 | G12: 99.759349 | H12: 100.95579 | I12: 99.756364 | J12: 99.014956 | K12: 97.851686 | L12: 99.36804 | M12: 99.61084 | N12: 99.690348 | O12: 97.136464 | P12: 99.722692
A13: 38199 | B13: 95.745901 | C13: 85.723979 | D13: 98.468451 | E13: 100.61251 | F13: 100.06066 | G13: 101.21964 | H13: 101.01451 | I13: 99.663173 | J13: 100.12606 | K13: 99.427988 | L13: 100.76038 | M13: 100.3526 | N13: 100.24666 | O13: 100.74605 | P13: 99.709656
A14: 38230 | B14: 96.568804 | C14: 93.827971 | D14: 99.761613 | E14: 100.11916 | F14: 99.962659 | G14: 101.92253 | H14: 100.19253 | I14: 99.638707 | J14: 100.97793 | K14: 101.39772 | L14: 100.59223 | M14: 100.74237 | N14: 100.91954 | O14: 101.61606 | P14: 100.78969
A15: 38260 | B15: 96.451106 | C15: 95.213754 | D15: 100.62568 | E15: 101.82907 | F15: 100.38428 | G15: 103.33532 | H15: 101.4396 | I15: 100.5412 | J15: 102.11846 | K15: 102.0709 | L15: 101.19767 | M15: 101.14971 | N15: 101.14245 | O15: 103.76512 | P15: 102.20401
A16: 38291 | B16: 98.346911 | C16: 101.37345 | D16: 100.18109 | E16: 101.84207 | F16: 101.93668 | G16: 101.80758 | H16: 102.80095 | I16: 102.66899 | J16: 103.67006 | K16: 102.9485 | L16: 101.11211 | M16: 101.47379 | N16: 101.66834 | O16: 102.87006 | P16: 102.9248
A17: 38321 | B17: 98.015937 | C17: 97.521605 | D17: 100.31158 | E17: 102.26075 | F17: 100.06837 | G17: 103.10352 | H17: 102.438 | I17: 104.33856 | J17: 105.71184 | K17: 103.1753 | L17: 101.85321 | M17: 101.63802 | N17: 101.78141 | O17: 103.04606 | P17: 103.24338
A18: 38352 | B18: 96.917687 | C18: 85.253374 | D18: 100.72696 | E18: 103.23365 | F18: 103.11383 | G18: 104.56885 | H18: 104.77428 | I18: 105.52918 | J18: 106.42123 | K18: 103.37564 | L18: 101.85083 | M18: 101.8581 | N18: 102.60687 | O18: 103.46387 | P18: 104.17037
... A275: 46173 | B275: 144.42671 | C275: 124.72598 | D275: 136.60389 | E275: 111.15195 | F275: 153.22317 | G275: 130.81158 | H275: 149.12501 | I275: 176.68432 | J275: 187.90798 | K275: 193.83434 | L275: 158.84077 | M275: 159.42283 | N275: 171.44841 | O275: 185.39148 | P275: 128.24676

Sheet SF Workings
A1: Seasonal Factor Workings — live
A2: Trend = centred 2x12 moving average of the NSA series. Ratio = NSA / trend. Raw factor = mean of the ratios for the same calendar month inside a rolling window centred on that date, so seasonality is allowed to evolve. Normalised factor rescales so the twelve factors around any date average to 1.
A6: Date | B6: Month | C6: Agri. trend | D6: Agri. ratio | E6: Agri. raw fac | F6: Agri. FACTOR | G6: Fishing trend | H6: Fishing ratio | I6: Fishing raw fac | J6: Fishing FACTOR | K6: Mining trend | L6: Mining ratio | M6: Mining raw fac | N6: Mining FACTOR | O6: Mfg. trend | P6: Mfg. ratio | Q6: Mfg. raw fac | R6: Mfg. FACTOR | S6: Utilities trend | T6: Utilities ratio | U6: Utilities raw fac | V6: Utilities FACTOR | W6: Const. trend | X6: Const. ratio | Y6: Const. raw fac | Z6: Const. FACTOR | AA6: Trade trend | AB6: Trade ratio | AC6: Trade raw fac | AD6: Trade FACTOR | AE6: Hotels trend | AF6: Hotels ratio | AG6: Hotels raw fac | AH6: Hotels FACTOR | AI6: Transport trend | AJ6: Transport ratio | AK6: Transport raw fac | AL6: Transport FACTOR | AM6: Finance trend | AN6: Finance ratio | AO6: Finance raw fac | AP6: Finance FACTOR | AQ6: Real Estate trend | AR6: Real Estate ratio | AS6: Real Estate raw fac | AT6: Real Estate FACTOR | AU6: Public Admin. trend | AV6: Public Admin. ratio | AW6: Public Admin. raw fac | AX6: Public Admin. FACTOR | AY6: Education trend | AZ6: Education ratio | BA6: Education raw fac | BB6: Education FACTOR | BC6: Health trend | BD6: Health ratio | BE6: Health raw fac | BF6: Health FACTOR | BG6: Other Services trend | BH6: Other Services ratio | BI6: Other Services raw fac | BJ6: Other Services FACTOR
A7: 38017 | B7: =MONTH(A7) -> 1 | E7: =IFERROR(AVERAGEIFS($D$7:$D$294,$B$7:$B$294,$B7,$A$7:$A$294,">="&EDATE($A7,-12*'Seasonal Factors'!$E$4),$A$7:$A$294,"<="&EDATE($A7,12*'Seasonal Factors'!$E$4)),"") -> 0.55594837 | F7: =IFERROR(E7/AVERAGE(E7:E13),"") -> 0.43397409 | I7: =IFERROR(AVERAGEIFS($H$7:$H$294,$B$7:$B$294,$B7,$A$7:$A$294,">="&EDATE($A7,-12*'Seasonal Factors'!$E$4),$A$7:$A$294,"<="&EDATE($A7,12*'Seasonal Factors'!$E$4)),"") -> 0.33273156 | J7: =IFERROR(I7/AVERAGE(I7:I13),"") -> 0.27241964 | M7: =IFERROR(AVERAGEIFS($L$7:$L$294,$B$7:$B$294,$B7,$A$7:$A$294,">="&EDATE($A7,-12*'Seasonal Factors'!$E$4),$A$7:$A$294,"<="&EDATE($A7,12*'Seasonal Factors'!$E$4)),"") -> 1.0048836 | N7: =IFERROR(M7/AVERAGE(M7:M13),"") -> 1.0075163 | Q7: =IFERROR(AVERAGEIFS($P$7:$P$294,$B$7:$B$294,$B7,$A$7:$A$294,">="&EDATE($A7,-12*'Seasonal Factors'!$E$4),$A$7:$A$294,"<="&EDATE($A7,12*'Seasonal Factors'!$E$4)),"") -> 0.92746321 | R7: =IFERROR(Q7/AVERAGE(Q7:Q13),"") -> 0.93923788 | U7: =IFERROR(AVERAGEIFS($T$7:$T$294,$B$7:$B$294,$B7,$A$7:$A$294,">="&EDATE($A7,-12*'Seasonal Factors'!$E$4),$A$7:$A$294,"<="&EDATE($A7,12*'Seasonal Factors'!$E$4)),"") -> 1.0385353 | V7: =IFERROR(U7/AVERAGE(U7:U13),"") -> 1.0280534 | Y7: =IFERROR(AVERAGEIFS($X$7:$X$294,$B$7:$B$294,$B7,$A$7:$A$294,">="&EDATE($A7,-12*'Seasonal Factors'!$E$4),$A$7:$A$294,"<="&EDATE($A7,12*'Seasonal Factors'!$E$4)),"") -> 1.0084391 | Z7: =IFERROR(Y7/AVERAGE(Y7:Y13),"") -> 1.0004949 | AC7: =IFERROR(AVERAGEIFS($AB$7:$AB$294,$B$7:$B$294,$B7,$A$7:$A$294,">="&EDATE($A7,-12*'Seasonal Factors'!$E$4),$A$7:$A$294,"<="&EDATE($A7,12*'Seasonal Factors'!$E$4)),"") -> 0.9502026 | AD7: =IFERROR(AC7/AVERAGE(AC7:AC13),"") -> 0.94122974 | AG7: =IFERROR(AVERAGEIFS($AF$7:$AF$294,$B$7:$B$294,$B7,$A$7:$A$294,">="&EDATE($A7,-12*'Seasonal Factors'!$E$4),$A$7:$A$294,"<="&EDATE($A7,12*'Seasonal Factors'!$E$4)),"") -> 1.1152737 | AH7: =IFERROR(AG7/AVERAGE(AG7:AG13),"") -> 1.1144596 | AK7: =IFERROR(AVERAGEIFS($AJ$7:$AJ$294,$B$7:$B$294,$B7,$A$7:$A$294,">="&EDATE($A7,-12*'Seasonal Factors'!$E$4),$A$7:$A$294,"<="&EDATE($A7,12*'Seasonal Factors'!$E$4)),"") -> 0.99191057 | AL7: =IFERROR(AK7/AVERAGE(AK7:AK13),"") -> 0.98109924 | AO7: =IFERROR(AVERAGEIFS($AN$7:$AN$294,$B$7:$B$294,$B7,$A$7:$A$294,">="&EDATE($A7,-12*'Seasonal Factors'!$E$4),$A$7:$A$294,"<="&EDATE($A7,12*'Seasonal Factors'!$E$4)),"") -> 1.0319244 | AP7: =IFERROR(AO7/AVERAGE(AO7:AO13),"") -> 1.0317935 | AS7: =IFERROR(AVERAGEIFS($AR$7:$AR$294,$B$7:$B$294,$B7,$A$7:$A$294,">="&EDATE($A7,-12*'Seasonal Factors'!$E$4),$A$7:$A$294,"<="&EDATE($A7,12*'Seasonal Factors'!$E$4)),"") -> 0.94364373 | AT7: =IFERROR(AS7/AVERAGE(AS7:AS13),"") -> 0.95347275 | AW7: =IFERROR(AVERAGEIFS($AV$7:$AV$294,$B$7:$B$294,$B7,$A$7:$A$294,">="&EDATE($A7,-12*'Seasonal Factors'!$E$4),$A$7:$A$294,"<="&EDATE($A7,12*'Seasonal Factors'!$E$4)),"") -> 0.98778628 | AX7: =IFERROR(AW7/AVERAGE(AW7:AW13),"") -> 0.99091297 | BA7: =IFERROR(AVERAGEIFS($AZ$7:$AZ$294,$B$7:$B$294,$B7,$A$7:$A$294,">="&EDATE($A7,-12*'Seasonal Factors'!$E$4),$A$7:$A$294,"<="&EDATE($A7,12*'Seasonal Factors'!$E$4)),"") -> 0.97209641 | BB7: =IFERROR(BA7/AVERAGE(BA7:BA13),"") -> 0.97938267 | BE7: =IFERROR(AVERAGEIFS($BD$7:$BD$294,$B$7:$B$294,$B7,$A$7:$A$294,">="&EDATE($A7,-12*'Seasonal Factors'!$E$4),$A$7:$A$294,"<="&EDATE($A7,12*'Seasonal Factors'!$E$4)),"") -> 0.97829956 | BF7: =IFERROR(BE7/AVERAGE(BE7:BE13),"") -> 0.97039575 | BI7: =IFERROR(AVERAGEIFS($BH$7:$BH$294,$B$7:$B$294,$B7,$A$7:$A$294,">="&EDATE($A7,-12*'Seasonal Factors'!$E$4),$A$7:$A$294,"<="&EDATE($A7,12*'Seasonal Factors'!$E$4)),"") -> 1.0171449 | BJ7: =IFERROR(BI7/AVERAGE(BI7:BI13),"") -> 1.0038065
A8: 38046 | B8: =MONTH(A8) -> 2 | E8: =IFERROR(AVERAGEIFS($D$7:$D$294,$B$7:$B$294,$B8,$A$7:$A$294,">="&EDATE($A8,-12*'Seasonal Factors'!$E$4),$A$7:$A$294,"<="&EDATE($A8,12*'Seasonal Factors'!$E$4)),"") -> 0.56108749 | F8: =IFERROR(E8/AVERAGE(E7:E14),"") -> 0.47005066 | I8: =IFERROR(AVERAGEIFS($H$7:$H$294,$B$7:$B$294,$B8,$A$7:$A$294,">="&EDATE($A8,-12*'Seasonal Factors'!$E$4),$A$7:$A$294,"<="&EDATE($A8,12*'Seasonal Factors'!$E$4)),"") -> 0.75044925 | J8: =IFERROR(I8/AVERAGE(I7:I14),"") -> 0.63175003 | M8: =IFERROR(AVERAGEIFS($L$7:$L$294,$B$7:$B$294,$B8,$A$7:$A$294,">="&EDATE($A8,-12*'Seasonal Factors'!$E$4),$A$7:$A$294,"<="&EDATE($A8,12*'Seasonal Factors'!$E$4)),"") -> 0.93281158 | N8: =IFERROR(M8/AVERAGE(M7:M14),"") -> 0.9318041 | Q8: =IFERROR(AVERAGEIFS($P$7:$P$294,$B$7:$B$294,$B8,$A$7:$A$294,">="&EDATE($A8,-12*'Seasonal Factors'!$E$4),$A$7:$A$294,"<="&EDATE($A8,12*'Seasonal Factors'!$E$4)),"") -> 0.90529023 | R8: =IFERROR(Q8/AVERAGE(Q7:Q14),"") -> 0.91324232 | U8: =IFERROR(AVERAGEIFS($T$7:$T$294,$B$7:$B$294,$B8,$A$7:$A$294,">="&EDATE($A8,-12*'Seasonal Factors'!$E$4),$A$7:$A$294,"<="&EDATE($A8,12*'Seasonal Factors'!$E$4)),"") -> 0.97299595 | V8: =IFERROR(U8/AVERAGE(U7:U14),"") -> 0.95962324 | Y8: =IFERROR(AVERAGEIFS($X$7:$X$294,$B$7:$B$294,$B8,$A$7:$A$294,">="&EDATE($A8,-12*'Seasonal Factors'!$E$4),$A$7:$A$294,"<="&EDATE($A8,12*'Seasonal Factors'!$E$4)),"") -> 1.022715 | Z8: =IFERROR(Y8/AVERAGE(Y7:Y14),"") -> 1.0140206 | AC8: =IFERROR(AVERAGEIFS($AB$7:$AB$294,$B$7:$B$294,$B8,$A$7:$A$294,">="&EDATE($A8,-12*'Seasonal Factors'!$E$4),$A$7:$A$294,"<="&EDATE($A8,12*'Seasonal Factors'!$E$4)),"") -> 0.93505428 | AD8: =IFERROR(AC8/AVERAGE(AC7:AC14),"") -> 0.92660012 | AG8: =IFERROR(AVERAGEIFS($AF$7:$AF$294,$B$7:$B$294,$B8,$A$7:$A$294,">="&EDATE($A8,-12*'Seasonal Factors'!$E$4),$A$7:$A$294,"<="&EDATE($A8,12*'Seasonal Factors'!$E$4)),"") -> 1.0666997 | AH8: =IFERROR(AG8/AVERAGE(AG7:AG14),"") -> 1.0671696 | AK8: =IFERROR(AVERAGEIFS($AJ$7:$AJ$294,$B$7:$B$294,$B8,$A$7:$A$294,">="&EDATE($A8,-12*'Seasonal Factors'!$E$4),$A$7:$A$294,"<="&EDATE($A8,12*'Seasonal Factors'!$E$4)),"") -> 0.94166902 | AL8: =IFERROR(AK8/AVERAGE(AK7:AK14),"") -> 0.9335053 | AO8: =IFERROR(AVERAGEIFS($AN$7:$AN$294,$B$7:$B$294,$B8,$A$7:$A$294,">="&EDATE($A8,-12*'Seasonal Factors'!$E$4),$A$7:$A$294,"<="&EDATE($A8,12*'Seasonal Factors'!$E$4)),"") -> 0.97988114 | AP8: =IFERROR(AO8/AVERAGE(AO7:AO14),"") -> 0.97878408 | AS8: =IFERROR(AVERAGEIFS($AR$7:$AR$294,$B$7:$B$294,$B8,$A$7:$A$294,">="&EDATE($A8,-12*'Seasonal Factors'!$E$4),$A$7:$A$294,"<="&EDATE($A8,12*'Seasonal Factors'!$E$4)),"") -> 0.96137716 | AT8: =IFERROR(AS8/AVERAGE(AS7:AS14),"") -> 0.96900999 | AW8: =IFERROR(AVERAGEIFS($AV$7:$AV$294,$B$7:$B$294,$B8,$A$7:$A$294,">="&EDATE($A8,-12*'Seasonal Factors'!$E$4),$A$7:$A$294,"<="&EDATE($A8,12*'Seasonal Factors'!$E$4)),"") -> 0.99481363 | AX8: =IFERROR(AW8/AVERAGE(AW7:AW14),"") -> 0.99740147 | BA8: =IFERROR(AVERAGEIFS($AZ$7:$AZ$294,$B$7:$B$294,$B8,$A$7:$A$294,">="&EDATE($A8,-12*'Seasonal Factors'!$E$4),$A$7:$A$294,"<="&EDATE($A8,12*'Seasonal Factors'!$E$4)),"") -> 0.9791379 | BB8: =IFERROR(BA8/AVERAGE(BA7:BA14),"") -> 0.98472307 | BE8: =IFERROR(AVERAGEIFS($BD$7:$BD$294,$B$7:$B$294,$B8,$A$7:$A$294,">="&EDATE($A8,-12*'Seasonal Factors'!$E$4),$A$7:$A$294,"<="&EDATE($A8,12*'Seasonal Factors'!$E$4)),"") -> 0.93126298 | BF8: =IFERROR(BE8/AVERAGE(BE7:BE14),"") -> 0.92013996 | BI8: =IFERROR(AVERAGEIFS($BH$7:$BH$294,$B$7:$B$294,$B8,$A$7:$A$294,">="&EDATE($A8,-12*'Seasonal Factors'!$E$4),$A$7:$A$294,"<="&EDATE($A8,12*'Seasonal Factors'!$E$4)),"") -> 0.98890195 | BJ8: =IFERROR(BI8/AVERAGE(BI7:BI14),"") -> 0.97515355
A9: 38077 | B9: =MONTH(A9) -> 3 | E9: =IFERROR(AVERAGEIFS($D$7:$D$294,$B$7:$B$294,$B9,$A$7:$A$294,">="&EDATE($A9,-12*'Seasonal Factors'!$E$4),$A$7:$A$294,"<="&EDATE($A9,12*'Seasonal Factors'!$E$4)),"") -> 1.0933966 | F9: =IFERROR(E9/AVERAGE(E7:E15),"") -> 0.97502151 | I9: =IFERROR(AVERAGEIFS($H$7:$H$294,$B$7:$B$294,$B9,$A$7:$A$294,">="&EDATE($A9,-12*'Seasonal Factors'!$E$4),$A$7:$A$294,"<="&EDATE($A9,12*'Seasonal Factors'!$E$4)),"") -> 1.5458909 | J9: =IFERROR(I9/AVERAGE(I7:I15),"") -> 1.3751622 | M9: =IFERROR(AVERAGEIFS($L$7:$L$294,$B$7:$B$294,$B9,$A$7:$A$294,">="&EDATE($A9,-12*'Seasonal Factors'!$E$4),$A$7:$A$294,"<="&EDATE($A9,12*'Seasonal Factors'!$E$4)),"") -> 1.0232224 | N9: =IFERROR(M9/AVERAGE(M7:M15),"") -> 1.0218324 | Q9: =IFERROR(AVERAGEIFS($P$7:$P$294,$B$7:$B$294,$B9,$A$7:$A$294,">="&EDATE($A9,-12*'Seasonal Factors'!$E$4),$A$7:$A$294,"<="&EDATE($A9,12*'Seasonal Factors'!$E$4)),"") -> 1.0195923 | R9: =IFERROR(Q9/AVERAGE(Q7:Q15),"") -> 1.0241282 | U9: =IFERROR(AVERAGEIFS($T$7:$T$294,$B$7:$B$294,$B9,$A$7:$A$294,">="&EDATE($A9,-12*'Seasonal Factors'!$E$4),$A$7:$A$294,"<="&EDATE($A9,12*'Seasonal Factors'!$E$4)),"") -> 1.004162 | V9: =IFERROR(U9/AVERAGE(U7:U15),"") -> 0.99454363 | Y9: =IFERROR(AVERAGEIFS($X$7:$X$294,$B$7:$B$294,$B9,$A$7:$A$294,">="&EDATE($A9,-12*'Seasonal Factors'!$E$4),$A$7:$A$294,"<="&EDATE($A9,12*'Seasonal Factors'!$E$4)),"") -> 1.0447517 | Z9: =IFERROR(Y9/AVERAGE(Y7:Y15),"") -> 1.0330931 | AC9: =IFERROR(AVERAGEIFS($AB$7:$AB$294,$B$7:$B$294,$B9,$A$7:$A$294,">="&EDATE($A9,-12*'Seasonal Factors'!$E$4),$A$7:$A$294,"<="&EDATE($A9,12*'Seasonal Factors'!$E$4)),"") -> 1.0813157 | AD9: =IFERROR(AC9/AVERAGE(AC7:AC15),"") -> 1.0722606 | AG9: =IFERROR(AVERAGEIFS($AF$7:$AF$294,$B$7:$B$294,$B9,$A$7:$A$294,">="&EDATE($A9,-12*'Seasonal Factors'!$E$4),$A$7:$A$294,"<="&EDATE($A9,12*'Seasonal Factors'!$E$4)),"") -> 1.0360265 | AH9: =IFERROR(AG9/AVERAGE(AG7:AG15),"") -> 1.0369591 | AK9: =IFERROR(AVERAGEIFS($AJ$7:$AJ$294,$B$7:$B$294,$B9,$A$7:$A$294,">="&EDATE($A9,-12*'Seasonal Factors'!$E$4),$A$7:$A$294,"<="&EDATE($A9,12*'Seasonal Factors'!$E$4)),"") -> 1.0011586 | AL9: =IFERROR(AK9/AVERAGE(AK7:AK15),"") -> 0.99583494 | AO9: =IFERROR(AVERAGEIFS($AN$7:$AN$294,$B$7:$B$294,$B9,$A$7:$A$294,">="&EDATE($A9,-12*'Seasonal Factors'!$E$4),$A$7:$A$294,"<="&EDATE($A9,12*'Seasonal Factors'!$E$4)),"") -> 0.99533554 | AP9: =IFERROR(AO9/AVERAGE(AO7:AO15),"") -> 0.99588458 | AS9: =IFERROR(AVERAGEIFS($AR$7:$AR$294,$B$7:$B$294,$B9,$A$7:$A$294,">="&EDATE($A9,-12*'Seasonal Factors'!$E$4),$A$7:$A$294,"<="&EDATE($A9,12*'Seasonal Factors'!$E$4)),"") -> 0.99343659 | AT9: =IFERROR(AS9/AVERAGE(AS7:AS15),"") -> 0.99899244 | AW9: =IFERROR(AVERAGEIFS($AV$7:$AV$294,$B$7:$B$294,$B9,$A$7:$A$294,">="&EDATE($A9,-12*'Seasonal Factors'!$E$4),$A$7:$A$294,"<="&EDATE($A9,12*'Seasonal Factors'!$E$4)),"") -> 0.99296142 | AX9: =IFERROR(AW9/AVERAGE(AW7:AW15),"") -> 0.99478134 | BA9: =IFERROR(AVERAGEIFS($AZ$7:$AZ$294,$B$7:$B$294,$B9,$A$7:$A$294,">="&EDATE($A9,-12*'Seasonal Factors'!$E$4),$A$7:$A$294,"<="&EDATE($A9,12*'Seasonal Factors'!$E$4)),"") -> 0.98299206 | BB9: =IFERROR(BA9/AVERAGE(BA7:BA15),"") -> 0.98699367 | BE9: =IFERROR(AVERAGEIFS($BD$7:$BD$294,$B$7:$B$294,$B9,$A$7:$A$294,">="&EDATE($A9,-12*'Seasonal Factors'!$E$4),$A$7:$A$294,"<="&EDATE($A9,12*'Seasonal Factors'!$E$4)),"") -> 1.0051527 | BF9: =IFERROR(BE9/AVERAGE(BE7:BE15),"") -> 0.99246899 | BI9: =IFERROR(AVERAGEIFS($BH$7:$BH$294,$B$7:$B$294,$B9,$A$7:$A$294,">="&EDATE($A9,-12*'Seasonal Factors'!$E$4),$A$7:$A$294,"<="&EDATE($A9,12*'Seasonal Factors'!$E$4)),"") -> 0.98407741 | BJ9: =IFERROR(BI9/AVERAGE(BI7:BI15),"") -> 0.97432417
A10: 38107 | B10: =MONTH(A10) -> 4 | E10: =IFERROR(AVERAGEIFS($D$7:$D$294,$B$7:$B$294,$B10,$A$7:$A$294,">="&EDATE($A10,-12*'Seasonal Factors'!$E$4),$A$7:$A$294,"<="&EDATE($A10,12*'Seasonal Factors'!$E$4)),"") -> 1.7147611 | F10: =IFERROR(E10/AVERAGE(E7:E16),"") -> 1.6119791 | I10: =IFERROR(AVERAGEIFS($H$7:$H$294,$B$7:$B$294,$B10,$A$7:$A$294,">="&EDATE($A10,-12*'Seasonal Factors'!$E$4),$A$7:$A$294,"<="&EDATE($A10,12*'Seasonal Factors'!$E$4)),"") -> 1.6033055 | J10: =IFERROR(I10/AVERAGE(I7:I16),"") -> 1.4809592 | M10: =IFERROR(AVERAGEIFS($L$7:$L$294,$B$7:$B$294,$B10,$A$7:$A$294,">="&EDATE($A10,-12*'Seasonal Factors'!$E$4),$A$7:$A$294,"<="&EDATE($A10,12*'Seasonal Factors'!$E$4)),"") -> 0.99819723 | N10: =IFERROR(M10/AVERAGE(M7:M16),"") -> 0.99570031 | Q10: =IFERROR(AVERAGEIFS($P$7:$P$294,$B$7:$B$294,$B10,$A$7:$A$294,">="&EDATE($A10,-12*'Seasonal Factors'!$E$4),$A$7:$A$294,"<="&EDATE($A10,12*'Seasonal Factors'!$E$4)),"") -> 1.0189036 | R10: =IFERROR(Q10/AVERAGE(Q7:Q16),"") -> 1.0171125 | U10: =IFERROR(AVERAGEIFS($T$7:$T$294,$B$7:$B$294,$B10,$A$7:$A$294,">="&EDATE($A10,-12*'Seasonal Factors'!$E$4),$A$7:$A$294,"<="&EDATE($A10,12*'Seasonal Factors'!$E$4)),"") -> 0.96038707 | V10: =IFERROR(U10/AVERAGE(U7:U16),"") -> 0.95691836 | Y10: =IFERROR(AVERAGEIFS($X$7:$X$294,$B$7:$B$294,$B10,$A$7:$A$294,">="&EDATE($A10,-12*'Seasonal Factors'!$E$4),$A$7:$A$294,"<="&EDATE($A10,12*'Seasonal Factors'!$E$4)),"") -> 0.98850621 | Z10: =IFERROR(Y10/AVERAGE(Y7:Y16),"") -> 0.98058683 | AC10: =IFERROR(AVERAGEIFS($AB$7:$AB$294,$B$7:$B$294,$B10,$A$7:$A$294,">="&EDATE($A10,-12*'Seasonal Factors'!$E$4),$A$7:$A$294,"<="&EDATE($A10,12*'Seasonal Factors'!$E$4)),"") -> 1.0322933 | AD10: =IFERROR(AC10/AVERAGE(AC7:AC16),"") -> 1.0239038 | AG10: =IFERROR(AVERAGEIFS($AF$7:$AF$294,$B$7:$B$294,$B10,$A$7:$A$294,">="&EDATE($A10,-12*'Seasonal Factors'!$E$4),$A$7:$A$294,"<="&EDATE($A10,12*'Seasonal Factors'!$E$4)),"") -> 0.96683337 | AH10: =IFERROR(AG10/AVERAGE(AG7:AG16),"") -> 0.96731026 | AK10: =IFERROR(AVERAGEIFS($AJ$7:$AJ$294,$B$7:$B$294,$B10,$A$7:$A$294,">="&EDATE($A10,-12*'Seasonal Factors'!$E$4),$A$7:$A$294,"<="&EDATE($A10,12*'Seasonal Factors'!$E$4)),"") -> 1.02507 | AL10: =IFERROR(AK10/AVERAGE(AK7:AK16),"") -> 1.0212437 | AO10: =IFERROR(AVERAGEIFS($AN$7:$AN$294,$B$7:$B$294,$B10,$A$7:$A$294,">="&EDATE($A10,-12*'Seasonal Factors'!$E$4),$A$7:$A$294,"<="&EDATE($A10,12*'Seasonal Factors'!$E$4)),"") -> 0.98641846 | AP10: =IFERROR(AO10/AVERAGE(AO7:AO16),"") -> 0.98655906 | AS10: =IFERROR(AVERAGEIFS($AR$7:$AR$294,$B$7:$B$294,$B10,$A$7:$A$294,">="&EDATE($A10,-12*'Seasonal Factors'!$E$4),$A$7:$A$294,"<="&EDATE($A10,12*'Seasonal Factors'!$E$4)),"") -> 0.99085338 | AT10: =IFERROR(AS10/AVERAGE(AS7:AS16),"") -> 0.99494487 | AW10: =IFERROR(AVERAGEIFS($AV$7:$AV$294,$B$7:$B$294,$B10,$A$7:$A$294,">="&EDATE($A10,-12*'Seasonal Factors'!$E$4),$A$7:$A$294,"<="&EDATE($A10,12*'Seasonal Factors'!$E$4)),"") -> 0.98879329 | AX10: =IFERROR(AW10/AVERAGE(AW7:AW16),"") -> 0.99032196 | BA10: =IFERROR(AVERAGEIFS($AZ$7:$AZ$294,$B$7:$B$294,$B10,$A$7:$A$294,">="&EDATE($A10,-12*'Seasonal Factors'!$E$4),$A$7:$A$294,"<="&EDATE($A10,12*'Seasonal Factors'!$E$4)),"") -> 0.98157309 | BB10: =IFERROR(BA10/AVERAGE(BA7:BA16),"") -> 0.98444783 | BE10: =IFERROR(AVERAGEIFS($BD$7:$BD$294,$B$7:$B$294,$B10,$A$7:$A$294,">="&EDATE($A10,-12*'Seasonal Factors'!$E$4),$A$7:$A$294,"<="&EDATE($A10,12*'Seasonal Factors'!$E$4)),"") -> 1.024565 | BF10: =IFERROR(BE10/AVERAGE(BE7:BE16),"") -> 1.0153866 | BI10: =IFERROR(AVERAGEIFS($BH$7:$BH$294,$B$7:$B$294,$B10,$A$7:$A$294,">="&EDATE($A10,-12*'Seasonal Factors'!$E$4),$A$7:$A$294,"<="&EDATE($A10,12*'Seasonal Factors'!$E$4)),"") -> 0.99409956 | BJ10: =IFERROR(BI10/AVERAGE(BI7:BI16),"") -> 0.98750863
A11: 38138 | B11: =MONTH(A11) -> 5 | E11: =IFERROR(AVERAGEIFS($D$7:$D$294,$B$7:$B$294,$B11,$A$7:$A$294,">="&EDATE($A11,-12*'Seasonal Factors'!$E$4),$A$7:$A$294,"<="&EDATE($A11,12*'Seasonal Factors'!$E$4)),"") -> 2.4954434 | F11: =IFERROR(E11/AVERAGE(E7:E17),"") -> 2.4238026 | I11: =IFERROR(AVERAGEIFS($H$7:$H$294,$B$7:$B$294,$B11,$A$7:$A$294,">="&EDATE($A11,-12*'Seasonal Factors'!$E$4),$A$7:$A$294,"<="&EDATE($A11,12*'Seasonal Factors'!$E$4)),"") -> 1.9508447 | J11: =IFERROR(I11/AVERAGE(I7:I17),"") -> 1.8893728 | M11: =IFERROR(AVERAGEIFS($L$7:$L$294,$B$7:$B$294,$B11,$A$7:$A$294,">="&EDATE($A11,-12*'Seasonal Factors'!$E$4),$A$7:$A$294,"<="&EDATE($A11,12*'Seasonal Factors'!$E$4)),"") -> 1.0067049 | N11: =IFERROR(M11/AVERAGE(M7:M17),"") -> 1.0076563 | Q11: =IFERROR(AVERAGEIFS($P$7:$P$294,$B$7:$B$294,$B11,$A$7:$A$294,">="&EDATE($A11,-12*'Seasonal Factors'!$E$4),$A$7:$A$294,"<="&EDATE($A11,12*'Seasonal Factors'!$E$4)),"") -> 1.0315528 | R11: =IFERROR(Q11/AVERAGE(Q7:Q17),"") -> 1.0273258 | U11: =IFERROR(AVERAGEIFS($T$7:$T$294,$B$7:$B$294,$B11,$A$7:$A$294,">="&EDATE($A11,-12*'Seasonal Factors'!$E$4),$A$7:$A$294,"<="&EDATE($A11,12*'Seasonal Factors'!$E$4)),"") -> 1.0196935 | V11: =IFERROR(U11/AVERAGE(U7:U17),"") -> 1.0202449 | Y11: =IFERROR(AVERAGEIFS($X$7:$X$294,$B$7:$B$294,$B11,$A$7:$A$294,">="&EDATE($A11,-12*'Seasonal Factors'!$E$4),$A$7:$A$294,"<="&EDATE($A11,12*'Seasonal Factors'!$E$4)),"") -> 0.99949192 | Z11: =IFERROR(Y11/AVERAGE(Y7:Y17),"") -> 0.99293647 | AC11: =IFERROR(AVERAGEIFS($AB$7:$AB$294,$B$7:$B$294,$B11,$A$7:$A$294,">="&EDATE($A11,-12*'Seasonal Factors'!$E$4),$A$7:$A$294,"<="&EDATE($A11,12*'Seasonal Factors'!$E$4)),"") -> 1.0447874 | AD11: =IFERROR(AC11/AVERAGE(AC7:AC17),"") -> 1.0364543 | AG11: =IFERROR(AVERAGEIFS($AF$7:$AF$294,$B$7:$B$294,$B11,$A$7:$A$294,">="&EDATE($A11,-12*'Seasonal Factors'!$E$4),$A$7:$A$294,"<="&EDATE($A11,12*'Seasonal Factors'!$E$4)),"") -> 0.92077967 | AH11: =IFERROR(AG11/AVERAGE(AG7:AG17),"") -> 0.91991651 | AK11: =IFERROR(AVERAGEIFS($AJ$7:$AJ$294,$B$7:$B$294,$B11,$A$7:$A$294,">="&EDATE($A11,-12*'Seasonal Factors'!$E$4),$A$7:$A$294,"<="&EDATE($A11,12*'Seasonal Factors'!$E$4)),"") -> 1.0858807 | AL11: =IFERROR(AK11/AVERAGE(AK7:AK17),"") -> 1.0836358 | AO11: =IFERROR(AVERAGEIFS($AN$7:$AN$294,$B$7:$B$294,$B11,$A$7:$A$294,">="&EDATE($A11,-12*'Seasonal Factors'!$E$4),$A$7:$A$294,"<="&EDATE($A11,12*'Seasonal Factors'!$E$4)),"") -> 1.004411 | AP11: =IFERROR(AO11/AVERAGE(AO7:AO17),"") -> 1.004877 | AS11: =IFERROR(AVERAGEIFS($AR$7:$AR$294,$B$7:$B$294,$B11,$A$7:$A$294,">="&EDATE($A11,-12*'Seasonal Factors'!$E$4),$A$7:$A$294,"<="&EDATE($A11,12*'Seasonal Factors'!$E$4)),"") -> 1.0125759 | AT11: =IFERROR(AS11/AVERAGE(AS7:AS17),"") -> 1.0148549 | AW11: =IFERROR(AVERAGEIFS($AV$7:$AV$294,$B$7:$B$294,$B11,$A$7:$A$294,">="&EDATE($A11,-12*'Seasonal Factors'!$E$4),$A$7:$A$294,"<="&EDATE($A11,12*'Seasonal Factors'!$E$4)),"") -> 1.001495 | AX11: =IFERROR(AW11/AVERAGE(AW7:AW17),"") -> 1.002299 | BA11: =IFERROR(AVERAGEIFS($AZ$7:$AZ$294,$B$7:$B$294,$B11,$A$7:$A$294,">="&EDATE($A11,-12*'Seasonal Factors'!$E$4),$A$7:$A$294,"<="&EDATE($A11,12*'Seasonal Factors'!$E$4)),"") -> 1.0019443 | BB11: =IFERROR(BA11/AVERAGE(BA7:BA17),"") -> 1.0034055 | BE11: =IFERROR(AVERAGEIFS($BD$7:$BD$294,$B$7:$B$294,$B11,$A$7:$A$294,">="&EDATE($A11,-12*'Seasonal Factors'!$E$4),$A$7:$A$294,"<="&EDATE($A11,12*'Seasonal Factors'!$E$4)),"") -> 1.0389657 | BF11: =IFERROR(BE11/AVERAGE(BE7:BE17),"") -> 1.0334543 | BI11: =IFERROR(AVERAGEIFS($BH$7:$BH$294,$B$7:$B$294,$B11,$A$7:$A$294,">="&EDATE($A11,-12*'Seasonal Factors'!$E$4),$A$7:$A$294,"<="&EDATE($A11,12*'Seasonal Factors'!$E$4)),"") -> 1.0039624 | BJ11: =IFERROR(BI11/AVERAGE(BI7:BI17),"") -> 1.0013693
A12: 38168 | B12: =MONTH(A12) -> 6 | E12: =IFERROR(AVERAGEIFS($D$7:$D$294,$B$7:$B$294,$B12,$A$7:$A$294,">="&EDATE($A12,-12*'Seasonal Factors'!$E$4),$A$7:$A$294,"<="&EDATE($A12,12*'Seasonal Factors'!$E$4)),"") -> 1.6661829 | F12: =IFERROR(E12/AVERAGE(E7:E18),"") -> 1.6491461 | I12: =IFERROR(AVERAGEIFS($H$7:$H$294,$B$7:$B$294,$B12,$A$7:$A$294,">="&EDATE($A12,-12*'Seasonal Factors'!$E$4),$A$7:$A$294,"<="&EDATE($A12,12*'Seasonal Factors'!$E$4)),"") -> 1.3570439 | J12: =IFERROR(I12/AVERAGE(I7:I18),"") -> 1.351842 | M12: =IFERROR(AVERAGEIFS($L$7:$L$294,$B$7:$B$294,$B12,$A$7:$A$294,">="&EDATE($A12,-12*'Seasonal Factors'!$E$4),$A$7:$A$294,"<="&EDATE($A12,12*'Seasonal Factors'!$E$4)),"") -> 0.99536377 | N12: =IFERROR(M12/AVERAGE(M7:M18),"") -> 0.99570164 | Q12: =IFERROR(AVERAGEIFS($P$7:$P$294,$B$7:$B$294,$B12,$A$7:$A$294,">="&EDATE($A12,-12*'Seasonal Factors'!$E$4),$A$7:$A$294,"<="&EDATE($A12,12*'Seasonal Factors'!$E$4)),"") -> 0.99393891 | R12: =IFERROR(Q12/AVERAGE(Q7:Q18),"") -> 0.99136184 | U12: =IFERROR(AVERAGEIFS($T$7:$T$294,$B$7:$B$294,$B12,$A$7:$A$294,">="&EDATE($A12,-12*'Seasonal Factors'!$E$4),$A$7:$A$294,"<="&EDATE($A12,12*'Seasonal Factors'!$E$4)),"") -> 1.0348985 | V12: =IFERROR(U12/AVERAGE(U7:U18),"") -> 1.0344673 | Y12: =IFERROR(AVERAGEIFS($X$7:$X$294,$B$7:$B$294,$B12,$A$7:$A$294,">="&EDATE($A12,-12*'Seasonal Factors'!$E$4),$A$7:$A$294,"<="&EDATE($A12,12*'Seasonal Factors'!$E$4)),"") -> 0.98961986 | Z12: =IFERROR(Y12/AVERAGE(Y7:Y18),"") -> 0.98628167 | AC12: =IFERROR(AVERAGEIFS($AB$7:$AB$294,$B$7:$B$294,$B12,$A$7:$A$294,">="&EDATE($A12,-12*'Seasonal Factors'!$E$4),$A$7:$A$294,"<="&EDATE($A12,12*'Seasonal Factors'!$E$4)),"") -> 1.0128541 | AD12: =IFERROR(AC12/AVERAGE(AC7:AC18),"") -> 1.0105514 | AG12: =IFERROR(AVERAGEIFS($AF$7:$AF$294,$B$7:$B$294,$B12,$A$7:$A$294,">="&EDATE($A12,-12*'Seasonal Factors'!$E$4),$A$7:$A$294,"<="&EDATE($A12,12*'Seasonal Factors'!$E$4)),"") -> 0.90123594 | AH12: =IFERROR(AG12/AVERAGE(AG7:AG18),"") -> 0.90032369 | AK12: =IFERROR(AVERAGEIFS($AJ$7:$AJ$294,$B$7:$B$294,$B12,$A$7:$A$294,">="&EDATE($A12,-12*'Seasonal Factors'!$E$4),$A$7:$A$294,"<="&EDATE($A12,12*'Seasonal Factors'!$E$4)),"") -> 1.0249945 | AL12: =IFERROR(AK12/AVERAGE(AK7:AK18),"") -> 1.0239421 | AO12: =IFERROR(AVERAGEIFS($AN$7:$AN$294,$B$7:$B$294,$B12,$A$7:$A$294,">="&EDATE($A12,-12*'Seasonal Factors'!$E$4),$A$7:$A$294,"<="&EDATE($A12,12*'Seasonal Factors'!$E$4)),"") -> 1.008062 | AP12: =IFERROR(AO12/AVERAGE(AO7:AO18),"") -> 1.0070507 | AS12: =IFERROR(AVERAGEIFS($AR$7:$AR$294,$B$7:$B$294,$B12,$A$7:$A$294,">="&EDATE($A12,-12*'Seasonal Factors'!$E$4),$A$7:$A$294,"<="&EDATE($A12,12*'Seasonal Factors'!$E$4)),"") -> 1.0184399 | AT12: =IFERROR(AS12/AVERAGE(AS7:AS18),"") -> 1.0174386 | AW12: =IFERROR(AVERAGEIFS($AV$7:$AV$294,$B$7:$B$294,$B12,$A$7:$A$294,">="&EDATE($A12,-12*'Seasonal Factors'!$E$4),$A$7:$A$294,"<="&EDATE($A12,12*'Seasonal Factors'!$E$4)),"") -> 1.0120421 | AX12: =IFERROR(AW12/AVERAGE(AW7:AW18),"") -> 1.0115858 | BA12: =IFERROR(AVERAGEIFS($AZ$7:$AZ$294,$B$7:$B$294,$B12,$A$7:$A$294,">="&EDATE($A12,-12*'Seasonal Factors'!$E$4),$A$7:$A$294,"<="&EDATE($A12,12*'Seasonal Factors'!$E$4)),"") -> 1.0250141 | BB12: =IFERROR(BA12/AVERAGE(BA7:BA18),"") -> 1.0246728 | BE12: =IFERROR(AVERAGEIFS($BD$7:$BD$294,$B$7:$B$294,$B12,$A$7:$A$294,">="&EDATE($A12,-12*'Seasonal Factors'!$E$4),$A$7:$A$294,"<="&EDATE($A12,12*'Seasonal Factors'!$E$4)),"") -> 1.0689872 | BF12: =IFERROR(BE12/AVERAGE(BE7:BE18),"") -> 1.0692322 | BI12: =IFERROR(AVERAGEIFS($BH$7:$BH$294,$B$7:$B$294,$B12,$A$7:$A$294,">="&EDATE($A12,-12*'Seasonal Factors'!$E$4),$A$7:$A$294,"<="&EDATE($A12,12*'Seasonal Factors'!$E$4)),"") -> 1.0044053 | BJ12: =IFERROR(BI12/AVERAGE(BI7:BI18),"") -> 1.0034798
A13: 38199 | B13: =MONTH(A13) -> 7 | C13: =IF(ISNUMBER(Tabelle1!E20),(0.5*Tabelle1!E8+SUM(Tabelle1!E9:E19)+0.5*Tabelle1!E20)/12,"") -> 99.987505 | D13: =IFERROR(Tabelle1!E14/C13,"") -> 0.94874315 | E13: =IFERROR(AVERAGEIFS($D$7:$D$294,$B$7:$B$294,$B13,$A$7:$A$294,">="&EDATE($A13,-12*'Seasonal Factors'!$E$4),$A$7:$A$294,"<="&EDATE($A13,12*'Seasonal Factors'!$E$4)),"") -> 0.88062469 | F13: =IFERROR(E13/AVERAGE(E8:E19),"") -> 0.87075378 | G13: =IF(ISNUMBER(Tabelle1!F20),(0.5*Tabelle1!F8+SUM(Tabelle1!F9:F19)+0.5*Tabelle1!F20)/12,"") -> 99.72049 | H13: =IFERROR(Tabelle1!F14/G13,"") -> 0.77620296 | I13: =IFERROR(AVERAGEIFS($H$7:$H$294,$B$7:$B$294,$B13,$A$7:$A$294,">="&EDATE($A13,-12*'Seasonal Factors'!$E$4),$A$7:$A$294,"<="&EDATE($A13,12*'Seasonal Factors'!$E$4)),"") -> 1.0094883 | J13: =IFERROR(I13/AVERAGE(I8:I19),"") -> 1.0059012 | K13: =IF(ISNUMBER(Tabelle1!G20),(0.5*Tabelle1!G8+SUM(Tabelle1!G9:G19)+0.5*Tabelle1!G20)/12,"") -> 100.02053 | L13: =IFERROR(Tabelle1!G14/K13,"") -> 1.0078105 | M13: =IFERROR(AVERAGEIFS($L$7:$L$294,$B$7:$B$294,$B13,$A$7:$A$294,">="&EDATE($A13,-12*'Seasonal Factors'!$E$4),$A$7:$A$294,"<="&EDATE($A13,12*'Seasonal Factors'!$E$4)),"") -> 1.0205251 | N13: =IFERROR(M13/AVERAGE(M8:M19),"") -> 1.0206765 | O13: =IF(ISNUMBER(Tabelle1!H20),(0.5*Tabelle1!H8+SUM(Tabelle1!H9:H19)+0.5*Tabelle1!H20)/12,"") -> 100.24349 | P13: =IFERROR(Tabelle1!H14/O13,"") -> 1.0225954 | Q13: =IFERROR(AVERAGEIFS($P$7:$P$294,$B$7:$B$294,$B13,$A$7:$A$294,">="&EDATE($A13,-12*'Seasonal Factors'!$E$4),$A$7:$A$294,"<="&EDATE($A13,12*'Seasonal Factors'!$E$4)),"") -> 1.015504 | R13: =IFERROR(Q13/AVERAGE(Q8:Q19),"") -> 1.0140626 | S13: =IF(ISNUMBER(Tabelle1!I20),(0.5*Tabelle1!I8+SUM(Tabelle1!I9:I19)+0.5*Tabelle1!I20)/12,"") -> 100.38109 | T13: =IFERROR(Tabelle1!I14/S13,"") -> 1.0501633 | U13: =IFERROR(AVERAGEIFS($T$7:$T$294,$B$7:$B$294,$B13,$A$7:$A$294,">="&EDATE($A13,-12*'Seasonal Factors'!$E$4),$A$7:$A$294,"<="&EDATE($A13,12*'Seasonal Factors'!$E$4)),"") -> 1.0406992 | V13: =IFERROR(U13/AVERAGE(U8:U19),"") -> 1.0404922 | W13: =IF(ISNUMBER(Tabelle1!J20),(0.5*Tabelle1!J8+SUM(Tabelle1!J9:J19)+0.5*Tabelle1!J20)/12,"") -> 100.39079 | X13: =IFERROR(Tabelle1!J14/W13,"") -> 0.98520988 | Y13: =IFERROR(AVERAGEIFS($X$7:$X$294,$B$7:$B$294,$B13,$A$7:$A$294,">="&EDATE($A13,-12*'Seasonal Factors'!$E$4),$A$7:$A$294,"<="&EDATE($A13,12*'Seasonal Factors'!$E$4)),"") -> 1.0020583 | Z13: =IFERROR(Y13/AVERAGE(Y8:Y19),"") -> 0.9996508 | AA13: =IF(ISNUMBER(Tabelle1!K20),(0.5*Tabelle1!K8+SUM(Tabelle1!K9:K19)+0.5*Tabelle1!K20)/12,"") -> 100.31609 | AB13: =IFERROR(Tabelle1!K14/AA13,"") -> 1.0050952 | AC13: =IFERROR(AVERAGEIFS($AB$7:$AB$294,$B$7:$B$294,$B13,$A$7:$A$294,">="&EDATE($A13,-12*'Seasonal Factors'!$E$4),$A$7:$A$294,"<="&EDATE($A13,12*'Seasonal Factors'!$E$4)),"") -> 1.0102246 | AD13: =IFERROR(AC13/AVERAGE(AC8:AC19),"") -> 1.0087873 | AE13: =IF(ISNUMBER(Tabelle1!L20),(0.5*Tabelle1!L8+SUM(Tabelle1!L9:L19)+0.5*Tabelle1!L20)/12,"") -> 100.41925 | AF13: =IFERROR(Tabelle1!L14/AE13,"") -> 0.98637577 | AG13: =IFERROR(AVERAGEIFS($AF$7:$AF$294,$B$7:$B$294,$B13,$A$7:$A$294,">="&EDATE($A13,-12*'Seasonal Factors'!$E$4),$A$7:$A$294,"<="&EDATE($A13,12*'Seasonal Factors'!$E$4)),"") -> 0.99826455 | AH13: =IFERROR(AG13/AVERAGE(AG8:AG19),"") -> 0.99787215 | AI13: =IF(ISNUMBER(Tabelle1!M20),(0.5*Tabelle1!M8+SUM(Tabelle1!M9:M19)+0.5*Tabelle1!M20)/12,"") -> 100.48959 | AJ13: =IFERROR(Tabelle1!M14/AI13,"") -> 0.99343818 | AK13: =IFERROR(AVERAGEIFS($AJ$7:$AJ$294,$B$7:$B$294,$B13,$A$7:$A$294,">="&EDATE($A13,-12*'Seasonal Factors'!$E$4),$A$7:$A$294,"<="&EDATE($A13,12*'Seasonal Factors'!$E$4)),"") -> 1.0064539 | AL13: =IFERROR(AK13/AVERAGE(AK8:AK19),"") -> 1.0058714 | AM13: =IF(ISNUMBER(Tabelle1!N20),(0.5*Tabelle1!N8+SUM(Tabelle1!N9:N19)+0.5*Tabelle1!N20)/12,"") -> 100.04978 | AN13: =IFERROR(Tabelle1!N14/AM13,"") -> 0.98970245 | AO13: =IFERROR(AVERAGEIFS($AN$7:$AN$294,$B$7:$B$294,$B13,$A$7:$A$294,">="&EDATE($A13,-12*'Seasonal Factors'!$E$4),$A$7:$A$294,"<="&EDATE($A13,12*'Seasonal Factors'!$E$4)),"") -> 0.99485597 | AP13: =IFERROR(AO13/AVERAGE(AO8:AO19),"") -> 0.99421867 | AQ13: =IF(ISNUMBER(Tabelle1!O20),(0.5*Tabelle1!O8+SUM(Tabelle1!O9:O19)+0.5*Tabelle1!O20)/12,"") -> 100.18704 | AR13: =IFERROR(Tabelle1!O14/AQ13,"") -> 1.006713 | AS13: =IFERROR(AVERAGEIFS($AR$7:$AR$294,$B$7:$B$294,$B13,$A$7:$A$294,">="&EDATE($A13,-12*'Seasonal Factors'!$E$4),$A$7:$A$294,"<="&EDATE($A13,12*'Seasonal Factors'!$E$4)),"") -> 1.0075128 | AT13: =IFERROR(AS13/AVERAGE(AS8:AS19),"") -> 1.0065622 | AU13: =IF(ISNUMBER(Tabelle1!P20),(0.5*Tabelle1!P8+SUM(Tabelle1!P9:P19)+0.5*Tabelle1!P20)/12,"") -> 100.2139 | AV13: =IFERROR(Tabelle1!P14/AU13,"") -> 0.99951396 | AW13: =IFERROR(AVERAGEIFS($AV$7:$AV$294,$B$7:$B$294,$B13,$A$7:$A$294,">="&EDATE($A13,-12*'Seasonal Factors'!$E$4),$A$7:$A$294,"<="&EDATE($A13,12*'Seasonal Factors'!$E$4)),"") -> 1.0000207 | AX13: =IFERROR(AW13/AVERAGE(AW8:AW19),"") -> 0.99969297 | AY13: =IF(ISNUMBER(Tabelle1!Q20),(0.5*Tabelle1!Q8+SUM(Tabelle1!Q9:Q19)+0.5*Tabelle1!Q20)/12,"") -> 100.24358 | AZ13: =IFERROR(Tabelle1!Q14/AY13,"") -> 1.0025589 | BA13: =IFERROR(AVERAGEIFS($AZ$7:$AZ$294,$B$7:$B$294,$B13,$A$7:$A$294,">="&EDATE($A13,-12*'Seasonal Factors'!$E$4),$A$7:$A$294,"<="&EDATE($A13,12*'Seasonal Factors'!$E$4)),"") -> 1.0051647 | BB13: =IFERROR(BA13/AVERAGE(BA8:BA19),"") -> 1.0047149 | BC13: =IF(ISNUMBER(Tabelle1!R20),(0.5*Tabelle1!R8+SUM(Tabelle1!R9:R19)+0.5*Tabelle1!R20)/12,"") -> 100.39896 | BD13: =IFERROR(Tabelle1!R14/BC13,"") -> 1.0143927 | BE13: =IFERROR(AVERAGEIFS($BD$7:$BD$294,$B$7:$B$294,$B13,$A$7:$A$294,">="&EDATE($A13,-12*'Seasonal Factors'!$E$4),$A$7:$A$294,"<="&EDATE($A13,12*'Seasonal Factors'!$E$4)),"") -> 1.0097814 | BF13: =IFERROR(BE13/AVERAGE(BE8:BE19),"") -> 1.009743 | BG13: =IF(ISNUMBER(Tabelle1!S20),(0.5*Tabelle1!S8+SUM(Tabelle1!S9:S19)+0.5*Tabelle1!S20)/12,"") -> 100.40304 | BH13: =IFERROR(Tabelle1!S14/BG13,"") -> 1.0829364 | BI13: =IFERROR(AVERAGEIFS($BH$7:$BH$294,$B$7:$B$294,$B13,$A$7:$A$294,">="&EDATE($A13,-12*'Seasonal Factors'!$E$4),$A$7:$A$294,"<="&EDATE($A13,12*'Seasonal Factors'!$E$4)),"") -> 1.1004231 | BJ13: =IFERROR(BI13/AVERAGE(BI8:BI19),"") -> 1.0997816
A14: 38230 | B14: =MONTH(A14) -> 8 | C14: =IF(ISNUMBER(Tabelle1!E21),(0.5*Tabelle1!E9+SUM(Tabelle1!E10:E20)+0.5*Tabelle1!E21)/12,"") -> 100.15347 | D14: =IFERROR(Tabelle1!E15/C14,"") -> 0.64761767 | E14: =IFERROR(AVERAGEIFS($D$7:$D$294,$B$7:$B$294,$B14,$A$7:$A$294,">="&EDATE($A14,-12*'Seasonal Factors'!$E$4),$A$7:$A$294,"<="&EDATE($A14,12*'Seasonal Factors'!$E$4)),"") -> 0.58195165 | F14: =IFERROR(E14/AVERAGE(E9:E20),"") -> 0.5744149 | G14: =IF(ISNUMBER(Tabelle1!F21),(0.5*Tabelle1!F9+SUM(Tabelle1!F10:F20)+0.5*Tabelle1!F21)/12,"") -> 100.54597 | H14: =IFERROR(Tabelle1!F15/G14,"") -> 0.98759685 | I14: =IFERROR(AVERAGEIFS($H$7:$H$294,$B$7:$B$294,$B14,$A$7:$A$294,">="&EDATE($A14,-12*'Seasonal Factors'!$E$4),$A$7:$A$294,"<="&EDATE($A14,12*'Seasonal Factors'!$E$4)),"") -> 0.95336216 | J14: =IFERROR(I14/AVERAGE(I9:I20),"") -> 0.95391366 | K14: =IF(ISNUMBER(Tabelle1!G21),(0.5*Tabelle1!G9+SUM(Tabelle1!G10:G20)+0.5*Tabelle1!G21)/12,"") -> 99.949785 | L14: =IFERROR(Tabelle1!G15/K14,"") -> 1.0232489 | M14: =IFERROR(AVERAGEIFS($L$7:$L$294,$B$7:$B$294,$B14,$A$7:$A$294,">="&EDATE($A14,-12*'Seasonal Factors'!$E$4),$A$7:$A$294,"<="&EDATE($A14,12*'Seasonal Factors'!$E$4)),"") -> 1.0269412 | N14: =IFERROR(M14/AVERAGE(M9:M20),"") -> 1.0267912 | O14: =IF(ISNUMBER(Tabelle1!H21),(0.5*Tabelle1!H9+SUM(Tabelle1!H10:H20)+0.5*Tabelle1!H21)/12,"") -> 100.7071 | P14: =IFERROR(Tabelle1!H15/O14,"") -> 1.003017 | Q14: =IFERROR(AVERAGEIFS($P$7:$P$294,$B$7:$B$294,$B14,$A$7:$A$294,">="&EDATE($A14,-12*'Seasonal Factors'!$E$4),$A$7:$A$294,"<="&EDATE($A14,12*'Seasonal Factors'!$E$4)),"") -> 1.0180946 | R14: =IFERROR(Q14/AVERAGE(Q9:Q20),"") -> 1.0176384 | S14: =IF(ISNUMBER(Tabelle1!I21),(0.5*Tabelle1!I9+SUM(Tabelle1!I10:I20)+0.5*Tabelle1!I21)/12,"") -> 101.02465 | T14: =IFERROR(Tabelle1!I15/S14,"") -> 1.0292321 | U14: =IFERROR(AVERAGEIFS($T$7:$T$294,$B$7:$B$294,$B14,$A$7:$A$294,">="&EDATE($A14,-12*'Seasonal Factors'!$E$4),$A$7:$A$294,"<="&EDATE($A14,12*'Seasonal Factors'!$E$4)),"") -> 1.0401114 | V14: =IFERROR(U14/AVERAGE(U9:U20),"") -> 1.0405504 | W14: =IF(ISNUMBER(Tabelle1!J21),(0.5*Tabelle1!J9+SUM(Tabelle1!J10:J20)+0.5*Tabelle1!J21)/12,"") -> 101.20497 | X14: =IFERROR(Tabelle1!J15/W14,"") -> 1.0081798 | Y14: =IFERROR(AVERAGEIFS($X$7:$X$294,$B$7:$B$294,$B14,$A$7:$A$294,">="&EDATE($A14,-12*'Seasonal Factors'!$E$4),$A$7:$A$294,"<="&EDATE($A14,12*'Seasonal Factors'!$E$4)),"") -> 1.0130115 | Z14: =IFERROR(Y14/AVERAGE(Y9:Y20),"") -> 1.0115484 | AA14: =IF(ISNUMBER(Tabelle1!K21),(0.5*Tabelle1!K9+SUM(Tabelle1!K10:K20)+0.5*Tabelle1!K21)/12,"") -> 100.9768 | AB14: =IFERROR(Tabelle1!K15/AA14,"") -> 0.9858935 | AC14: =IFERROR(AVERAGEIFS($AB$7:$AB$294,$B$7:$B$294,$B14,$A$7:$A$294,">="&EDATE($A14,-12*'Seasonal Factors'!$E$4),$A$7:$A$294,"<="&EDATE($A14,12*'Seasonal Factors'!$E$4)),"") -> 1.0062589 | AD14: =IFERROR(AC14/AVERAGE(AC9:AC20),"") -> 1.005631 | AE14: =IF(ISNUMBER(Tabelle1!L21),(0.5*Tabelle1!L9+SUM(Tabelle1!L10:L20)+0.5*Tabelle1!L21)/12,"") -> 101.22427 | AF14: =IFERROR(Tabelle1!L15/AE14,"") -> 0.96983162 | AG14: =IFERROR(AVERAGEIFS($AF$7:$AF$294,$B$7:$B$294,$B14,$A$7:$A$294,">="&EDATE($A14,-12*'Seasonal Factors'!$E$4),$A$7:$A$294,"<="&EDATE($A14,12*'Seasonal Factors'!$E$4)),"") -> 0.99136388 | AH14: =IFERROR(AG14/AVERAGE(AG9:AG20),"") -> 0.99143347 | AI14: =IF(ISNUMBER(Tabelle1!M21),(0.5*Tabelle1!M9+SUM(Tabelle1!M10:M20)+0.5*Tabelle1!M21)/12,"") -> 101.44893 | AJ14: =IFERROR(Tabelle1!M15/AI14,"") -> 0.97806553 | AK14: =IFERROR(AVERAGEIFS($AJ$7:$AJ$294,$B$7:$B$294,$B14,$A$7:$A$294,">="&EDATE($A14,-12*'Seasonal Factors'!$E$4),$A$7:$A$294,"<="&EDATE($A14,12*'Seasonal Factors'!$E$4)),"") -> 0.99282457 | AL14: =IFERROR(AK14/AVERAGE(AK9:AK20),"") -> 0.99230491 | AM14: =IF(ISNUMBER(Tabelle1!N21),(0.5*Tabelle1!N9+SUM(Tabelle1!N10:N20)+0.5*Tabelle1!N21)/12,"") -> 100.33379 | AN14: =IFERROR(Tabelle1!N15/AM14,"") -> 1.008437 | AO14: =IFERROR(AVERAGEIFS($AN$7:$AN$294,$B$7:$B$294,$B14,$A$7:$A$294,">="&EDATE($A14,-12*'Seasonal Factors'!$E$4),$A$7:$A$294,"<="&EDATE($A14,12*'Seasonal Factors'!$E$4)),"") -> 1.0080782 | AP14: =IFERROR(AO14/AVERAGE(AO9:AO20),"") -> 1.0076492 | AQ14: =IF(ISNUMBER(Tabelle1!O21),(0.5*Tabelle1!O9+SUM(Tabelle1!O10:O20)+0.5*Tabelle1!O21)/12,"") -> 100.56177 | AR14: =IFERROR(Tabelle1!O15/AQ14,"") -> 1.0100705 | AS14: =IFERROR(AVERAGEIFS($AR$7:$AR$294,$B$7:$B$294,$B14,$A$7:$A$294,">="&EDATE($A14,-12*'Seasonal Factors'!$E$4),$A$7:$A$294,"<="&EDATE($A14,12*'Seasonal Factors'!$E$4)),"") -> 1.009145 | AT14: =IFERROR(AS14/AVERAGE(AS9:AS20),"") -> 1.008314 | AU14: =IF(ISNUMBER(Tabelle1!P21),(0.5*Tabelle1!P9+SUM(Tabelle1!P10:P20)+0.5*Tabelle1!P21)/12,"") -> 100.63895 | AV14: =IFERROR(Tabelle1!P15/AU14,"") -> 1.0003705 | AW14: =IFERROR(AVERAGEIFS($AV$7:$AV$294,$B$7:$B$294,$B14,$A$7:$A$294,">="&EDATE($A14,-12*'Seasonal Factors'!$E$4),$A$7:$A$294,"<="&EDATE($A14,12*'Seasonal Factors'!$E$4)),"") -> 1.0013309 | AX14: =IFERROR(AW14/AVERAGE(AW9:AW20),"") -> 1.0010332 | AY14: =IF(ISNUMBER(Tabelle1!Q21),(0.5*Tabelle1!Q9+SUM(Tabelle1!Q10:Q20)+0.5*Tabelle1!Q21)/12,"") -> 100.73548 | AZ14: =IFERROR(Tabelle1!Q15/AY14,"") -> 1.0065287 | BA14: =IFERROR(AVERAGEIFS($AZ$7:$AZ$294,$B$7:$B$294,$B14,$A$7:$A$294,">="&EDATE($A14,-12*'Seasonal Factors'!$E$4),$A$7:$A$294,"<="&EDATE($A14,12*'Seasonal Factors'!$E$4)),"") -> 1.006703 | BB14: =IFERROR(BA14/AVERAGE(BA9:BA20),"") -> 1.0062965 | BC14: =IF(ISNUMBER(Tabelle1!R21),(0.5*Tabelle1!R9+SUM(Tabelle1!R10:R20)+0.5*Tabelle1!R21)/12,"") -> 101.19695 | BD14: =IFERROR(Tabelle1!R15/BC14,"") -> 1.0325722 | BE14: =IFERROR(AVERAGEIFS($BD$7:$BD$294,$B$7:$B$294,$B14,$A$7:$A$294,">="&EDATE($A14,-12*'Seasonal Factors'!$E$4),$A$7:$A$294,"<="&EDATE($A14,12*'Seasonal Factors'!$E$4)),"") -> 1.0396926 | BF14: =IFERROR(BE14/AVERAGE(BE9:BE20),"") -> 1.0397487 | BG14: =IF(ISNUMBER(Tabelle1!S21),(0.5*Tabelle1!S9+SUM(Tabelle1!S10:S20)+0.5*Tabelle1!S21)/12,"") -> 101.16524 | BH14: =IFERROR(Tabelle1!S15/BG14,"") -> 0.99299738 | BI14: =IFERROR(AVERAGEIFS($BH$7:$BH$294,$B$7:$B$294,$B14,$A$7:$A$294,">="&EDATE($A14,-12*'Seasonal Factors'!$E$4),$A$7:$A$294,"<="&EDATE($A14,12*'Seasonal Factors'!$E$4)),"") -> 1.0197751 | BJ14: =IFERROR(BI14/AVERAGE(BI9:BI20),"") -> 1.019261
A15: 38260 | B15: =MONTH(A15) -> 9 | C15: =IF(ISNUMBER(Tabelle1!E22),(0.5*Tabelle1!E10+SUM(Tabelle1!E11:E21)+0.5*Tabelle1!E22)/12,"") -> 101.49432 | D15: =IFERROR(Tabelle1!E16/C15,"") -> 0.59855471 | E15: =IFERROR(AVERAGEIFS($D$7:$D$294,$B$7:$B$294,$B15,$A$7:$A$294,">="&EDATE($A15,-12*'Seasonal Factors'!$E$4),$A$7:$A$294,"<="&EDATE($A15,12*'Seasonal Factors'!$E$4)),"") -> 0.54327249 | F15: =IFERROR(E15/AVERAGE(E10:E21),"") -> 0.53577022 | G15: =IF(ISNUMBER(Tabelle1!F22),(0.5*Tabelle1!F10+SUM(Tabelle1!F11:F21)+0.5*Tabelle1!F22)/12,"") -> 100.50938 | H15: =IFERROR(Tabelle1!F16/G15,"") -> 0.67812753 | I15: =IFERROR(AVERAGEIFS($H$7:$H$294,$B$7:$B$294,$B15,$A$7:$A$294,">="&EDATE($A15,-12*'Seasonal Factors'!$E$4),$A$7:$A$294,"<="&EDATE($A15,12*'Seasonal Factors'!$E$4)),"") -> 0.61424877 | J15: =IFERROR(I15/AVERAGE(I10:I21),"") -> 0.61805241 | K15: =IF(ISNUMBER(Tabelle1!G22),(0.5*Tabelle1!G10+SUM(Tabelle1!G11:G21)+0.5*Tabelle1!G22)/12,"") -> 99.914345 | L15: =IFERROR(Tabelle1!G16/K15,"") -> 1.0067031 | M15: =IFERROR(AVERAGEIFS($L$7:$L$294,$B$7:$B$294,$B15,$A$7:$A$294,">="&EDATE($A15,-12*'Seasonal Factors'!$E$4),$A$7:$A$294,"<="&EDATE($A15,12*'Seasonal Factors'!$E$4)),"") -> 1.0035929 | N15: =IFERROR(M15/AVERAGE(M10:M21),"") -> 1.0030391 | O15: =IF(ISNUMBER(Tabelle1!H22),(0.5*Tabelle1!H10+SUM(Tabelle1!H11:H21)+0.5*Tabelle1!H22)/12,"") -> 101.1832 | P15: =IFERROR(Tabelle1!H16/O15,"") -> 1.0136339 | Q15: =IFERROR(AVERAGEIFS($P$7:$P$294,$B$7:$B$294,$B15,$A$7:$A$294,">="&EDATE($A15,-12*'Seasonal Factors'!$E$4),$A$7:$A$294,"<="&EDATE($A15,12*'Seasonal Factors'!$E$4)),"") -> 1.0297992 | R15: =IFERROR(Q15/AVERAGE(Q10:Q21),"") -> 1.0302029 | S15: =IF(ISNUMBER(Tabelle1!I22),(0.5*Tabelle1!I10+SUM(Tabelle1!I11:I21)+0.5*Tabelle1!I22)/12,"") -> 101.45955 | T15: =IFERROR(Tabelle1!I16/S15,"") -> 0.9625148 | U15: =IFERROR(AVERAGEIFS($T$7:$T$294,$B$7:$B$294,$B15,$A$7:$A$294,">="&EDATE($A15,-12*'Seasonal Factors'!$E$4),$A$7:$A$294,"<="&EDATE($A15,12*'Seasonal Factors'!$E$4)),"") -> 0.97555714 | V15: =IFERROR(U15/AVERAGE(U10:U21),"") -> 0.97568071 | W15: =IF(ISNUMBER(Tabelle1!J22),(0.5*Tabelle1!J10+SUM(Tabelle1!J11:J21)+0.5*Tabelle1!J22)/12,"") -> 102.09113 | X15: =IFERROR(Tabelle1!J16/W15,"") -> 1.0462724 | Y15: =IFERROR(AVERAGEIFS($X$7:$X$294,$B$7:$B$294,$B15,$A$7:$A$294,">="&EDATE($A15,-12*'Seasonal Factors'!$E$4),$A$7:$A$294,"<="&EDATE($A15,12*'Seasonal Factors'!$E$4)),"") -> 1.0329722 | Z15: =IFERROR(Y15/AVERAGE(Y10:Y21),"") -> 1.0325504 | AA15: =IF(ISNUMBER(Tabelle1!K22),(0.5*Tabelle1!K10+SUM(Tabelle1!K11:K21)+0.5*Tabelle1!K22)/12,"") -> 101.70465 | AB15: =IFERROR(Tabelle1!K16/AA15,"") -> 0.98284908 | AC15: =IFERROR(AVERAGEIFS($AB$7:$AB$294,$B$7:$B$294,$B15,$A$7:$A$294,">="&EDATE($A15,-12*'Seasonal Factors'!$E$4),$A$7:$A$294,"<="&EDATE($A15,12*'Seasonal Factors'!$E$4)),"") -> 1.0030128 | AD15: =IFERROR(AC15/AVERAGE(AC10:AC21),"") -> 1.0030307 | AE15: =IF(ISNUMBER(Tabelle1!L22),(0.5*Tabelle1!L10+SUM(Tabelle1!L11:L21)+0.5*Tabelle1!L22)/12,"") -> 102.01444 | AF15: =IFERROR(Tabelle1!L16/AE15,"") -> 0.9807538 | AG15: =IFERROR(AVERAGEIFS($AF$7:$AF$294,$B$7:$B$294,$B15,$A$7:$A$294,">="&EDATE($A15,-12*'Seasonal Factors'!$E$4),$A$7:$A$294,"<="&EDATE($A15,12*'Seasonal Factors'!$E$4)),"") -> 0.99542832 | AH15: =IFERROR(AG15/AVERAGE(AG10:AG21),"") -> 0.99623044 | AI15: =IF(ISNUMBER(Tabelle1!M22),(0.5*Tabelle1!M10+SUM(Tabelle1!M11:M21)+0.5*Tabelle1!M22)/12,"") -> 102.50241 | AJ15: =IFERROR(Tabelle1!M16/AI15,"") -> 0.96476898 | AK15: =IFERROR(AVERAGEIFS($AJ$7:$AJ$294,$B$7:$B$294,$B15,$A$7:$A$294,">="&EDATE($A15,-12*'Seasonal Factors'!$E$4),$A$7:$A$294,"<="&EDATE($A15,12*'Seasonal Factors'!$E$4)),"") -> 0.97815191 | AL15: =IFERROR(AK15/AVERAGE(AK10:AK21),"") -> 0.97774128 | AM15: =IF(ISNUMBER(Tabelle1!N22),(0.5*Tabelle1!N10+SUM(Tabelle1!N11:N21)+0.5*Tabelle1!N22)/12,"") -> 100.89563 | AN15: =IFERROR(Tabelle1!N16/AM15,"") -> 0.99913676 | AO15: =IFERROR(AVERAGEIFS($AN$7:$AN$294,$B$7:$B$294,$B15,$A$7:$A$294,">="&EDATE($A15,-12*'Seasonal Factors'!$E$4),$A$7:$A$294,"<="&EDATE($A15,12*'Seasonal Factors'!$E$4)),"") -> 0.98607158 | AP15: =IFERROR(AO15/AVERAGE(AO10:AO21),"") -> 0.98564667 | AQ15: =IF(ISNUMBER(Tabelle1!O22),(0.5*Tabelle1!O10+SUM(Tabelle1!O11:O21)+0.5*Tabelle1!O22)/12,"") -> 100.88825 | AR15: =IFERROR(Tabelle1!O16/AQ15,"") -> 1.0209746 | AS15: =IFERROR(AVERAGEIFS($AR$7:$AR$294,$B$7:$B$294,$B15,$A$7:$A$294,">="&EDATE($A15,-12*'Seasonal Factors'!$E$4),$A$7:$A$294,"<="&EDATE($A15,12*'Seasonal Factors'!$E$4)),"") -> 1.0129625 | AT15: =IFERROR(AS15/AVERAGE(AS10:AS21),"") -> 1.0122392 | AU15: =IF(ISNUMBER(Tabelle1!P22),(0.5*Tabelle1!P10+SUM(Tabelle1!P11:P21)+0.5*Tabelle1!P22)/12,"") -> 101.09291 | AV15: =IFERROR(Tabelle1!P16/AU15,"") -> 1.0042899 | AW15: =IFERROR(AVERAGEIFS($AV$7:$AV$294,$B$7:$B$294,$B15,$A$7:$A$294,">="&EDATE($A15,-12*'Seasonal Factors'!$E$4),$A$7:$A$294,"<="&EDATE($A15,12*'Seasonal Factors'!$E$4)),"") -> 1.0042915 | AX15: =IFERROR(AW15/AVERAGE(AW10:AW21),"") -> 1.0040053 | AY15: =IF(ISNUMBER(Tabelle1!Q22),(0.5*Tabelle1!Q10+SUM(Tabelle1!Q11:Q21)+0.5*Tabelle1!Q22)/12,"") -> 101.29736 | AZ15: =IFERROR(Tabelle1!Q16/AY15,"") -> 1.0049944 | BA15: =IFERROR(AVERAGEIFS($AZ$7:$AZ$294,$B$7:$B$294,$B15,$A$7:$A$294,">="&EDATE($A15,-12*'Seasonal Factors'!$E$4),$A$7:$A$294,"<="&EDATE($A15,12*'Seasonal Factors'!$E$4)),"") -> 1.0088855 | BB15: =IFERROR(BA15/AVERAGE(BA10:BA21),"") -> 1.0085877 | BC15: =IF(ISNUMBER(Tabelle1!R22),(0.5*Tabelle1!R10+SUM(Tabelle1!R11:R21)+0.5*Tabelle1!R22)/12,"") -> 102.11446 | BD15: =IFERROR(Tabelle1!R16/BC15,"") -> 1.0253194 | BE15: =IFERROR(AVERAGEIFS($BD$7:$BD$294,$B$7:$B$294,$B15,$A$7:$A$294,">="&EDATE($A15,-12*'Seasonal Factors'!$E$4),$A$7:$A$294,"<="&EDATE($A15,12*'Seasonal Factors'!$E$4)),"") -> 1.0183128 | BF15: =IFERROR(BE15/AVERAGE(BE10:BE21),"") -> 1.0185622 | BG15: =IF(ISNUMBER(Tabelle1!S22),(0.5*Tabelle1!S10+SUM(Tabelle1!S11:S21)+0.5*Tabelle1!S22)/12,"") -> 101.88021 | BH15: =IFERROR(Tabelle1!S16/BG15,"") -> 0.98080404 | BI15: =IFERROR(AVERAGEIFS($BH$7:$BH$294,$B$7:$B$294,$B15,$A$7:$A$294,">="&EDATE($A15,-12*'Seasonal Factors'!$E$4),$A$7:$A$294,"<="&EDATE($A15,12*'Seasonal Factors'!$E$4)),"") -> 0.97730266 | BJ15: =IFERROR(BI15/AVERAGE(BI10:BI21),"") -> 0.9772039
