Workbook

Sheet Read me
C2: Argentina — chart pack
C3: UBS sovereign research. CPI data through 2026-06 (INDEC). Built Aug-2026.
B5: STATUS
B6: Live now | C6: Charts 1, 3, 4 and 7 are fully populated and recalculate end-to-end. CPI runs through 2026-06, GDP through 2026-Q1, fiscal through 2026-05, and the regulated decomposition through 2026-04. Nothing to do on these.
B7: Still needs data | C7: Charts 2, 5 and 6 are fully built — every transformation, chart, axis and format is wired — but the underlying series were not in the files supplied. Chart 2 needs EMAE manufacturing and mining sub-indices plus registered jobs by sector; chart 5 needs the BCRA REM; chart 6 needs monthly ICA trade with the energy split. Paste into the yellow columns and the charts populate. The Sources tab gives the exact identifier for each.
B9: THE SEVEN CHARTS
B10: 1. GDP contributions | C10: Stacked bars: contribution to y/y real GDP growth, pp, by demand component (private consumption, government consumption, GFCF, inventories+discrepancy, exports, imports) with headline GDP growth as a line. From 1Q-2023.
B11: 2. Industry vs mining | C11: Manufacturing and industrial activity against oil and mining, plus registered jobs in each — the point being that mining/oil job creation does not offset manufacturing job losses.
B12: 3. Regulated prices | C12: Shows the regulated-price catch-up is largely done: regulated prices are up 405% since Dec-2023 against 216% for core, a 60% relative-price gain, and the monthly wedge over core has compressed toward zero.
B13: 4. Monthly CPI | C13: Headline and core m/m in bars with the 2% monthly threshold as a line, and a panel explaining why 2% is the number that matters.
B14: 5. Inflation expectations | C14: BCRA REM expectations at the 12-month and 24-month horizon.
B15: 6. Trade balance | C15: 12-month rolling goods balance in bars, with the energy and non-energy balances as lines, ten years.
B16: 7. Fiscal | C16: 12-month rolling primary and overall balance of the national public sector, % of GDP, with markers on the government's year-end targets.
B18: CONVENTIONS
B19: Cell colours | C19: Blue = hardcoded input from source. Black = formula. Green = link to another tab. Yellow fill = paste your data here.
B20: Percentages | C20: Stored as fractions, so 0.02 renders as 2.0%. Contributions are in percentage points.
B21: Refreshing | C21: INDEC publishes CPI around the 13th-15th. Paste new index levels into the yellow rows on CPI Data; every rate, wedge and chart updates by formula.

Sheet CPI Data
C2: INDEC IPC nacional — levels and derived series
C3: Blue = INDEC index level (base dic-2016 = 100). Black = formula. Paste new prints into the yellow rows.
B5: Month | C5: Year | D5: M# | E5: Nivel General (index) | F5: Núcleo (index) | G5: Regulados (index) | H5: Estacionales (index) | I5: m/m Headline | J5: m/m Core | K5: m/m Regulated | L5: m/m Seasonal | M5: y/y Headline | N5: y/y Core | O5: Regulated Dec-23=100 | P5: Core Dec-23=100 | Q5: Relative price Reg/Core, Dec-23=100 | R5: Monthly wedge Reg m/m − Core m/m | S5: Wedge 3m average | T5: 2% line
B6: 2018-12 | C6: 2018 | D6: 12 | E6: 184.2552 | F6: 178.9326 | O6: =IF(G6="","",G6/$G$66*100) | P6: =IF(F6="","",F6/$F$66*100) -> 4.7088162 | Q6: =IF(OR(F6="",G6=""),"",(G6/$G$66)/(F6/$F$66)*100) | R6: =IF(OR(K6="",J6=""),"",K6-J6) | T6: 0.02
B7: 2019-01 | C7: 2019 | D7: 1 | E7: 189.6101 | F7: 184.3056 | I7: =IF(OR(E7="",E6=""),"",E7/E6-1) -> 0.029062409 | J7: =IF(OR(F7="",F6=""),"",F7/F6-1) -> 0.030028066 | K7: =IF(OR(G7="",G6=""),"",G7/G6-1) | L7: =IF(OR(H7="",H6=""),"",H7/H6-1) | O7: =IF(G7="","",G7/$G$66*100) | P7: =IF(F7="","",F7/$F$66*100) -> 4.8502128 | Q7: =IF(OR(F7="",G7=""),"",(G7/$G$66)/(F7/$F$66)*100) | R7: =IF(OR(K7="",J7=""),"",K7-J7) | T7: 0.02
B8: 2019-02 | C8: 2019 | D8: 2 | E8: 196.7501 | F8: 191.4115 | I8: =IF(OR(E8="",E7=""),"",E8/E7-1) -> 0.037656222 | J8: =IF(OR(F8="",F7=""),"",F8/F7-1) -> 0.038554987 | K8: =IF(OR(G8="",G7=""),"",G8/G7-1) | L8: =IF(OR(H8="",H7=""),"",H8/H7-1) | O8: =IF(G8="","",G8/$G$66*100) | P8: =IF(F8="","",F8/$F$66*100) -> 5.0372127 | Q8: =IF(OR(F8="",G8=""),"",(G8/$G$66)/(F8/$F$66)*100) | R8: =IF(OR(K8="",J8=""),"",K8-J8) | T8: 0.02
B9: 2019-03 | C9: 2019 | D9: 3 | E9: 205.9571 | F9: 200.1771 | I9: =IF(OR(E9="",E8=""),"",E9/E8-1) -> 0.046795402 | J9: =IF(OR(F9="",F8=""),"",F9/F8-1) -> 0.045794532 | K9: =IF(OR(G9="",G8=""),"",G9/G8-1) | L9: =IF(OR(H9="",H8=""),"",H9/H8-1) | O9: =IF(G9="","",G9/$G$66*100) | P9: =IF(F9="","",F9/$F$66*100) -> 5.2678895 | Q9: =IF(OR(F9="",G9=""),"",(G9/$G$66)/(F9/$F$66)*100) | R9: =IF(OR(K9="",J9=""),"",K9-J9) | S9: =IFERROR(AVERAGE(R7:R9),"") | T9: 0.02
B10: 2019-04 | C10: 2019 | D10: 4 | E10: 212.95964 | F10: 207.7179 | I10: =IF(OR(E10="",E9=""),"",E10/E9-1) -> 0.034 | J10: =IF(OR(F10="",F9=""),"",F10/F9-1) -> 0.037670643 | K10: =IF(OR(G10="",G9=""),"",G10/G9-1) | L10: =IF(OR(H10="",H9=""),"",H10/H9-1) | O10: =IF(G10="","",G10/$G$66*100) | P10: =IF(F10="","",F10/$F$66*100) -> 5.4663343 | Q10: =IF(OR(F10="",G10=""),"",(G10/$G$66)/(F10/$F$66)*100) | R10: =IF(OR(K10="",J10=""),"",K10-J10) | S10: =IFERROR(AVERAGE(R8:R10),"") | T10: 0.02
B11: 2019-05 | C11: 2019 | D11: 5 | E11: 219.5691 | F11: 214.3182 | I11: =IF(OR(E11="",E10=""),"",E11/E10-1) -> 0.031036203 | J11: =IF(OR(F11="",F10=""),"",F11/F10-1) -> 0.031775307 | K11: =IF(OR(G11="",G10=""),"",G11/G10-1) | L11: =IF(OR(H11="",H10=""),"",H11/H10-1) | O11: =IF(G11="","",G11/$G$66*100) | P11: =IF(F11="","",F11/$F$66*100) -> 5.6400288 | Q11: =IF(OR(F11="",G11=""),"",(G11/$G$66)/(F11/$F$66)*100) | R11: =IF(OR(K11="",J11=""),"",K11-J11) | S11: =IFERROR(AVERAGE(R9:R11),"") | T11: 0.02
B12: 2019-06 | C12: 2019 | D12: 6 | E12: 225.537 | F12: 220.1725 | I12: =IF(OR(E12="",E11=""),"",E12/E11-1) -> 0.027180054 | J12: =IF(OR(F12="",F11=""),"",F12/F11-1) -> 0.027315926 | K12: =IF(OR(G12="",G11=""),"",G12/G11-1) | L12: =IF(OR(H12="",H11=""),"",H12/H11-1) | O12: =IF(G12="","",G12/$G$66*100) | P12: =IF(F12="","",F12/$F$66*100) -> 5.7940914 | Q12: =IF(OR(F12="",G12=""),"",(G12/$G$66)/(F12/$F$66)*100) | R12: =IF(OR(K12="",J12=""),"",K12-J12) | S12: =IFERROR(AVERAGE(R10:R12),"") | T12: 0.02
B13: 2019-07 | C13: 2019 | D13: 7 | E13: 230.494 | F13: 224.9011 | I13: =IF(OR(E13="",E12=""),"",E13/E12-1) -> 0.021978655 | J13: =IF(OR(F13="",F12=""),"",F13/F12-1) -> 0.021476797 | K13: =IF(OR(G13="",G12=""),"",G13/G12-1) | L13: =IF(OR(H13="",H12=""),"",H13/H12-1) | O13: =IF(G13="","",G13/$G$66*100) | P13: =IF(F13="","",F13/$F$66*100) -> 5.9185299 | Q13: =IF(OR(F13="",G13=""),"",(G13/$G$66)/(F13/$F$66)*100) | R13: =IF(OR(K13="",J13=""),"",K13-J13) | S13: =IFERROR(AVERAGE(R11:R13),"") | T13: 0.02
B14: 2019-08 | C14: 2019 | D14: 8 | E14: 239.6077 | F14: 235.3317 | I14: =IF(OR(E14="",E13=""),"",E14/E13-1) -> 0.039539858 | J14: =IF(OR(F14="",F13=""),"",F14/F13-1) -> 0.046378608 | K14: =IF(OR(G14="",G13=""),"",G14/G13-1) | L14: =IF(OR(H14="",H13=""),"",H14/H13-1) | O14: =IF(G14="","",G14/$G$66*100) | P14: =IF(F14="","",F14/$F$66*100) -> 6.1930231 | Q14: =IF(OR(F14="",G14=""),"",(G14/$G$66)/(F14/$F$66)*100) | R14: =IF(OR(K14="",J14=""),"",K14-J14) | S14: =IFERROR(AVERAGE(R12:R14),"") | T14: 0.02
B15: 2019-09 | C15: 2019 | D15: 9 | E15: 253.7102 | F15: 250.4818 | I15: =IF(OR(E15="",E14=""),"",E15/E14-1) -> 0.058856623 | J15: =IF(OR(F15="",F14=""),"",F15/F14-1) -> 0.064377642 | K15: =IF(OR(G15="",G14=""),"",G15/G14-1) | L15: =IF(OR(H15="",H14=""),"",H15/H14-1) | O15: =IF(G15="","",G15/$G$66*100) | P15: =IF(F15="","",F15/$F$66*100) -> 6.5917153 | Q15: =IF(OR(F15="",G15=""),"",(G15/$G$66)/(F15/$F$66)*100) | R15: =IF(OR(K15="",J15=""),"",K15-J15) | S15: =IFERROR(AVERAGE(R13:R15),"") | T15: 0.02
B16: 2019-10 | C16: 2019 | D16: 10 | E16: 262.0661 | F16: 260.0118 | I16: =IF(OR(E16="",E15=""),"",E16/E15-1) -> 0.032934821 | J16: =IF(OR(F16="",F15=""),"",F16/F15-1) -> 0.038046676 | K16: =IF(OR(G16="",G15=""),"",G16/G15-1) | L16: =IF(OR(H16="",H15=""),"",H16/H15-1) | O16: =IF(G16="","",G16/$G$66*100) | P16: =IF(F16="","",F16/$F$66*100) -> 6.8425082 | Q16: =IF(OR(F16="",G16=""),"",(G16/$G$66)/(F16/$F$66)*100) | R16: =IF(OR(K16="",J16=""),"",K16-J16) | S16: =IFERROR(AVERAGE(R14:R16),"") | T16: 0.02
B17: 2019-11 | C17: 2019 | D17: 11 | E17: 273.2158 | F17: 270.3554 | I17: =IF(OR(E17="",E16=""),"",E17/E16-1) -> 0.042545373 | J17: =IF(OR(F17="",F16=""),"",F17/F16-1) -> 0.039781271 | K17: =IF(OR(G17="",G16=""),"",G17/G16-1) | L17: =IF(OR(H17="",H16=""),"",H17/H16-1) | O17: =IF(G17="","",G17/$G$66*100) | P17: =IF(F17="","",F17/$F$66*100) -> 7.1147118 | Q17: =IF(OR(F17="",G17=""),"",(G17/$G$66)/(F17/$F$66)*100) | R17: =IF(OR(K17="",J17=""),"",K17-J17) | S17: =IFERROR(AVERAGE(R15:R17),"") | T17: 0.02
B18: 2019-12 | C18: 2019 | D18: 12 | E18: 283.4442 | F18: 280.3107 | I18: =IF(OR(E18="",E17=""),"",E18/E17-1) -> 0.037437074 | J18: =IF(OR(F18="",F17=""),"",F18/F17-1) -> 0.036823011 | K18: =IF(OR(G18="",G17=""),"",G18/G17-1) | L18: =IF(OR(H18="",H17=""),"",H18/H17-1) | M18: =IF(OR(E18="",E6=""),"",E18/E6-1) -> 0.53832402 | N18: =IF(OR(F18="",F6=""),"",F18/F6-1) -> 0.56657144 | O18: =IF(G18="","",G18/$G$66*100) | P18: =IF(F18="","",F18/$F$66*100) -> 7.376697 | Q18: =IF(OR(F18="",G18=""),"",(G18/$G$66)/(F18/$F$66)*100) | R18: =IF(OR(K18="",J18=""),"",K18-J18) | S18: =IFERROR(AVERAGE(R16:R18),"") | T18: 0.02
B19: 2020-01 | C19: 2020 | D19: 1 | E19: 289.8299 | F19: 287.1529 | I19: =IF(OR(E19="",E18=""),"",E19/E18-1) -> 0.022528949 | J19: =IF(OR(F19="",F18=""),"",F19/F18-1) -> 0.024409343 | K19: =IF(OR(G19="",G18=""),"",G19/G18-1) | L19: =IF(OR(H19="",H18=""),"",H19/H18-1) | M19: =IF(OR(E19="",E7=""),"",E19/E7-1) -> 0.52855729 | N19: =IF(OR(F19="",F7=""),"",F19/F7-1) -> 0.55802591 | O19: =IF(G19="","",G19/$G$66*100) | P19: =IF(F19="","",F19/$F$66*100) -> 7.5567573 | Q19: =IF(OR(F19="",G19=""),"",(G19/$G$66)/(F19/$F$66)*100) | R19: =IF(OR(K19="",J19=""),"",K19-J19) | S19: =IFERROR(AVERAGE(R17:R19),"") | T19: 0.02
B20: 2020-02 | C20: 2020 | D20: 2 | E20: 295.666 | F20: 293.9922 | I20: =IF(OR(E20="",E19=""),"",E20/E19-1) -> 0.020136294 | J20: =IF(OR(F20="",F19=""),"",F20/F19-1) -> 0.023817625 | K20: =IF(OR(G20="",G19=""),"",G20/G19-1) | L20: =IF(OR(H20="",H19=""),"",H20/H19-1) | M20: =IF(OR(E20="",E8=""),"",E20/E8-1) -> 0.50274892 | N20: =IF(OR(F20="",F8=""),"",F20/F8-1) -> 0.53591712 | O20: =IF(G20="","",G20/$G$66*100) | P20: =IF(F20="","",F20/$F$66*100) -> 7.7367413 | Q20: =IF(OR(F20="",G20=""),"",(G20/$G$66)/(F20/$F$66)*100) | R20: =IF(OR(K20="",J20=""),"",K20-J20) | S20: =IFERROR(AVERAGE(R18:R20),"") | T20: 0.02
B21: 2020-03 | C21: 2020 | D21: 3 | E21: 305.5515 | F21: 303.1665 | I21: =IF(OR(E21="",E20=""),"",E21/E20-1) -> 0.033434686 | J21: =IF(OR(F21="",F20=""),"",F21/F20-1) -> 0.03120593 | K21: =IF(OR(G21="",G20=""),"",G21/G20-1) | L21: =IF(OR(H21="",H20=""),"",H21/H20-1) | M21: =IF(OR(E21="",E9=""),"",E21/E9-1) -> 0.48356867 | N21: =IF(OR(F21="",F9=""),"",F21/F9-1) -> 0.51449142 | O21: =IF(G21="","",G21/$G$66*100) | P21: =IF(F21="","",F21/$F$66*100) -> 7.9781735 | Q21: =IF(OR(F21="",G21=""),"",(G21/$G$66)/(F21/$F$66)*100) | R21: =IF(OR(K21="",J21=""),"",K21-J21) | S21: =IFERROR(AVERAGE(R19:R21),"") | T21: 0.02
B22: 2020-04 | C22: 2020 | D22: 4 | E22: 310.1243 | F22: 308.3681 | I22: =IF(OR(E22="",E21=""),"",E22/E21-1) -> 0.014965726 | J22: =IF(OR(F22="",F21=""),"",F22/F21-1) -> 0.017157569 | K22: =IF(OR(G22="",G21=""),"",G22/G21-1) | L22: =IF(OR(H22="",H21=""),"",H22/H21-1) | M22: =IF(OR(E22="",E10=""),"",E22/E10-1) -> 0.45625856 | N22: =IF(OR(F22="",F10=""),"",F22/F10-1) -> 0.48455237 | O22: =IF(G22="","",G22/$G$66*100) | P22: =IF(F22="","",F22/$F$66*100) -> 8.1150596 | Q22: =IF(OR(F22="",G22=""),"",(G22/$G$66)/(F22/$F$66)*100) | R22: =IF(OR(K22="",J22=""),"",K22-J22) | S22: =IFERROR(AVERAGE(R20:R22),"") | T22: 0.02
B23: 2020-05 | C23: 2020 | D23: 5 | E23: 314.9087 | F23: 313.3195 | I23: =IF(OR(E23="",E22=""),"",E23/E22-1) -> 0.015427363 | J23: =IF(OR(F23="",F22=""),"",F23/F22-1) -> 0.016056784 | K23: =IF(OR(G23="",G22=""),"",G23/G22-1) | L23: =IF(OR(H23="",H22=""),"",H23/H22-1) | M23: =IF(OR(E23="",E11=""),"",E23/E11-1) -> 0.43421228 | N23: =IF(OR(F23="",F11=""),"",F23/F11-1) -> 0.46193604 | O23: =IF(G23="","",G23/$G$66*100) | P23: =IF(F23="","",F23/$F$66*100) -> 8.2453613 | Q23: =IF(OR(F23="",G23=""),"",(G23/$G$66)/(F23/$F$66)*100) | R23: =IF(OR(K23="",J23=""),"",K23-J23) | S23: =IFERROR(AVERAGE(R21:R23),"") | T23: 0.02
B24: 2020-06 | C24: 2020 | D24: 6 | E24: 321.9738 | F24: 320.5733 | I24: =IF(OR(E24="",E23=""),"",E24/E23-1) -> 0.022435392 | J24: =IF(OR(F24="",F23=""),"",F24/F23-1) -> 0.023151448 | K24: =IF(OR(G24="",G23=""),"",G24/G23-1) | L24: =IF(OR(H24="",H23=""),"",H24/H23-1) | M24: =IF(OR(E24="",E12=""),"",E24/E12-1) -> 0.42758749 | N24: =IF(OR(F24="",F12=""),"",F24/F12-1) -> 0.45600972 | O24: =IF(G24="","",G24/$G$66*100) | P24: =IF(F24="","",F24/$F$66*100) -> 8.4362534 | Q24: =IF(OR(F24="",G24=""),"",(G24/$G$66)/(F24/$F$66)*100) | R24: =IF(OR(K24="",J24=""),"",K24-J24) | S24: =IFERROR(AVERAGE(R22:R24),"") | T24: 0.02
B25: 2020-07 | C25: 2020 | D25: 7 | E25: 328.2014 | F25: 328.6943 | I25: =IF(OR(E25="",E24=""),"",E25/E24-1) -> 0.019341946 | J25: =IF(OR(F25="",F24=""),"",F25/F24-1) -> 0.02533274 | K25: =IF(OR(G25="",G24=""),"",G25/G24-1) | L25: =IF(OR(H25="",H24=""),"",H25/H24-1) | M25: =IF(OR(E25="",E13=""),"",E25/E13-1) -> 0.42390431 | N25: =IF(OR(F25="",F13=""),"",F25/F13-1) -> 0.46150597 | O25: =IF(G25="","",G25/$G$66*100) | P25: =IF(F25="","",F25/$F$66*100) -> 8.6499668 | Q25: =IF(OR(F25="",G25=""),"",(G25/$G$66)/(F25/$F$66)*100) | R25: =IF(OR(K25="",J25=""),"",K25-J25) | S25: =IFERROR(AVERAGE(R23:R25),"") | T25: 0.02
B26: 2020-08 | C26: 2020 | D26: 8 | E26: 337.0632 | F26: 338.6645 | I26: =IF(OR(E26="",E25=""),"",E26/E25-1) -> 0.027001104 | J26: =IF(OR(F26="",F25=""),"",F26/F25-1) -> 0.030332744 | K26: =IF(OR(G26="",G25=""),"",G26/G25-1) | L26: =IF(OR(H26="",H25=""),"",H26/H25-1) | M26: =IF(OR(E26="",E14=""),"",E26/E14-1) -> 0.40672942 | N26: =IF(OR(F26="",F14=""),"",F26/F14-1) -> 0.43909427 | O26: =IF(G26="","",G26/$G$66*100) | P26: =IF(F26="","",F26/$F$66*100) -> 8.912344 | Q26: =IF(OR(F26="",G26=""),"",(G26/$G$66)/(F26/$F$66)*100) | R26: =IF(OR(K26="",J26=""),"",K26-J26) | S26: =IFERROR(AVERAGE(R24:R26),"") | T26: 0.02
B27: 2020-09 | C27: 2020 | D27: 9 | E27: 346.6207 | F27: 346.511 | I27: =IF(OR(E27="",E26=""),"",E27/E26-1) -> 0.028355216 | J27: =IF(OR(F27="",F26=""),"",F27/F26-1) -> 0.023168947 | K27: =IF(OR(G27="",G26=""),"",G27/G26-1) | L27: =IF(OR(H27="",H26=""),"",H27/H26-1) | M27: =IF(OR(E27="",E15=""),"",E27/E15-1) -> 0.36620719 | N27: =IF(OR(F27="",F15=""),"",F27/F15-1) -> 0.38337795 | O27: =IF(G27="","",G27/$G$66*100) | P27: =IF(F27="","",F27/$F$66*100) -> 9.1188336 | Q27: =IF(OR(F27="",G27=""),"",(G27/$G$66)/(F27/$F$66)*100) | R27: =IF(OR(K27="",J27=""),"",K27-J27) | S27: =IFERROR(AVERAGE(R25:R27),"") | T27: 0.02
B28: 2020-10 | C28: 2020 | D28: 10 | E28: 359.657 | F28: 358.4989 | I28: =IF(OR(E28="",E27=""),"",E28/E27-1) -> 0.037609698 | J28: =IF(OR(F28="",F27=""),"",F28/F27-1) -> 0.034596016 | K28: =IF(OR(G28="",G27=""),"",G28/G27-1) | L28: =IF(OR(H28="",H27=""),"",H28/H27-1) | M28: =IF(OR(E28="",E16=""),"",E28/E16-1) -> 0.3723904 | N28: =IF(OR(F28="",F16=""),"",F28/F16-1) -> 0.37877935 | O28: =IF(G28="","",G28/$G$66*100) | P28: =IF(F28="","",F28/$F$66*100) -> 9.4343089 | Q28: =IF(OR(F28="",G28=""),"",(G28/$G$66)/(F28/$F$66)*100) | R28: =IF(OR(K28="",J28=""),"",K28-J28) | S28: =IFERROR(AVERAGE(R26:R28),"") | T28: 0.02
B29: 2020-11 | C29: 2020 | D29: 11 | E29: 371.0211 | F29: 372.6154 | I29: =IF(OR(E29="",E28=""),"",E29/E28-1) -> 0.031597049 | J29: =IF(OR(F29="",F28=""),"",F29/F28-1) -> 0.03937669 | K29: =IF(OR(G29="",G28=""),"",G29/G28-1) | L29: =IF(OR(H29="",H28=""),"",H29/H28-1) | M29: =IF(OR(E29="",E17=""),"",E29/E17-1) -> 0.3579782 | N29: =IF(OR(F29="",F17=""),"",F29/F17-1) -> 0.37824286 | O29: =IF(G29="","",G29/$G$66*100) | P29: =IF(F29="","",F29/$F$66*100) -> 9.8058008 | Q29: =IF(OR(F29="",G29=""),"",(G29/$G$66)/(F29/$F$66)*100) | R29: =IF(OR(K29="",J29=""),"",K29-J29) | S29: =IFERROR(AVERAGE(R27:R29),"") | T29: 0.02
... B42: 2021-12 | C42: 2021 | D42: 12 | E42: 582.4575 | F42: 605.1759 | I42: =IF(OR(E42="",E41=""),"",E42/E41-1) -> 0.038399703 | J42: =IF(OR(F42="",F41=""),"",F42/F41-1) -> 0.044232388 | K42: =IF(OR(G42="",G41=""),"",G42/G41-1) | L42: =IF(OR(H42="",H41=""),"",H42/H41-1) | M42: =IF(OR(E42="",E30=""),"",E42/E30-1) -> 0.50941634 | N42: =IF(OR(F42="",F30=""),"",F42/F30-1) -> 0.54869327 | O42: =IF(G42="","",G42/$G$66*100) | P42: =IF(F42="","",F42/$F$66*100) -> 15.925897 | Q42: =IF(OR(F42="",G42=""),"",(G42/$G$66)/(F42/$F$66)*100) | R42: =IF(OR(K42="",J42=""),"",K42-J42) | S42: =IFERROR(AVERAGE(R40:R42),"") | T42: 0.02
B43: 2022-01 | C43: 2022 | D43: 1 | E43: 605.0317 | F43: 625.1594 | G43: 512.3766 | H43: 658.2543 | I43: =IF(OR(E43="",E42=""),"",E43/E42-1) -> 0.038756819 | J43: =IF(OR(F43="",F42=""),"",F43/F42-1) -> 0.033020978 | K43: =IF(OR(G43="",G42=""),"",G43/G42-1) | L43: =IF(OR(H43="",H42=""),"",H43/H42-1) | M43: =IF(OR(E43="",E31=""),"",E43/E31-1) -> 0.50690162 | N43: =IF(OR(F43="",F31=""),"",F43/F31-1) -> 0.5395459 | O43: =IF(G43="","",G43/$G$66*100) -> 20.88959 | P43: =IF(F43="","",F43/$F$66*100) -> 16.451785 | Q43: =IF(OR(F43="",G43=""),"",(G43/$G$66)/(F43/$F$66)*100) -> 126.97461 | R43: =IF(OR(K43="",J43=""),"",K43-J43) | S43: =IFERROR(AVERAGE(R41:R43),"") | T43: 0.02
B44: 2022-02 | C44: 2022 | D44: 2 | E44: 633.4341 | F44: 652.9838 | G44: 528.2683 | H44: 713.7013 | I44: =IF(OR(E44="",E43=""),"",E44/E43-1) -> 0.046943656 | J44: =IF(OR(F44="",F43=""),"",F44/F43-1) -> 0.044507689 | K44: =IF(OR(G44="",G43=""),"",G44/G43-1) -> 0.031015663 | L44: =IF(OR(H44="",H43=""),"",H44/H43-1) -> 0.084233403 | M44: =IF(OR(E44="",E32=""),"",E44/E32-1) -> 0.52319257 | N44: =IF(OR(F44="",F32=""),"",F44/F32-1) -> 0.54518293 | O44: =IF(G44="","",G44/$G$66*100) -> 21.537494 | P44: =IF(F44="","",F44/$F$66*100) -> 17.184016 | Q44: =IF(OR(F44="",G44=""),"",(G44/$G$66)/(F44/$F$66)*100) -> 125.33446 | R44: =IF(OR(K44="",J44=""),"",K44-J44) -> -0.013492026 | S44: =IFERROR(AVERAGE(R42:R44),"") -> -0.013492026 | T44: 0.02
B45: 2022-03 | C45: 2022 | D45: 3 | E45: 676.0566 | F45: 694.7515 | G45: 572.7992 | H45: 757.8963 | I45: =IF(OR(E45="",E44=""),"",E45/E44-1) -> 0.067287978 | J45: =IF(OR(F45="",F44=""),"",F45/F44-1) -> 0.063964374 | K45: =IF(OR(G45="",G44=""),"",G45/G44-1) -> 0.084295991 | L45: =IF(OR(H45="",H44=""),"",H45/H44-1) -> 0.061923665 | M45: =IF(OR(E45="",E33=""),"",E45/E33-1) -> 0.5510663 | N45: =IF(OR(F45="",F33=""),"",F45/F33-1) -> 0.57283234 | O45: =IF(G45="","",G45/$G$66*100) -> 23.353019 | P45: =IF(F45="","",F45/$F$66*100) -> 18.283181 | Q45: =IF(OR(F45="",G45=""),"",(G45/$G$66)/(F45/$F$66)*100) -> 127.72952 | R45: =IF(OR(K45="",J45=""),"",K45-J45) -> 0.020331617 | S45: =IFERROR(AVERAGE(R43:R45),"") -> 0.0034197958 | T45: 0.02
B46: 2022-04 | C46: 2022 | D46: 4 | E46: 716.9399 | F46: 741.3622 | G46: 595.2223 | H46: 799.0308 | I46: =IF(OR(E46="",E45=""),"",E46/E45-1) -> 0.060473191 | J46: =IF(OR(F46="",F45=""),"",F46/F45-1) -> 0.067089744 | K46: =IF(OR(G46="",G45=""),"",G46/G45-1) -> 0.039146528 | L46: =IF(OR(H46="",H45=""),"",H46/H45-1) -> 0.054274576 | M46: =IF(OR(E46="",E34=""),"",E46/E34-1) -> 0.58038009 | N46: =IF(OR(F46="",F34=""),"",F46/F34-1) -> 0.60517415 | O46: =IF(G46="","",G46/$G$66*100) -> 24.267208 | P46: =IF(F46="","",F46/$F$66*100) -> 19.509795 | Q46: =IF(OR(F46="",G46=""),"",(G46/$G$66)/(F46/$F$66)*100) -> 124.38474 | R46: =IF(OR(K46="",J46=""),"",K46-J46) -> -0.027943215 | S46: =IFERROR(AVERAGE(R44:R46),"") -> -0.0070345413 | T46: 0.02
B47: 2022-05 | C47: 2022 | D47: 5 | E47: 753.147 | F47: 779.9267 | G47: 629.0029 | H47: 825.8088 | I47: =IF(OR(E47="",E46=""),"",E47/E46-1) -> 0.050502281 | J47: =IF(OR(F47="",F46=""),"",F47/F46-1) -> 0.052018433 | K47: =IF(OR(G47="",G46=""),"",G47/G46-1) -> 0.056752914 | L47: =IF(OR(H47="",H46=""),"",H47/H46-1) -> 0.033513101 | M47: =IF(OR(E47="",E35=""),"",E47/E35-1) -> 0.6067993 | N47: =IF(OR(F47="",F35=""),"",F47/F35-1) -> 0.63188718 | O47: =IF(G47="","",G47/$G$66*100) -> 25.644443 | P47: =IF(F47="","",F47/$F$66*100) -> 20.524664 | Q47: =IF(OR(F47="",G47=""),"",(G47/$G$66)/(F47/$F$66)*100) -> 124.94452 | R47: =IF(OR(K47="",J47=""),"",K47-J47) -> 0.0047344809 | S47: =IFERROR(AVERAGE(R45:R47),"") -> -0.0009590391 | T47: 0.02
B48: 2022-06 | C48: 2022 | D48: 6 | E48: 793.0278 | F48: 819.5734 | G48: 662.0938 | H48: 880.3186 | I48: =IF(OR(E48="",E47=""),"",E48/E47-1) -> 0.052952213 | J48: =IF(OR(F48="",F47=""),"",F48/F47-1) -> 0.05083388 | K48: =IF(OR(G48="",G47=""),"",G48/G47-1) -> 0.052608501 | L48: =IF(OR(H48="",H47=""),"",H48/H47-1) -> 0.066007773 | M48: =IF(OR(E48="",E36=""),"",E48/E36-1) -> 0.63982582 | N48: =IF(OR(F48="",F36=""),"",F48/F36-1) -> 0.65509897 | O48: =IF(G48="","",G48/$G$66*100) -> 26.993559 | P48: =IF(F48="","",F48/$F$66*100) -> 21.568012 | Q48: =IF(OR(F48="",G48=""),"",(G48/$G$66)/(F48/$F$66)*100) -> 125.15552 | R48: =IF(OR(K48="",J48=""),"",K48-J48) -> 0.0017746218 | S48: =IFERROR(AVERAGE(R46:R48),"") -> -0.0071447042 | T48: 0.02
B49: 2022-07 | C49: 2022 | D49: 7 | E49: 851.761 | F49: 879.6383 | G49: 694.6115 | H49: 979.7957 | I49: =IF(OR(E49="",E48=""),"",E49/E48-1) -> 0.074061969 | J49: =IF(OR(F49="",F48=""),"",F49/F48-1) -> 0.073288006 | K49: =IF(OR(G49="",G48=""),"",G49/G48-1) -> 0.049113434 | L49: =IF(OR(H49="",H48=""),"",H49/H48-1) -> 0.11300125 | M49: =IF(OR(E49="",E37=""),"",E49/E37-1) -> 0.71002454 | N49: =IF(OR(F49="",F37=""),"",F49/F37-1) -> 0.72242565 | O49: =IF(G49="","",G49/$G$66*100) -> 28.319305 | P49: =IF(F49="","",F49/$F$66*100) -> 23.148689 | Q49: =IF(OR(F49="",G49=""),"",(G49/$G$66)/(F49/$F$66)*100) -> 122.33654 | R49: =IF(OR(K49="",J49=""),"",K49-J49) -> -0.024174572 | S49: =IFERROR(AVERAGE(R47:R49),"") -> -0.0058884897 | T49: 0.02
B50: 2022-08 | C50: 2022 | D50: 8 | E50: 911.1316 | F50: 939.4677 | G50: 738.3105 | H50: 1064.731 | I50: =IF(OR(E50="",E49=""),"",E50/E49-1) -> 0.069703356 | J50: =IF(OR(F50="",F49=""),"",F50/F49-1) -> 0.068015911 | K50: =IF(OR(G50="",G49=""),"",G50/G49-1) -> 0.062911426 | L50: =IF(OR(H50="",H49=""),"",H50/H49-1) -> 0.086686745 | M50: =IF(OR(E50="",E38=""),"",E50/E38-1) -> 0.78515273 | N50: =IF(OR(F50="",F38=""),"",F50/F38-1) -> 0.78370889 | O50: =IF(G50="","",G50/$G$66*100) -> 30.100913 | P50: =IF(F50="","",F50/$F$66*100) -> 24.723168 | Q50: =IF(OR(F50="",G50=""),"",(G50/$G$66)/(F50/$F$66)*100) -> 121.75184 | R50: =IF(OR(K50="",J50=""),"",K50-J50) -> -0.0051044846 | S50: =IFERROR(AVERAGE(R48:R50),"") -> -0.0091681449 | T50: 0.02
B51: 2022-09 | C51: 2022 | D51: 9 | E51: 967.3076 | F51: 991.2585 | G51: 771.8891 | H51: 1189.6609 | I51: =IF(OR(E51="",E50=""),"",E51/E50-1) -> 0.061655199 | J51: =IF(OR(F51="",F50=""),"",F51/F50-1) -> 0.055127813 | K51: =IF(OR(G51="",G50=""),"",G51/G50-1) -> 0.045480323 | L51: =IF(OR(H51="",H50=""),"",H51/H50-1) -> 0.11733471 | M51: =IF(OR(E51="",E39=""),"",E51/E39-1) -> 0.83029982 | N51: =IF(OR(F51="",F39=""),"",F51/F39-1) -> 0.82258582 | O51: =IF(G51="","",G51/$G$66*100) -> 31.469912 | P51: =IF(F51="","",F51/$F$66*100) -> 26.086102 | Q51: =IF(OR(F51="",G51=""),"",(G51/$G$66)/(F51/$F$66)*100) -> 120.63861 | R51: =IF(OR(K51="",J51=""),"",K51-J51) -> -0.0096474904 | S51: =IFERROR(AVERAGE(R49:R51),"") -> -0.012975516 | T51: 0.02
B52: 2022-10 | C52: 2022 | D52: 10 | E52: 1028.706 | F52: 1046.265 | G52: 829.1011 | H52: 1297.2889 | I52: =IF(OR(E52="",E51=""),"",E52/E51-1) -> 0.063473501 | J52: =IF(OR(F52="",F51=""),"",F52/F51-1) -> 0.05549158 | K52: =IF(OR(G52="",G51=""),"",G52/G51-1) -> 0.074119456 | L52: =IF(OR(H52="",H51=""),"",H52/H51-1) -> 0.090469477 | M52: =IF(OR(E52="",E40=""),"",E52/E40-1) -> 0.88035685 | N52: =IF(OR(F52="",F40=""),"",F52/F40-1) -> 0.86405535 | O52: =IF(G52="","",G52/$G$66*100) -> 33.802445 | P52: =IF(F52="","",F52/$F$66*100) -> 27.533661 | Q52: =IF(OR(F52="",G52=""),"",(G52/$G$66)/(F52/$F$66)*100) -> 122.76771 | R52: =IF(OR(K52="",J52=""),"",K52-J52) -> 0.018627876 | S52: =IFERROR(AVERAGE(R50:R52),"") -> 0.0012919671 | T52: 0.02
B53: 2022-11 | C53: 2022 | D53: 11 | E53: 1079.2787 | F53: 1096.024 | G53: 880.7676 | H53: 1350.5167 | I53: =IF(OR(E53="",E52=""),"",E53/E52-1) -> 0.049161471 | J53: =IF(OR(F53="",F52=""),"",F53/F52-1) -> 0.047558697 | K53: =IF(OR(G53="",G52=""),"",G53/G52-1) -> 0.062316284 | L53: =IF(OR(H53="",H52=""),"",H53/H52-1) -> 0.041030028 | M53: =IF(OR(E53="",E41=""),"",E53/E41-1) -> 0.92412782 | N53: =IF(OR(F53="",F41=""),"",F53/F41-1) -> 0.8911919 | O53: =IF(G53="","",G53/$G$66*100) -> 35.908888 | P53: =IF(F53="","",F53/$F$66*100) -> 28.843126 | Q53: =IF(OR(F53="",G53=""),"",(G53/$G$66)/(F53/$F$66)*100) -> 124.49721 | R53: =IF(OR(K53="",J53=""),"",K53-J53) -> 0.014757588 | S53: =IFERROR(AVERAGE(R51:R53),"") -> 0.0079126578 | T53: 0.02
B54: 2022-12 | C54: 2022 | D54: 12 | E54: 1134.5875 | F54: 1153.5771 | G54: 925.7853 | H54: 1413.2059 | I54: =IF(OR(E54="",E53=""),"",E54/E53-1) -> 0.051246078 | J54: =IF(OR(F54="",F53=""),"",F54/F53-1) -> 0.052510803 | K54: =IF(OR(G54="",G53=""),"",G54/G53-1) -> 0.051111894 | L54: =IF(OR(H54="",H53=""),"",H54/H53-1) -> 0.046418678 | M54: =IF(OR(E54="",E42=""),"",E54/E42-1) -> 0.94793182 | N54: =IF(OR(F54="",F42=""),"",F54/F42-1) -> 0.9061848 | O54: =IF(G54="","",G54/$G$66*100) -> 37.744259 | P54: =IF(F54="","",F54/$F$66*100) -> 30.357702 | Q54: =IF(OR(F54="",G54=""),"",(G54/$G$66)/(F54/$F$66)*100) -> 124.33174 | R54: =IF(OR(K54="",J54=""),"",K54-J54) -> -0.0013989089 | S54: =IFERROR(AVERAGE(R52:R54),"") -> 0.010662185 | T54: 0.02
...

Sheet Ch4 Monthly CPI
C2: Monthly inflation against the 2% threshold
C3: Headline and core, month on month. INDEC through 2026-06.
B5: Month | C5: Headline m/m | D5: Core m/m | E5: 2% threshold | F5: Below 2%?
B6: ='CPI Data'!B67 -> 2024-01 | C6: ='CPI Data'!I67 -> 0.20614225 | D6: ='CPI Data'!J67 -> 0.20216489 | E6: 0.02 | F6: =IF(C6="","",IF(C6<$E6,"yes","no")) -> no
B7: ='CPI Data'!B68 -> 2024-02 | C7: ='CPI Data'!I68 -> 0.13240676 | D7: ='CPI Data'!J68 -> 0.12290141 | E7: 0.02 | F7: =IF(C7="","",IF(C7<$E7,"yes","no")) -> no
B8: ='CPI Data'!B69 -> 2024-03 | C8: ='CPI Data'!I69 -> 0.110097 | D8: ='CPI Data'!J69 -> 0.09412048 | E8: 0.02 | F8: =IF(C8="","",IF(C8<$E8,"yes","no")) -> no
B9: ='CPI Data'!B70 -> 2024-04 | C9: ='CPI Data'!I70 -> 0.088319208 | D9: ='CPI Data'!J70 -> 0.062984384 | E9: 0.02 | F9: =IF(C9="","",IF(C9<$E9,"yes","no")) -> no
B10: ='CPI Data'!B71 -> 2024-05 | C10: ='CPI Data'!I71 -> 0.041760449 | D10: ='CPI Data'!J71 -> 0.037346867 | E10: 0.02 | F10: =IF(C10="","",IF(C10<$E10,"yes","no")) -> no
B11: ='CPI Data'!B72 -> 2024-06 | C11: ='CPI Data'!I72 -> 0.045773499 | D11: ='CPI Data'!J72 -> 0.036511303 | E11: 0.02 | F11: =IF(C11="","",IF(C11<$E11,"yes","no")) -> no
B12: ='CPI Data'!B73 -> 2024-07 | C12: ='CPI Data'!I73 -> 0.040309337 | D12: ='CPI Data'!J73 -> 0.037855879 | E12: 0.02 | F12: =IF(C12="","",IF(C12<$E12,"yes","no")) -> no
B13: ='CPI Data'!B74 -> 2024-08 | C13: ='CPI Data'!I74 -> 0.041722733 | D13: ='CPI Data'!J74 -> 0.041202856 | E13: 0.02 | F13: =IF(C13="","",IF(C13<$E13,"yes","no")) -> no
B14: ='CPI Data'!B75 -> 2024-09 | C14: ='CPI Data'!I75 -> 0.034692081 | D14: ='CPI Data'!J75 -> 0.032622058 | E14: 0.02 | F14: =IF(C14="","",IF(C14<$E14,"yes","no")) -> no
B15: ='CPI Data'!B76 -> 2024-10 | C15: ='CPI Data'!I76 -> 0.02691738 | D15: ='CPI Data'!J76 -> 0.029178168 | E15: 0.02 | F15: =IF(C15="","",IF(C15<$E15,"yes","no")) -> no
B16: ='CPI Data'!B77 -> 2024-11 | C16: ='CPI Data'!I77 -> 0.024265561 | D16: ='CPI Data'!J77 -> 0.027148339 | E16: 0.02 | F16: =IF(C16="","",IF(C16<$E16,"yes","no")) -> no
B17: ='CPI Data'!B78 -> 2024-12 | C17: ='CPI Data'!I78 -> 0.027041041 | D17: ='CPI Data'!J78 -> 0.031972815 | E17: 0.02 | F17: =IF(C17="","",IF(C17<$E17,"yes","no")) -> no
... B35: ='CPI Data'!B96 -> 2026-06 | C35: ='CPI Data'!I96 -> 0.018868715 | D35: ='CPI Data'!J96 -> 0.015695812 | E35: 0.02 | F35: =IF(C35="","",IF(C35<$E35,"yes","no")) -> yes
B38: Why 2% a month is the number that matters
B40: Arithmetic | D40: 2.0% a month compounds to 26.8% a year. Sustained sub-2% is what puts the annual print into the low-20s and below — the zone where indexation stops being the rational default for wage and contract setting.
B42: The nominal anchor | D42: The FX band crawls at 1% a month. Any monthly CPI meaningfully above that appreciates the real exchange rate. 2% is roughly the level at which the crawl and domestic price-setting stop pulling against each other; above it, disinflation is being bought with real appreciation.
B44: Real rates | D44: At prevailing policy rates, sub-2% monthly inflation is what makes the ex-post real rate decisively positive and keeps peso demand intact.
B46: Expectations | D46: It is a visible, round threshold. Breaking it durably — not for one month — is what shifts the REM and, more importantly, private contract behaviour.
B48: Where we are | D48: Since Jan-2024 only five months have printed below 2 per cent. 2026-06 came in at 1.89% headline and 1.57% core, the cleanest reading of the series — but one print is not a regime.

Sheet Ch3 Regulated
C2: The regulated-price adjustment is largely behind us
C3: Regulated vs core prices since Dec-2023. INDEC through 2026-06.
B5: Month | C5: Regulated Dec-23=100 | D5: Core Dec-23=100 | E5: Relative price Reg/Core | F5: Monthly wedge (Reg − Core) | G5: Wedge, 3m avg
B6: ='CPI Data'!B66 -> 2023-12 | C6: ='CPI Data'!O66 -> 100 | D6: ='CPI Data'!P66 -> 100 | E6: ='CPI Data'!Q66 -> 100 | F6: ='CPI Data'!R66 -> -0.075788269 | G6: ='CPI Data'!S66 -> -0.043720216
B7: ='CPI Data'!B67 -> 2024-01 | C7: ='CPI Data'!O67 -> 126.57194 | D7: ='CPI Data'!P67 -> 120.21649 | E7: ='CPI Data'!Q67 -> 105.28667 | F7: ='CPI Data'!R67 -> 0.063554472 | G7: ='CPI Data'!S67 -> -0.015235864
B8: ='CPI Data'!B68 -> 2024-02 | C8: ='CPI Data'!O68 -> 153.28636 | D8: ='CPI Data'!P68 -> 134.99126 | E8: ='CPI Data'!Q68 -> 113.5528 | F8: ='CPI Data'!R68 -> 0.08815981 | G8: ='CPI Data'!S68 -> 0.025308671
B9: ='CPI Data'!B69 -> 2024-03 | C9: ='CPI Data'!O69 -> 181.0723 | D9: ='CPI Data'!P69 -> 147.69671 | E9: ='CPI Data'!Q69 -> 122.59739 | F9: ='CPI Data'!R69 -> 0.087147699 | G9: ='CPI Data'!S69 -> 0.079620661
B10: ='CPI Data'!B70 -> 2024-04 | C10: ='CPI Data'!O70 -> 214.3789 | D10: ='CPI Data'!P70 -> 156.99929 | E10: ='CPI Data'!Q70 -> 136.54769 | F10: ='CPI Data'!R70 -> 0.12095651 | G10: ='CPI Data'!S70 -> 0.098754672
B11: ='CPI Data'!B71 -> 2024-05 | C11: ='CPI Data'!O71 -> 222.99147 | D11: ='CPI Data'!P71 -> 162.86272 | E11: ='CPI Data'!Q71 -> 136.91989 | F11: ='CPI Data'!R71 -> 0.0028276407 | G11: ='CPI Data'!S71 -> 0.070310615
B12: ='CPI Data'!B72 -> 2024-06 | C12: ='CPI Data'!O72 -> 240.95693 | D12: ='CPI Data'!P72 -> 168.80906 | E12: ='CPI Data'!Q72 -> 142.73934 | F12: ='CPI Data'!R72 -> 0.04405438 | G12: ='CPI Data'!S72 -> 0.055946175
B13: ='CPI Data'!B73 -> 2024-07 | C13: ='CPI Data'!O73 -> 251.39584 | D13: ='CPI Data'!P73 -> 175.19947 | E13: ='CPI Data'!Q73 -> 143.49121 | F13: ='CPI Data'!R73 -> 0.0054668497 | G13: ='CPI Data'!S73 -> 0.017449623
B14: ='CPI Data'!B74 -> 2024-08 | C14: ='CPI Data'!O74 -> 266.20235 | D14: ='CPI Data'!P74 -> 182.41819 | E14: ='CPI Data'!Q74 -> 145.92972 | F14: ='CPI Data'!R74 -> 0.017694312 | G14: ='CPI Data'!S74 -> 0.022405181
B15: ='CPI Data'!B75 -> 2024-09 | C15: ='CPI Data'!O75 -> 278.2657 | D15: ='CPI Data'!P75 -> 188.36905 | E15: ='CPI Data'!Q75 -> 147.72369 | F15: ='CPI Data'!R75 -> 0.012694431 | G15: ='CPI Data'!S75 -> 0.011951864
B16: ='CPI Data'!B76 -> 2024-10 | C16: ='CPI Data'!O76 -> 285.76832 | D16: ='CPI Data'!P76 -> 193.86531 | E16: ='CPI Data'!Q76 -> 147.4056 | F16: ='CPI Data'!R76 -> -0.0022160945 | G16: ='CPI Data'!S76 -> 0.0093908828
B17: ='CPI Data'!B77 -> 2024-11 | C17: ='CPI Data'!O77 -> 295.89495 | D17: ='CPI Data'!P77 -> 199.12843 | E17: ='CPI Data'!Q77 -> 148.59503 | F17: ='CPI Data'!R77 -> 0.0082881644 | G17: ='CPI Data'!S77 -> 0.0062555002
... B36: ='CPI Data'!B96 -> 2026-06 | C36: ='CPI Data'!O96 -> 505.11714 | D36: ='CPI Data'!P96 -> 316.06532 | E36: ='CPI Data'!Q96 -> 159.81416 | F36: ='CPI Data'!R96 -> 0.0072561076 | G36: ='CPI Data'!S96 -> 0.01205565
B40: Reading | I40: Decomposition of headline y/y
I41: Month | J41: Headline y/y | K41: of which: Regulated (pp) | L41: of which: Non-regulated (pp) | M41: Regulated share of headline
B42: Regulated prices are up 405% since Dec-2023 against 216% for core: a 60% gain in relative price. That is the tariff and transport catch-up being paid for, and it is the reason headline has run above core through most of the adjustment. The third panel is the operative one — the monthly wedge over core has compressed from double digits in early 2024 toward roughly zero, so the mechanical drag regulated prices impose on headline from here is far smaller than the drag already absorbed. Residual risk sits in the items still lagging rather than in the aggregate. The fourth panel puts a number on it: regulated prices carry a 21% basket weight and contributed 8.7pp of the 32.4% headline y/y in Apr-2026 — still material, but the contribution has been falling as the wedge closes. | I42: 2022-01 | J42: 0.50690162 | K42: 0.068898339 | L42: 0.43811525 | M42: =IF(OR(J42="",J42=0),"",K42/J42) -> 0.13592053
I43: 2022-02 | J43: 0.52319257 | K43: 0.0704071 | L43: 0.45303222 | M43: =IF(OR(J43="",J43=0),"",K43/J43) -> 0.13457206
I44: 2022-03 | J44: 0.5510663 | K44: 0.080177349 | L44: 0.47089873 | M44: =IF(OR(J44="",J44=0),"",K44/J44) -> 0.14549492
I45: 2022-04 | J45: 0.58038009 | K45: 0.080773537 | L45: 0.4997397 | M45: =IF(OR(J45="",J45=0),"",K45/J45) -> 0.13917352
I46: 2022-05 | J46: 0.6067993 | K46: 0.086205613 | L46: 0.52092212 | M46: =IF(OR(J46="",J46=0),"",K46/J46) -> 0.14206611
I47: 2022-06 | J47: 0.63982582 | K47: 0.091822815 | L47: 0.54849039 | M47: =IF(OR(J47="",J47=0),"",K47/J47) -> 0.14351221
I48: 2022-07 | J48: 0.71002454 | K48: 0.10011633 | L48: 0.61044023 | M48: =IF(OR(J48="",J48=0),"",K48/J48) -> 0.14100404
I49: 2022-08 | J49: 0.78515273 | K49: 0.11356005 | L49: 0.67211804 | M49: =IF(OR(J49="",J49=0),"",K49/J49) -> 0.14463435
I50: 2022-09 | J50: 0.83029982 | K50: 0.11758072 | L50: 0.71343205 | M50: =IF(OR(J50="",J50=0),"",K50/J50) -> 0.14161236
I51: 2022-10 | J51: 0.88035685 | K51: 0.13203899 | L51: 0.74901641 | M51: =IF(OR(J51="",J51=0),"",K51/J51) -> 0.14998349
I52: 2022-11 | J52: 0.92412782 | K52: 0.14625078 | L52: 0.77872349 | M52: =IF(OR(J52="",J52=0),"",K52/J52) -> 0.15825817
I53: 2022-12 | J53: 0.94793182 | K53: 0.15404693 | L53: 0.79498781 | M53: =IF(OR(J53="",J53=0),"",K53/J53) -> 0.16250845
I54: 2023-01 | J54: 0.98829086 | K54: 0.1663488 | L54: 0.82277547 | M54: =IF(OR(J54="",J54=0),"",K54/J54) -> 0.16831968
... I93: 2026-04 | J93: 0.32350448 | K93: 0.086955476 | L93: 0.23647423 | M93: =IF(OR(J93="",J93=0),"",K93/J93) -> 0.26879218
I95: Source: INDEC IPC by category with the regulated weight estimated at 21.0% of the basket (IPC_Regulados_Annual.xlsx, tab 'Weights'). Contributions are weight x category y/y and sum to headline. Data run to 2026-04.

Sheet Ch1 GDP contributions
C2: Contributions to real GDP growth, y/y
C3: Demand-side decomposition, percentage points. Paste INDEC constant-price levels (millions of 2004 pesos).
C4: Chart runs from 2023-Q1; 2022 rows are the base for the first y/y. Imports enter with the sign already flipped, so the six bars sum to GDP growth.
B5: POPULATED FROM SOURCE — blue cells are data, black are formulas
B6: Period | C6: Private consumption | D6: Government consumption | E6: GFCF (IBIF) | F6: Inventories + discrepancy | G6: Exports | H6: Imports | I6: GDP | J6: Consumption pp | K6: Government pp | L6: GFCF pp | M6: Invent.+disc. pp | N6: Exports pp | O6: Imports pp | P6: GDP y/y % | Q6: Check: sum − GDP (should be 0)
B8: 2022-Q1 | C8: 516582.48 | D8: 94876.315 | E8: 143683.72 | F8: -10285.127 | G8: 135342.64 | H8: 182574.75 | I8: 697625.28
B9: 2022-Q2 | C9: 576435.44 | D9: 99651.253 | E9: 160568.55 | F9: -7371.0004 | G9: 157619.7 | H9: 204565.31 | I9: 782338.63
B10: 2022-Q3 | C10: 497399.58 | D10: 96128.789 | E10: 160952.87 | F10: 22366.004 | G10: 157115.55 | H10: 201300.63 | I10: 732662.16
B11: 2022-Q4 | C11: 490167.72 | D11: 100882.29 | E11: 148604.11 | F11: 3388.3809 | G11: 154135.03 | H11: 184437.07 | I11: 712740.46
B12: 2023-Q1 | C12: 535974.73 | D12: 97699.373 | E12: 141756.11 | F12: -8051.1048 | G12: 126446.8 | H12: 189816.87 | I12: 704009.04 | J12: =IF(OR(C12="",C8="",$I8=""),"",(C12-C8)/$I8) -> 0.027797511 | K12: =IF(OR(D12="",D8="",$I8=""),"",(D12-D8)/$I8) -> 0.0040466674 | L12: =IF(OR(E12="",E8="",$I8=""),"",(E12-E8)/$I8) -> -0.0027631036 | M12: =IF(OR(F12="",F8="",$I8=""),"",(F12-F8)/$I8) -> 0.0032023245 | N12: =IF(OR(G12="",G8="",$I8=""),"",(G12-G8)/$I8) -> -0.012751609 | O12: =IF(OR(H12="",H8="",$I8=""),"",-(H12-H8)/$I8) -> -0.010381103 | P12: =IF(OR(I12="",I8=""),"",I12/I8-1) -> 0.0091506868 | Q12: =IF(P12="","",SUM(J12:O12)-P12) -> 9.8705766e-16
B13: 2023-Q2 | C13: 588087.03 | D13: 104013.85 | E13: 157587.98 | F13: -36051.054 | G13: 136912.27 | H13: 212421.67 | I13: 738128.41 | J13: =IF(OR(C13="",C9="",$I9=""),"",(C13-C9)/$I9) -> 0.014893286 | K13: =IF(OR(D13="",D9="",$I9=""),"",(D13-D9)/$I9) -> 0.0055763556 | L13: =IF(OR(E13="",E9="",$I9=""),"",(E13-E9)/$I9) -> -0.0038098268 | M13: =IF(OR(F13="",F9="",$I9=""),"",(F13-F9)/$I9) -> -0.036659386 | N13: =IF(OR(G13="",G9="",$I9=""),"",(G13-G9)/$I9) -> -0.026468624 | O13: =IF(OR(H13="",H9="",$I9=""),"",-(H13-H9)/$I9) -> -0.010042139 | P13: =IF(OR(I13="",I9=""),"",I13/I9-1) -> -0.056510334 | Q13: =IF(P13="","",SUM(J13:O13)-P13) -> 6.5225603e-16
B14: 2023-Q3 | C14: 496373.77 | D14: 99537.229 | E14: 162177.09 | F14: 31511.919 | G14: 143916.19 | H14: 204973.94 | I14: 728542.26 | J14: =IF(OR(C14="",C10="",$I10=""),"",(C14-C10)/$I10) -> -0.0014001165 | K14: =IF(OR(D14="",D10="",$I10=""),"",(D14-D10)/$I10) -> 0.0046521309 | L14: =IF(OR(E14="",E10="",$I10=""),"",(E14-E10)/$I10) -> 0.0016709168 | M14: =IF(OR(F14="",F10="",$I10=""),"",(F14-F10)/$I10) -> 0.012483127 | N14: =IF(OR(G14="",G10="",$I10=""),"",(G14-G10)/$I10) -> -0.018015615 | O14: =IF(OR(H14="",H10="",$I10=""),"",-(H14-H10)/$I10) -> -0.0050136465 | P14: =IF(OR(I14="",I10=""),"",I14/I10-1) -> -0.0056232029 | Q14: =IF(P14="","",SUM(J14:O14)-P14) -> -2.6176977e-15
B15: 2023-Q4 | C15: 480687.41 | D15: 99272.705 | E15: 137053.09 | F15: 30180.388 | G15: 136117.33 | H15: 182767.72 | I15: 700543.2 | J15: =IF(OR(C15="",C11="",$I11=""),"",(C15-C11)/$I11) -> -0.013301208 | K15: =IF(OR(D15="",D11="",$I11=""),"",(D15-D11)/$I11) -> -0.0022582985 | L15: =IF(OR(E15="",E11="",$I11=""),"",(E15-E11)/$I11) -> -0.016206495 | M15: =IF(OR(F15="",F11="",$I11=""),"",(F15-F11)/$I11) -> 0.037590131 | N15: =IF(OR(G15="",G11="",$I11=""),"",(G15-G11)/$I11) -> -0.025279465 | O15: =IF(OR(H15="",H11="",$I11=""),"",-(H15-H11)/$I11) -> 0.0023421513 | P15: =IF(OR(I15="",I11=""),"",I15/I11-1) -> -0.017113185 | Q15: =IF(P15="","",SUM(J15:O15)-P15) -> -5.7592819e-16
B16: 2024-Q1 | C16: 508286.75 | D16: 93290.784 | E16: 107772.24 | F16: -24824.302 | G16: 147382.29 | H16: 163688.13 | I16: 668219.63 | J16: =IF(OR(C16="",C12="",$I12=""),"",(C16-C12)/$I12) -> -0.03932901 | K16: =IF(OR(D16="",D12="",$I12=""),"",(D16-D12)/$I12) -> -0.0062621193 | L16: =IF(OR(E16="",E12="",$I12=""),"",(E16-E12)/$I12) -> -0.04827192 | M16: =IF(OR(F16="",F12="",$I12=""),"",(F16-F12)/$I12) -> -0.023825258 | N16: =IF(OR(G16="",G12="",$I12=""),"",(G16-G12)/$I12) -> 0.02973753 | O16: =IF(OR(H16="",H12="",$I12=""),"",-(H16-H12)/$I12) -> 0.037114207 | P16: =IF(OR(I16="",I12=""),"",I16/I12-1) -> -0.05083657 | Q16: =IF(P16="","",SUM(J16:O16)-P16) -> -9.15934e-16
B17: 2024-Q2 | C17: 538393.96 | D17: 98261.488 | E17: 111250.68 | F17: -18156.725 | G17: 164179.76 | H17: 164019.8 | I17: 729909.37 | J17: =IF(OR(C17="",C13="",$I13=""),"",(C17-C13)/$I13) -> -0.067323065 | K17: =IF(OR(D17="",D13="",$I13=""),"",(D17-D13)/$I13) -> -0.0077931733 | L17: =IF(OR(E17="",E13="",$I13=""),"",(E17-E13)/$I13) -> -0.062776746 | M17: =IF(OR(F17="",F13="",$I13=""),"",(F17-F13)/$I13) -> 0.02424284 | N17: =IF(OR(G17="",G13="",$I13=""),"",(G17-G13)/$I13) -> 0.036941387 | O17: =IF(OR(H17="",H13="",$I13=""),"",-(H17-H13)/$I13) -> 0.06557378 | P17: =IF(OR(I17="",I13=""),"",I17/I13-1) -> -0.011134976 | Q17: =IF(P17="","",SUM(J17:O17)-P17) -> 3.469447e-16
B18: 2024-Q3 | C18: 490119.31 | D18: 95614.376 | E18: 134999.68 | F18: 1861.2691 | G18: 172087.52 | H18: 180382.93 | I18: 714299.22 | J18: =IF(OR(C18="",C14="",$I14=""),"",(C18-C14)/$I14) -> -0.0085848964 | K18: =IF(OR(D18="",D14="",$I14=""),"",(D18-D14)/$I14) -> -0.0053845233 | L18: =IF(OR(E18="",E14="",$I14=""),"",(E18-E14)/$I14) -> -0.037303826 | M18: =IF(OR(F18="",F14="",$I14=""),"",(F18-F14)/$I14) -> -0.0406986 | N18: =IF(OR(G18="",G14="",$I14=""),"",(G18-G14)/$I14) -> 0.038668075 | O18: =IF(OR(H18="",H14="",$I14=""),"",-(H18-H14)/$I14) -> 0.03375372 | P18: =IF(OR(I18="",I14=""),"",I18/I14-1) -> -0.01955005 | Q18: =IF(P18="","",SUM(J18:O18)-P18) -> 1.6445179e-15
B19: 2024-Q4 | C19: 504095.17 | D19: 101219.34 | E19: 139618.48 | F19: 1560.5084 | G19: 172594.56 | H19: 199564.73 | I19: 719523.32 | J19: =IF(OR(C19="",C15="",$I15=""),"",(C19-C15)/$I15) -> 0.033413722 | K19: =IF(OR(D19="",D15="",$I15=""),"",(D19-D15)/$I15) -> 0.0027787572 | L19: =IF(OR(E19="",E15="",$I15=""),"",(E19-E15)/$I15) -> 0.0036620014 | M19: =IF(OR(F19="",F15="",$I15=""),"",(F19-F15)/$I15) -> -0.04085384 | N19: =IF(OR(G19="",G15="",$I15=""),"",(G19-G15)/$I15) -> 0.052069911 | O19: =IF(OR(H19="",H15="",$I15=""),"",-(H19-H15)/$I15) -> -0.023977117 | P19: =IF(OR(I19="",I15=""),"",I19/I15-1) -> 0.027093436 | Q19: =IF(P19="","",SUM(J19:O19)-P19) -> 7.5633944e-16
B20: 2025-Q1 | C20: 566590.76 | D20: 91687.793 | E20: 141620.55 | F20: -17572.916 | G20: 156881.31 | H20: 230112.38 | I20: 709095.12 | J20: =IF(OR(C20="",C16="",$I16=""),"",(C20-C16)/$I16) -> 0.087252764 | K20: =IF(OR(D20="",D16="",$I16=""),"",(D20-D16)/$I16) -> -0.0023988993 | L20: =IF(OR(E20="",E16="",$I16=""),"",(E20-E16)/$I16) -> 0.050654468 | M20: =IF(OR(F20="",F16="",$I16=""),"",(F20-F16)/$I16) -> 0.0108518 | N20: =IF(OR(G20="",G16="",$I16=""),"",(G20-G16)/$I16) -> 0.014215424 | O20: =IF(OR(H20="",H16="",$I16=""),"",-(H20-H16)/$I16) -> -0.09940481 | P20: =IF(OR(I20="",I16=""),"",I20/I16-1) -> 0.061170747 | Q20: =IF(P20="","",SUM(J20:O20)-P20) -> 0
B21: 2025-Q2 | C21: 601163.87 | D21: 99731.984 | E21: 147249.23 | F21: -12464.021 | G21: 169976.52 | H21: 228175.02 | I21: 777482.56 | J21: =IF(OR(C21="",C17="",$I17=""),"",(C21-C17)/$I17) -> 0.085996844 | K21: =IF(OR(D21="",D17="",$I17=""),"",(D21-D17)/$I17) -> 0.0020146279 | L21: =IF(OR(E21="",E17="",$I17=""),"",(E21-E17)/$I17) -> 0.049319207 | M21: =IF(OR(F21="",F17="",$I17=""),"",(F21-F17)/$I17) -> 0.0077991926 | N21: =IF(OR(G21="",G17="",$I17=""),"",(G21-G17)/$I17) -> 0.0079417543 | O21: =IF(OR(H21="",H17="",$I17=""),"",-(H21-H17)/$I17) -> -0.087894785 | P21: =IF(OR(I21="",I17=""),"",I21/I17-1) -> 0.065176841 | Q21: =IF(P21="","",SUM(J21:O21)-P21) -> 3.8857806e-16
B22: 2025-Q3 | C22: 522534.77 | D22: 96837.224 | E22: 148829.51 | F22: 5036.7038 | G22: 189756.07 | H22: 225859.21 | I22: 737135.07 | J22: =IF(OR(C22="",C18="",$I18=""),"",(C22-C18)/$I18) -> 0.045380793 | K22: =IF(OR(D22="",D18="",$I18=""),"",(D22-D18)/$I18) -> 0.0017119547 | L22: =IF(OR(E22="",E18="",$I18=""),"",(E22-E18)/$I18) -> 0.019361397 | M22: =IF(OR(F22="",F18="",$I18=""),"",(F22-F18)/$I18) -> 0.0044455245 | N22: =IF(OR(G22="",G18="",$I18=""),"",(G22-G18)/$I18) -> 0.024735513 | O22: =IF(OR(H22="",H18="",$I18=""),"",-(H22-H18)/$I18) -> -0.063665597 | P22: =IF(OR(I22="",I18=""),"",I22/I18-1) -> 0.031969585 | Q22: =IF(P22="","",SUM(J22:O22)-P22) -> -4.0245585e-16
B23: 2025-Q4 | C23: 525445.78 | D23: 101592.27 | E23: 135974 | F23: 933.07651 | G23: 192971.24 | H23: 221714.27 | I23: 735202.11 | J23: =IF(OR(C23="",C19="",$I19=""),"",(C23-C19)/$I19) -> 0.029673279 | K23: =IF(OR(D23="",D19="",$I19=""),"",(D23-D19)/$I19) -> 0.00051830121 | L23: =IF(OR(E23="",E19="",$I19=""),"",(E23-E19)/$I19) -> -0.0050651191 | M23: =IF(OR(F23="",F19="",$I19=""),"",(F23-F19)/$I19) -> -0.00087201048 | N23: =IF(OR(G23="",G19="",$I19=""),"",(G23-G19)/$I19) -> 0.028319701 | O23: =IF(OR(H23="",H19="",$I19=""),"",-(H23-H19)/$I19) -> -0.030783635 | P23: =IF(OR(I23="",I19=""),"",I23/I19-1) -> 0.021790516 | Q23: =IF(P23="","",SUM(J23:O23)-P23) -> -2.1753432e-15
B24: 2026-Q1 | C24: 582154.8 | D24: 90857.061 | E24: 125135.44 | F24: -31897.148 | G24: 172306.88 | H24: 212956.78 | I24: 725600.24 | J24: =IF(OR(C24="",C20="",$I20=""),"",(C24-C20)/$I20) -> 0.021949153 | K24: =IF(OR(D24="",D20="",$I20=""),"",(D24-D20)/$I20) -> -0.0011715373 | L24: =IF(OR(E24="",E20="",$I20=""),"",(E24-E20)/$I20) -> -0.023248095 | M24: =IF(OR(F24="",F20="",$I20=""),"",(F24-F20)/$I20) -> -0.020200721 | N24: =IF(OR(G24="",G20="",$I20=""),"",(G24-G20)/$I20) -> 0.021753871 | O24: =IF(OR(H24="",H20="",$I20=""),"",-(H24-H20)/$I20) -> 0.024193642 | P24: =IF(OR(I24="",I20=""),"",I24/I20-1) -> 0.023276313 | Q24: =IF(P24="","",SUM(J24:O24)-P24) -> 0
B25: 2026-Q2 | J25: =IF(OR(C25="",C21="",$I21=""),"",(C25-C21)/$I21) | K25: =IF(OR(D25="",D21="",$I21=""),"",(D25-D21)/$I21) | L25: =IF(OR(E25="",E21="",$I21=""),"",(E25-E21)/$I21) | M25: =IF(OR(F25="",F21="",$I21=""),"",(F25-F21)/$I21) | N25: =IF(OR(G25="",G21="",$I21=""),"",(G25-G21)/$I21) | O25: =IF(OR(H25="",H21="",$I21=""),"",-(H25-H21)/$I21) | P25: =IF(OR(I25="",I21=""),"",I25/I21-1) | Q25: =IF(P25="","",SUM(J25:O25)-P25)
B26: 2026-Q3 | J26: =IF(OR(C26="",C22="",$I22=""),"",(C26-C22)/$I22) | K26: =IF(OR(D26="",D22="",$I22=""),"",(D26-D22)/$I22) | L26: =IF(OR(E26="",E22="",$I22=""),"",(E26-E22)/$I22) | M26: =IF(OR(F26="",F22="",$I22=""),"",(F26-F22)/$I22) | N26: =IF(OR(G26="",G22="",$I22=""),"",(G26-G22)/$I22) | O26: =IF(OR(H26="",H22="",$I22=""),"",-(H26-H22)/$I22) | P26: =IF(OR(I26="",I22=""),"",I26/I22-1) | Q26: =IF(P26="","",SUM(J26:O26)-P26)
B27: 2026-Q4 | J27: =IF(OR(C27="",C23="",$I23=""),"",(C27-C23)/$I23) | K27: =IF(OR(D27="",D23="",$I23=""),"",(D27-D23)/$I23) | L27: =IF(OR(E27="",E23="",$I23=""),"",(E27-E23)/$I23) | M27: =IF(OR(F27="",F23="",$I23=""),"",(F27-F23)/$I23) | N27: =IF(OR(G27="",G23="",$I23=""),"",(G27-G23)/$I23) | O27: =IF(OR(H27="",H23="",$I23=""),"",-(H27-H23)/$I23) | P27: =IF(OR(I27="",I23=""),"",I27/I23-1) | Q27: =IF(P27="","",SUM(J27:O27)-P27)
B28: 2027-Q1 | J28: =IF(OR(C28="",C24="",$I24=""),"",(C28-C24)/$I24) | K28: =IF(OR(D28="",D24="",$I24=""),"",(D28-D24)/$I24) | L28: =IF(OR(E28="",E24="",$I24=""),"",(E28-E24)/$I24) | M28: =IF(OR(F28="",F24="",$I24=""),"",(F28-F24)/$I24) | N28: =IF(OR(G28="",G24="",$I24=""),"",(G28-G24)/$I24) | O28: =IF(OR(H28="",H24="",$I24=""),"",-(H28-H24)/$I24) | P28: =IF(OR(I28="",I24=""),"",I28/I24-1) | Q28: =IF(P28="","",SUM(J28:O28)-P28)
B29: 2027-Q2 | J29: =IF(OR(C29="",C25="",$I25=""),"",(C29-C25)/$I25) | K29: =IF(OR(D29="",D25="",$I25=""),"",(D29-D25)/$I25) | L29: =IF(OR(E29="",E25="",$I25=""),"",(E29-E25)/$I25) | M29: =IF(OR(F29="",F25="",$I25=""),"",(F29-F25)/$I25) | N29: =IF(OR(G29="",G25="",$I25=""),"",(G29-G25)/$I25) | O29: =IF(OR(H29="",H25="",$I25=""),"",-(H29-H25)/$I25) | P29: =IF(OR(I29="",I25=""),"",I29/I25-1) | Q29: =IF(P29="","",SUM(J29:O29)-P29)
B30: 2027-Q3 | J30: =IF(OR(C30="",C26="",$I26=""),"",(C30-C26)/$I26) | K30: =IF(OR(D30="",D26="",$I26=""),"",(D30-D26)/$I26) | L30: =IF(OR(E30="",E26="",$I26=""),"",(E30-E26)/$I26) | M30: =IF(OR(F30="",F26="",$I26=""),"",(F30-F26)/$I26) | N30: =IF(OR(G30="",G26="",$I26=""),"",(G30-G26)/$I26) | O30: =IF(OR(H30="",H26="",$I26=""),"",-(H30-H26)/$I26) | P30: =IF(OR(I30="",I26=""),"",I30/I26-1) | Q30: =IF(P30="","",SUM(J30:O30)-P30)
B31: 2027-Q4 | J31: =IF(OR(C31="",C27="",$I27=""),"",(C31-C27)/$I27) | K31: =IF(OR(D31="",D27="",$I27=""),"",(D31-D27)/$I27) | L31: =IF(OR(E31="",E27="",$I27=""),"",(E31-E27)/$I27) | M31: =IF(OR(F31="",F27="",$I27=""),"",(F31-F27)/$I27) | N31: =IF(OR(G31="",G27="",$I27=""),"",(G31-G27)/$I27) | O31: =IF(OR(H31="",H27="",$I27=""),"",-(H31-H27)/$I27) | P31: =IF(OR(I31="",I27=""),"",I31/I27-1) | Q31: =IF(P31="","",SUM(J31:O31)-P31)
B33: Source: INDEC, Oferta y demanda globales, precios constantes base 2004, valores trimestrales (dataset 4.2). Bulk CSV: infra.datos.gob.ar/catalog/sspm/dataset/4.0/distribution/4.2/. IMPORTANT: quarterly national accounts are published at ANNUAL RATES — a year's level is the AVERAGE of its four quarters, never the sum. The statistical discrepancy exists only from Q1-2024; before that it sits inside variación de existencias, which is why the two are combined in one column. Levels taken from Argentina_GDP.xlsx, tab 'Data Constant', which carries the INDEC vintage through 2026-Q1; contributions are recomputed here rather than copied.

Sheet Ch2 Industry vs mining
C2: Manufacturing decline is not offset by oil and mining
C3: Activity rebased to Nov-2023 = 100; jobs as cumulative change on Nov-2023, in thousands.
C4: The black line is the net of the two. If mining and oil were offsetting manufacturing, it would sit near zero.
B5: PASTE INTO THE YELLOW COLUMNS →
B6: Period | C6: EMAE Manufacturing (index 2004=100) | D6: EMAE Mining & quarrying (index 2004=100) | E6: Registered jobs — manufacturing (000s) | F6: Registered jobs — mining & oil (000s) | G6: Manufacturing Nov-23=100 | H6: Mining Nov-23=100 | I6: Manufacturing jobs, change vs Nov-23 (000s) | J6: Mining & oil jobs, change vs Nov-23 (000s) | K6: Net jobs, both sectors (000s)
B7: EXAMPLE — overwrite | C7: 138.2 | D7: 121.5 | E7: 1215 | F7: 92
B8: 2023-01 | G8: =IF(OR(C8="",C$18=""),"",C8/C$18*100) | H8: =IF(OR(D8="",D$18=""),"",D8/D$18*100) | I8: =IF(OR(E8="",E$18=""),"",E8-E$18) | J8: =IF(OR(F8="",F$18=""),"",F8-F$18) | K8: =IF(OR(I8="",J8=""),"",I8+J8)
B9: 2023-02 | G9: =IF(OR(C9="",C$18=""),"",C9/C$18*100) | H9: =IF(OR(D9="",D$18=""),"",D9/D$18*100) | I9: =IF(OR(E9="",E$18=""),"",E9-E$18) | J9: =IF(OR(F9="",F$18=""),"",F9-F$18) | K9: =IF(OR(I9="",J9=""),"",I9+J9)
B10: 2023-03 | G10: =IF(OR(C10="",C$18=""),"",C10/C$18*100) | H10: =IF(OR(D10="",D$18=""),"",D10/D$18*100) | I10: =IF(OR(E10="",E$18=""),"",E10-E$18) | J10: =IF(OR(F10="",F$18=""),"",F10-F$18) | K10: =IF(OR(I10="",J10=""),"",I10+J10)
B11: 2023-04 | G11: =IF(OR(C11="",C$18=""),"",C11/C$18*100) | H11: =IF(OR(D11="",D$18=""),"",D11/D$18*100) | I11: =IF(OR(E11="",E$18=""),"",E11-E$18) | J11: =IF(OR(F11="",F$18=""),"",F11-F$18) | K11: =IF(OR(I11="",J11=""),"",I11+J11)
B12: 2023-05 | G12: =IF(OR(C12="",C$18=""),"",C12/C$18*100) | H12: =IF(OR(D12="",D$18=""),"",D12/D$18*100) | I12: =IF(OR(E12="",E$18=""),"",E12-E$18) | J12: =IF(OR(F12="",F$18=""),"",F12-F$18) | K12: =IF(OR(I12="",J12=""),"",I12+J12)
B13: 2023-06 | G13: =IF(OR(C13="",C$18=""),"",C13/C$18*100) | H13: =IF(OR(D13="",D$18=""),"",D13/D$18*100) | I13: =IF(OR(E13="",E$18=""),"",E13-E$18) | J13: =IF(OR(F13="",F$18=""),"",F13-F$18) | K13: =IF(OR(I13="",J13=""),"",I13+J13)
B14: 2023-07 | G14: =IF(OR(C14="",C$18=""),"",C14/C$18*100) | H14: =IF(OR(D14="",D$18=""),"",D14/D$18*100) | I14: =IF(OR(E14="",E$18=""),"",E14-E$18) | J14: =IF(OR(F14="",F$18=""),"",F14-F$18) | K14: =IF(OR(I14="",J14=""),"",I14+J14)
B15: 2023-08 | G15: =IF(OR(C15="",C$18=""),"",C15/C$18*100) | H15: =IF(OR(D15="",D$18=""),"",D15/D$18*100) | I15: =IF(OR(E15="",E$18=""),"",E15-E$18) | J15: =IF(OR(F15="",F$18=""),"",F15-F$18) | K15: =IF(OR(I15="",J15=""),"",I15+J15)
B16: 2023-09 | G16: =IF(OR(C16="",C$18=""),"",C16/C$18*100) | H16: =IF(OR(D16="",D$18=""),"",D16/D$18*100) | I16: =IF(OR(E16="",E$18=""),"",E16-E$18) | J16: =IF(OR(F16="",F$18=""),"",F16-F$18) | K16: =IF(OR(I16="",J16=""),"",I16+J16)
B17: 2023-10 | G17: =IF(OR(C17="",C$18=""),"",C17/C$18*100) | H17: =IF(OR(D17="",D$18=""),"",D17/D$18*100) | I17: =IF(OR(E17="",E$18=""),"",E17-E$18) | J17: =IF(OR(F17="",F$18=""),"",F17-F$18) | K17: =IF(OR(I17="",J17=""),"",I17+J17)
B18: 2023-11 | G18: =IF(OR(C18="",C$18=""),"",C18/C$18*100) | H18: =IF(OR(D18="",D$18=""),"",D18/D$18*100) | I18: =IF(OR(E18="",E$18=""),"",E18-E$18) | J18: =IF(OR(F18="",F$18=""),"",F18-F$18) | K18: =IF(OR(I18="",J18=""),"",I18+J18)
B19: 2023-12 | G19: =IF(OR(C19="",C$18=""),"",C19/C$18*100) | H19: =IF(OR(D19="",D$18=""),"",D19/D$18*100) | I19: =IF(OR(E19="",E$18=""),"",E19-E$18) | J19: =IF(OR(F19="",F$18=""),"",F19-F$18) | K19: =IF(OR(I19="",J19=""),"",I19+J19)
... B67: 2027-12 | G67: =IF(OR(C67="",C$18=""),"",C67/C$18*100) | H67: =IF(OR(D67="",D$18=""),"",D67/D$18*100) | I67: =IF(OR(E67="",E$18=""),"",E67-E$18) | J67: =IF(OR(F67="",F$18=""),"",F67-F$18) | K67: =IF(OR(I67="",J67=""),"",I67+J67)
B69: Sources: INDEC, EMAE apertura por sectores, base 2004 (dataset 11.3 — bulk CSV at infra.datos.gob.ar/catalog/sspm/dataset/11.0/distribution/11.3/), for the two activity indices; and Puestos de trabajo registrados por sector de actividad económica en el sector privado (dataset 325.2) for registered jobs. Nov-2023 is used as the base — the last full month before the change of administration.

Sheet Ch5 Expectations
C2: Inflation expectations, 12 and 24 months ahead
C3: BCRA Relevamiento de Expectativas de Mercado (REM), median of respondents. Enter as fractions: 0.25 = 25%.
B5: PASTE INTO THE YELLOW COLUMNS →
B6: Period | C6: REM expected inflation, next 12 months (%) | D6: REM expected inflation, next 24 months (%) | E6: 1Y − 2Y spread (pp)
B7: EXAMPLE — overwrite | C7: 0.28 | D7: 0.19
B8: 2023-01 | E8: =IF(OR(C8="",D8=""),"",C8-D8)
B9: 2023-02 | E9: =IF(OR(C9="",D9=""),"",C9-D9)
B10: 2023-03 | E10: =IF(OR(C10="",D10=""),"",C10-D10)
B11: 2023-04 | E11: =IF(OR(C11="",D11=""),"",C11-D11)
B12: 2023-05 | E12: =IF(OR(C12="",D12=""),"",C12-D12)
B13: 2023-06 | E13: =IF(OR(C13="",D13=""),"",C13-D13)
B14: 2023-07 | E14: =IF(OR(C14="",D14=""),"",C14-D14)
B15: 2023-08 | E15: =IF(OR(C15="",D15=""),"",C15-D15)
B16: 2023-09 | E16: =IF(OR(C16="",D16=""),"",C16-D16)
B17: 2023-10 | E17: =IF(OR(C17="",D17=""),"",C17-D17)
B18: 2023-11 | E18: =IF(OR(C18="",D18=""),"",C18-D18)
B19: 2023-12 | E19: =IF(OR(C19="",D19=""),"",C19-D19)
... B67: 2027-12 | E67: =IF(OR(C67="",D67=""),"",C67-D67)
B69: Source: BCRA, Relevamiento de Expectativas de Mercado (REM), published around the 6th of each month at bcra.gob.ar. The 24-month horizon is the closest thing Argentina has to a long-term expectations anchor; the gap between the two is the market's implied disinflation path.

Sheet Ch6 Trade balance
C2: Goods trade balance, 12-month rolling
C3: Total balance in bars; energy and non-energy balances as lines. USD millions.
C4: Rolling sums need 12 months of history, so the first usable reading is Dec-2015. Chart categories start Jul-2016 to give a clean ten years.
B5: PASTE INTO THE YELLOW COLUMNS →
B6: Period | C6: Exports, total (USD mn) | D6: Imports, total (USD mn, CIF) | E6: Energy exports (Comb. y energía) | F6: Energy imports (Comb. y lubricantes) | G6: Total balance (monthly) | H6: Energy balance (monthly) | I6: Non-energy balance (monthly) | J6: Total balance 12m rolling | K6: Energy balance 12m rolling | L6: Non-energy balance 12m rolling
B7: EXAMPLE — overwrite | C7: 5200 | D7: 4800 | E7: 520 | F7: 640
B8: 2015-01 | G8: =IF(OR(C8="",D8=""),"",C8-D8) | H8: =IF(OR(E8="",F8=""),"",E8-F8) | I8: =IF(OR(G8="",H8=""),"",G8-H8)
B9: 2015-02 | G9: =IF(OR(C9="",D9=""),"",C9-D9) | H9: =IF(OR(E9="",F9=""),"",E9-F9) | I9: =IF(OR(G9="",H9=""),"",G9-H9)
B10: 2015-03 | G10: =IF(OR(C10="",D10=""),"",C10-D10) | H10: =IF(OR(E10="",F10=""),"",E10-F10) | I10: =IF(OR(G10="",H10=""),"",G10-H10)
B11: 2015-04 | G11: =IF(OR(C11="",D11=""),"",C11-D11) | H11: =IF(OR(E11="",F11=""),"",E11-F11) | I11: =IF(OR(G11="",H11=""),"",G11-H11)
B12: 2015-05 | G12: =IF(OR(C12="",D12=""),"",C12-D12) | H12: =IF(OR(E12="",F12=""),"",E12-F12) | I12: =IF(OR(G12="",H12=""),"",G12-H12)
B13: 2015-06 | G13: =IF(OR(C13="",D13=""),"",C13-D13) | H13: =IF(OR(E13="",F13=""),"",E13-F13) | I13: =IF(OR(G13="",H13=""),"",G13-H13)
B14: 2015-07 | G14: =IF(OR(C14="",D14=""),"",C14-D14) | H14: =IF(OR(E14="",F14=""),"",E14-F14) | I14: =IF(OR(G14="",H14=""),"",G14-H14)
B15: 2015-08 | G15: =IF(OR(C15="",D15=""),"",C15-D15) | H15: =IF(OR(E15="",F15=""),"",E15-F15) | I15: =IF(OR(G15="",H15=""),"",G15-H15)
B16: 2015-09 | G16: =IF(OR(C16="",D16=""),"",C16-D16) | H16: =IF(OR(E16="",F16=""),"",E16-F16) | I16: =IF(OR(G16="",H16=""),"",G16-H16)
B17: 2015-10 | G17: =IF(OR(C17="",D17=""),"",C17-D17) | H17: =IF(OR(E17="",F17=""),"",E17-F17) | I17: =IF(OR(G17="",H17=""),"",G17-H17)
B18: 2015-11 | G18: =IF(OR(C18="",D18=""),"",C18-D18) | H18: =IF(OR(E18="",F18=""),"",E18-F18) | I18: =IF(OR(G18="",H18=""),"",G18-H18)
B19: 2015-12 | G19: =IF(OR(C19="",D19=""),"",C19-D19) | H19: =IF(OR(E19="",F19=""),"",E19-F19) | I19: =IF(OR(G19="",H19=""),"",G19-H19) | J19: =IF(COUNT(G8:G19)<12,"",SUM(G8:G19)) | K19: =IF(COUNT(H8:H19)<12,"",SUM(H8:H19)) | L19: =IF(COUNT(I8:I19)<12,"",SUM(I8:I19))
B20: 2016-01 | G20: =IF(OR(C20="",D20=""),"",C20-D20) | H20: =IF(OR(E20="",F20=""),"",E20-F20) | I20: =IF(OR(G20="",H20=""),"",G20-H20) | J20: =IF(COUNT(G9:G20)<12,"",SUM(G9:G20)) | K20: =IF(COUNT(H9:H20)<12,"",SUM(H9:H20)) | L20: =IF(COUNT(I9:I20)<12,"",SUM(I9:I20))
B21: 2016-02 | G21: =IF(OR(C21="",D21=""),"",C21-D21) | H21: =IF(OR(E21="",F21=""),"",E21-F21) | I21: =IF(OR(G21="",H21=""),"",G21-H21) | J21: =IF(COUNT(G10:G21)<12,"",SUM(G10:G21)) | K21: =IF(COUNT(H10:H21)<12,"",SUM(H10:H21)) | L21: =IF(COUNT(I10:I21)<12,"",SUM(I10:I21))
B22: 2016-03 | G22: =IF(OR(C22="",D22=""),"",C22-D22) | H22: =IF(OR(E22="",F22=""),"",E22-F22) | I22: =IF(OR(G22="",H22=""),"",G22-H22) | J22: =IF(COUNT(G11:G22)<12,"",SUM(G11:G22)) | K22: =IF(COUNT(H11:H22)<12,"",SUM(H11:H22)) | L22: =IF(COUNT(I11:I22)<12,"",SUM(I11:I22))
B23: 2016-04 | G23: =IF(OR(C23="",D23=""),"",C23-D23) | H23: =IF(OR(E23="",F23=""),"",E23-F23) | I23: =IF(OR(G23="",H23=""),"",G23-H23) | J23: =IF(COUNT(G12:G23)<12,"",SUM(G12:G23)) | K23: =IF(COUNT(H12:H23)<12,"",SUM(H12:H23)) | L23: =IF(COUNT(I12:I23)<12,"",SUM(I12:I23))
B24: 2016-05 | G24: =IF(OR(C24="",D24=""),"",C24-D24) | H24: =IF(OR(E24="",F24=""),"",E24-F24) | I24: =IF(OR(G24="",H24=""),"",G24-H24) | J24: =IF(COUNT(G13:G24)<12,"",SUM(G13:G24)) | K24: =IF(COUNT(H13:H24)<12,"",SUM(H13:H24)) | L24: =IF(COUNT(I13:I24)<12,"",SUM(I13:I24))
B25: 2016-06 | G25: =IF(OR(C25="",D25=""),"",C25-D25) | H25: =IF(OR(E25="",F25=""),"",E25-F25) | I25: =IF(OR(G25="",H25=""),"",G25-H25) | J25: =IF(COUNT(G14:G25)<12,"",SUM(G14:G25)) | K25: =IF(COUNT(H14:H25)<12,"",SUM(H14:H25)) | L25: =IF(COUNT(I14:I25)<12,"",SUM(I14:I25))
B26: 2016-07 | G26: =IF(OR(C26="",D26=""),"",C26-D26) | H26: =IF(OR(E26="",F26=""),"",E26-F26) | I26: =IF(OR(G26="",H26=""),"",G26-H26) | J26: =IF(COUNT(G15:G26)<12,"",SUM(G15:G26)) | K26: =IF(COUNT(H15:H26)<12,"",SUM(H15:H26)) | L26: =IF(COUNT(I15:I26)<12,"",SUM(I15:I26))
B27: 2016-08 | G27: =IF(OR(C27="",D27=""),"",C27-D27) | H27: =IF(OR(E27="",F27=""),"",E27-F27) | I27: =IF(OR(G27="",H27=""),"",G27-H27) | J27: =IF(COUNT(G16:G27)<12,"",SUM(G16:G27)) | K27: =IF(COUNT(H16:H27)<12,"",SUM(H16:H27)) | L27: =IF(COUNT(I16:I27)<12,"",SUM(I16:I27))
B28: 2016-09 | G28: =IF(OR(C28="",D28=""),"",C28-D28) | H28: =IF(OR(E28="",F28=""),"",E28-F28) | I28: =IF(OR(G28="",H28=""),"",G28-H28) | J28: =IF(COUNT(G17:G28)<12,"",SUM(G17:G28)) | K28: =IF(COUNT(H17:H28)<12,"",SUM(H17:H28)) | L28: =IF(COUNT(I17:I28)<12,"",SUM(I17:I28))
B29: 2016-10 | G29: =IF(OR(C29="",D29=""),"",C29-D29) | H29: =IF(OR(E29="",F29=""),"",E29-F29) | I29: =IF(OR(G29="",H29=""),"",G29-H29) | J29: =IF(COUNT(G18:G29)<12,"",SUM(G18:G29)) | K29: =IF(COUNT(H18:H29)<12,"",SUM(H18:H29)) | L29: =IF(COUNT(I18:I29)<12,"",SUM(I18:I29))
B30: 2016-11 | G30: =IF(OR(C30="",D30=""),"",C30-D30) | H30: =IF(OR(E30="",F30=""),"",E30-F30) | I30: =IF(OR(G30="",H30=""),"",G30-H30) | J30: =IF(COUNT(G19:G30)<12,"",SUM(G19:G30)) | K30: =IF(COUNT(H19:H30)<12,"",SUM(H19:H30)) | L30: =IF(COUNT(I19:I30)<12,"",SUM(I19:I30))
... B163: 2027-12 | G163: =IF(OR(C163="",D163=""),"",C163-D163) | H163: =IF(OR(E163="",F163=""),"",E163-F163) | I163: =IF(OR(G163="",H163=""),"",G163-H163) | J163: =IF(COUNT(G152:G163)<12,"",SUM(G152:G163)) | K163: =IF(COUNT(H152:H163)<12,"",SUM(H152:H163)) | L163: =IF(COUNT(I152:I163)<12,"",SUM(I152:I163))
