Workbook

Sheet Read me
B2: Argentina — national public sector, revenue, spending and the fiscal adjustment
B3: SPNF base caja (IMIG), millions of pesos, monthly Jan-2016 to May-2026.
B5: What's here
B6: Data | C6: Every published IMIG line, monthly. Blue = source. Capital spending is derived as a residual (total revenue less current primary spending less the primary balance) and reproduces the sum of the twelve published capital lines exactly.
B7: Monthly | C7: Raw monthly flows. Argentine fiscal data is violently seasonal — December alone carries bonus payments and arrears — so never read a single month.
B8: Rolling 12m | C8: Trailing twelve-month sums, nominal. This is the frame to read.
B9: Rolling 12m %GDP | C9: The same sums over trailing four-quarter nominal GDP. Scale-free, so 2017 and 2026 are directly comparable despite a price level that has risen roughly 120-fold.
B10: Annual | C10: Calendar years, nominal and as a share of GDP, plus 2026 year-to-date.
B11: Adjustment | C11: The heart of it: change in each line as a share of GDP between chosen dates, so you can see exactly which spending lines delivered the consolidation and how much each contributed.
B13: Three things to know
B14: Interest is CASH, not accrued | C14: The base caja interest line records interest actually paid. Capitalising instruments (LECAP, BONCAP, duales) accrue interest that never appears here until it is paid. In some months since 2024 that accrual has exceeded the reported overall balance, so the headline financial surplus overstates the accrual position. This is the single biggest caveat in the pack.
B15: Quarterly GDP is at ANNUAL rates | C15: A year's nominal GDP is the AVERAGE of its four quarters, never the sum. The monthly GDP path here is the quarterly flow (level/4) interpolated log-linearly and renormalised so each quarter's three months sum exactly to that quarter.
B16: Q2-2026 GDP is estimated | C16: National accounts run to Q1-2026. Q2-2026 is extrapolated at the Q1 y/y rate to let the ratios run to the last fiscal month. Any month after Mar-2026 carries that assumption.
B18: Validation | C18: Primary balance less interest equals the overall balance on all 125 months (max error 1, rounding). Derived capital spending is positive throughout. Annual nominal GDP for 2025 computes to 850,239,798 million pesos, matching INDEC.
B19: Source | C19: Secretaria de Hacienda, Ministerio de Economia — Informe Mensual de Ingresos y Gastos del SPNF, distribution 452.3 via datos.gob.ar. GDP: INDEC via SSPM distribution 4.4.

Sheet Data
B2: IMIG monthly source data
B3: Millions of pesos. Blue = published. Green = derived / linked.
B6: Month | C6: Year | D6: iva | E6: gan | F6: ss | G6: debcred | H6: bp | I6: internos | J6: comb | K6: dex | L6: dim | M6: restotrib | N6: fgs | O6: rentas | P6: notrib | Q6: transfctes | R6: restoctes | S6: ingcap | T6: jub | U6: asig | V6: pnc | W6: pami | X6: otrosprog | Y6: energia | Z6: transporte | AA6: otrasfunc | AB6: sal | AC6: otrosfunc | AD6: tpeduc | AE6: tpss | AF6: tpds | AG6: tpsalud | AH6: tpotras | AI6: univ | AJ6: emppub | AK6: otrosctes | AL6: cap | AM6: rprim | AN6: int | AO6: rfin | AP6: GDP (month, mn $) | AQ6: Check prim-int-fin
B7: 2016-01 | C7: 2016 | D7: 20467 | E7: 20340 | F7: 50824 | G7: 7765 | H7: 162 | I7: 1570 | J7: 1115 | K7: 5103 | L7: 3846 | M7: 5140 | N7: 1335 | O7: 270 | P7: 2476 | Q7: 30 | R7: 1175 | S7: 3 | T7: 44935 | U7: 5000 | V7: 7270 | W7: 5437 | X7: 1052 | Y7: 3754 | Z7: 5732 | AA7: 138 | AB7: 19099 | AC7: 4448 | AD7: 813 | AE7: 0 | AF7: 27 | AG7: 339 | AH7: 475 | AI7: 4411 | AJ7: 281 | AK7: 2817 | AL7: 14852 | AM7: 741 | AN7: 2938 | AO7: -2197 | AP7: 563619.95 | AQ7: =AM7-AN7-AO7 -> 0
B8: 2016-02 | C8: 2016 | D8: 20110 | E8: 15531 | F8: 37246 | G8: 7233 | H8: 559 | I8: 1692 | J8: 1960 | K8: 3512 | L8: 3679 | M8: 4319 | N8: 792 | O8: 234 | P8: 2293 | Q8: 32 | R8: 1481 | S8: 5 | T8: 40460 | U8: 5842 | V8: 4493 | W8: 5667 | X8: 2302 | Y8: 6464 | Z8: 4963 | AA8: 73 | AB8: 19032 | AC8: 4943 | AD8: 938 | AE8: 0 | AF8: 66 | AG8: 266 | AH8: 158 | AI8: 4187 | AJ8: 1976 | AK8: 5761 | AL8: 9729 | AM8: -16642 | AN8: 3894 | AO8: -20537 | AP8: 576502.06 | AQ8: =AM8-AN8-AO8 -> 1
B9: 2016-03 | C9: 2016 | D9: 21943 | E9: 12671 | F9: 37907 | G9: 7891 | H9: 160 | I9: 1590 | J9: 1855 | K9: 6750 | L9: 4680 | M9: 4287 | N9: 1726 | O9: 481 | P9: 3200 | Q9: 2513 | R9: 1162 | S9: 17 | T9: 47092 | U9: 12034 | V9: 6211 | W9: 5911 | X9: 1475 | Y9: 8585 | Z9: 6181 | AA9: 57 | AB9: 18491 | AC9: 5162 | AD9: 2173 | AE9: 400 | AF9: 260 | AG9: 643 | AH9: 629 | AI9: 4324 | AJ9: 605 | AK9: 5776 | AL9: 12836 | AM9: -30012 | AN9: 11820 | AO9: -41832 | AP9: 611539.25 | AQ9: =AM9-AN9-AO9 -> 0
B10: 2016-04 | C10: 2016 | D10: 22904 | E10: 11898 | F10: 42731 | G10: 8815 | H10: 381 | I10: 1683 | J10: 1894 | K10: 12214 | L10: 4630 | M10: 4854 | N10: 1914 | O10: 493 | P10: 2682 | Q10: 83 | R10: 968 | S10: 3 | T10: 47795 | U10: 7707 | V10: 6169 | W10: 5271 | X10: 2081 | Y10: 8525 | Z10: 6489 | AA10: 166 | AB10: 16944 | AC10: 5068 | AD10: 1668 | AE10: 0 | AF10: 178 | AG10: 352 | AH10: 533 | AI10: 4628 | AJ10: 151 | AK10: 3365 | AL10: 11950 | AM10: -10893 | AN10: 6181 | AO10: -17075 | AP10: 671946.8 | AQ10: =AM10-AN10-AO10 -> 1
B11: 2016-05 | C11: 2016 | D11: 26738 | E11: 25961 | F11: 42640 | G11: 8919 | H11: 2288 | I11: 2108 | J11: 1905 | K11: 8199 | L11: 4519 | M11: 5856 | N11: 1813 | O11: 1008 | P11: 3002 | Q11: 808 | R11: 1175 | S11: 86 | T11: 48802 | U11: 10586 | V11: 7183 | W11: 5893 | X11: 2296 | Y11: 14618 | Z11: 6641 | AA11: 144 | AB11: 17530 | AC11: 6109 | AD11: 1831 | AE11: 0 | AF11: 57 | AG11: 350 | AH11: 677 | AI11: 4874 | AJ11: 985 | AK11: 4609 | AL11: 15814 | AM11: -11974 | AN11: 12019 | AO11: -23994 | AP11: 714236.31 | AQ11: =AM11-AN11-AO11 -> 1
B12: 2016-06 | C12: 2016 | D12: 22218 | E12: 25274 | F12: 43030 | G12: 9263 | H12: 1306 | I12: 2091 | J12: 2690 | K12: 5004 | L12: 4612 | M12: 7201 | N12: 1242 | O12: 440 | P12: 3707 | Q12: 548 | R12: 1360 | S12: 66 | T12: 70396 | U12: 8682 | V12: 8055 | W12: 6271 | X12: 1405 | Y12: 17158 | Z12: 6993 | AA12: 410 | AB12: 20272 | AC12: 6286 | AD12: 1573 | AE12: 0 | AF12: 462 | AG12: 395 | AH12: 680 | AI12: 4671 | AJ12: 745 | AK12: 4544 | AL12: 15062 | AM12: -44008 | AN12: 28579 | AO12: -72587 | AP12: 717456.02 | AQ12: =AM12-AN12-AO12 -> 0
B13: 2016-07 | C13: 2016 | D13: 22482 | E13: 18614 | F13: 59399 | G13: 10098 | H13: 692 | I13: 2098 | J13: 2716 | K13: 7698 | L13: 4727 | M13: 7425 | N13: 1371 | O13: 1229 | P13: 3534 | Q13: 814 | R13: 1372 | S13: 4 | T13: 49197 | U13: 7996 | V13: 5974 | W13: 6323 | X13: 1975 | Y13: 21771 | Z13: 6543 | AA13: 178 | AB13: 27085 | AC13: 6464 | AD13: 2124 | AE13: 6207 | AF13: 363 | AG13: 623 | AH13: 632 | AI13: 7403 | AJ13: 236 | AK13: 5029 | AL13: 12516 | AM13: -24366 | AN13: 3218 | AO13: -27584 | AP13: 704519.81 | AQ13: =AM13-AN13-AO13 -> 0
B14: 2016-08 | C14: 2016 | D14: 24007 | E14: 17507 | F14: 46452 | G14: 9019 | H14: 657 | I14: 2422 | J14: 3041 | K14: 4465 | L14: 4998 | M14: 7160 | N14: 1922 | O14: 1665 | P14: 3785 | Q14: 585 | R14: 1408 | S14: 16 | T14: 49948 | U14: 8868 | V14: 6165 | W14: 9908 | X14: 2422 | Y14: 14912 | Z14: 7910 | AA14: 133 | AB14: 23009 | AC14: 6144 | AD14: 2035 | AE14: 1479 | AF14: 213 | AG14: 805 | AH14: 777 | AI14: 5203 | AJ14: 814 | AK14: 4770 | AL14: 19010 | AM14: -35416 | AN14: 3360 | AO14: -38775 | AP14: 707695.72 | AQ14: =AM14-AN14-AO14 -> -1
B15: 2016-09 | C15: 2016 | D15: 25256 | E15: 17402 | F15: 46070 | G15: 10122 | H15: 250 | I15: 2463 | J15: 2309 | K15: 5249 | L15: 5294 | M15: 6565 | N15: 1940 | O15: 1387 | P15: 4019 | Q15: 1053 | R15: 2372 | S15: 15 | T15: 56049 | U15: 9669 | V15: 6807 | W15: 6615 | X15: 2593 | Y15: 20204 | Z15: 6592 | AA15: 100 | AB15: 24103 | AC15: 6431 | AD15: 2103 | AE15: 1949 | AF15: 598 | AG15: 423 | AH15: 191 | AI15: 4570 | AJ15: 514 | AK15: 5383 | AL15: 13889 | AM15: -37017 | AN15: 11979 | AO15: -48996 | AP15: 719691.67 | AQ15: =AM15-AN15-AO15 -> 0
B16: 2016-10 | C16: 2016 | D16: 22917 | E16: 17777 | F16: 46476 | G16: 9186 | H16: 609 | I16: 2498 | J16: 2443 | K16: 4507 | L16: 4790 | M16: 9138 | N16: 1159 | O16: 641 | P16: 4076 | Q16: 698 | R16: 1107 | S16: 51 | T16: 57252 | U16: 9716 | V16: 6742 | W16: 8106 | X16: 2632 | Y16: 25779 | Z16: 6842 | AA16: 106 | AB16: 23635 | AC16: 11007 | AD16: 1688 | AE16: 1620 | AF16: 398 | AG16: 465 | AH16: 1334 | AI16: 5250 | AJ16: 104 | AK16: 4127 | AL16: 23138 | AM16: -61868 | AN16: 15632 | AO16: -77500 | AP16: 736175.31 | AQ16: =AM16-AN16-AO16 -> 0
B17: 2016-11 | C17: 2016 | D17: 23911 | E17: 19152 | F17: 51942 | G17: 10188 | H17: 176 | I17: 2631 | J17: 2474 | K17: 4313 | L17: 4411 | M17: 18733 | N17: 851 | O17: 489 | P17: 4184 | Q17: 1168 | R17: 997 | S17: 165 | T17: 57463 | U17: 9766 | V17: 9389 | W17: 6946 | X17: 2236 | Y17: 10606 | Z17: 6498 | AA17: 95 | AB17: 22753 | AC17: 8268 | AD17: 816 | AE17: 3081 | AF17: 367 | AG17: 796 | AH17: 1113 | AI17: 5056 | AJ17: 396 | AK17: 2461 | AL17: 10979 | AM17: -13300 | AN17: 6558 | AO17: -19858 | AP17: 748654.01 | AQ17: =AM17-AN17-AO17 -> 0
B18: 2016-12 | C18: 2016 | D18: 24889 | E18: 21295 | F18: 53371 | G18: 10840 | H18: 569 | I18: 2704 | J18: 3594 | K18: 5104 | L18: 5210 | M18: 96513 | N18: 820 | O18: 2339 | P18: 4323 | Q18: 714 | R18: 1654 | S18: 13 | T18: 85081 | U18: 12294 | V18: 5791 | W18: 9061 | X18: 7833 | Y18: 56827 | Z18: 8863 | AA18: 121 | AB18: 34877 | AC18: 9010 | AD18: 2763 | AE18: 4435 | AF18: 723 | AG18: 603 | AH18: 16926 | AI18: 7925 | AJ18: 1332 | AK18: 5988 | AL18: 22268 | AM18: -58769 | AN18: 25081 | AO18: -83850 | AP18: 756122.65 | AQ18: =AM18-AN18-AO18 -> 0
... B131: 2026-05 | C131: 2026 | D131: 2433370 | E131: 2970423 | F131: 4736191 | G131: 1419595 | H131: 27837 | I131: 135477 | J131: 0 | K131: 545337 | L131: 394152 | M131: 872399 | N131: 157659 | O131: 277880 | P131: 380800 | Q131: 9515 | R131: 157201 | S131: 13820 | T131: 5253082 | U131: 900085 | V131: 424468 | W131: 850633 | X131: 953150 | Y131: 523417 | Z131: 258687 | AA131: 2073 | AB131: 1618197 | AC131: 471191 | AD131: 86624 | AE131: 47167 | AF131: 0 | AG131: 16971 | AH131: 9537 | AI131: 780000 | AJ131: 0 | AK131: 228489 | AL131: 183518 | AM131: 1924367 | AN131: 1445754 | AO131: 478613 | AP131: 94319731 | AQ131: =AM131-AN131-AO131 -> 0
B133: Capital spending is the residual of the published identity and matches the sum of the twelve capital lines in the source file.

Sheet Monthly
B2: Monthly flows, nominal
B3: Millions of pesos. Seasonal — do not read a single month in isolation.
B6: Month | C6: TOTAL REVENUE | D6: Tax revenue | E6: VAT (net) | F6: Income tax | G6: Export duties | H6: Import duties | I6: Debits & credits | J6: Other taxes | K6: Social security contrib. | L6: Non-tax and capital | M6: PRIMARY EXPENDITURE | N6: Social benefits | O6: Contributory pensions | P6: Family allowances | Q6: Non-contrib. pensions | R6: PAMI | S6: Other social programmes | T6: Economic subsidies | U6: Energy | V6: Transport | W6: Wages | X6: Other operating | Y6: Transfers to provinces | Z6: Universities | AA6: Public enterprises | AB6: Other current | AC6: Capital expenditure | AD6: PRIMARY BALANCE | AE6: Interest (net) | AF6: OVERALL BALANCE
B7: =Data!B7 -> 2016-01 | C7: =Data!D7+Data!E7+Data!F7+Data!G7+Data!H7+Data!I7+Data!J7+Data!K7+Data!L7+Data!M7+Data!N7+Data!O7+Data!P7+Data!Q7+Data!R7+Data!S7 -> 121621 | D7: =Data!D7+Data!E7+Data!G7+Data!H7+Data!I7+Data!J7+Data!K7+Data!L7+Data!M7 -> 65508 | E7: =Data!D7 -> 20467 | F7: =Data!E7 -> 20340 | G7: =Data!K7 -> 5103 | H7: =Data!L7 -> 3846 | I7: =Data!G7 -> 7765 | J7: =Data!H7+Data!I7+Data!J7+Data!M7 -> 7987 | K7: =Data!F7 -> 50824 | L7: =Data!N7+Data!O7+Data!P7+Data!Q7+Data!R7+Data!S7 -> 5289 | M7: =Data!T7+Data!U7+Data!V7+Data!W7+Data!X7+Data!Y7+Data!Z7+Data!AA7+Data!AB7+Data!AC7+Data!AD7+Data!AE7+Data!AF7+Data!AG7+Data!AH7+Data!AI7+Data!AJ7+Data!AK7+Data!AL7 -> 120880 | N7: =Data!T7+Data!U7+Data!V7+Data!W7 -> 62642 | O7: =Data!T7 -> 44935 | P7: =Data!U7 -> 5000 | Q7: =Data!V7 -> 7270 | R7: =Data!W7 -> 5437 | S7: =Data!X7 -> 1052 | T7: =Data!Y7+Data!Z7+Data!AA7 -> 9624 | U7: =Data!Y7 -> 3754 | V7: =Data!Z7 -> 5732 | W7: =Data!AB7 -> 19099 | X7: =Data!AC7 -> 4448 | Y7: =Data!AD7+Data!AE7+Data!AF7+Data!AG7+Data!AH7 -> 1654 | Z7: =Data!AI7 -> 4411 | AA7: =Data!AJ7 -> 281 | AB7: =Data!AK7 -> 2817 | AC7: =Data!AL7 -> 14852 | AD7: =Data!AM7 -> 741 | AE7: =Data!AN7 -> 2938 | AF7: =Data!AO7 -> -2197
B8: =Data!B8 -> 2016-02 | C8: =Data!D8+Data!E8+Data!F8+Data!G8+Data!H8+Data!I8+Data!J8+Data!K8+Data!L8+Data!M8+Data!N8+Data!O8+Data!P8+Data!Q8+Data!R8+Data!S8 -> 100678 | D8: =Data!D8+Data!E8+Data!G8+Data!H8+Data!I8+Data!J8+Data!K8+Data!L8+Data!M8 -> 58595 | E8: =Data!D8 -> 20110 | F8: =Data!E8 -> 15531 | G8: =Data!K8 -> 3512 | H8: =Data!L8 -> 3679 | I8: =Data!G8 -> 7233 | J8: =Data!H8+Data!I8+Data!J8+Data!M8 -> 8530 | K8: =Data!F8 -> 37246 | L8: =Data!N8+Data!O8+Data!P8+Data!Q8+Data!R8+Data!S8 -> 4837 | M8: =Data!T8+Data!U8+Data!V8+Data!W8+Data!X8+Data!Y8+Data!Z8+Data!AA8+Data!AB8+Data!AC8+Data!AD8+Data!AE8+Data!AF8+Data!AG8+Data!AH8+Data!AI8+Data!AJ8+Data!AK8+Data!AL8 -> 117320 | N8: =Data!T8+Data!U8+Data!V8+Data!W8 -> 56462 | O8: =Data!T8 -> 40460 | P8: =Data!U8 -> 5842 | Q8: =Data!V8 -> 4493 | R8: =Data!W8 -> 5667 | S8: =Data!X8 -> 2302 | T8: =Data!Y8+Data!Z8+Data!AA8 -> 11500 | U8: =Data!Y8 -> 6464 | V8: =Data!Z8 -> 4963 | W8: =Data!AB8 -> 19032 | X8: =Data!AC8 -> 4943 | Y8: =Data!AD8+Data!AE8+Data!AF8+Data!AG8+Data!AH8 -> 1428 | Z8: =Data!AI8 -> 4187 | AA8: =Data!AJ8 -> 1976 | AB8: =Data!AK8 -> 5761 | AC8: =Data!AL8 -> 9729 | AD8: =Data!AM8 -> -16642 | AE8: =Data!AN8 -> 3894 | AF8: =Data!AO8 -> -20537
B9: =Data!B9 -> 2016-03 | C9: =Data!D9+Data!E9+Data!F9+Data!G9+Data!H9+Data!I9+Data!J9+Data!K9+Data!L9+Data!M9+Data!N9+Data!O9+Data!P9+Data!Q9+Data!R9+Data!S9 -> 108833 | D9: =Data!D9+Data!E9+Data!G9+Data!H9+Data!I9+Data!J9+Data!K9+Data!L9+Data!M9 -> 61827 | E9: =Data!D9 -> 21943 | F9: =Data!E9 -> 12671 | G9: =Data!K9 -> 6750 | H9: =Data!L9 -> 4680 | I9: =Data!G9 -> 7891 | J9: =Data!H9+Data!I9+Data!J9+Data!M9 -> 7892 | K9: =Data!F9 -> 37907 | L9: =Data!N9+Data!O9+Data!P9+Data!Q9+Data!R9+Data!S9 -> 9099 | M9: =Data!T9+Data!U9+Data!V9+Data!W9+Data!X9+Data!Y9+Data!Z9+Data!AA9+Data!AB9+Data!AC9+Data!AD9+Data!AE9+Data!AF9+Data!AG9+Data!AH9+Data!AI9+Data!AJ9+Data!AK9+Data!AL9 -> 138845 | N9: =Data!T9+Data!U9+Data!V9+Data!W9 -> 71248 | O9: =Data!T9 -> 47092 | P9: =Data!U9 -> 12034 | Q9: =Data!V9 -> 6211 | R9: =Data!W9 -> 5911 | S9: =Data!X9 -> 1475 | T9: =Data!Y9+Data!Z9+Data!AA9 -> 14823 | U9: =Data!Y9 -> 8585 | V9: =Data!Z9 -> 6181 | W9: =Data!AB9 -> 18491 | X9: =Data!AC9 -> 5162 | Y9: =Data!AD9+Data!AE9+Data!AF9+Data!AG9+Data!AH9 -> 4105 | Z9: =Data!AI9 -> 4324 | AA9: =Data!AJ9 -> 605 | AB9: =Data!AK9 -> 5776 | AC9: =Data!AL9 -> 12836 | AD9: =Data!AM9 -> -30012 | AE9: =Data!AN9 -> 11820 | AF9: =Data!AO9 -> -41832
B10: =Data!B10 -> 2016-04 | C10: =Data!D10+Data!E10+Data!F10+Data!G10+Data!H10+Data!I10+Data!J10+Data!K10+Data!L10+Data!M10+Data!N10+Data!O10+Data!P10+Data!Q10+Data!R10+Data!S10 -> 118147 | D10: =Data!D10+Data!E10+Data!G10+Data!H10+Data!I10+Data!J10+Data!K10+Data!L10+Data!M10 -> 69273 | E10: =Data!D10 -> 22904 | F10: =Data!E10 -> 11898 | G10: =Data!K10 -> 12214 | H10: =Data!L10 -> 4630 | I10: =Data!G10 -> 8815 | J10: =Data!H10+Data!I10+Data!J10+Data!M10 -> 8812 | K10: =Data!F10 -> 42731 | L10: =Data!N10+Data!O10+Data!P10+Data!Q10+Data!R10+Data!S10 -> 6143 | M10: =Data!T10+Data!U10+Data!V10+Data!W10+Data!X10+Data!Y10+Data!Z10+Data!AA10+Data!AB10+Data!AC10+Data!AD10+Data!AE10+Data!AF10+Data!AG10+Data!AH10+Data!AI10+Data!AJ10+Data!AK10+Data!AL10 -> 129040 | N10: =Data!T10+Data!U10+Data!V10+Data!W10 -> 66942 | O10: =Data!T10 -> 47795 | P10: =Data!U10 -> 7707 | Q10: =Data!V10 -> 6169 | R10: =Data!W10 -> 5271 | S10: =Data!X10 -> 2081 | T10: =Data!Y10+Data!Z10+Data!AA10 -> 15180 | U10: =Data!Y10 -> 8525 | V10: =Data!Z10 -> 6489 | W10: =Data!AB10 -> 16944 | X10: =Data!AC10 -> 5068 | Y10: =Data!AD10+Data!AE10+Data!AF10+Data!AG10+Data!AH10 -> 2731 | Z10: =Data!AI10 -> 4628 | AA10: =Data!AJ10 -> 151 | AB10: =Data!AK10 -> 3365 | AC10: =Data!AL10 -> 11950 | AD10: =Data!AM10 -> -10893 | AE10: =Data!AN10 -> 6181 | AF10: =Data!AO10 -> -17075
B11: =Data!B11 -> 2016-05 | C11: =Data!D11+Data!E11+Data!F11+Data!G11+Data!H11+Data!I11+Data!J11+Data!K11+Data!L11+Data!M11+Data!N11+Data!O11+Data!P11+Data!Q11+Data!R11+Data!S11 -> 137025 | D11: =Data!D11+Data!E11+Data!G11+Data!H11+Data!I11+Data!J11+Data!K11+Data!L11+Data!M11 -> 86493 | E11: =Data!D11 -> 26738 | F11: =Data!E11 -> 25961 | G11: =Data!K11 -> 8199 | H11: =Data!L11 -> 4519 | I11: =Data!G11 -> 8919 | J11: =Data!H11+Data!I11+Data!J11+Data!M11 -> 12157 | K11: =Data!F11 -> 42640 | L11: =Data!N11+Data!O11+Data!P11+Data!Q11+Data!R11+Data!S11 -> 7892 | M11: =Data!T11+Data!U11+Data!V11+Data!W11+Data!X11+Data!Y11+Data!Z11+Data!AA11+Data!AB11+Data!AC11+Data!AD11+Data!AE11+Data!AF11+Data!AG11+Data!AH11+Data!AI11+Data!AJ11+Data!AK11+Data!AL11 -> 148999 | N11: =Data!T11+Data!U11+Data!V11+Data!W11 -> 72464 | O11: =Data!T11 -> 48802 | P11: =Data!U11 -> 10586 | Q11: =Data!V11 -> 7183 | R11: =Data!W11 -> 5893 | S11: =Data!X11 -> 2296 | T11: =Data!Y11+Data!Z11+Data!AA11 -> 21403 | U11: =Data!Y11 -> 14618 | V11: =Data!Z11 -> 6641 | W11: =Data!AB11 -> 17530 | X11: =Data!AC11 -> 6109 | Y11: =Data!AD11+Data!AE11+Data!AF11+Data!AG11+Data!AH11 -> 2915 | Z11: =Data!AI11 -> 4874 | AA11: =Data!AJ11 -> 985 | AB11: =Data!AK11 -> 4609 | AC11: =Data!AL11 -> 15814 | AD11: =Data!AM11 -> -11974 | AE11: =Data!AN11 -> 12019 | AF11: =Data!AO11 -> -23994
B12: =Data!B12 -> 2016-06 | C12: =Data!D12+Data!E12+Data!F12+Data!G12+Data!H12+Data!I12+Data!J12+Data!K12+Data!L12+Data!M12+Data!N12+Data!O12+Data!P12+Data!Q12+Data!R12+Data!S12 -> 130052 | D12: =Data!D12+Data!E12+Data!G12+Data!H12+Data!I12+Data!J12+Data!K12+Data!L12+Data!M12 -> 79659 | E12: =Data!D12 -> 22218 | F12: =Data!E12 -> 25274 | G12: =Data!K12 -> 5004 | H12: =Data!L12 -> 4612 | I12: =Data!G12 -> 9263 | J12: =Data!H12+Data!I12+Data!J12+Data!M12 -> 13288 | K12: =Data!F12 -> 43030 | L12: =Data!N12+Data!O12+Data!P12+Data!Q12+Data!R12+Data!S12 -> 7363 | M12: =Data!T12+Data!U12+Data!V12+Data!W12+Data!X12+Data!Y12+Data!Z12+Data!AA12+Data!AB12+Data!AC12+Data!AD12+Data!AE12+Data!AF12+Data!AG12+Data!AH12+Data!AI12+Data!AJ12+Data!AK12+Data!AL12 -> 174060 | N12: =Data!T12+Data!U12+Data!V12+Data!W12 -> 93404 | O12: =Data!T12 -> 70396 | P12: =Data!U12 -> 8682 | Q12: =Data!V12 -> 8055 | R12: =Data!W12 -> 6271 | S12: =Data!X12 -> 1405 | T12: =Data!Y12+Data!Z12+Data!AA12 -> 24561 | U12: =Data!Y12 -> 17158 | V12: =Data!Z12 -> 6993 | W12: =Data!AB12 -> 20272 | X12: =Data!AC12 -> 6286 | Y12: =Data!AD12+Data!AE12+Data!AF12+Data!AG12+Data!AH12 -> 3110 | Z12: =Data!AI12 -> 4671 | AA12: =Data!AJ12 -> 745 | AB12: =Data!AK12 -> 4544 | AC12: =Data!AL12 -> 15062 | AD12: =Data!AM12 -> -44008 | AE12: =Data!AN12 -> 28579 | AF12: =Data!AO12 -> -72587
B13: =Data!B13 -> 2016-07 | C13: =Data!D13+Data!E13+Data!F13+Data!G13+Data!H13+Data!I13+Data!J13+Data!K13+Data!L13+Data!M13+Data!N13+Data!O13+Data!P13+Data!Q13+Data!R13+Data!S13 -> 144273 | D13: =Data!D13+Data!E13+Data!G13+Data!H13+Data!I13+Data!J13+Data!K13+Data!L13+Data!M13 -> 76550 | E13: =Data!D13 -> 22482 | F13: =Data!E13 -> 18614 | G13: =Data!K13 -> 7698 | H13: =Data!L13 -> 4727 | I13: =Data!G13 -> 10098 | J13: =Data!H13+Data!I13+Data!J13+Data!M13 -> 12931 | K13: =Data!F13 -> 59399 | L13: =Data!N13+Data!O13+Data!P13+Data!Q13+Data!R13+Data!S13 -> 8324 | M13: =Data!T13+Data!U13+Data!V13+Data!W13+Data!X13+Data!Y13+Data!Z13+Data!AA13+Data!AB13+Data!AC13+Data!AD13+Data!AE13+Data!AF13+Data!AG13+Data!AH13+Data!AI13+Data!AJ13+Data!AK13+Data!AL13 -> 168639 | N13: =Data!T13+Data!U13+Data!V13+Data!W13 -> 69490 | O13: =Data!T13 -> 49197 | P13: =Data!U13 -> 7996 | Q13: =Data!V13 -> 5974 | R13: =Data!W13 -> 6323 | S13: =Data!X13 -> 1975 | T13: =Data!Y13+Data!Z13+Data!AA13 -> 28492 | U13: =Data!Y13 -> 21771 | V13: =Data!Z13 -> 6543 | W13: =Data!AB13 -> 27085 | X13: =Data!AC13 -> 6464 | Y13: =Data!AD13+Data!AE13+Data!AF13+Data!AG13+Data!AH13 -> 9949 | Z13: =Data!AI13 -> 7403 | AA13: =Data!AJ13 -> 236 | AB13: =Data!AK13 -> 5029 | AC13: =Data!AL13 -> 12516 | AD13: =Data!AM13 -> -24366 | AE13: =Data!AN13 -> 3218 | AF13: =Data!AO13 -> -27584
B14: =Data!B14 -> 2016-08 | C14: =Data!D14+Data!E14+Data!F14+Data!G14+Data!H14+Data!I14+Data!J14+Data!K14+Data!L14+Data!M14+Data!N14+Data!O14+Data!P14+Data!Q14+Data!R14+Data!S14 -> 129109 | D14: =Data!D14+Data!E14+Data!G14+Data!H14+Data!I14+Data!J14+Data!K14+Data!L14+Data!M14 -> 73276 | E14: =Data!D14 -> 24007 | F14: =Data!E14 -> 17507 | G14: =Data!K14 -> 4465 | H14: =Data!L14 -> 4998 | I14: =Data!G14 -> 9019 | J14: =Data!H14+Data!I14+Data!J14+Data!M14 -> 13280 | K14: =Data!F14 -> 46452 | L14: =Data!N14+Data!O14+Data!P14+Data!Q14+Data!R14+Data!S14 -> 9381 | M14: =Data!T14+Data!U14+Data!V14+Data!W14+Data!X14+Data!Y14+Data!Z14+Data!AA14+Data!AB14+Data!AC14+Data!AD14+Data!AE14+Data!AF14+Data!AG14+Data!AH14+Data!AI14+Data!AJ14+Data!AK14+Data!AL14 -> 164525 | N14: =Data!T14+Data!U14+Data!V14+Data!W14 -> 74889 | O14: =Data!T14 -> 49948 | P14: =Data!U14 -> 8868 | Q14: =Data!V14 -> 6165 | R14: =Data!W14 -> 9908 | S14: =Data!X14 -> 2422 | T14: =Data!Y14+Data!Z14+Data!AA14 -> 22955 | U14: =Data!Y14 -> 14912 | V14: =Data!Z14 -> 7910 | W14: =Data!AB14 -> 23009 | X14: =Data!AC14 -> 6144 | Y14: =Data!AD14+Data!AE14+Data!AF14+Data!AG14+Data!AH14 -> 5309 | Z14: =Data!AI14 -> 5203 | AA14: =Data!AJ14 -> 814 | AB14: =Data!AK14 -> 4770 | AC14: =Data!AL14 -> 19010 | AD14: =Data!AM14 -> -35416 | AE14: =Data!AN14 -> 3360 | AF14: =Data!AO14 -> -38775
B15: =Data!B15 -> 2016-09 | C15: =Data!D15+Data!E15+Data!F15+Data!G15+Data!H15+Data!I15+Data!J15+Data!K15+Data!L15+Data!M15+Data!N15+Data!O15+Data!P15+Data!Q15+Data!R15+Data!S15 -> 131766 | D15: =Data!D15+Data!E15+Data!G15+Data!H15+Data!I15+Data!J15+Data!K15+Data!L15+Data!M15 -> 74910 | E15: =Data!D15 -> 25256 | F15: =Data!E15 -> 17402 | G15: =Data!K15 -> 5249 | H15: =Data!L15 -> 5294 | I15: =Data!G15 -> 10122 | J15: =Data!H15+Data!I15+Data!J15+Data!M15 -> 11587 | K15: =Data!F15 -> 46070 | L15: =Data!N15+Data!O15+Data!P15+Data!Q15+Data!R15+Data!S15 -> 10786 | M15: =Data!T15+Data!U15+Data!V15+Data!W15+Data!X15+Data!Y15+Data!Z15+Data!AA15+Data!AB15+Data!AC15+Data!AD15+Data!AE15+Data!AF15+Data!AG15+Data!AH15+Data!AI15+Data!AJ15+Data!AK15+Data!AL15 -> 168783 | N15: =Data!T15+Data!U15+Data!V15+Data!W15 -> 79140 | O15: =Data!T15 -> 56049 | P15: =Data!U15 -> 9669 | Q15: =Data!V15 -> 6807 | R15: =Data!W15 -> 6615 | S15: =Data!X15 -> 2593 | T15: =Data!Y15+Data!Z15+Data!AA15 -> 26896 | U15: =Data!Y15 -> 20204 | V15: =Data!Z15 -> 6592 | W15: =Data!AB15 -> 24103 | X15: =Data!AC15 -> 6431 | Y15: =Data!AD15+Data!AE15+Data!AF15+Data!AG15+Data!AH15 -> 5264 | Z15: =Data!AI15 -> 4570 | AA15: =Data!AJ15 -> 514 | AB15: =Data!AK15 -> 5383 | AC15: =Data!AL15 -> 13889 | AD15: =Data!AM15 -> -37017 | AE15: =Data!AN15 -> 11979 | AF15: =Data!AO15 -> -48996
B16: =Data!B16 -> 2016-10 | C16: =Data!D16+Data!E16+Data!F16+Data!G16+Data!H16+Data!I16+Data!J16+Data!K16+Data!L16+Data!M16+Data!N16+Data!O16+Data!P16+Data!Q16+Data!R16+Data!S16 -> 128073 | D16: =Data!D16+Data!E16+Data!G16+Data!H16+Data!I16+Data!J16+Data!K16+Data!L16+Data!M16 -> 73865 | E16: =Data!D16 -> 22917 | F16: =Data!E16 -> 17777 | G16: =Data!K16 -> 4507 | H16: =Data!L16 -> 4790 | I16: =Data!G16 -> 9186 | J16: =Data!H16+Data!I16+Data!J16+Data!M16 -> 14688 | K16: =Data!F16 -> 46476 | L16: =Data!N16+Data!O16+Data!P16+Data!Q16+Data!R16+Data!S16 -> 7732 | M16: =Data!T16+Data!U16+Data!V16+Data!W16+Data!X16+Data!Y16+Data!Z16+Data!AA16+Data!AB16+Data!AC16+Data!AD16+Data!AE16+Data!AF16+Data!AG16+Data!AH16+Data!AI16+Data!AJ16+Data!AK16+Data!AL16 -> 189941 | N16: =Data!T16+Data!U16+Data!V16+Data!W16 -> 81816 | O16: =Data!T16 -> 57252 | P16: =Data!U16 -> 9716 | Q16: =Data!V16 -> 6742 | R16: =Data!W16 -> 8106 | S16: =Data!X16 -> 2632 | T16: =Data!Y16+Data!Z16+Data!AA16 -> 32727 | U16: =Data!Y16 -> 25779 | V16: =Data!Z16 -> 6842 | W16: =Data!AB16 -> 23635 | X16: =Data!AC16 -> 11007 | Y16: =Data!AD16+Data!AE16+Data!AF16+Data!AG16+Data!AH16 -> 5505 | Z16: =Data!AI16 -> 5250 | AA16: =Data!AJ16 -> 104 | AB16: =Data!AK16 -> 4127 | AC16: =Data!AL16 -> 23138 | AD16: =Data!AM16 -> -61868 | AE16: =Data!AN16 -> 15632 | AF16: =Data!AO16 -> -77500
B17: =Data!B17 -> 2016-11 | C17: =Data!D17+Data!E17+Data!F17+Data!G17+Data!H17+Data!I17+Data!J17+Data!K17+Data!L17+Data!M17+Data!N17+Data!O17+Data!P17+Data!Q17+Data!R17+Data!S17 -> 145785 | D17: =Data!D17+Data!E17+Data!G17+Data!H17+Data!I17+Data!J17+Data!K17+Data!L17+Data!M17 -> 85989 | E17: =Data!D17 -> 23911 | F17: =Data!E17 -> 19152 | G17: =Data!K17 -> 4313 | H17: =Data!L17 -> 4411 | I17: =Data!G17 -> 10188 | J17: =Data!H17+Data!I17+Data!J17+Data!M17 -> 24014 | K17: =Data!F17 -> 51942 | L17: =Data!N17+Data!O17+Data!P17+Data!Q17+Data!R17+Data!S17 -> 7854 | M17: =Data!T17+Data!U17+Data!V17+Data!W17+Data!X17+Data!Y17+Data!Z17+Data!AA17+Data!AB17+Data!AC17+Data!AD17+Data!AE17+Data!AF17+Data!AG17+Data!AH17+Data!AI17+Data!AJ17+Data!AK17+Data!AL17 -> 159085 | N17: =Data!T17+Data!U17+Data!V17+Data!W17 -> 83564 | O17: =Data!T17 -> 57463 | P17: =Data!U17 -> 9766 | Q17: =Data!V17 -> 9389 | R17: =Data!W17 -> 6946 | S17: =Data!X17 -> 2236 | T17: =Data!Y17+Data!Z17+Data!AA17 -> 17199 | U17: =Data!Y17 -> 10606 | V17: =Data!Z17 -> 6498 | W17: =Data!AB17 -> 22753 | X17: =Data!AC17 -> 8268 | Y17: =Data!AD17+Data!AE17+Data!AF17+Data!AG17+Data!AH17 -> 6173 | Z17: =Data!AI17 -> 5056 | AA17: =Data!AJ17 -> 396 | AB17: =Data!AK17 -> 2461 | AC17: =Data!AL17 -> 10979 | AD17: =Data!AM17 -> -13300 | AE17: =Data!AN17 -> 6558 | AF17: =Data!AO17 -> -19858
B18: =Data!B18 -> 2016-12 | C18: =Data!D18+Data!E18+Data!F18+Data!G18+Data!H18+Data!I18+Data!J18+Data!K18+Data!L18+Data!M18+Data!N18+Data!O18+Data!P18+Data!Q18+Data!R18+Data!S18 -> 233952 | D18: =Data!D18+Data!E18+Data!G18+Data!H18+Data!I18+Data!J18+Data!K18+Data!L18+Data!M18 -> 170718 | E18: =Data!D18 -> 24889 | F18: =Data!E18 -> 21295 | G18: =Data!K18 -> 5104 | H18: =Data!L18 -> 5210 | I18: =Data!G18 -> 10840 | J18: =Data!H18+Data!I18+Data!J18+Data!M18 -> 103380 | K18: =Data!F18 -> 53371 | L18: =Data!N18+Data!O18+Data!P18+Data!Q18+Data!R18+Data!S18 -> 9863 | M18: =Data!T18+Data!U18+Data!V18+Data!W18+Data!X18+Data!Y18+Data!Z18+Data!AA18+Data!AB18+Data!AC18+Data!AD18+Data!AE18+Data!AF18+Data!AG18+Data!AH18+Data!AI18+Data!AJ18+Data!AK18+Data!AL18 -> 292721 | N18: =Data!T18+Data!U18+Data!V18+Data!W18 -> 112227 | O18: =Data!T18 -> 85081 | P18: =Data!U18 -> 12294 | Q18: =Data!V18 -> 5791 | R18: =Data!W18 -> 9061 | S18: =Data!X18 -> 7833 | T18: =Data!Y18+Data!Z18+Data!AA18 -> 65811 | U18: =Data!Y18 -> 56827 | V18: =Data!Z18 -> 8863 | W18: =Data!AB18 -> 34877 | X18: =Data!AC18 -> 9010 | Y18: =Data!AD18+Data!AE18+Data!AF18+Data!AG18+Data!AH18 -> 25450 | Z18: =Data!AI18 -> 7925 | AA18: =Data!AJ18 -> 1332 | AB18: =Data!AK18 -> 5988 | AC18: =Data!AL18 -> 22268 | AD18: =Data!AM18 -> -58769 | AE18: =Data!AN18 -> 25081 | AF18: =Data!AO18 -> -83850
... B131: =Data!B131 -> 2026-05 | C131: =Data!D131+Data!E131+Data!F131+Data!G131+Data!H131+Data!I131+Data!J131+Data!K131+Data!L131+Data!M131+Data!N131+Data!O131+Data!P131+Data!Q131+Data!R131+Data!S131 -> 14531656 | D131: =Data!D131+Data!E131+Data!G131+Data!H131+Data!I131+Data!J131+Data!K131+Data!L131+Data!M131 -> 8798590 | E131: =Data!D131 -> 2433370 | F131: =Data!E131 -> 2970423 | G131: =Data!K131 -> 545337 | H131: =Data!L131 -> 394152 | I131: =Data!G131 -> 1419595 | J131: =Data!H131+Data!I131+Data!J131+Data!M131 -> 1035713 | K131: =Data!F131 -> 4736191 | L131: =Data!N131+Data!O131+Data!P131+Data!Q131+Data!R131+Data!S131 -> 996875 | M131: =Data!T131+Data!U131+Data!V131+Data!W131+Data!X131+Data!Y131+Data!Z131+Data!AA131+Data!AB131+Data!AC131+Data!AD131+Data!AE131+Data!AF131+Data!AG131+Data!AH131+Data!AI131+Data!AJ131+Data!AK131+Data!AL131 -> 12607289 | N131: =Data!T131+Data!U131+Data!V131+Data!W131 -> 7428268 | O131: =Data!T131 -> 5253082 | P131: =Data!U131 -> 900085 | Q131: =Data!V131 -> 424468 | R131: =Data!W131 -> 850633 | S131: =Data!X131 -> 953150 | T131: =Data!Y131+Data!Z131+Data!AA131 -> 784177 | U131: =Data!Y131 -> 523417 | V131: =Data!Z131 -> 258687 | W131: =Data!AB131 -> 1618197 | X131: =Data!AC131 -> 471191 | Y131: =Data!AD131+Data!AE131+Data!AF131+Data!AG131+Data!AH131 -> 160299 | Z131: =Data!AI131 -> 780000 | AA131: =Data!AJ131 -> 0 | AB131: =Data!AK131 -> 228489 | AC131: =Data!AL131 -> 183518 | AD131: =Data!AM131 -> 1924367 | AE131: =Data!AN131 -> 1445754 | AF131: =Data!AO131 -> 478613

Sheet Rolling 12m
B2: Trailing twelve-month sums, nominal
B3: Millions of pesos. The frame to read.
B6: Month | C6: TOTAL REVENUE | D6: Tax revenue | E6: VAT (net) | F6: Income tax | G6: Export duties | H6: Import duties | I6: Debits & credits | J6: Other taxes | K6: Social security contrib. | L6: Non-tax and capital | M6: PRIMARY EXPENDITURE | N6: Social benefits | O6: Contributory pensions | P6: Family allowances | Q6: Non-contrib. pensions | R6: PAMI | S6: Other social programmes | T6: Economic subsidies | U6: Energy | V6: Transport | W6: Wages | X6: Other operating | Y6: Transfers to provinces | Z6: Universities | AA6: Public enterprises | AB6: Other current | AC6: Capital expenditure | AD6: PRIMARY BALANCE | AE6: Interest (net) | AF6: OVERALL BALANCE
B7: =Data!B7 -> 2016-01
B8: =Data!B8 -> 2016-02
B9: =Data!B9 -> 2016-03
B10: =Data!B10 -> 2016-04
B11: =Data!B11 -> 2016-05
B12: =Data!B12 -> 2016-06
B13: =Data!B13 -> 2016-07
B14: =Data!B14 -> 2016-08
B15: =Data!B15 -> 2016-09
B16: =Data!B16 -> 2016-10
B17: =Data!B17 -> 2016-11
B18: =Data!B18 -> 2016-12 | C18: =Data!D7+Data!E7+Data!F7+Data!G7+Data!H7+Data!I7+Data!J7+Data!K7+Data!L7+Data!M7+Data!N7+Data!O7+Data!P7+Data!Q7+Data!R7+Data!S7+Data!D8+Data!E8+Data!F8+Data!G8+Data!H8+Data!I8+Data!J8+Data!K8+Data!L8+Data!M8+Data!N8+Data!O8+Data!P8+Data!Q8+Data!R8+Data!S8+Data!D9+Data!E9+Data!F9+Data!G9+Data!H9+Data!I9+Data!J9+Data!K9+Data!L9+Data!M9+Data!N9+Data!O9+Data!P9+Data!Q9+Data!R9+Data!S9+Data!D10+Data!E10+Data!F10+Data!G10+Data!H10+Data!I10+Data!J10+Data!K10+Data!L10+Data!M10+Data!N10+Data!O10+Data!P10+Data!Q10+Data!R10+Data!S10+Data!D11+Data!E11+Data!F11+Data!G11+Data!H11+Data!I11+Data!J11+Data!K11+Data!L11+Data!M11+Data!N11+Data!O11+Data!P11+Data!Q11+Data!R11+Data!S11+Data!D12+Data!E12+Data!F12+Data!G12+Data!H12+Data!I12+Data!J12+Data!K12+Data!L12+Data!M12+Data!N12+Data!O12+Data!P12+Data!Q12+Data!R12+Data!S12+Data!D13+Data!E13+Data!F13+Data!G13+Data!H13+Data!I13+Data!J13+Data!K13+Data!L13+Data!M13+Data!N13+Data!O13+Data!P13+Data!Q13+Data!R13+Data!S13+Data!D14+Data!E14+Data!F14+Data!G14+Data!H14+Data!I14+Data!J14+Data!K14+Data!L14+Data!M14+Data!N14+Data!O14+Data!P14+Data!Q14+Data!R14+Data!S14+Data!D15+Data!E15+Data!F15+Data!G15+Data!H15+Data!I15+Data!J15+Data!K15+Data!L15+Data!M15+Data!N15+Data!O15+Data!P15+Data!Q15+Data!R15+Data!S15+Data!D16+Data!E16+Data!F16+Data!G16+Data!H16+Data!I16+Data!J16+Data!K16+Data!L16+Data!M16+Data!N16+Data!O16+Data!P16+Data!Q16+Data!R16+Data!S16+Data!D17+Data!E17+Data!F17+Data!G17+Data!H17+Data!I17+Data!J17+Data!K17+Data!L17+Data!M17+Data!N17+Data!O17+Data!P17+Data!Q17+Data!R17+Data!S17+Data!D18+Data!E18+Data!F18+Data!G18+Data!H18+Data!I18+Data!J18+Data!K18+Data!L18+Data!M18+Data!N18+Data!O18+Data!P18+Data!Q18+Data!R18+Data!S18 -> 1629314 | D18: =Data!D7+Data!E7+Data!G7+Data!H7+Data!I7+Data!J7+Data!K7+Data!L7+Data!M7+Data!D8+Data!E8+Data!G8+Data!H8+Data!I8+Data!J8+Data!K8+Data!L8+Data!M8+Data!D9+Data!E9+Data!G9+Data!H9+Data!I9+Data!J9+Data!K9+Data!L9+Data!M9+Data!D10+Data!E10+Data!G10+Data!H10+Data!I10+Data!J10+Data!K10+Data!L10+Data!M10+Data!D11+Data!E11+Data!G11+Data!H11+Data!I11+Data!J11+Data!K11+Data!L11+Data!M11+Data!D12+Data!E12+Data!G12+Data!H12+Data!I12+Data!J12+Data!K12+Data!L12+Data!M12+Data!D13+Data!E13+Data!G13+Data!H13+Data!I13+Data!J13+Data!K13+Data!L13+Data!M13+Data!D14+Data!E14+Data!G14+Data!H14+Data!I14+Data!J14+Data!K14+Data!L14+Data!M14+Data!D15+Data!E15+Data!G15+Data!H15+Data!I15+Data!J15+Data!K15+Data!L15+Data!M15+Data!D16+Data!E16+Data!G16+Data!H16+Data!I16+Data!J16+Data!K16+Data!L16+Data!M16+Data!D17+Data!E17+Data!G17+Data!H17+Data!I17+Data!J17+Data!K17+Data!L17+Data!M17+Data!D18+Data!E18+Data!G18+Data!H18+Data!I18+Data!J18+Data!K18+Data!L18+Data!M18 -> 976663 | E18: =Data!D7+Data!D8+Data!D9+Data!D10+Data!D11+Data!D12+Data!D13+Data!D14+Data!D15+Data!D16+Data!D17+Data!D18 -> 277842 | F18: =Data!E7+Data!E8+Data!E9+Data!E10+Data!E11+Data!E12+Data!E13+Data!E14+Data!E15+Data!E16+Data!E17+Data!E18 -> 223422 | G18: =Data!K7+Data!K8+Data!K9+Data!K10+Data!K11+Data!K12+Data!K13+Data!K14+Data!K15+Data!K16+Data!K17+Data!K18 -> 72118 | H18: =Data!L7+Data!L8+Data!L9+Data!L10+Data!L11+Data!L12+Data!L13+Data!L14+Data!L15+Data!L16+Data!L17+Data!L18 -> 55396 | I18: =Data!G7+Data!G8+Data!G9+Data!G10+Data!G11+Data!G12+Data!G13+Data!G14+Data!G15+Data!G16+Data!G17+Data!G18 -> 109339 | J18: =Data!H7+Data!I7+Data!J7+Data!M7+Data!H8+Data!I8+Data!J8+Data!M8+Data!H9+Data!I9+Data!J9+Data!M9+Data!H10+Data!I10+Data!J10+Data!M10+Data!H11+Data!I11+Data!J11+Data!M11+Data!H12+Data!I12+Data!J12+Data!M12+Data!H13+Data!I13+Data!J13+Data!M13+Data!H14+Data!I14+Data!J14+Data!M14+Data!H15+Data!I15+Data!J15+Data!M15+Data!H16+Data!I16+Data!J16+Data!M16+Data!H17+Data!I17+Data!J17+Data!M17+Data!H18+Data!I18+Data!J18+Data!M18 -> 238546 | K18: =Data!F7+Data!F8+Data!F9+Data!F10+Data!F11+Data!F12+Data!F13+Data!F14+Data!F15+Data!F16+Data!F17+Data!F18 -> 558088 | L18: =Data!N7+Data!O7+Data!P7+Data!Q7+Data!R7+Data!S7+Data!N8+Data!O8+Data!P8+Data!Q8+Data!R8+Data!S8+Data!N9+Data!O9+Data!P9+Data!Q9+Data!R9+Data!S9+Data!N10+Data!O10+Data!P10+Data!Q10+Data!R10+Data!S10+Data!N11+Data!O11+Data!P11+Data!Q11+Data!R11+Data!S11+Data!N12+Data!O12+Data!P12+Data!Q12+Data!R12+Data!S12+Data!N13+Data!O13+Data!P13+Data!Q13+Data!R13+Data!S13+Data!N14+Data!O14+Data!P14+Data!Q14+Data!R14+Data!S14+Data!N15+Data!O15+Data!P15+Data!Q15+Data!R15+Data!S15+Data!N16+Data!O16+Data!P16+Data!Q16+Data!R16+Data!S16+Data!N17+Data!O17+Data!P17+Data!Q17+Data!R17+Data!S17+Data!N18+Data!O18+Data!P18+Data!Q18+Data!R18+Data!S18 -> 94563 | M18: =Data!T7+Data!U7+Data!V7+Data!W7+Data!X7+Data!Y7+Data!Z7+Data!AA7+Data!AB7+Data!AC7+Data!AD7+Data!AE7+Data!AF7+Data!AG7+Data!AH7+Data!AI7+Data!AJ7+Data!AK7+Data!AL7+Data!T8+Data!U8+Data!V8+Data!W8+Data!X8+Data!Y8+Data!Z8+Data!AA8+Data!AB8+Data!AC8+Data!AD8+Data!AE8+Data!AF8+Data!AG8+Data!AH8+Data!AI8+Data!AJ8+Data!AK8+Data!AL8+Data!T9+Data!U9+Data!V9+Data!W9+Data!X9+Data!Y9+Data!Z9+Data!AA9+Data!AB9+Data!AC9+Data!AD9+Data!AE9+Data!AF9+Data!AG9+Data!AH9+Data!AI9+Data!AJ9+Data!AK9+Data!AL9+Data!T10+Data!U10+Data!V10+Data!W10+Data!X10+Data!Y10+Data!Z10+Data!AA10+Data!AB10+Data!AC10+Data!AD10+Data!AE10+Data!AF10+Data!AG10+Data!AH10+Data!AI10+Data!AJ10+Data!AK10+Data!AL10+Data!T11+Data!U11+Data!V11+Data!W11+Data!X11+Data!Y11+Data!Z11+Data!AA11+Data!AB11+Data!AC11+Data!AD11+Data!AE11+Data!AF11+Data!AG11+Data!AH11+Data!AI11+Data!AJ11+Data!AK11+Data!AL11+Data!T12+Data!U12+Data!V12+Data!W12+Data!X12+Data!Y12+Data!Z12+Data!AA12+Data!AB12+Data!AC12+Data!AD12+Data!AE12+Data!AF12+Data!AG12+Data!AH12+Data!AI12+Data!AJ12+Data!AK12+Data!AL12+Data!T13+Data!U13+Data!V13+Data!W13+Data!X13+Data!Y13+Data!Z13+Data!AA13+Data!AB13+Data!AC13+Data!AD13+Data!AE13+Data!AF13+Data!AG13+Data!AH13+Data!AI13+Data!AJ13+Data!AK13+Data!AL13+Data!T14+Data!U14+Data!V14+Data!W14+Data!X14+Data!Y14+Data!Z14+Data!AA14+Data!AB14+Data!AC14+Data!AD14+Data!AE14+Data!AF14+Data!AG14+Data!AH14+Data!AI14+Data!AJ14+Data!AK14+Data!AL14+Data!T15+Data!U15+Data!V15+Data!W15+Data!X15+Data!Y15+Data!Z15+Data!AA15+Data!AB15+Data!AC15+Data!AD15+Data!AE15+Data!AF15+Data!AG15+Data!AH15+Data!AI15+Data!AJ15+Data!AK15+Data!AL15+Data!T16+Data!U16+Data!V16+Data!W16+Data!X16+Data!Y16+Data!Z16+Data!AA16+Data!AB16+Data!AC16+Data!AD16+Data!AE16+Data!AF16+Data!AG16+Data!AH16+Data!AI16+Data!AJ16+Data!AK16+Data!AL16+Data!T17+Data!U17+Data!V17+Data!W17+Data!X17+Data!Y17+Data!Z17+Data!AA17+Data!AB17+Data!AC17+Data!AD17+Data!AE17+Data!AF17+Data!AG17+Data!AH17+Data!AI17+Data!AJ17+Data!AK17+Data!AL17+Data!T18+Data!U18+Data!V18+Data!W18+Data!X18+Data!Y18+Data!Z18+Data!AA18+Data!AB18+Data!AC18+Data!AD18+Data!AE18+Data!AF18+Data!AG18+Data!AH18+Data!AI18+Data!AJ18+Data!AK18+Data!AL18 -> 1972838 | N18: =Data!T7+Data!U7+Data!V7+Data!W7+Data!T8+Data!U8+Data!V8+Data!W8+Data!T9+Data!U9+Data!V9+Data!W9+Data!T10+Data!U10+Data!V10+Data!W10+Data!T11+Data!U11+Data!V11+Data!W11+Data!T12+Data!U12+Data!V12+Data!W12+Data!T13+Data!U13+Data!V13+Data!W13+Data!T14+Data!U14+Data!V14+Data!W14+Data!T15+Data!U15+Data!V15+Data!W15+Data!T16+Data!U16+Data!V16+Data!W16+Data!T17+Data!U17+Data!V17+Data!W17+Data!T18+Data!U18+Data!V18+Data!W18 -> 924288 | O18: =Data!T7+Data!T8+Data!T9+Data!T10+Data!T11+Data!T12+Data!T13+Data!T14+Data!T15+Data!T16+Data!T17+Data!T18 -> 654470 | P18: =Data!U7+Data!U8+Data!U9+Data!U10+Data!U11+Data!U12+Data!U13+Data!U14+Data!U15+Data!U16+Data!U17+Data!U18 -> 108160 | Q18: =Data!V7+Data!V8+Data!V9+Data!V10+Data!V11+Data!V12+Data!V13+Data!V14+Data!V15+Data!V16+Data!V17+Data!V18 -> 80249 | R18: =Data!W7+Data!W8+Data!W9+Data!W10+Data!W11+Data!W12+Data!W13+Data!W14+Data!W15+Data!W16+Data!W17+Data!W18 -> 81409 | S18: =Data!X7+Data!X8+Data!X9+Data!X10+Data!X11+Data!X12+Data!X13+Data!X14+Data!X15+Data!X16+Data!X17+Data!X18 -> 30302 | T18: =Data!Y7+Data!Z7+Data!AA7+Data!Y8+Data!Z8+Data!AA8+Data!Y9+Data!Z9+Data!AA9+Data!Y10+Data!Z10+Data!AA10+Data!Y11+Data!Z11+Data!AA11+Data!Y12+Data!Z12+Data!AA12+Data!Y13+Data!Z13+Data!AA13+Data!Y14+Data!Z14+Data!AA14+Data!Y15+Data!Z15+Data!AA15+Data!Y16+Data!Z16+Data!AA16+Data!Y17+Data!Z17+Data!AA17+Data!Y18+Data!Z18+Data!AA18 -> 291171 | U18: =Data!Y7+Data!Y8+Data!Y9+Data!Y10+Data!Y11+Data!Y12+Data!Y13+Data!Y14+Data!Y15+Data!Y16+Data!Y17+Data!Y18 -> 209203 | V18: =Data!Z7+Data!Z8+Data!Z9+Data!Z10+Data!Z11+Data!Z12+Data!Z13+Data!Z14+Data!Z15+Data!Z16+Data!Z17+Data!Z18 -> 80247 | W18: =Data!AB7+Data!AB8+Data!AB9+Data!AB10+Data!AB11+Data!AB12+Data!AB13+Data!AB14+Data!AB15+Data!AB16+Data!AB17+Data!AB18 -> 266830 | X18: =Data!AC7+Data!AC8+Data!AC9+Data!AC10+Data!AC11+Data!AC12+Data!AC13+Data!AC14+Data!AC15+Data!AC16+Data!AC17+Data!AC18 -> 79340 | Y18: =Data!AD7+Data!AE7+Data!AF7+Data!AG7+Data!AH7+Data!AD8+Data!AE8+Data!AF8+Data!AG8+Data!AH8+Data!AD9+Data!AE9+Data!AF9+Data!AG9+Data!AH9+Data!AD10+Data!AE10+Data!AF10+Data!AG10+Data!AH10+Data!AD11+Data!AE11+Data!AF11+Data!AG11+Data!AH11+Data!AD12+Data!AE12+Data!AF12+Data!AG12+Data!AH12+Data!AD13+Data!AE13+Data!AF13+Data!AG13+Data!AH13+Data!AD14+Data!AE14+Data!AF14+Data!AG14+Data!AH14+Data!AD15+Data!AE15+Data!AF15+Data!AG15+Data!AH15+Data!AD16+Data!AE16+Data!AF16+Data!AG16+Data!AH16+Data!AD17+Data!AE17+Data!AF17+Data!AG17+Data!AH17+Data!AD18+Data!AE18+Data!AF18+Data!AG18+Data!AH18 -> 73593 | Z18: =Data!AI7+Data!AI8+Data!AI9+Data!AI10+Data!AI11+Data!AI12+Data!AI13+Data!AI14+Data!AI15+Data!AI16+Data!AI17+Data!AI18 -> 62502 | AA18: =Data!AJ7+Data!AJ8+Data!AJ9+Data!AJ10+Data!AJ11+Data!AJ12+Data!AJ13+Data!AJ14+Data!AJ15+Data!AJ16+Data!AJ17+Data!AJ18 -> 8139 | AB18: =Data!AK7+Data!AK8+Data!AK9+Data!AK10+Data!AK11+Data!AK12+Data!AK13+Data!AK14+Data!AK15+Data!AK16+Data!AK17+Data!AK18 -> 54630 | AC18: =Data!AL7+Data!AL8+Data!AL9+Data!AL10+Data!AL11+Data!AL12+Data!AL13+Data!AL14+Data!AL15+Data!AL16+Data!AL17+Data!AL18 -> 182043 | AD18: =Data!AM7+Data!AM8+Data!AM9+Data!AM10+Data!AM11+Data!AM12+Data!AM13+Data!AM14+Data!AM15+Data!AM16+Data!AM17+Data!AM18 -> -343524 | AE18: =Data!AN7+Data!AN8+Data!AN9+Data!AN10+Data!AN11+Data!AN12+Data!AN13+Data!AN14+Data!AN15+Data!AN16+Data!AN17+Data!AN18 -> 131259 | AF18: =Data!AO7+Data!AO8+Data!AO9+Data!AO10+Data!AO11+Data!AO12+Data!AO13+Data!AO14+Data!AO15+Data!AO16+Data!AO17+Data!AO18 -> -474785
B19: =Data!B19 -> 2017-01 | C19: =Data!D8+Data!E8+Data!F8+Data!G8+Data!H8+Data!I8+Data!J8+Data!K8+Data!L8+Data!M8+Data!N8+Data!O8+Data!P8+Data!Q8+Data!R8+Data!S8+Data!D9+Data!E9+Data!F9+Data!G9+Data!H9+Data!I9+Data!J9+Data!K9+Data!L9+Data!M9+Data!N9+Data!O9+Data!P9+Data!Q9+Data!R9+Data!S9+Data!D10+Data!E10+Data!F10+Data!G10+Data!H10+Data!I10+Data!J10+Data!K10+Data!L10+Data!M10+Data!N10+Data!O10+Data!P10+Data!Q10+Data!R10+Data!S10+Data!D11+Data!E11+Data!F11+Data!G11+Data!H11+Data!I11+Data!J11+Data!K11+Data!L11+Data!M11+Data!N11+Data!O11+Data!P11+Data!Q11+Data!R11+Data!S11+Data!D12+Data!E12+Data!F12+Data!G12+Data!H12+Data!I12+Data!J12+Data!K12+Data!L12+Data!M12+Data!N12+Data!O12+Data!P12+Data!Q12+Data!R12+Data!S12+Data!D13+Data!E13+Data!F13+Data!G13+Data!H13+Data!I13+Data!J13+Data!K13+Data!L13+Data!M13+Data!N13+Data!O13+Data!P13+Data!Q13+Data!R13+Data!S13+Data!D14+Data!E14+Data!F14+Data!G14+Data!H14+Data!I14+Data!J14+Data!K14+Data!L14+Data!M14+Data!N14+Data!O14+Data!P14+Data!Q14+Data!R14+Data!S14+Data!D15+Data!E15+Data!F15+Data!G15+Data!H15+Data!I15+Data!J15+Data!K15+Data!L15+Data!M15+Data!N15+Data!O15+Data!P15+Data!Q15+Data!R15+Data!S15+Data!D16+Data!E16+Data!F16+Data!G16+Data!H16+Data!I16+Data!J16+Data!K16+Data!L16+Data!M16+Data!N16+Data!O16+Data!P16+Data!Q16+Data!R16+Data!S16+Data!D17+Data!E17+Data!F17+Data!G17+Data!H17+Data!I17+Data!J17+Data!K17+Data!L17+Data!M17+Data!N17+Data!O17+Data!P17+Data!Q17+Data!R17+Data!S17+Data!D18+Data!E18+Data!F18+Data!G18+Data!H18+Data!I18+Data!J18+Data!K18+Data!L18+Data!M18+Data!N18+Data!O18+Data!P18+Data!Q18+Data!R18+Data!S18+Data!D19+Data!E19+Data!F19+Data!G19+Data!H19+Data!I19+Data!J19+Data!K19+Data!L19+Data!M19+Data!N19+Data!O19+Data!P19+Data!Q19+Data!R19+Data!S19 -> 1677949 | D19: =Data!D8+Data!E8+Data!G8+Data!H8+Data!I8+Data!J8+Data!K8+Data!L8+Data!M8+Data!D9+Data!E9+Data!G9+Data!H9+Data!I9+Data!J9+Data!K9+Data!L9+Data!M9+Data!D10+Data!E10+Data!G10+Data!H10+Data!I10+Data!J10+Data!K10+Data!L10+Data!M10+Data!D11+Data!E11+Data!G11+Data!H11+Data!I11+Data!J11+Data!K11+Data!L11+Data!M11+Data!D12+Data!E12+Data!G12+Data!H12+Data!I12+Data!J12+Data!K12+Data!L12+Data!M12+Data!D13+Data!E13+Data!G13+Data!H13+Data!I13+Data!J13+Data!K13+Data!L13+Data!M13+Data!D14+Data!E14+Data!G14+Data!H14+Data!I14+Data!J14+Data!K14+Data!L14+Data!M14+Data!D15+Data!E15+Data!G15+Data!H15+Data!I15+Data!J15+Data!K15+Data!L15+Data!M15+Data!D16+Data!E16+Data!G16+Data!H16+Data!I16+Data!J16+Data!K16+Data!L16+Data!M16+Data!D17+Data!E17+Data!G17+Data!H17+Data!I17+Data!J17+Data!K17+Data!L17+Data!M17+Data!D18+Data!E18+Data!G18+Data!H18+Data!I18+Data!J18+Data!K18+Data!L18+Data!M18+Data!D19+Data!E19+Data!G19+Data!H19+Data!I19+Data!J19+Data!K19+Data!L19+Data!M19 -> 1004340 | E19: =Data!D8+Data!D9+Data!D10+Data!D11+Data!D12+Data!D13+Data!D14+Data!D15+Data!D16+Data!D17+Data!D18+Data!D19 -> 283872 | F19: =Data!E8+Data!E9+Data!E10+Data!E11+Data!E12+Data!E13+Data!E14+Data!E15+Data!E16+Data!E17+Data!E18+Data!E19 -> 224706 | G19: =Data!K8+Data!K9+Data!K10+Data!K11+Data!K12+Data!K13+Data!K14+Data!K15+Data!K16+Data!K17+Data!K18+Data!K19 -> 73014 | H19: =Data!L8+Data!L9+Data!L10+Data!L11+Data!L12+Data!L13+Data!L14+Data!L15+Data!L16+Data!L17+Data!L18+Data!L19 -> 56581 | I19: =Data!G8+Data!G9+Data!G10+Data!G11+Data!G12+Data!G13+Data!G14+Data!G15+Data!G16+Data!G17+Data!G18+Data!G19 -> 112443 | J19: =Data!H8+Data!I8+Data!J8+Data!M8+Data!H9+Data!I9+Data!J9+Data!M9+Data!H10+Data!I10+Data!J10+Data!M10+Data!H11+Data!I11+Data!J11+Data!M11+Data!H12+Data!I12+Data!J12+Data!M12+Data!H13+Data!I13+Data!J13+Data!M13+Data!H14+Data!I14+Data!J14+Data!M14+Data!H15+Data!I15+Data!J15+Data!M15+Data!H16+Data!I16+Data!J16+Data!M16+Data!H17+Data!I17+Data!J17+Data!M17+Data!H18+Data!I18+Data!J18+Data!M18+Data!H19+Data!I19+Data!J19+Data!M19 -> 253724 | K19: =Data!F8+Data!F9+Data!F10+Data!F11+Data!F12+Data!F13+Data!F14+Data!F15+Data!F16+Data!F17+Data!F18+Data!F19 -> 574456 | L19: =Data!N8+Data!O8+Data!P8+Data!Q8+Data!R8+Data!S8+Data!N9+Data!O9+Data!P9+Data!Q9+Data!R9+Data!S9+Data!N10+Data!O10+Data!P10+Data!Q10+Data!R10+Data!S10+Data!N11+Data!O11+Data!P11+Data!Q11+Data!R11+Data!S11+Data!N12+Data!O12+Data!P12+Data!Q12+Data!R12+Data!S12+Data!N13+Data!O13+Data!P13+Data!Q13+Data!R13+Data!S13+Data!N14+Data!O14+Data!P14+Data!Q14+Data!R14+Data!S14+Data!N15+Data!O15+Data!P15+Data!Q15+Data!R15+Data!S15+Data!N16+Data!O16+Data!P16+Data!Q16+Data!R16+Data!S16+Data!N17+Data!O17+Data!P17+Data!Q17+Data!R17+Data!S17+Data!N18+Data!O18+Data!P18+Data!Q18+Data!R18+Data!S18+Data!N19+Data!O19+Data!P19+Data!Q19+Data!R19+Data!S19 -> 99153 | M19: =Data!T8+Data!U8+Data!V8+Data!W8+Data!X8+Data!Y8+Data!Z8+Data!AA8+Data!AB8+Data!AC8+Data!AD8+Data!AE8+Data!AF8+Data!AG8+Data!AH8+Data!AI8+Data!AJ8+Data!AK8+Data!AL8+Data!T9+Data!U9+Data!V9+Data!W9+Data!X9+Data!Y9+Data!Z9+Data!AA9+Data!AB9+Data!AC9+Data!AD9+Data!AE9+Data!AF9+Data!AG9+Data!AH9+Data!AI9+Data!AJ9+Data!AK9+Data!AL9+Data!T10+Data!U10+Data!V10+Data!W10+Data!X10+Data!Y10+Data!Z10+Data!AA10+Data!AB10+Data!AC10+Data!AD10+Data!AE10+Data!AF10+Data!AG10+Data!AH10+Data!AI10+Data!AJ10+Data!AK10+Data!AL10+Data!T11+Data!U11+Data!V11+Data!W11+Data!X11+Data!Y11+Data!Z11+Data!AA11+Data!AB11+Data!AC11+Data!AD11+Data!AE11+Data!AF11+Data!AG11+Data!AH11+Data!AI11+Data!AJ11+Data!AK11+Data!AL11+Data!T12+Data!U12+Data!V12+Data!W12+Data!X12+Data!Y12+Data!Z12+Data!AA12+Data!AB12+Data!AC12+Data!AD12+Data!AE12+Data!AF12+Data!AG12+Data!AH12+Data!AI12+Data!AJ12+Data!AK12+Data!AL12+Data!T13+Data!U13+Data!V13+Data!W13+Data!X13+Data!Y13+Data!Z13+Data!AA13+Data!AB13+Data!AC13+Data!AD13+Data!AE13+Data!AF13+Data!AG13+Data!AH13+Data!AI13+Data!AJ13+Data!AK13+Data!AL13+Data!T14+Data!U14+Data!V14+Data!W14+Data!X14+Data!Y14+Data!Z14+Data!AA14+Data!AB14+Data!AC14+Data!AD14+Data!AE14+Data!AF14+Data!AG14+Data!AH14+Data!AI14+Data!AJ14+Data!AK14+Data!AL14+Data!T15+Data!U15+Data!V15+Data!W15+Data!X15+Data!Y15+Data!Z15+Data!AA15+Data!AB15+Data!AC15+Data!AD15+Data!AE15+Data!AF15+Data!AG15+Data!AH15+Data!AI15+Data!AJ15+Data!AK15+Data!AL15+Data!T16+Data!U16+Data!V16+Data!W16+Data!X16+Data!Y16+Data!Z16+Data!AA16+Data!AB16+Data!AC16+Data!AD16+Data!AE16+Data!AF16+Data!AG16+Data!AH16+Data!AI16+Data!AJ16+Data!AK16+Data!AL16+Data!T17+Data!U17+Data!V17+Data!W17+Data!X17+Data!Y17+Data!Z17+Data!AA17+Data!AB17+Data!AC17+Data!AD17+Data!AE17+Data!AF17+Data!AG17+Data!AH17+Data!AI17+Data!AJ17+Data!AK17+Data!AL17+Data!T18+Data!U18+Data!V18+Data!W18+Data!X18+Data!Y18+Data!Z18+Data!AA18+Data!AB18+Data!AC18+Data!AD18+Data!AE18+Data!AF18+Data!AG18+Data!AH18+Data!AI18+Data!AJ18+Data!AK18+Data!AL18+Data!T19+Data!U19+Data!V19+Data!W19+Data!X19+Data!Y19+Data!Z19+Data!AA19+Data!AB19+Data!AC19+Data!AD19+Data!AE19+Data!AF19+Data!AG19+Data!AH19+Data!AI19+Data!AJ19+Data!AK19+Data!AL19 -> 2018627 | N19: =Data!T8+Data!U8+Data!V8+Data!W8+Data!T9+Data!U9+Data!V9+Data!W9+Data!T10+Data!U10+Data!V10+Data!W10+Data!T11+Data!U11+Data!V11+Data!W11+Data!T12+Data!U12+Data!V12+Data!W12+Data!T13+Data!U13+Data!V13+Data!W13+Data!T14+Data!U14+Data!V14+Data!W14+Data!T15+Data!U15+Data!V15+Data!W15+Data!T16+Data!U16+Data!V16+Data!W16+Data!T17+Data!U17+Data!V17+Data!W17+Data!T18+Data!U18+Data!V18+Data!W18+Data!T19+Data!U19+Data!V19+Data!W19 -> 950075 | O19: =Data!T8+Data!T9+Data!T10+Data!T11+Data!T12+Data!T13+Data!T14+Data!T15+Data!T16+Data!T17+Data!T18+Data!T19 -> 672515 | P19: =Data!U8+Data!U9+Data!U10+Data!U11+Data!U12+Data!U13+Data!U14+Data!U15+Data!U16+Data!U17+Data!U18+Data!U19 -> 112645 | Q19: =Data!V8+Data!V9+Data!V10+Data!V11+Data!V12+Data!V13+Data!V14+Data!V15+Data!V16+Data!V17+Data!V18+Data!V19 -> 81141 | R19: =Data!W8+Data!W9+Data!W10+Data!W11+Data!W12+Data!W13+Data!W14+Data!W15+Data!W16+Data!W17+Data!W18+Data!W19 -> 83774 | S19: =Data!X8+Data!X9+Data!X10+Data!X11+Data!X12+Data!X13+Data!X14+Data!X15+Data!X16+Data!X17+Data!X18+Data!X19 -> 31453 | T19: =Data!Y8+Data!Z8+Data!AA8+Data!Y9+Data!Z9+Data!AA9+Data!Y10+Data!Z10+Data!AA10+Data!Y11+Data!Z11+Data!AA11+Data!Y12+Data!Z12+Data!AA12+Data!Y13+Data!Z13+Data!AA13+Data!Y14+Data!Z14+Data!AA14+Data!Y15+Data!Z15+Data!AA15+Data!Y16+Data!Z16+Data!AA16+Data!Y17+Data!Z17+Data!AA17+Data!Y18+Data!Z18+Data!AA18+Data!Y19+Data!Z19+Data!AA19 -> 290528 | U19: =Data!Y8+Data!Y9+Data!Y10+Data!Y11+Data!Y12+Data!Y13+Data!Y14+Data!Y15+Data!Y16+Data!Y17+Data!Y18+Data!Y19 -> 208340 | V19: =Data!Z8+Data!Z9+Data!Z10+Data!Z11+Data!Z12+Data!Z13+Data!Z14+Data!Z15+Data!Z16+Data!Z17+Data!Z18+Data!Z19 -> 80387 | W19: =Data!AB8+Data!AB9+Data!AB10+Data!AB11+Data!AB12+Data!AB13+Data!AB14+Data!AB15+Data!AB16+Data!AB17+Data!AB18+Data!AB19 -> 273836 | X19: =Data!AC8+Data!AC9+Data!AC10+Data!AC11+Data!AC12+Data!AC13+Data!AC14+Data!AC15+Data!AC16+Data!AC17+Data!AC18+Data!AC19 -> 82865 | Y19: =Data!AD8+Data!AE8+Data!AF8+Data!AG8+Data!AH8+Data!AD9+Data!AE9+Data!AF9+Data!AG9+Data!AH9+Data!AD10+Data!AE10+Data!AF10+Data!AG10+Data!AH10+Data!AD11+Data!AE11+Data!AF11+Data!AG11+Data!AH11+Data!AD12+Data!AE12+Data!AF12+Data!AG12+Data!AH12+Data!AD13+Data!AE13+Data!AF13+Data!AG13+Data!AH13+Data!AD14+Data!AE14+Data!AF14+Data!AG14+Data!AH14+Data!AD15+Data!AE15+Data!AF15+Data!AG15+Data!AH15+Data!AD16+Data!AE16+Data!AF16+Data!AG16+Data!AH16+Data!AD17+Data!AE17+Data!AF17+Data!AG17+Data!AH17+Data!AD18+Data!AE18+Data!AF18+Data!AG18+Data!AH18+Data!AD19+Data!AE19+Data!AF19+Data!AG19+Data!AH19 -> 76934 | Z19: =Data!AI8+Data!AI9+Data!AI10+Data!AI11+Data!AI12+Data!AI13+Data!AI14+Data!AI15+Data!AI16+Data!AI17+Data!AI18+Data!AI19 -> 63965 | AA19: =Data!AJ8+Data!AJ9+Data!AJ10+Data!AJ11+Data!AJ12+Data!AJ13+Data!AJ14+Data!AJ15+Data!AJ16+Data!AJ17+Data!AJ18+Data!AJ19 -> 8141 | AB19: =Data!AK8+Data!AK9+Data!AK10+Data!AK11+Data!AK12+Data!AK13+Data!AK14+Data!AK15+Data!AK16+Data!AK17+Data!AK18+Data!AK19 -> 56691 | AC19: =Data!AL8+Data!AL9+Data!AL10+Data!AL11+Data!AL12+Data!AL13+Data!AL14+Data!AL15+Data!AL16+Data!AL17+Data!AL18+Data!AL19 -> 184139 | AD19: =Data!AM8+Data!AM9+Data!AM10+Data!AM11+Data!AM12+Data!AM13+Data!AM14+Data!AM15+Data!AM16+Data!AM17+Data!AM18+Data!AM19 -> -340678 | AE19: =Data!AN8+Data!AN9+Data!AN10+Data!AN11+Data!AN12+Data!AN13+Data!AN14+Data!AN15+Data!AN16+Data!AN17+Data!AN18+Data!AN19 -> 137464 | AF19: =Data!AO8+Data!AO9+Data!AO10+Data!AO11+Data!AO12+Data!AO13+Data!AO14+Data!AO15+Data!AO16+Data!AO17+Data!AO18+Data!AO19 -> -478144
