Workbook

Sheet Tabelle1
D1: EMAE | E1: Agri. | F1: Fishing | G1: Mining | H1: Mfg. | I1: Utilities | J1: Const. | K1: Trade | L1: Hotels | M1: Transport | N1: Finance | O1: Real Estate | P1: Public Admin. | Q1: Education | R1: Health | S1: Other Services
B2: 10401 !M NA_ | C2: .excel_last | D2: S213GVI@EMERGELA | E2: N213GAFI@EMERGELA | F2: N213GFFI@EMERGELA | G2: N213GQI@EMERGELA | H2: N213GMI@EMERGELA | I2: N213GEI@EMERGELA | J2: N213GCOI@EMERGELA | K2: N213GWRI@EMERGELA | L2: N213GHI@EMERGELA | M2: N213GTSI@EMERGELA | N2: N213GFMI@EMERGELA | O2: N213GPRI@EMERGELA | P2: N213GGI@EMERGELA | Q2: N213GDI@EMERGELA | R2: N213GHSI@EMERGELA | S2: N213GSOI@EMERGELA
B3: .DESC | D3: Argentina: Economic Activity Indicator (SA, 2004=100) | E3: Argentina: Economic Act: Agr, Livestock, Hunting & Forestry (NSA, 2004=100) | F3: Argentina: Economic Activity: Fishing (NSA, 2004=100) | G3: Argentina: Economic Activity: Mining & Quarrying(NSA, 2004=100) | H3: Argentina: Economic Activity: Manufacturing (NSA, 2004=100) | I3: Argentina: Economic Activity: Electricity, Gas & Water (NSA, 2004=100) | J3: Argentina: Economic Activity: Construction (NSA, 2004=100) | K3: Argentina: Economic Act: Wholesale & Retail Trade and Repairs (NSA, 2004=100) | L3: Argentina: Economic Activity: Hotel & Restaurants (NSA, 2004=100) | M3: Argentina: Economic Activity: Transportation & Communications (NSA, 2004=100) | N3: Argentina: Economic Activity: Financial Intermediation (NSA, 2004=100) | O3: Argentina: Econ Act: Real Estate, Business & Rental Activities (NSA, 2004=100) | P3: Argentina: Econ Act: Public Admin & Defense, SocSec Plans (NSA, 2004=100) | Q3: Argentina: Economic Activity: Education (NSA, 2004=100) | R3: Argentina: Economic Activity: Social & Health Services (NSA, 2004=100) | S3: Argentina: EconAct: Other Community, Social & Personal Srvc Act (NSA, 2004=100)
B4: .SOURCE | D4: INDEC | E4: INDEC | F4: INDEC | G4: INDEC | H4: INDEC | I4: INDEC | J4: INDEC | K4: INDEC | L4: INDEC | M4: INDEC | N4: INDEC | O4: INDEC | P4: INDEC | Q4: INDEC | R4: INDEC | S4: INDEC
B5: .DTLM | D5: Jul-22-2026 15:06 | E5: Jul-22-2026 15:06 | F5: Jul-22-2026 15:06 | G5: Jul-22-2026 15:06 | H5: Jul-22-2026 15:06 | I5: Jul-22-2026 15:06 | J5: Jul-22-2026 15:06 | K5: Jul-22-2026 15:06 | L5: Jul-22-2026 15:06 | M5: Jul-22-2026 15:06 | N5: Jul-22-2026 15:06 | O5: Jul-22-2026 15:06 | P5: Jul-22-2026 15:06 | Q5: Jul-22-2026 15:06 | R5: Jul-22-2026 15:06 | S5: Jul-22-2026 15:06
B6: .DATA_TYPE | D6: INDEX | E6: INDEX | F6: INDEX | G6: INDEX | H6: INDEX | I6: INDEX | J6: INDEX | K6: INDEX | L6: INDEX | M6: INDEX | N6: INDEX | O6: INDEX | P6: INDEX | Q6: INDEX | R6: INDEX | S6: INDEX
B7: .MAG | D7: 0 | E7: 0 | F7: 0 | G7: 0 | H7: 0 | I7: 0 | J7: 0 | K7: 0 | L7: 0 | M7: 0 | N7: 0 | O7: 0 | P7: 0 | Q7: 0 | R7: 0 | S7: 0
B8: 0401 | C8: 38017 | D8: 98.33957 | E8: 65.99535 | F8: 42.54787 | G8: 100.7045 | H8: 91.45461 | I8: 99.91798 | J8: 95.93805 | K8: 92.06534 | L8: 108.41168 | M8: 95.50673 | N8: 103.89026 | O8: 91.41838 | P8: 97.26127 | Q8: 95.6277 | R8: 94.19839 | S8: 97.00618
B9: 0402 | C9: 38046 | D9: 98.07072 | E9: 64.9266 | F9: 62.44077 | G9: 95.41419 | H9: 89.42485 | I9: 92.89344 | J9: 98.85339 | K9: 91.46472 | L9: 103.44826 | M9: 90.73641 | N9: 96.48146 | O9: 94.04698 | P9: 97.88228 | Q9: 96.08425 | R9: 90.31346 | S9: 96.83613
B10: 0403 | C10: 38077 | D10: 97.66795 | E10: 110.66656 | F10: 174.08465 | G10: 100.25104 | H10: 101.42643 | I10: 103.77021 | J10: 103.12453 | K10: 109.12778 | L10: 101.06184 | M10: 97.17581 | N10: 98.30457 | O10: 99.64872 | P10: 97.71846 | Q10: 96.3803 | R10: 98.08149 | S10: 96.15504
B11: 0404 | C11: 38107 | D11: 95.23678 | E11: 150.06592 | F11: 153.87764 | G11: 96.69755 | H11: 98.43731 | I11: 97.00985 | J11: 95.81549 | K11: 99.42014 | L11: 93.243 | M11: 99.70693 | N11: 95.3159 | O11: 97.60226 | P11: 98.40554 | Q11: 97.71187 | R11: 102.18435 | S11: 98.08314
B12: 0405 | C12: 38138 | D12: 96.95127 | E12: 209.38808 | F12: 132.35766 | G12: 104.10053 | H12: 100.35314 | I12: 102.47183 | J12: 97.99457 | K12: 100.53274 | L12: 90.98526 | M12: 105.55244 | N12: 97.00467 | O12: 99.80349 | P12: 99.20852 | Q12: 99.13689 | R12: 102.76126 | S12: 98.05435
B13: 0406 | C13: 38168 | D13: 98.68356 | E13: 144.66132 | F13: 158.95986 | G13: 100.67785 | H13: 100.66693 | I13: 101.91112 | J13: 99.15678 | K13: 104.34202 | L13: 90.55608 | M13: 101.67565 | N13: 97.31215 | O13: 101.71298 | P13: 100.4454 | Q13: 102.20951 | R13: 104.26446 | S13: 99.76658
B14: 0407 | C14: 38199 | D14: 100.8411 | E14: 94.86246 | F14: 77.40334 | G14: 100.80174 | H14: 102.50853 | I14: 105.41654 | J14: 98.906 | K14: 100.82722 | L14: 99.05112 | M14: 99.8302 | N14: 99.01951 | O14: 100.85959 | P14: 100.16519 | Q14: 100.50009 | R14: 101.84397 | S14: 108.7301
B15: 0408 | C15: 38230 | D15: 102.17769 | E15: 64.86116 | F15: 99.29888 | G15: 102.27351 | H15: 101.01094 | I15: 103.97781 | J15: 102.03281 | K15: 99.55237 | L15: 98.1705 | M15: 99.2237 | N15: 101.18031 | O15: 101.57448 | P15: 100.67623 | Q15: 101.39315 | R15: 104.49316 | S15: 100.45682
B16: 0409 | C16: 38260 | D16: 102.35036 | E16: 60.7499 | F16: 68.15818 | G16: 100.58408 | H16: 102.56272 | I16: 97.65632 | J16: 106.81513 | K16: 99.96032 | L16: 100.05105 | M16: 98.89115 | N16: 100.80853 | O16: 103.00434 | P16: 101.52659 | Q16: 101.80328 | R16: 104.69994 | S16: 99.92452
B17: 0410 | C17: 38291 | D17: 103.12368 | E17: 62.66926 | F17: 84.44642 | G17: 101.39273 | H17: 105.90569 | I17: 96.18753 | J17: 97.84211 | K17: 101.16296 | L17: 102.93943 | M17: 101.57252 | N17: 102.0793 | O17: 100.69115 | P17: 101.68981 | Q17: 102.21213 | R17: 100.22067 | S17: 101.16164
B18: 0411 | C18: 38321 | D18: 103.57877 | E18: 78.41525 | F18: 70.43561 | G18: 96.38347 | H18: 104.37511 | I18: 95.06963 | J18: 101.65557 | K18: 102.41598 | L18: 106.49311 | M18: 104.54272 | N18: 102.96217 | O18: 103.28028 | P18: 102.03612 | Q18: 102.50137 | R18: 99.69656 | S18: 100.02634
B19: 0412 | C19: 38352 | D19: 102.97856 | E19: 92.73814 | F19: 75.98912 | G19: 100.71881 | H19: 101.87374 | I19: 103.71775 | J19: 101.86557 | K19: 99.12842 | L19: 105.58867 | M19: 105.58575 | N19: 105.64116 | O19: 106.35733 | P19: 102.9846 | Q19: 104.43946 | R19: 97.24229 | S19: 103.79916
... B276: 2605 | C276: 46173 | D276: 153.62027 | E276: 297.66329 | F276: 102.84501 | G276: 144.59675 | H276: 114.35306 | I276: 158.63625 | J276: 124.37794 | K276: 153.91377 | L276: 157.15323 | M276: 197.26347 | N276: 179.16448 | O276: 159.78965 | P276: 158.5742 | Q276: 171.81406 | R276: 198.56366 | S276: 116.71788

Sheet Weights & Assumptions
A1: Weights, Sector Mapping and Forecast Assumptions
A2: Blue cells are inputs you can overwrite. Everything downstream is formula-driven and will recalculate.
A4: 1 | Sector weights and bucket mapping
A5: Sector | B5: Bucket | C5: Weight (%) | D5: INDEC 2004 prior (%) | E5: Deviation (pp) | F5: Weight within bucket | G5: Contribution check
A6: Agri. | B6: Primary | C6: 8.2873 | D6: 8.7 | E6: =C6-D6*100/SUM($D$6:$D$20) -> -0.71891118 | F6: =C6/SUMIF($B$6:$B$20,B6,$C$6:$C$20) -> 0.98774746 | G6: =C6/SUM($C$6:$C$20) -> 0.082872834
A7: Fishing | B7: Primary | C7: 0.1028 | D7: 0.4 | E7: =C7-D7*100/SUM($D$6:$D$20) -> -0.31127867 | F7: =C7/SUMIF($B$6:$B$20,B7,$C$6:$C$20) -> 0.012252536 | G7: =C7/SUM($C$6:$C$20) -> 0.0010279979
A8: Mining | B8: Industrial | C8: 3.175 | D8: 4 | E8: =C8-D8*100/SUM($D$6:$D$20) -> -0.96578675 | F8: =C8/SUMIF($B$6:$B$20,B8,$C$6:$C$20) -> 0.11939771 | G8: =C8/SUM($C$6:$C$20) -> 0.031749937
A9: Mfg. | B9: Industrial | C9: 17.8771 | D9: 17.5 | E9: =C9-D9*100/SUM($D$6:$D$20) -> -0.23884203 | F9: =C9/SUMIF($B$6:$B$20,B9,$C$6:$C$20) -> 0.67227867 | G9: =C9/SUM($C$6:$C$20) -> 0.17877064
A10: Utilities | B10: Services | C10: 1.8434 | D10: 2 | E10: =C10-D10*100/SUM($D$6:$D$20) -> -0.22699337 | F10: =C10/SUMIF($B$6:$B$20,B10,$C$6:$C$20) -> 0.028352018 | G10: =C10/SUM($C$6:$C$20) -> 0.018433963
A11: Const. | B11: Industrial | C11: 5.5397 | D11: 5.3 | E11: =C11-D11*100/SUM($D$6:$D$20) -> 0.053157557 | F11: =C11/SUMIF($B$6:$B$20,B11,$C$6:$C$20) -> 0.20832362 | G11: =C11/SUM($C$6:$C$20) -> 0.055396889
A12: Trade | B12: Services | C12: 13.2283 | D12: 12.4 | E12: =C12-D12*100/SUM($D$6:$D$20) -> 0.39186108 | F12: =C12/SUMIF($B$6:$B$20,B12,$C$6:$C$20) -> 0.20345503 | G12: =C12/SUM($C$6:$C$20) -> 0.13228274
A13: Hotels | B13: Services | C13: 3.0404 | D13: 2.7 | E13: =C13-D13*100/SUM($D$6:$D$20) -> 0.24536894 | F13: =C13/SUMIF($B$6:$B$20,B13,$C$6:$C$20) -> 0.046762219 | G13: =C13/SUM($C$6:$C$20) -> 0.030403939
A14: Transport | B14: Services | C14: 9.4699 | D14: 8.3 | E14: =C14-D14*100/SUM($D$6:$D$20) -> 0.87776749 | F14: =C14/SUMIF($B$6:$B$20,B14,$C$6:$C$20) -> 0.14564976 | G14: =C14/SUM($C$6:$C$20) -> 0.094698811
A15: Finance | B15: Services | C15: 4.9519 | D15: 4 | E15: =C15-D15*100/SUM($D$6:$D$20) -> 0.81111325 | F15: =C15/SUMIF($B$6:$B$20,B15,$C$6:$C$20) -> 0.076161634 | G15: =C15/SUM($C$6:$C$20) -> 0.049518901
A16: Real Estate | B16: Services | C16: 13.2728 | D16: 12.9 | E16: =C16-D16*100/SUM($D$6:$D$20) -> -0.081237267 | F16: =C16/SUMIF($B$6:$B$20,B16,$C$6:$C$20) -> 0.20413945 | G16: =C16/SUM($C$6:$C$20) -> 0.13272773
A17: Public Admin. | B17: Services | C17: 6.1054 | D17: 6 | E17: =C17-D17*100/SUM($D$6:$D$20) -> -0.10578012 | F17: =C17/SUMIF($B$6:$B$20,B17,$C$6:$C$20) -> 0.093902794 | G17: =C17/SUM($C$6:$C$20) -> 0.061053878
... A20: Other Services | B20: Services | C20: 3.5611 | D20: 3.6 | E20: =C20-D20*100/SUM($D$6:$D$20) -> -0.16560807 | F20: =C20/SUMIF($B$6:$B$20,B20,$C$6:$C$20) -> 0.054770734 | G20: =C20/SUM($C$6:$C$20) -> 0.035610929
A21: Total | C21: =SUM(C6:C20) -> 100.0002 | D21: =SUM(D6:D20) -> 96.6 | G21: =SUM(G6:G20) -> 1
A23: 2 | Bucket weights (derived)
A24: Bucket | B24: Weight (%) | C24: Share of EMAE
A25: Primary | B25: =SUMIF($B$6:$B$20,A25,$C$6:$C$20) -> 8.3901 | C25: =B25/SUM($B$25:$B$27) -> 0.083900832
A26: Industrial | B26: =SUMIF($B$6:$B$20,A26,$C$6:$C$20) -> 26.5918 | C26: =B26/SUM($B$25:$B$27) -> 0.26591747
A27: Services | B27: =SUMIF($B$6:$B$20,A27,$C$6:$C$20) -> 65.0183 | C27: =B27/SUM($B$25:$B$27) -> 0.6501817
A28: Total | B28: =SUM(B25:B27) -> 100.0002
A30: 3 | Forecast assumptions — average m/m growth of each sub-index, SA (%)
A31: The forecast is built bottom-up: these three pairs of assumptions drive the sub-index level paths, which aggregate to EMAE using the bucket weights above. Change a cell and every forecast number moves.
A32: Sub-index | B32: May-26 to Dec-26 (% m/m) | C32: 2027 (% m/m) | D32: Implied ann. pace 2026H2 | E32: Implied ann. pace 2027 | F32: Trailing 6m actual (% m/m)
A33: Primary | B33: 0.1 | C33: 0.25 | D33: =((1+B33/100)^12-1)*100 -> 1.206622 | E33: =((1+C33/100)^12-1)*100 -> 3.0415957 | F33: 2.62
A34: Industrial | B34: 0.15 | C34: 0.35 | D34: =((1+B34/100)^12-1)*100 -> 1.8149245 | E34: =((1+C34/100)^12-1)*100 -> 4.2818007 | F34: 0
A35: Services | B35: 0.15 | C35: 0.3 | D35: =((1+B35/100)^12-1)*100 -> 1.8149245 | E35: =((1+C35/100)^12-1)*100 -> 3.659998 | F35: 0.03
A38: 4 | Weight estimation diagnostics
A39: Method | B39: Constrained least squares of the 15 seasonally-adjusted sector indices on the published SA EMAE, shrunk toward the INDEC 2004 value-added shares.
A40: Why shrinkage | B40: Every series is rebased to 2004=100, so EMAE is exactly a convex combination of the sectors and the weights are the 2004 value-added shares. But the services block is highly collinear: the unpenalised fit pins Education, Utilities, Public Admin and Other Services at zero and pushes Trade to 22.9%. Shrinkage restores economically sensible weights at almost no cost in fit.
A41: Shrinkage parameter | B41: lambda = 5.0
A42: R-squared | B42: 0.98958
A43: Residual std. dev. (index pts) | B43: 1.469
A44: Max abs. residual (index pts) | B44: 4.301
A45: Bucket weights: stability | B45: Primary 8-10%, Industrial 26-27%, Services 63-65% across the entire shrinkage range. The bucket split is well identified even though individual sector weights are not.
A46: Override | B46: If you have INDEC's official EMAE base-2004 weights, paste them into column C. Nothing else needs changing.

Sheet SA Data
A1: Seasonally Adjusted Levels
A2: Sector SA levels are computed values (X-11-style multiplicative decomposition) and do NOT auto-update with Haver. NSA columns and all sub-indices are live formulas.
A4: Sub-index levels are SUMPRODUCTs of the sector indices and the within-bucket weights on 'Weights & Assumptions', so they respond immediately to any weight change.
A6: Date | B6: EMAE published (SA) | C6: Agri. (SA) | D6: Fishing (SA) | E6: Mining (SA) | F6: Mfg. (SA) | G6: Utilities (SA) | H6: Const. (SA) | I6: Trade (SA) | J6: Hotels (SA) | K6: Transport (SA) | L6: Finance (SA) | M6: Real Estate (SA) | N6: Public Admin. (SA) | O6: Education (SA) | P6: Health (SA) | Q6: Other Services (SA) | R6: Primary (SA) | S6: Industrial (SA) | T6: Services (SA) | U6: EMAE reconstructed (SA) | V6: Primary (NSA) | W6: Industrial (NSA) | X6: Services (NSA) | Y6: EMAE reconstructed (NSA)
A7: 38017 | B7: 98.33957 | C7: 122.29655 | D7: 120.21122 | E7: 99.535438 | F7: 95.81535 | G7: 97.308176 | H7: 96.577477 | I7: 97.979626 | J7: 95.579602 | K7: 96.389149 | L7: 98.779296 | M7: 96.182671 | N7: 97.505233 | O7: 96.74534 | P7: 97.417586 | Q7: 95.35565 | R7: =C7*'Weights & Assumptions'!$F$6+D7*'Weights & Assumptions'!$F$7 -> 122.271 | S7: =E7*'Weights & Assumptions'!$F$8+F7*'Weights & Assumptions'!$F$9+H7*'Weights & Assumptions'!$F$11 -> 96.418289 | T7: =G7*'Weights & Assumptions'!$F$10+I7*'Weights & Assumptions'!$F$12+J7*'Weights & Assumptions'!$F$13+K7*'Weights & Assumptions'!$F$14+L7*'Weights & Assumptions'!$F$15+M7*'Weights & Assumptions'!$F$16+N7*'Weights & Assumptions'!$F$17+O7*'Weights & Assumptions'!$F$18+P7*'Weights & Assumptions'!$F$19+Q7*'Weights & Assumptions'!$F$20 -> 96.990289 | U7: =R7*'Weights & Assumptions'!$B$25/'Weights & Assumptions'!$B$28+S7*'Weights & Assumptions'!$B$26/'Weights & Assumptions'!$B$28+T7*'Weights & Assumptions'!$B$27/'Weights & Assumptions'!$B$28 -> 98.959257 | V7: =IFERROR(Tabelle1!E8*'Weights & Assumptions'!$F$6+Tabelle1!F8*'Weights & Assumptions'!$F$7,"") -> 65.708059 | W7: =IFERROR(Tabelle1!G8*'Weights & Assumptions'!$F$8+Tabelle1!H8*'Weights & Assumptions'!$F$9+Tabelle1!J8*'Weights & Assumptions'!$F$11,"") -> 93.493032 | X7: =IFERROR(Tabelle1!I8*'Weights & Assumptions'!$F$10+Tabelle1!K8*'Weights & Assumptions'!$F$12+Tabelle1!L8*'Weights & Assumptions'!$F$13+Tabelle1!M8*'Weights & Assumptions'!$F$14+Tabelle1!N8*'Weights & Assumptions'!$F$15+Tabelle1!O8*'Weights & Assumptions'!$F$16+Tabelle1!P8*'Weights & Assumptions'!$F$17+Tabelle1!Q8*'Weights & Assumptions'!$F$18+Tabelle1!R8*'Weights & Assumptions'!$F$19+Tabelle1!S8*'Weights & Assumptions'!$F$20,"") -> 95.499519 | Y7: =IFERROR(V7*'Weights & Assumptions'!$B$25/'Weights & Assumptions'!$B$28+W7*'Weights & Assumptions'!$B$26/'Weights & Assumptions'!$B$28+X7*'Weights & Assumptions'!$B$27/'Weights & Assumptions'!$B$28,"") -> 92.466431
A8: 38046 | B8: 98.07072 | C8: 115.81236 | D8: 87.445869 | E8: 101.41784 | F8: 96.976622 | G8: 98.858384 | H8: 96.992826 | I8: 98.207697 | J8: 96.466881 | K8: 97.06902 | L8: 97.805568 | M8: 96.906771 | N8: 97.963489 | O8: 97.33128 | P8: 97.916659 | Q8: 98.126777 | R8: =C8*'Weights & Assumptions'!$F$6+D8*'Weights & Assumptions'!$F$7 -> 115.4648 | S8: =E8*'Weights & Assumptions'!$F$8+F8*'Weights & Assumptions'!$F$9+H8*'Weights & Assumptions'!$F$11 -> 97.510269 | T8: =G8*'Weights & Assumptions'!$F$10+I8*'Weights & Assumptions'!$F$12+J8*'Weights & Assumptions'!$F$13+K8*'Weights & Assumptions'!$F$14+L8*'Weights & Assumptions'!$F$15+M8*'Weights & Assumptions'!$F$16+N8*'Weights & Assumptions'!$F$17+O8*'Weights & Assumptions'!$F$18+P8*'Weights & Assumptions'!$F$19+Q8*'Weights & Assumptions'!$F$20 -> 97.569313 | U8: =R8*'Weights & Assumptions'!$B$25/'Weights & Assumptions'!$B$28+S8*'Weights & Assumptions'!$B$26/'Weights & Assumptions'!$B$28+T8*'Weights & Assumptions'!$B$27/'Weights & Assumptions'!$B$28 -> 99.055058 | V8: =IFERROR(Tabelle1!E9*'Weights & Assumptions'!$F$6+Tabelle1!F9*'Weights & Assumptions'!$F$7,"") -> 64.896142 | W8: =IFERROR(Tabelle1!G9*'Weights & Assumptions'!$F$8+Tabelle1!H9*'Weights & Assumptions'!$F$9+Tabelle1!J9*'Weights & Assumptions'!$F$11,"") -> 92.104151 | X8: =IFERROR(Tabelle1!I9*'Weights & Assumptions'!$F$10+Tabelle1!K9*'Weights & Assumptions'!$F$12+Tabelle1!L9*'Weights & Assumptions'!$F$13+Tabelle1!M9*'Weights & Assumptions'!$F$14+Tabelle1!N9*'Weights & Assumptions'!$F$15+Tabelle1!O9*'Weights & Assumptions'!$F$16+Tabelle1!P9*'Weights & Assumptions'!$F$17+Tabelle1!Q9*'Weights & Assumptions'!$F$18+Tabelle1!R9*'Weights & Assumptions'!$F$19+Tabelle1!S9*'Weights & Assumptions'!$F$20,"") -> 94.023346 | Y8: =IFERROR(V8*'Weights & Assumptions'!$B$25/'Weights & Assumptions'!$B$28+W8*'Weights & Assumptions'!$B$26/'Weights & Assumptions'!$B$28+X8*'Weights & Assumptions'!$B$27/'Weights & Assumptions'!$B$28,"") -> 91.069202
A9: 38077 | B9: 97.66795 | C9: 100.7906 | D9: 108.54386 | E9: 99.754717 | F9: 97.557282 | G9: 101.62633 | H9: 97.766438 | I9: 99.037171 | J9: 96.995971 | K9: 97.125243 | L9: 97.763415 | M9: 98.182217 | N9: 98.126239 | O9: 97.400252 | P9: 98.022085 | Q9: 98.595348 | R9: =C9*'Weights & Assumptions'!$F$6+D9*'Weights & Assumptions'!$F$7 -> 100.88559 | S9: =E9*'Weights & Assumptions'!$F$8+F9*'Weights & Assumptions'!$F$9+H9*'Weights & Assumptions'!$F$11 -> 97.863223 | T9: =G9*'Weights & Assumptions'!$F$10+I9*'Weights & Assumptions'!$F$12+J9*'Weights & Assumptions'!$F$13+K9*'Weights & Assumptions'!$F$14+L9*'Weights & Assumptions'!$F$15+M9*'Weights & Assumptions'!$F$16+N9*'Weights & Assumptions'!$F$17+O9*'Weights & Assumptions'!$F$18+P9*'Weights & Assumptions'!$F$19+Q9*'Weights & Assumptions'!$F$20 -> 98.160367 | U9: =R9*'Weights & Assumptions'!$B$25/'Weights & Assumptions'!$B$28+S9*'Weights & Assumptions'!$B$26/'Weights & Assumptions'!$B$28+T9*'Weights & Assumptions'!$B$27/'Weights & Assumptions'!$B$28 -> 98.31 | V9: =IFERROR(Tabelle1!E10*'Weights & Assumptions'!$F$6+Tabelle1!F10*'Weights & Assumptions'!$F$7,"") -> 111.44359 | W9: =IFERROR(Tabelle1!G10*'Weights & Assumptions'!$F$8+Tabelle1!H10*'Weights & Assumptions'!$F$9+Tabelle1!J10*'Weights & Assumptions'!$F$11,"") -> 101.63985 | X9: =IFERROR(Tabelle1!I10*'Weights & Assumptions'!$F$10+Tabelle1!K10*'Weights & Assumptions'!$F$12+Tabelle1!L10*'Weights & Assumptions'!$F$13+Tabelle1!M10*'Weights & Assumptions'!$F$14+Tabelle1!N10*'Weights & Assumptions'!$F$15+Tabelle1!O10*'Weights & Assumptions'!$F$16+Tabelle1!P10*'Weights & Assumptions'!$F$17+Tabelle1!Q10*'Weights & Assumptions'!$F$18+Tabelle1!R10*'Weights & Assumptions'!$F$19+Tabelle1!S10*'Weights & Assumptions'!$F$20,"") -> 100.56916 | Y9: =IFERROR(V9*'Weights & Assumptions'!$B$25/'Weights & Assumptions'!$B$28+W9*'Weights & Assumptions'!$B$26/'Weights & Assumptions'!$B$28+X9*'Weights & Assumptions'!$B$27/'Weights & Assumptions'!$B$28,"") -> 101.76625
A10: 38107 | B10: 95.23678 | C10: 90.244558 | D10: 103.80445 | E10: 99.13117 | F10: 97.177344 | G10: 100.5615 | H10: 98.034028 | I10: 98.050647 | J10: 97.48835 | K10: 97.54146 | L10: 97.146005 | M10: 97.861236 | N10: 98.9659 | O10: 98.61292 | P10: 100.31625 | Q10: 98.69831 | R10: =C10*'Weights & Assumptions'!$F$6+D10*'Weights & Assumptions'!$F$7 -> 90.410701 | S10: =E10*'Weights & Assumptions'!$F$8+F10*'Weights & Assumptions'!$F$9+H10*'Weights & Assumptions'!$F$11 -> 97.589094 | T10: =G10*'Weights & Assumptions'!$F$10+I10*'Weights & Assumptions'!$F$12+J10*'Weights & Assumptions'!$F$13+K10*'Weights & Assumptions'!$F$14+L10*'Weights & Assumptions'!$F$15+M10*'Weights & Assumptions'!$F$16+N10*'Weights & Assumptions'!$F$17+O10*'Weights & Assumptions'!$F$18+P10*'Weights & Assumptions'!$F$19+Q10*'Weights & Assumptions'!$F$20 -> 98.241864 | U10: =R10*'Weights & Assumptions'!$B$25/'Weights & Assumptions'!$B$28+S10*'Weights & Assumptions'!$B$26/'Weights & Assumptions'!$B$28+T10*'Weights & Assumptions'!$B$27/'Weights & Assumptions'!$B$28 -> 97.41124 | V10: =IFERROR(Tabelle1!E11*'Weights & Assumptions'!$F$6+Tabelle1!F11*'Weights & Assumptions'!$F$7,"") -> 150.11262 | W10: =IFERROR(Tabelle1!G11*'Weights & Assumptions'!$F$8+Tabelle1!H11*'Weights & Assumptions'!$F$9+Tabelle1!J11*'Weights & Assumptions'!$F$11,"") -> 97.6834 | X10: =IFERROR(Tabelle1!I11*'Weights & Assumptions'!$F$10+Tabelle1!K11*'Weights & Assumptions'!$F$12+Tabelle1!L11*'Weights & Assumptions'!$F$13+Tabelle1!M11*'Weights & Assumptions'!$F$14+Tabelle1!N11*'Weights & Assumptions'!$F$15+Tabelle1!O11*'Weights & Assumptions'!$F$16+Tabelle1!P11*'Weights & Assumptions'!$F$17+Tabelle1!Q11*'Weights & Assumptions'!$F$18+Tabelle1!R11*'Weights & Assumptions'!$F$19+Tabelle1!S11*'Weights & Assumptions'!$F$20,"") -> 98.327565 | Y10: =IFERROR(V10*'Weights & Assumptions'!$B$25/'Weights & Assumptions'!$B$28+W10*'Weights & Assumptions'!$B$26/'Weights & Assumptions'!$B$28+X10*'Weights & Assumptions'!$B$27/'Weights & Assumptions'!$B$28,"") -> 102.50108
A11: 38138 | B11: 96.95127 | C11: 85.140239 | D11: 78.751344 | E11: 100.26006 | F11: 98.233277 | G11: 100.17702 | H11: 98.627322 | I11: 97.842738 | J11: 98.952839 | K11: 97.639471 | L11: 97.336068 | M11: 98.405466 | N11: 99.22246 | O11: 99.022886 | P11: 99.587195 | Q11: 99.046811 | R11: =C11*'Weights & Assumptions'!$F$6+D11*'Weights & Assumptions'!$F$7 -> 85.061959 | S11: =E11*'Weights & Assumptions'!$F$8+F11*'Weights & Assumptions'!$F$9+H11*'Weights & Assumptions'!$F$11 -> 98.557359 | T11: =G11*'Weights & Assumptions'!$F$10+I11*'Weights & Assumptions'!$F$12+J11*'Weights & Assumptions'!$F$13+K11*'Weights & Assumptions'!$F$14+L11*'Weights & Assumptions'!$F$15+M11*'Weights & Assumptions'!$F$16+N11*'Weights & Assumptions'!$F$17+O11*'Weights & Assumptions'!$F$18+P11*'Weights & Assumptions'!$F$19+Q11*'Weights & Assumptions'!$F$20 -> 98.417382 | U11: =R11*'Weights & Assumptions'!$B$25/'Weights & Assumptions'!$B$28+S11*'Weights & Assumptions'!$B$26/'Weights & Assumptions'!$B$28+T11*'Weights & Assumptions'!$B$27/'Weights & Assumptions'!$B$28 -> 97.334073 | V11: =IFERROR(Tabelle1!E12*'Weights & Assumptions'!$F$6+Tabelle1!F12*'Weights & Assumptions'!$F$7,"") -> 208.44426 | W11: =IFERROR(Tabelle1!G12*'Weights & Assumptions'!$F$8+Tabelle1!H12*'Weights & Assumptions'!$F$9+Tabelle1!J12*'Weights & Assumptions'!$F$11,"") -> 100.30922 | X11: =IFERROR(Tabelle1!I12*'Weights & Assumptions'!$F$10+Tabelle1!K12*'Weights & Assumptions'!$F$12+Tabelle1!L12*'Weights & Assumptions'!$F$13+Tabelle1!M12*'Weights & Assumptions'!$F$14+Tabelle1!N12*'Weights & Assumptions'!$F$15+Tabelle1!O12*'Weights & Assumptions'!$F$16+Tabelle1!P12*'Weights & Assumptions'!$F$17+Tabelle1!Q12*'Weights & Assumptions'!$F$18+Tabelle1!R12*'Weights & Assumptions'!$F$19+Tabelle1!S12*'Weights & Assumptions'!$F$20,"") -> 100.25383 | Y11: =IFERROR(V11*'Weights & Assumptions'!$B$25/'Weights & Assumptions'!$B$28+W11*'Weights & Assumptions'!$B$26/'Weights & Assumptions'!$B$28+X11*'Weights & Assumptions'!$B$27/'Weights & Assumptions'!$B$28,"") -> 109.34583
A12: 38168 | B12: 98.68356 | C12: 84.794334 | D12: 103.31534 | E12: 100.25824 | F12: 99.765487 | G12: 100.19932 | H12: 99.759349 | I12: 100.95579 | J12: 99.756364 | K12: 99.014956 | L12: 97.851686 | M12: 99.36804 | N12: 99.61084 | O12: 99.690348 | P12: 97.136464 | Q12: 99.722692 | R12: =C12*'Weights & Assumptions'!$F$6+D12*'Weights & Assumptions'!$F$7 -> 85.021263 | S12: =E12*'Weights & Assumptions'!$F$8+F12*'Weights & Assumptions'!$F$9+H12*'Weights & Assumptions'!$F$11 -> 99.823043 | T12: =G12*'Weights & Assumptions'!$F$10+I12*'Weights & Assumptions'!$F$12+J12*'Weights & Assumptions'!$F$13+K12*'Weights & Assumptions'!$F$14+L12*'Weights & Assumptions'!$F$15+M12*'Weights & Assumptions'!$F$16+N12*'Weights & Assumptions'!$F$17+O12*'Weights & Assumptions'!$F$18+P12*'Weights & Assumptions'!$F$19+Q12*'Weights & Assumptions'!$F$20 -> 99.469379 | U12: =R12*'Weights & Assumptions'!$B$25/'Weights & Assumptions'!$B$28+S12*'Weights & Assumptions'!$B$26/'Weights & Assumptions'!$B$28+T12*'Weights & Assumptions'!$B$27/'Weights & Assumptions'!$B$28 -> 98.351216 | V12: =IFERROR(Tabelle1!E13*'Weights & Assumptions'!$F$6+Tabelle1!F13*'Weights & Assumptions'!$F$7,"") -> 144.83651 | W12: =IFERROR(Tabelle1!G13*'Weights & Assumptions'!$F$8+Tabelle1!H13*'Weights & Assumptions'!$F$9+Tabelle1!J13*'Weights & Assumptions'!$F$11,"") -> 100.35363 | X12: =IFERROR(Tabelle1!I13*'Weights & Assumptions'!$F$10+Tabelle1!K13*'Weights & Assumptions'!$F$12+Tabelle1!L13*'Weights & Assumptions'!$F$13+Tabelle1!M13*'Weights & Assumptions'!$F$14+Tabelle1!N13*'Weights & Assumptions'!$F$15+Tabelle1!O13*'Weights & Assumptions'!$F$16+Tabelle1!P13*'Weights & Assumptions'!$F$17+Tabelle1!Q13*'Weights & Assumptions'!$F$18+Tabelle1!R13*'Weights & Assumptions'!$F$19+Tabelle1!S13*'Weights & Assumptions'!$F$20,"") -> 101.38812 | Y12: =IFERROR(V12*'Weights & Assumptions'!$B$25/'Weights & Assumptions'!$B$28+W12*'Weights & Assumptions'!$B$26/'Weights & Assumptions'!$B$28+X12*'Weights & Assumptions'!$B$27/'Weights & Assumptions'!$B$28,"") -> 104.75839
A13: 38199 | B13: 100.8411 | C13: 95.745901 | D13: 85.723979 | E13: 98.468451 | F13: 100.61251 | G13: 100.06066 | H13: 101.21964 | I13: 101.01451 | J13: 99.663173 | K13: 100.12606 | L13: 99.427988 | M13: 100.76038 | N13: 100.3526 | O13: 100.24666 | P13: 100.74605 | Q13: 99.709656 | R13: =C13*'Weights & Assumptions'!$F$6+D13*'Weights & Assumptions'!$F$7 -> 95.623107 | S13: =E13*'Weights & Assumptions'!$F$8+F13*'Weights & Assumptions'!$F$9+H13*'Weights & Assumptions'!$F$11 -> 100.483 | T13: =G13*'Weights & Assumptions'!$F$10+I13*'Weights & Assumptions'!$F$12+J13*'Weights & Assumptions'!$F$13+K13*'Weights & Assumptions'!$F$14+L13*'Weights & Assumptions'!$F$15+M13*'Weights & Assumptions'!$F$16+N13*'Weights & Assumptions'!$F$17+O13*'Weights & Assumptions'!$F$18+P13*'Weights & Assumptions'!$F$19+Q13*'Weights & Assumptions'!$F$20 -> 100.4122 | U13: =R13*'Weights & Assumptions'!$B$25/'Weights & Assumptions'!$B$28+S13*'Weights & Assumptions'!$B$26/'Weights & Assumptions'!$B$28+T13*'Weights & Assumptions'!$B$27/'Weights & Assumptions'!$B$28 -> 100.02921 | V13: =IFERROR(Tabelle1!E14*'Weights & Assumptions'!$F$6+Tabelle1!F14*'Weights & Assumptions'!$F$7,"") -> 94.648542 | W13: =IFERROR(Tabelle1!G14*'Weights & Assumptions'!$F$8+Tabelle1!H14*'Weights & Assumptions'!$F$9+Tabelle1!J14*'Weights & Assumptions'!$F$11,"") -> 101.55425 | X13: =IFERROR(Tabelle1!I14*'Weights & Assumptions'!$F$10+Tabelle1!K14*'Weights & Assumptions'!$F$12+Tabelle1!L14*'Weights & Assumptions'!$F$13+Tabelle1!M14*'Weights & Assumptions'!$F$14+Tabelle1!N14*'Weights & Assumptions'!$F$15+Tabelle1!O14*'Weights & Assumptions'!$F$16+Tabelle1!P14*'Weights & Assumptions'!$F$17+Tabelle1!Q14*'Weights & Assumptions'!$F$18+Tabelle1!R14*'Weights & Assumptions'!$F$19+Tabelle1!S14*'Weights & Assumptions'!$F$20,"") -> 101.01855 | Y13: =IFERROR(V13*'Weights & Assumptions'!$B$25/'Weights & Assumptions'!$B$28+W13*'Weights & Assumptions'!$B$26/'Weights & Assumptions'!$B$28+X13*'Weights & Assumptions'!$B$27/'Weights & Assumptions'!$B$28,"") -> 100.62656
A14: 38230 | B14: 102.17769 | C14: 96.568804 | D14: 93.827971 | E14: 99.761613 | F14: 100.11916 | G14: 99.962659 | H14: 101.92253 | I14: 100.19253 | J14: 99.638707 | K14: 100.97793 | L14: 101.39772 | M14: 100.59223 | N14: 100.74237 | O14: 100.91954 | P14: 101.61606 | Q14: 100.78969 | R14: =C14*'Weights & Assumptions'!$F$6+D14*'Weights & Assumptions'!$F$7 -> 96.535222 | S14: =E14*'Weights & Assumptions'!$F$8+F14*'Weights & Assumptions'!$F$9+H14*'Weights & Assumptions'!$F$11 -> 100.45216 | T14: =G14*'Weights & Assumptions'!$F$10+I14*'Weights & Assumptions'!$F$12+J14*'Weights & Assumptions'!$F$13+K14*'Weights & Assumptions'!$F$14+L14*'Weights & Assumptions'!$F$15+M14*'Weights & Assumptions'!$F$16+N14*'Weights & Assumptions'!$F$17+O14*'Weights & Assumptions'!$F$18+P14*'Weights & Assumptions'!$F$19+Q14*'Weights & Assumptions'!$F$20 -> 100.6897 | U14: =R14*'Weights & Assumptions'!$B$25/'Weights & Assumptions'!$B$28+S14*'Weights & Assumptions'!$B$26/'Weights & Assumptions'!$B$28+T14*'Weights & Assumptions'!$B$27/'Weights & Assumptions'!$B$28 -> 100.27797 | V14: =IFERROR(Tabelle1!E15*'Weights & Assumptions'!$F$6+Tabelle1!F15*'Weights & Assumptions'!$F$7,"") -> 65.283109 | W14: =IFERROR(Tabelle1!G15*'Weights & Assumptions'!$F$8+Tabelle1!H15*'Weights & Assumptions'!$F$9+Tabelle1!J15*'Weights & Assumptions'!$F$11,"") -> 101.37457 | X14: =IFERROR(Tabelle1!I15*'Weights & Assumptions'!$F$10+Tabelle1!K15*'Weights & Assumptions'!$F$12+Tabelle1!L15*'Weights & Assumptions'!$F$13+Tabelle1!M15*'Weights & Assumptions'!$F$14+Tabelle1!N15*'Weights & Assumptions'!$F$15+Tabelle1!O15*'Weights & Assumptions'!$F$16+Tabelle1!P15*'Weights & Assumptions'!$F$17+Tabelle1!Q15*'Weights & Assumptions'!$F$18+Tabelle1!R15*'Weights & Assumptions'!$F$19+Tabelle1!S15*'Weights & Assumptions'!$F$20,"") -> 100.75327 | Y14: =IFERROR(V14*'Weights & Assumptions'!$B$25/'Weights & Assumptions'!$B$28+W14*'Weights & Assumptions'!$B$26/'Weights & Assumptions'!$B$28+X14*'Weights & Assumptions'!$B$27/'Weights & Assumptions'!$B$28,"") -> 97.942511
A15: 38260 | B15: 102.35036 | C15: 96.451106 | D15: 95.213754 | E15: 100.62568 | F15: 101.82907 | G15: 100.38428 | H15: 103.33532 | I15: 101.4396 | J15: 100.5412 | K15: 102.11846 | L15: 102.0709 | M15: 101.19767 | N15: 101.14971 | O15: 101.14245 | P15: 103.76512 | Q15: 102.20401 | R15: =C15*'Weights & Assumptions'!$F$6+D15*'Weights & Assumptions'!$F$7 -> 96.435945 | S15: =E15*'Weights & Assumptions'!$F$8+F15*'Weights & Assumptions'!$F$9+H15*'Weights & Assumptions'!$F$11 -> 101.99917 | T15: =G15*'Weights & Assumptions'!$F$10+I15*'Weights & Assumptions'!$F$12+J15*'Weights & Assumptions'!$F$13+K15*'Weights & Assumptions'!$F$14+L15*'Weights & Assumptions'!$F$15+M15*'Weights & Assumptions'!$F$16+N15*'Weights & Assumptions'!$F$17+O15*'Weights & Assumptions'!$F$18+P15*'Weights & Assumptions'!$F$19+Q15*'Weights & Assumptions'!$F$20 -> 101.62732 | U15: =R15*'Weights & Assumptions'!$B$25/'Weights & Assumptions'!$B$28+S15*'Weights & Assumptions'!$B$26/'Weights & Assumptions'!$B$28+T15*'Weights & Assumptions'!$B$27/'Weights & Assumptions'!$B$28 -> 101.29064 | V15: =IFERROR(Tabelle1!E16*'Weights & Assumptions'!$F$6+Tabelle1!F16*'Weights & Assumptions'!$F$7,"") -> 60.84067 | W15: =IFERROR(Tabelle1!G16*'Weights & Assumptions'!$F$8+Tabelle1!H16*'Weights & Assumptions'!$F$9+Tabelle1!J16*'Weights & Assumptions'!$F$11,"") -> 103.21235 | X15: =IFERROR(Tabelle1!I16*'Weights & Assumptions'!$F$10+Tabelle1!K16*'Weights & Assumptions'!$F$12+Tabelle1!L16*'Weights & Assumptions'!$F$13+Tabelle1!M16*'Weights & Assumptions'!$F$14+Tabelle1!N16*'Weights & Assumptions'!$F$15+Tabelle1!O16*'Weights & Assumptions'!$F$16+Tabelle1!P16*'Weights & Assumptions'!$F$17+Tabelle1!Q16*'Weights & Assumptions'!$F$18+Tabelle1!R16*'Weights & Assumptions'!$F$19+Tabelle1!S16*'Weights & Assumptions'!$F$20,"") -> 101.05622 | Y15: =IFERROR(V15*'Weights & Assumptions'!$B$25/'Weights & Assumptions'!$B$28+W15*'Weights & Assumptions'!$B$26/'Weights & Assumptions'!$B$28+X15*'Weights & Assumptions'!$B$27/'Weights & Assumptions'!$B$28,"") -> 98.255454
A16: 38291 | B16: 103.12368 | C16: 98.346911 | D16: 101.37345 | E16: 100.18109 | F16: 101.84207 | G16: 101.93668 | H16: 101.80758 | I16: 102.80095 | J16: 102.66899 | K16: 103.67006 | L16: 102.9485 | M16: 101.11211 | N16: 101.47379 | O16: 101.66834 | P16: 102.87006 | Q16: 102.9248 | R16: =C16*'Weights & Assumptions'!$F$6+D16*'Weights & Assumptions'!$F$7 -> 98.383994 | S16: =E16*'Weights & Assumptions'!$F$8+F16*'Weights & Assumptions'!$F$9+H16*'Weights & Assumptions'!$F$11 -> 101.63656 | T16: =G16*'Weights & Assumptions'!$F$10+I16*'Weights & Assumptions'!$F$12+J16*'Weights & Assumptions'!$F$13+K16*'Weights & Assumptions'!$F$14+L16*'Weights & Assumptions'!$F$15+M16*'Weights & Assumptions'!$F$16+N16*'Weights & Assumptions'!$F$17+O16*'Weights & Assumptions'!$F$18+P16*'Weights & Assumptions'!$F$19+Q16*'Weights & Assumptions'!$F$20 -> 102.36677 | U16: =R16*'Weights & Assumptions'!$B$25/'Weights & Assumptions'!$B$28+S16*'Weights & Assumptions'!$B$26/'Weights & Assumptions'!$B$28+T16*'Weights & Assumptions'!$B$27/'Weights & Assumptions'!$B$28 -> 101.83844 | V16: =IFERROR(Tabelle1!E17*'Weights & Assumptions'!$F$6+Tabelle1!F17*'Weights & Assumptions'!$F$7,"") -> 62.936085 | W16: =IFERROR(Tabelle1!G17*'Weights & Assumptions'!$F$8+Tabelle1!H17*'Weights & Assumptions'!$F$9+Tabelle1!J17*'Weights & Assumptions'!$F$11,"") -> 103.68702 | X16: =IFERROR(Tabelle1!I17*'Weights & Assumptions'!$F$10+Tabelle1!K17*'Weights & Assumptions'!$F$12+Tabelle1!L17*'Weights & Assumptions'!$F$13+Tabelle1!M17*'Weights & Assumptions'!$F$14+Tabelle1!N17*'Weights & Assumptions'!$F$15+Tabelle1!O17*'Weights & Assumptions'!$F$16+Tabelle1!P17*'Weights & Assumptions'!$F$17+Tabelle1!Q17*'Weights & Assumptions'!$F$18+Tabelle1!R17*'Weights & Assumptions'!$F$19+Tabelle1!S17*'Weights & Assumptions'!$F$20,"") -> 101.19644 | Y16: =IFERROR(V16*'Weights & Assumptions'!$B$25/'Weights & Assumptions'!$B$28+W16*'Weights & Assumptions'!$B$26/'Weights & Assumptions'!$B$28+X16*'Weights & Assumptions'!$B$27/'Weights & Assumptions'!$B$28,"") -> 98.648654
A17: 38321 | B17: 103.57877 | C17: 98.015937 | D17: 97.521605 | E17: 100.31158 | F17: 102.26075 | G17: 100.06837 | H17: 103.10352 | I17: 102.438 | J17: 104.33856 | K17: 105.71184 | L17: 103.1753 | M17: 101.85321 | N17: 101.63802 | O17: 101.78141 | P17: 103.04606 | Q17: 103.24338 | R17: =C17*'Weights & Assumptions'!$F$6+D17*'Weights & Assumptions'!$F$7 -> 98.00988 | S17: =E17*'Weights & Assumptions'!$F$8+F17*'Weights & Assumptions'!$F$9+H17*'Weights & Assumptions'!$F$11 -> 102.20359 | T17: =G17*'Weights & Assumptions'!$F$10+I17*'Weights & Assumptions'!$F$12+J17*'Weights & Assumptions'!$F$13+K17*'Weights & Assumptions'!$F$14+L17*'Weights & Assumptions'!$F$15+M17*'Weights & Assumptions'!$F$16+N17*'Weights & Assumptions'!$F$17+O17*'Weights & Assumptions'!$F$18+P17*'Weights & Assumptions'!$F$19+Q17*'Weights & Assumptions'!$F$20 -> 102.83803 | U17: =R17*'Weights & Assumptions'!$B$25/'Weights & Assumptions'!$B$28+S17*'Weights & Assumptions'!$B$26/'Weights & Assumptions'!$B$28+T17*'Weights & Assumptions'!$B$27/'Weights & Assumptions'!$B$28 -> 102.26424 | V17: =IFERROR(Tabelle1!E18*'Weights & Assumptions'!$F$6+Tabelle1!F18*'Weights & Assumptions'!$F$7,"") -> 78.317479 | W17: =IFERROR(Tabelle1!G18*'Weights & Assumptions'!$F$8+Tabelle1!H18*'Weights & Assumptions'!$F$9+Tabelle1!J18*'Weights & Assumptions'!$F$11,"") -> 102.85438 | X17: =IFERROR(Tabelle1!I18*'Weights & Assumptions'!$F$10+Tabelle1!K18*'Weights & Assumptions'!$F$12+Tabelle1!L18*'Weights & Assumptions'!$F$13+Tabelle1!M18*'Weights & Assumptions'!$F$14+Tabelle1!N18*'Weights & Assumptions'!$F$15+Tabelle1!O18*'Weights & Assumptions'!$F$16+Tabelle1!P18*'Weights & Assumptions'!$F$17+Tabelle1!Q18*'Weights & Assumptions'!$F$18+Tabelle1!R18*'Weights & Assumptions'!$F$19+Tabelle1!S18*'Weights & Assumptions'!$F$20,"") -> 102.5678 | Y17: =IFERROR(V17*'Weights & Assumptions'!$B$25/'Weights & Assumptions'!$B$28+W17*'Weights & Assumptions'!$B$26/'Weights & Assumptions'!$B$28+X17*'Weights & Assumptions'!$B$27/'Weights & Assumptions'!$B$28,"") -> 100.60938
A18: 38352 | B18: 102.97856 | C18: 96.917687 | D18: 85.253374 | E18: 100.72696 | F18: 103.23365 | G18: 103.11383 | H18: 104.56885 | I18: 104.77428 | J18: 105.52918 | K18: 106.42123 | L18: 103.37564 | M18: 101.85083 | N18: 101.8581 | O18: 102.60687 | P18: 103.46387 | Q18: 104.17037 | R18: =C18*'Weights & Assumptions'!$F$6+D18*'Weights & Assumptions'!$F$7 -> 96.77477 | S18: =E18*'Weights & Assumptions'!$F$8+F18*'Weights & Assumptions'!$F$9+H18*'Weights & Assumptions'!$F$11 -> 103.21251 | T18: =G18*'Weights & Assumptions'!$F$10+I18*'Weights & Assumptions'!$F$12+J18*'Weights & Assumptions'!$F$13+K18*'Weights & Assumptions'!$F$14+L18*'Weights & Assumptions'!$F$15+M18*'Weights & Assumptions'!$F$16+N18*'Weights & Assumptions'!$F$17+O18*'Weights & Assumptions'!$F$18+P18*'Weights & Assumptions'!$F$19+Q18*'Weights & Assumptions'!$F$20 -> 103.7364 | U18: =R18*'Weights & Assumptions'!$B$25/'Weights & Assumptions'!$B$28+S18*'Weights & Assumptions'!$B$26/'Weights & Assumptions'!$B$28+T18*'Weights & Assumptions'!$B$27/'Weights & Assumptions'!$B$28 -> 103.013 | V18: =IFERROR(Tabelle1!E19*'Weights & Assumptions'!$F$6+Tabelle1!F19*'Weights & Assumptions'!$F$7,"") -> 92.532922 | W18: =IFERROR(Tabelle1!G19*'Weights & Assumptions'!$F$8+Tabelle1!H19*'Weights & Assumptions'!$F$9+Tabelle1!J19*'Weights & Assumptions'!$F$11,"") -> 101.73414 | X18: =IFERROR(Tabelle1!I19*'Weights & Assumptions'!$F$10+Tabelle1!K19*'Weights & Assumptions'!$F$12+Tabelle1!L19*'Weights & Assumptions'!$F$13+Tabelle1!M19*'Weights & Assumptions'!$F$14+Tabelle1!N19*'Weights & Assumptions'!$F$15+Tabelle1!O19*'Weights & Assumptions'!$F$16+Tabelle1!P19*'Weights & Assumptions'!$F$17+Tabelle1!Q19*'Weights & Assumptions'!$F$18+Tabelle1!R19*'Weights & Assumptions'!$F$19+Tabelle1!S19*'Weights & Assumptions'!$F$20,"") -> 103.34617 | Y18: =IFERROR(V18*'Weights & Assumptions'!$B$25/'Weights & Assumptions'!$B$28+W18*'Weights & Assumptions'!$B$26/'Weights & Assumptions'!$B$28+X18*'Weights & Assumptions'!$B$27/'Weights & Assumptions'!$B$28,"") -> 102.01026
... A275: 46173 | B275: 153.62027 | C275: 144.42671 | D275: 124.72598 | E275: 136.60389 | F275: 111.15195 | G275: 153.22317 | H275: 130.81158 | I275: 149.12501 | J275: 176.68432 | K275: 187.90798 | L275: 193.83434 | M275: 158.84077 | N275: 159.42283 | O275: 171.44841 | P275: 185.39148 | Q275: 128.24676 | R275: =C275*'Weights & Assumptions'!$F$6+D275*'Weights & Assumptions'!$F$7 -> 144.18533 | S275: =E275*'Weights & Assumptions'!$F$8+F275*'Weights & Assumptions'!$F$9+H275*'Weights & Assumptions'!$F$11 -> 118.28642 | T275: =G275*'Weights & Assumptions'!$F$10+I275*'Weights & Assumptions'!$F$12+J275*'Weights & Assumptions'!$F$13+K275*'Weights & Assumptions'!$F$14+L275*'Weights & Assumptions'!$F$15+M275*'Weights & Assumptions'!$F$16+N275*'Weights & Assumptions'!$F$17+O275*'Weights & Assumptions'!$F$18+P275*'Weights & Assumptions'!$F$19+Q275*'Weights & Assumptions'!$F$20 -> 165.68362 | U275: =R275*'Weights & Assumptions'!$B$25/'Weights & Assumptions'!$B$28+S275*'Weights & Assumptions'!$B$26/'Weights & Assumptions'!$B$28+T275*'Weights & Assumptions'!$B$27/'Weights & Assumptions'!$B$28 -> 151.27615 | V275: =IFERROR(Tabelle1!E276*'Weights & Assumptions'!$F$6+Tabelle1!F276*'Weights & Assumptions'!$F$7,"") -> 295.27627 | W275: =IFERROR(Tabelle1!G276*'Weights & Assumptions'!$F$8+Tabelle1!H276*'Weights & Assumptions'!$F$9+Tabelle1!J276*'Weights & Assumptions'!$F$11,"") -> 120.05251 | X275: =IFERROR(Tabelle1!I276*'Weights & Assumptions'!$F$10+Tabelle1!K276*'Weights & Assumptions'!$F$12+Tabelle1!L276*'Weights & Assumptions'!$F$13+Tabelle1!M276*'Weights & Assumptions'!$F$14+Tabelle1!N276*'Weights & Assumptions'!$F$15+Tabelle1!O276*'Weights & Assumptions'!$F$16+Tabelle1!P276*'Weights & Assumptions'!$F$17+Tabelle1!Q276*'Weights & Assumptions'!$F$18+Tabelle1!R276*'Weights & Assumptions'!$F$19+Tabelle1!S276*'Weights & Assumptions'!$F$20,"") -> 166.61263 | Y275: =IFERROR(V275*'Weights & Assumptions'!$B$25/'Weights & Assumptions'!$B$28+W275*'Weights & Assumptions'!$B$26/'Weights & Assumptions'!$B$28+X275*'Weights & Assumptions'!$B$27/'Weights & Assumptions'!$B$28,"") -> 165.02646
A276: 46203
A277: 46234
A278: 46265
A279: 46295
A280: 46326
A281: 46356
A282: 46387
A283: 46418
A284: 46446
A285: 46477
A286: 46507
A287: 46538
... A294: 46752

Sheet EMAE Analysis
A1: EMAE Analysis
A2: Headline activity. 'Published' is INDEC's own SA series; 'reconstructed' is our weighted aggregate of the three sub-indices — the gap between them is the aggregation error and is the honest measure of model quality.
A6: Date | B6: EMAE published: SA level | C6: EMAE published: m/m % | D6: EMAE published: 3m/3m % | E6: EMAE published: 3m/3m ann. % | F6: EMAE published: y/y % | G6: EMAE published: YTD avg % | H6: EMAE reconstructed: SA level | I6: EMAE reconstructed: m/m % | J6: EMAE reconstructed: 3m/3m % | K6: EMAE reconstructed: 3m/3m ann. % | L6: EMAE reconstructed: y/y % | M6: EMAE reconstructed: YTD avg %
A7: 38017 | B7: ='SA Data'!B7 -> 98.33957 | H7: ='SA Data'!U7 -> 98.959257
A8: 38046 | B8: ='SA Data'!B8 -> 98.07072 | C8: =(B8/B7-1)*100 -> -0.27338944 | H8: ='SA Data'!U8 -> 99.055058 | I8: =(H8/H7-1)*100 -> 0.096808672
A9: 38077 | B9: ='SA Data'!B9 -> 97.66795 | C9: =(B9/B8-1)*100 -> -0.41069343 | H9: ='SA Data'!U9 -> 98.31 | I9: =(H9/H8-1)*100 -> -0.75216548
A10: 38107 | B10: ='SA Data'!B10 -> 95.23678 | C10: =(B10/B9-1)*100 -> -2.4892199 | H10: ='SA Data'!U10 -> 97.41124 | I10: =(H10/H9-1)*100 -> -0.91421073
A11: 38138 | B11: ='SA Data'!B11 -> 96.95127 | C11: =(B11/B10-1)*100 -> 1.8002394 | H11: ='SA Data'!U11 -> 97.334073 | I11: =(H11/H10-1)*100 -> -0.079217119
A12: 38168 | B12: ='SA Data'!B12 -> 98.68356 | C12: =(B12/B11-1)*100 -> 1.7867636 | D12: =(AVERAGE(B10:B12)/AVERAGE(B7:B9)-1)*100 -> -1.0904003 | E12: =((AVERAGE(B10:B12)/AVERAGE(B7:B9))^4-1)*100 -> -4.29078 | H12: ='SA Data'!U12 -> 98.351216 | I12: =(H12/H11-1)*100 -> 1.0450012 | J12: =(AVERAGE(H10:H12)/AVERAGE(H7:H9)-1)*100 -> -1.0892751 | K12: =((AVERAGE(H10:H12)/AVERAGE(H7:H9))^4-1)*100 -> -4.2864247
A13: 38199 | B13: ='SA Data'!B13 -> 100.8411 | C13: =(B13/B12-1)*100 -> 2.1863216 | D13: =(AVERAGE(B11:B13)/AVERAGE(B8:B10)-1)*100 -> 1.8903588 | E13: =((AVERAGE(B11:B13)/AVERAGE(B8:B10))^4-1)*100 -> 7.7785574 | H13: ='SA Data'!U13 -> 100.02921 | I13: =(H13/H12-1)*100 -> 1.7061297 | J13: =(AVERAGE(H11:H13)/AVERAGE(H8:H10)-1)*100 -> 0.31827715 | K13: =((AVERAGE(H11:H13)/AVERAGE(H8:H10))^4-1)*100 -> 1.2791995
A14: 38230 | B14: ='SA Data'!B14 -> 102.17769 | C14: =(B14/B13-1)*100 -> 1.3254417 | D14: =(AVERAGE(B12:B14)/AVERAGE(B9:B11)-1)*100 -> 4.0869777 | E14: =((AVERAGE(B12:B14)/AVERAGE(B9:B11))^4-1)*100 -> 17.377699 | H14: ='SA Data'!U14 -> 100.27797 | I14: =(H14/H13-1)*100 -> 0.24868178 | J14: =(AVERAGE(H12:H14)/AVERAGE(H9:H11)-1)*100 -> 1.9119553 | K14: =((AVERAGE(H12:H14)/AVERAGE(H9:H11))^4-1)*100 -> 7.8699645
A15: 38260 | B15: ='SA Data'!B15 -> 102.35036 | C15: =(B15/B14-1)*100 -> 0.16898992 | D15: =(AVERAGE(B13:B15)/AVERAGE(B10:B12)-1)*100 -> 4.9841715 | E15: =((AVERAGE(B13:B15)/AVERAGE(B10:B12))^4-1)*100 -> 21.477348 | H15: ='SA Data'!U15 -> 101.29064 | I15: =(H15/H14-1)*100 -> 1.0098653 | J15: =(AVERAGE(H13:H15)/AVERAGE(H10:H12)-1)*100 -> 2.9005111 | K15: =((AVERAGE(H13:H15)/AVERAGE(H10:H12))^4-1)*100 -> 12.116654
A16: 38291 | B16: ='SA Data'!B16 -> 103.12368 | C16: =(B16/B15-1)*100 -> 0.75556158 | D16: =(AVERAGE(B14:B16)/AVERAGE(B11:B13)-1)*100 -> 3.7695472 | E16: =((AVERAGE(B14:B16)/AVERAGE(B11:B13))^4-1)*100 -> 15.952385 | H16: ='SA Data'!U16 -> 101.83844 | I16: =(H16/H15-1)*100 -> 0.5408151 | J16: =(AVERAGE(H14:H16)/AVERAGE(H11:H13)-1)*100 -> 2.6013415 | K16: =((AVERAGE(H14:H16)/AVERAGE(H11:H13))^4-1)*100 -> 10.818472
A17: 38321 | B17: ='SA Data'!B17 -> 103.57877 | C17: =(B17/B16-1)*100 -> 0.44130504 | D17: =(AVERAGE(B15:B17)/AVERAGE(B12:B14)-1)*100 -> 2.4363284 | E17: =((AVERAGE(B15:B17)/AVERAGE(B12:B14))^4-1)*100 -> 10.107275 | H17: ='SA Data'!U17 -> 102.26424 | I17: =(H17/H16-1)*100 -> 0.4181133 | J17: =(AVERAGE(H15:H17)/AVERAGE(H12:H14)-1)*100 -> 2.2550565 | K17: =((AVERAGE(H15:H17)/AVERAGE(H12:H14))^4-1)*100 -> 9.3299556
A18: 38352 | B18: ='SA Data'!B18 -> 102.97856 | C18: =(B18/B17-1)*100 -> -0.57947203 | D18: =(AVERAGE(B16:B18)/AVERAGE(B13:B15)-1)*100 -> 1.4120156 | E18: =((AVERAGE(B16:B18)/AVERAGE(B13:B15))^4-1)*100 -> 5.7688197 | H18: ='SA Data'!U18 -> 103.013 | I18: =(H18/H17-1)*100 -> 0.73218507 | J18: =(AVERAGE(H16:H18)/AVERAGE(H13:H15)-1)*100 -> 1.8295384 | K18: =((AVERAGE(H16:H18)/AVERAGE(H13:H15))^4-1)*100 -> 7.5214471
A19: 38383 | B19: ='SA Data'!B19 -> 105.74978 | C19: =(B19/B18-1)*100 -> 2.691065 | D19: =(AVERAGE(B17:B19)/AVERAGE(B14:B16)-1)*100 -> 1.5131981 | E19: =((AVERAGE(B17:B19)/AVERAGE(B14:B16))^4-1)*100 -> 6.1915695 | F19: =(B19/B7-1)*100 -> 7.5353289 | G19: =IFERROR((AVERAGE(B19:B19)/AVERAGE(B7:B7)-1)*100,"") -> 7.5353289 | H19: ='SA Data'!U19 -> 103.2978 | I19: =(H19/H18-1)*100 -> 0.27646619 | J19: =(AVERAGE(H17:H19)/AVERAGE(H14:H16)-1)*100 -> 1.7033177 | K19: =((AVERAGE(H17:H19)/AVERAGE(H14:H16))^4-1)*100 -> 6.9893332 | L19: =IFERROR(('SA Data'!Y19/'SA Data'!Y7-1)*100,"") -> 6.6904198 | M19: =IFERROR((AVERAGE('SA Data'!Y19:Y19)/AVERAGE('SA Data'!Y7:Y7)-1)*100,"") -> 6.6904198
A20: 38411 | B20: ='SA Data'!B20 -> 106.05741 | C20: =(B20/B19-1)*100 -> 0.29090368 | D20: =(AVERAGE(B18:B20)/AVERAGE(B15:B17)-1)*100 -> 1.8550034 | E20: =((AVERAGE(B18:B20)/AVERAGE(B15:B17))^4-1)*100 -> 7.6290408 | F20: =(B20/B8-1)*100 -> 8.1438068 | G20: =IFERROR((AVERAGE(B19:B20)/AVERAGE(B7:B8)-1)*100,"") -> 7.8391514 | H20: ='SA Data'!U20 -> 104.44938 | I20: =(H20/H19-1)*100 -> 1.1148164 | J20: =(AVERAGE(H18:H20)/AVERAGE(H15:H17)-1)*100 -> 1.7573595 | K20: =((AVERAGE(H18:H20)/AVERAGE(H15:H17))^4-1)*100 -> 7.2169174 | L20: =IFERROR(('SA Data'!Y20/'SA Data'!Y8-1)*100,"") -> 7.2606189 | M20: =IFERROR((AVERAGE('SA Data'!Y19:Y20)/AVERAGE('SA Data'!Y7:Y8)-1)*100,"") -> 6.9733489
A21: 38442 | B21: ='SA Data'!B21 -> 106.85062 | C21: =(B21/B20-1)*100 -> 0.74790625 | D21: =(AVERAGE(B19:B21)/AVERAGE(B16:B18)-1)*100 -> 2.8987247 | E21: =((AVERAGE(B19:B21)/AVERAGE(B16:B18))^4-1)*100 -> 12.108869 | F21: =(B21/B9-1)*100 -> 9.4019277 | G21: =IFERROR((AVERAGE(B19:B21)/AVERAGE(B7:B9)-1)*100,"") -> 8.3581737 | H21: ='SA Data'!U21 -> 105.83395 | I21: =(H21/H20-1)*100 -> 1.3255911 | J21: =(AVERAGE(H19:H21)/AVERAGE(H16:H18)-1)*100 -> 2.105216 | K21: =((AVERAGE(H19:H21)/AVERAGE(H16:H18))^4-1)*100 -> 8.6905319 | L21: =IFERROR(('SA Data'!Y21/'SA Data'!Y9-1)*100,"") -> 9.234009 | M21: =IFERROR((AVERAGE('SA Data'!Y19:Y21)/AVERAGE('SA Data'!Y7:Y9)-1)*100,"") -> 7.779719
A22: 38472 | B22: ='SA Data'!B22 -> 107.96569 | C22: =(B22/B21-1)*100 -> 1.0435784 | D22: =(AVERAGE(B20:B22)/AVERAGE(B17:B19)-1)*100 -> 2.7430083 | E22: =((AVERAGE(B20:B22)/AVERAGE(B17:B19))^4-1)*100 -> 11.431791 | F22: =(B22/B10-1)*100 -> 13.36554 | G22: =IFERROR((AVERAGE(B19:B22)/AVERAGE(B7:B10)-1)*100,"") -> 9.5831083 | H22: ='SA Data'!U22 -> 107.70261 | I22: =(H22/H21-1)*100 -> 1.7656575 | J22: =(AVERAGE(H20:H22)/AVERAGE(H17:H19)-1)*100 -> 3.0497951 | K22: =((AVERAGE(H20:H22)/AVERAGE(H17:H19))^4-1)*100 -> 12.768688 | L22: =IFERROR(('SA Data'!Y22/'SA Data'!Y10-1)*100,"") -> 13.173464 | M22: =IFERROR((AVERAGE('SA Data'!Y19:Y22)/AVERAGE('SA Data'!Y7:Y10)-1)*100,"") -> 9.2053519
A23: 38503 | B23: ='SA Data'!B23 -> 109.10032 | C23: =(B23/B22-1)*100 -> 1.0509172 | D23: =(AVERAGE(B21:B23)/AVERAGE(B18:B20)-1)*100 -> 2.900665 | E23: =((AVERAGE(B21:B23)/AVERAGE(B18:B20))^4-1)*100 -> 12.117324 | F23: =(B23/B11-1)*100 -> 12.531089 | G23: =IFERROR((AVERAGE(B19:B23)/AVERAGE(B7:B11)-1)*100,"") -> 10.170874 | H23: ='SA Data'!U23 -> 108.26116 | I23: =(H23/H22-1)*100 -> 0.51859643 | J23: =(AVERAGE(H21:H23)/AVERAGE(H18:H20)-1)*100 -> 3.5517886 | K23: =((AVERAGE(H21:H23)/AVERAGE(H18:H20))^4-1)*100 -> 14.982148 | L23: =IFERROR(('SA Data'!Y23/'SA Data'!Y11-1)*100,"") -> 14.987227 | M23: =IFERROR((AVERAGE('SA Data'!Y19:Y23)/AVERAGE('SA Data'!Y7:Y11)-1)*100,"") -> 10.477051
A24: 38533 | B24: ='SA Data'!B24 -> 108.58363 | C24: =(B24/B23-1)*100 -> -0.47359164 | D24: =(AVERAGE(B22:B24)/AVERAGE(B19:B21)-1)*100 -> 2.1941499 | E24: =((AVERAGE(B22:B24)/AVERAGE(B19:B21))^4-1)*100 -> 9.0697057 | F24: =(B24/B12-1)*100 -> 10.032137 | G24: =IFERROR((AVERAGE(B19:B24)/AVERAGE(B7:B12)-1)*100,"") -> 10.147468 | H24: ='SA Data'!U24 -> 108.49831 | I24: =(H24/H23-1)*100 -> 0.21905426 | J24: =(AVERAGE(H22:H24)/AVERAGE(H19:H21)-1)*100 -> 3.4699007 | K24: =((AVERAGE(H22:H24)/AVERAGE(H19:H21))^4-1)*100 -> 14.618872 | L24: =IFERROR(('SA Data'!Y24/'SA Data'!Y12-1)*100,"") -> 11.880952 | M24: =IFERROR((AVERAGE('SA Data'!Y19:Y24)/AVERAGE('SA Data'!Y7:Y12)-1)*100,"") -> 10.721392
A25: 38564 | B25: ='SA Data'!B25 -> 109.13426 | C25: =(B25/B24-1)*100 -> 0.50710222 | D25: =(AVERAGE(B23:B25)/AVERAGE(B20:B22)-1)*100 -> 1.8525948 | E25: =((AVERAGE(B23:B25)/AVERAGE(B20:B22))^4-1)*100 -> 7.6188609 | F25: =(B25/B13-1)*100 -> 8.223988 | G25: =IFERROR((AVERAGE(B19:B25)/AVERAGE(B7:B13)-1)*100,"") -> 9.8646329 | H25: ='SA Data'!U25 -> 108.09296 | I25: =(H25/H24-1)*100 -> -0.37359255 | J25: =(AVERAGE(H23:H25)/AVERAGE(H20:H22)-1)*100 -> 2.1593682 | K25: =((AVERAGE(H23:H25)/AVERAGE(H20:H22))^4-1)*100 -> 8.9212941 | L25: =IFERROR(('SA Data'!Y25/'SA Data'!Y13-1)*100,"") -> 8.0422462 | M25: =IFERROR((AVERAGE('SA Data'!Y19:Y25)/AVERAGE('SA Data'!Y7:Y13)-1)*100,"") -> 10.337648
A26: 38595 | B26: ='SA Data'!B26 -> 109.37691 | C26: =(B26/B25-1)*100 -> 0.22234081 | D26: =(AVERAGE(B24:B26)/AVERAGE(B21:B23)-1)*100 -> 0.98116914 | E26: =((AVERAGE(B24:B26)/AVERAGE(B21:B23))^4-1)*100 -> 3.9828169 | F26: =(B26/B14-1)*100 -> 7.0457847 | G26: =IFERROR((AVERAGE(B19:B26)/AVERAGE(B7:B14)-1)*100,"") -> 9.4991065 | H26: ='SA Data'!U26 -> 108.73991 | I26: =(H26/H25-1)*100 -> 0.59850978 | J26: =(AVERAGE(H24:H26)/AVERAGE(H21:H23)-1)*100 -> 1.0980391 | K26: =((AVERAGE(H24:H26)/AVERAGE(H21:H23))^4-1)*100 -> 4.4650286 | L26: =IFERROR(('SA Data'!Y26/'SA Data'!Y14-1)*100,"") -> 8.8615012 | M26: =IFERROR((AVERAGE('SA Data'!Y19:Y26)/AVERAGE('SA Data'!Y7:Y14)-1)*100,"") -> 10.157034
A27: 38625 | B27: ='SA Data'!B27 -> 109.26148 | C27: =(B27/B26-1)*100 -> -0.10553416 | D27: =(AVERAGE(B25:B27)/AVERAGE(B22:B24)-1)*100 -> 0.65193071 | E27: =((AVERAGE(B25:B27)/AVERAGE(B22:B24))^4-1)*100 -> 2.6333347 | F27: =(B27/B15-1)*100 -> 6.752414 | G27: =IFERROR((AVERAGE(B19:B27)/AVERAGE(B7:B15)-1)*100,"") -> 9.1833489 | H27: ='SA Data'!U27 -> 109.28881 | I27: =(H27/H26-1)*100 -> 0.50477998 | J27: =(AVERAGE(H25:H27)/AVERAGE(H22:H24)-1)*100 -> 0.51149575 | K27: =((AVERAGE(H25:H27)/AVERAGE(H22:H24))^4-1)*100 -> 2.0617343 | L27: =IFERROR(('SA Data'!Y27/'SA Data'!Y15-1)*100,"") -> 8.0144371 | M27: =IFERROR((AVERAGE('SA Data'!Y19:Y27)/AVERAGE('SA Data'!Y7:Y15)-1)*100,"") -> 9.9227903
A28: 38656 | B28: ='SA Data'!B28 -> 109.94966 | C28: =(B28/B27-1)*100 -> 0.62984686 | D28: =(AVERAGE(B26:B28)/AVERAGE(B23:B25)-1)*100 -> 0.54153653 | E28: =((AVERAGE(B26:B28)/AVERAGE(B23:B25))^4-1)*100 -> 2.1838054 | F28: =(B28/B16-1)*100 -> 6.6192168 | G28: =IFERROR((AVERAGE(B19:B28)/AVERAGE(B7:B16)-1)*100,"") -> 8.9171808 | H28: ='SA Data'!U28 -> 109.42562 | I28: =(H28/H27-1)*100 -> 0.12518556 | J28: =(AVERAGE(H26:H28)/AVERAGE(H23:H25)-1)*100 -> 0.80095348 | K28: =((AVERAGE(H26:H28)/AVERAGE(H23:H25))^4-1)*100 -> 3.2425115 | L28: =IFERROR(('SA Data'!Y28/'SA Data'!Y16-1)*100,"") -> 7.921953 | M28: =IFERROR((AVERAGE('SA Data'!Y19:Y28)/AVERAGE('SA Data'!Y7:Y16)-1)*100,"") -> 9.724892
A29: 38686 | B29: ='SA Data'!B29 -> 111.16807 | C29: =(B29/B28-1)*100 -> 1.1081526 | D29: =(AVERAGE(B27:B29)/AVERAGE(B24:B26)-1)*100 -> 1.0041156 | E29: =((AVERAGE(B27:B29)/AVERAGE(B24:B26))^4-1)*100 -> 4.0773634 | F29: =(B29/B17-1)*100 -> 7.3270806 | G29: =IFERROR((AVERAGE(B19:B29)/AVERAGE(B7:B17)-1)*100,"") -> 8.7670464 | H29: ='SA Data'!U29 -> 111.20769 | I29: =(H29/H28-1)*100 -> 1.6285603 | J29: =(AVERAGE(H27:H29)/AVERAGE(H24:H26)-1)*100 -> 1.4111571 | K29: =((AVERAGE(H27:H29)/AVERAGE(H24:H26))^4-1)*100 -> 5.7652384 | L29: =IFERROR(('SA Data'!Y29/'SA Data'!Y17-1)*100,"") -> 9.013403 | M29: =IFERROR((AVERAGE('SA Data'!Y19:Y29)/AVERAGE('SA Data'!Y7:Y17)-1)*100,"") -> 9.6596979
A30: 38717 | B30: ='SA Data'!B30 -> 113.02209 | C30: =(B30/B29-1)*100 -> 1.6677631 | D30: =(AVERAGE(B28:B30)/AVERAGE(B25:B27)-1)*100 -> 1.9425568 | E30: =((AVERAGE(B28:B30)/AVERAGE(B25:B27))^4-1)*100 -> 7.9995853 | F30: =(B30/B18-1)*100 -> 9.7530301 | G30: =IFERROR((AVERAGE(B19:B30)/AVERAGE(B7:B18)-1)*100,"") -> 8.8516591 | H30: ='SA Data'!U30 -> 112.72023 | I30: =(H30/H29-1)*100 -> 1.3601068 | J30: =(AVERAGE(H28:H30)/AVERAGE(H25:H27)-1)*100 -> 2.2175314 | K30: =((AVERAGE(H28:H30)/AVERAGE(H25:H27))^4-1)*100 -> 9.1695585 | L30: =IFERROR(('SA Data'!Y30/'SA Data'!Y18-1)*100,"") -> 9.2519023 | M30: =IFERROR((AVERAGE('SA Data'!Y19:Y30)/AVERAGE('SA Data'!Y7:Y18)-1)*100,"") -> 9.6250318
A31: 38748 | B31: ='SA Data'!B31 -> 113.8318 | C31: =(B31/B30-1)*100 -> 0.71641747 | D31: =(AVERAGE(B29:B31)/AVERAGE(B26:B28)-1)*100 -> 2.8710448 | E31: =((AVERAGE(B29:B31)/AVERAGE(B26:B28))^4-1)*100 -> 11.988287 | F31: =(B31/B19-1)*100 -> 7.642588 | G31: =IFERROR((AVERAGE(B31:B31)/AVERAGE(B19:B19)-1)*100,"") -> 7.642588 | H31: ='SA Data'!U31 -> 112.69003 | I31: =(H31/H30-1)*100 -> -0.02679253 | J31: =(AVERAGE(H29:H31)/AVERAGE(H26:H28)-1)*100 -> 2.7984352 | K31: =((AVERAGE(H29:H31)/AVERAGE(H26:H28))^4-1)*100 -> 11.672443 | L31: =IFERROR(('SA Data'!Y31/'SA Data'!Y19-1)*100,"") -> 8.7003606 | M31: =IFERROR((AVERAGE('SA Data'!Y31:Y31)/AVERAGE('SA Data'!Y19:Y19)-1)*100,"") -> 8.7003606
A32: 38776 | B32: ='SA Data'!B32 -> 114.74988 | C32: =(B32/B31-1)*100 -> 0.80652331 | D32: =(AVERAGE(B30:B32)/AVERAGE(B27:B29)-1)*100 -> 3.3974777 | E32: =((AVERAGE(B30:B32)/AVERAGE(B27:B29))^4-1)*100 -> 14.298302 | F32: =(B32/B20-1)*100 -> 8.1960044 | G32: =IFERROR((AVERAGE(B31:B32)/AVERAGE(B19:B20)-1)*100,"") -> 7.9196981 | H32: ='SA Data'!U32 -> 113.14459 | I32: =(H32/H31-1)*100 -> 0.40337751 | J32: =(AVERAGE(H30:H32)/AVERAGE(H27:H29)-1)*100 -> 2.6165973 | K32: =((AVERAGE(H30:H32)/AVERAGE(H27:H29))^4-1)*100 -> 10.884397 | L32: =IFERROR(('SA Data'!Y32/'SA Data'!Y20-1)*100,"") -> 8.1433357 | M32: =IFERROR((AVERAGE('SA Data'!Y31:Y32)/AVERAGE('SA Data'!Y19:Y20)-1)*100,"") -> 8.4232262
A33: 38807 | B33: ='SA Data'!B33 -> 114.30687 | C33: =(B33/B32-1)*100 -> -0.38606576 | D33: =(AVERAGE(B31:B33)/AVERAGE(B28:B30)-1)*100 -> 2.6182842 | E33: =((AVERAGE(B31:B33)/AVERAGE(B28:B30))^4-1)*100 -> 10.891688 | F33: =(B33/B21-1)*100 -> 6.9782 | G33: =IFERROR((AVERAGE(B31:B33)/AVERAGE(B19:B21)-1)*100,"") -> 7.604 | H33: ='SA Data'!U33 -> 114.20108 | I33: =(H33/H32-1)*100 -> 0.93374683 | J33: =(AVERAGE(H31:H33)/AVERAGE(H28:H30)-1)*100 -> 2.0045276 | K33: =((AVERAGE(H31:H33)/AVERAGE(H28:H30))^4-1)*100 -> 8.2624361 | L33: =IFERROR(('SA Data'!Y33/'SA Data'!Y21-1)*100,"") -> 7.0801418 | M33: =IFERROR((AVERAGE('SA Data'!Y31:Y33)/AVERAGE('SA Data'!Y19:Y21)-1)*100,"") -> 7.9376882
A34: 38837 | B34: ='SA Data'!B34 -> 115.84398 | C34: =(B34/B33-1)*100 -> 1.3447223 | D34: =(AVERAGE(B32:B34)/AVERAGE(B29:B31)-1)*100 -> 2.0350068 | E34: =((AVERAGE(B32:B34)/AVERAGE(B29:B31))^4-1)*100 -> 8.3918907 | F34: =(B34/B22-1)*100 -> 7.2970311 | G34: =IFERROR((AVERAGE(B31:B34)/AVERAGE(B19:B22)-1)*100,"") -> 7.5263154 | H34: ='SA Data'!U34 -> 114.11494 | I34: =(H34/H33-1)*100 -> -0.075430427 | J34: =(AVERAGE(H32:H34)/AVERAGE(H29:H31)-1)*100 -> 1.438624 | K34: =((AVERAGE(H32:H34)/AVERAGE(H29:H31))^4-1)*100 -> 5.8798696 | L34: =IFERROR(('SA Data'!Y34/'SA Data'!Y22-1)*100,"") -> 5.2639413 | M34: =IFERROR((AVERAGE('SA Data'!Y31:Y34)/AVERAGE('SA Data'!Y19:Y22)-1)*100,"") -> 7.2053051
A35: 38868 | B35: ='SA Data'!B35 -> 115.09969 | C35: =(B35/B34-1)*100 -> -0.64249346 | D35: =(AVERAGE(B33:B35)/AVERAGE(B30:B32)-1)*100 -> 1.0675438 | E35: =((AVERAGE(B33:B35)/AVERAGE(B30:B32))^4-1)*100 -> 4.3390423 | F35: =(B35/B23-1)*100 -> 5.4989481 | G35: =IFERROR((AVERAGE(B31:B35)/AVERAGE(B19:B23)-1)*100,"") -> 7.1134414 | H35: ='SA Data'!U35 -> 115.3633 | I35: =(H35/H34-1)*100 -> 1.0939537 | J35: =(AVERAGE(H33:H35)/AVERAGE(H30:H32)-1)*100 -> 1.5136288 | K35: =((AVERAGE(H33:H35)/AVERAGE(H30:H32))^4-1)*100 -> 6.1933721 | L35: =IFERROR(('SA Data'!Y35/'SA Data'!Y23-1)*100,"") -> 5.642845 | M35: =IFERROR((AVERAGE('SA Data'!Y31:Y35)/AVERAGE('SA Data'!Y19:Y23)-1)*100,"") -> 6.8476188
A36: 38898 | B36: ='SA Data'!B36 -> 116.25305 | C36: =(B36/B35-1)*100 -> 1.0020531 | D36: =(AVERAGE(B34:B36)/AVERAGE(B31:B33)-1)*100 -> 1.2564345 | E36: =((AVERAGE(B34:B36)/AVERAGE(B31:B33))^4-1)*100 -> 5.1212515 | F36: =(B36/B24-1)*100 -> 7.0631457 | G36: =IFERROR((AVERAGE(B31:B36)/AVERAGE(B19:B24)-1)*100,"") -> 7.1049652 | H36: ='SA Data'!U36 -> 116.37329 | I36: =(H36/H35-1)*100 -> 0.87548347 | J36: =(AVERAGE(H34:H36)/AVERAGE(H31:H33)-1)*100 -> 1.7103566 | K36: =((AVERAGE(H34:H36)/AVERAGE(H31:H33))^4-1)*100 -> 7.0189553 | L36: =IFERROR(('SA Data'!Y36/'SA Data'!Y24-1)*100,"") -> 6.5126307 | M36: =IFERROR((AVERAGE('SA Data'!Y31:Y36)/AVERAGE('SA Data'!Y19:Y24)-1)*100,"") -> 6.7887055
A37: 38929 | B37: ='SA Data'!B37 -> 118.14538 | C37: =(B37/B36-1)*100 -> 1.627768 | D37: =(AVERAGE(B35:B37)/AVERAGE(B32:B34)-1)*100 -> 1.3329604 | E37: =((AVERAGE(B35:B37)/AVERAGE(B32:B34))^4-1)*100 -> 5.4393989 | F37: =(B37/B25-1)*100 -> 8.2569122 | G37: =IFERROR((AVERAGE(B31:B37)/AVERAGE(B19:B25)-1)*100,"") -> 7.271822 | H37: ='SA Data'!U37 -> 117.48594 | I37: =(H37/H36-1)*100 -> 0.9561033 | J37: =(AVERAGE(H35:H37)/AVERAGE(H32:H34)-1)*100 -> 2.2731509 | K37: =((AVERAGE(H35:H37)/AVERAGE(H32:H34))^4-1)*100 -> 9.4073617 | L37: =IFERROR(('SA Data'!Y37/'SA Data'!Y25-1)*100,"") -> 8.9912799 | M37: =IFERROR((AVERAGE('SA Data'!Y31:Y37)/AVERAGE('SA Data'!Y19:Y25)-1)*100,"") -> 7.0976254
A38: 38960 | B38: ='SA Data'!B38 -> 118.75377 | C38: =(B38/B37-1)*100 -> 0.51495031 | D38: =(AVERAGE(B36:B38)/AVERAGE(B33:B35)-1)*100 -> 2.2886742 | E38: =((AVERAGE(B36:B38)/AVERAGE(B33:B35))^4-1)*100 -> 9.4738012 | F38: =(B38/B26-1)*100 -> 8.5729794 | G38: =IFERROR((AVERAGE(B31:B38)/AVERAGE(B19:B26)-1)*100,"") -> 7.4367658 | H38: ='SA Data'!U38 -> 118.70914 | I38: =(H38/H37-1)*100 -> 1.0411481 | J38: =(AVERAGE(H36:H38)/AVERAGE(H33:H35)-1)*100 -> 2.5864364 | K38: =((AVERAGE(H36:H38)/AVERAGE(H33:H35))^4-1)*100 -> 10.75409 | L38: =IFERROR(('SA Data'!Y38/'SA Data'!Y26-1)*100,"") -> 9.4978368 | M38: =IFERROR((AVERAGE('SA Data'!Y31:Y38)/AVERAGE('SA Data'!Y19:Y26)-1)*100,"") -> 7.3878501
A39: 38990 | B39: ='SA Data'!B39 -> 119.80935 | C39: =(B39/B38-1)*100 -> 0.88888125 | D39: =(AVERAGE(B37:B39)/AVERAGE(B34:B36)-1)*100 -> 2.7395939 | E39: =((AVERAGE(B37:B39)/AVERAGE(B34:B36))^4-1)*100 -> 11.416979 | F39: =(B39/B27-1)*100 -> 9.6537865 | G39: =IFERROR((AVERAGE(B31:B39)/AVERAGE(B19:B27)-1)*100,"") -> 7.6859582 | H39: ='SA Data'!U39 -> 118.8921 | I39: =(H39/H38-1)*100 -> 0.15412875 | J39: =(AVERAGE(H37:H39)/AVERAGE(H34:H36)-1)*100 -> 2.6704102 | K39: =((AVERAGE(H37:H39)/AVERAGE(H34:H36))^4-1)*100 -> 11.117174 | L39: =IFERROR(('SA Data'!Y39/'SA Data'!Y27-1)*100,"") -> 8.9774449 | M39: =IFERROR((AVERAGE('SA Data'!Y31:Y39)/AVERAGE('SA Data'!Y19:Y27)-1)*100,"") -> 7.5586184
A40: 39021 | B40: ='SA Data'!B40 -> 120.53007 | C40: =(B40/B39-1)*100 -> 0.60155572 | D40: =(AVERAGE(B38:B40)/AVERAGE(B35:B37)-1)*100 -> 2.7453853 | E40: =((AVERAGE(B38:B40)/AVERAGE(B35:B37))^4-1)*100 -> 11.442103 | F40: =(B40/B28-1)*100 -> 9.6229584 | G40: =IFERROR((AVERAGE(B31:B40)/AVERAGE(B19:B28)-1)*100,"") -> 7.882785 | H40: ='SA Data'!U40 -> 119.06702 | I40: =(H40/H39-1)*100 -> 0.14712446 | J40: =(AVERAGE(H38:H40)/AVERAGE(H35:H37)-1)*100 -> 2.1320908 | K40: =((AVERAGE(H38:H40)/AVERAGE(H35:H37))^4-1)*100 -> 8.8050093 | L40: =IFERROR(('SA Data'!Y40/'SA Data'!Y28-1)*100,"") -> 9.5187217 | M40: =IFERROR((AVERAGE('SA Data'!Y31:Y40)/AVERAGE('SA Data'!Y19:Y28)-1)*100,"") -> 7.7493022
A41: 39051 | B41: ='SA Data'!B41 -> 120.65319 | C41: =(B41/B40-1)*100 -> 0.10214878 | D41: =(AVERAGE(B39:B41)/AVERAGE(B36:B38)-1)*100 -> 2.2201221 | E41: =((AVERAGE(B39:B41)/AVERAGE(B36:B38))^4-1)*100 -> 9.1806263 | F41: =(B41/B29-1)*100 -> 8.5322341 | G41: =IFERROR((AVERAGE(B31:B41)/AVERAGE(B19:B29)-1)*100,"") -> 7.943293 | H41: ='SA Data'!U41 -> 120.37996 | I41: =(H41/H40-1)*100 -> 1.1026845 | J41: =(AVERAGE(H39:H41)/AVERAGE(H36:H38)-1)*100 -> 1.6367666 | K41: =((AVERAGE(H39:H41)/AVERAGE(H36:H38))^4-1)*100 -> 6.7095677 | L41: =IFERROR(('SA Data'!Y41/'SA Data'!Y29-1)*100,"") -> 8.4766264 | M41: =IFERROR((AVERAGE('SA Data'!Y31:Y41)/AVERAGE('SA Data'!Y19:Y29)-1)*100,"") -> 7.8155546
