Workbook

Sheet README
A1: Macro Tracker — Argentina
A2: Pure-Excel workbook driven by Haver DLX. Edit codes on the Codes tab, hit DLX > Refresh / Calculate, every tab and chart updates.
A4: How to use
A5: 1. | B5: Make sure the Haver DLX add-in is loaded (Excel > File > Options > Add-ins).
A6: 2. | B6: Open the Codes tab and review the Haver codes. Yellow cells are inputs.
A7: 3. | B7: Hit DLX > Refresh (or just press F9) to pull data.
A8: 4. | B8: Open any category tab (GDP, Inflation, …). Each indicator has a quarterly block, an annual block, and a chart.
A9: 5. | B9: The Dashboard tab summarises the latest read and 2-year forecast for every indicator.
A11: Forecasts
A12: Linear (TREND) | B12: Excel's TREND() extends the levels linearly over the next 8 quarters. Robust to zero / negative values.
A13: Holt-Winters (ETS) | B13: Excel's FORECAST.ETS() is exponential triple smoothing with auto seasonality. Pair with FORECAST.ETS.CONFINT() for 95% bands.
A15: Notes on Argentina
A16: Inflation regime breaks | B16: INDEC suspended/restated CPI 2007-15. Forecasts on the full history will look strange — consider trimming the date range used in the formula or relying on Holt-Winters which damps.
A17: Currency revaluations | B17: Pesos series may have notch jumps. Inspect the chart before quoting a forecast.
A19: Files
A20: Argentina_Tracker.xlsx | B20: This workbook. Open this every day.
A21: build_argentina.py | B21: Regenerates the workbook layout. Only run if you want to add/remove categories or rebuild from scratch.

Sheet Codes
A1: Codes — Single Source of Truth (Argentina)
A2: Edit the yellow cells. Quarterly Code is required; Annual Code is optional (the workbook aggregates from Q if blank). Aggregation: avg | sum | last.
A4: Section | B4: Indicator | C4: Frequency hint | D4: Quarterly Code | E4: Annual Code | F4: Units | G4: Aggregation | H4: Notes
A5: GDP | B5: Real GDP (SA) | C5: Q | D5: S213NGPC@LATAM | E5: S213NGPCA@LATAM | F5: Mn 2004 ARS | G5: avg | H5: [VERIFY] AR is country code 213 in IFS-style mnemonics.
A6: GDP | B6: Nominal GDP | C6: Q | D6: S213NGDP@LATAM | E6: S213NGDPA@LATAM | F6: Mn ARS | G6: avg | H6: [VERIFY]
A7: GDP | B7: EMAE Activity Index | C7: Q | D7: EMAE@ARGEN | E7: EMAEA@ARGEN | F7: Index 2004=100 | G7: avg | H7: INDEC monthly activity proxy. [VERIFY] code on your subscription.
A8: Inflation | B8: CPI National (IPC nacional) | C8: Q | D8: IPCNAC@ARGEN | E8: IPCNACA@ARGEN | F8: Index Dec-16=100 | G8: avg | H8: INDEC. Pre-2017 series has structural breaks (INDEC reform).
A9: Inflation | B9: Core CPI | C9: Q | D9: IPCCORE@ARGEN | E9: IPCCOREA@ARGEN | F9: Index | G9: avg | H9: [VERIFY]
A10: Inflation | B10: Wholesale Price Index (IPIM) | C10: Q | D10: IPIM@ARGEN | E10: IPIMA@ARGEN | F10: Index | G10: avg | H10: [VERIFY]
A11: Fiscal | B11: Primary Fiscal Balance | C11: Q | D11: SPNFBAL@ARGEN | E11: SPNFBALA@ARGEN | F11: Mn ARS | G11: sum | H11: Sector Publico Nacional No Financiero. [VERIFY]
A12: Fiscal | B12: Federal Tax Revenue | C12: Q | D12: RECNAC@ARGEN | E12: RECNACA@ARGEN | F12: Mn ARS | G12: sum | H12: [VERIFY]
A13: Fiscal | B13: Public Debt | C13: Q | D13: DEUDPUB@ARGEN | E13: DEUDPUBA@ARGEN | F13: USD Mn | G13: last | H13: End-period stock. [VERIFY]
A14: BoP | B14: Current Account Balance | C14: Q | D14: S213NCABA@LATAM | E14: S213NCABAA@LATAM | F14: USD Mn | G14: sum | H14: INDEC / BCRA. [VERIFY]
A15: BoP | B15: Trade Balance | C15: Q | D15: EXPMP@ARGEN | E15: EXPMPA@ARGEN | F15: USD Mn | G15: sum | H15: Exports - imports. [VERIFY]
... A18: Reserves | B18: Net International Reserves | C18: Q | D18: RESNET@ARGEN | E18: RESNETA@ARGEN | F18: USD Mn | G18: last | H18: BCRA NIR. [VERIFY]

Sheet GDP
A1: GDP — Argentina
A2: Each block: live HaverData pulls (col B) → growth metrics → TREND + FORECAST.ETS forecasts → chart.
A4: =Codes!$B$5&" ["&Codes!$D$5&"] "&Codes!$F$5 -> Real GDP (SA) [S213NGPC@LATAM] Mn 2004 ARS
A5: Aggregation: | B5: =Codes!$G$5 -> avg | D5: Notes: | E5: =Codes!$H$5 -> [VERIFY] AR is country code 213 in IFS-style mnemonics.
A6: Quarterly | J6: Annual
A7: Date | B7: Level | C7: QoQ % | D7: YoY % | E7: Linear Fcst | F7: ETS Fcst | G7: ETS Low 95% | H7: ETS High 95% | J7: Year | K7: Level | L7: YoY % | M7: Forecast
A8: 39448 | B8: =IFERROR(haverdata(Codes!$D$5,$A8),"") | E8: =IFERROR(IF(B8="",IFERROR(GROWTH($B$8:$B$95,$A$8:$A$95,$A8),TREND($B$8:$B$95,$A$8:$A$95,$A8)),""),"") | F8: =IFERROR(forecast.ets($A8,$B$8:$B$95,$A$8:$A$95,4,1,1),"") | G8: =IFERROR(F8-forecast.ets.confint($A8,$B$8:$B$95,$A$8:$A$95,0.95,4,1,1),"") | H8: =IFERROR(F8+forecast.ets.confint($A8,$B$8:$B$95,$A$8:$A$95,0.95,4,1,1),"") | J8: 2008 | K8: =IFERROR(AVERAGEIFS($B$8:$B$95,$A$8:$A$95,">="&DATE(J8,1,1),$A$8:$A$95,"<="&DATE(J8,12,31)),"") | M8: =IFERROR(AVERAGEIFS($F$8:$F$95,$A$8:$A$95,">="&DATE(J8,1,1),$A$8:$A$95,"<="&DATE(J8,12,31)),"")
A9: 39539 | B9: =IFERROR(haverdata(Codes!$D$5,$A9),"") | C9: =IFERROR(B9/B8-1,"") | E9: =IFERROR(IF(B9="",IFERROR(GROWTH($B$8:$B$95,$A$8:$A$95,$A9),TREND($B$8:$B$95,$A$8:$A$95,$A9)),""),"") | F9: =IFERROR(forecast.ets($A9,$B$8:$B$95,$A$8:$A$95,4,1,1),"") | G9: =IFERROR(F9-forecast.ets.confint($A9,$B$8:$B$95,$A$8:$A$95,0.95,4,1,1),"") | H9: =IFERROR(F9+forecast.ets.confint($A9,$B$8:$B$95,$A$8:$A$95,0.95,4,1,1),"") | J9: 2009 | K9: =IFERROR(AVERAGEIFS($B$8:$B$95,$A$8:$A$95,">="&DATE(J9,1,1),$A$8:$A$95,"<="&DATE(J9,12,31)),"") | L9: =IFERROR(K9/K8-1,"") | M9: =IFERROR(AVERAGEIFS($F$8:$F$95,$A$8:$A$95,">="&DATE(J9,1,1),$A$8:$A$95,"<="&DATE(J9,12,31)),"")
A10: 39630 | B10: =IFERROR(haverdata(Codes!$D$5,$A10),"") | C10: =IFERROR(B10/B9-1,"") | E10: =IFERROR(IF(B10="",IFERROR(GROWTH($B$8:$B$95,$A$8:$A$95,$A10),TREND($B$8:$B$95,$A$8:$A$95,$A10)),""),"") | F10: =IFERROR(forecast.ets($A10,$B$8:$B$95,$A$8:$A$95,4,1,1),"") | G10: =IFERROR(F10-forecast.ets.confint($A10,$B$8:$B$95,$A$8:$A$95,0.95,4,1,1),"") | H10: =IFERROR(F10+forecast.ets.confint($A10,$B$8:$B$95,$A$8:$A$95,0.95,4,1,1),"") | J10: 2010 | K10: =IFERROR(AVERAGEIFS($B$8:$B$95,$A$8:$A$95,">="&DATE(J10,1,1),$A$8:$A$95,"<="&DATE(J10,12,31)),"") | L10: =IFERROR(K10/K9-1,"") | M10: =IFERROR(AVERAGEIFS($F$8:$F$95,$A$8:$A$95,">="&DATE(J10,1,1),$A$8:$A$95,"<="&DATE(J10,12,31)),"")
A11: 39722 | B11: =IFERROR(haverdata(Codes!$D$5,$A11),"") | C11: =IFERROR(B11/B10-1,"") | E11: =IFERROR(IF(B11="",IFERROR(GROWTH($B$8:$B$95,$A$8:$A$95,$A11),TREND($B$8:$B$95,$A$8:$A$95,$A11)),""),"") | F11: =IFERROR(forecast.ets($A11,$B$8:$B$95,$A$8:$A$95,4,1,1),"") | G11: =IFERROR(F11-forecast.ets.confint($A11,$B$8:$B$95,$A$8:$A$95,0.95,4,1,1),"") | H11: =IFERROR(F11+forecast.ets.confint($A11,$B$8:$B$95,$A$8:$A$95,0.95,4,1,1),"") | J11: 2011 | K11: =IFERROR(AVERAGEIFS($B$8:$B$95,$A$8:$A$95,">="&DATE(J11,1,1),$A$8:$A$95,"<="&DATE(J11,12,31)),"") | L11: =IFERROR(K11/K10-1,"") | M11: =IFERROR(AVERAGEIFS($F$8:$F$95,$A$8:$A$95,">="&DATE(J11,1,1),$A$8:$A$95,"<="&DATE(J11,12,31)),"")
A12: 39814 | B12: =IFERROR(haverdata(Codes!$D$5,$A12),"") | C12: =IFERROR(B12/B11-1,"") | D12: =IFERROR(B12/B8-1,"") | E12: =IFERROR(IF(B12="",IFERROR(GROWTH($B$8:$B$95,$A$8:$A$95,$A12),TREND($B$8:$B$95,$A$8:$A$95,$A12)),""),"") | F12: =IFERROR(forecast.ets($A12,$B$8:$B$95,$A$8:$A$95,4,1,1),"") | G12: =IFERROR(F12-forecast.ets.confint($A12,$B$8:$B$95,$A$8:$A$95,0.95,4,1,1),"") | H12: =IFERROR(F12+forecast.ets.confint($A12,$B$8:$B$95,$A$8:$A$95,0.95,4,1,1),"") | J12: 2012 | K12: =IFERROR(AVERAGEIFS($B$8:$B$95,$A$8:$A$95,">="&DATE(J12,1,1),$A$8:$A$95,"<="&DATE(J12,12,31)),"") | L12: =IFERROR(K12/K11-1,"") | M12: =IFERROR(AVERAGEIFS($F$8:$F$95,$A$8:$A$95,">="&DATE(J12,1,1),$A$8:$A$95,"<="&DATE(J12,12,31)),"")
A13: 39904 | B13: =IFERROR(haverdata(Codes!$D$5,$A13),"") | C13: =IFERROR(B13/B12-1,"") | D13: =IFERROR(B13/B9-1,"") | E13: =IFERROR(IF(B13="",IFERROR(GROWTH($B$8:$B$95,$A$8:$A$95,$A13),TREND($B$8:$B$95,$A$8:$A$95,$A13)),""),"") | F13: =IFERROR(forecast.ets($A13,$B$8:$B$95,$A$8:$A$95,4,1,1),"") | G13: =IFERROR(F13-forecast.ets.confint($A13,$B$8:$B$95,$A$8:$A$95,0.95,4,1,1),"") | H13: =IFERROR(F13+forecast.ets.confint($A13,$B$8:$B$95,$A$8:$A$95,0.95,4,1,1),"") | J13: 2013 | K13: =IFERROR(AVERAGEIFS($B$8:$B$95,$A$8:$A$95,">="&DATE(J13,1,1),$A$8:$A$95,"<="&DATE(J13,12,31)),"") | L13: =IFERROR(K13/K12-1,"") | M13: =IFERROR(AVERAGEIFS($F$8:$F$95,$A$8:$A$95,">="&DATE(J13,1,1),$A$8:$A$95,"<="&DATE(J13,12,31)),"")
A14: 39995 | B14: =IFERROR(haverdata(Codes!$D$5,$A14),"") | C14: =IFERROR(B14/B13-1,"") | D14: =IFERROR(B14/B10-1,"") | E14: =IFERROR(IF(B14="",IFERROR(GROWTH($B$8:$B$95,$A$8:$A$95,$A14),TREND($B$8:$B$95,$A$8:$A$95,$A14)),""),"") | F14: =IFERROR(forecast.ets($A14,$B$8:$B$95,$A$8:$A$95,4,1,1),"") | G14: =IFERROR(F14-forecast.ets.confint($A14,$B$8:$B$95,$A$8:$A$95,0.95,4,1,1),"") | H14: =IFERROR(F14+forecast.ets.confint($A14,$B$8:$B$95,$A$8:$A$95,0.95,4,1,1),"") | J14: 2014 | K14: =IFERROR(AVERAGEIFS($B$8:$B$95,$A$8:$A$95,">="&DATE(J14,1,1),$A$8:$A$95,"<="&DATE(J14,12,31)),"") | L14: =IFERROR(K14/K13-1,"") | M14: =IFERROR(AVERAGEIFS($F$8:$F$95,$A$8:$A$95,">="&DATE(J14,1,1),$A$8:$A$95,"<="&DATE(J14,12,31)),"")
A15: 40087 | B15: =IFERROR(haverdata(Codes!$D$5,$A15),"") | C15: =IFERROR(B15/B14-1,"") | D15: =IFERROR(B15/B11-1,"") | E15: =IFERROR(IF(B15="",IFERROR(GROWTH($B$8:$B$95,$A$8:$A$95,$A15),TREND($B$8:$B$95,$A$8:$A$95,$A15)),""),"") | F15: =IFERROR(forecast.ets($A15,$B$8:$B$95,$A$8:$A$95,4,1,1),"") | G15: =IFERROR(F15-forecast.ets.confint($A15,$B$8:$B$95,$A$8:$A$95,0.95,4,1,1),"") | H15: =IFERROR(F15+forecast.ets.confint($A15,$B$8:$B$95,$A$8:$A$95,0.95,4,1,1),"") | J15: 2015 | K15: =IFERROR(AVERAGEIFS($B$8:$B$95,$A$8:$A$95,">="&DATE(J15,1,1),$A$8:$A$95,"<="&DATE(J15,12,31)),"") | L15: =IFERROR(K15/K14-1,"") | M15: =IFERROR(AVERAGEIFS($F$8:$F$95,$A$8:$A$95,">="&DATE(J15,1,1),$A$8:$A$95,"<="&DATE(J15,12,31)),"")
A16: 40179 | B16: =IFERROR(haverdata(Codes!$D$5,$A16),"") | C16: =IFERROR(B16/B15-1,"") | D16: =IFERROR(B16/B12-1,"") | E16: =IFERROR(IF(B16="",IFERROR(GROWTH($B$8:$B$95,$A$8:$A$95,$A16),TREND($B$8:$B$95,$A$8:$A$95,$A16)),""),"") | F16: =IFERROR(forecast.ets($A16,$B$8:$B$95,$A$8:$A$95,4,1,1),"") | G16: =IFERROR(F16-forecast.ets.confint($A16,$B$8:$B$95,$A$8:$A$95,0.95,4,1,1),"") | H16: =IFERROR(F16+forecast.ets.confint($A16,$B$8:$B$95,$A$8:$A$95,0.95,4,1,1),"") | J16: 2016 | K16: =IFERROR(AVERAGEIFS($B$8:$B$95,$A$8:$A$95,">="&DATE(J16,1,1),$A$8:$A$95,"<="&DATE(J16,12,31)),"") | L16: =IFERROR(K16/K15-1,"") | M16: =IFERROR(AVERAGEIFS($F$8:$F$95,$A$8:$A$95,">="&DATE(J16,1,1),$A$8:$A$95,"<="&DATE(J16,12,31)),"")
A17: 40269 | B17: =IFERROR(haverdata(Codes!$D$5,$A17),"") | C17: =IFERROR(B17/B16-1,"") | D17: =IFERROR(B17/B13-1,"") | E17: =IFERROR(IF(B17="",IFERROR(GROWTH($B$8:$B$95,$A$8:$A$95,$A17),TREND($B$8:$B$95,$A$8:$A$95,$A17)),""),"") | F17: =IFERROR(forecast.ets($A17,$B$8:$B$95,$A$8:$A$95,4,1,1),"") | G17: =IFERROR(F17-forecast.ets.confint($A17,$B$8:$B$95,$A$8:$A$95,0.95,4,1,1),"") | H17: =IFERROR(F17+forecast.ets.confint($A17,$B$8:$B$95,$A$8:$A$95,0.95,4,1,1),"") | J17: 2017 | K17: =IFERROR(AVERAGEIFS($B$8:$B$95,$A$8:$A$95,">="&DATE(J17,1,1),$A$8:$A$95,"<="&DATE(J17,12,31)),"") | L17: =IFERROR(K17/K16-1,"") | M17: =IFERROR(AVERAGEIFS($F$8:$F$95,$A$8:$A$95,">="&DATE(J17,1,1),$A$8:$A$95,"<="&DATE(J17,12,31)),"")
A18: 40360 | B18: =IFERROR(haverdata(Codes!$D$5,$A18),"") | C18: =IFERROR(B18/B17-1,"") | D18: =IFERROR(B18/B14-1,"") | E18: =IFERROR(IF(B18="",IFERROR(GROWTH($B$8:$B$95,$A$8:$A$95,$A18),TREND($B$8:$B$95,$A$8:$A$95,$A18)),""),"") | F18: =IFERROR(forecast.ets($A18,$B$8:$B$95,$A$8:$A$95,4,1,1),"") | G18: =IFERROR(F18-forecast.ets.confint($A18,$B$8:$B$95,$A$8:$A$95,0.95,4,1,1),"") | H18: =IFERROR(F18+forecast.ets.confint($A18,$B$8:$B$95,$A$8:$A$95,0.95,4,1,1),"") | J18: 2018 | K18: =IFERROR(AVERAGEIFS($B$8:$B$95,$A$8:$A$95,">="&DATE(J18,1,1),$A$8:$A$95,"<="&DATE(J18,12,31)),"") | L18: =IFERROR(K18/K17-1,"") | M18: =IFERROR(AVERAGEIFS($F$8:$F$95,$A$8:$A$95,">="&DATE(J18,1,1),$A$8:$A$95,"<="&DATE(J18,12,31)),"")
A19: 40452 | B19: =IFERROR(haverdata(Codes!$D$5,$A19),"") | C19: =IFERROR(B19/B18-1,"") | D19: =IFERROR(B19/B15-1,"") | E19: =IFERROR(IF(B19="",IFERROR(GROWTH($B$8:$B$95,$A$8:$A$95,$A19),TREND($B$8:$B$95,$A$8:$A$95,$A19)),""),"") | F19: =IFERROR(forecast.ets($A19,$B$8:$B$95,$A$8:$A$95,4,1,1),"") | G19: =IFERROR(F19-forecast.ets.confint($A19,$B$8:$B$95,$A$8:$A$95,0.95,4,1,1),"") | H19: =IFERROR(F19+forecast.ets.confint($A19,$B$8:$B$95,$A$8:$A$95,0.95,4,1,1),"") | J19: 2019 | K19: =IFERROR(AVERAGEIFS($B$8:$B$95,$A$8:$A$95,">="&DATE(J19,1,1),$A$8:$A$95,"<="&DATE(J19,12,31)),"") | L19: =IFERROR(K19/K18-1,"") | M19: =IFERROR(AVERAGEIFS($F$8:$F$95,$A$8:$A$95,">="&DATE(J19,1,1),$A$8:$A$95,"<="&DATE(J19,12,31)),"")
A20: 40544 | B20: =IFERROR(haverdata(Codes!$D$5,$A20),"") | C20: =IFERROR(B20/B19-1,"") | D20: =IFERROR(B20/B16-1,"") | E20: =IFERROR(IF(B20="",IFERROR(GROWTH($B$8:$B$95,$A$8:$A$95,$A20),TREND($B$8:$B$95,$A$8:$A$95,$A20)),""),"") | F20: =IFERROR(forecast.ets($A20,$B$8:$B$95,$A$8:$A$95,4,1,1),"") | G20: =IFERROR(F20-forecast.ets.confint($A20,$B$8:$B$95,$A$8:$A$95,0.95,4,1,1),"") | H20: =IFERROR(F20+forecast.ets.confint($A20,$B$8:$B$95,$A$8:$A$95,0.95,4,1,1),"") | J20: 2020 | K20: =IFERROR(AVERAGEIFS($B$8:$B$95,$A$8:$A$95,">="&DATE(J20,1,1),$A$8:$A$95,"<="&DATE(J20,12,31)),"") | L20: =IFERROR(K20/K19-1,"") | M20: =IFERROR(AVERAGEIFS($F$8:$F$95,$A$8:$A$95,">="&DATE(J20,1,1),$A$8:$A$95,"<="&DATE(J20,12,31)),"")
A21: 40634 | B21: =IFERROR(haverdata(Codes!$D$5,$A21),"") | C21: =IFERROR(B21/B20-1,"") | D21: =IFERROR(B21/B17-1,"") | E21: =IFERROR(IF(B21="",IFERROR(GROWTH($B$8:$B$95,$A$8:$A$95,$A21),TREND($B$8:$B$95,$A$8:$A$95,$A21)),""),"") | F21: =IFERROR(forecast.ets($A21,$B$8:$B$95,$A$8:$A$95,4,1,1),"") | G21: =IFERROR(F21-forecast.ets.confint($A21,$B$8:$B$95,$A$8:$A$95,0.95,4,1,1),"") | H21: =IFERROR(F21+forecast.ets.confint($A21,$B$8:$B$95,$A$8:$A$95,0.95,4,1,1),"") | J21: 2021 | K21: =IFERROR(AVERAGEIFS($B$8:$B$95,$A$8:$A$95,">="&DATE(J21,1,1),$A$8:$A$95,"<="&DATE(J21,12,31)),"") | L21: =IFERROR(K21/K20-1,"") | M21: =IFERROR(AVERAGEIFS($F$8:$F$95,$A$8:$A$95,">="&DATE(J21,1,1),$A$8:$A$95,"<="&DATE(J21,12,31)),"")
A22: 40725 | B22: =IFERROR(haverdata(Codes!$D$5,$A22),"") | C22: =IFERROR(B22/B21-1,"") | D22: =IFERROR(B22/B18-1,"") | E22: =IFERROR(IF(B22="",IFERROR(GROWTH($B$8:$B$95,$A$8:$A$95,$A22),TREND($B$8:$B$95,$A$8:$A$95,$A22)),""),"") | F22: =IFERROR(forecast.ets($A22,$B$8:$B$95,$A$8:$A$95,4,1,1),"") | G22: =IFERROR(F22-forecast.ets.confint($A22,$B$8:$B$95,$A$8:$A$95,0.95,4,1,1),"") | H22: =IFERROR(F22+forecast.ets.confint($A22,$B$8:$B$95,$A$8:$A$95,0.95,4,1,1),"") | J22: 2022 | K22: =IFERROR(AVERAGEIFS($B$8:$B$95,$A$8:$A$95,">="&DATE(J22,1,1),$A$8:$A$95,"<="&DATE(J22,12,31)),"") | L22: =IFERROR(K22/K21-1,"") | M22: =IFERROR(AVERAGEIFS($F$8:$F$95,$A$8:$A$95,">="&DATE(J22,1,1),$A$8:$A$95,"<="&DATE(J22,12,31)),"")
A23: 40817 | B23: =IFERROR(haverdata(Codes!$D$5,$A23),"") | C23: =IFERROR(B23/B22-1,"") | D23: =IFERROR(B23/B19-1,"") | E23: =IFERROR(IF(B23="",IFERROR(GROWTH($B$8:$B$95,$A$8:$A$95,$A23),TREND($B$8:$B$95,$A$8:$A$95,$A23)),""),"") | F23: =IFERROR(forecast.ets($A23,$B$8:$B$95,$A$8:$A$95,4,1,1),"") | G23: =IFERROR(F23-forecast.ets.confint($A23,$B$8:$B$95,$A$8:$A$95,0.95,4,1,1),"") | H23: =IFERROR(F23+forecast.ets.confint($A23,$B$8:$B$95,$A$8:$A$95,0.95,4,1,1),"") | J23: 2023 | K23: =IFERROR(AVERAGEIFS($B$8:$B$95,$A$8:$A$95,">="&DATE(J23,1,1),$A$8:$A$95,"<="&DATE(J23,12,31)),"") | L23: =IFERROR(K23/K22-1,"") | M23: =IFERROR(AVERAGEIFS($F$8:$F$95,$A$8:$A$95,">="&DATE(J23,1,1),$A$8:$A$95,"<="&DATE(J23,12,31)),"")
... A29: 41365 | B29: =IFERROR(haverdata(Codes!$D$5,$A29),"") | C29: =IFERROR(B29/B28-1,"") | D29: =IFERROR(B29/B25-1,"") | E29: =IFERROR(IF(B29="",IFERROR(GROWTH($B$8:$B$95,$A$8:$A$95,$A29),TREND($B$8:$B$95,$A$8:$A$95,$A29)),""),"") | F29: =IFERROR(forecast.ets($A29,$B$8:$B$95,$A$8:$A$95,4,1,1),"") | G29: =IFERROR(F29-forecast.ets.confint($A29,$B$8:$B$95,$A$8:$A$95,0.95,4,1,1),"") | H29: =IFERROR(F29+forecast.ets.confint($A29,$B$8:$B$95,$A$8:$A$95,0.95,4,1,1),"") | J29: 2029 | K29: =IFERROR(AVERAGEIFS($B$8:$B$95,$A$8:$A$95,">="&DATE(J29,1,1),$A$8:$A$95,"<="&DATE(J29,12,31)),"") | L29: =IFERROR(K29/K28-1,"") | M29: =IFERROR(AVERAGEIFS($F$8:$F$95,$A$8:$A$95,">="&DATE(J29,1,1),$A$8:$A$95,"<="&DATE(J29,12,31)),"")
A30: 41456 | B30: =IFERROR(haverdata(Codes!$D$5,$A30),"") | C30: =IFERROR(B30/B29-1,"") | D30: =IFERROR(B30/B26-1,"") | E30: =IFERROR(IF(B30="",IFERROR(GROWTH($B$8:$B$95,$A$8:$A$95,$A30),TREND($B$8:$B$95,$A$8:$A$95,$A30)),""),"") | F30: =IFERROR(forecast.ets($A30,$B$8:$B$95,$A$8:$A$95,4,1,1),"") | G30: =IFERROR(F30-forecast.ets.confint($A30,$B$8:$B$95,$A$8:$A$95,0.95,4,1,1),"") | H30: =IFERROR(F30+forecast.ets.confint($A30,$B$8:$B$95,$A$8:$A$95,0.95,4,1,1),"")
A31: 41548 | B31: =IFERROR(haverdata(Codes!$D$5,$A31),"") | C31: =IFERROR(B31/B30-1,"") | D31: =IFERROR(B31/B27-1,"") | E31: =IFERROR(IF(B31="",IFERROR(GROWTH($B$8:$B$95,$A$8:$A$95,$A31),TREND($B$8:$B$95,$A$8:$A$95,$A31)),""),"") | F31: =IFERROR(forecast.ets($A31,$B$8:$B$95,$A$8:$A$95,4,1,1),"") | G31: =IFERROR(F31-forecast.ets.confint($A31,$B$8:$B$95,$A$8:$A$95,0.95,4,1,1),"") | H31: =IFERROR(F31+forecast.ets.confint($A31,$B$8:$B$95,$A$8:$A$95,0.95,4,1,1),"")
A32: 41640 | B32: =IFERROR(haverdata(Codes!$D$5,$A32),"") | C32: =IFERROR(B32/B31-1,"") | D32: =IFERROR(B32/B28-1,"") | E32: =IFERROR(IF(B32="",IFERROR(GROWTH($B$8:$B$95,$A$8:$A$95,$A32),TREND($B$8:$B$95,$A$8:$A$95,$A32)),""),"") | F32: =IFERROR(forecast.ets($A32,$B$8:$B$95,$A$8:$A$95,4,1,1),"") | G32: =IFERROR(F32-forecast.ets.confint($A32,$B$8:$B$95,$A$8:$A$95,0.95,4,1,1),"") | H32: =IFERROR(F32+forecast.ets.confint($A32,$B$8:$B$95,$A$8:$A$95,0.95,4,1,1),"")
A33: 41730 | B33: =IFERROR(haverdata(Codes!$D$5,$A33),"") | C33: =IFERROR(B33/B32-1,"") | D33: =IFERROR(B33/B29-1,"") | E33: =IFERROR(IF(B33="",IFERROR(GROWTH($B$8:$B$95,$A$8:$A$95,$A33),TREND($B$8:$B$95,$A$8:$A$95,$A33)),""),"") | F33: =IFERROR(forecast.ets($A33,$B$8:$B$95,$A$8:$A$95,4,1,1),"") | G33: =IFERROR(F33-forecast.ets.confint($A33,$B$8:$B$95,$A$8:$A$95,0.95,4,1,1),"") | H33: =IFERROR(F33+forecast.ets.confint($A33,$B$8:$B$95,$A$8:$A$95,0.95,4,1,1),"")
A34: 41821 | B34: =IFERROR(haverdata(Codes!$D$5,$A34),"") | C34: =IFERROR(B34/B33-1,"") | D34: =IFERROR(B34/B30-1,"") | E34: =IFERROR(IF(B34="",IFERROR(GROWTH($B$8:$B$95,$A$8:$A$95,$A34),TREND($B$8:$B$95,$A$8:$A$95,$A34)),""),"") | F34: =IFERROR(forecast.ets($A34,$B$8:$B$95,$A$8:$A$95,4,1,1),"") | G34: =IFERROR(F34-forecast.ets.confint($A34,$B$8:$B$95,$A$8:$A$95,0.95,4,1,1),"") | H34: =IFERROR(F34+forecast.ets.confint($A34,$B$8:$B$95,$A$8:$A$95,0.95,4,1,1),"")
A35: 41913 | B35: =IFERROR(haverdata(Codes!$D$5,$A35),"") | C35: =IFERROR(B35/B34-1,"") | D35: =IFERROR(B35/B31-1,"") | E35: =IFERROR(IF(B35="",IFERROR(GROWTH($B$8:$B$95,$A$8:$A$95,$A35),TREND($B$8:$B$95,$A$8:$A$95,$A35)),""),"") | F35: =IFERROR(forecast.ets($A35,$B$8:$B$95,$A$8:$A$95,4,1,1),"") | G35: =IFERROR(F35-forecast.ets.confint($A35,$B$8:$B$95,$A$8:$A$95,0.95,4,1,1),"") | H35: =IFERROR(F35+forecast.ets.confint($A35,$B$8:$B$95,$A$8:$A$95,0.95,4,1,1),"")
A36: 42005 | B36: =IFERROR(haverdata(Codes!$D$5,$A36),"") | C36: =IFERROR(B36/B35-1,"") | D36: =IFERROR(B36/B32-1,"") | E36: =IFERROR(IF(B36="",IFERROR(GROWTH($B$8:$B$95,$A$8:$A$95,$A36),TREND($B$8:$B$95,$A$8:$A$95,$A36)),""),"") | F36: =IFERROR(forecast.ets($A36,$B$8:$B$95,$A$8:$A$95,4,1,1),"") | G36: =IFERROR(F36-forecast.ets.confint($A36,$B$8:$B$95,$A$8:$A$95,0.95,4,1,1),"") | H36: =IFERROR(F36+forecast.ets.confint($A36,$B$8:$B$95,$A$8:$A$95,0.95,4,1,1),"")
A37: 42095 | B37: =IFERROR(haverdata(Codes!$D$5,$A37),"") | C37: =IFERROR(B37/B36-1,"") | D37: =IFERROR(B37/B33-1,"") | E37: =IFERROR(IF(B37="",IFERROR(GROWTH($B$8:$B$95,$A$8:$A$95,$A37),TREND($B$8:$B$95,$A$8:$A$95,$A37)),""),"") | F37: =IFERROR(forecast.ets($A37,$B$8:$B$95,$A$8:$A$95,4,1,1),"") | G37: =IFERROR(F37-forecast.ets.confint($A37,$B$8:$B$95,$A$8:$A$95,0.95,4,1,1),"") | H37: =IFERROR(F37+forecast.ets.confint($A37,$B$8:$B$95,$A$8:$A$95,0.95,4,1,1),"")
A38: 42186 | B38: =IFERROR(haverdata(Codes!$D$5,$A38),"") | C38: =IFERROR(B38/B37-1,"") | D38: =IFERROR(B38/B34-1,"") | E38: =IFERROR(IF(B38="",IFERROR(GROWTH($B$8:$B$95,$A$8:$A$95,$A38),TREND($B$8:$B$95,$A$8:$A$95,$A38)),""),"") | F38: =IFERROR(forecast.ets($A38,$B$8:$B$95,$A$8:$A$95,4,1,1),"") | G38: =IFERROR(F38-forecast.ets.confint($A38,$B$8:$B$95,$A$8:$A$95,0.95,4,1,1),"") | H38: =IFERROR(F38+forecast.ets.confint($A38,$B$8:$B$95,$A$8:$A$95,0.95,4,1,1),"")
A39: 42278 | B39: =IFERROR(haverdata(Codes!$D$5,$A39),"") | C39: =IFERROR(B39/B38-1,"") | D39: =IFERROR(B39/B35-1,"") | E39: =IFERROR(IF(B39="",IFERROR(GROWTH($B$8:$B$95,$A$8:$A$95,$A39),TREND($B$8:$B$95,$A$8:$A$95,$A39)),""),"") | F39: =IFERROR(forecast.ets($A39,$B$8:$B$95,$A$8:$A$95,4,1,1),"") | G39: =IFERROR(F39-forecast.ets.confint($A39,$B$8:$B$95,$A$8:$A$95,0.95,4,1,1),"") | H39: =IFERROR(F39+forecast.ets.confint($A39,$B$8:$B$95,$A$8:$A$95,0.95,4,1,1),"")
A40: 42370 | B40: =IFERROR(haverdata(Codes!$D$5,$A40),"") | C40: =IFERROR(B40/B39-1,"") | D40: =IFERROR(B40/B36-1,"") | E40: =IFERROR(IF(B40="",IFERROR(GROWTH($B$8:$B$95,$A$8:$A$95,$A40),TREND($B$8:$B$95,$A$8:$A$95,$A40)),""),"") | F40: =IFERROR(forecast.ets($A40,$B$8:$B$95,$A$8:$A$95,4,1,1),"") | G40: =IFERROR(F40-forecast.ets.confint($A40,$B$8:$B$95,$A$8:$A$95,0.95,4,1,1),"") | H40: =IFERROR(F40+forecast.ets.confint($A40,$B$8:$B$95,$A$8:$A$95,0.95,4,1,1),"")
A41: 42461 | B41: =IFERROR(haverdata(Codes!$D$5,$A41),"") | C41: =IFERROR(B41/B40-1,"") | D41: =IFERROR(B41/B37-1,"") | E41: =IFERROR(IF(B41="",IFERROR(GROWTH($B$8:$B$95,$A$8:$A$95,$A41),TREND($B$8:$B$95,$A$8:$A$95,$A41)),""),"") | F41: =IFERROR(forecast.ets($A41,$B$8:$B$95,$A$8:$A$95,4,1,1),"") | G41: =IFERROR(F41-forecast.ets.confint($A41,$B$8:$B$95,$A$8:$A$95,0.95,4,1,1),"") | H41: =IFERROR(F41+forecast.ets.confint($A41,$B$8:$B$95,$A$8:$A$95,0.95,4,1,1),"")
... A95: 47392 | B95: =IFERROR(haverdata(Codes!$D$5,$A95),"") | C95: =IFERROR(B95/B94-1,"") | D95: =IFERROR(B95/B91-1,"") | E95: =IFERROR(IF(B95="",IFERROR(GROWTH($B$8:$B$95,$A$8:$A$95,$A95),TREND($B$8:$B$95,$A$8:$A$95,$A95)),""),"") | F95: =IFERROR(forecast.ets($A95,$B$8:$B$95,$A$8:$A$95,4,1,1),"") | G95: =IFERROR(F95-forecast.ets.confint($A95,$B$8:$B$95,$A$8:$A$95,0.95,4,1,1),"") | H95: =IFERROR(F95+forecast.ets.confint($A95,$B$8:$B$95,$A$8:$A$95,0.95,4,1,1),"")
A100: =Codes!$B$6&" ["&Codes!$D$6&"] "&Codes!$F$6 -> Nominal GDP [S213NGDP@LATAM] Mn ARS
A101: Aggregation: | B101: =Codes!$G$6 -> avg | D101: Notes: | E101: =Codes!$H$6 -> [VERIFY]
A102: Quarterly | J102: Annual
A103: Date | B103: Level | C103: QoQ % | D103: YoY % | E103: Linear Fcst | F103: ETS Fcst | G103: ETS Low 95% | H103: ETS High 95% | J103: Year | K103: Level | L103: YoY % | M103: Forecast
...

Sheet Inflation
A1: Inflation — Argentina
A2: Each block: live HaverData pulls (col B) → growth metrics → TREND + FORECAST.ETS forecasts → chart.
A4: =Codes!$B$8&" ["&Codes!$D$8&"] "&Codes!$F$8 -> CPI National (IPC nacional) [IPCNAC@ARGEN] Index Dec-16=100
A5: Aggregation: | B5: =Codes!$G$8 -> avg | D5: Notes: | E5: =Codes!$H$8 -> INDEC. Pre-2017 series has structural breaks (INDEC reform).
A6: Quarterly | J6: Annual
A7: Date | B7: Level | C7: QoQ % | D7: YoY % | E7: Linear Fcst | F7: ETS Fcst | G7: ETS Low 95% | H7: ETS High 95% | J7: Year | K7: Level | L7: YoY % | M7: Forecast
A8: 39448 | B8: =IFERROR(haverdata(Codes!$D$8,$A8),"") | E8: =IFERROR(IF(B8="",IFERROR(GROWTH($B$8:$B$95,$A$8:$A$95,$A8),TREND($B$8:$B$95,$A$8:$A$95,$A8)),""),"") | F8: =IFERROR(forecast.ets($A8,$B$8:$B$95,$A$8:$A$95,4,1,1),"") | G8: =IFERROR(F8-forecast.ets.confint($A8,$B$8:$B$95,$A$8:$A$95,0.95,4,1,1),"") | H8: =IFERROR(F8+forecast.ets.confint($A8,$B$8:$B$95,$A$8:$A$95,0.95,4,1,1),"") | J8: 2008 | K8: =IFERROR(AVERAGEIFS($B$8:$B$95,$A$8:$A$95,">="&DATE(J8,1,1),$A$8:$A$95,"<="&DATE(J8,12,31)),"") | M8: =IFERROR(AVERAGEIFS($F$8:$F$95,$A$8:$A$95,">="&DATE(J8,1,1),$A$8:$A$95,"<="&DATE(J8,12,31)),"")
A9: 39539 | B9: =IFERROR(haverdata(Codes!$D$8,$A9),"") | C9: =IFERROR(B9/B8-1,"") | E9: =IFERROR(IF(B9="",IFERROR(GROWTH($B$8:$B$95,$A$8:$A$95,$A9),TREND($B$8:$B$95,$A$8:$A$95,$A9)),""),"") | F9: =IFERROR(forecast.ets($A9,$B$8:$B$95,$A$8:$A$95,4,1,1),"") | G9: =IFERROR(F9-forecast.ets.confint($A9,$B$8:$B$95,$A$8:$A$95,0.95,4,1,1),"") | H9: =IFERROR(F9+forecast.ets.confint($A9,$B$8:$B$95,$A$8:$A$95,0.95,4,1,1),"") | J9: 2009 | K9: =IFERROR(AVERAGEIFS($B$8:$B$95,$A$8:$A$95,">="&DATE(J9,1,1),$A$8:$A$95,"<="&DATE(J9,12,31)),"") | L9: =IFERROR(K9/K8-1,"") | M9: =IFERROR(AVERAGEIFS($F$8:$F$95,$A$8:$A$95,">="&DATE(J9,1,1),$A$8:$A$95,"<="&DATE(J9,12,31)),"")
A10: 39630 | B10: =IFERROR(haverdata(Codes!$D$8,$A10),"") | C10: =IFERROR(B10/B9-1,"") | E10: =IFERROR(IF(B10="",IFERROR(GROWTH($B$8:$B$95,$A$8:$A$95,$A10),TREND($B$8:$B$95,$A$8:$A$95,$A10)),""),"") | F10: =IFERROR(forecast.ets($A10,$B$8:$B$95,$A$8:$A$95,4,1,1),"") | G10: =IFERROR(F10-forecast.ets.confint($A10,$B$8:$B$95,$A$8:$A$95,0.95,4,1,1),"") | H10: =IFERROR(F10+forecast.ets.confint($A10,$B$8:$B$95,$A$8:$A$95,0.95,4,1,1),"") | J10: 2010 | K10: =IFERROR(AVERAGEIFS($B$8:$B$95,$A$8:$A$95,">="&DATE(J10,1,1),$A$8:$A$95,"<="&DATE(J10,12,31)),"") | L10: =IFERROR(K10/K9-1,"") | M10: =IFERROR(AVERAGEIFS($F$8:$F$95,$A$8:$A$95,">="&DATE(J10,1,1),$A$8:$A$95,"<="&DATE(J10,12,31)),"")
A11: 39722 | B11: =IFERROR(haverdata(Codes!$D$8,$A11),"") | C11: =IFERROR(B11/B10-1,"") | E11: =IFERROR(IF(B11="",IFERROR(GROWTH($B$8:$B$95,$A$8:$A$95,$A11),TREND($B$8:$B$95,$A$8:$A$95,$A11)),""),"") | F11: =IFERROR(forecast.ets($A11,$B$8:$B$95,$A$8:$A$95,4,1,1),"") | G11: =IFERROR(F11-forecast.ets.confint($A11,$B$8:$B$95,$A$8:$A$95,0.95,4,1,1),"") | H11: =IFERROR(F11+forecast.ets.confint($A11,$B$8:$B$95,$A$8:$A$95,0.95,4,1,1),"") | J11: 2011 | K11: =IFERROR(AVERAGEIFS($B$8:$B$95,$A$8:$A$95,">="&DATE(J11,1,1),$A$8:$A$95,"<="&DATE(J11,12,31)),"") | L11: =IFERROR(K11/K10-1,"") | M11: =IFERROR(AVERAGEIFS($F$8:$F$95,$A$8:$A$95,">="&DATE(J11,1,1),$A$8:$A$95,"<="&DATE(J11,12,31)),"")
A12: 39814 | B12: =IFERROR(haverdata(Codes!$D$8,$A12),"") | C12: =IFERROR(B12/B11-1,"") | D12: =IFERROR(B12/B8-1,"") | E12: =IFERROR(IF(B12="",IFERROR(GROWTH($B$8:$B$95,$A$8:$A$95,$A12),TREND($B$8:$B$95,$A$8:$A$95,$A12)),""),"") | F12: =IFERROR(forecast.ets($A12,$B$8:$B$95,$A$8:$A$95,4,1,1),"") | G12: =IFERROR(F12-forecast.ets.confint($A12,$B$8:$B$95,$A$8:$A$95,0.95,4,1,1),"") | H12: =IFERROR(F12+forecast.ets.confint($A12,$B$8:$B$95,$A$8:$A$95,0.95,4,1,1),"") | J12: 2012 | K12: =IFERROR(AVERAGEIFS($B$8:$B$95,$A$8:$A$95,">="&DATE(J12,1,1),$A$8:$A$95,"<="&DATE(J12,12,31)),"") | L12: =IFERROR(K12/K11-1,"") | M12: =IFERROR(AVERAGEIFS($F$8:$F$95,$A$8:$A$95,">="&DATE(J12,1,1),$A$8:$A$95,"<="&DATE(J12,12,31)),"")
A13: 39904 | B13: =IFERROR(haverdata(Codes!$D$8,$A13),"") | C13: =IFERROR(B13/B12-1,"") | D13: =IFERROR(B13/B9-1,"") | E13: =IFERROR(IF(B13="",IFERROR(GROWTH($B$8:$B$95,$A$8:$A$95,$A13),TREND($B$8:$B$95,$A$8:$A$95,$A13)),""),"") | F13: =IFERROR(forecast.ets($A13,$B$8:$B$95,$A$8:$A$95,4,1,1),"") | G13: =IFERROR(F13-forecast.ets.confint($A13,$B$8:$B$95,$A$8:$A$95,0.95,4,1,1),"") | H13: =IFERROR(F13+forecast.ets.confint($A13,$B$8:$B$95,$A$8:$A$95,0.95,4,1,1),"") | J13: 2013 | K13: =IFERROR(AVERAGEIFS($B$8:$B$95,$A$8:$A$95,">="&DATE(J13,1,1),$A$8:$A$95,"<="&DATE(J13,12,31)),"") | L13: =IFERROR(K13/K12-1,"") | M13: =IFERROR(AVERAGEIFS($F$8:$F$95,$A$8:$A$95,">="&DATE(J13,1,1),$A$8:$A$95,"<="&DATE(J13,12,31)),"")
A14: 39995 | B14: =IFERROR(haverdata(Codes!$D$8,$A14),"") | C14: =IFERROR(B14/B13-1,"") | D14: =IFERROR(B14/B10-1,"") | E14: =IFERROR(IF(B14="",IFERROR(GROWTH($B$8:$B$95,$A$8:$A$95,$A14),TREND($B$8:$B$95,$A$8:$A$95,$A14)),""),"") | F14: =IFERROR(forecast.ets($A14,$B$8:$B$95,$A$8:$A$95,4,1,1),"") | G14: =IFERROR(F14-forecast.ets.confint($A14,$B$8:$B$95,$A$8:$A$95,0.95,4,1,1),"") | H14: =IFERROR(F14+forecast.ets.confint($A14,$B$8:$B$95,$A$8:$A$95,0.95,4,1,1),"") | J14: 2014 | K14: =IFERROR(AVERAGEIFS($B$8:$B$95,$A$8:$A$95,">="&DATE(J14,1,1),$A$8:$A$95,"<="&DATE(J14,12,31)),"") | L14: =IFERROR(K14/K13-1,"") | M14: =IFERROR(AVERAGEIFS($F$8:$F$95,$A$8:$A$95,">="&DATE(J14,1,1),$A$8:$A$95,"<="&DATE(J14,12,31)),"")
A15: 40087 | B15: =IFERROR(haverdata(Codes!$D$8,$A15),"") | C15: =IFERROR(B15/B14-1,"") | D15: =IFERROR(B15/B11-1,"") | E15: =IFERROR(IF(B15="",IFERROR(GROWTH($B$8:$B$95,$A$8:$A$95,$A15),TREND($B$8:$B$95,$A$8:$A$95,$A15)),""),"") | F15: =IFERROR(forecast.ets($A15,$B$8:$B$95,$A$8:$A$95,4,1,1),"") | G15: =IFERROR(F15-forecast.ets.confint($A15,$B$8:$B$95,$A$8:$A$95,0.95,4,1,1),"") | H15: =IFERROR(F15+forecast.ets.confint($A15,$B$8:$B$95,$A$8:$A$95,0.95,4,1,1),"") | J15: 2015 | K15: =IFERROR(AVERAGEIFS($B$8:$B$95,$A$8:$A$95,">="&DATE(J15,1,1),$A$8:$A$95,"<="&DATE(J15,12,31)),"") | L15: =IFERROR(K15/K14-1,"") | M15: =IFERROR(AVERAGEIFS($F$8:$F$95,$A$8:$A$95,">="&DATE(J15,1,1),$A$8:$A$95,"<="&DATE(J15,12,31)),"")
A16: 40179 | B16: =IFERROR(haverdata(Codes!$D$8,$A16),"") | C16: =IFERROR(B16/B15-1,"") | D16: =IFERROR(B16/B12-1,"") | E16: =IFERROR(IF(B16="",IFERROR(GROWTH($B$8:$B$95,$A$8:$A$95,$A16),TREND($B$8:$B$95,$A$8:$A$95,$A16)),""),"") | F16: =IFERROR(forecast.ets($A16,$B$8:$B$95,$A$8:$A$95,4,1,1),"") | G16: =IFERROR(F16-forecast.ets.confint($A16,$B$8:$B$95,$A$8:$A$95,0.95,4,1,1),"") | H16: =IFERROR(F16+forecast.ets.confint($A16,$B$8:$B$95,$A$8:$A$95,0.95,4,1,1),"") | J16: 2016 | K16: =IFERROR(AVERAGEIFS($B$8:$B$95,$A$8:$A$95,">="&DATE(J16,1,1),$A$8:$A$95,"<="&DATE(J16,12,31)),"") | L16: =IFERROR(K16/K15-1,"") | M16: =IFERROR(AVERAGEIFS($F$8:$F$95,$A$8:$A$95,">="&DATE(J16,1,1),$A$8:$A$95,"<="&DATE(J16,12,31)),"")
A17: 40269 | B17: =IFERROR(haverdata(Codes!$D$8,$A17),"") | C17: =IFERROR(B17/B16-1,"") | D17: =IFERROR(B17/B13-1,"") | E17: =IFERROR(IF(B17="",IFERROR(GROWTH($B$8:$B$95,$A$8:$A$95,$A17),TREND($B$8:$B$95,$A$8:$A$95,$A17)),""),"") | F17: =IFERROR(forecast.ets($A17,$B$8:$B$95,$A$8:$A$95,4,1,1),"") | G17: =IFERROR(F17-forecast.ets.confint($A17,$B$8:$B$95,$A$8:$A$95,0.95,4,1,1),"") | H17: =IFERROR(F17+forecast.ets.confint($A17,$B$8:$B$95,$A$8:$A$95,0.95,4,1,1),"") | J17: 2017 | K17: =IFERROR(AVERAGEIFS($B$8:$B$95,$A$8:$A$95,">="&DATE(J17,1,1),$A$8:$A$95,"<="&DATE(J17,12,31)),"") | L17: =IFERROR(K17/K16-1,"") | M17: =IFERROR(AVERAGEIFS($F$8:$F$95,$A$8:$A$95,">="&DATE(J17,1,1),$A$8:$A$95,"<="&DATE(J17,12,31)),"")
A18: 40360 | B18: =IFERROR(haverdata(Codes!$D$8,$A18),"") | C18: =IFERROR(B18/B17-1,"") | D18: =IFERROR(B18/B14-1,"") | E18: =IFERROR(IF(B18="",IFERROR(GROWTH($B$8:$B$95,$A$8:$A$95,$A18),TREND($B$8:$B$95,$A$8:$A$95,$A18)),""),"") | F18: =IFERROR(forecast.ets($A18,$B$8:$B$95,$A$8:$A$95,4,1,1),"") | G18: =IFERROR(F18-forecast.ets.confint($A18,$B$8:$B$95,$A$8:$A$95,0.95,4,1,1),"") | H18: =IFERROR(F18+forecast.ets.confint($A18,$B$8:$B$95,$A$8:$A$95,0.95,4,1,1),"") | J18: 2018 | K18: =IFERROR(AVERAGEIFS($B$8:$B$95,$A$8:$A$95,">="&DATE(J18,1,1),$A$8:$A$95,"<="&DATE(J18,12,31)),"") | L18: =IFERROR(K18/K17-1,"") | M18: =IFERROR(AVERAGEIFS($F$8:$F$95,$A$8:$A$95,">="&DATE(J18,1,1),$A$8:$A$95,"<="&DATE(J18,12,31)),"")
A19: 40452 | B19: =IFERROR(haverdata(Codes!$D$8,$A19),"") | C19: =IFERROR(B19/B18-1,"") | D19: =IFERROR(B19/B15-1,"") | E19: =IFERROR(IF(B19="",IFERROR(GROWTH($B$8:$B$95,$A$8:$A$95,$A19),TREND($B$8:$B$95,$A$8:$A$95,$A19)),""),"") | F19: =IFERROR(forecast.ets($A19,$B$8:$B$95,$A$8:$A$95,4,1,1),"") | G19: =IFERROR(F19-forecast.ets.confint($A19,$B$8:$B$95,$A$8:$A$95,0.95,4,1,1),"") | H19: =IFERROR(F19+forecast.ets.confint($A19,$B$8:$B$95,$A$8:$A$95,0.95,4,1,1),"") | J19: 2019 | K19: =IFERROR(AVERAGEIFS($B$8:$B$95,$A$8:$A$95,">="&DATE(J19,1,1),$A$8:$A$95,"<="&DATE(J19,12,31)),"") | L19: =IFERROR(K19/K18-1,"") | M19: =IFERROR(AVERAGEIFS($F$8:$F$95,$A$8:$A$95,">="&DATE(J19,1,1),$A$8:$A$95,"<="&DATE(J19,12,31)),"")
A20: 40544 | B20: =IFERROR(haverdata(Codes!$D$8,$A20),"") | C20: =IFERROR(B20/B19-1,"") | D20: =IFERROR(B20/B16-1,"") | E20: =IFERROR(IF(B20="",IFERROR(GROWTH($B$8:$B$95,$A$8:$A$95,$A20),TREND($B$8:$B$95,$A$8:$A$95,$A20)),""),"") | F20: =IFERROR(forecast.ets($A20,$B$8:$B$95,$A$8:$A$95,4,1,1),"") | G20: =IFERROR(F20-forecast.ets.confint($A20,$B$8:$B$95,$A$8:$A$95,0.95,4,1,1),"") | H20: =IFERROR(F20+forecast.ets.confint($A20,$B$8:$B$95,$A$8:$A$95,0.95,4,1,1),"") | J20: 2020 | K20: =IFERROR(AVERAGEIFS($B$8:$B$95,$A$8:$A$95,">="&DATE(J20,1,1),$A$8:$A$95,"<="&DATE(J20,12,31)),"") | L20: =IFERROR(K20/K19-1,"") | M20: =IFERROR(AVERAGEIFS($F$8:$F$95,$A$8:$A$95,">="&DATE(J20,1,1),$A$8:$A$95,"<="&DATE(J20,12,31)),"")
A21: 40634 | B21: =IFERROR(haverdata(Codes!$D$8,$A21),"") | C21: =IFERROR(B21/B20-1,"") | D21: =IFERROR(B21/B17-1,"") | E21: =IFERROR(IF(B21="",IFERROR(GROWTH($B$8:$B$95,$A$8:$A$95,$A21),TREND($B$8:$B$95,$A$8:$A$95,$A21)),""),"") | F21: =IFERROR(forecast.ets($A21,$B$8:$B$95,$A$8:$A$95,4,1,1),"") | G21: =IFERROR(F21-forecast.ets.confint($A21,$B$8:$B$95,$A$8:$A$95,0.95,4,1,1),"") | H21: =IFERROR(F21+forecast.ets.confint($A21,$B$8:$B$95,$A$8:$A$95,0.95,4,1,1),"") | J21: 2021 | K21: =IFERROR(AVERAGEIFS($B$8:$B$95,$A$8:$A$95,">="&DATE(J21,1,1),$A$8:$A$95,"<="&DATE(J21,12,31)),"") | L21: =IFERROR(K21/K20-1,"") | M21: =IFERROR(AVERAGEIFS($F$8:$F$95,$A$8:$A$95,">="&DATE(J21,1,1),$A$8:$A$95,"<="&DATE(J21,12,31)),"")
A22: 40725 | B22: =IFERROR(haverdata(Codes!$D$8,$A22),"") | C22: =IFERROR(B22/B21-1,"") | D22: =IFERROR(B22/B18-1,"") | E22: =IFERROR(IF(B22="",IFERROR(GROWTH($B$8:$B$95,$A$8:$A$95,$A22),TREND($B$8:$B$95,$A$8:$A$95,$A22)),""),"") | F22: =IFERROR(forecast.ets($A22,$B$8:$B$95,$A$8:$A$95,4,1,1),"") | G22: =IFERROR(F22-forecast.ets.confint($A22,$B$8:$B$95,$A$8:$A$95,0.95,4,1,1),"") | H22: =IFERROR(F22+forecast.ets.confint($A22,$B$8:$B$95,$A$8:$A$95,0.95,4,1,1),"") | J22: 2022 | K22: =IFERROR(AVERAGEIFS($B$8:$B$95,$A$8:$A$95,">="&DATE(J22,1,1),$A$8:$A$95,"<="&DATE(J22,12,31)),"") | L22: =IFERROR(K22/K21-1,"") | M22: =IFERROR(AVERAGEIFS($F$8:$F$95,$A$8:$A$95,">="&DATE(J22,1,1),$A$8:$A$95,"<="&DATE(J22,12,31)),"")
A23: 40817 | B23: =IFERROR(haverdata(Codes!$D$8,$A23),"") | C23: =IFERROR(B23/B22-1,"") | D23: =IFERROR(B23/B19-1,"") | E23: =IFERROR(IF(B23="",IFERROR(GROWTH($B$8:$B$95,$A$8:$A$95,$A23),TREND($B$8:$B$95,$A$8:$A$95,$A23)),""),"") | F23: =IFERROR(forecast.ets($A23,$B$8:$B$95,$A$8:$A$95,4,1,1),"") | G23: =IFERROR(F23-forecast.ets.confint($A23,$B$8:$B$95,$A$8:$A$95,0.95,4,1,1),"") | H23: =IFERROR(F23+forecast.ets.confint($A23,$B$8:$B$95,$A$8:$A$95,0.95,4,1,1),"") | J23: 2023 | K23: =IFERROR(AVERAGEIFS($B$8:$B$95,$A$8:$A$95,">="&DATE(J23,1,1),$A$8:$A$95,"<="&DATE(J23,12,31)),"") | L23: =IFERROR(K23/K22-1,"") | M23: =IFERROR(AVERAGEIFS($F$8:$F$95,$A$8:$A$95,">="&DATE(J23,1,1),$A$8:$A$95,"<="&DATE(J23,12,31)),"")
... A29: 41365 | B29: =IFERROR(haverdata(Codes!$D$8,$A29),"") | C29: =IFERROR(B29/B28-1,"") | D29: =IFERROR(B29/B25-1,"") | E29: =IFERROR(IF(B29="",IFERROR(GROWTH($B$8:$B$95,$A$8:$A$95,$A29),TREND($B$8:$B$95,$A$8:$A$95,$A29)),""),"") | F29: =IFERROR(forecast.ets($A29,$B$8:$B$95,$A$8:$A$95,4,1,1),"") | G29: =IFERROR(F29-forecast.ets.confint($A29,$B$8:$B$95,$A$8:$A$95,0.95,4,1,1),"") | H29: =IFERROR(F29+forecast.ets.confint($A29,$B$8:$B$95,$A$8:$A$95,0.95,4,1,1),"") | J29: 2029 | K29: =IFERROR(AVERAGEIFS($B$8:$B$95,$A$8:$A$95,">="&DATE(J29,1,1),$A$8:$A$95,"<="&DATE(J29,12,31)),"") | L29: =IFERROR(K29/K28-1,"") | M29: =IFERROR(AVERAGEIFS($F$8:$F$95,$A$8:$A$95,">="&DATE(J29,1,1),$A$8:$A$95,"<="&DATE(J29,12,31)),"")
A30: 41456 | B30: =IFERROR(haverdata(Codes!$D$8,$A30),"") | C30: =IFERROR(B30/B29-1,"") | D30: =IFERROR(B30/B26-1,"") | E30: =IFERROR(IF(B30="",IFERROR(GROWTH($B$8:$B$95,$A$8:$A$95,$A30),TREND($B$8:$B$95,$A$8:$A$95,$A30)),""),"") | F30: =IFERROR(forecast.ets($A30,$B$8:$B$95,$A$8:$A$95,4,1,1),"") | G30: =IFERROR(F30-forecast.ets.confint($A30,$B$8:$B$95,$A$8:$A$95,0.95,4,1,1),"") | H30: =IFERROR(F30+forecast.ets.confint($A30,$B$8:$B$95,$A$8:$A$95,0.95,4,1,1),"")
A31: 41548 | B31: =IFERROR(haverdata(Codes!$D$8,$A31),"") | C31: =IFERROR(B31/B30-1,"") | D31: =IFERROR(B31/B27-1,"") | E31: =IFERROR(IF(B31="",IFERROR(GROWTH($B$8:$B$95,$A$8:$A$95,$A31),TREND($B$8:$B$95,$A$8:$A$95,$A31)),""),"") | F31: =IFERROR(forecast.ets($A31,$B$8:$B$95,$A$8:$A$95,4,1,1),"") | G31: =IFERROR(F31-forecast.ets.confint($A31,$B$8:$B$95,$A$8:$A$95,0.95,4,1,1),"") | H31: =IFERROR(F31+forecast.ets.confint($A31,$B$8:$B$95,$A$8:$A$95,0.95,4,1,1),"")
A32: 41640 | B32: =IFERROR(haverdata(Codes!$D$8,$A32),"") | C32: =IFERROR(B32/B31-1,"") | D32: =IFERROR(B32/B28-1,"") | E32: =IFERROR(IF(B32="",IFERROR(GROWTH($B$8:$B$95,$A$8:$A$95,$A32),TREND($B$8:$B$95,$A$8:$A$95,$A32)),""),"") | F32: =IFERROR(forecast.ets($A32,$B$8:$B$95,$A$8:$A$95,4,1,1),"") | G32: =IFERROR(F32-forecast.ets.confint($A32,$B$8:$B$95,$A$8:$A$95,0.95,4,1,1),"") | H32: =IFERROR(F32+forecast.ets.confint($A32,$B$8:$B$95,$A$8:$A$95,0.95,4,1,1),"")
A33: 41730 | B33: =IFERROR(haverdata(Codes!$D$8,$A33),"") | C33: =IFERROR(B33/B32-1,"") | D33: =IFERROR(B33/B29-1,"") | E33: =IFERROR(IF(B33="",IFERROR(GROWTH($B$8:$B$95,$A$8:$A$95,$A33),TREND($B$8:$B$95,$A$8:$A$95,$A33)),""),"") | F33: =IFERROR(forecast.ets($A33,$B$8:$B$95,$A$8:$A$95,4,1,1),"") | G33: =IFERROR(F33-forecast.ets.confint($A33,$B$8:$B$95,$A$8:$A$95,0.95,4,1,1),"") | H33: =IFERROR(F33+forecast.ets.confint($A33,$B$8:$B$95,$A$8:$A$95,0.95,4,1,1),"")
A34: 41821 | B34: =IFERROR(haverdata(Codes!$D$8,$A34),"") | C34: =IFERROR(B34/B33-1,"") | D34: =IFERROR(B34/B30-1,"") | E34: =IFERROR(IF(B34="",IFERROR(GROWTH($B$8:$B$95,$A$8:$A$95,$A34),TREND($B$8:$B$95,$A$8:$A$95,$A34)),""),"") | F34: =IFERROR(forecast.ets($A34,$B$8:$B$95,$A$8:$A$95,4,1,1),"") | G34: =IFERROR(F34-forecast.ets.confint($A34,$B$8:$B$95,$A$8:$A$95,0.95,4,1,1),"") | H34: =IFERROR(F34+forecast.ets.confint($A34,$B$8:$B$95,$A$8:$A$95,0.95,4,1,1),"")
A35: 41913 | B35: =IFERROR(haverdata(Codes!$D$8,$A35),"") | C35: =IFERROR(B35/B34-1,"") | D35: =IFERROR(B35/B31-1,"") | E35: =IFERROR(IF(B35="",IFERROR(GROWTH($B$8:$B$95,$A$8:$A$95,$A35),TREND($B$8:$B$95,$A$8:$A$95,$A35)),""),"") | F35: =IFERROR(forecast.ets($A35,$B$8:$B$95,$A$8:$A$95,4,1,1),"") | G35: =IFERROR(F35-forecast.ets.confint($A35,$B$8:$B$95,$A$8:$A$95,0.95,4,1,1),"") | H35: =IFERROR(F35+forecast.ets.confint($A35,$B$8:$B$95,$A$8:$A$95,0.95,4,1,1),"")
A36: 42005 | B36: =IFERROR(haverdata(Codes!$D$8,$A36),"") | C36: =IFERROR(B36/B35-1,"") | D36: =IFERROR(B36/B32-1,"") | E36: =IFERROR(IF(B36="",IFERROR(GROWTH($B$8:$B$95,$A$8:$A$95,$A36),TREND($B$8:$B$95,$A$8:$A$95,$A36)),""),"") | F36: =IFERROR(forecast.ets($A36,$B$8:$B$95,$A$8:$A$95,4,1,1),"") | G36: =IFERROR(F36-forecast.ets.confint($A36,$B$8:$B$95,$A$8:$A$95,0.95,4,1,1),"") | H36: =IFERROR(F36+forecast.ets.confint($A36,$B$8:$B$95,$A$8:$A$95,0.95,4,1,1),"")
A37: 42095 | B37: =IFERROR(haverdata(Codes!$D$8,$A37),"") | C37: =IFERROR(B37/B36-1,"") | D37: =IFERROR(B37/B33-1,"") | E37: =IFERROR(IF(B37="",IFERROR(GROWTH($B$8:$B$95,$A$8:$A$95,$A37),TREND($B$8:$B$95,$A$8:$A$95,$A37)),""),"") | F37: =IFERROR(forecast.ets($A37,$B$8:$B$95,$A$8:$A$95,4,1,1),"") | G37: =IFERROR(F37-forecast.ets.confint($A37,$B$8:$B$95,$A$8:$A$95,0.95,4,1,1),"") | H37: =IFERROR(F37+forecast.ets.confint($A37,$B$8:$B$95,$A$8:$A$95,0.95,4,1,1),"")
A38: 42186 | B38: =IFERROR(haverdata(Codes!$D$8,$A38),"") | C38: =IFERROR(B38/B37-1,"") | D38: =IFERROR(B38/B34-1,"") | E38: =IFERROR(IF(B38="",IFERROR(GROWTH($B$8:$B$95,$A$8:$A$95,$A38),TREND($B$8:$B$95,$A$8:$A$95,$A38)),""),"") | F38: =IFERROR(forecast.ets($A38,$B$8:$B$95,$A$8:$A$95,4,1,1),"") | G38: =IFERROR(F38-forecast.ets.confint($A38,$B$8:$B$95,$A$8:$A$95,0.95,4,1,1),"") | H38: =IFERROR(F38+forecast.ets.confint($A38,$B$8:$B$95,$A$8:$A$95,0.95,4,1,1),"")
A39: 42278 | B39: =IFERROR(haverdata(Codes!$D$8,$A39),"") | C39: =IFERROR(B39/B38-1,"") | D39: =IFERROR(B39/B35-1,"") | E39: =IFERROR(IF(B39="",IFERROR(GROWTH($B$8:$B$95,$A$8:$A$95,$A39),TREND($B$8:$B$95,$A$8:$A$95,$A39)),""),"") | F39: =IFERROR(forecast.ets($A39,$B$8:$B$95,$A$8:$A$95,4,1,1),"") | G39: =IFERROR(F39-forecast.ets.confint($A39,$B$8:$B$95,$A$8:$A$95,0.95,4,1,1),"") | H39: =IFERROR(F39+forecast.ets.confint($A39,$B$8:$B$95,$A$8:$A$95,0.95,4,1,1),"")
A40: 42370 | B40: =IFERROR(haverdata(Codes!$D$8,$A40),"") | C40: =IFERROR(B40/B39-1,"") | D40: =IFERROR(B40/B36-1,"") | E40: =IFERROR(IF(B40="",IFERROR(GROWTH($B$8:$B$95,$A$8:$A$95,$A40),TREND($B$8:$B$95,$A$8:$A$95,$A40)),""),"") | F40: =IFERROR(forecast.ets($A40,$B$8:$B$95,$A$8:$A$95,4,1,1),"") | G40: =IFERROR(F40-forecast.ets.confint($A40,$B$8:$B$95,$A$8:$A$95,0.95,4,1,1),"") | H40: =IFERROR(F40+forecast.ets.confint($A40,$B$8:$B$95,$A$8:$A$95,0.95,4,1,1),"")
A41: 42461 | B41: =IFERROR(haverdata(Codes!$D$8,$A41),"") | C41: =IFERROR(B41/B40-1,"") | D41: =IFERROR(B41/B37-1,"") | E41: =IFERROR(IF(B41="",IFERROR(GROWTH($B$8:$B$95,$A$8:$A$95,$A41),TREND($B$8:$B$95,$A$8:$A$95,$A41)),""),"") | F41: =IFERROR(forecast.ets($A41,$B$8:$B$95,$A$8:$A$95,4,1,1),"") | G41: =IFERROR(F41-forecast.ets.confint($A41,$B$8:$B$95,$A$8:$A$95,0.95,4,1,1),"") | H41: =IFERROR(F41+forecast.ets.confint($A41,$B$8:$B$95,$A$8:$A$95,0.95,4,1,1),"")
... A95: 47392 | B95: =IFERROR(haverdata(Codes!$D$8,$A95),"") | C95: =IFERROR(B95/B94-1,"") | D95: =IFERROR(B95/B91-1,"") | E95: =IFERROR(IF(B95="",IFERROR(GROWTH($B$8:$B$95,$A$8:$A$95,$A95),TREND($B$8:$B$95,$A$8:$A$95,$A95)),""),"") | F95: =IFERROR(forecast.ets($A95,$B$8:$B$95,$A$8:$A$95,4,1,1),"") | G95: =IFERROR(F95-forecast.ets.confint($A95,$B$8:$B$95,$A$8:$A$95,0.95,4,1,1),"") | H95: =IFERROR(F95+forecast.ets.confint($A95,$B$8:$B$95,$A$8:$A$95,0.95,4,1,1),"")
A100: =Codes!$B$9&" ["&Codes!$D$9&"] "&Codes!$F$9 -> Core CPI [IPCCORE@ARGEN] Index
A101: Aggregation: | B101: =Codes!$G$9 -> avg | D101: Notes: | E101: =Codes!$H$9 -> [VERIFY]
A102: Quarterly | J102: Annual
A103: Date | B103: Level | C103: QoQ % | D103: YoY % | E103: Linear Fcst | F103: ETS Fcst | G103: ETS Low 95% | H103: ETS High 95% | J103: Year | K103: Level | L103: YoY % | M103: Forecast
...

Sheet Fiscal
A1: Fiscal — Argentina
A2: Each block: live HaverData pulls (col B) → growth metrics → TREND + FORECAST.ETS forecasts → chart.
A4: =Codes!$B$11&" ["&Codes!$D$11&"] "&Codes!$F$11 -> Primary Fiscal Balance [SPNFBAL@ARGEN] Mn ARS
A5: Aggregation: | B5: =Codes!$G$11 -> sum | D5: Notes: | E5: =Codes!$H$11 -> Sector Publico Nacional No Financiero. [VERIFY]
A6: Quarterly | J6: Annual
A7: Date | B7: Level | C7: QoQ % | D7: YoY % | E7: Linear Fcst | F7: ETS Fcst | G7: ETS Low 95% | H7: ETS High 95% | J7: Year | K7: Level | L7: YoY % | M7: Forecast
A8: 39448 | B8: =IFERROR(haverdata(Codes!$D$11,$A8),"") | E8: =IFERROR(IF(B8="",IFERROR(GROWTH($B$8:$B$95,$A$8:$A$95,$A8),TREND($B$8:$B$95,$A$8:$A$95,$A8)),""),"") | F8: =IFERROR(forecast.ets($A8,$B$8:$B$95,$A$8:$A$95,4,1,1),"") | G8: =IFERROR(F8-forecast.ets.confint($A8,$B$8:$B$95,$A$8:$A$95,0.95,4,1,1),"") | H8: =IFERROR(F8+forecast.ets.confint($A8,$B$8:$B$95,$A$8:$A$95,0.95,4,1,1),"") | J8: 2008 | K8: =IFERROR(SUMIFS($B$8:$B$95,$A$8:$A$95,">="&DATE(J8,1,1),$A$8:$A$95,"<="&DATE(J8,12,31)),"") -> 0 | M8: =IFERROR(SUMIFS($F$8:$F$95,$A$8:$A$95,">="&DATE(J8,1,1),$A$8:$A$95,"<="&DATE(J8,12,31)),"") -> 0
A9: 39539 | B9: =IFERROR(haverdata(Codes!$D$11,$A9),"") | C9: =IFERROR(B9/B8-1,"") | E9: =IFERROR(IF(B9="",IFERROR(GROWTH($B$8:$B$95,$A$8:$A$95,$A9),TREND($B$8:$B$95,$A$8:$A$95,$A9)),""),"") | F9: =IFERROR(forecast.ets($A9,$B$8:$B$95,$A$8:$A$95,4,1,1),"") | G9: =IFERROR(F9-forecast.ets.confint($A9,$B$8:$B$95,$A$8:$A$95,0.95,4,1,1),"") | H9: =IFERROR(F9+forecast.ets.confint($A9,$B$8:$B$95,$A$8:$A$95,0.95,4,1,1),"") | J9: 2009 | K9: =IFERROR(SUMIFS($B$8:$B$95,$A$8:$A$95,">="&DATE(J9,1,1),$A$8:$A$95,"<="&DATE(J9,12,31)),"") -> 0 | L9: =IFERROR(K9/K8-1,"") | M9: =IFERROR(SUMIFS($F$8:$F$95,$A$8:$A$95,">="&DATE(J9,1,1),$A$8:$A$95,"<="&DATE(J9,12,31)),"") -> 0
A10: 39630 | B10: =IFERROR(haverdata(Codes!$D$11,$A10),"") | C10: =IFERROR(B10/B9-1,"") | E10: =IFERROR(IF(B10="",IFERROR(GROWTH($B$8:$B$95,$A$8:$A$95,$A10),TREND($B$8:$B$95,$A$8:$A$95,$A10)),""),"") | F10: =IFERROR(forecast.ets($A10,$B$8:$B$95,$A$8:$A$95,4,1,1),"") | G10: =IFERROR(F10-forecast.ets.confint($A10,$B$8:$B$95,$A$8:$A$95,0.95,4,1,1),"") | H10: =IFERROR(F10+forecast.ets.confint($A10,$B$8:$B$95,$A$8:$A$95,0.95,4,1,1),"") | J10: 2010 | K10: =IFERROR(SUMIFS($B$8:$B$95,$A$8:$A$95,">="&DATE(J10,1,1),$A$8:$A$95,"<="&DATE(J10,12,31)),"") -> 0 | L10: =IFERROR(K10/K9-1,"") | M10: =IFERROR(SUMIFS($F$8:$F$95,$A$8:$A$95,">="&DATE(J10,1,1),$A$8:$A$95,"<="&DATE(J10,12,31)),"") -> 0
A11: 39722 | B11: =IFERROR(haverdata(Codes!$D$11,$A11),"") | C11: =IFERROR(B11/B10-1,"") | E11: =IFERROR(IF(B11="",IFERROR(GROWTH($B$8:$B$95,$A$8:$A$95,$A11),TREND($B$8:$B$95,$A$8:$A$95,$A11)),""),"") | F11: =IFERROR(forecast.ets($A11,$B$8:$B$95,$A$8:$A$95,4,1,1),"") | G11: =IFERROR(F11-forecast.ets.confint($A11,$B$8:$B$95,$A$8:$A$95,0.95,4,1,1),"") | H11: =IFERROR(F11+forecast.ets.confint($A11,$B$8:$B$95,$A$8:$A$95,0.95,4,1,1),"") | J11: 2011 | K11: =IFERROR(SUMIFS($B$8:$B$95,$A$8:$A$95,">="&DATE(J11,1,1),$A$8:$A$95,"<="&DATE(J11,12,31)),"") -> 0 | L11: =IFERROR(K11/K10-1,"") | M11: =IFERROR(SUMIFS($F$8:$F$95,$A$8:$A$95,">="&DATE(J11,1,1),$A$8:$A$95,"<="&DATE(J11,12,31)),"") -> 0
A12: 39814 | B12: =IFERROR(haverdata(Codes!$D$11,$A12),"") | C12: =IFERROR(B12/B11-1,"") | D12: =IFERROR(B12/B8-1,"") | E12: =IFERROR(IF(B12="",IFERROR(GROWTH($B$8:$B$95,$A$8:$A$95,$A12),TREND($B$8:$B$95,$A$8:$A$95,$A12)),""),"") | F12: =IFERROR(forecast.ets($A12,$B$8:$B$95,$A$8:$A$95,4,1,1),"") | G12: =IFERROR(F12-forecast.ets.confint($A12,$B$8:$B$95,$A$8:$A$95,0.95,4,1,1),"") | H12: =IFERROR(F12+forecast.ets.confint($A12,$B$8:$B$95,$A$8:$A$95,0.95,4,1,1),"") | J12: 2012 | K12: =IFERROR(SUMIFS($B$8:$B$95,$A$8:$A$95,">="&DATE(J12,1,1),$A$8:$A$95,"<="&DATE(J12,12,31)),"") -> 0 | L12: =IFERROR(K12/K11-1,"") | M12: =IFERROR(SUMIFS($F$8:$F$95,$A$8:$A$95,">="&DATE(J12,1,1),$A$8:$A$95,"<="&DATE(J12,12,31)),"") -> 0
A13: 39904 | B13: =IFERROR(haverdata(Codes!$D$11,$A13),"") | C13: =IFERROR(B13/B12-1,"") | D13: =IFERROR(B13/B9-1,"") | E13: =IFERROR(IF(B13="",IFERROR(GROWTH($B$8:$B$95,$A$8:$A$95,$A13),TREND($B$8:$B$95,$A$8:$A$95,$A13)),""),"") | F13: =IFERROR(forecast.ets($A13,$B$8:$B$95,$A$8:$A$95,4,1,1),"") | G13: =IFERROR(F13-forecast.ets.confint($A13,$B$8:$B$95,$A$8:$A$95,0.95,4,1,1),"") | H13: =IFERROR(F13+forecast.ets.confint($A13,$B$8:$B$95,$A$8:$A$95,0.95,4,1,1),"") | J13: 2013 | K13: =IFERROR(SUMIFS($B$8:$B$95,$A$8:$A$95,">="&DATE(J13,1,1),$A$8:$A$95,"<="&DATE(J13,12,31)),"") -> 0 | L13: =IFERROR(K13/K12-1,"") | M13: =IFERROR(SUMIFS($F$8:$F$95,$A$8:$A$95,">="&DATE(J13,1,1),$A$8:$A$95,"<="&DATE(J13,12,31)),"") -> 0
A14: 39995 | B14: =IFERROR(haverdata(Codes!$D$11,$A14),"") | C14: =IFERROR(B14/B13-1,"") | D14: =IFERROR(B14/B10-1,"") | E14: =IFERROR(IF(B14="",IFERROR(GROWTH($B$8:$B$95,$A$8:$A$95,$A14),TREND($B$8:$B$95,$A$8:$A$95,$A14)),""),"") | F14: =IFERROR(forecast.ets($A14,$B$8:$B$95,$A$8:$A$95,4,1,1),"") | G14: =IFERROR(F14-forecast.ets.confint($A14,$B$8:$B$95,$A$8:$A$95,0.95,4,1,1),"") | H14: =IFERROR(F14+forecast.ets.confint($A14,$B$8:$B$95,$A$8:$A$95,0.95,4,1,1),"") | J14: 2014 | K14: =IFERROR(SUMIFS($B$8:$B$95,$A$8:$A$95,">="&DATE(J14,1,1),$A$8:$A$95,"<="&DATE(J14,12,31)),"") -> 0 | L14: =IFERROR(K14/K13-1,"") | M14: =IFERROR(SUMIFS($F$8:$F$95,$A$8:$A$95,">="&DATE(J14,1,1),$A$8:$A$95,"<="&DATE(J14,12,31)),"") -> 0
A15: 40087 | B15: =IFERROR(haverdata(Codes!$D$11,$A15),"") | C15: =IFERROR(B15/B14-1,"") | D15: =IFERROR(B15/B11-1,"") | E15: =IFERROR(IF(B15="",IFERROR(GROWTH($B$8:$B$95,$A$8:$A$95,$A15),TREND($B$8:$B$95,$A$8:$A$95,$A15)),""),"") | F15: =IFERROR(forecast.ets($A15,$B$8:$B$95,$A$8:$A$95,4,1,1),"") | G15: =IFERROR(F15-forecast.ets.confint($A15,$B$8:$B$95,$A$8:$A$95,0.95,4,1,1),"") | H15: =IFERROR(F15+forecast.ets.confint($A15,$B$8:$B$95,$A$8:$A$95,0.95,4,1,1),"") | J15: 2015 | K15: =IFERROR(SUMIFS($B$8:$B$95,$A$8:$A$95,">="&DATE(J15,1,1),$A$8:$A$95,"<="&DATE(J15,12,31)),"") -> 0 | L15: =IFERROR(K15/K14-1,"") | M15: =IFERROR(SUMIFS($F$8:$F$95,$A$8:$A$95,">="&DATE(J15,1,1),$A$8:$A$95,"<="&DATE(J15,12,31)),"") -> 0
A16: 40179 | B16: =IFERROR(haverdata(Codes!$D$11,$A16),"") | C16: =IFERROR(B16/B15-1,"") | D16: =IFERROR(B16/B12-1,"") | E16: =IFERROR(IF(B16="",IFERROR(GROWTH($B$8:$B$95,$A$8:$A$95,$A16),TREND($B$8:$B$95,$A$8:$A$95,$A16)),""),"") | F16: =IFERROR(forecast.ets($A16,$B$8:$B$95,$A$8:$A$95,4,1,1),"") | G16: =IFERROR(F16-forecast.ets.confint($A16,$B$8:$B$95,$A$8:$A$95,0.95,4,1,1),"") | H16: =IFERROR(F16+forecast.ets.confint($A16,$B$8:$B$95,$A$8:$A$95,0.95,4,1,1),"") | J16: 2016 | K16: =IFERROR(SUMIFS($B$8:$B$95,$A$8:$A$95,">="&DATE(J16,1,1),$A$8:$A$95,"<="&DATE(J16,12,31)),"") -> 0 | L16: =IFERROR(K16/K15-1,"") | M16: =IFERROR(SUMIFS($F$8:$F$95,$A$8:$A$95,">="&DATE(J16,1,1),$A$8:$A$95,"<="&DATE(J16,12,31)),"") -> 0
A17: 40269 | B17: =IFERROR(haverdata(Codes!$D$11,$A17),"") | C17: =IFERROR(B17/B16-1,"") | D17: =IFERROR(B17/B13-1,"") | E17: =IFERROR(IF(B17="",IFERROR(GROWTH($B$8:$B$95,$A$8:$A$95,$A17),TREND($B$8:$B$95,$A$8:$A$95,$A17)),""),"") | F17: =IFERROR(forecast.ets($A17,$B$8:$B$95,$A$8:$A$95,4,1,1),"") | G17: =IFERROR(F17-forecast.ets.confint($A17,$B$8:$B$95,$A$8:$A$95,0.95,4,1,1),"") | H17: =IFERROR(F17+forecast.ets.confint($A17,$B$8:$B$95,$A$8:$A$95,0.95,4,1,1),"") | J17: 2017 | K17: =IFERROR(SUMIFS($B$8:$B$95,$A$8:$A$95,">="&DATE(J17,1,1),$A$8:$A$95,"<="&DATE(J17,12,31)),"") -> 0 | L17: =IFERROR(K17/K16-1,"") | M17: =IFERROR(SUMIFS($F$8:$F$95,$A$8:$A$95,">="&DATE(J17,1,1),$A$8:$A$95,"<="&DATE(J17,12,31)),"") -> 0
A18: 40360 | B18: =IFERROR(haverdata(Codes!$D$11,$A18),"") | C18: =IFERROR(B18/B17-1,"") | D18: =IFERROR(B18/B14-1,"") | E18: =IFERROR(IF(B18="",IFERROR(GROWTH($B$8:$B$95,$A$8:$A$95,$A18),TREND($B$8:$B$95,$A$8:$A$95,$A18)),""),"") | F18: =IFERROR(forecast.ets($A18,$B$8:$B$95,$A$8:$A$95,4,1,1),"") | G18: =IFERROR(F18-forecast.ets.confint($A18,$B$8:$B$95,$A$8:$A$95,0.95,4,1,1),"") | H18: =IFERROR(F18+forecast.ets.confint($A18,$B$8:$B$95,$A$8:$A$95,0.95,4,1,1),"") | J18: 2018 | K18: =IFERROR(SUMIFS($B$8:$B$95,$A$8:$A$95,">="&DATE(J18,1,1),$A$8:$A$95,"<="&DATE(J18,12,31)),"") -> 0 | L18: =IFERROR(K18/K17-1,"") | M18: =IFERROR(SUMIFS($F$8:$F$95,$A$8:$A$95,">="&DATE(J18,1,1),$A$8:$A$95,"<="&DATE(J18,12,31)),"") -> 0
A19: 40452 | B19: =IFERROR(haverdata(Codes!$D$11,$A19),"") | C19: =IFERROR(B19/B18-1,"") | D19: =IFERROR(B19/B15-1,"") | E19: =IFERROR(IF(B19="",IFERROR(GROWTH($B$8:$B$95,$A$8:$A$95,$A19),TREND($B$8:$B$95,$A$8:$A$95,$A19)),""),"") | F19: =IFERROR(forecast.ets($A19,$B$8:$B$95,$A$8:$A$95,4,1,1),"") | G19: =IFERROR(F19-forecast.ets.confint($A19,$B$8:$B$95,$A$8:$A$95,0.95,4,1,1),"") | H19: =IFERROR(F19+forecast.ets.confint($A19,$B$8:$B$95,$A$8:$A$95,0.95,4,1,1),"") | J19: 2019 | K19: =IFERROR(SUMIFS($B$8:$B$95,$A$8:$A$95,">="&DATE(J19,1,1),$A$8:$A$95,"<="&DATE(J19,12,31)),"") -> 0 | L19: =IFERROR(K19/K18-1,"") | M19: =IFERROR(SUMIFS($F$8:$F$95,$A$8:$A$95,">="&DATE(J19,1,1),$A$8:$A$95,"<="&DATE(J19,12,31)),"") -> 0
A20: 40544 | B20: =IFERROR(haverdata(Codes!$D$11,$A20),"") | C20: =IFERROR(B20/B19-1,"") | D20: =IFERROR(B20/B16-1,"") | E20: =IFERROR(IF(B20="",IFERROR(GROWTH($B$8:$B$95,$A$8:$A$95,$A20),TREND($B$8:$B$95,$A$8:$A$95,$A20)),""),"") | F20: =IFERROR(forecast.ets($A20,$B$8:$B$95,$A$8:$A$95,4,1,1),"") | G20: =IFERROR(F20-forecast.ets.confint($A20,$B$8:$B$95,$A$8:$A$95,0.95,4,1,1),"") | H20: =IFERROR(F20+forecast.ets.confint($A20,$B$8:$B$95,$A$8:$A$95,0.95,4,1,1),"") | J20: 2020 | K20: =IFERROR(SUMIFS($B$8:$B$95,$A$8:$A$95,">="&DATE(J20,1,1),$A$8:$A$95,"<="&DATE(J20,12,31)),"") -> 0 | L20: =IFERROR(K20/K19-1,"") | M20: =IFERROR(SUMIFS($F$8:$F$95,$A$8:$A$95,">="&DATE(J20,1,1),$A$8:$A$95,"<="&DATE(J20,12,31)),"") -> 0
A21: 40634 | B21: =IFERROR(haverdata(Codes!$D$11,$A21),"") | C21: =IFERROR(B21/B20-1,"") | D21: =IFERROR(B21/B17-1,"") | E21: =IFERROR(IF(B21="",IFERROR(GROWTH($B$8:$B$95,$A$8:$A$95,$A21),TREND($B$8:$B$95,$A$8:$A$95,$A21)),""),"") | F21: =IFERROR(forecast.ets($A21,$B$8:$B$95,$A$8:$A$95,4,1,1),"") | G21: =IFERROR(F21-forecast.ets.confint($A21,$B$8:$B$95,$A$8:$A$95,0.95,4,1,1),"") | H21: =IFERROR(F21+forecast.ets.confint($A21,$B$8:$B$95,$A$8:$A$95,0.95,4,1,1),"") | J21: 2021 | K21: =IFERROR(SUMIFS($B$8:$B$95,$A$8:$A$95,">="&DATE(J21,1,1),$A$8:$A$95,"<="&DATE(J21,12,31)),"") -> 0 | L21: =IFERROR(K21/K20-1,"") | M21: =IFERROR(SUMIFS($F$8:$F$95,$A$8:$A$95,">="&DATE(J21,1,1),$A$8:$A$95,"<="&DATE(J21,12,31)),"") -> 0
A22: 40725 | B22: =IFERROR(haverdata(Codes!$D$11,$A22),"") | C22: =IFERROR(B22/B21-1,"") | D22: =IFERROR(B22/B18-1,"") | E22: =IFERROR(IF(B22="",IFERROR(GROWTH($B$8:$B$95,$A$8:$A$95,$A22),TREND($B$8:$B$95,$A$8:$A$95,$A22)),""),"") | F22: =IFERROR(forecast.ets($A22,$B$8:$B$95,$A$8:$A$95,4,1,1),"") | G22: =IFERROR(F22-forecast.ets.confint($A22,$B$8:$B$95,$A$8:$A$95,0.95,4,1,1),"") | H22: =IFERROR(F22+forecast.ets.confint($A22,$B$8:$B$95,$A$8:$A$95,0.95,4,1,1),"") | J22: 2022 | K22: =IFERROR(SUMIFS($B$8:$B$95,$A$8:$A$95,">="&DATE(J22,1,1),$A$8:$A$95,"<="&DATE(J22,12,31)),"") -> 0 | L22: =IFERROR(K22/K21-1,"") | M22: =IFERROR(SUMIFS($F$8:$F$95,$A$8:$A$95,">="&DATE(J22,1,1),$A$8:$A$95,"<="&DATE(J22,12,31)),"") -> 0
A23: 40817 | B23: =IFERROR(haverdata(Codes!$D$11,$A23),"") | C23: =IFERROR(B23/B22-1,"") | D23: =IFERROR(B23/B19-1,"") | E23: =IFERROR(IF(B23="",IFERROR(GROWTH($B$8:$B$95,$A$8:$A$95,$A23),TREND($B$8:$B$95,$A$8:$A$95,$A23)),""),"") | F23: =IFERROR(forecast.ets($A23,$B$8:$B$95,$A$8:$A$95,4,1,1),"") | G23: =IFERROR(F23-forecast.ets.confint($A23,$B$8:$B$95,$A$8:$A$95,0.95,4,1,1),"") | H23: =IFERROR(F23+forecast.ets.confint($A23,$B$8:$B$95,$A$8:$A$95,0.95,4,1,1),"") | J23: 2023 | K23: =IFERROR(SUMIFS($B$8:$B$95,$A$8:$A$95,">="&DATE(J23,1,1),$A$8:$A$95,"<="&DATE(J23,12,31)),"") -> 0 | L23: =IFERROR(K23/K22-1,"") | M23: =IFERROR(SUMIFS($F$8:$F$95,$A$8:$A$95,">="&DATE(J23,1,1),$A$8:$A$95,"<="&DATE(J23,12,31)),"") -> 0
... A29: 41365 | B29: =IFERROR(haverdata(Codes!$D$11,$A29),"") | C29: =IFERROR(B29/B28-1,"") | D29: =IFERROR(B29/B25-1,"") | E29: =IFERROR(IF(B29="",IFERROR(GROWTH($B$8:$B$95,$A$8:$A$95,$A29),TREND($B$8:$B$95,$A$8:$A$95,$A29)),""),"") | F29: =IFERROR(forecast.ets($A29,$B$8:$B$95,$A$8:$A$95,4,1,1),"") | G29: =IFERROR(F29-forecast.ets.confint($A29,$B$8:$B$95,$A$8:$A$95,0.95,4,1,1),"") | H29: =IFERROR(F29+forecast.ets.confint($A29,$B$8:$B$95,$A$8:$A$95,0.95,4,1,1),"") | J29: 2029 | K29: =IFERROR(SUMIFS($B$8:$B$95,$A$8:$A$95,">="&DATE(J29,1,1),$A$8:$A$95,"<="&DATE(J29,12,31)),"") -> 0 | L29: =IFERROR(K29/K28-1,"") | M29: =IFERROR(SUMIFS($F$8:$F$95,$A$8:$A$95,">="&DATE(J29,1,1),$A$8:$A$95,"<="&DATE(J29,12,31)),"") -> 0
A30: 41456 | B30: =IFERROR(haverdata(Codes!$D$11,$A30),"") | C30: =IFERROR(B30/B29-1,"") | D30: =IFERROR(B30/B26-1,"") | E30: =IFERROR(IF(B30="",IFERROR(GROWTH($B$8:$B$95,$A$8:$A$95,$A30),TREND($B$8:$B$95,$A$8:$A$95,$A30)),""),"") | F30: =IFERROR(forecast.ets($A30,$B$8:$B$95,$A$8:$A$95,4,1,1),"") | G30: =IFERROR(F30-forecast.ets.confint($A30,$B$8:$B$95,$A$8:$A$95,0.95,4,1,1),"") | H30: =IFERROR(F30+forecast.ets.confint($A30,$B$8:$B$95,$A$8:$A$95,0.95,4,1,1),"")
A31: 41548 | B31: =IFERROR(haverdata(Codes!$D$11,$A31),"") | C31: =IFERROR(B31/B30-1,"") | D31: =IFERROR(B31/B27-1,"") | E31: =IFERROR(IF(B31="",IFERROR(GROWTH($B$8:$B$95,$A$8:$A$95,$A31),TREND($B$8:$B$95,$A$8:$A$95,$A31)),""),"") | F31: =IFERROR(forecast.ets($A31,$B$8:$B$95,$A$8:$A$95,4,1,1),"") | G31: =IFERROR(F31-forecast.ets.confint($A31,$B$8:$B$95,$A$8:$A$95,0.95,4,1,1),"") | H31: =IFERROR(F31+forecast.ets.confint($A31,$B$8:$B$95,$A$8:$A$95,0.95,4,1,1),"")
A32: 41640 | B32: =IFERROR(haverdata(Codes!$D$11,$A32),"") | C32: =IFERROR(B32/B31-1,"") | D32: =IFERROR(B32/B28-1,"") | E32: =IFERROR(IF(B32="",IFERROR(GROWTH($B$8:$B$95,$A$8:$A$95,$A32),TREND($B$8:$B$95,$A$8:$A$95,$A32)),""),"") | F32: =IFERROR(forecast.ets($A32,$B$8:$B$95,$A$8:$A$95,4,1,1),"") | G32: =IFERROR(F32-forecast.ets.confint($A32,$B$8:$B$95,$A$8:$A$95,0.95,4,1,1),"") | H32: =IFERROR(F32+forecast.ets.confint($A32,$B$8:$B$95,$A$8:$A$95,0.95,4,1,1),"")
A33: 41730 | B33: =IFERROR(haverdata(Codes!$D$11,$A33),"") | C33: =IFERROR(B33/B32-1,"") | D33: =IFERROR(B33/B29-1,"") | E33: =IFERROR(IF(B33="",IFERROR(GROWTH($B$8:$B$95,$A$8:$A$95,$A33),TREND($B$8:$B$95,$A$8:$A$95,$A33)),""),"") | F33: =IFERROR(forecast.ets($A33,$B$8:$B$95,$A$8:$A$95,4,1,1),"") | G33: =IFERROR(F33-forecast.ets.confint($A33,$B$8:$B$95,$A$8:$A$95,0.95,4,1,1),"") | H33: =IFERROR(F33+forecast.ets.confint($A33,$B$8:$B$95,$A$8:$A$95,0.95,4,1,1),"")
A34: 41821 | B34: =IFERROR(haverdata(Codes!$D$11,$A34),"") | C34: =IFERROR(B34/B33-1,"") | D34: =IFERROR(B34/B30-1,"") | E34: =IFERROR(IF(B34="",IFERROR(GROWTH($B$8:$B$95,$A$8:$A$95,$A34),TREND($B$8:$B$95,$A$8:$A$95,$A34)),""),"") | F34: =IFERROR(forecast.ets($A34,$B$8:$B$95,$A$8:$A$95,4,1,1),"") | G34: =IFERROR(F34-forecast.ets.confint($A34,$B$8:$B$95,$A$8:$A$95,0.95,4,1,1),"") | H34: =IFERROR(F34+forecast.ets.confint($A34,$B$8:$B$95,$A$8:$A$95,0.95,4,1,1),"")
A35: 41913 | B35: =IFERROR(haverdata(Codes!$D$11,$A35),"") | C35: =IFERROR(B35/B34-1,"") | D35: =IFERROR(B35/B31-1,"") | E35: =IFERROR(IF(B35="",IFERROR(GROWTH($B$8:$B$95,$A$8:$A$95,$A35),TREND($B$8:$B$95,$A$8:$A$95,$A35)),""),"") | F35: =IFERROR(forecast.ets($A35,$B$8:$B$95,$A$8:$A$95,4,1,1),"") | G35: =IFERROR(F35-forecast.ets.confint($A35,$B$8:$B$95,$A$8:$A$95,0.95,4,1,1),"") | H35: =IFERROR(F35+forecast.ets.confint($A35,$B$8:$B$95,$A$8:$A$95,0.95,4,1,1),"")
A36: 42005 | B36: =IFERROR(haverdata(Codes!$D$11,$A36),"") | C36: =IFERROR(B36/B35-1,"") | D36: =IFERROR(B36/B32-1,"") | E36: =IFERROR(IF(B36="",IFERROR(GROWTH($B$8:$B$95,$A$8:$A$95,$A36),TREND($B$8:$B$95,$A$8:$A$95,$A36)),""),"") | F36: =IFERROR(forecast.ets($A36,$B$8:$B$95,$A$8:$A$95,4,1,1),"") | G36: =IFERROR(F36-forecast.ets.confint($A36,$B$8:$B$95,$A$8:$A$95,0.95,4,1,1),"") | H36: =IFERROR(F36+forecast.ets.confint($A36,$B$8:$B$95,$A$8:$A$95,0.95,4,1,1),"")
A37: 42095 | B37: =IFERROR(haverdata(Codes!$D$11,$A37),"") | C37: =IFERROR(B37/B36-1,"") | D37: =IFERROR(B37/B33-1,"") | E37: =IFERROR(IF(B37="",IFERROR(GROWTH($B$8:$B$95,$A$8:$A$95,$A37),TREND($B$8:$B$95,$A$8:$A$95,$A37)),""),"") | F37: =IFERROR(forecast.ets($A37,$B$8:$B$95,$A$8:$A$95,4,1,1),"") | G37: =IFERROR(F37-forecast.ets.confint($A37,$B$8:$B$95,$A$8:$A$95,0.95,4,1,1),"") | H37: =IFERROR(F37+forecast.ets.confint($A37,$B$8:$B$95,$A$8:$A$95,0.95,4,1,1),"")
A38: 42186 | B38: =IFERROR(haverdata(Codes!$D$11,$A38),"") | C38: =IFERROR(B38/B37-1,"") | D38: =IFERROR(B38/B34-1,"") | E38: =IFERROR(IF(B38="",IFERROR(GROWTH($B$8:$B$95,$A$8:$A$95,$A38),TREND($B$8:$B$95,$A$8:$A$95,$A38)),""),"") | F38: =IFERROR(forecast.ets($A38,$B$8:$B$95,$A$8:$A$95,4,1,1),"") | G38: =IFERROR(F38-forecast.ets.confint($A38,$B$8:$B$95,$A$8:$A$95,0.95,4,1,1),"") | H38: =IFERROR(F38+forecast.ets.confint($A38,$B$8:$B$95,$A$8:$A$95,0.95,4,1,1),"")
A39: 42278 | B39: =IFERROR(haverdata(Codes!$D$11,$A39),"") | C39: =IFERROR(B39/B38-1,"") | D39: =IFERROR(B39/B35-1,"") | E39: =IFERROR(IF(B39="",IFERROR(GROWTH($B$8:$B$95,$A$8:$A$95,$A39),TREND($B$8:$B$95,$A$8:$A$95,$A39)),""),"") | F39: =IFERROR(forecast.ets($A39,$B$8:$B$95,$A$8:$A$95,4,1,1),"") | G39: =IFERROR(F39-forecast.ets.confint($A39,$B$8:$B$95,$A$8:$A$95,0.95,4,1,1),"") | H39: =IFERROR(F39+forecast.ets.confint($A39,$B$8:$B$95,$A$8:$A$95,0.95,4,1,1),"")
A40: 42370 | B40: =IFERROR(haverdata(Codes!$D$11,$A40),"") | C40: =IFERROR(B40/B39-1,"") | D40: =IFERROR(B40/B36-1,"") | E40: =IFERROR(IF(B40="",IFERROR(GROWTH($B$8:$B$95,$A$8:$A$95,$A40),TREND($B$8:$B$95,$A$8:$A$95,$A40)),""),"") | F40: =IFERROR(forecast.ets($A40,$B$8:$B$95,$A$8:$A$95,4,1,1),"") | G40: =IFERROR(F40-forecast.ets.confint($A40,$B$8:$B$95,$A$8:$A$95,0.95,4,1,1),"") | H40: =IFERROR(F40+forecast.ets.confint($A40,$B$8:$B$95,$A$8:$A$95,0.95,4,1,1),"")
A41: 42461 | B41: =IFERROR(haverdata(Codes!$D$11,$A41),"") | C41: =IFERROR(B41/B40-1,"") | D41: =IFERROR(B41/B37-1,"") | E41: =IFERROR(IF(B41="",IFERROR(GROWTH($B$8:$B$95,$A$8:$A$95,$A41),TREND($B$8:$B$95,$A$8:$A$95,$A41)),""),"") | F41: =IFERROR(forecast.ets($A41,$B$8:$B$95,$A$8:$A$95,4,1,1),"") | G41: =IFERROR(F41-forecast.ets.confint($A41,$B$8:$B$95,$A$8:$A$95,0.95,4,1,1),"") | H41: =IFERROR(F41+forecast.ets.confint($A41,$B$8:$B$95,$A$8:$A$95,0.95,4,1,1),"")
