Workbook

Sheet Read me
B2: Argentina — balance of payments and external funding
B3: INDEC balanza de pagos, BPM6 basis, millions of US dollars. Data through 2026-Q1.
B5: What's in here
B6: Data BoP | C6: All 33 published BPM6 lines, quarterly from 2006. Blue = INDEC source. The identity and build-up check columns must read zero — they are how you know nothing has been mistyped or mis-signed.
B7: Current Account | C7: Every current-account line in three frames: quarterly, four-quarter rolling, and annual. The rolling frame is the one to read — quarterly Argentine BoP is violently seasonal (the harvest lands in Q2) and the annual frame is too slow to trade on.
B8: Financial Account | C8: The same three frames for the financial account, split into direct, portfolio, derivatives, other investment and reserve assets, each further split into what residents did with assets and what non-residents did with liabilities.
B9: Funding | C9: How the current account is actually funded. Reads down from the current account to the change in reserves, showing every source of financing in between. This is the tab that answers what builds and what dents reserves.
B10: % of GDP | C10: The four-quarter rolling frame divided by four-quarter rolling USD GDP. Scale-free, so 2006 and 2026 are comparable.
B11: Reserves | C11: The reserve-asset line on its own: quarterly, rolling, annual, and cumulated since 2006.
B12: Forecast | C12: Bull / base / bear current-account paths for 2026 and 2027, built up from the components, with the assumptions behind each and the IMF projection as a benchmark.
B14: Sign conventions — read this before using any number
B15: Financial account | C15: BPM6 net lending(+) / net borrowing(-). The financial account equals net acquisition of financial assets MINUS net incurrence of liabilities, and reserve assets sit inside it. So a NEGATIVE financial account is a net capital INFLOW. This trips people up constantly; the Funding tab restates everything in inflow-positive terms so you never have to hold it in your head.
B16: Reserve assets | C16: POSITIVE = reserves BUILT. Verified against the known years: 2019 -21,375 and 2023 -21,675 (the two big loss years), 2024 +6,093, 2025 +7,221.
B17: The identity | C17: Current account + capital account - financial account + errors and omissions = 0. It holds to machine precision in 77 of 81 quarters; the four 2016 quarters carry a residual of up to 2.1 that is internal to INDEC's own vintage.
B18: A trap in the source data | C18: The other-investment liabilities series is stored with its sign FLIPPED from Q1-2017 onward, but in natural sign before that. Column AL of the Data tab corrects for it with an explicit date test, and everything downstream uses the corrected column. If you pull this series yourself and assume one sign convention, you will silently corrupt 2006-2016.
B20: Two gaps in what INDEC publishes
B21: Investment income | C21: Investment income does not decompose into direct + portfolio + other. A fourth component — income earned ON reserve assets — is in the total but not published separately. It averages about +88mn a quarter and is always a credit. Column AN backs it out as the residual so the decomposition closes.
B22: Sector detail | C22: INDEC's API does not carry other investment split by sector (central bank, government, banks, other) or by instrument (currency and deposits, loans, trade credit). That detail exists only in the informe tecnico spreadsheets. If you need to see which sector borrowed, that is the source, not this.
B24: Source | C24: INDEC, Balanza de pagos, posicion de inversion internacional y deuda externa, MBP6, quarterly, retrieved from the official series API at apis.datos.gob.ar, dataset 160 (quarterly family 160.2). USD GDP for the ratio tab is INDEC current-price GDP converted at the BCRA Comunicacion "A" 3500 wholesale rate, period average — the same series used in the companion GDP pack.
B25: Validation | C25: Annual current account reproduces INDEC's published figures for 2023 (-22,355), 2024 (+5,891) and 2025 (-7,788), and every quarterly print from Q1-2025 to Q1-2026, to within rounding. Reserve assets reproduce 2019, 2023, 2024 and 2025 exactly. One benchmark did NOT reproduce: 2021 computes to 6,624.8 against a published 6,645 — INDEC has since revised 2021 down by 20.2, so the live series is right and the old print is stale.
B26: Provisional data | C26: INDEC marks everything from 2022 onward as provisional and has revised it more than once. Do not treat the last four years as settled.

Sheet Data BoP
B2: INDEC balance of payments, BPM6 — quarterly source data
B3: Millions of US dollars. Blue = INDEC source value. Black = formula. Check columns must read zero.
B5: Quarter | C5: Year | D5: Q | E5: CURRENT ACCOUNT | F5: Goods & services | G5: Goods balance | H5: Goods exports FOB | I5: Goods imports FOB | J5: Services balance | K5: Services credits | L5: Services debits | M5: Primary income | N5: of which: compensation | O5: Investment income | P5: Income on direct inv. | Q5: Income on portfolio | R5: Income on other inv. | S5: Secondary income | T5: CAPITAL ACCOUNT | U5: FINANCIAL ACCOUNT | V5: Direct inv. total | W5: DI assets equity | X5: DI assets debt | Y5: DI liab. equity | Z5: DI liab. debt | AA5: Portfolio total | AB5: PI assets equity | AC5: PI assets debt | AD5: PI liab. equity | AE5: PI liab. debt | AF5: Financial derivatives | AG5: Other inv. total | AH5: OI assets | AI5: OI liab. (as published) | AJ5: RESERVE ASSETS | AK5: Errors & omissions | AL5: OI liab., sign corrected | AM5: Identity check | AN5: Fin. acct build check | AO5: Income on reserves (resid.) | AP5: Nominal GDP (USD mn, qtr) | AQ5: 4q rolling GDP (USD mn)
B6: 2006-Q1 | C6: 2006 | D6: 1 | E6: 703.26687 | F6: 2691.0759 | G6: 2906.3 | H6: 9945.6 | I6: 7039.3 | J6: -215.22406 | K6: 1945.1375 | L6: 2160.3616 | M6: -2177.7489 | N6: -13.484736 | O6: -2164.2641 | P6: -1542.4722 | Q6: -715.4277 | R6: -85.475302 | S6: 189.93979 | T6: 10.4 | U6: 781.03661 | V6: -1375.7522 | W6: 377.20756 | X6: 0 | Y6: 1469.9598 | Z6: 283 | AA6: -2253.0962 | AB6: 205.538 | AC6: 541.692 | AD6: 247.06557 | AE6: 2753.2606 | AF6: -15.956819 | AG6: 11059.782 | AH6: 587.04922 | AI6: -10472.733 | AJ6: -6633.94 | AK6: 67.369736 | AL6: =IF($C6<2017,AI6,-AI6) -> -10472.733 | AM6: =E6+T6-U6+AK6 -> 0 | AN6: =V6+AA6+AF6+AG6+AJ6-U6 -> 6.3664629e-12 | AO6: =O6-P6-Q6-R6 -> 179.11111 | AP6: 52522.526
B7: 2006-Q2 | C7: 2006 | D7: 2 | E7: 1916.5945 | F7: 3803.208 | G7: 4123.5 | H7: 11980.3 | I7: 7856.8 | J7: -320.29197 | K7: 1712.9188 | L7: 2033.2108 | M7: -2159.0401 | N7: -18.373753 | O7: -2140.6663 | P7: -1514.785 | Q7: -803.74297 | R7: -51.674519 | S7: 272.42649 | T7: 39.9 | U7: 1980.8828 | V7: -672.39111 | W7: 1090.9457 | X7: 0 | Y7: 612.3368 | Z7: 1151 | AA7: -1970.5648 | AB7: -54.226 | AC7: 104.85 | AD7: 110.72396 | AE7: 1910.4648 | AF7: -32.365185 | AG7: 813.19386 | AH7: 224.66308 | AI7: -588.53078 | AJ7: 3843.01 | AK7: 24.388326 | AL7: =IF($C7<2017,AI7,-AI7) -> -588.53078 | AM7: =E7+T7-U7+AK7 -> 4.5119464e-13 | AN7: =V7+AA7+AF7+AG7+AJ7-U7 -> 0 | AO7: =O7-P7-Q7-R7 -> 229.53616 | AP7: 59326.411
B8: 2006-Q3 | C8: 2006 | D8: 3 | E8: 1516.8665 | F8: 2986.876 | G8: 3255.5 | H8: 12126.8 | I8: 8871.3 | J8: -268.62401 | K8: 1898.8544 | L8: 2167.4784 | M8: -1690.7436 | N8: -15.609485 | O8: -1675.1341 | P8: -1220.3751 | Q8: -700.76873 | R8: -27.196085 | S8: 220.73404 | T8: 45.430412 | U8: 1232.3861 | V8: -1116.8668 | W8: 424.95187 | X8: 0 | Y8: 1653.8187 | Z8: -112 | AA8: -802.52817 | AB8: 122.74 | AC8: 59.778 | AD8: 132.1497 | AE8: 852.89648 | AF8: -37.995426 | AG8: 659.8165 | AH8: 421.67896 | AI8: -238.13754 | AJ8: 2529.96 | AK8: -329.91081 | AL8: =IF($C8<2017,AI8,-AI8) -> -238.13754 | AM8: =E8+T8-U8+AK8 -> 0 | AN8: =V8+AA8+AF8+AG8+AJ8-U8 -> 0 | AO8: =O8-P8-Q8-R8 -> 273.20583 | AP8: 59067.254
B9: 2006-Q4 | C9: 2006 | D9: 4 | E9: 2362.0747 | F9: 3785.4826 | G9: 3744.3 | H9: 12564.8 | I9: 8820.5 | J9: 41.182608 | K9: 2354.1044 | L9: 2312.9218 | M9: -1695.0775 | N9: -13.631065 | O9: -1681.4464 | P9: -1199.1867 | Q9: -772.49442 | R9: -17.558833 | S9: 271.66961 | T9: 1.8939157 | U9: 3486.1254 | V9: 66.383086 | W9: 545.61561 | X9: 0 | Y9: 1538.2325 | Z9: -1059 | AA9: -2213.2076 | AB9: 127.706 | AC9: 152.9156 | AD9: 216.7165 | AE9: 2277.1127 | AF9: 212.96197 | AG9: 1629.188 | AH9: 2007.1773 | AI9: 377.98928 | AJ9: 3790.8 | AK9: 1122.1568 | AL9: =IF($C9<2017,AI9,-AI9) -> 377.98928 | AM9: =E9+T9-U9+AK9 -> 0 | AN9: =V9+AA9+AF9+AG9+AJ9-U9 -> 0 | AO9: =O9-P9-Q9-R9 -> 307.79351 | AP9: 61950.301 | AQ9: =SUM(AP6:AP9) -> 232866.49
B10: 2007-Q1 | C10: 2007 | D10: 1 | E10: 601.80209 | F10: 2327.7692 | G10: 2424.5 | H10: 11178.1 | I10: 8753.6 | J10: -96.730777 | K10: 2600.1297 | L10: 2696.8605 | M10: -1957.6619 | N10: -17.718326 | O10: -1939.9436 | P10: -1443.2163 | Q10: -829.19126 | R10: -29.5053 | S10: 231.69475 | T10: 11.5 | U10: 1476.2968 | V10: -717.42879 | W10: 409.62905 | X10: 0 | Y10: 425.75946 | Z10: 701.29838 | AA10: -2299.2615 | AB10: 257.825 | AC10: 14.9075 | AD10: 549.90636 | AE10: 2022.0877 | AF10: 7.8881731 | AG10: -174.59106 | AH10: 398.64055 | AI10: 573.23161 | AJ10: 4659.69 | AK10: 862.99469 | AL10: =IF($C10<2017,AI10,-AI10) -> 573.23161 | AM10: =E10+T10-U10+AK10 -> 0 | AN10: =V10+AA10+AF10+AG10+AJ10-U10 -> 0 | AO10: =O10-P10-Q10-R10 -> 361.96932 | AP10: 62530.88 | AQ10: =SUM(AP7:AP10) -> 242874.85
B11: 2007-Q2 | C11: 2007 | D11: 2 | E11: 2026.1906 | F11: 3622.2503 | G11: 3984.2 | H11: 13693.2 | I11: 9709 | J11: -361.94967 | K11: 2154.1852 | L11: 2516.1349 | M11: -1881.3289 | N11: -15.892115 | O11: -1865.4368 | P11: -1416.4047 | Q11: -857.36352 | R11: -42.155252 | S11: 285.26918 | T11: 6.6831964 | U11: 961.59229 | V11: -702.35407 | W11: 397.46312 | X11: 0 | Y11: 502.60256 | Z11: 597.21464 | AA11: -5662.7037 | AB11: 398.552 | AC11: -192.7557 | AD11: 594.93145 | AE11: 5273.5686 | AF11: 26.852836 | AG11: 960.15724 | AH11: 1776.4563 | AI11: 816.29904 | AJ11: 6339.64 | AK11: -1071.2815 | AL11: =IF($C11<2017,AI11,-AI11) -> 816.29904 | AM11: =E11+T11-U11+AK11 -> 0 | AN11: =V11+AA11+AF11+AG11+AJ11-U11 -> 0 | AO11: =O11-P11-Q11-R11 -> 450.48669 | AP11: 73317.957 | AQ11: =SUM(AP8:AP11) -> 256866.39
B12: 2007-Q3 | C12: 2007 | D12: 3 | E12: 449.26483 | F12: 1863.7897 | G12: 2346.262 | H12: 14388.562 | I12: 12042.3 | J12: -482.47226 | K12: 2321.4119 | L12: 2803.8841 | M12: -1665.6199 | N12: -19.473336 | O12: -1646.1466 | P12: -1294.3058 | Q12: -823.4659 | R12: -25.805467 | S12: 251.09502 | T12: 102.21072 | U12: 696.76192 | V12: -1530.032 | W12: 361.66316 | X12: 0 | Y12: 1460.4957 | Z12: 431.19949 | AA12: 1488.8172 | AB12: 245.997 | AC12: -31.229 | AD12: 228.47213 | AE12: -1502.5213 | AF12: -17.9536 | AG12: 1597.6804 | AH12: 4161.8946 | AI12: 2564.2142 | AJ12: -841.75 | AK12: 145.28638 | AL12: =IF($C12<2017,AI12,-AI12) -> 2564.2142 | AM12: =E12+T12-U12+AK12 -> 0 | AN12: =V12+AA12+AF12+AG12+AJ12-U12 -> 0 | AO12: =O12-P12-Q12-R12 -> 497.43057 | AP12: 72852.009 | AQ12: =SUM(AP9:AP12) -> 270651.15
B13: 2007-Q4 | C13: 2007 | D13: 4 | E13: 2971.2804 | F13: 4756.7707 | G13: 4797.1 | H13: 16816.7 | I13: 12019.6 | J13: -40.329315 | K13: 2970.0097 | L13: 3010.3391 | M13: -2090.045 | N13: -19.383139 | O13: -2070.6619 | P13: -1643.9381 | Q13: -768.97376 | R13: -147.08146 | S13: 304.55473 | T13: 0.751977 | U13: 2764.7959 | V13: -2019.1099 | W13: 335.47763 | X13: 0 | Y13: 2238.6632 | Z13: 115.92433 | AA13: -994.81481 | AB13: 486.984 | AC13: -6.732 | AD13: 411.62508 | AE13: 1063.4417 | AF13: 547.8 | AG13: 2298.7806 | AH13: 4219.682 | AI13: 1920.9014 | AJ13: 2932.14 | AK13: -207.23652 | AL13: =IF($C13<2017,AI13,-AI13) -> 1920.9014 | AM13: =E13+T13-U13+AK13 -> 0 | AN13: =V13+AA13+AF13+AG13+AJ13-U13 -> 0 | AO13: =O13-P13-Q13-R13 -> 489.33151 | AP13: 79085.289 | AQ13: =SUM(AP10:AP13) -> 287786.14
B14: 2008-Q1 | C14: 2008 | D14: 1 | E14: 1323.2146 | F14: 3303.6277 | G14: 3860.4 | H14: 16067.5 | I14: 12207.1 | J14: -556.77226 | K14: 2943.9976 | L14: 3500.7698 | M14: -2254.5385 | N14: -12.769577 | O14: -2241.7689 | P14: -1770.1325 | Q14: -797.86913 | R14: -121.01397 | S14: 274.1253 | T14: 43.631 | U14: 2610.9358 | V14: -3137.0014 | W14: 346.00328 | X14: 0 | Y14: 1537.4968 | Z14: 1945.5079 | AA14: 1033.6156 | AB14: 130.501 | AC14: 583.686 | AD14: -92.909673 | AE14: -226.51895 | AF14: -12.4 | AG14: 1192.5116 | AH14: 2617.8398 | AI14: 1425.3282 | AJ14: 3534.21 | AK14: 1244.0903 | AL14: =IF($C14<2017,AI14,-AI14) -> 1425.3282 | AM14: =E14+T14-U14+AK14 -> 0 | AN14: =V14+AA14+AF14+AG14+AJ14-U14 -> 0 | AO14: =O14-P14-Q14-R14 -> 447.24671 | AP14: 81874.729 | AQ14: =SUM(AP11:AP14) -> 307129.98
B15: 2008-Q2 | C15: 2008 | D15: 2 | E15: 319.25979 | F15: 2235.4626 | G15: 2942.3 | H15: 17526.3 | I15: 14584 | J15: -706.83744 | K15: 2579.4281 | L15: 3286.2656 | M15: -2229.8294 | N15: -15.403454 | O15: -2214.426 | P15: -1575.9096 | Q15: -866.31909 | R15: -160.93806 | S15: 313.62666 | T15: 14.751145 | U15: -667.96176 | V15: -1946.1919 | W15: 318.61091 | X15: 0 | Y15: 329.71942 | Z15: 1935.0834 | AA15: 2143.6934 | AB15: 669.137 | AC15: 18.489 | AD15: -202.87302 | AE15: -1253.1944 | AF15: 59.9 | AG15: 1695.5768 | AH15: 5196.4462 | AI15: 3500.8695 | AJ15: -2620.94 | AK15: -1001.9727 | AL15: =IF($C15<2017,AI15,-AI15) -> 3500.8695 | AM15: =E15+T15-U15+AK15 -> 0 | AN15: =V15+AA15+AF15+AG15+AJ15-U15 -> 0 | AO15: =O15-P15-Q15-R15 -> 388.74082 | AP15: 97237.603 | AQ15: =SUM(AP12:AP15) -> 331049.63
B16: 2008-Q3 | C16: 2008 | D16: 3 | E16: 2991.9188 | F16: 4958.9146 | G16: 5658.472 | H16: 21338.372 | I16: 15679.9 | J16: -699.55743 | K16: 2838.161 | L16: 3537.7185 | M16: -2226.4907 | N16: -17.448658 | O16: -2209.042 | P16: -1641.9865 | Q16: -740.69902 | R16: -132.02734 | S16: 259.49491 | T16: 123.8 | U16: 4535.4996 | V16: -1854.0751 | W16: 498.52132 | X16: 0 | Y16: 1906.2467 | Z16: 446.3498 | AA16: 4012.0782 | AB16: 97.261 | AC16: 1679.4657 | AD16: -58.179793 | AE16: -2177.1717 | AF16: 11.8 | AG16: 2415.1265 | AH16: 4809.1173 | AI16: 2393.9908 | AJ16: -49.43 | AK16: 1419.7808 | AL16: =IF($C16<2017,AI16,-AI16) -> 2393.9908 | AM16: =E16+T16-U16+AK16 -> 0 | AN16: =V16+AA16+AF16+AG16+AJ16-U16 -> 0 | AO16: =O16-P16-Q16-R16 -> 305.67088 | AP16: 97142.793 | AQ16: =SUM(AP13:AP16) -> 355340.41
B17: 2008-Q4 | C17: 2008 | D17: 4 | E17: 786.81315 | F17: 2842.9321 | G17: 3102.1 | H17: 15227.3 | I17: 12125.2 | J17: -259.16789 | K17: 3062.5623 | L17: 3321.7302 | M17: -2323.3321 | N17: -6.0199771 | O17: -2317.3122 | P17: -1591.5095 | Q17: -678.93522 | R17: -276.4716 | S17: 267.21319 | T17: 2.8778719 | U17: 75.48052 | V17: -1397.3501 | W17: 227.79908 | X17: 0 | Y17: 1175.4658 | Z17: 449.68337 | AA17: 689.20184 | AB17: -370.519 | AC17: -652.45685 | AD17: -176.65929 | AE17: -1535.5184 | AF17: 875.4 | AG17: 754.68881 | AH17: -382.88831 | AI17: -1137.5771 | AJ17: -846.46 | AK17: -714.2105 | AL17: =IF($C17<2017,AI17,-AI17) -> -1137.5771 | AM17: =E17+T17-U17+AK17 -> 0 | AN17: =V17+AA17+AF17+AG17+AJ17-U17 -> 0 | AO17: =O17-P17-Q17-R17 -> 229.60419 | AP17: 87623.248 | AQ17: =SUM(AP14:AP17) -> 363878.37
B18: 2009-Q1 | C18: 2009 | D18: 1 | E18: 1190.6916 | F18: 3367.8917 | G18: 3998.7 | H18: 11954.2 | I18: 7955.5 | J18: -630.80834 | K18: 2755.1961 | L18: 3386.0045 | M18: -2372.6826 | N18: -9.9565829 | O18: -2362.7261 | P18: -1760.2154 | Q18: -478.92568 | R18: -239.12318 | S18: 195.48254 | T18: 22.068297 | U18: 1063.5869 | V18: -1329.3758 | W18: 341.10497 | X18: 0 | Y18: 1974 | Z18: -303.51926 | AA18: 826.39481 | AB18: 109 | AC18: 740.44186 | AD18: -73.100388 | AE18: 96.147442 | AF18: -0.9 | AG18: 1300.3479 | AH18: 1731.6305 | AI18: 431.28262 | AJ18: 267.12 | AK18: -149.17293 | AL18: =IF($C18<2017,AI18,-AI18) -> 431.28262 | AM18: =E18+T18-U18+AK18 -> 0 | AN18: =V18+AA18+AF18+AG18+AJ18-U18 -> 0 | AO18: =O18-P18-Q18-R18 -> 115.53817 | AP18: 78497.112 | AQ18: =SUM(AP15:AP18) -> 360500.76
B19: 2009-Q2 | C19: 2009 | D19: 2 | E19: 4297.8251 | F19: 6449.4047 | G19: 6799.439 | H19: 15499.383 | I19: 8699.944 | J19: -350.03432 | K19: 2346.0162 | L19: 2696.0505 | M19: -2419.5556 | N19: -15.197304 | O19: -2404.3583 | P19: -1590.0895 | Q19: -667.8151 | R19: -248.42321 | S19: 267.97598 | T19: 0.6 | U19: 3073.7654 | V19: -581.00071 | W19: -235.17713 | X19: 0 | Y19: 533 | Z19: -187.17642 | AA19: -29.596546 | AB19: 165 | AC19: -480.54175 | AD19: 10.404173 | AE19: -296.34937 | AF19: 3.1 | AG19: 4379.9826 | AH19: 4536.052 | AI19: 156.06941 | AJ19: -698.72 | AK19: -1224.6597 | AL19: =IF($C19<2017,AI19,-AI19) -> 156.06941 | AM19: =E19+T19-U19+AK19 -> 0 | AN19: =V19+AA19+AF19+AG19+AJ19-U19 -> 0 | AO19: =O19-P19-Q19-R19 -> 101.96953 | AP19: 83898.257 | AQ19: =SUM(AP16:AP19) -> 347161.41
B20: 2009-Q3 | C20: 2009 | D20: 3 | E20: 704.7219 | F20: 3041.6864 | G20: 3764.488 | H20: 13837.668 | I20: 10073.18 | J20: -722.80164 | K20: 2313.6869 | L20: 3036.4885 | M20: -2528.8122 | N20: -21.413775 | O20: -2507.3984 | P20: -1663.9376 | Q20: -668.77588 | R20: -255.42397 | S20: 191.84776 | T20: 54.716732 | U20: 556.71391 | V20: -330.6616 | W20: 354.193 | X20: 0 | Y20: 1381 | Z20: -696.1454 | AA20: 817.14725 | AB20: 304 | AC20: -168.6982 | AD20: -54.286803 | AE20: -627.55864 | AF20: 20.4 | AG20: -1761.2617 | AH20: 367.69448 | AI20: 2128.9562 | AJ20: 1811.09 | AK20: -202.72472 | AL20: =IF($C20<2017,AI20,-AI20) -> 2128.9562 | AM20: =E20+T20-U20+AK20 -> 0 | AN20: =V20+AA20+AF20+AG20+AJ20-U20 -> 0 | AO20: =O20-P20-Q20-R20 -> 80.739055 | AP20: 82875.044 | AQ20: =SUM(AP17:AP20) -> 332893.66
... B86: 2026-Q1 | C86: 2026 | D86: 1 | E86: -1650.5258 | F86: 2311.3867 | G86: 6339.4596 | H86: 21916.049 | I86: 15576.589 | J86: -4028.0729 | K86: 5208.8695 | L86: 9236.9424 | M86: -4675.8332 | N86: -25.140044 | O86: -4650.6931 | P86: -2781.2949 | Q86: -799.5285 | R86: -1202.8977 | S86: 713.92067 | T86: 63.375631 | U86: -2398.2541 | V86: -1290.6768 | W86: 503.0621 | X86: 0 | Y86: 1913.9839 | Z86: -120.245 | AA86: 656.59172 | AB86: 397.43909 | AC86: 1046.3974 | AD86: -352.59237 | AE86: 1139.8371 | AF86: -10.350472 | AG86: -1764.4027 | AH86: -575.69209 | AI86: -1188.7106 | AJ86: 10.584206 | AK86: -811.10384 | AL86: =IF($C86<2017,AI86,-AI86) -> 1188.7106 | AM86: =E86+T86-U86+AK86 -> 0 | AN86: =V86+AA86+AF86+AG86+AJ86-U86 -> 0 | AO86: =O86-P86-Q86-R86 -> 133.02798 | AP86: 171682.28 | AQ86: =SUM(AP83:AP86) -> 684502
B88: Identity check = current account + capital account - financial account + errors and omissions. Zero except the four 2016 quarters (residual up to 2.1), which is internal to INDEC's vintage.
B89: Other-investment liabilities are published in natural sign to Q4-2016 and sign-flipped from Q1-2017. Column AL corrects for that; use AL, never AI, in any calculation. In AL a POSITIVE value is a net incurrence of liabilities, i.e. an inflow.
B90: Income on reserve assets is not published separately; it is the residual that makes investment income close. Always a credit, averaging about +88mn a quarter.
B91: Nominal GDP in USD: INDEC current-price GDP (published at annual rates, so divided by four for a true quarterly flow) converted at the period-average Com. "A" 3500 wholesale rate. Same construction as the companion GDP pack.

Sheet Current Account
B2: Current account — quarterly, four-quarter rolling and annual
B3: Millions of US dollars. Positive = credit / surplus. The rolling frame is the one to read: Argentine quarterly BoP is dominated by the Q2 harvest.
B4: Quarterly | T4: Four-quarter rolling
B5: Quarter | C5: CURRENT ACCOUNT | D5: Goods balance | E5: Exports FOB | F5: Imports FOB | G5: Services balance | H5: Services credits | I5: Services debits | J5: Primary income | K5: Compensation | L5: Investment income | M5: on direct inv. | N5: on portfolio | O5: on other inv. | P5: on reserves | Q5: Secondary income | R5: Capital account | T5: Quarter | U5: CURRENT ACCOUNT | V5: Goods balance | W5: Exports FOB | X5: Imports FOB | Y5: Services balance | Z5: Services credits | AA5: Services debits | AB5: Primary income | AC5: Compensation | AD5: Investment income | AE5: on direct inv. | AF5: on portfolio | AG5: on other inv. | AH5: on reserves | AI5: Secondary income | AJ5: Capital account
B6: ='Data BoP'!B6 -> 2006-Q1 | C6: ='Data BoP'!E6 -> 703.26687 | D6: ='Data BoP'!G6 -> 2906.3 | E6: ='Data BoP'!H6 -> 9945.6 | F6: ='Data BoP'!I6 -> 7039.3 | G6: ='Data BoP'!J6 -> -215.22406 | H6: ='Data BoP'!K6 -> 1945.1375 | I6: ='Data BoP'!L6 -> 2160.3616 | J6: ='Data BoP'!M6 -> -2177.7489 | K6: ='Data BoP'!N6 -> -13.484736 | ... O6: ='Data BoP'!R6 -> -85.475302 | P6: ='Data BoP'!AO6 -> 179.11111 | Q6: ='Data BoP'!S6 -> 189.93979 | R6: ='Data BoP'!T6 -> 10.4 | T6: ='Data BoP'!B6 -> 2006-Q1
B7: ='Data BoP'!B7 -> 2006-Q2 | C7: ='Data BoP'!E7 -> 1916.5945 | D7: ='Data BoP'!G7 -> 4123.5 | E7: ='Data BoP'!H7 -> 11980.3 | F7: ='Data BoP'!I7 -> 7856.8 | G7: ='Data BoP'!J7 -> -320.29197 | H7: ='Data BoP'!K7 -> 1712.9188 | I7: ='Data BoP'!L7 -> 2033.2108 | J7: ='Data BoP'!M7 -> -2159.0401 | K7: ='Data BoP'!N7 -> -18.373753 | ... O7: ='Data BoP'!R7 -> -51.674519 | P7: ='Data BoP'!AO7 -> 229.53616 | Q7: ='Data BoP'!S7 -> 272.42649 | R7: ='Data BoP'!T7 -> 39.9 | T7: ='Data BoP'!B7 -> 2006-Q2
B8: ='Data BoP'!B8 -> 2006-Q3 | C8: ='Data BoP'!E8 -> 1516.8665 | D8: ='Data BoP'!G8 -> 3255.5 | E8: ='Data BoP'!H8 -> 12126.8 | F8: ='Data BoP'!I8 -> 8871.3 | G8: ='Data BoP'!J8 -> -268.62401 | H8: ='Data BoP'!K8 -> 1898.8544 | I8: ='Data BoP'!L8 -> 2167.4784 | J8: ='Data BoP'!M8 -> -1690.7436 | K8: ='Data BoP'!N8 -> -15.609485 | ... O8: ='Data BoP'!R8 -> -27.196085 | P8: ='Data BoP'!AO8 -> 273.20583 | Q8: ='Data BoP'!S8 -> 220.73404 | R8: ='Data BoP'!T8 -> 45.430412 | T8: ='Data BoP'!B8 -> 2006-Q3
B9: ='Data BoP'!B9 -> 2006-Q4 | C9: ='Data BoP'!E9 -> 2362.0747 | D9: ='Data BoP'!G9 -> 3744.3 | E9: ='Data BoP'!H9 -> 12564.8 | F9: ='Data BoP'!I9 -> 8820.5 | G9: ='Data BoP'!J9 -> 41.182608 | H9: ='Data BoP'!K9 -> 2354.1044 | I9: ='Data BoP'!L9 -> 2312.9218 | J9: ='Data BoP'!M9 -> -1695.0775 | K9: ='Data BoP'!N9 -> -13.631065 | ... O9: ='Data BoP'!R9 -> -17.558833 | P9: ='Data BoP'!AO9 -> 307.79351 | Q9: ='Data BoP'!S9 -> 271.66961 | R9: ='Data BoP'!T9 -> 1.8939157 | T9: ='Data BoP'!B9 -> 2006-Q4 | U9: =('Data BoP'!E6)+('Data BoP'!E7)+('Data BoP'!E8)+('Data BoP'!E9) -> 6498.8025 | V9: =('Data BoP'!G6)+('Data BoP'!G7)+('Data BoP'!G8)+('Data BoP'!G9) -> 14029.6 | W9: =('Data BoP'!H6)+('Data BoP'!H7)+('Data BoP'!H8)+('Data BoP'!H9) -> 46617.5 | X9: =('Data BoP'!I6)+('Data BoP'!I7)+('Data BoP'!I8)+('Data BoP'!I9) -> 32587.9 | Y9: =('Data BoP'!J6)+('Data BoP'!J7)+('Data BoP'!J8)+('Data BoP'!J9) -> -762.95743 | Z9: =('Data BoP'!K6)+('Data BoP'!K7)+('Data BoP'!K8)+('Data BoP'!K9) -> 7911.0151 | AA9: =('Data BoP'!L6)+('Data BoP'!L7)+('Data BoP'!L8)+('Data BoP'!L9) -> 8673.9725 | AB9: =('Data BoP'!M6)+('Data BoP'!M7)+('Data BoP'!M8)+('Data BoP'!M9) -> -7722.61 | AC9: =('Data BoP'!N6)+('Data BoP'!N7)+('Data BoP'!N8)+('Data BoP'!N9) -> -61.099038 | ... AG9: =('Data BoP'!R6)+('Data BoP'!R7)+('Data BoP'!R8)+('Data BoP'!R9) -> -181.90474 | AH9: =('Data BoP'!AO6)+('Data BoP'!AO7)+('Data BoP'!AO8)+('Data BoP'!AO9) -> 989.6466 | AI9: =('Data BoP'!S6)+('Data BoP'!S7)+('Data BoP'!S8)+('Data BoP'!S9) -> 954.76993 | AJ9: =('Data BoP'!T6)+('Data BoP'!T7)+('Data BoP'!T8)+('Data BoP'!T9) -> 97.624328
B10: ='Data BoP'!B10 -> 2007-Q1 | C10: ='Data BoP'!E10 -> 601.80209 | D10: ='Data BoP'!G10 -> 2424.5 | E10: ='Data BoP'!H10 -> 11178.1 | F10: ='Data BoP'!I10 -> 8753.6 | G10: ='Data BoP'!J10 -> -96.730777 | H10: ='Data BoP'!K10 -> 2600.1297 | I10: ='Data BoP'!L10 -> 2696.8605 | J10: ='Data BoP'!M10 -> -1957.6619 | K10: ='Data BoP'!N10 -> -17.718326 | ... O10: ='Data BoP'!R10 -> -29.5053 | P10: ='Data BoP'!AO10 -> 361.96932 | Q10: ='Data BoP'!S10 -> 231.69475 | R10: ='Data BoP'!T10 -> 11.5 | T10: ='Data BoP'!B10 -> 2007-Q1 | U10: =('Data BoP'!E7)+('Data BoP'!E8)+('Data BoP'!E9)+('Data BoP'!E10) -> 6397.3377 | V10: =('Data BoP'!G7)+('Data BoP'!G8)+('Data BoP'!G9)+('Data BoP'!G10) -> 13547.8 | W10: =('Data BoP'!H7)+('Data BoP'!H8)+('Data BoP'!H9)+('Data BoP'!H10) -> 47850 | X10: =('Data BoP'!I7)+('Data BoP'!I8)+('Data BoP'!I9)+('Data BoP'!I10) -> 34302.2 | Y10: =('Data BoP'!J7)+('Data BoP'!J8)+('Data BoP'!J9)+('Data BoP'!J10) -> -644.46415 | Z10: =('Data BoP'!K7)+('Data BoP'!K8)+('Data BoP'!K9)+('Data BoP'!K10) -> 8566.0073 | AA10: =('Data BoP'!L7)+('Data BoP'!L8)+('Data BoP'!L9)+('Data BoP'!L10) -> 9210.4714 | AB10: =('Data BoP'!M7)+('Data BoP'!M8)+('Data BoP'!M9)+('Data BoP'!M10) -> -7502.523 | AC10: =('Data BoP'!N7)+('Data BoP'!N8)+('Data BoP'!N9)+('Data BoP'!N10) -> -65.332629 | ... AG10: =('Data BoP'!R7)+('Data BoP'!R8)+('Data BoP'!R9)+('Data BoP'!R10) -> -125.93474 | AH10: =('Data BoP'!AO7)+('Data BoP'!AO8)+('Data BoP'!AO9)+('Data BoP'!AO10) -> 1172.5048 | AI10: =('Data BoP'!S7)+('Data BoP'!S8)+('Data BoP'!S9)+('Data BoP'!S10) -> 996.52489 | AJ10: =('Data BoP'!T7)+('Data BoP'!T8)+('Data BoP'!T9)+('Data BoP'!T10) -> 98.724328
B11: ='Data BoP'!B11 -> 2007-Q2 | C11: ='Data BoP'!E11 -> 2026.1906 | D11: ='Data BoP'!G11 -> 3984.2 | E11: ='Data BoP'!H11 -> 13693.2 | F11: ='Data BoP'!I11 -> 9709 | G11: ='Data BoP'!J11 -> -361.94967 | H11: ='Data BoP'!K11 -> 2154.1852 | I11: ='Data BoP'!L11 -> 2516.1349 | J11: ='Data BoP'!M11 -> -1881.3289 | K11: ='Data BoP'!N11 -> -15.892115 | ... O11: ='Data BoP'!R11 -> -42.155252 | P11: ='Data BoP'!AO11 -> 450.48669 | Q11: ='Data BoP'!S11 -> 285.26918 | R11: ='Data BoP'!T11 -> 6.6831964 | T11: ='Data BoP'!B11 -> 2007-Q2 | U11: =('Data BoP'!E8)+('Data BoP'!E9)+('Data BoP'!E10)+('Data BoP'!E11) -> 6506.9338 | V11: =('Data BoP'!G8)+('Data BoP'!G9)+('Data BoP'!G10)+('Data BoP'!G11) -> 13408.5 | W11: =('Data BoP'!H8)+('Data BoP'!H9)+('Data BoP'!H10)+('Data BoP'!H11) -> 49562.9 | X11: =('Data BoP'!I8)+('Data BoP'!I9)+('Data BoP'!I10)+('Data BoP'!I11) -> 36154.4 | Y11: =('Data BoP'!J8)+('Data BoP'!J9)+('Data BoP'!J10)+('Data BoP'!J11) -> -686.12185 | Z11: =('Data BoP'!K8)+('Data BoP'!K9)+('Data BoP'!K10)+('Data BoP'!K11) -> 9007.2736 | AA11: =('Data BoP'!L8)+('Data BoP'!L9)+('Data BoP'!L10)+('Data BoP'!L11) -> 9693.3955 | AB11: =('Data BoP'!M8)+('Data BoP'!M9)+('Data BoP'!M10)+('Data BoP'!M11) -> -7224.8119 | AC11: =('Data BoP'!N8)+('Data BoP'!N9)+('Data BoP'!N10)+('Data BoP'!N11) -> -62.850991 | ... AG11: =('Data BoP'!R8)+('Data BoP'!R9)+('Data BoP'!R10)+('Data BoP'!R11) -> -116.41547 | AH11: =('Data BoP'!AO8)+('Data BoP'!AO9)+('Data BoP'!AO10)+('Data BoP'!AO11) -> 1393.4553 | AI11: =('Data BoP'!S8)+('Data BoP'!S9)+('Data BoP'!S10)+('Data BoP'!S11) -> 1009.3676 | AJ11: =('Data BoP'!T8)+('Data BoP'!T9)+('Data BoP'!T10)+('Data BoP'!T11) -> 65.507524
B12: ='Data BoP'!B12 -> 2007-Q3 | C12: ='Data BoP'!E12 -> 449.26483 | D12: ='Data BoP'!G12 -> 2346.262 | E12: ='Data BoP'!H12 -> 14388.562 | F12: ='Data BoP'!I12 -> 12042.3 | G12: ='Data BoP'!J12 -> -482.47226 | H12: ='Data BoP'!K12 -> 2321.4119 | I12: ='Data BoP'!L12 -> 2803.8841 | J12: ='Data BoP'!M12 -> -1665.6199 | K12: ='Data BoP'!N12 -> -19.473336 | ... O12: ='Data BoP'!R12 -> -25.805467 | P12: ='Data BoP'!AO12 -> 497.43057 | Q12: ='Data BoP'!S12 -> 251.09502 | R12: ='Data BoP'!T12 -> 102.21072 | T12: ='Data BoP'!B12 -> 2007-Q3 | U12: =('Data BoP'!E9)+('Data BoP'!E10)+('Data BoP'!E11)+('Data BoP'!E12) -> 5439.3322 | V12: =('Data BoP'!G9)+('Data BoP'!G10)+('Data BoP'!G11)+('Data BoP'!G12) -> 12499.262 | W12: =('Data BoP'!H9)+('Data BoP'!H10)+('Data BoP'!H11)+('Data BoP'!H12) -> 51824.662 | X12: =('Data BoP'!I9)+('Data BoP'!I10)+('Data BoP'!I11)+('Data BoP'!I12) -> 39325.4 | Y12: =('Data BoP'!J9)+('Data BoP'!J10)+('Data BoP'!J11)+('Data BoP'!J12) -> -899.9701 | Z12: =('Data BoP'!K9)+('Data BoP'!K10)+('Data BoP'!K11)+('Data BoP'!K12) -> 9429.8311 | AA12: =('Data BoP'!L9)+('Data BoP'!L10)+('Data BoP'!L11)+('Data BoP'!L12) -> 10329.801 | AB12: =('Data BoP'!M9)+('Data BoP'!M10)+('Data BoP'!M11)+('Data BoP'!M12) -> -7199.6883 | AC12: =('Data BoP'!N9)+('Data BoP'!N10)+('Data BoP'!N11)+('Data BoP'!N12) -> -66.714842 | ... AG12: =('Data BoP'!R9)+('Data BoP'!R10)+('Data BoP'!R11)+('Data BoP'!R12) -> -115.02485 | AH12: =('Data BoP'!AO9)+('Data BoP'!AO10)+('Data BoP'!AO11)+('Data BoP'!AO12) -> 1617.6801 | AI12: =('Data BoP'!S9)+('Data BoP'!S10)+('Data BoP'!S11)+('Data BoP'!S12) -> 1039.7286 | AJ12: =('Data BoP'!T9)+('Data BoP'!T10)+('Data BoP'!T11)+('Data BoP'!T12) -> 122.28783
B13: ='Data BoP'!B13 -> 2007-Q4 | C13: ='Data BoP'!E13 -> 2971.2804 | D13: ='Data BoP'!G13 -> 4797.1 | E13: ='Data BoP'!H13 -> 16816.7 | F13: ='Data BoP'!I13 -> 12019.6 | G13: ='Data BoP'!J13 -> -40.329315 | H13: ='Data BoP'!K13 -> 2970.0097 | I13: ='Data BoP'!L13 -> 3010.3391 | J13: ='Data BoP'!M13 -> -2090.045 | K13: ='Data BoP'!N13 -> -19.383139 | ... O13: ='Data BoP'!R13 -> -147.08146 | P13: ='Data BoP'!AO13 -> 489.33151 | Q13: ='Data BoP'!S13 -> 304.55473 | R13: ='Data BoP'!T13 -> 0.751977 | T13: ='Data BoP'!B13 -> 2007-Q4 | U13: =('Data BoP'!E10)+('Data BoP'!E11)+('Data BoP'!E12)+('Data BoP'!E13) -> 6048.5379 | V13: =('Data BoP'!G10)+('Data BoP'!G11)+('Data BoP'!G12)+('Data BoP'!G13) -> 13552.062 | W13: =('Data BoP'!H10)+('Data BoP'!H11)+('Data BoP'!H12)+('Data BoP'!H13) -> 56076.562 | X13: =('Data BoP'!I10)+('Data BoP'!I11)+('Data BoP'!I12)+('Data BoP'!I13) -> 42524.5 | Y13: =('Data BoP'!J10)+('Data BoP'!J11)+('Data BoP'!J12)+('Data BoP'!J13) -> -981.48202 | Z13: =('Data BoP'!K10)+('Data BoP'!K11)+('Data BoP'!K12)+('Data BoP'!K13) -> 10045.736 | AA13: =('Data BoP'!L10)+('Data BoP'!L11)+('Data BoP'!L12)+('Data BoP'!L13) -> 11027.219 | AB13: =('Data BoP'!M10)+('Data BoP'!M11)+('Data BoP'!M12)+('Data BoP'!M13) -> -7594.6558 | AC13: =('Data BoP'!N10)+('Data BoP'!N11)+('Data BoP'!N12)+('Data BoP'!N13) -> -72.466917 | ... AG13: =('Data BoP'!R10)+('Data BoP'!R11)+('Data BoP'!R12)+('Data BoP'!R13) -> -244.54748 | AH13: =('Data BoP'!AO10)+('Data BoP'!AO11)+('Data BoP'!AO12)+('Data BoP'!AO13) -> 1799.2181 | AI13: =('Data BoP'!S10)+('Data BoP'!S11)+('Data BoP'!S12)+('Data BoP'!S13) -> 1072.6137 | AJ13: =('Data BoP'!T10)+('Data BoP'!T11)+('Data BoP'!T12)+('Data BoP'!T13) -> 121.14589
B14: ='Data BoP'!B14 -> 2008-Q1 | C14: ='Data BoP'!E14 -> 1323.2146 | D14: ='Data BoP'!G14 -> 3860.4 | E14: ='Data BoP'!H14 -> 16067.5 | F14: ='Data BoP'!I14 -> 12207.1 | G14: ='Data BoP'!J14 -> -556.77226 | H14: ='Data BoP'!K14 -> 2943.9976 | I14: ='Data BoP'!L14 -> 3500.7698 | J14: ='Data BoP'!M14 -> -2254.5385 | K14: ='Data BoP'!N14 -> -12.769577 | ... O14: ='Data BoP'!R14 -> -121.01397 | P14: ='Data BoP'!AO14 -> 447.24671 | Q14: ='Data BoP'!S14 -> 274.1253 | R14: ='Data BoP'!T14 -> 43.631 | T14: ='Data BoP'!B14 -> 2008-Q1 | U14: =('Data BoP'!E11)+('Data BoP'!E12)+('Data BoP'!E13)+('Data BoP'!E14) -> 6769.9504 | V14: =('Data BoP'!G11)+('Data BoP'!G12)+('Data BoP'!G13)+('Data BoP'!G14) -> 14987.962 | W14: =('Data BoP'!H11)+('Data BoP'!H12)+('Data BoP'!H13)+('Data BoP'!H14) -> 60965.962 | X14: =('Data BoP'!I11)+('Data BoP'!I12)+('Data BoP'!I13)+('Data BoP'!I14) -> 45978 | Y14: =('Data BoP'!J11)+('Data BoP'!J12)+('Data BoP'!J13)+('Data BoP'!J14) -> -1441.5235 | Z14: =('Data BoP'!K11)+('Data BoP'!K12)+('Data BoP'!K13)+('Data BoP'!K14) -> 10389.604 | AA14: =('Data BoP'!L11)+('Data BoP'!L12)+('Data BoP'!L13)+('Data BoP'!L14) -> 11831.128 | AB14: =('Data BoP'!M11)+('Data BoP'!M12)+('Data BoP'!M13)+('Data BoP'!M14) -> -7891.5323 | AC14: =('Data BoP'!N11)+('Data BoP'!N12)+('Data BoP'!N13)+('Data BoP'!N14) -> -67.518168 | ... AG14: =('Data BoP'!R11)+('Data BoP'!R12)+('Data BoP'!R13)+('Data BoP'!R14) -> -336.05615 | AH14: =('Data BoP'!AO11)+('Data BoP'!AO12)+('Data BoP'!AO13)+('Data BoP'!AO14) -> 1884.4955 | AI14: =('Data BoP'!S11)+('Data BoP'!S12)+('Data BoP'!S13)+('Data BoP'!S14) -> 1115.0442 | AJ14: =('Data BoP'!T11)+('Data BoP'!T12)+('Data BoP'!T13)+('Data BoP'!T14) -> 153.27689
B15: ='Data BoP'!B15 -> 2008-Q2 | C15: ='Data BoP'!E15 -> 319.25979 | D15: ='Data BoP'!G15 -> 2942.3 | E15: ='Data BoP'!H15 -> 17526.3 | F15: ='Data BoP'!I15 -> 14584 | G15: ='Data BoP'!J15 -> -706.83744 | H15: ='Data BoP'!K15 -> 2579.4281 | I15: ='Data BoP'!L15 -> 3286.2656 | J15: ='Data BoP'!M15 -> -2229.8294 | K15: ='Data BoP'!N15 -> -15.403454 | ... O15: ='Data BoP'!R15 -> -160.93806 | P15: ='Data BoP'!AO15 -> 388.74082 | Q15: ='Data BoP'!S15 -> 313.62666 | R15: ='Data BoP'!T15 -> 14.751145 | T15: ='Data BoP'!B15 -> 2008-Q2 | U15: =('Data BoP'!E12)+('Data BoP'!E13)+('Data BoP'!E14)+('Data BoP'!E15) -> 5063.0196 | V15: =('Data BoP'!G12)+('Data BoP'!G13)+('Data BoP'!G14)+('Data BoP'!G15) -> 13946.062 | W15: =('Data BoP'!H12)+('Data BoP'!H13)+('Data BoP'!H14)+('Data BoP'!H15) -> 64799.062 | X15: =('Data BoP'!I12)+('Data BoP'!I13)+('Data BoP'!I14)+('Data BoP'!I15) -> 50853 | Y15: =('Data BoP'!J12)+('Data BoP'!J13)+('Data BoP'!J14)+('Data BoP'!J15) -> -1786.4113 | Z15: =('Data BoP'!K12)+('Data BoP'!K13)+('Data BoP'!K14)+('Data BoP'!K15) -> 10814.847 | AA15: =('Data BoP'!L12)+('Data BoP'!L13)+('Data BoP'!L14)+('Data BoP'!L15) -> 12601.259 | AB15: =('Data BoP'!M12)+('Data BoP'!M13)+('Data BoP'!M14)+('Data BoP'!M15) -> -8240.0328 | AC15: =('Data BoP'!N12)+('Data BoP'!N13)+('Data BoP'!N14)+('Data BoP'!N15) -> -67.029506 | ... AG15: =('Data BoP'!R12)+('Data BoP'!R13)+('Data BoP'!R14)+('Data BoP'!R15) -> -454.83896 | AH15: =('Data BoP'!AO12)+('Data BoP'!AO13)+('Data BoP'!AO14)+('Data BoP'!AO15) -> 1822.7496 | AI15: =('Data BoP'!S12)+('Data BoP'!S13)+('Data BoP'!S14)+('Data BoP'!S15) -> 1143.4017 | AJ15: =('Data BoP'!T12)+('Data BoP'!T13)+('Data BoP'!T14)+('Data BoP'!T15) -> 161.34484
B16: ='Data BoP'!B16 -> 2008-Q3 | C16: ='Data BoP'!E16 -> 2991.9188 | D16: ='Data BoP'!G16 -> 5658.472 | E16: ='Data BoP'!H16 -> 21338.372 | F16: ='Data BoP'!I16 -> 15679.9 | G16: ='Data BoP'!J16 -> -699.55743 | H16: ='Data BoP'!K16 -> 2838.161 | I16: ='Data BoP'!L16 -> 3537.7185 | J16: ='Data BoP'!M16 -> -2226.4907 | K16: ='Data BoP'!N16 -> -17.448658 | ... O16: ='Data BoP'!R16 -> -132.02734 | P16: ='Data BoP'!AO16 -> 305.67088 | Q16: ='Data BoP'!S16 -> 259.49491 | R16: ='Data BoP'!T16 -> 123.8 | T16: ='Data BoP'!B16 -> 2008-Q3 | U16: =('Data BoP'!E13)+('Data BoP'!E14)+('Data BoP'!E15)+('Data BoP'!E16) -> 7605.6736 | V16: =('Data BoP'!G13)+('Data BoP'!G14)+('Data BoP'!G15)+('Data BoP'!G16) -> 17258.272 | W16: =('Data BoP'!H13)+('Data BoP'!H14)+('Data BoP'!H15)+('Data BoP'!H16) -> 71748.872 | X16: =('Data BoP'!I13)+('Data BoP'!I14)+('Data BoP'!I15)+('Data BoP'!I16) -> 54490.6 | Y16: =('Data BoP'!J13)+('Data BoP'!J14)+('Data BoP'!J15)+('Data BoP'!J16) -> -2003.4964 | Z16: =('Data BoP'!K13)+('Data BoP'!K14)+('Data BoP'!K15)+('Data BoP'!K16) -> 11331.596 | AA16: =('Data BoP'!L13)+('Data BoP'!L14)+('Data BoP'!L15)+('Data BoP'!L16) -> 13335.093 | AB16: =('Data BoP'!M13)+('Data BoP'!M14)+('Data BoP'!M15)+('Data BoP'!M16) -> -8800.9035 | AC16: =('Data BoP'!N13)+('Data BoP'!N14)+('Data BoP'!N15)+('Data BoP'!N16) -> -65.004828 | ... AG16: =('Data BoP'!R13)+('Data BoP'!R14)+('Data BoP'!R15)+('Data BoP'!R16) -> -561.06083 | AH16: =('Data BoP'!AO13)+('Data BoP'!AO14)+('Data BoP'!AO15)+('Data BoP'!AO16) -> 1630.9899 | AI16: =('Data BoP'!S13)+('Data BoP'!S14)+('Data BoP'!S15)+('Data BoP'!S16) -> 1151.8016 | AJ16: =('Data BoP'!T13)+('Data BoP'!T14)+('Data BoP'!T15)+('Data BoP'!T16) -> 182.93412
B17: ='Data BoP'!B17 -> 2008-Q4 | C17: ='Data BoP'!E17 -> 786.81315 | D17: ='Data BoP'!G17 -> 3102.1 | E17: ='Data BoP'!H17 -> 15227.3 | F17: ='Data BoP'!I17 -> 12125.2 | G17: ='Data BoP'!J17 -> -259.16789 | H17: ='Data BoP'!K17 -> 3062.5623 | I17: ='Data BoP'!L17 -> 3321.7302 | J17: ='Data BoP'!M17 -> -2323.3321 | K17: ='Data BoP'!N17 -> -6.0199771 | ... O17: ='Data BoP'!R17 -> -276.4716 | P17: ='Data BoP'!AO17 -> 229.60419 | Q17: ='Data BoP'!S17 -> 267.21319 | R17: ='Data BoP'!T17 -> 2.8778719 | T17: ='Data BoP'!B17 -> 2008-Q4 | U17: =('Data BoP'!E14)+('Data BoP'!E15)+('Data BoP'!E16)+('Data BoP'!E17) -> 5421.2063 | V17: =('Data BoP'!G14)+('Data BoP'!G15)+('Data BoP'!G16)+('Data BoP'!G17) -> 15563.272 | W17: =('Data BoP'!H14)+('Data BoP'!H15)+('Data BoP'!H16)+('Data BoP'!H17) -> 70159.472 | X17: =('Data BoP'!I14)+('Data BoP'!I15)+('Data BoP'!I16)+('Data BoP'!I17) -> 54596.2 | Y17: =('Data BoP'!J14)+('Data BoP'!J15)+('Data BoP'!J16)+('Data BoP'!J17) -> -2222.335 | Z17: =('Data BoP'!K14)+('Data BoP'!K15)+('Data BoP'!K16)+('Data BoP'!K17) -> 11424.149 | AA17: =('Data BoP'!L14)+('Data BoP'!L15)+('Data BoP'!L16)+('Data BoP'!L17) -> 13646.484 | AB17: =('Data BoP'!M14)+('Data BoP'!M15)+('Data BoP'!M16)+('Data BoP'!M17) -> -9034.1907 | AC17: =('Data BoP'!N14)+('Data BoP'!N15)+('Data BoP'!N16)+('Data BoP'!N17) -> -51.641666 | ... AG17: =('Data BoP'!R14)+('Data BoP'!R15)+('Data BoP'!R16)+('Data BoP'!R17) -> -690.45097 | AH17: =('Data BoP'!AO14)+('Data BoP'!AO15)+('Data BoP'!AO16)+('Data BoP'!AO17) -> 1371.2626 | AI17: =('Data BoP'!S14)+('Data BoP'!S15)+('Data BoP'!S16)+('Data BoP'!S17) -> 1114.4601 | AJ17: =('Data BoP'!T14)+('Data BoP'!T15)+('Data BoP'!T16)+('Data BoP'!T17) -> 185.06002
B18: ='Data BoP'!B18 -> 2009-Q1 | C18: ='Data BoP'!E18 -> 1190.6916 | D18: ='Data BoP'!G18 -> 3998.7 | E18: ='Data BoP'!H18 -> 11954.2 | F18: ='Data BoP'!I18 -> 7955.5 | G18: ='Data BoP'!J18 -> -630.80834 | H18: ='Data BoP'!K18 -> 2755.1961 | I18: ='Data BoP'!L18 -> 3386.0045 | J18: ='Data BoP'!M18 -> -2372.6826 | K18: ='Data BoP'!N18 -> -9.9565829 | ... O18: ='Data BoP'!R18 -> -239.12318 | P18: ='Data BoP'!AO18 -> 115.53817 | Q18: ='Data BoP'!S18 -> 195.48254 | R18: ='Data BoP'!T18 -> 22.068297 | T18: ='Data BoP'!B18 -> 2009-Q1 | U18: =('Data BoP'!E15)+('Data BoP'!E16)+('Data BoP'!E17)+('Data BoP'!E18) -> 5288.6833 | V18: =('Data BoP'!G15)+('Data BoP'!G16)+('Data BoP'!G17)+('Data BoP'!G18) -> 15701.572 | W18: =('Data BoP'!H15)+('Data BoP'!H16)+('Data BoP'!H17)+('Data BoP'!H18) -> 66046.172 | X18: =('Data BoP'!I15)+('Data BoP'!I16)+('Data BoP'!I17)+('Data BoP'!I18) -> 50344.6 | Y18: =('Data BoP'!J15)+('Data BoP'!J16)+('Data BoP'!J17)+('Data BoP'!J18) -> -2296.3711 | Z18: =('Data BoP'!K15)+('Data BoP'!K16)+('Data BoP'!K17)+('Data BoP'!K18) -> 11235.348 | AA18: =('Data BoP'!L15)+('Data BoP'!L16)+('Data BoP'!L17)+('Data BoP'!L18) -> 13531.719 | AB18: =('Data BoP'!M15)+('Data BoP'!M16)+('Data BoP'!M17)+('Data BoP'!M18) -> -9152.3349 | AC18: =('Data BoP'!N15)+('Data BoP'!N16)+('Data BoP'!N17)+('Data BoP'!N18) -> -48.828671 | ... AG18: =('Data BoP'!R15)+('Data BoP'!R16)+('Data BoP'!R17)+('Data BoP'!R18) -> -808.56017 | AH18: =('Data BoP'!AO15)+('Data BoP'!AO16)+('Data BoP'!AO17)+('Data BoP'!AO18) -> 1039.5541 | AI18: =('Data BoP'!S15)+('Data BoP'!S16)+('Data BoP'!S17)+('Data BoP'!S18) -> 1035.8173 | AJ18: =('Data BoP'!T15)+('Data BoP'!T16)+('Data BoP'!T17)+('Data BoP'!T18) -> 163.49731
B19: ='Data BoP'!B19 -> 2009-Q2 | C19: ='Data BoP'!E19 -> 4297.8251 | D19: ='Data BoP'!G19 -> 6799.439 | E19: ='Data BoP'!H19 -> 15499.383 | F19: ='Data BoP'!I19 -> 8699.944 | G19: ='Data BoP'!J19 -> -350.03432 | H19: ='Data BoP'!K19 -> 2346.0162 | I19: ='Data BoP'!L19 -> 2696.0505 | J19: ='Data BoP'!M19 -> -2419.5556 | K19: ='Data BoP'!N19 -> -15.197304 | ... O19: ='Data BoP'!R19 -> -248.42321 | P19: ='Data BoP'!AO19 -> 101.96953 | Q19: ='Data BoP'!S19 -> 267.97598 | R19: ='Data BoP'!T19 -> 0.6 | T19: ='Data BoP'!B19 -> 2009-Q2 | U19: =('Data BoP'!E16)+('Data BoP'!E17)+('Data BoP'!E18)+('Data BoP'!E19) -> 9267.2486 | V19: =('Data BoP'!G16)+('Data BoP'!G17)+('Data BoP'!G18)+('Data BoP'!G19) -> 19558.711 | W19: =('Data BoP'!H16)+('Data BoP'!H17)+('Data BoP'!H18)+('Data BoP'!H19) -> 64019.255 | X19: =('Data BoP'!I16)+('Data BoP'!I17)+('Data BoP'!I18)+('Data BoP'!I19) -> 44460.544 | Y19: =('Data BoP'!J16)+('Data BoP'!J17)+('Data BoP'!J18)+('Data BoP'!J19) -> -1939.568 | Z19: =('Data BoP'!K16)+('Data BoP'!K17)+('Data BoP'!K18)+('Data BoP'!K19) -> 11001.936 | AA19: =('Data BoP'!L16)+('Data BoP'!L17)+('Data BoP'!L18)+('Data BoP'!L19) -> 12941.504 | AB19: =('Data BoP'!M16)+('Data BoP'!M17)+('Data BoP'!M18)+('Data BoP'!M19) -> -9342.061 | AC19: =('Data BoP'!N16)+('Data BoP'!N17)+('Data BoP'!N18)+('Data BoP'!N19) -> -48.622522 | ... AG19: =('Data BoP'!R16)+('Data BoP'!R17)+('Data BoP'!R18)+('Data BoP'!R19) -> -896.04533 | AH19: =('Data BoP'!AO16)+('Data BoP'!AO17)+('Data BoP'!AO18)+('Data BoP'!AO19) -> 752.78277 | AI19: =('Data BoP'!S16)+('Data BoP'!S17)+('Data BoP'!S18)+('Data BoP'!S19) -> 990.16662 | AJ19: =('Data BoP'!T16)+('Data BoP'!T17)+('Data BoP'!T18)+('Data BoP'!T19) -> 149.34617
B20: ='Data BoP'!B20 -> 2009-Q3 | C20: ='Data BoP'!E20 -> 704.7219 | D20: ='Data BoP'!G20 -> 3764.488 | E20: ='Data BoP'!H20 -> 13837.668 | F20: ='Data BoP'!I20 -> 10073.18 | G20: ='Data BoP'!J20 -> -722.80164 | H20: ='Data BoP'!K20 -> 2313.6869 | I20: ='Data BoP'!L20 -> 3036.4885 | J20: ='Data BoP'!M20 -> -2528.8122 | K20: ='Data BoP'!N20 -> -21.413775 | ... O20: ='Data BoP'!R20 -> -255.42397 | P20: ='Data BoP'!AO20 -> 80.739055 | Q20: ='Data BoP'!S20 -> 191.84776 | R20: ='Data BoP'!T20 -> 54.716732 | T20: ='Data BoP'!B20 -> 2009-Q3 | U20: =('Data BoP'!E17)+('Data BoP'!E18)+('Data BoP'!E19)+('Data BoP'!E20) -> 6980.0517 | V20: =('Data BoP'!G17)+('Data BoP'!G18)+('Data BoP'!G19)+('Data BoP'!G20) -> 17664.727 | W20: =('Data BoP'!H17)+('Data BoP'!H18)+('Data BoP'!H19)+('Data BoP'!H20) -> 56518.551 | X20: =('Data BoP'!I17)+('Data BoP'!I18)+('Data BoP'!I19)+('Data BoP'!I20) -> 38853.824 | Y20: =('Data BoP'!J17)+('Data BoP'!J18)+('Data BoP'!J19)+('Data BoP'!J20) -> -1962.8122 | Z20: =('Data BoP'!K17)+('Data BoP'!K18)+('Data BoP'!K19)+('Data BoP'!K20) -> 10477.462 | AA20: =('Data BoP'!L17)+('Data BoP'!L18)+('Data BoP'!L19)+('Data BoP'!L20) -> 12440.274 | AB20: =('Data BoP'!M17)+('Data BoP'!M18)+('Data BoP'!M19)+('Data BoP'!M20) -> -9644.3826 | AC20: =('Data BoP'!N17)+('Data BoP'!N18)+('Data BoP'!N19)+('Data BoP'!N20) -> -52.587638 | ... AG20: =('Data BoP'!R17)+('Data BoP'!R18)+('Data BoP'!R19)+('Data BoP'!R20) -> -1019.442 | AH20: =('Data BoP'!AO17)+('Data BoP'!AO18)+('Data BoP'!AO19)+('Data BoP'!AO20) -> 527.85094 | AI20: =('Data BoP'!S17)+('Data BoP'!S18)+('Data BoP'!S19)+('Data BoP'!S20) -> 922.51947 | AJ20: =('Data BoP'!T17)+('Data BoP'!T18)+('Data BoP'!T19)+('Data BoP'!T20) -> 80.262901
... B86: ='Data BoP'!B86 -> 2026-Q1 | C86: ='Data BoP'!E86 -> -1650.5258 | D86: ='Data BoP'!G86 -> 6339.4596 | E86: ='Data BoP'!H86 -> 21916.049 | F86: ='Data BoP'!I86 -> 15576.589 | G86: ='Data BoP'!J86 -> -4028.0729 | H86: ='Data BoP'!K86 -> 5208.8695 | I86: ='Data BoP'!L86 -> 9236.9424 | J86: ='Data BoP'!M86 -> -4675.8332 | K86: ='Data BoP'!N86 -> -25.140044 | ... O86: ='Data BoP'!R86 -> -1202.8977 | P86: ='Data BoP'!AO86 -> 133.02798 | Q86: ='Data BoP'!S86 -> 713.92067 | R86: ='Data BoP'!T86 -> 63.375631 | T86: ='Data BoP'!B86 -> 2026-Q1 | U86: =('Data BoP'!E83)+('Data BoP'!E84)+('Data BoP'!E85)+('Data BoP'!E86) -> -4281.0987 | V86: =('Data BoP'!G83)+('Data BoP'!G84)+('Data BoP'!G85)+('Data BoP'!G86) -> 19638.654 | W86: =('Data BoP'!H83)+('Data BoP'!H84)+('Data BoP'!H85)+('Data BoP'!H86) -> 90365.617 | X86: =('Data BoP'!I83)+('Data BoP'!I84)+('Data BoP'!I85)+('Data BoP'!I86) -> 70726.963 | Y86: =('Data BoP'!J83)+('Data BoP'!J84)+('Data BoP'!J85)+('Data BoP'!J86) -> -11069.201 | Z86: =('Data BoP'!K83)+('Data BoP'!K84)+('Data BoP'!K85)+('Data BoP'!K86) -> 18898.494 | AA86: =('Data BoP'!L83)+('Data BoP'!L84)+('Data BoP'!L85)+('Data BoP'!L86) -> 29967.695 | AB86: =('Data BoP'!M83)+('Data BoP'!M84)+('Data BoP'!M85)+('Data BoP'!M86) -> -15737.007 | AC86: =('Data BoP'!N83)+('Data BoP'!N84)+('Data BoP'!N85)+('Data BoP'!N86) -> -99.457177 | ... AG86: =('Data BoP'!R83)+('Data BoP'!R84)+('Data BoP'!R85)+('Data BoP'!R86) -> -4631.2247 | AH86: =('Data BoP'!AO83)+('Data BoP'!AO84)+('Data BoP'!AO85)+('Data BoP'!AO86) -> 417.21132 | AI86: =('Data BoP'!S83)+('Data BoP'!S84)+('Data BoP'!S85)+('Data BoP'!S86) -> 2886.4562 | AJ86: =('Data BoP'!T83)+('Data BoP'!T84)+('Data BoP'!T85)+('Data BoP'!T86) -> 458.3965
B89: Annual
B90: Year | C90: CURRENT ACCOUNT | D90: Goods balance | E90: Exports FOB | F90: Imports FOB | G90: Services balance | H90: Services credits | I90: Services debits | J90: Primary income | K90: Compensation | L90: Investment income | M90: on direct inv. | N90: on portfolio | O90: on other inv. | P90: on reserves | Q90: Secondary income | R90: Capital account
B91: 2006 | C91: =SUMIFS('Data BoP'!$E$6:$E$86,'Data BoP'!$C$6:$C$86,$B91) -> 6498.8025 | D91: =SUMIFS('Data BoP'!$G$6:$G$86,'Data BoP'!$C$6:$C$86,$B91) -> 14029.6 | E91: =SUMIFS('Data BoP'!$H$6:$H$86,'Data BoP'!$C$6:$C$86,$B91) -> 46617.5 | F91: =SUMIFS('Data BoP'!$I$6:$I$86,'Data BoP'!$C$6:$C$86,$B91) -> 32587.9 | G91: =SUMIFS('Data BoP'!$J$6:$J$86,'Data BoP'!$C$6:$C$86,$B91) -> -762.95743 | H91: =SUMIFS('Data BoP'!$K$6:$K$86,'Data BoP'!$C$6:$C$86,$B91) -> 7911.0151 | I91: =SUMIFS('Data BoP'!$L$6:$L$86,'Data BoP'!$C$6:$C$86,$B91) -> 8673.9725 | J91: =SUMIFS('Data BoP'!$M$6:$M$86,'Data BoP'!$C$6:$C$86,$B91) -> -7722.61 | K91: =SUMIFS('Data BoP'!$N$6:$N$86,'Data BoP'!$C$6:$C$86,$B91) -> -61.099038 | L91: =SUMIFS('Data BoP'!$O$6:$O$86,'Data BoP'!$C$6:$C$86,$B91) -> -7661.5109 | M91: =SUMIFS('Data BoP'!$P$6:$P$86,'Data BoP'!$C$6:$C$86,$B91) -> -5476.819 | N91: =SUMIFS('Data BoP'!$Q$6:$Q$86,'Data BoP'!$C$6:$C$86,$B91) -> -2992.4338 | O91: =SUMIFS('Data BoP'!$R$6:$R$86,'Data BoP'!$C$6:$C$86,$B91) -> -181.90474 | P91: =SUMIFS('Data BoP'!$AO$6:$AO$86,'Data BoP'!$C$6:$C$86,$B91) -> 989.6466 | Q91: =SUMIFS('Data BoP'!$S$6:$S$86,'Data BoP'!$C$6:$C$86,$B91) -> 954.76993 | R91: =SUMIFS('Data BoP'!$T$6:$T$86,'Data BoP'!$C$6:$C$86,$B91) -> 97.624328
B92: 2007 | C92: =SUMIFS('Data BoP'!$E$6:$E$86,'Data BoP'!$C$6:$C$86,$B92) -> 6048.5379 | D92: =SUMIFS('Data BoP'!$G$6:$G$86,'Data BoP'!$C$6:$C$86,$B92) -> 13552.062 | E92: =SUMIFS('Data BoP'!$H$6:$H$86,'Data BoP'!$C$6:$C$86,$B92) -> 56076.562 | F92: =SUMIFS('Data BoP'!$I$6:$I$86,'Data BoP'!$C$6:$C$86,$B92) -> 42524.5 | G92: =SUMIFS('Data BoP'!$J$6:$J$86,'Data BoP'!$C$6:$C$86,$B92) -> -981.48202 | H92: =SUMIFS('Data BoP'!$K$6:$K$86,'Data BoP'!$C$6:$C$86,$B92) -> 10045.736 | I92: =SUMIFS('Data BoP'!$L$6:$L$86,'Data BoP'!$C$6:$C$86,$B92) -> 11027.219 | J92: =SUMIFS('Data BoP'!$M$6:$M$86,'Data BoP'!$C$6:$C$86,$B92) -> -7594.6558 | K92: =SUMIFS('Data BoP'!$N$6:$N$86,'Data BoP'!$C$6:$C$86,$B92) -> -72.466917 | L92: =SUMIFS('Data BoP'!$O$6:$O$86,'Data BoP'!$C$6:$C$86,$B92) -> -7522.1888 | M92: =SUMIFS('Data BoP'!$P$6:$P$86,'Data BoP'!$C$6:$C$86,$B92) -> -5797.865 | N92: =SUMIFS('Data BoP'!$Q$6:$Q$86,'Data BoP'!$C$6:$C$86,$B92) -> -3278.9944 | O92: =SUMIFS('Data BoP'!$R$6:$R$86,'Data BoP'!$C$6:$C$86,$B92) -> -244.54748 | P92: =SUMIFS('Data BoP'!$AO$6:$AO$86,'Data BoP'!$C$6:$C$86,$B92) -> 1799.2181 | Q92: =SUMIFS('Data BoP'!$S$6:$S$86,'Data BoP'!$C$6:$C$86,$B92) -> 1072.6137 | R92: =SUMIFS('Data BoP'!$T$6:$T$86,'Data BoP'!$C$6:$C$86,$B92) -> 121.14589
B93: 2008 | C93: =SUMIFS('Data BoP'!$E$6:$E$86,'Data BoP'!$C$6:$C$86,$B93) -> 5421.2063 | D93: =SUMIFS('Data BoP'!$G$6:$G$86,'Data BoP'!$C$6:$C$86,$B93) -> 15563.272 | E93: =SUMIFS('Data BoP'!$H$6:$H$86,'Data BoP'!$C$6:$C$86,$B93) -> 70159.472 | F93: =SUMIFS('Data BoP'!$I$6:$I$86,'Data BoP'!$C$6:$C$86,$B93) -> 54596.2 | G93: =SUMIFS('Data BoP'!$J$6:$J$86,'Data BoP'!$C$6:$C$86,$B93) -> -2222.335 | H93: =SUMIFS('Data BoP'!$K$6:$K$86,'Data BoP'!$C$6:$C$86,$B93) -> 11424.149 | I93: =SUMIFS('Data BoP'!$L$6:$L$86,'Data BoP'!$C$6:$C$86,$B93) -> 13646.484 | J93: =SUMIFS('Data BoP'!$M$6:$M$86,'Data BoP'!$C$6:$C$86,$B93) -> -9034.1907 | K93: =SUMIFS('Data BoP'!$N$6:$N$86,'Data BoP'!$C$6:$C$86,$B93) -> -51.641666 | L93: =SUMIFS('Data BoP'!$O$6:$O$86,'Data BoP'!$C$6:$C$86,$B93) -> -8982.549 | M93: =SUMIFS('Data BoP'!$P$6:$P$86,'Data BoP'!$C$6:$C$86,$B93) -> -6579.5382 | N93: =SUMIFS('Data BoP'!$Q$6:$Q$86,'Data BoP'!$C$6:$C$86,$B93) -> -3083.8225 | O93: =SUMIFS('Data BoP'!$R$6:$R$86,'Data BoP'!$C$6:$C$86,$B93) -> -690.45097 | P93: =SUMIFS('Data BoP'!$AO$6:$AO$86,'Data BoP'!$C$6:$C$86,$B93) -> 1371.2626 | Q93: =SUMIFS('Data BoP'!$S$6:$S$86,'Data BoP'!$C$6:$C$86,$B93) -> 1114.4601 | R93: =SUMIFS('Data BoP'!$T$6:$T$86,'Data BoP'!$C$6:$C$86,$B93) -> 185.06002
B94: 2009 | C94: =SUMIFS('Data BoP'!$E$6:$E$86,'Data BoP'!$C$6:$C$86,$B94) -> 7254.1157 | D94: =SUMIFS('Data BoP'!$G$6:$G$86,'Data BoP'!$C$6:$C$86,$B94) -> 18644.85 | E94: =SUMIFS('Data BoP'!$H$6:$H$86,'Data BoP'!$C$6:$C$86,$B94) -> 55790.984 | F94: =SUMIFS('Data BoP'!$I$6:$I$86,'Data BoP'!$C$6:$C$86,$B94) -> 37146.134 | G94: =SUMIFS('Data BoP'!$J$6:$J$86,'Data BoP'!$C$6:$C$86,$B94) -> -1992.0315 | H94: =SUMIFS('Data BoP'!$K$6:$K$86,'Data BoP'!$C$6:$C$86,$B94) -> 10544.621 | I94: =SUMIFS('Data BoP'!$L$6:$L$86,'Data BoP'!$C$6:$C$86,$B94) -> 12536.653 | J94: =SUMIFS('Data BoP'!$M$6:$M$86,'Data BoP'!$C$6:$C$86,$B94) -> -10318.875 | K94: =SUMIFS('Data BoP'!$N$6:$N$86,'Data BoP'!$C$6:$C$86,$B94) -> -59.357787 | L94: =SUMIFS('Data BoP'!$O$6:$O$86,'Data BoP'!$C$6:$C$86,$B94) -> -10259.517 | M94: =SUMIFS('Data BoP'!$P$6:$P$86,'Data BoP'!$C$6:$C$86,$B94) -> -7069.7925 | N94: =SUMIFS('Data BoP'!$Q$6:$Q$86,'Data BoP'!$C$6:$C$86,$B94) -> -2548.7037 | O94: =SUMIFS('Data BoP'!$R$6:$R$86,'Data BoP'!$C$6:$C$86,$B94) -> -998.42778 | P94: =SUMIFS('Data BoP'!$AO$6:$AO$86,'Data BoP'!$C$6:$C$86,$B94) -> 357.40675 | Q94: =SUMIFS('Data BoP'!$S$6:$S$86,'Data BoP'!$C$6:$C$86,$B94) -> 920.17218 | R94: =SUMIFS('Data BoP'!$T$6:$T$86,'Data BoP'!$C$6:$C$86,$B94) -> 79.984228
B95: 2010 | C95: =SUMIFS('Data BoP'!$E$6:$E$86,'Data BoP'!$C$6:$C$86,$B95) -> -1622.9959 | D95: =SUMIFS('Data BoP'!$G$6:$G$86,'Data BoP'!$C$6:$C$86,$B95) -> 14147.109 | E95: =SUMIFS('Data BoP'!$H$6:$H$86,'Data BoP'!$C$6:$C$86,$B95) -> 68305.873 | F95: =SUMIFS('Data BoP'!$I$6:$I$86,'Data BoP'!$C$6:$C$86,$B95) -> 54158.764 | G95: =SUMIFS('Data BoP'!$J$6:$J$86,'Data BoP'!$C$6:$C$86,$B95) -> -1803.5886 | H95: =SUMIFS('Data BoP'!$K$6:$K$86,'Data BoP'!$C$6:$C$86,$B95) -> 12817.143 | I95: =SUMIFS('Data BoP'!$L$6:$L$86,'Data BoP'!$C$6:$C$86,$B95) -> 14620.732 | J95: =SUMIFS('Data BoP'!$M$6:$M$86,'Data BoP'!$C$6:$C$86,$B95) -> -14547.533 | K95: =SUMIFS('Data BoP'!$N$6:$N$86,'Data BoP'!$C$6:$C$86,$B95) -> -54.723346 | L95: =SUMIFS('Data BoP'!$O$6:$O$86,'Data BoP'!$C$6:$C$86,$B95) -> -14492.81 | M95: =SUMIFS('Data BoP'!$P$6:$P$86,'Data BoP'!$C$6:$C$86,$B95) -> -11161.705 | N95: =SUMIFS('Data BoP'!$Q$6:$Q$86,'Data BoP'!$C$6:$C$86,$B95) -> -2413.1417 | O95: =SUMIFS('Data BoP'!$R$6:$R$86,'Data BoP'!$C$6:$C$86,$B95) -> -1066.902 | P95: =SUMIFS('Data BoP'!$AO$6:$AO$86,'Data BoP'!$C$6:$C$86,$B95) -> 148.93835 | Q95: =SUMIFS('Data BoP'!$S$6:$S$86,'Data BoP'!$C$6:$C$86,$B95) -> 581.01668 | R95: =SUMIFS('Data BoP'!$T$6:$T$86,'Data BoP'!$C$6:$C$86,$B95) -> 78.477885
B96: 2011 | C96: =SUMIFS('Data BoP'!$E$6:$E$86,'Data BoP'!$C$6:$C$86,$B96) -> -5340.1812 | D96: =SUMIFS('Data BoP'!$G$6:$G$86,'Data BoP'!$C$6:$C$86,$B96) -> 12350.931 | E96: =SUMIFS('Data BoP'!$H$6:$H$86,'Data BoP'!$C$6:$C$86,$B96) -> 83119.709 | F96: =SUMIFS('Data BoP'!$I$6:$I$86,'Data BoP'!$C$6:$C$86,$B96) -> 70768.778 | G96: =SUMIFS('Data BoP'!$J$6:$J$86,'Data BoP'!$C$6:$C$86,$B96) -> -3152.488 | H96: =SUMIFS('Data BoP'!$K$6:$K$86,'Data BoP'!$C$6:$C$86,$B96) -> 14496.981 | I96: =SUMIFS('Data BoP'!$L$6:$L$86,'Data BoP'!$C$6:$C$86,$B96) -> 17649.469 | J96: =SUMIFS('Data BoP'!$M$6:$M$86,'Data BoP'!$C$6:$C$86,$B96) -> -15073.067 | K96: =SUMIFS('Data BoP'!$N$6:$N$86,'Data BoP'!$C$6:$C$86,$B96) -> -45.897878 | L96: =SUMIFS('Data BoP'!$O$6:$O$86,'Data BoP'!$C$6:$C$86,$B96) -> -15027.169 | M96: =SUMIFS('Data BoP'!$P$6:$P$86,'Data BoP'!$C$6:$C$86,$B96) -> -11136.355 | N96: =SUMIFS('Data BoP'!$Q$6:$Q$86,'Data BoP'!$C$6:$C$86,$B96) -> -2744.6919 | O96: =SUMIFS('Data BoP'!$R$6:$R$86,'Data BoP'!$C$6:$C$86,$B96) -> -1227.8537 | P96: =SUMIFS('Data BoP'!$AO$6:$AO$86,'Data BoP'!$C$6:$C$86,$B96) -> 81.731558 | Q96: =SUMIFS('Data BoP'!$S$6:$S$86,'Data BoP'!$C$6:$C$86,$B96) -> 534.44286 | R96: =SUMIFS('Data BoP'!$T$6:$T$86,'Data BoP'!$C$6:$C$86,$B96) -> 62.723846
B97: 2012 | C97: =SUMIFS('Data BoP'!$E$6:$E$86,'Data BoP'!$C$6:$C$86,$B97) -> -2138.0404 | D97: =SUMIFS('Data BoP'!$G$6:$G$86,'Data BoP'!$C$6:$C$86,$B97) -> 15040.913 | E97: =SUMIFS('Data BoP'!$H$6:$H$86,'Data BoP'!$C$6:$C$86,$B97) -> 80083.655 | F97: =SUMIFS('Data BoP'!$I$6:$I$86,'Data BoP'!$C$6:$C$86,$B97) -> 65042.742 | G97: =SUMIFS('Data BoP'!$J$6:$J$86,'Data BoP'!$C$6:$C$86,$B97) -> -4097.2247 | H97: =SUMIFS('Data BoP'!$K$6:$K$86,'Data BoP'!$C$6:$C$86,$B97) -> 14247.101 | I97: =SUMIFS('Data BoP'!$L$6:$L$86,'Data BoP'!$C$6:$C$86,$B97) -> 18344.325 | J97: =SUMIFS('Data BoP'!$M$6:$M$86,'Data BoP'!$C$6:$C$86,$B97) -> -13753.841 | K97: =SUMIFS('Data BoP'!$N$6:$N$86,'Data BoP'!$C$6:$C$86,$B97) -> -62.771927 | L97: =SUMIFS('Data BoP'!$O$6:$O$86,'Data BoP'!$C$6:$C$86,$B97) -> -13691.069 | M97: =SUMIFS('Data BoP'!$P$6:$P$86,'Data BoP'!$C$6:$C$86,$B97) -> -9616.2488 | N97: =SUMIFS('Data BoP'!$Q$6:$Q$86,'Data BoP'!$C$6:$C$86,$B97) -> -2658.5003 | O97: =SUMIFS('Data BoP'!$R$6:$R$86,'Data BoP'!$C$6:$C$86,$B97) -> -1470.1735 | P97: =SUMIFS('Data BoP'!$AO$6:$AO$86,'Data BoP'!$C$6:$C$86,$B97) -> 53.85394 | Q97: =SUMIFS('Data BoP'!$S$6:$S$86,'Data BoP'!$C$6:$C$86,$B97) -> 672.1122 | R97: =SUMIFS('Data BoP'!$T$6:$T$86,'Data BoP'!$C$6:$C$86,$B97) -> 47.884045
B98: 2013 | C98: =SUMIFS('Data BoP'!$E$6:$E$86,'Data BoP'!$C$6:$C$86,$B98) -> -13124.374 | D98: =SUMIFS('Data BoP'!$G$6:$G$86,'Data BoP'!$C$6:$C$86,$B98) -> 4635.2352 | E98: =SUMIFS('Data BoP'!$H$6:$H$86,'Data BoP'!$C$6:$C$86,$B98) -> 75928.228 | F98: =SUMIFS('Data BoP'!$I$6:$I$86,'Data BoP'!$C$6:$C$86,$B98) -> 71292.993 | G98: =SUMIFS('Data BoP'!$J$6:$J$86,'Data BoP'!$C$6:$C$86,$B98) -> -5328.9161 | H98: =SUMIFS('Data BoP'!$K$6:$K$86,'Data BoP'!$C$6:$C$86,$B98) -> 13679.892 | I98: =SUMIFS('Data BoP'!$L$6:$L$86,'Data BoP'!$C$6:$C$86,$B98) -> 19008.808 | J98: =SUMIFS('Data BoP'!$M$6:$M$86,'Data BoP'!$C$6:$C$86,$B98) -> -13164.828 | K98: =SUMIFS('Data BoP'!$N$6:$N$86,'Data BoP'!$C$6:$C$86,$B98) -> -65.409421 | L98: =SUMIFS('Data BoP'!$O$6:$O$86,'Data BoP'!$C$6:$C$86,$B98) -> -13099.418 | M98: =SUMIFS('Data BoP'!$P$6:$P$86,'Data BoP'!$C$6:$C$86,$B98) -> -8978.5668 | N98: =SUMIFS('Data BoP'!$Q$6:$Q$86,'Data BoP'!$C$6:$C$86,$B98) -> -2773.2992 | O98: =SUMIFS('Data BoP'!$R$6:$R$86,'Data BoP'!$C$6:$C$86,$B98) -> -1384.8637 | P98: =SUMIFS('Data BoP'!$AO$6:$AO$86,'Data BoP'!$C$6:$C$86,$B98) -> 37.311542 | Q98: =SUMIFS('Data BoP'!$S$6:$S$86,'Data BoP'!$C$6:$C$86,$B98) -> 734.13466 | R98: =SUMIFS('Data BoP'!$T$6:$T$86,'Data BoP'!$C$6:$C$86,$B98) -> 33.412874
B99: 2014 | C99: =SUMIFS('Data BoP'!$E$6:$E$86,'Data BoP'!$C$6:$C$86,$B99) -> -9179.0263 | D99: =SUMIFS('Data BoP'!$G$6:$G$86,'Data BoP'!$C$6:$C$86,$B99) -> 5541.4698 | E99: =SUMIFS('Data BoP'!$H$6:$H$86,'Data BoP'!$C$6:$C$86,$B99) -> 68440.436 | F99: =SUMIFS('Data BoP'!$I$6:$I$86,'Data BoP'!$C$6:$C$86,$B99) -> 62898.966 | G99: =SUMIFS('Data BoP'!$J$6:$J$86,'Data BoP'!$C$6:$C$86,$B99) -> -4641.2922 | H99: =SUMIFS('Data BoP'!$K$6:$K$86,'Data BoP'!$C$6:$C$86,$B99) -> 13396.372 | I99: =SUMIFS('Data BoP'!$L$6:$L$86,'Data BoP'!$C$6:$C$86,$B99) -> 18037.664 | J99: =SUMIFS('Data BoP'!$M$6:$M$86,'Data BoP'!$C$6:$C$86,$B99) -> -11613.847 | K99: =SUMIFS('Data BoP'!$N$6:$N$86,'Data BoP'!$C$6:$C$86,$B99) -> -34.191273 | L99: =SUMIFS('Data BoP'!$O$6:$O$86,'Data BoP'!$C$6:$C$86,$B99) -> -11579.656 | M99: =SUMIFS('Data BoP'!$P$6:$P$86,'Data BoP'!$C$6:$C$86,$B99) -> -7299.5735 | N99: =SUMIFS('Data BoP'!$Q$6:$Q$86,'Data BoP'!$C$6:$C$86,$B99) -> -2938.6885 | O99: =SUMIFS('Data BoP'!$R$6:$R$86,'Data BoP'!$C$6:$C$86,$B99) -> -1358.8475 | P99: =SUMIFS('Data BoP'!$AO$6:$AO$86,'Data BoP'!$C$6:$C$86,$B99) -> 17.453245 | Q99: =SUMIFS('Data BoP'!$S$6:$S$86,'Data BoP'!$C$6:$C$86,$B99) -> 1534.6436 | R99: =SUMIFS('Data BoP'!$T$6:$T$86,'Data BoP'!$C$6:$C$86,$B99) -> 56.797105
B100: 2015 | C100: =SUMIFS('Data BoP'!$E$6:$E$86,'Data BoP'!$C$6:$C$86,$B100) -> -17621.985 | D100: =SUMIFS('Data BoP'!$G$6:$G$86,'Data BoP'!$C$6:$C$86,$B100) -> -785.17639 | E100: =SUMIFS('Data BoP'!$H$6:$H$86,'Data BoP'!$C$6:$C$86,$B100) -> 56809.053 | F100: =SUMIFS('Data BoP'!$I$6:$I$86,'Data BoP'!$C$6:$C$86,$B100) -> 57594.23 | G100: =SUMIFS('Data BoP'!$J$6:$J$86,'Data BoP'!$C$6:$C$86,$B100) -> -5815.0447 | H100: =SUMIFS('Data BoP'!$K$6:$K$86,'Data BoP'!$C$6:$C$86,$B100) -> 13213.512 | I100: =SUMIFS('Data BoP'!$L$6:$L$86,'Data BoP'!$C$6:$C$86,$B100) -> 19028.557 | J100: =SUMIFS('Data BoP'!$M$6:$M$86,'Data BoP'!$C$6:$C$86,$B100) -> -12104.599 | K100: =SUMIFS('Data BoP'!$N$6:$N$86,'Data BoP'!$C$6:$C$86,$B100) -> 25.812828 | L100: =SUMIFS('Data BoP'!$O$6:$O$86,'Data BoP'!$C$6:$C$86,$B100) -> -12130.411 | M100: =SUMIFS('Data BoP'!$P$6:$P$86,'Data BoP'!$C$6:$C$86,$B100) -> -8145.1451 | N100: =SUMIFS('Data BoP'!$Q$6:$Q$86,'Data BoP'!$C$6:$C$86,$B100) -> -2687.2444 | O100: =SUMIFS('Data BoP'!$R$6:$R$86,'Data BoP'!$C$6:$C$86,$B100) -> -1322.4984 | P100: =SUMIFS('Data BoP'!$AO$6:$AO$86,'Data BoP'!$C$6:$C$86,$B100) -> 24.476529 | Q100: =SUMIFS('Data BoP'!$S$6:$S$86,'Data BoP'!$C$6:$C$86,$B100) -> 1082.8345 | R100: =SUMIFS('Data BoP'!$T$6:$T$86,'Data BoP'!$C$6:$C$86,$B100) -> 51.9292
B101: 2016 | C101: =SUMIFS('Data BoP'!$E$6:$E$86,'Data BoP'!$C$6:$C$86,$B101) -> -15104.787 | D101: =SUMIFS('Data BoP'!$G$6:$G$86,'Data BoP'!$C$6:$C$86,$B101) -> 4416.1569 | E101: =SUMIFS('Data BoP'!$H$6:$H$86,'Data BoP'!$C$6:$C$86,$B101) -> 57959.934 | F101: =SUMIFS('Data BoP'!$I$6:$I$86,'Data BoP'!$C$6:$C$86,$B101) -> 53543.777 | G101: =SUMIFS('Data BoP'!$J$6:$J$86,'Data BoP'!$C$6:$C$86,$B101) -> -8451.6552 | H101: =SUMIFS('Data BoP'!$K$6:$K$86,'Data BoP'!$C$6:$C$86,$B101) -> 13424.707 | I101: =SUMIFS('Data BoP'!$L$6:$L$86,'Data BoP'!$C$6:$C$86,$B101) -> 21876.362 | J101: =SUMIFS('Data BoP'!$M$6:$M$86,'Data BoP'!$C$6:$C$86,$B101) -> -12192.211 | K101: =SUMIFS('Data BoP'!$N$6:$N$86,'Data BoP'!$C$6:$C$86,$B101) -> -93.937831 | L101: =SUMIFS('Data BoP'!$O$6:$O$86,'Data BoP'!$C$6:$C$86,$B101) -> -12098.273 | M101: =SUMIFS('Data BoP'!$P$6:$P$86,'Data BoP'!$C$6:$C$86,$B101) -> -7166.2554 | N101: =SUMIFS('Data BoP'!$Q$6:$Q$86,'Data BoP'!$C$6:$C$86,$B101) -> -3505.4293 | O101: =SUMIFS('Data BoP'!$R$6:$R$86,'Data BoP'!$C$6:$C$86,$B101) -> -1487.1405 | P101: =SUMIFS('Data BoP'!$AO$6:$AO$86,'Data BoP'!$C$6:$C$86,$B101) -> 60.552378 | Q101: =SUMIFS('Data BoP'!$S$6:$S$86,'Data BoP'!$C$6:$C$86,$B101) -> 1122.9225 | R101: =SUMIFS('Data BoP'!$T$6:$T$86,'Data BoP'!$C$6:$C$86,$B101) -> 370.80455
B102: 2017 | C102: =SUMIFS('Data BoP'!$E$6:$E$86,'Data BoP'!$C$6:$C$86,$B102) -> -31151.352 | D102: =SUMIFS('Data BoP'!$G$6:$G$86,'Data BoP'!$C$6:$C$86,$B102) -> -5447.0631 | E102: =SUMIFS('Data BoP'!$H$6:$H$86,'Data BoP'!$C$6:$C$86,$B102) -> 58661.874 | F102: =SUMIFS('Data BoP'!$I$6:$I$86,'Data BoP'!$C$6:$C$86,$B102) -> 64108.937 | G102: =SUMIFS('Data BoP'!$J$6:$J$86,'Data BoP'!$C$6:$C$86,$B102) -> -9695.4386 | H102: =SUMIFS('Data BoP'!$K$6:$K$86,'Data BoP'!$C$6:$C$86,$B102) -> 15506.202 | I102: =SUMIFS('Data BoP'!$L$6:$L$86,'Data BoP'!$C$6:$C$86,$B102) -> 25201.641 | J102: =SUMIFS('Data BoP'!$M$6:$M$86,'Data BoP'!$C$6:$C$86,$B102) -> -16380.284 | K102: =SUMIFS('Data BoP'!$N$6:$N$86,'Data BoP'!$C$6:$C$86,$B102) -> -80.803522 | L102: =SUMIFS('Data BoP'!$O$6:$O$86,'Data BoP'!$C$6:$C$86,$B102) -> -16299.48 | M102: =SUMIFS('Data BoP'!$P$6:$P$86,'Data BoP'!$C$6:$C$86,$B102) -> -8681.6453 | N102: =SUMIFS('Data BoP'!$Q$6:$Q$86,'Data BoP'!$C$6:$C$86,$B102) -> -5980.8424 | O102: =SUMIFS('Data BoP'!$R$6:$R$86,'Data BoP'!$C$6:$C$86,$B102) -> -1767.3448 | P102: =SUMIFS('Data BoP'!$AO$6:$AO$86,'Data BoP'!$C$6:$C$86,$B102) -> 130.35228 | Q102: =SUMIFS('Data BoP'!$S$6:$S$86,'Data BoP'!$C$6:$C$86,$B102) -> 371.43365 | R102: =SUMIFS('Data BoP'!$T$6:$T$86,'Data BoP'!$C$6:$C$86,$B102) -> 173.49547
