Workbook

Sheet README
A1: Argentina Macro Analysis — Workbook Guide
A2: Refresh Haver downloads on raw tabs and run standard quarterly / monthly / annual analyses with 2-yr projections.
A4: TAB OVERVIEW
A5: • Real and nominal GDP — raw Haver download (quarterly). Paste new data over rows 8+, keep column order.
A6: • CPI — raw Haver download (monthly). Paste new data over rows 8+.
A7: • GDP Analysis — pre-linked. Quarterly + Annual + Nominal GDP USD + Projections + Charts.
A8: • CPI Analysis — pre-linked. Monthly + Quarterly + Annual + Projections + Charts.
A9: • TEMPLATE - Quarterly / Monthly / Annual — reusable templates for any new metric.
A11: REFRESHING HAVER DATA
A12: 1. Download with the same layout: header rows 1–7, data row 8+. Date in col A, period code in col B.
A13: 2. Paste over rows 8+ on the matching raw tab. All Analysis tabs and charts auto-recalculate.
A14: 3. Formulas extend to row 220 (quarterly, ~55 yrs buffer) / row 260 (monthly, ~21 yrs buffer).
... A43: • Year derivation parses the Haver period code: '244'→2024Q4, '2603'→2026M03.

Sheet Real and nominal GDP
C1: SA | D1: SA | E1: SA | F1: SA | G1: NSA | H1: NSA | I1: NSA
A2: Date | C2: Real GDP | D2: Consumption | E2: Gvt. Expenditures | F2: Investment | G2: Real GDP | H2: Nominal | I2: CPI | J2: FX | K2: FX informal
B3: 1041 !Q NA_ | C3: S213NGPC@EMERGELA | D3: S213NCPC@EMERGELA | E3: S213NCGC@EMERGELA | F3: S213NFC@EMERGELA | G3: N213NGPC@EMERGELA | H3: N213NGDP@EMERGELA | I3: N213PC@EMERGELA | J3: N213XUSV@EMERGELA | K3: X213DIM@EMERGELA
B4: .DESC | C4: Argentina: Gross Domestic Product at Market Prices (SAAR, Mil.2004.Pesos) | D4: Argentina: GDP: Private Consumption Expenditure (SAAR, Mil.2004.Pesos) | E4: Argentina: GDP: Govt Consumption Expenditure (SAAR, Mil.2004.Pesos) | F4: Argentina: GDP: Gross Fixed Capital Formation (SAAR, Mil.2004.Pesos) | G4: Argentina: Gross Domestic Product at Market Prices (NSAAR, Mil.2004.Pesos) | H4: Argentina: Gross Domestic Product at Market Prices (NSAAR, Mil.Pesos) | I4: Argentina: Consumer Price Index (NSA, Dec-16=100) | J4: Argentina: Exchange Rate: United States (Avg, Argentinian Peso/US$) | K4: Argentina: Informal US$ Exchange Rate, Mid Rate (Avg, Peso/US$)
B5: .SOURCE | C5: INDEC | D5: INDEC | E5: INDEC | F5: INDEC | G5: INDEC | H5: INDEC | I5: INDEC | J5: BCRA | K5: AMB
B6: .DATA_TYPE | C6: LocCur | D6: LocCur | E6: LocCur | F6: LocCur | G6: LocCur | H6: LocCur | I6: INDEX | J6: RATIO | K6: LC/US$
B7: .MAG | C7: 6 | D7: 6 | E7: 6 | F7: 6 | G7: 6 | H7: 6 | I7: 0 | J7: 0 | K7: 0
A8: 38047 | B8: 041 | C8: 476036.53 | D8: 302781.11 | E8: 52668.16 | F8: 74498.627 | G8: 460369.44 | H8: 439196 | J8: 2.9072667 | K8: 2.9163333
A9: 38139 | B9: 042 | C9: 470010.07 | D9: 304361.81 | E9: 52818.974 | F9: 76869.591 | G9: 514395.68 | H9: 509499 | J9: 2.9050733 | K9: 2.9093333
A10: 38231 | B10: 043 | C10: 493895.12 | D10: 316912.03 | E10: 54483.809 | F10: 77809.682 | G10: 481151.98 | H10: 488462 | J10: 2.9879933 | K10: 2.9956667
A11: 38322 | B11: 044 | C11: 500519.07 | D11: 324272.59 | E11: 55704.211 | F11: 79234.809 | G11: 484543.68 | H11: 503304 | J11: 2.9646167
A12: 38412 | B12: 051 | C12: 514918.46 | D12: 318967.71 | E12: 57528.588 | F12: 85178.716 | G12: 493602.53 | H12: 510703 | J12: 2.9297667 | K12: 2.9343333
A13: 38504 | B13: 052 | C13: 527084.2 | D13: 346690.41 | E13: 58964.326 | F13: 87994.464 | G13: 581668.25 | H13: 605772 | J13: 2.89173 | K13: 2.8986667
A14: 38596 | B14: 053 | C14: 530101.96 | D14: 331326.97 | E14: 59826.06 | F14: 88235.413 | G14: 514697.79 | H14: 590220 | J14: 2.8896033 | K14: 2.8846667
A15: 38687 | B15: 054 | C15: 540119.16 | D15: 343626.04 | E15: 60611.905 | F15: 95820.827 | G15: 522255.2 | H15: 623458 | J15: 2.98288 | K15: 2.9876667
A16: 38777 | B16: 061 | C16: 554455.77 | D16: 353511.32 | E16: 60524.269 | F16: 97450.782 | G16: 532348.21 | H16: 643562 | J16: 3.0649333 | K16: 3.0796667
A17: 38869 | B17: 062 | C17: 561157.22 | D17: 371905.79 | E17: 60706.294 | F17: 100741.05 | G17: 614076.39 | H17: 727989 | J17: 3.06794 | K17: 3.083
A18: 38961 | B18: 063 | C18: 577088.46 | D18: 381137.22 | E18: 61658.229 | F18: 103927.85 | G18: 562978.97 | H18: 729299 | J18: 3.0872567 | K18: 3.1033333
A19: 39052 | B19: 064 | C19: 589496.16 | D19: 380937.31 | E19: 62861.894 | F19: 106810.9 | G19: 572794.05 | H19: 762766 | J19: 3.0774 | K19: 3.098
A20: 39142 | B20: 071 | C20: 603483.21 | D20: 392667.41 | E20: 65392.759 | F20: 116267.52 | G20: 576846.89 | H20: 774388 | J20: 3.09675 | K20: 3.114
A21: 39234 | B21: 072 | C21: 616073.37 | D21: 402296.08 | E21: 65948.641 | F21: 121508.99 | G21: 674620.56 | H21: 904350 | J21: 3.0828667 | K21: 3.111
A22: 39326 | B22: 073 | C22: 624446.9 | D22: 412291.88 | E22: 66182.353 | F22: 125653.67 | G22: 610425.69 | H22: 914104 | J22: 3.1380133 | K22: 3.1816667
A23: 39417 | B23: 074 | C23: 643766.54 | D23: 419150.79 | E23: 67468.668 | F23: 129139.78 | G23: 625876.87 | H23: 995079 | J23: 3.1450767 | K23: 3.1746667
... A41: 41061 | B41: 122 | C41: 683593.32 | D41: 493768.88 | E41: 82764.047 | F41: 133906.72 | G41: 730838.27 | H41: 2651098 | J41: 4.4497267 | K41: 5.468
A42: 41153 | B42: 123 | C42: 705293.74 | D42: 515643.41 | E42: 84004.922 | F42: 143391.77 | G42: 703461.65 | H42: 2704828 | I42: 29.739833 | J42: 4.6116067 | K42: 6.2866667
A43: 41244 | B43: 124 | C43: 716708.04 | D43: 519592.21 | E43: 84715.909 | F43: 148410.68 | G43: 706958.04 | H43: 2850170 | I43: 31.3387 | J43: 4.80352 | K43: 6.3916667
A44: 41334 | B44: 131 | C44: 715943.74 | D44: 514386.79 | E44: 86326.806 | F44: 145736 | G44: 677085.53 | H44: 2888981 | I44: 33.105433 | J44: 5.0156467 | K44: 7.721
A45: 41426 | B45: 132 | C45: 720882.85 | D45: 517251.74 | E45: 87404.109 | F45: 147670.82 | G45: 776486.6 | H45: 3387811 | I45: 34.798233 | J45: 5.2423567 | K45: 8.7116667
A46: 41518 | B46: 133 | C46: 725588.38 | D46: 535655.93 | E46: 87951.009 | F46: 145972.59 | G46: 721458.94 | H46: 3436547 | I46: 37.0408 | J46: 5.58808 | K46: 8.8253333
A47: 41609 | B47: 134 | C47: 719213.45 | D47: 535403.67 | E47: 89983.227 | F47: 144846.87 | G47: 706597.34 | H47: 3679896 | I47: 39.5626 | J47: 6.0668567 | K47: 9.723
A48: 41699 | B48: 141 | C48: 708278.97 | D48: 521790.9 | E48: 90817.606 | F48: 141725.87 | G48: 671066.05 | H48: 3917649 | I48: 44.1826 | J48: 7.6322467 | K48: 11.300333
A49: 41791 | B49: 142 | C49: 702914.57 | D49: 498942.24 | E49: 89305.792 | F49: 139110.59 | G49: 760576.87 | H49: 4702630 | I49: 48.474633 | J49: 8.0561933 | K49: 11.125333
A50: 41883 | B50: 143 | C50: 697281.49 | D50: 490465.14 | E50: 90467.767 | F50: 133831.35 | G50: 690879.8 | H50: 4685503 | I50: 51.884633 | J50: 8.2984567 | K50: 13.411
A51: 41974 | B51: 144 | C51: 700749.15 | D51: 499859.46 | E51: 91430.632 | F51: 130090.78 | G51: 686701.47 | H51: 5010564 | I51: 54.994467 | J51: 8.51345 | K51: 13.700333
A52: 42064 | B52: 151 | C52: 710714.75 | D52: 508612.97 | E52: 94414.588 | F52: 138222.16 | G52: 672749.81 | H52: 5092694 | I52: 57.8225 | J52: 8.69027 | K52: 13.172667
A53: 42156 | B53: 152 | C53: 728934.83 | D53: 532927.69 | E53: 97682.915 | F53: 141538.9 | G53: 791235.97 | H53: 5951479 | I53: 61.293333 | J53: 8.9531667 | K53: 12.678333
... A95: 45992 | B95: 254 | C95: 744527.79 | D95: 557631.51 | E95: 95985.853 | F95: 137468.13 | G95: 733788.67 | H95: 939450203 | I95: 9855.5306 | J95: 1437.0627 | K95: 1453.069
A96: 46082 | B96: 261 | I96: 10734.906 | J96: 1417.7638 | K96: 1443.6893

Sheet CPI
C2: Headline | D2: Core
B3: 11501 !M | C3: N213PC@EMERGELA | D3: N213PCXQ@EMERGELA
B4: .DESC | C4: Argentina: Consumer Price Index (NSA, Dec-16=100) | D4: Argentina: CPI Ex Seasonal & Regulated (NSA, Dec-16=100)
B5: .SOURCE | C5: INDEC | D5: INDEC
B6: .DATA_TYPE | C6: INDEX | D6: INDEX
B7: .MAG | C7: 0 | D7: 0
B8: 1501 | C8: 56.9509 | D8: =#N/A -> #N/A
B9: 1502 | C9: 57.7781 | D9: =#N/A -> #N/A
B10: 1503 | C10: 58.7385 | D10: =#N/A -> #N/A
B11: 1504 | C11: 60.1294 | D11: =#N/A -> #N/A
B12: 1505 | C12: 61.4604 | D12: =#N/A -> #N/A
B13: 1506 | C13: 62.2902 | D13: =#N/A -> #N/A
B14: 1507 | C14: 63.5612 | D14: =#N/A -> #N/A
B15: 1508 | C15: 64.7251 | D15: =#N/A -> #N/A
B16: 1509 | C16: 65.7976 | D16: =#N/A -> #N/A
B17: 1510 | C17: 66.9172 | D17: =#N/A -> #N/A
B18: 1511 | C18: 68.2246 | D18: =#N/A -> #N/A
B19: 1512 | C19: 70.8969 | D19: =#N/A -> #N/A
... B30: 1611 | C30: 98.7735 | D30: =#N/A -> #N/A
B31: 1612 | C31: 100 | D31: 100
B32: 1701 | C32: 101.5859 | D32: 101.5039
B33: 1702 | C33: 103.6859 | D33: 103.2105
B34: 1703 | C34: 106.1476 | D34: 105.2057
B35: 1704 | C35: 108.9667 | D35: 107.427
B36: 1705 | C36: 110.5301 | D36: 109.2069
B37: 1706 | C37: 111.8477 | D37: 110.6653
B38: 1707 | C38: 113.7852 | D38: 112.6183
B39: 1708 | C39: 115.3819 | D39: 114.231
B40: 1709 | C40: 117.5719 | D40: 116.0978
B41: 1710 | C41: 119.3528 | D41: 117.6245
B42: 1711 | C42: 120.994 | D42: 119.1358
... B142: 2603 | C142: 11077.061 | D142: 11344.457

Sheet GDP Analysis
A1: GDP Analysis — Argentina
A2: Linked to raw tab 'Real and nominal GDP'. Refresh by pasting new Haver download over row 8+. Formulas extend to row 224 (≈53 yrs buffer).
A4: SETTINGS
A5: Annual aggregation | B5: Per-column (Sum for flow vars; Average for indices/rates)
A7: PROJECTION ASSUMPTIONS (annual YoY %)
A8: Series | B8: Year +1 YoY % | C8: Year +2 YoY %
A9: Real GDP (SA) | B9: 0.03 | C9: 0.025
A10: Consumption | B10: 0.03 | C10: 0.025
A11: Gvt Exp. | B11: 0.02 | C11: 0.02
A12: Investment | B12: 0.05 | C12: 0.04
A13: Real GDP (NSA) | B13: 0.03 | C13: 0.025
A14: Nominal GDP | B14: 0.5 | C14: 0.3
A15: CPI | B15: 0.5 | C15: 0.3
A16: FX (off) | B16: 0.4 | C16: 0.3
A17: FX (informal) | B17: 0.35 | C17: 0.25
A19: DATA & ANALYTICS (linked from raw tab) | V19: ANNUAL AGGREGATION | AI19: PROJECTIONS (annual)
A20: Date | B20: Period | C20: Year | D20: Real GDP (SA) | E20: Consumption | F20: Gvt Exp. | G20: Investment | H20: Real GDP (NSA) | I20: Nominal GDP | J20: CPI | K20: FX (off) | L20: FX (informal) | M20: YoY % Real GDP (SA) | N20: QoQ % Real GDP (SA) | O20: YoY % Nominal GDP | P20: 4Q sum Real GDP (SA) | Q20: 4Q sum Nominal GDP | R20: Nominal GDP USD off (mm) | S20: Nominal GDP USD inf (mm) | V20: Year | W20: Real GDP (SA) | X20: Consumption | Y20: Gvt Exp. | Z20: Investment | AA20: Real GDP (NSA) | AB20: Nominal GDP | AC20: CPI | AD20: FX (off) | AE20: FX (informal) | AF20: YoY % Real GDP (SA) | AI20: Year | AJ20: Real GDP (SA) (proj.) | AK20: Consumption (proj.) | AL20: Gvt Exp. (proj.) | AM20: Investment (proj.) | AN20: Real GDP (NSA) (proj.) | AO20: Nominal GDP (proj.) | AP20: CPI (proj.) | AQ20: FX (off) (proj.) | AR20: FX (informal) (proj.) | AS20: Nominal GDP USD (proj., off)
A21: =IFERROR(IF(ISNUMBER('Real and nominal GDP'!A8),'Real and nominal GDP'!A8,NA()),NA()) -> 38047 | B21: =IFERROR(IF('Real and nominal GDP'!B8="",NA(),'Real and nominal GDP'!B8),NA()) -> 041 | C21: =IFERROR(YEAR(A21),0) -> 2004 | D21: =IFERROR(IF('Real and nominal GDP'!C8="",NA(),IF(ISNUMBER('Real and nominal GDP'!C8),'Real and nominal GDP'!C8,NA())),NA()) -> 476036.53 | E21: =IFERROR(IF('Real and nominal GDP'!D8="",NA(),IF(ISNUMBER('Real and nominal GDP'!D8),'Real and nominal GDP'!D8,NA())),NA()) -> 302781.11 | F21: =IFERROR(IF('Real and nominal GDP'!E8="",NA(),IF(ISNUMBER('Real and nominal GDP'!E8),'Real and nominal GDP'!E8,NA())),NA()) -> 52668.16 | G21: =IFERROR(IF('Real and nominal GDP'!F8="",NA(),IF(ISNUMBER('Real and nominal GDP'!F8),'Real and nominal GDP'!F8,NA())),NA()) -> 74498.627 | H21: =IFERROR(IF('Real and nominal GDP'!G8="",NA(),IF(ISNUMBER('Real and nominal GDP'!G8),'Real and nominal GDP'!G8,NA())),NA()) -> 460369.44 | I21: =IFERROR(IF('Real and nominal GDP'!H8="",NA(),IF(ISNUMBER('Real and nominal GDP'!H8),'Real and nominal GDP'!H8,NA())),NA()) -> 439196 | J21: =IFERROR(IF('Real and nominal GDP'!I8="",NA(),IF(ISNUMBER('Real and nominal GDP'!I8),'Real and nominal GDP'!I8,NA())),NA()) -> #N/A | K21: =IFERROR(IF('Real and nominal GDP'!J8="",NA(),IF(ISNUMBER('Real and nominal GDP'!J8),'Real and nominal GDP'!J8,NA())),NA()) -> 2.9072667 | L21: =IFERROR(IF('Real and nominal GDP'!K8="",NA(),IF(ISNUMBER('Real and nominal GDP'!K8),'Real and nominal GDP'!K8,NA())),NA()) -> 2.9163333 | M21: =NA() -> #N/A | N21: =NA() -> #N/A | O21: =NA() -> #N/A | P21: =NA() -> #N/A | Q21: =NA() -> #N/A | R21: =IFERROR(I21/K21,NA()) -> 151068.36 | S21: =IFERROR(I21/L21,NA()) -> 150598.7 | V21: 2004 | W21: =IF(SUMPRODUCT(($C$21:$C$233=$V$21)*ISNUMBER($D$21:$D$233))=0,NA(),SUMPRODUCT(($C$21:$C$233=$V$21)*IFERROR($D$21:$D$233,0))) -> 1940460.8 | X21: =IF(SUMPRODUCT(($C$21:$C$233=$V$21)*ISNUMBER($E$21:$E$233))=0,NA(),SUMPRODUCT(($C$21:$C$233=$V$21)*IFERROR($E$21:$E$233,0))) -> 1248327.5 | Y21: =IF(SUMPRODUCT(($C$21:$C$233=$V$21)*ISNUMBER($F$21:$F$233))=0,NA(),SUMPRODUCT(($C$21:$C$233=$V$21)*IFERROR($F$21:$F$233,0))) -> 215675.15 | Z21: =IF(SUMPRODUCT(($C$21:$C$233=$V$21)*ISNUMBER($G$21:$G$233))=0,NA(),SUMPRODUCT(($C$21:$C$233=$V$21)*IFERROR($G$21:$G$233,0))) -> 308412.71 | AA21: =IF(SUMPRODUCT(($C$21:$C$233=$V$21)*ISNUMBER($H$21:$H$233))=0,NA(),SUMPRODUCT(($C$21:$C$233=$V$21)*IFERROR($H$21:$H$233,0))) -> 1940460.8 | AB21: =IF(SUMPRODUCT(($C$21:$C$233=$V$21)*ISNUMBER($I$21:$I$233))=0,NA(),SUMPRODUCT(($C$21:$C$233=$V$21)*IFERROR($I$21:$I$233,0))) -> 1940461 | AC21: =IF(SUMPRODUCT(($C$21:$C$233=$V$21)*ISNUMBER($J$21:$J$233))=0,NA(),SUMPRODUCT(($C$21:$C$233=$V$21)*IFERROR($J$21:$J$233,0))/SUMPRODUCT(($C$21:$C$233=$V$21)*ISNUMBER($J$21:$J$233))) -> #N/A | AD21: =IF(SUMPRODUCT(($C$21:$C$233=$V$21)*ISNUMBER($K$21:$K$233))=0,NA(),SUMPRODUCT(($C$21:$C$233=$V$21)*IFERROR($K$21:$K$233,0))/SUMPRODUCT(($C$21:$C$233=$V$21)*ISNUMBER($K$21:$K$233))) -> 2.9412375 | AE21: =IF(SUMPRODUCT(($C$21:$C$233=$V$21)*ISNUMBER($L$21:$L$233))=0,NA(),SUMPRODUCT(($C$21:$C$233=$V$21)*IFERROR($L$21:$L$233,0))/SUMPRODUCT(($C$21:$C$233=$V$21)*ISNUMBER($L$21:$L$233))) -> 2.9404444 | AF21: =NA() -> #N/A | AI21: =IFERROR(IFERROR(LOOKUP(2,1/ISNUMBER(W21:W50),V21:V50),NA())+1,NA()) -> 2026 | AJ21: =IFERROR((IFERROR(INDEX(W21:W50,MATCH(AI21-1,V21:V50,0)),NA()))*(1+$B9),NA()) -> 3044913.8 | AK21: =IFERROR((IFERROR(INDEX(X21:X50,MATCH(AI21-1,V21:V50,0)),NA()))*(1+$B10),NA()) -> 2266003.6 | AL21: =IFERROR((IFERROR(INDEX(Y21:Y50,MATCH(AI21-1,V21:V50,0)),NA()))*(1+$B11),NA()) -> 392792.12 | AM21: =IFERROR((IFERROR(INDEX(Z21:Z50,MATCH(AI21-1,V21:V50,0)),NA()))*(1+$B12),NA()) -> 608643.62 | AN21: =IFERROR((IFERROR(INDEX(AA21:AA50,MATCH(AI21-1,V21:V50,0)),NA()))*(1+$B13),NA()) -> 3044913.8 | AO21: =IFERROR((IFERROR(INDEX(AB21:AB50,MATCH(AI21-1,V21:V50,0)),NA()))*(1+$B9)*(1+$B15),NA()) -> 5.2383094e+09 | AP21: =IFERROR((IFERROR(INDEX(AC21:AC50,MATCH(AI21-1,V21:V50,0)),NA()))*(1+$B15),NA()) -> 13449.25 | AQ21: =IFERROR((IFERROR(INDEX(AD21:AD50,MATCH(AI21-1,V21:V50,0)),NA()))*(1+$B16),NA()) -> 1742.3515 | AR21: =IFERROR((IFERROR(INDEX(AE21:AE50,MATCH(AI21-1,V21:V50,0)),NA()))*(1+$B17),NA()) -> 1761.4922 | AS21: =IFERROR(AO21/AQ21,NA()) -> 3006459.6
A22: =IFERROR(IF(ISNUMBER('Real and nominal GDP'!A9),'Real and nominal GDP'!A9,NA()),NA()) -> 38139 | B22: =IFERROR(IF('Real and nominal GDP'!B9="",NA(),'Real and nominal GDP'!B9),NA()) -> 042 | C22: =IFERROR(YEAR(A22),0) -> 2004 | D22: =IFERROR(IF('Real and nominal GDP'!C9="",NA(),IF(ISNUMBER('Real and nominal GDP'!C9),'Real and nominal GDP'!C9,NA())),NA()) -> 470010.07 | E22: =IFERROR(IF('Real and nominal GDP'!D9="",NA(),IF(ISNUMBER('Real and nominal GDP'!D9),'Real and nominal GDP'!D9,NA())),NA()) -> 304361.81 | F22: =IFERROR(IF('Real and nominal GDP'!E9="",NA(),IF(ISNUMBER('Real and nominal GDP'!E9),'Real and nominal GDP'!E9,NA())),NA()) -> 52818.974 | G22: =IFERROR(IF('Real and nominal GDP'!F9="",NA(),IF(ISNUMBER('Real and nominal GDP'!F9),'Real and nominal GDP'!F9,NA())),NA()) -> 76869.591 | H22: =IFERROR(IF('Real and nominal GDP'!G9="",NA(),IF(ISNUMBER('Real and nominal GDP'!G9),'Real and nominal GDP'!G9,NA())),NA()) -> 514395.68 | I22: =IFERROR(IF('Real and nominal GDP'!H9="",NA(),IF(ISNUMBER('Real and nominal GDP'!H9),'Real and nominal GDP'!H9,NA())),NA()) -> 509499 | J22: =IFERROR(IF('Real and nominal GDP'!I9="",NA(),IF(ISNUMBER('Real and nominal GDP'!I9),'Real and nominal GDP'!I9,NA())),NA()) -> #N/A | K22: =IFERROR(IF('Real and nominal GDP'!J9="",NA(),IF(ISNUMBER('Real and nominal GDP'!J9),'Real and nominal GDP'!J9,NA())),NA()) -> 2.9050733 | L22: =IFERROR(IF('Real and nominal GDP'!K9="",NA(),IF(ISNUMBER('Real and nominal GDP'!K9),'Real and nominal GDP'!K9,NA())),NA()) -> 2.9093333 | M22: =NA() -> #N/A | N22: =IFERROR(D22/D21-1,NA()) -> -0.012659661 | O22: =NA() -> #N/A | P22: =NA() -> #N/A | Q22: =NA() -> #N/A | R22: =IFERROR(I22/K22,NA()) -> 175382.49 | S22: =IFERROR(I22/L22,NA()) -> 175125.69 | V22: 2005 | W22: =IF(SUMPRODUCT(($C$21:$C$233=$V$22)*ISNUMBER($D$21:$D$233))=0,NA(),SUMPRODUCT(($C$21:$C$233=$V$22)*IFERROR($D$21:$D$233,0))) -> 2112223.8 | X22: =IF(SUMPRODUCT(($C$21:$C$233=$V$22)*ISNUMBER($E$21:$E$233))=0,NA(),SUMPRODUCT(($C$21:$C$233=$V$22)*IFERROR($E$21:$E$233,0))) -> 1340611.1 | Y22: =IF(SUMPRODUCT(($C$21:$C$233=$V$22)*ISNUMBER($F$21:$F$233))=0,NA(),SUMPRODUCT(($C$21:$C$233=$V$22)*IFERROR($F$21:$F$233,0))) -> 236930.88 | Z22: =IF(SUMPRODUCT(($C$21:$C$233=$V$22)*ISNUMBER($G$21:$G$233))=0,NA(),SUMPRODUCT(($C$21:$C$233=$V$22)*IFERROR($G$21:$G$233,0))) -> 357229.42 | AA22: =IF(SUMPRODUCT(($C$21:$C$233=$V$22)*ISNUMBER($H$21:$H$233))=0,NA(),SUMPRODUCT(($C$21:$C$233=$V$22)*IFERROR($H$21:$H$233,0))) -> 2112223.8 | AB22: =IF(SUMPRODUCT(($C$21:$C$233=$V$22)*ISNUMBER($I$21:$I$233))=0,NA(),SUMPRODUCT(($C$21:$C$233=$V$22)*IFERROR($I$21:$I$233,0))) -> 2330153 | AC22: =IF(SUMPRODUCT(($C$21:$C$233=$V$22)*ISNUMBER($J$21:$J$233))=0,NA(),SUMPRODUCT(($C$21:$C$233=$V$22)*IFERROR($J$21:$J$233,0))/SUMPRODUCT(($C$21:$C$233=$V$22)*ISNUMBER($J$21:$J$233))) -> #N/A | AD22: =IF(SUMPRODUCT(($C$21:$C$233=$V$22)*ISNUMBER($K$21:$K$233))=0,NA(),SUMPRODUCT(($C$21:$C$233=$V$22)*IFERROR($K$21:$K$233,0))/SUMPRODUCT(($C$21:$C$233=$V$22)*ISNUMBER($K$21:$K$233))) -> 2.923495 | AE22: =IF(SUMPRODUCT(($C$21:$C$233=$V$22)*ISNUMBER($L$21:$L$233))=0,NA(),SUMPRODUCT(($C$21:$C$233=$V$22)*IFERROR($L$21:$L$233,0))/SUMPRODUCT(($C$21:$C$233=$V$22)*ISNUMBER($L$21:$L$233))) -> 2.9263333 | AF22: =IFERROR(W22/W21-1,NA()) -> 0.088516599 | AI22: =AI21+1 -> 2027 | AJ22: =IFERROR(AJ21*(1+$C9),NA()) -> 3121036.6 | AK22: =IFERROR(AK21*(1+$C10),NA()) -> 2322653.7 | AL22: =IFERROR(AL21*(1+$C11),NA()) -> 400647.97 | AM22: =IFERROR(AM21*(1+$C12),NA()) -> 632989.37 | AN22: =IFERROR(AN21*(1+$C13),NA()) -> 3121036.6 | AO22: =IFERROR(AO21*(1+$C9)*(1+$C15),NA()) -> 6.9800472e+09 | AP22: =IFERROR(AP21*(1+$C15),NA()) -> 17484.025 | AQ22: =IFERROR(AQ21*(1+$C16),NA()) -> 2265.0569 | AR22: =IFERROR(AR21*(1+$C17),NA()) -> 2201.8652 | AS22: =IFERROR(AO22/AQ22,NA()) -> 3081621.1
A23: =IFERROR(IF(ISNUMBER('Real and nominal GDP'!A10),'Real and nominal GDP'!A10,NA()),NA()) -> 38231 | B23: =IFERROR(IF('Real and nominal GDP'!B10="",NA(),'Real and nominal GDP'!B10),NA()) -> 043 | C23: =IFERROR(YEAR(A23),0) -> 2004 | D23: =IFERROR(IF('Real and nominal GDP'!C10="",NA(),IF(ISNUMBER('Real and nominal GDP'!C10),'Real and nominal GDP'!C10,NA())),NA()) -> 493895.12 | E23: =IFERROR(IF('Real and nominal GDP'!D10="",NA(),IF(ISNUMBER('Real and nominal GDP'!D10),'Real and nominal GDP'!D10,NA())),NA()) -> 316912.03 | F23: =IFERROR(IF('Real and nominal GDP'!E10="",NA(),IF(ISNUMBER('Real and nominal GDP'!E10),'Real and nominal GDP'!E10,NA())),NA()) -> 54483.809 | G23: =IFERROR(IF('Real and nominal GDP'!F10="",NA(),IF(ISNUMBER('Real and nominal GDP'!F10),'Real and nominal GDP'!F10,NA())),NA()) -> 77809.682 | H23: =IFERROR(IF('Real and nominal GDP'!G10="",NA(),IF(ISNUMBER('Real and nominal GDP'!G10),'Real and nominal GDP'!G10,NA())),NA()) -> 481151.98 | I23: =IFERROR(IF('Real and nominal GDP'!H10="",NA(),IF(ISNUMBER('Real and nominal GDP'!H10),'Real and nominal GDP'!H10,NA())),NA()) -> 488462 | J23: =IFERROR(IF('Real and nominal GDP'!I10="",NA(),IF(ISNUMBER('Real and nominal GDP'!I10),'Real and nominal GDP'!I10,NA())),NA()) -> #N/A | K23: =IFERROR(IF('Real and nominal GDP'!J10="",NA(),IF(ISNUMBER('Real and nominal GDP'!J10),'Real and nominal GDP'!J10,NA())),NA()) -> 2.9879933 | L23: =IFERROR(IF('Real and nominal GDP'!K10="",NA(),IF(ISNUMBER('Real and nominal GDP'!K10),'Real and nominal GDP'!K10,NA())),NA()) -> 2.9956667 | M23: =NA() -> #N/A | N23: =IFERROR(D23/D22-1,NA()) -> 0.050818178 | O23: =NA() -> #N/A | P23: =NA() -> #N/A | Q23: =NA() -> #N/A | R23: =IFERROR(I23/K23,NA()) -> 163474.93 | S23: =IFERROR(I23/L23,NA()) -> 163056.19 | V23: 2006 | W23: =IF(SUMPRODUCT(($C$21:$C$233=$V$23)*ISNUMBER($D$21:$D$233))=0,NA(),SUMPRODUCT(($C$21:$C$233=$V$23)*IFERROR($D$21:$D$233,0))) -> 2282197.6 | X23: =IF(SUMPRODUCT(($C$21:$C$233=$V$23)*ISNUMBER($E$21:$E$233))=0,NA(),SUMPRODUCT(($C$21:$C$233=$V$23)*IFERROR($E$21:$E$233,0))) -> 1487491.6 | Y23: =IF(SUMPRODUCT(($C$21:$C$233=$V$23)*ISNUMBER($F$21:$F$233))=0,NA(),SUMPRODUCT(($C$21:$C$233=$V$23)*IFERROR($F$21:$F$233,0))) -> 245750.69 | Z23: =IF(SUMPRODUCT(($C$21:$C$233=$V$23)*ISNUMBER($G$21:$G$233))=0,NA(),SUMPRODUCT(($C$21:$C$233=$V$23)*IFERROR($G$21:$G$233,0))) -> 408930.58 | AA23: =IF(SUMPRODUCT(($C$21:$C$233=$V$23)*ISNUMBER($H$21:$H$233))=0,NA(),SUMPRODUCT(($C$21:$C$233=$V$23)*IFERROR($H$21:$H$233,0))) -> 2282197.6 | AB23: =IF(SUMPRODUCT(($C$21:$C$233=$V$23)*ISNUMBER($I$21:$I$233))=0,NA(),SUMPRODUCT(($C$21:$C$233=$V$23)*IFERROR($I$21:$I$233,0))) -> 2863616 | AC23: =IF(SUMPRODUCT(($C$21:$C$233=$V$23)*ISNUMBER($J$21:$J$233))=0,NA(),SUMPRODUCT(($C$21:$C$233=$V$23)*IFERROR($J$21:$J$233,0))/SUMPRODUCT(($C$21:$C$233=$V$23)*ISNUMBER($J$21:$J$233))) -> #N/A | AD23: =IF(SUMPRODUCT(($C$21:$C$233=$V$23)*ISNUMBER($K$21:$K$233))=0,NA(),SUMPRODUCT(($C$21:$C$233=$V$23)*IFERROR($K$21:$K$233,0))/SUMPRODUCT(($C$21:$C$233=$V$23)*ISNUMBER($K$21:$K$233))) -> 3.0743825 | AE23: =IF(SUMPRODUCT(($C$21:$C$233=$V$23)*ISNUMBER($L$21:$L$233))=0,NA(),SUMPRODUCT(($C$21:$C$233=$V$23)*IFERROR($L$21:$L$233,0))/SUMPRODUCT(($C$21:$C$233=$V$23)*ISNUMBER($L$21:$L$233))) -> 3.091 | AF23: =IFERROR(W23/W22-1,NA()) -> 0.080471515
A24: =IFERROR(IF(ISNUMBER('Real and nominal GDP'!A11),'Real and nominal GDP'!A11,NA()),NA()) -> 38322 | B24: =IFERROR(IF('Real and nominal GDP'!B11="",NA(),'Real and nominal GDP'!B11),NA()) -> 044 | C24: =IFERROR(YEAR(A24),0) -> 2004 | D24: =IFERROR(IF('Real and nominal GDP'!C11="",NA(),IF(ISNUMBER('Real and nominal GDP'!C11),'Real and nominal GDP'!C11,NA())),NA()) -> 500519.07 | E24: =IFERROR(IF('Real and nominal GDP'!D11="",NA(),IF(ISNUMBER('Real and nominal GDP'!D11),'Real and nominal GDP'!D11,NA())),NA()) -> 324272.59 | F24: =IFERROR(IF('Real and nominal GDP'!E11="",NA(),IF(ISNUMBER('Real and nominal GDP'!E11),'Real and nominal GDP'!E11,NA())),NA()) -> 55704.211 | G24: =IFERROR(IF('Real and nominal GDP'!F11="",NA(),IF(ISNUMBER('Real and nominal GDP'!F11),'Real and nominal GDP'!F11,NA())),NA()) -> 79234.809 | H24: =IFERROR(IF('Real and nominal GDP'!G11="",NA(),IF(ISNUMBER('Real and nominal GDP'!G11),'Real and nominal GDP'!G11,NA())),NA()) -> 484543.68 | I24: =IFERROR(IF('Real and nominal GDP'!H11="",NA(),IF(ISNUMBER('Real and nominal GDP'!H11),'Real and nominal GDP'!H11,NA())),NA()) -> 503304 | J24: =IFERROR(IF('Real and nominal GDP'!I11="",NA(),IF(ISNUMBER('Real and nominal GDP'!I11),'Real and nominal GDP'!I11,NA())),NA()) -> #N/A | K24: =IFERROR(IF('Real and nominal GDP'!J11="",NA(),IF(ISNUMBER('Real and nominal GDP'!J11),'Real and nominal GDP'!J11,NA())),NA()) -> 2.9646167 | L24: =IFERROR(IF('Real and nominal GDP'!K11="",NA(),IF(ISNUMBER('Real and nominal GDP'!K11),'Real and nominal GDP'!K11,NA())),NA()) -> #N/A | M24: =NA() -> #N/A | N24: =IFERROR(D24/D23-1,NA()) -> 0.013411645 | O24: =NA() -> #N/A | P24: =IF(COUNT(D21:D24)=4,SUM(D21:D24),NA()) -> 1940460.8 | Q24: =IF(COUNT(I21:I24)=4,SUM(I21:I24),NA()) -> 1940461 | R24: =IFERROR(I24/K24,NA()) -> 169770.35 | S24: =IFERROR(I24/L24,NA()) -> #N/A | V24: 2007 | W24: =IF(SUMPRODUCT(($C$21:$C$233=$V$24)*ISNUMBER($D$21:$D$233))=0,NA(),SUMPRODUCT(($C$21:$C$233=$V$24)*IFERROR($D$21:$D$233,0))) -> 2487770 | X24: =IF(SUMPRODUCT(($C$21:$C$233=$V$24)*ISNUMBER($E$21:$E$233))=0,NA(),SUMPRODUCT(($C$21:$C$233=$V$24)*IFERROR($E$21:$E$233,0))) -> 1626406.2 | Y24: =IF(SUMPRODUCT(($C$21:$C$233=$V$24)*ISNUMBER($F$21:$F$233))=0,NA(),SUMPRODUCT(($C$21:$C$233=$V$24)*IFERROR($F$21:$F$233,0))) -> 264992.42 | Z24: =IF(SUMPRODUCT(($C$21:$C$233=$V$24)*ISNUMBER($G$21:$G$233))=0,NA(),SUMPRODUCT(($C$21:$C$233=$V$24)*IFERROR($G$21:$G$233,0))) -> 492569.96 | AA24: =IF(SUMPRODUCT(($C$21:$C$233=$V$24)*ISNUMBER($H$21:$H$233))=0,NA(),SUMPRODUCT(($C$21:$C$233=$V$24)*IFERROR($H$21:$H$233,0))) -> 2487770 | AB24: =IF(SUMPRODUCT(($C$21:$C$233=$V$24)*ISNUMBER($I$21:$I$233))=0,NA(),SUMPRODUCT(($C$21:$C$233=$V$24)*IFERROR($I$21:$I$233,0))) -> 3587921 | AC24: =IF(SUMPRODUCT(($C$21:$C$233=$V$24)*ISNUMBER($J$21:$J$233))=0,NA(),SUMPRODUCT(($C$21:$C$233=$V$24)*IFERROR($J$21:$J$233,0))/SUMPRODUCT(($C$21:$C$233=$V$24)*ISNUMBER($J$21:$J$233))) -> #N/A | AD24: =IF(SUMPRODUCT(($C$21:$C$233=$V$24)*ISNUMBER($K$21:$K$233))=0,NA(),SUMPRODUCT(($C$21:$C$233=$V$24)*IFERROR($K$21:$K$233,0))/SUMPRODUCT(($C$21:$C$233=$V$24)*ISNUMBER($K$21:$K$233))) -> 3.1156767 | AE24: =IF(SUMPRODUCT(($C$21:$C$233=$V$24)*ISNUMBER($L$21:$L$233))=0,NA(),SUMPRODUCT(($C$21:$C$233=$V$24)*IFERROR($L$21:$L$233,0))/SUMPRODUCT(($C$21:$C$233=$V$24)*ISNUMBER($L$21:$L$233))) -> 3.1453333 | AF24: =IFERROR(W24/W23-1,NA()) -> 0.090076509
A25: =IFERROR(IF(ISNUMBER('Real and nominal GDP'!A12),'Real and nominal GDP'!A12,NA()),NA()) -> 38412 | B25: =IFERROR(IF('Real and nominal GDP'!B12="",NA(),'Real and nominal GDP'!B12),NA()) -> 051 | C25: =IFERROR(YEAR(A25),0) -> 2005 | D25: =IFERROR(IF('Real and nominal GDP'!C12="",NA(),IF(ISNUMBER('Real and nominal GDP'!C12),'Real and nominal GDP'!C12,NA())),NA()) -> 514918.46 | E25: =IFERROR(IF('Real and nominal GDP'!D12="",NA(),IF(ISNUMBER('Real and nominal GDP'!D12),'Real and nominal GDP'!D12,NA())),NA()) -> 318967.71 | F25: =IFERROR(IF('Real and nominal GDP'!E12="",NA(),IF(ISNUMBER('Real and nominal GDP'!E12),'Real and nominal GDP'!E12,NA())),NA()) -> 57528.588 | G25: =IFERROR(IF('Real and nominal GDP'!F12="",NA(),IF(ISNUMBER('Real and nominal GDP'!F12),'Real and nominal GDP'!F12,NA())),NA()) -> 85178.716 | H25: =IFERROR(IF('Real and nominal GDP'!G12="",NA(),IF(ISNUMBER('Real and nominal GDP'!G12),'Real and nominal GDP'!G12,NA())),NA()) -> 493602.53 | I25: =IFERROR(IF('Real and nominal GDP'!H12="",NA(),IF(ISNUMBER('Real and nominal GDP'!H12),'Real and nominal GDP'!H12,NA())),NA()) -> 510703 | J25: =IFERROR(IF('Real and nominal GDP'!I12="",NA(),IF(ISNUMBER('Real and nominal GDP'!I12),'Real and nominal GDP'!I12,NA())),NA()) -> #N/A | K25: =IFERROR(IF('Real and nominal GDP'!J12="",NA(),IF(ISNUMBER('Real and nominal GDP'!J12),'Real and nominal GDP'!J12,NA())),NA()) -> 2.9297667 | L25: =IFERROR(IF('Real and nominal GDP'!K12="",NA(),IF(ISNUMBER('Real and nominal GDP'!K12),'Real and nominal GDP'!K12,NA())),NA()) -> 2.9343333 | M25: =IFERROR(D25/D21-1,NA()) -> 0.081678463 | N25: =IFERROR(D25/D24-1,NA()) -> 0.028768918 | O25: =IFERROR(I25/I21-1,NA()) -> 0.16281341 | P25: =IF(COUNT(D22:D25)=4,SUM(D22:D25),NA()) -> 1979342.7 | Q25: =IF(COUNT(I22:I25)=4,SUM(I22:I25),NA()) -> 2011968 | R25: =IFERROR(I25/K25,NA()) -> 174315.25 | S25: =IFERROR(I25/L25,NA()) -> 174043.96 | V25: 2008 | W25: =IF(SUMPRODUCT(($C$21:$C$233=$V$25)*ISNUMBER($D$21:$D$233))=0,NA(),SUMPRODUCT(($C$21:$C$233=$V$25)*IFERROR($D$21:$D$233,0))) -> 2588704.6 | X25: =IF(SUMPRODUCT(($C$21:$C$233=$V$25)*ISNUMBER($E$21:$E$233))=0,NA(),SUMPRODUCT(($C$21:$C$233=$V$25)*IFERROR($E$21:$E$233,0))) -> 1744233.6 | Y25: =IF(SUMPRODUCT(($C$21:$C$233=$V$25)*ISNUMBER($F$21:$F$233))=0,NA(),SUMPRODUCT(($C$21:$C$233=$V$25)*IFERROR($F$21:$F$233,0))) -> 278282 | Z25: =IF(SUMPRODUCT(($C$21:$C$233=$V$25)*ISNUMBER($G$21:$G$233))=0,NA(),SUMPRODUCT(($C$21:$C$233=$V$25)*IFERROR($G$21:$G$233,0))) -> 535401.06 | AA25: =IF(SUMPRODUCT(($C$21:$C$233=$V$25)*ISNUMBER($H$21:$H$233))=0,NA(),SUMPRODUCT(($C$21:$C$233=$V$25)*IFERROR($H$21:$H$233,0))) -> 2588704.6 | AB25: =IF(SUMPRODUCT(($C$21:$C$233=$V$25)*ISNUMBER($I$21:$I$233))=0,NA(),SUMPRODUCT(($C$21:$C$233=$V$25)*IFERROR($I$21:$I$233,0))) -> 4598584 | AC25: =IF(SUMPRODUCT(($C$21:$C$233=$V$25)*ISNUMBER($J$21:$J$233))=0,NA(),SUMPRODUCT(($C$21:$C$233=$V$25)*IFERROR($J$21:$J$233,0))/SUMPRODUCT(($C$21:$C$233=$V$25)*ISNUMBER($J$21:$J$233))) -> #N/A | AD25: =IF(SUMPRODUCT(($C$21:$C$233=$V$25)*ISNUMBER($K$21:$K$233))=0,NA(),SUMPRODUCT(($C$21:$C$233=$V$25)*IFERROR($K$21:$K$233,0))/SUMPRODUCT(($C$21:$C$233=$V$25)*ISNUMBER($K$21:$K$233))) -> 3.1634033 | AE25: =IF(SUMPRODUCT(($C$21:$C$233=$V$25)*ISNUMBER($L$21:$L$233))=0,NA(),SUMPRODUCT(($C$21:$C$233=$V$25)*IFERROR($L$21:$L$233,0))/SUMPRODUCT(($C$21:$C$233=$V$25)*ISNUMBER($L$21:$L$233))) -> 3.2099167 | AF25: =IFERROR(W25/W24-1,NA()) -> 0.040572331
A26: =IFERROR(IF(ISNUMBER('Real and nominal GDP'!A13),'Real and nominal GDP'!A13,NA()),NA()) -> 38504 | B26: =IFERROR(IF('Real and nominal GDP'!B13="",NA(),'Real and nominal GDP'!B13),NA()) -> 052 | C26: =IFERROR(YEAR(A26),0) -> 2005 | D26: =IFERROR(IF('Real and nominal GDP'!C13="",NA(),IF(ISNUMBER('Real and nominal GDP'!C13),'Real and nominal GDP'!C13,NA())),NA()) -> 527084.2 | E26: =IFERROR(IF('Real and nominal GDP'!D13="",NA(),IF(ISNUMBER('Real and nominal GDP'!D13),'Real and nominal GDP'!D13,NA())),NA()) -> 346690.41 | F26: =IFERROR(IF('Real and nominal GDP'!E13="",NA(),IF(ISNUMBER('Real and nominal GDP'!E13),'Real and nominal GDP'!E13,NA())),NA()) -> 58964.326 | G26: =IFERROR(IF('Real and nominal GDP'!F13="",NA(),IF(ISNUMBER('Real and nominal GDP'!F13),'Real and nominal GDP'!F13,NA())),NA()) -> 87994.464 | H26: =IFERROR(IF('Real and nominal GDP'!G13="",NA(),IF(ISNUMBER('Real and nominal GDP'!G13),'Real and nominal GDP'!G13,NA())),NA()) -> 581668.25 | I26: =IFERROR(IF('Real and nominal GDP'!H13="",NA(),IF(ISNUMBER('Real and nominal GDP'!H13),'Real and nominal GDP'!H13,NA())),NA()) -> 605772 | J26: =IFERROR(IF('Real and nominal GDP'!I13="",NA(),IF(ISNUMBER('Real and nominal GDP'!I13),'Real and nominal GDP'!I13,NA())),NA()) -> #N/A | K26: =IFERROR(IF('Real and nominal GDP'!J13="",NA(),IF(ISNUMBER('Real and nominal GDP'!J13),'Real and nominal GDP'!J13,NA())),NA()) -> 2.89173 | L26: =IFERROR(IF('Real and nominal GDP'!K13="",NA(),IF(ISNUMBER('Real and nominal GDP'!K13),'Real and nominal GDP'!K13,NA())),NA()) -> 2.8986667 | M26: =IFERROR(D26/D22-1,NA()) -> 0.12143172 | N26: =IFERROR(D26/D25-1,NA()) -> 0.023626535 | O26: =IFERROR(I26/I22-1,NA()) -> 0.18895621 | P26: =IF(COUNT(D23:D26)=4,SUM(D23:D26),NA()) -> 2036416.8 | Q26: =IF(COUNT(I23:I26)=4,SUM(I23:I26),NA()) -> 2108241 | R26: =IFERROR(I26/K26,NA()) -> 209484.29 | S26: =IFERROR(I26/L26,NA()) -> 208982.98 | V26: 2009 | W26: =IF(SUMPRODUCT(($C$21:$C$233=$V$26)*ISNUMBER($D$21:$D$233))=0,NA(),SUMPRODUCT(($C$21:$C$233=$V$26)*IFERROR($D$21:$D$233,0))) -> 2435491.5 | X26: =IF(SUMPRODUCT(($C$21:$C$233=$V$26)*ISNUMBER($E$21:$E$233))=0,NA(),SUMPRODUCT(($C$21:$C$233=$V$26)*IFERROR($E$21:$E$233,0))) -> 1650085.9 | Y26: =IF(SUMPRODUCT(($C$21:$C$233=$V$26)*ISNUMBER($F$21:$F$233))=0,NA(),SUMPRODUCT(($C$21:$C$233=$V$26)*IFERROR($F$21:$F$233,0))) -> 293961.11 | Z26: =IF(SUMPRODUCT(($C$21:$C$233=$V$26)*ISNUMBER($G$21:$G$233))=0,NA(),SUMPRODUCT(($C$21:$C$233=$V$26)*IFERROR($G$21:$G$233,0))) -> 414545.77 | AA26: =IF(SUMPRODUCT(($C$21:$C$233=$V$26)*ISNUMBER($H$21:$H$233))=0,NA(),SUMPRODUCT(($C$21:$C$233=$V$26)*IFERROR($H$21:$H$233,0))) -> 2435491.5 | AB26: =IF(SUMPRODUCT(($C$21:$C$233=$V$26)*ISNUMBER($I$21:$I$233))=0,NA(),SUMPRODUCT(($C$21:$C$233=$V$26)*IFERROR($I$21:$I$233,0))) -> 4991717 | AC26: =IF(SUMPRODUCT(($C$21:$C$233=$V$26)*ISNUMBER($J$21:$J$233))=0,NA(),SUMPRODUCT(($C$21:$C$233=$V$26)*IFERROR($J$21:$J$233,0))/SUMPRODUCT(($C$21:$C$233=$V$26)*ISNUMBER($J$21:$J$233))) -> #N/A | AD26: =IF(SUMPRODUCT(($C$21:$C$233=$V$26)*ISNUMBER($K$21:$K$233))=0,NA(),SUMPRODUCT(($C$21:$C$233=$V$26)*IFERROR($K$21:$K$233,0))/SUMPRODUCT(($C$21:$C$233=$V$26)*ISNUMBER($K$21:$K$233))) -> 3.7296117 | AE26: =IF(SUMPRODUCT(($C$21:$C$233=$V$26)*ISNUMBER($L$21:$L$233))=0,NA(),SUMPRODUCT(($C$21:$C$233=$V$26)*IFERROR($L$21:$L$233,0))/SUMPRODUCT(($C$21:$C$233=$V$26)*ISNUMBER($L$21:$L$233))) -> 3.7694167 | AF26: =IFERROR(W26/W25-1,NA()) -> -0.059185251
A27: =IFERROR(IF(ISNUMBER('Real and nominal GDP'!A14),'Real and nominal GDP'!A14,NA()),NA()) -> 38596 | B27: =IFERROR(IF('Real and nominal GDP'!B14="",NA(),'Real and nominal GDP'!B14),NA()) -> 053 | C27: =IFERROR(YEAR(A27),0) -> 2005 | D27: =IFERROR(IF('Real and nominal GDP'!C14="",NA(),IF(ISNUMBER('Real and nominal GDP'!C14),'Real and nominal GDP'!C14,NA())),NA()) -> 530101.96 | E27: =IFERROR(IF('Real and nominal GDP'!D14="",NA(),IF(ISNUMBER('Real and nominal GDP'!D14),'Real and nominal GDP'!D14,NA())),NA()) -> 331326.97 | F27: =IFERROR(IF('Real and nominal GDP'!E14="",NA(),IF(ISNUMBER('Real and nominal GDP'!E14),'Real and nominal GDP'!E14,NA())),NA()) -> 59826.06 | G27: =IFERROR(IF('Real and nominal GDP'!F14="",NA(),IF(ISNUMBER('Real and nominal GDP'!F14),'Real and nominal GDP'!F14,NA())),NA()) -> 88235.413 | H27: =IFERROR(IF('Real and nominal GDP'!G14="",NA(),IF(ISNUMBER('Real and nominal GDP'!G14),'Real and nominal GDP'!G14,NA())),NA()) -> 514697.79 | I27: =IFERROR(IF('Real and nominal GDP'!H14="",NA(),IF(ISNUMBER('Real and nominal GDP'!H14),'Real and nominal GDP'!H14,NA())),NA()) -> 590220 | J27: =IFERROR(IF('Real and nominal GDP'!I14="",NA(),IF(ISNUMBER('Real and nominal GDP'!I14),'Real and nominal GDP'!I14,NA())),NA()) -> #N/A | K27: =IFERROR(IF('Real and nominal GDP'!J14="",NA(),IF(ISNUMBER('Real and nominal GDP'!J14),'Real and nominal GDP'!J14,NA())),NA()) -> 2.8896033 | L27: =IFERROR(IF('Real and nominal GDP'!K14="",NA(),IF(ISNUMBER('Real and nominal GDP'!K14),'Real and nominal GDP'!K14,NA())),NA()) -> 2.8846667 | M27: =IFERROR(D27/D23-1,NA()) -> 0.073308756 | N27: =IFERROR(D27/D26-1,NA()) -> 0.0057253851 | O27: =IFERROR(I27/I23-1,NA()) -> 0.20832327 | P27: =IF(COUNT(D24:D27)=4,SUM(D24:D27),NA()) -> 2072623.7 | Q27: =IF(COUNT(I24:I27)=4,SUM(I24:I27),NA()) -> 2209999 | R27: =IFERROR(I27/K27,NA()) -> 204256.41 | S27: =IFERROR(I27/L27,NA()) -> 204605.96 | V27: 2010 | W27: =IF(SUMPRODUCT(($C$21:$C$233=$V$27)*ISNUMBER($D$21:$D$233))=0,NA(),SUMPRODUCT(($C$21:$C$233=$V$27)*IFERROR($D$21:$D$233,0))) -> 2682094.7 | X27: =IF(SUMPRODUCT(($C$21:$C$233=$V$27)*ISNUMBER($E$21:$E$233))=0,NA(),SUMPRODUCT(($C$21:$C$233=$V$27)*IFERROR($E$21:$E$233,0))) -> 1834700.7 | Y27: =IF(SUMPRODUCT(($C$21:$C$233=$V$27)*ISNUMBER($F$21:$F$233))=0,NA(),SUMPRODUCT(($C$21:$C$233=$V$27)*IFERROR($F$21:$F$233,0))) -> 309988.39 | Z27: =IF(SUMPRODUCT(($C$21:$C$233=$V$27)*ISNUMBER($G$21:$G$233))=0,NA(),SUMPRODUCT(($C$21:$C$233=$V$27)*IFERROR($G$21:$G$233,0))) -> 523383.03 | AA27: =IF(SUMPRODUCT(($C$21:$C$233=$V$27)*ISNUMBER($H$21:$H$233))=0,NA(),SUMPRODUCT(($C$21:$C$233=$V$27)*IFERROR($H$21:$H$233,0))) -> 2682094.7 | AB27: =IF(SUMPRODUCT(($C$21:$C$233=$V$27)*ISNUMBER($I$21:$I$233))=0,NA(),SUMPRODUCT(($C$21:$C$233=$V$27)*IFERROR($I$21:$I$233,0))) -> 6646884 | AC27: =IF(SUMPRODUCT(($C$21:$C$233=$V$27)*ISNUMBER($J$21:$J$233))=0,NA(),SUMPRODUCT(($C$21:$C$233=$V$27)*IFERROR($J$21:$J$233,0))/SUMPRODUCT(($C$21:$C$233=$V$27)*ISNUMBER($J$21:$J$233))) -> #N/A | AD27: =IF(SUMPRODUCT(($C$21:$C$233=$V$27)*ISNUMBER($K$21:$K$233))=0,NA(),SUMPRODUCT(($C$21:$C$233=$V$27)*IFERROR($K$21:$K$233,0))/SUMPRODUCT(($C$21:$C$233=$V$27)*ISNUMBER($K$21:$K$233))) -> 3.9123375 | AE27: =IF(SUMPRODUCT(($C$21:$C$233=$V$27)*ISNUMBER($L$21:$L$233))=0,NA(),SUMPRODUCT(($C$21:$C$233=$V$27)*IFERROR($L$21:$L$233,0))/SUMPRODUCT(($C$21:$C$233=$V$27)*ISNUMBER($L$21:$L$233))) -> 3.975 | AF27: =IFERROR(W27/W26-1,NA()) -> 0.10125398
A28: =IFERROR(IF(ISNUMBER('Real and nominal GDP'!A15),'Real and nominal GDP'!A15,NA()),NA()) -> 38687 | B28: =IFERROR(IF('Real and nominal GDP'!B15="",NA(),'Real and nominal GDP'!B15),NA()) -> 054 | C28: =IFERROR(YEAR(A28),0) -> 2005 | D28: =IFERROR(IF('Real and nominal GDP'!C15="",NA(),IF(ISNUMBER('Real and nominal GDP'!C15),'Real and nominal GDP'!C15,NA())),NA()) -> 540119.16 | E28: =IFERROR(IF('Real and nominal GDP'!D15="",NA(),IF(ISNUMBER('Real and nominal GDP'!D15),'Real and nominal GDP'!D15,NA())),NA()) -> 343626.04 | F28: =IFERROR(IF('Real and nominal GDP'!E15="",NA(),IF(ISNUMBER('Real and nominal GDP'!E15),'Real and nominal GDP'!E15,NA())),NA()) -> 60611.905 | G28: =IFERROR(IF('Real and nominal GDP'!F15="",NA(),IF(ISNUMBER('Real and nominal GDP'!F15),'Real and nominal GDP'!F15,NA())),NA()) -> 95820.827 | H28: =IFERROR(IF('Real and nominal GDP'!G15="",NA(),IF(ISNUMBER('Real and nominal GDP'!G15),'Real and nominal GDP'!G15,NA())),NA()) -> 522255.2 | I28: =IFERROR(IF('Real and nominal GDP'!H15="",NA(),IF(ISNUMBER('Real and nominal GDP'!H15),'Real and nominal GDP'!H15,NA())),NA()) -> 623458 | J28: =IFERROR(IF('Real and nominal GDP'!I15="",NA(),IF(ISNUMBER('Real and nominal GDP'!I15),'Real and nominal GDP'!I15,NA())),NA()) -> #N/A | K28: =IFERROR(IF('Real and nominal GDP'!J15="",NA(),IF(ISNUMBER('Real and nominal GDP'!J15),'Real and nominal GDP'!J15,NA())),NA()) -> 2.98288 | L28: =IFERROR(IF('Real and nominal GDP'!K15="",NA(),IF(ISNUMBER('Real and nominal GDP'!K15),'Real and nominal GDP'!K15,NA())),NA()) -> 2.9876667 | M28: =IFERROR(D28/D24-1,NA()) -> 0.079118041 | N28: =IFERROR(D28/D27-1,NA()) -> 0.018896736 | O28: =IFERROR(I28/I24-1,NA()) -> 0.23873047 | P28: =IF(COUNT(D25:D28)=4,SUM(D25:D28),NA()) -> 2112223.8 | Q28: =IF(COUNT(I25:I28)=4,SUM(I25:I28),NA()) -> 2330153 | R28: =IFERROR(I28/K28,NA()) -> 209012.1 | S28: =IFERROR(I28/L28,NA()) -> 208677.23 | V28: 2011 | W28: =IF(SUMPRODUCT(($C$21:$C$233=$V$28)*ISNUMBER($D$21:$D$233))=0,NA(),SUMPRODUCT(($C$21:$C$233=$V$28)*IFERROR($D$21:$D$233,0))) -> 2843126.4 | X28: =IF(SUMPRODUCT(($C$21:$C$233=$V$28)*ISNUMBER($E$21:$E$233))=0,NA(),SUMPRODUCT(($C$21:$C$233=$V$28)*IFERROR($E$21:$E$233,0))) -> 2006588.6 | Y28: =IF(SUMPRODUCT(($C$21:$C$233=$V$28)*ISNUMBER($F$21:$F$233))=0,NA(),SUMPRODUCT(($C$21:$C$233=$V$28)*IFERROR($F$21:$F$233,0))) -> 324139.08 | Z28: =IF(SUMPRODUCT(($C$21:$C$233=$V$28)*ISNUMBER($G$21:$G$233))=0,NA(),SUMPRODUCT(($C$21:$C$233=$V$28)*IFERROR($G$21:$G$233,0))) -> 614336.34 | AA28: =IF(SUMPRODUCT(($C$21:$C$233=$V$28)*ISNUMBER($H$21:$H$233))=0,NA(),SUMPRODUCT(($C$21:$C$233=$V$28)*IFERROR($H$21:$H$233,0))) -> 2843126.4 | AB28: =IF(SUMPRODUCT(($C$21:$C$233=$V$28)*ISNUMBER($I$21:$I$233))=0,NA(),SUMPRODUCT(($C$21:$C$233=$V$28)*IFERROR($I$21:$I$233,0))) -> 8716096 | AC28: =IF(SUMPRODUCT(($C$21:$C$233=$V$28)*ISNUMBER($J$21:$J$233))=0,NA(),SUMPRODUCT(($C$21:$C$233=$V$28)*IFERROR($J$21:$J$233,0))/SUMPRODUCT(($C$21:$C$233=$V$28)*ISNUMBER($J$21:$J$233))) -> #N/A | AD28: =IF(SUMPRODUCT(($C$21:$C$233=$V$28)*ISNUMBER($K$21:$K$233))=0,NA(),SUMPRODUCT(($C$21:$C$233=$V$28)*IFERROR($K$21:$K$233,0))/SUMPRODUCT(($C$21:$C$233=$V$28)*ISNUMBER($K$21:$K$233))) -> 4.1300142 | AE28: =IF(SUMPRODUCT(($C$21:$C$233=$V$28)*ISNUMBER($L$21:$L$233))=0,NA(),SUMPRODUCT(($C$21:$C$233=$V$28)*IFERROR($L$21:$L$233,0))/SUMPRODUCT(($C$21:$C$233=$V$28)*ISNUMBER($L$21:$L$233))) -> 4.3434167 | AF28: =IFERROR(W28/W27-1,NA()) -> 0.060039517
A29: =IFERROR(IF(ISNUMBER('Real and nominal GDP'!A16),'Real and nominal GDP'!A16,NA()),NA()) -> 38777 | B29: =IFERROR(IF('Real and nominal GDP'!B16="",NA(),'Real and nominal GDP'!B16),NA()) -> 061 | C29: =IFERROR(YEAR(A29),0) -> 2006 | D29: =IFERROR(IF('Real and nominal GDP'!C16="",NA(),IF(ISNUMBER('Real and nominal GDP'!C16),'Real and nominal GDP'!C16,NA())),NA()) -> 554455.77 | E29: =IFERROR(IF('Real and nominal GDP'!D16="",NA(),IF(ISNUMBER('Real and nominal GDP'!D16),'Real and nominal GDP'!D16,NA())),NA()) -> 353511.32 | F29: =IFERROR(IF('Real and nominal GDP'!E16="",NA(),IF(ISNUMBER('Real and nominal GDP'!E16),'Real and nominal GDP'!E16,NA())),NA()) -> 60524.269 | G29: =IFERROR(IF('Real and nominal GDP'!F16="",NA(),IF(ISNUMBER('Real and nominal GDP'!F16),'Real and nominal GDP'!F16,NA())),NA()) -> 97450.782 | H29: =IFERROR(IF('Real and nominal GDP'!G16="",NA(),IF(ISNUMBER('Real and nominal GDP'!G16),'Real and nominal GDP'!G16,NA())),NA()) -> 532348.21 | I29: =IFERROR(IF('Real and nominal GDP'!H16="",NA(),IF(ISNUMBER('Real and nominal GDP'!H16),'Real and nominal GDP'!H16,NA())),NA()) -> 643562 | J29: =IFERROR(IF('Real and nominal GDP'!I16="",NA(),IF(ISNUMBER('Real and nominal GDP'!I16),'Real and nominal GDP'!I16,NA())),NA()) -> #N/A | K29: =IFERROR(IF('Real and nominal GDP'!J16="",NA(),IF(ISNUMBER('Real and nominal GDP'!J16),'Real and nominal GDP'!J16,NA())),NA()) -> 3.0649333 | L29: =IFERROR(IF('Real and nominal GDP'!K16="",NA(),IF(ISNUMBER('Real and nominal GDP'!K16),'Real and nominal GDP'!K16,NA())),NA()) -> 3.0796667 | M29: =IFERROR(D29/D25-1,NA()) -> 0.076783639 | N29: =IFERROR(D29/D28-1,NA()) -> 0.026543434 | O29: =IFERROR(I29/I25-1,NA()) -> 0.26014925 | P29: =IF(COUNT(D26:D29)=4,SUM(D26:D29),NA()) -> 2151761.1 | Q29: =IF(COUNT(I26:I29)=4,SUM(I26:I29),NA()) -> 2463012 | R29: =IFERROR(I29/K29,NA()) -> 209975.86 | S29: =IFERROR(I29/L29,NA()) -> 208971.32 | V29: 2012 | W29: =IF(SUMPRODUCT(($C$21:$C$233=$V$29)*ISNUMBER($D$21:$D$233))=0,NA(),SUMPRODUCT(($C$21:$C$233=$V$29)*IFERROR($D$21:$D$233,0))) -> 2813944 | X29: =IF(SUMPRODUCT(($C$21:$C$233=$V$29)*ISNUMBER($E$21:$E$233))=0,NA(),SUMPRODUCT(($C$21:$C$233=$V$29)*IFERROR($E$21:$E$233,0))) -> 2028867.4 | Y29: =IF(SUMPRODUCT(($C$21:$C$233=$V$29)*ISNUMBER($F$21:$F$233))=0,NA(),SUMPRODUCT(($C$21:$C$233=$V$29)*IFERROR($F$21:$F$233,0))) -> 333893.38 | Z29: =IF(SUMPRODUCT(($C$21:$C$233=$V$29)*ISNUMBER($G$21:$G$233))=0,NA(),SUMPRODUCT(($C$21:$C$233=$V$29)*IFERROR($G$21:$G$233,0))) -> 570870.81 | AA29: =IF(SUMPRODUCT(($C$21:$C$233=$V$29)*ISNUMBER($H$21:$H$233))=0,NA(),SUMPRODUCT(($C$21:$C$233=$V$29)*IFERROR($H$21:$H$233,0))) -> 2813944 | AB29: =IF(SUMPRODUCT(($C$21:$C$233=$V$29)*ISNUMBER($I$21:$I$233))=0,NA(),SUMPRODUCT(($C$21:$C$233=$V$29)*IFERROR($I$21:$I$233,0))) -> 10551656 | AC29: =IF(SUMPRODUCT(($C$21:$C$233=$V$29)*ISNUMBER($J$21:$J$233))=0,NA(),SUMPRODUCT(($C$21:$C$233=$V$29)*IFERROR($J$21:$J$233,0))/SUMPRODUCT(($C$21:$C$233=$V$29)*ISNUMBER($J$21:$J$233))) -> 30.539267 | AD29: =IF(SUMPRODUCT(($C$21:$C$233=$V$29)*ISNUMBER($K$21:$K$233))=0,NA(),SUMPRODUCT(($C$21:$C$233=$V$29)*IFERROR($K$21:$K$233,0))/SUMPRODUCT(($C$21:$C$233=$V$29)*ISNUMBER($K$21:$K$233))) -> 4.5515483 | AE29: =IF(SUMPRODUCT(($C$21:$C$233=$V$29)*ISNUMBER($L$21:$L$233))=0,NA(),SUMPRODUCT(($C$21:$C$233=$V$29)*IFERROR($L$21:$L$233,0))/SUMPRODUCT(($C$21:$C$233=$V$29)*ISNUMBER($L$21:$L$233))) -> 5.7314167 | AF29: =IFERROR(W29/W28-1,NA()) -> -0.010264205
A30: =IFERROR(IF(ISNUMBER('Real and nominal GDP'!A17),'Real and nominal GDP'!A17,NA()),NA()) -> 38869 | B30: =IFERROR(IF('Real and nominal GDP'!B17="",NA(),'Real and nominal GDP'!B17),NA()) -> 062 | C30: =IFERROR(YEAR(A30),0) -> 2006 | D30: =IFERROR(IF('Real and nominal GDP'!C17="",NA(),IF(ISNUMBER('Real and nominal GDP'!C17),'Real and nominal GDP'!C17,NA())),NA()) -> 561157.22 | E30: =IFERROR(IF('Real and nominal GDP'!D17="",NA(),IF(ISNUMBER('Real and nominal GDP'!D17),'Real and nominal GDP'!D17,NA())),NA()) -> 371905.79 | F30: =IFERROR(IF('Real and nominal GDP'!E17="",NA(),IF(ISNUMBER('Real and nominal GDP'!E17),'Real and nominal GDP'!E17,NA())),NA()) -> 60706.294 | G30: =IFERROR(IF('Real and nominal GDP'!F17="",NA(),IF(ISNUMBER('Real and nominal GDP'!F17),'Real and nominal GDP'!F17,NA())),NA()) -> 100741.05 | H30: =IFERROR(IF('Real and nominal GDP'!G17="",NA(),IF(ISNUMBER('Real and nominal GDP'!G17),'Real and nominal GDP'!G17,NA())),NA()) -> 614076.39 | I30: =IFERROR(IF('Real and nominal GDP'!H17="",NA(),IF(ISNUMBER('Real and nominal GDP'!H17),'Real and nominal GDP'!H17,NA())),NA()) -> 727989 | J30: =IFERROR(IF('Real and nominal GDP'!I17="",NA(),IF(ISNUMBER('Real and nominal GDP'!I17),'Real and nominal GDP'!I17,NA())),NA()) -> #N/A | K30: =IFERROR(IF('Real and nominal GDP'!J17="",NA(),IF(ISNUMBER('Real and nominal GDP'!J17),'Real and nominal GDP'!J17,NA())),NA()) -> 3.06794 | L30: =IFERROR(IF('Real and nominal GDP'!K17="",NA(),IF(ISNUMBER('Real and nominal GDP'!K17),'Real and nominal GDP'!K17,NA())),NA()) -> 3.083 | M30: =IFERROR(D30/D26-1,NA()) -> 0.064644368 | N30: =IFERROR(D30/D29-1,NA()) -> 0.012086538 | O30: =IFERROR(I30/I26-1,NA()) -> 0.20175413 | P30: =IF(COUNT(D27:D30)=4,SUM(D27:D30),NA()) -> 2185834.1 | Q30: =IF(COUNT(I27:I30)=4,SUM(I27:I30),NA()) -> 2585229 | R30: =IFERROR(I30/K30,NA()) -> 237289.19 | S30: =IFERROR(I30/L30,NA()) -> 236130.07 | V30: 2013 | W30: =IF(SUMPRODUCT(($C$21:$C$233=$V$30)*ISNUMBER($D$21:$D$233))=0,NA(),SUMPRODUCT(($C$21:$C$233=$V$30)*IFERROR($D$21:$D$233,0))) -> 2881628.4 | X30: =IF(SUMPRODUCT(($C$21:$C$233=$V$30)*ISNUMBER($E$21:$E$233))=0,NA(),SUMPRODUCT(($C$21:$C$233=$V$30)*IFERROR($E$21:$E$233,0))) -> 2102698.1 | Y30: =IF(SUMPRODUCT(($C$21:$C$233=$V$30)*ISNUMBER($F$21:$F$233))=0,NA(),SUMPRODUCT(($C$21:$C$233=$V$30)*IFERROR($F$21:$F$233,0))) -> 351665.15 | Z30: =IF(SUMPRODUCT(($C$21:$C$233=$V$30)*ISNUMBER($G$21:$G$233))=0,NA(),SUMPRODUCT(($C$21:$C$233=$V$30)*IFERROR($G$21:$G$233,0))) -> 584226.27 | AA30: =IF(SUMPRODUCT(($C$21:$C$233=$V$30)*ISNUMBER($H$21:$H$233))=0,NA(),SUMPRODUCT(($C$21:$C$233=$V$30)*IFERROR($H$21:$H$233,0))) -> 2881628.4 | AB30: =IF(SUMPRODUCT(($C$21:$C$233=$V$30)*ISNUMBER($I$21:$I$233))=0,NA(),SUMPRODUCT(($C$21:$C$233=$V$30)*IFERROR($I$21:$I$233,0))) -> 13393235 | AC30: =IF(SUMPRODUCT(($C$21:$C$233=$V$30)*ISNUMBER($J$21:$J$233))=0,NA(),SUMPRODUCT(($C$21:$C$233=$V$30)*IFERROR($J$21:$J$233,0))/SUMPRODUCT(($C$21:$C$233=$V$30)*ISNUMBER($J$21:$J$233))) -> 36.126767 | AD30: =IF(SUMPRODUCT(($C$21:$C$233=$V$30)*ISNUMBER($K$21:$K$233))=0,NA(),SUMPRODUCT(($C$21:$C$233=$V$30)*IFERROR($K$21:$K$233,0))/SUMPRODUCT(($C$21:$C$233=$V$30)*ISNUMBER($K$21:$K$233))) -> 5.478235 | AE30: =IF(SUMPRODUCT(($C$21:$C$233=$V$30)*ISNUMBER($L$21:$L$233))=0,NA(),SUMPRODUCT(($C$21:$C$233=$V$30)*IFERROR($L$21:$L$233,0))/SUMPRODUCT(($C$21:$C$233=$V$30)*ISNUMBER($L$21:$L$233))) -> 8.74525 | AF30: =IFERROR(W30/W29-1,NA()) -> 0.024053238
A31: =IFERROR(IF(ISNUMBER('Real and nominal GDP'!A18),'Real and nominal GDP'!A18,NA()),NA()) -> 38961 | B31: =IFERROR(IF('Real and nominal GDP'!B18="",NA(),'Real and nominal GDP'!B18),NA()) -> 063 | C31: =IFERROR(YEAR(A31),0) -> 2006 | D31: =IFERROR(IF('Real and nominal GDP'!C18="",NA(),IF(ISNUMBER('Real and nominal GDP'!C18),'Real and nominal GDP'!C18,NA())),NA()) -> 577088.46 | E31: =IFERROR(IF('Real and nominal GDP'!D18="",NA(),IF(ISNUMBER('Real and nominal GDP'!D18),'Real and nominal GDP'!D18,NA())),NA()) -> 381137.22 | F31: =IFERROR(IF('Real and nominal GDP'!E18="",NA(),IF(ISNUMBER('Real and nominal GDP'!E18),'Real and nominal GDP'!E18,NA())),NA()) -> 61658.229 | G31: =IFERROR(IF('Real and nominal GDP'!F18="",NA(),IF(ISNUMBER('Real and nominal GDP'!F18),'Real and nominal GDP'!F18,NA())),NA()) -> 103927.85 | H31: =IFERROR(IF('Real and nominal GDP'!G18="",NA(),IF(ISNUMBER('Real and nominal GDP'!G18),'Real and nominal GDP'!G18,NA())),NA()) -> 562978.97 | I31: =IFERROR(IF('Real and nominal GDP'!H18="",NA(),IF(ISNUMBER('Real and nominal GDP'!H18),'Real and nominal GDP'!H18,NA())),NA()) -> 729299 | J31: =IFERROR(IF('Real and nominal GDP'!I18="",NA(),IF(ISNUMBER('Real and nominal GDP'!I18),'Real and nominal GDP'!I18,NA())),NA()) -> #N/A | K31: =IFERROR(IF('Real and nominal GDP'!J18="",NA(),IF(ISNUMBER('Real and nominal GDP'!J18),'Real and nominal GDP'!J18,NA())),NA()) -> 3.0872567 | L31: =IFERROR(IF('Real and nominal GDP'!K18="",NA(),IF(ISNUMBER('Real and nominal GDP'!K18),'Real and nominal GDP'!K18,NA())),NA()) -> 3.1033333 | M31: =IFERROR(D31/D27-1,NA()) -> 0.088636722 | N31: =IFERROR(D31/D30-1,NA()) -> 0.028389967 | O31: =IFERROR(I31/I27-1,NA()) -> 0.23563925 | P31: =IF(COUNT(D28:D31)=4,SUM(D28:D31),NA()) -> 2232820.6 | Q31: =IF(COUNT(I28:I31)=4,SUM(I28:I31),NA()) -> 2724308 | R31: =IFERROR(I31/K31,NA()) -> 236228.82 | S31: =IFERROR(I31/L31,NA()) -> 235005.05 | V31: 2014 | W31: =IF(SUMPRODUCT(($C$21:$C$233=$V$31)*ISNUMBER($D$21:$D$233))=0,NA(),SUMPRODUCT(($C$21:$C$233=$V$31)*IFERROR($D$21:$D$233,0))) -> 2809224.2 | X31: =IF(SUMPRODUCT(($C$21:$C$233=$V$31)*ISNUMBER($E$21:$E$233))=0,NA(),SUMPRODUCT(($C$21:$C$233=$V$31)*IFERROR($E$21:$E$233,0))) -> 2011057.7 | Y31: =IF(SUMPRODUCT(($C$21:$C$233=$V$31)*ISNUMBER($F$21:$F$233))=0,NA(),SUMPRODUCT(($C$21:$C$233=$V$31)*IFERROR($F$21:$F$233,0))) -> 362021.8 | Z31: =IF(SUMPRODUCT(($C$21:$C$233=$V$31)*ISNUMBER($G$21:$G$233))=0,NA(),SUMPRODUCT(($C$21:$C$233=$V$31)*IFERROR($G$21:$G$233,0))) -> 544758.59 | AA31: =IF(SUMPRODUCT(($C$21:$C$233=$V$31)*ISNUMBER($H$21:$H$233))=0,NA(),SUMPRODUCT(($C$21:$C$233=$V$31)*IFERROR($H$21:$H$233,0))) -> 2809224.2 | AB31: =IF(SUMPRODUCT(($C$21:$C$233=$V$31)*ISNUMBER($I$21:$I$233))=0,NA(),SUMPRODUCT(($C$21:$C$233=$V$31)*IFERROR($I$21:$I$233,0))) -> 18316346 | AC31: =IF(SUMPRODUCT(($C$21:$C$233=$V$31)*ISNUMBER($J$21:$J$233))=0,NA(),SUMPRODUCT(($C$21:$C$233=$V$31)*IFERROR($J$21:$J$233,0))/SUMPRODUCT(($C$21:$C$233=$V$31)*ISNUMBER($J$21:$J$233))) -> 49.884083 | AD31: =IF(SUMPRODUCT(($C$21:$C$233=$V$31)*ISNUMBER($K$21:$K$233))=0,NA(),SUMPRODUCT(($C$21:$C$233=$V$31)*IFERROR($K$21:$K$233,0))/SUMPRODUCT(($C$21:$C$233=$V$31)*ISNUMBER($K$21:$K$233))) -> 8.1250867 | AE31: =IF(SUMPRODUCT(($C$21:$C$233=$V$31)*ISNUMBER($L$21:$L$233))=0,NA(),SUMPRODUCT(($C$21:$C$233=$V$31)*IFERROR($L$21:$L$233,0))/SUMPRODUCT(($C$21:$C$233=$V$31)*ISNUMBER($L$21:$L$233))) -> 12.38425 | AF31: =IFERROR(W31/W30-1,NA()) -> -0.025126153
A32: =IFERROR(IF(ISNUMBER('Real and nominal GDP'!A19),'Real and nominal GDP'!A19,NA()),NA()) -> 39052 | B32: =IFERROR(IF('Real and nominal GDP'!B19="",NA(),'Real and nominal GDP'!B19),NA()) -> 064 | C32: =IFERROR(YEAR(A32),0) -> 2006 | D32: =IFERROR(IF('Real and nominal GDP'!C19="",NA(),IF(ISNUMBER('Real and nominal GDP'!C19),'Real and nominal GDP'!C19,NA())),NA()) -> 589496.16 | E32: =IFERROR(IF('Real and nominal GDP'!D19="",NA(),IF(ISNUMBER('Real and nominal GDP'!D19),'Real and nominal GDP'!D19,NA())),NA()) -> 380937.31 | F32: =IFERROR(IF('Real and nominal GDP'!E19="",NA(),IF(ISNUMBER('Real and nominal GDP'!E19),'Real and nominal GDP'!E19,NA())),NA()) -> 62861.894 | G32: =IFERROR(IF('Real and nominal GDP'!F19="",NA(),IF(ISNUMBER('Real and nominal GDP'!F19),'Real and nominal GDP'!F19,NA())),NA()) -> 106810.9 | H32: =IFERROR(IF('Real and nominal GDP'!G19="",NA(),IF(ISNUMBER('Real and nominal GDP'!G19),'Real and nominal GDP'!G19,NA())),NA()) -> 572794.05 | I32: =IFERROR(IF('Real and nominal GDP'!H19="",NA(),IF(ISNUMBER('Real and nominal GDP'!H19),'Real and nominal GDP'!H19,NA())),NA()) -> 762766 | J32: =IFERROR(IF('Real and nominal GDP'!I19="",NA(),IF(ISNUMBER('Real and nominal GDP'!I19),'Real and nominal GDP'!I19,NA())),NA()) -> #N/A | K32: =IFERROR(IF('Real and nominal GDP'!J19="",NA(),IF(ISNUMBER('Real and nominal GDP'!J19),'Real and nominal GDP'!J19,NA())),NA()) -> 3.0774 | L32: =IFERROR(IF('Real and nominal GDP'!K19="",NA(),IF(ISNUMBER('Real and nominal GDP'!K19),'Real and nominal GDP'!K19,NA())),NA()) -> 3.098 | M32: =IFERROR(D32/D28-1,NA()) -> 0.091418731 | N32: =IFERROR(D32/D31-1,NA()) -> 0.021500525 | O32: =IFERROR(I32/I28-1,NA()) -> 0.22344408 | P32: =IF(COUNT(D29:D32)=4,SUM(D29:D32),NA()) -> 2282197.6 | Q32: =IF(COUNT(I29:I32)=4,SUM(I29:I32),NA()) -> 2863616 | R32: =IFERROR(I32/K32,NA()) -> 247860.53 | S32: =IFERROR(I32/L32,NA()) -> 246212.4 | V32: 2015 | W32: =IF(SUMPRODUCT(($C$21:$C$233=$V$32)*ISNUMBER($D$21:$D$233))=0,NA(),SUMPRODUCT(($C$21:$C$233=$V$32)*IFERROR($D$21:$D$233,0))) -> 2885948.6 | X32: =IF(SUMPRODUCT(($C$21:$C$233=$V$32)*ISNUMBER($E$21:$E$233))=0,NA(),SUMPRODUCT(($C$21:$C$233=$V$32)*IFERROR($E$21:$E$233,0))) -> 2084586 | Y32: =IF(SUMPRODUCT(($C$21:$C$233=$V$32)*ISNUMBER($F$21:$F$233))=0,NA(),SUMPRODUCT(($C$21:$C$233=$V$32)*IFERROR($F$21:$F$233,0))) -> 387167.85 | Z32: =IF(SUMPRODUCT(($C$21:$C$233=$V$32)*ISNUMBER($G$21:$G$233))=0,NA(),SUMPRODUCT(($C$21:$C$233=$V$32)*IFERROR($G$21:$G$233,0))) -> 563620.88 | AA32: =IF(SUMPRODUCT(($C$21:$C$233=$V$32)*ISNUMBER($H$21:$H$233))=0,NA(),SUMPRODUCT(($C$21:$C$233=$V$32)*IFERROR($H$21:$H$233,0))) -> 2885948.6 | AB32: =IF(SUMPRODUCT(($C$21:$C$233=$V$32)*ISNUMBER($I$21:$I$233))=0,NA(),SUMPRODUCT(($C$21:$C$233=$V$32)*IFERROR($I$21:$I$233,0))) -> 23818044 | AC32: =IF(SUMPRODUCT(($C$21:$C$233=$V$32)*ISNUMBER($J$21:$J$233))=0,NA(),SUMPRODUCT(($C$21:$C$233=$V$32)*IFERROR($J$21:$J$233,0))/SUMPRODUCT(($C$21:$C$233=$V$32)*ISNUMBER($J$21:$J$233))) -> 63.122508 | AD32: =IF(SUMPRODUCT(($C$21:$C$233=$V$32)*ISNUMBER($K$21:$K$233))=0,NA(),SUMPRODUCT(($C$21:$C$233=$V$32)*IFERROR($K$21:$K$233,0))/SUMPRODUCT(($C$21:$C$233=$V$32)*ISNUMBER($K$21:$K$233))) -> 9.2673817 | AE32: =IF(SUMPRODUCT(($C$21:$C$233=$V$32)*ISNUMBER($L$21:$L$233))=0,NA(),SUMPRODUCT(($C$21:$C$233=$V$32)*IFERROR($L$21:$L$233,0))/SUMPRODUCT(($C$21:$C$233=$V$32)*ISNUMBER($L$21:$L$233))) -> 13.982583 | AF32: =IFERROR(W32/W31-1,NA()) -> 0.027311598
A33: =IFERROR(IF(ISNUMBER('Real and nominal GDP'!A20),'Real and nominal GDP'!A20,NA()),NA()) -> 39142 | B33: =IFERROR(IF('Real and nominal GDP'!B20="",NA(),'Real and nominal GDP'!B20),NA()) -> 071 | C33: =IFERROR(YEAR(A33),0) -> 2007 | D33: =IFERROR(IF('Real and nominal GDP'!C20="",NA(),IF(ISNUMBER('Real and nominal GDP'!C20),'Real and nominal GDP'!C20,NA())),NA()) -> 603483.21 | E33: =IFERROR(IF('Real and nominal GDP'!D20="",NA(),IF(ISNUMBER('Real and nominal GDP'!D20),'Real and nominal GDP'!D20,NA())),NA()) -> 392667.41 | F33: =IFERROR(IF('Real and nominal GDP'!E20="",NA(),IF(ISNUMBER('Real and nominal GDP'!E20),'Real and nominal GDP'!E20,NA())),NA()) -> 65392.759 | G33: =IFERROR(IF('Real and nominal GDP'!F20="",NA(),IF(ISNUMBER('Real and nominal GDP'!F20),'Real and nominal GDP'!F20,NA())),NA()) -> 116267.52 | H33: =IFERROR(IF('Real and nominal GDP'!G20="",NA(),IF(ISNUMBER('Real and nominal GDP'!G20),'Real and nominal GDP'!G20,NA())),NA()) -> 576846.89 | I33: =IFERROR(IF('Real and nominal GDP'!H20="",NA(),IF(ISNUMBER('Real and nominal GDP'!H20),'Real and nominal GDP'!H20,NA())),NA()) -> 774388 | J33: =IFERROR(IF('Real and nominal GDP'!I20="",NA(),IF(ISNUMBER('Real and nominal GDP'!I20),'Real and nominal GDP'!I20,NA())),NA()) -> #N/A | K33: =IFERROR(IF('Real and nominal GDP'!J20="",NA(),IF(ISNUMBER('Real and nominal GDP'!J20),'Real and nominal GDP'!J20,NA())),NA()) -> 3.09675 | L33: =IFERROR(IF('Real and nominal GDP'!K20="",NA(),IF(ISNUMBER('Real and nominal GDP'!K20),'Real and nominal GDP'!K20,NA())),NA()) -> 3.114 | M33: =IFERROR(D33/D29-1,NA()) -> 0.088424429 | N33: =IFERROR(D33/D32-1,NA()) -> 0.023727116 | O33: =IFERROR(I33/I29-1,NA()) -> 0.20328422 | P33: =IF(COUNT(D30:D33)=4,SUM(D30:D33),NA()) -> 2331225.1 | Q33: =IF(COUNT(I30:I33)=4,SUM(I30:I33),NA()) -> 2994442 | R33: =IFERROR(I33/K33,NA()) -> 250064.75 | S33: =IFERROR(I33/L33,NA()) -> 248679.51 | V33: 2016 | W33: =IF(SUMPRODUCT(($C$21:$C$233=$V$33)*ISNUMBER($D$21:$D$233))=0,NA(),SUMPRODUCT(($C$21:$C$233=$V$33)*IFERROR($D$21:$D$233,0))) -> 2825911.4 | X33: =IF(SUMPRODUCT(($C$21:$C$233=$V$33)*ISNUMBER($E$21:$E$233))=0,NA(),SUMPRODUCT(($C$21:$C$233=$V$33)*IFERROR($E$21:$E$233,0))) -> 2068320.6 | Y33: =IF(SUMPRODUCT(($C$21:$C$233=$V$33)*ISNUMBER($F$21:$F$233))=0,NA(),SUMPRODUCT(($C$21:$C$233=$V$33)*IFERROR($F$21:$F$233,0))) -> 385137.64 | Z33: =IF(SUMPRODUCT(($C$21:$C$233=$V$33)*ISNUMBER($G$21:$G$233))=0,NA(),SUMPRODUCT(($C$21:$C$233=$V$33)*IFERROR($G$21:$G$233,0))) -> 531052.22 | AA33: =IF(SUMPRODUCT(($C$21:$C$233=$V$33)*ISNUMBER($H$21:$H$233))=0,NA(),SUMPRODUCT(($C$21:$C$233=$V$33)*IFERROR($H$21:$H$233,0))) -> 2825911.4 | AB33: =IF(SUMPRODUCT(($C$21:$C$233=$V$33)*ISNUMBER($I$21:$I$233))=0,NA(),SUMPRODUCT(($C$21:$C$233=$V$33)*IFERROR($I$21:$I$233,0))) -> 32912638 | AC33: =IF(SUMPRODUCT(($C$21:$C$233=$V$33)*ISNUMBER($J$21:$J$233))=0,NA(),SUMPRODUCT(($C$21:$C$233=$V$33)*IFERROR($J$21:$J$233,0))/SUMPRODUCT(($C$21:$C$233=$V$33)*ISNUMBER($J$21:$J$233))) -> 89.248583 | AD33: =IF(SUMPRODUCT(($C$21:$C$233=$V$33)*ISNUMBER($K$21:$K$233))=0,NA(),SUMPRODUCT(($C$21:$C$233=$V$33)*IFERROR($K$21:$K$233,0))/SUMPRODUCT(($C$21:$C$233=$V$33)*ISNUMBER($K$21:$K$233))) -> 14.781018 | AE33: =IF(SUMPRODUCT(($C$21:$C$233=$V$33)*ISNUMBER($L$21:$L$233))=0,NA(),SUMPRODUCT(($C$21:$C$233=$V$33)*IFERROR($L$21:$L$233,0))/SUMPRODUCT(($C$21:$C$233=$V$33)*ISNUMBER($L$21:$L$233))) -> 15.0565 | AF33: =IFERROR(W33/W32-1,NA()) -> -0.020803278
A34: =IFERROR(IF(ISNUMBER('Real and nominal GDP'!A21),'Real and nominal GDP'!A21,NA()),NA()) -> 39234 | B34: =IFERROR(IF('Real and nominal GDP'!B21="",NA(),'Real and nominal GDP'!B21),NA()) -> 072 | C34: =IFERROR(YEAR(A34),0) -> 2007 | D34: =IFERROR(IF('Real and nominal GDP'!C21="",NA(),IF(ISNUMBER('Real and nominal GDP'!C21),'Real and nominal GDP'!C21,NA())),NA()) -> 616073.37 | E34: =IFERROR(IF('Real and nominal GDP'!D21="",NA(),IF(ISNUMBER('Real and nominal GDP'!D21),'Real and nominal GDP'!D21,NA())),NA()) -> 402296.08 | F34: =IFERROR(IF('Real and nominal GDP'!E21="",NA(),IF(ISNUMBER('Real and nominal GDP'!E21),'Real and nominal GDP'!E21,NA())),NA()) -> 65948.641 | G34: =IFERROR(IF('Real and nominal GDP'!F21="",NA(),IF(ISNUMBER('Real and nominal GDP'!F21),'Real and nominal GDP'!F21,NA())),NA()) -> 121508.99 | H34: =IFERROR(IF('Real and nominal GDP'!G21="",NA(),IF(ISNUMBER('Real and nominal GDP'!G21),'Real and nominal GDP'!G21,NA())),NA()) -> 674620.56 | I34: =IFERROR(IF('Real and nominal GDP'!H21="",NA(),IF(ISNUMBER('Real and nominal GDP'!H21),'Real and nominal GDP'!H21,NA())),NA()) -> 904350 | J34: =IFERROR(IF('Real and nominal GDP'!I21="",NA(),IF(ISNUMBER('Real and nominal GDP'!I21),'Real and nominal GDP'!I21,NA())),NA()) -> #N/A | K34: =IFERROR(IF('Real and nominal GDP'!J21="",NA(),IF(ISNUMBER('Real and nominal GDP'!J21),'Real and nominal GDP'!J21,NA())),NA()) -> 3.0828667 | L34: =IFERROR(IF('Real and nominal GDP'!K21="",NA(),IF(ISNUMBER('Real and nominal GDP'!K21),'Real and nominal GDP'!K21,NA())),NA()) -> 3.111 | M34: =IFERROR(D34/D30-1,NA()) -> 0.097862312 | N34: =IFERROR(D34/D33-1,NA()) -> 0.020862484 | O34: =IFERROR(I34/I30-1,NA()) -> 0.24225778 | P34: =IF(COUNT(D31:D34)=4,SUM(D31:D34),NA()) -> 2386141.2 | Q34: =IF(COUNT(I31:I34)=4,SUM(I31:I34),NA()) -> 3170803 | R34: =IFERROR(I34/K34,NA()) -> 293347.1 | S34: =IFERROR(I34/L34,NA()) -> 290694.31 | V34: 2017 | W34: =IF(SUMPRODUCT(($C$21:$C$233=$V$34)*ISNUMBER($D$21:$D$233))=0,NA(),SUMPRODUCT(($C$21:$C$233=$V$34)*IFERROR($D$21:$D$233,0))) -> 2905559.8 | X34: =IF(SUMPRODUCT(($C$21:$C$233=$V$34)*ISNUMBER($E$21:$E$233))=0,NA(),SUMPRODUCT(($C$21:$C$233=$V$34)*IFERROR($E$21:$E$233,0))) -> 2154330.5 | Y34: =IF(SUMPRODUCT(($C$21:$C$233=$V$34)*ISNUMBER($F$21:$F$233))=0,NA(),SUMPRODUCT(($C$21:$C$233=$V$34)*IFERROR($F$21:$F$233,0))) -> 395294.2 | Z34: =IF(SUMPRODUCT(($C$21:$C$233=$V$34)*ISNUMBER($G$21:$G$233))=0,NA(),SUMPRODUCT(($C$21:$C$233=$V$34)*IFERROR($G$21:$G$233,0))) -> 602110.06 | AA34: =IF(SUMPRODUCT(($C$21:$C$233=$V$34)*ISNUMBER($H$21:$H$233))=0,NA(),SUMPRODUCT(($C$21:$C$233=$V$34)*IFERROR($H$21:$H$233,0))) -> 2905559.8 | AB34: =IF(SUMPRODUCT(($C$21:$C$233=$V$34)*ISNUMBER($I$21:$I$233))=0,NA(),SUMPRODUCT(($C$21:$C$233=$V$34)*IFERROR($I$21:$I$233,0))) -> 42640914 | AC34: =IF(SUMPRODUCT(($C$21:$C$233=$V$34)*ISNUMBER($J$21:$J$233))=0,NA(),SUMPRODUCT(($C$21:$C$233=$V$34)*IFERROR($J$21:$J$233,0))/SUMPRODUCT(($C$21:$C$233=$V$34)*ISNUMBER($J$21:$J$233))) -> 112.88711 | AD34: =IF(SUMPRODUCT(($C$21:$C$233=$V$34)*ISNUMBER($K$21:$K$233))=0,NA(),SUMPRODUCT(($C$21:$C$233=$V$34)*IFERROR($K$21:$K$233,0))/SUMPRODUCT(($C$21:$C$233=$V$34)*ISNUMBER($K$21:$K$233))) -> 16.561602 | AE34: =IF(SUMPRODUCT(($C$21:$C$233=$V$34)*ISNUMBER($L$21:$L$233))=0,NA(),SUMPRODUCT(($C$21:$C$233=$V$34)*IFERROR($L$21:$L$233,0))/SUMPRODUCT(($C$21:$C$233=$V$34)*ISNUMBER($L$21:$L$233))) -> 16.974583 | AF34: =IFERROR(W34/W33-1,NA()) -> 0.02818503
