Workbook

Sheet Read me
B2: Argentina inflation — INDEC IPC seasonality pack
B3: Data through 2026-06. Built automatically from INDEC national CPI.
B5: What's in here
B6: Data | C6: Every INDEC national CPI series used here, as index levels (blue = hardcoded from source) with month-on-month, year-on-year, 3m annualised and year-to-date calculated by formula.
B7: Seasonality Headline | C7: The chart you asked for: x-axis Jan-Dec, one line per year 2019 onwards, values = monthly headline m/m.
B8: Seasonality Core | C8: Same, for IPC Núcleo (core).
B9: Heatmap | C9: Year x month grid, colour-scaled — the fastest way to see which months run hot in a given regime.
B10: Momentum | C10: 3-month annualised vs year-on-year, headline and core. Shows turning points ~9 months before the y/y does.
B11: Components | C11: Núcleo vs Regulados vs Estacionales — where the 2026 pressure actually sits.
B12: Seasonal Factors | C12: Each month's m/m divided by that year's average month. Scale-free, so 2023 (211%) and 2025 (31%) are comparable. 1.20x = that month runs 20% hotter than a typical month of the same year.
B13: Forecast | C13: Bull / base / bear monthly paths to Dec-2027 with the FX and tariff assumptions behind each, benchmarked to the BCRA REM.
B15: Source | C15: INDEC, Índice de precios al consumidor nacional (base dic-2016 = 100), retrieved from the official series API at apis.datos.gob.ar (series 148.3_INIVELNAL_DICI_M_26, 148.3_INUCLEONAL_DICI_M_19, 148.3_IREGULANAL_DICI_M_22, 148.3_IESTACINAL_DICI_M_25).
B16: Validation | C16: Compounded monthly rates reproduce INDEC's published Dec/Dec prints exactly: 2019 53.8%, 2020 36.1%, 2021 50.9%, 2022 94.8%, 2023 211.4%, 2024 117.8%, 2025 31.5%. June-2026 y/y 33.5% and YTD 16.8% also match the official release.
B18: How to update
B19: Option 1 — automatic | C19: A scheduled task re-runs this build every month on the 16th (INDEC publishes around the 13th-15th) and sends you the refreshed workbook. Nothing to do.
B20: Option 2 — by hand | C20: On the Data tab, find the first empty yellow row and paste the new index levels into columns E-H. Every m/m, y/y, matrix and heatmap cell updates by formula. Chart series ranges cover the full calendar year, so a part-year line will read zero for months you have not filled — the automatic rebuild handles that for you.
B21: Caution | C21: INDEC occasionally revises the seasonal and regulated sub-indices. The automatic rebuild re-pulls the whole history each month, so revisions flow through; a manual paste-in does not restate history.

Sheet Data
B2: INDEC IPC nacional — index levels and derived rates
B3: Blue = hardcoded index level from INDEC. Black = formula. Paste new prints into the yellow rows.
B5: Month | C5: Year | D5: M# | E5: Nivel General (index) | F5: Núcleo (index) | G5: Regulados (index) | H5: Estacionales (index) | I5: m/m Nivel Gen. | J5: m/m Núcleo | K5: m/m Regulados | L5: m/m Estacion. | M5: y/y Nivel Gen. | N5: y/y Núcleo | O5: 3m ann. Nivel Gen. | P5: 3m ann. Núcleo | Q5: YTD Nivel Gen.
B6: 2018-12 | C6: 2018 | D6: 12 | E6: 184.2552 | F6: 178.9326
B7: 2019-01 | C7: 2019 | D7: 1 | E7: 189.6101 | F7: 184.3056 | I7: =IF(OR(E7="",E6=""),"",E7/E6-1) -> 0.029062409 | J7: =IF(OR(F7="",F6=""),"",F7/F6-1) -> 0.030028066 | K7: =IF(OR(G7="",G6=""),"",G7/G6-1) | L7: =IF(OR(H7="",H6=""),"",H7/H6-1) | Q7: =IF(E7="","",IFERROR(E7/INDEX($E:$E,MATCH(C7-1&"-12",$B:$B,0))-1,"")) -> 0.029062409
B8: 2019-02 | C8: 2019 | D8: 2 | E8: 196.7501 | F8: 191.4115 | I8: =IF(OR(E8="",E7=""),"",E8/E7-1) -> 0.037656222 | J8: =IF(OR(F8="",F7=""),"",F8/F7-1) -> 0.038554987 | K8: =IF(OR(G8="",G7=""),"",G8/G7-1) | L8: =IF(OR(H8="",H7=""),"",H8/H7-1) | Q8: =IF(E8="","",IFERROR(E8/INDEX($E:$E,MATCH(C8-1&"-12",$B:$B,0))-1,"")) -> 0.067813012
B9: 2019-03 | C9: 2019 | D9: 3 | E9: 205.9571 | F9: 200.1771 | I9: =IF(OR(E9="",E8=""),"",E9/E8-1) -> 0.046795402 | J9: =IF(OR(F9="",F8=""),"",F9/F8-1) -> 0.045794532 | K9: =IF(OR(G9="",G8=""),"",G9/G8-1) | L9: =IF(OR(H9="",H8=""),"",H9/H8-1) | O9: =IF(OR(E9="",E6=""),"",(E9/E6)^4-1) -> 0.56109042 | P9: =IF(OR(F9="",F6=""),"",(F9/F6)^4-1) -> 0.56638921 | Q9: =IF(E9="","",IFERROR(E9/INDEX($E:$E,MATCH(C9-1&"-12",$B:$B,0))-1,"")) -> 0.11778175
B10: 2019-04 | C10: 2019 | D10: 4 | E10: 212.95964 | F10: 207.7179 | I10: =IF(OR(E10="",E9=""),"",E10/E9-1) -> 0.034 | J10: =IF(OR(F10="",F9=""),"",F10/F9-1) -> 0.037670643 | K10: =IF(OR(G10="",G9=""),"",G10/G9-1) | L10: =IF(OR(H10="",H9=""),"",H10/H9-1) | O10: =IF(OR(E10="",E7=""),"",(E10/E7)^4-1) -> 0.59126811 | P10: =IF(OR(F10="",F7=""),"",(F10/F7)^4-1) -> 0.6133982 | Q10: =IF(E10="","",IFERROR(E10/INDEX($E:$E,MATCH(C10-1&"-12",$B:$B,0))-1,"")) -> 0.15578633
B11: 2019-05 | C11: 2019 | D11: 5 | E11: 219.5691 | F11: 214.3182 | I11: =IF(OR(E11="",E10=""),"",E11/E10-1) -> 0.031036203 | J11: =IF(OR(F11="",F10=""),"",F11/F10-1) -> 0.031775307 | K11: =IF(OR(G11="",G10=""),"",G11/G10-1) | L11: =IF(OR(H11="",H10=""),"",H11/H10-1) | O11: =IF(OR(E11="",E8=""),"",(E11/E8)^4-1) -> 0.55104729 | P11: =IF(OR(F11="",F8=""),"",(F11/F8)^4-1) -> 0.57167992 | Q11: =IF(E11="","",IFERROR(E11/INDEX($E:$E,MATCH(C11-1&"-12",$B:$B,0))-1,"")) -> 0.19165755
B12: 2019-06 | C12: 2019 | D12: 6 | E12: 225.537 | F12: 220.1725 | I12: =IF(OR(E12="",E11=""),"",E12/E11-1) -> 0.027180054 | J12: =IF(OR(F12="",F11=""),"",F12/F11-1) -> 0.027315926 | K12: =IF(OR(G12="",G11=""),"",G12/G11-1) | L12: =IF(OR(H12="",H11=""),"",H12/H11-1) | O12: =IF(OR(E12="",E9=""),"",(E12/E9)^4-1) -> 0.43801735 | P12: =IF(OR(F12="",F9=""),"",(F12/F9)^4-1) -> 0.46350672 | Q12: =IF(E12="","",IFERROR(E12/INDEX($E:$E,MATCH(C12-1&"-12",$B:$B,0))-1,"")) -> 0.22404687
B13: 2019-07 | C13: 2019 | D13: 7 | E13: 230.494 | F13: 224.9011 | I13: =IF(OR(E13="",E12=""),"",E13/E12-1) -> 0.021978655 | J13: =IF(OR(F13="",F12=""),"",F13/F12-1) -> 0.021476797 | K13: =IF(OR(G13="",G12=""),"",G13/G12-1) | L13: =IF(OR(H13="",H12=""),"",H13/H12-1) | O13: =IF(OR(E13="",E10=""),"",(E13/E10)^4-1) -> 0.37230066 | P13: =IF(OR(F13="",F10=""),"",(F13/F10)^4-1) -> 0.37426544 | Q13: =IF(E13="","",IFERROR(E13/INDEX($E:$E,MATCH(C13-1&"-12",$B:$B,0))-1,"")) -> 0.25094977
B14: 2019-08 | C14: 2019 | D14: 8 | E14: 239.6077 | F14: 235.3317 | I14: =IF(OR(E14="",E13=""),"",E14/E13-1) -> 0.039539858 | J14: =IF(OR(F14="",F13=""),"",F14/F13-1) -> 0.046378608 | K14: =IF(OR(G14="",G13=""),"",G14/G13-1) | L14: =IF(OR(H14="",H13=""),"",H14/H13-1) | O14: =IF(OR(E14="",E11=""),"",(E14/E11)^4-1) -> 0.41813702 | P14: =IF(OR(F14="",F11=""),"",(F14/F11)^4-1) -> 0.4537359 | Q14: =IF(E14="","",IFERROR(E14/INDEX($E:$E,MATCH(C14-1&"-12",$B:$B,0))-1,"")) -> 0.30041215
B15: 2019-09 | C15: 2019 | D15: 9 | E15: 253.7102 | F15: 250.4818 | I15: =IF(OR(E15="",E14=""),"",E15/E14-1) -> 0.058856623 | J15: =IF(OR(F15="",F14=""),"",F15/F14-1) -> 0.064377642 | K15: =IF(OR(G15="",G14=""),"",G15/G14-1) | L15: =IF(OR(H15="",H14=""),"",H15/H14-1) | O15: =IF(OR(E15="",E12=""),"",(E15/E12)^4-1) -> 0.6013288 | P15: =IF(OR(F15="",F12=""),"",(F15/F12)^4-1) -> 0.67514501 | Q15: =IF(E15="","",IFERROR(E15/INDEX($E:$E,MATCH(C15-1&"-12",$B:$B,0))-1,"")) -> 0.37695001
B16: 2019-10 | C16: 2019 | D16: 10 | E16: 262.0661 | F16: 260.0118 | I16: =IF(OR(E16="",E15=""),"",E16/E15-1) -> 0.032934821 | J16: =IF(OR(F16="",F15=""),"",F16/F15-1) -> 0.038046676 | K16: =IF(OR(G16="",G15=""),"",G16/G15-1) | L16: =IF(OR(H16="",H15=""),"",H16/H15-1) | O16: =IF(OR(E16="",E13=""),"",(E16/E13)^4-1) -> 0.67110941 | P16: =IF(OR(F16="",F13=""),"",(F16/F13)^4-1) -> 0.7865119 | Q16: =IF(E16="","",IFERROR(E16/INDEX($E:$E,MATCH(C16-1&"-12",$B:$B,0))-1,"")) -> 0.42229961
B17: 2019-11 | C17: 2019 | D17: 11 | E17: 273.2158 | F17: 270.3554 | I17: =IF(OR(E17="",E16=""),"",E17/E16-1) -> 0.042545373 | J17: =IF(OR(F17="",F16=""),"",F17/F16-1) -> 0.039781271 | K17: =IF(OR(G17="",G16=""),"",G17/G16-1) | L17: =IF(OR(H17="",H16=""),"",H17/H16-1) | O17: =IF(OR(E17="",E14=""),"",(E17/E14)^4-1) -> 0.69051941 | P17: =IF(OR(F17="",F14=""),"",(F17/F14)^4-1) -> 0.74188093 | Q17: =IF(E17="","",IFERROR(E17/INDEX($E:$E,MATCH(C17-1&"-12",$B:$B,0))-1,"")) -> 0.48281188
B18: 2019-12 | C18: 2019 | D18: 12 | E18: 283.4442 | F18: 280.3107 | I18: =IF(OR(E18="",E17=""),"",E18/E17-1) -> 0.037437074 | J18: =IF(OR(F18="",F17=""),"",F18/F17-1) -> 0.036823011 | K18: =IF(OR(G18="",G17=""),"",G18/G17-1) | L18: =IF(OR(H18="",H17=""),"",H18/H17-1) | M18: =IF(OR(E18="",E6=""),"",E18/E6-1) -> 0.53832402 | N18: =IF(OR(F18="",F6=""),"",F18/F6-1) -> 0.56657144 | O18: =IF(OR(E18="",E15=""),"",(E18/E15)^4-1) -> 0.55782471 | P18: =IF(OR(F18="",F15=""),"",(F18/F15)^4-1) -> 0.56838977 | Q18: =IF(E18="","",IFERROR(E18/INDEX($E:$E,MATCH(C18-1&"-12",$B:$B,0))-1,"")) -> 0.53832402
B19: 2020-01 | C19: 2020 | D19: 1 | E19: 289.8299 | F19: 287.1529 | I19: =IF(OR(E19="",E18=""),"",E19/E18-1) -> 0.022528949 | J19: =IF(OR(F19="",F18=""),"",F19/F18-1) -> 0.024409343 | K19: =IF(OR(G19="",G18=""),"",G19/G18-1) | L19: =IF(OR(H19="",H18=""),"",H19/H18-1) | M19: =IF(OR(E19="",E7=""),"",E19/E7-1) -> 0.52855729 | N19: =IF(OR(F19="",F7=""),"",F19/F7-1) -> 0.55802591 | O19: =IF(OR(E19="",E16=""),"",(E19/E16)^4-1) -> 0.49599232 | P19: =IF(OR(F19="",F16=""),"",(F19/F16)^4-1) -> 0.48758091 | Q19: =IF(E19="","",IFERROR(E19/INDEX($E:$E,MATCH(C19-1&"-12",$B:$B,0))-1,"")) -> 0.022528949
B20: 2020-02 | C20: 2020 | D20: 2 | E20: 295.666 | F20: 293.9922 | I20: =IF(OR(E20="",E19=""),"",E20/E19-1) -> 0.020136294 | J20: =IF(OR(F20="",F19=""),"",F20/F19-1) -> 0.023817625 | K20: =IF(OR(G20="",G19=""),"",G20/G19-1) | L20: =IF(OR(H20="",H19=""),"",H20/H19-1) | M20: =IF(OR(E20="",E8=""),"",E20/E8-1) -> 0.50274892 | N20: =IF(OR(F20="",F8=""),"",F20/F8-1) -> 0.53591712 | O20: =IF(OR(E20="",E17=""),"",(E20/E17)^4-1) -> 0.37145733 | P20: =IF(OR(F20="",F17=""),"",(F20/F17)^4-1) -> 0.39830863 | Q20: =IF(E20="","",IFERROR(E20/INDEX($E:$E,MATCH(C20-1&"-12",$B:$B,0))-1,"")) -> 0.043118893
B21: 2020-03 | C21: 2020 | D21: 3 | E21: 305.5515 | F21: 303.1665 | I21: =IF(OR(E21="",E20=""),"",E21/E20-1) -> 0.033434686 | J21: =IF(OR(F21="",F20=""),"",F21/F20-1) -> 0.03120593 | K21: =IF(OR(G21="",G20=""),"",G21/G20-1) | L21: =IF(OR(H21="",H20=""),"",H21/H20-1) | M21: =IF(OR(E21="",E9=""),"",E21/E9-1) -> 0.48356867 | N21: =IF(OR(F21="",F9=""),"",F21/F9-1) -> 0.51449142 | O21: =IF(OR(E21="",E18=""),"",(E21/E18)^4-1) -> 0.3504154 | P21: =IF(OR(F21="",F18=""),"",(F21/F18)^4-1) -> 0.36825214 | Q21: =IF(E21="","",IFERROR(E21/INDEX($E:$E,MATCH(C21-1&"-12",$B:$B,0))-1,"")) -> 0.077995246
B22: 2020-04 | C22: 2020 | D22: 4 | E22: 310.1243 | F22: 308.3681 | I22: =IF(OR(E22="",E21=""),"",E22/E21-1) -> 0.014965726 | J22: =IF(OR(F22="",F21=""),"",F22/F21-1) -> 0.017157569 | K22: =IF(OR(G22="",G21=""),"",G22/G21-1) | L22: =IF(OR(H22="",H21=""),"",H22/H21-1) | M22: =IF(OR(E22="",E10=""),"",E22/E10-1) -> 0.45625856 | N22: =IF(OR(F22="",F10=""),"",F22/F10-1) -> 0.48455237 | O22: =IF(OR(E22="",E19=""),"",(E22/E19)^4-1) -> 0.31090265 | P22: =IF(OR(F22="",F19=""),"",(F22/F19)^4-1) -> 0.32991827 | Q22: =IF(E22="","",IFERROR(E22/INDEX($E:$E,MATCH(C22-1&"-12",$B:$B,0))-1,"")) -> 0.094128227
B23: 2020-05 | C23: 2020 | D23: 5 | E23: 314.9087 | F23: 313.3195 | I23: =IF(OR(E23="",E22=""),"",E23/E22-1) -> 0.015427363 | J23: =IF(OR(F23="",F22=""),"",F23/F22-1) -> 0.016056784 | K23: =IF(OR(G23="",G22=""),"",G23/G22-1) | L23: =IF(OR(H23="",H22=""),"",H23/H22-1) | M23: =IF(OR(E23="",E11=""),"",E23/E11-1) -> 0.43421228 | N23: =IF(OR(F23="",F11=""),"",F23/F11-1) -> 0.46193604 | O23: =IF(OR(E23="",E20=""),"",(E23/E20)^4-1) -> 0.28686531 | P23: =IF(OR(F23="",F20=""),"",(F23/F20)^4-1) -> 0.29004977 | Q23: =IF(E23="","",IFERROR(E23/INDEX($E:$E,MATCH(C23-1&"-12",$B:$B,0))-1,"")) -> 0.11100774
B24: 2020-06 | C24: 2020 | D24: 6 | E24: 321.9738 | F24: 320.5733 | I24: =IF(OR(E24="",E23=""),"",E24/E23-1) -> 0.022435392 | J24: =IF(OR(F24="",F23=""),"",F24/F23-1) -> 0.023151448 | K24: =IF(OR(G24="",G23=""),"",G24/G23-1) | L24: =IF(OR(H24="",H23=""),"",H24/H23-1) | M24: =IF(OR(E24="",E12=""),"",E24/E12-1) -> 0.42758749 | N24: =IF(OR(F24="",F12=""),"",F24/F12-1) -> 0.45600972 | O24: =IF(OR(E24="",E21=""),"",(E24/E21)^4-1) -> 0.23294713 | P24: =IF(OR(F24="",F21=""),"",(F24/F21)^4-1) -> 0.25021456 | Q24: =IF(E24="","",IFERROR(E24/INDEX($E:$E,MATCH(C24-1&"-12",$B:$B,0))-1,"")) -> 0.13593363
B25: 2020-07 | C25: 2020 | D25: 7 | E25: 328.2014 | F25: 328.6943 | I25: =IF(OR(E25="",E24=""),"",E25/E24-1) -> 0.019341946 | J25: =IF(OR(F25="",F24=""),"",F25/F24-1) -> 0.02533274 | K25: =IF(OR(G25="",G24=""),"",G25/G24-1) | L25: =IF(OR(H25="",H24=""),"",H25/H24-1) | M25: =IF(OR(E25="",E13=""),"",E25/E13-1) -> 0.42390431 | N25: =IF(OR(F25="",F13=""),"",F25/F13-1) -> 0.46150597 | O25: =IF(OR(E25="",E22=""),"",(E25/E22)^4-1) -> 0.25434941 | P25: =IF(OR(F25="",F22=""),"",(F25/F22)^4-1) -> 0.29089498 | Q25: =IF(E25="","",IFERROR(E25/INDEX($E:$E,MATCH(C25-1&"-12",$B:$B,0))-1,"")) -> 0.1579048
B26: 2020-08 | C26: 2020 | D26: 8 | E26: 337.0632 | F26: 338.6645 | I26: =IF(OR(E26="",E25=""),"",E26/E25-1) -> 0.027001104 | J26: =IF(OR(F26="",F25=""),"",F26/F25-1) -> 0.030332744 | K26: =IF(OR(G26="",G25=""),"",G26/G25-1) | L26: =IF(OR(H26="",H25=""),"",H26/H25-1) | M26: =IF(OR(E26="",E14=""),"",E26/E14-1) -> 0.40672942 | N26: =IF(OR(F26="",F14=""),"",F26/F14-1) -> 0.43909427 | O26: =IF(OR(E26="",E23=""),"",(E26/E23)^4-1) -> 0.31252239 | P26: =IF(OR(F26="",F23=""),"",(F26/F23)^4-1) -> 0.36498852 | Q26: =IF(E26="","",IFERROR(E26/INDEX($E:$E,MATCH(C26-1&"-12",$B:$B,0))-1,"")) -> 0.18916951
B27: 2020-09 | C27: 2020 | D27: 9 | E27: 346.6207 | F27: 346.511 | I27: =IF(OR(E27="",E26=""),"",E27/E26-1) -> 0.028355216 | J27: =IF(OR(F27="",F26=""),"",F27/F26-1) -> 0.023168947 | K27: =IF(OR(G27="",G26=""),"",G27/G26-1) | L27: =IF(OR(H27="",H26=""),"",H27/H26-1) | M27: =IF(OR(E27="",E15=""),"",E27/E15-1) -> 0.36620719 | N27: =IF(OR(F27="",F15=""),"",F27/F15-1) -> 0.38337795 | O27: =IF(OR(E27="",E24=""),"",(E27/E24)^4-1) -> 0.34318504 | P27: =IF(OR(F27="",F24=""),"",(F27/F24)^4-1) -> 0.36508191 | Q27: =IF(E27="","",IFERROR(E27/INDEX($E:$E,MATCH(C27-1&"-12",$B:$B,0))-1,"")) -> 0.22288867
B28: 2020-10 | C28: 2020 | D28: 10 | E28: 359.657 | F28: 358.4989 | I28: =IF(OR(E28="",E27=""),"",E28/E27-1) -> 0.037609698 | J28: =IF(OR(F28="",F27=""),"",F28/F27-1) -> 0.034596016 | K28: =IF(OR(G28="",G27=""),"",G28/G27-1) | L28: =IF(OR(H28="",H27=""),"",H28/H27-1) | M28: =IF(OR(E28="",E16=""),"",E28/E16-1) -> 0.3723904 | N28: =IF(OR(F28="",F16=""),"",F28/F16-1) -> 0.37877935 | O28: =IF(OR(E28="",E25=""),"",(E28/E25)^4-1) -> 0.44208996 | P28: =IF(OR(F28="",F25=""),"",(F28/F25)^4-1) -> 0.4150853 | Q28: =IF(E28="","",IFERROR(E28/INDEX($E:$E,MATCH(C28-1&"-12",$B:$B,0))-1,"")) -> 0.26888114
B29: 2020-11 | C29: 2020 | D29: 11 | E29: 371.0211 | F29: 372.6154 | I29: =IF(OR(E29="",E28=""),"",E29/E28-1) -> 0.031597049 | J29: =IF(OR(F29="",F28=""),"",F29/F28-1) -> 0.03937669 | K29: =IF(OR(G29="",G28=""),"",G29/G28-1) | L29: =IF(OR(H29="",H28=""),"",H29/H28-1) | M29: =IF(OR(E29="",E17=""),"",E29/E17-1) -> 0.3579782 | N29: =IF(OR(F29="",F17=""),"",F29/F17-1) -> 0.37824286 | O29: =IF(OR(E29="",E26=""),"",(E29/E26)^4-1) -> 0.46807782 | P29: =IF(OR(F29="",F26=""),"",(F29/F26)^4-1) -> 0.46542805 | Q29: =IF(E29="","",IFERROR(E29/INDEX($E:$E,MATCH(C29-1&"-12",$B:$B,0))-1,"")) -> 0.30897404
... B42: 2021-12 | C42: 2021 | D42: 12 | E42: 582.4575 | F42: 605.1759 | I42: =IF(OR(E42="",E41=""),"",E42/E41-1) -> 0.038399703 | J42: =IF(OR(F42="",F41=""),"",F42/F41-1) -> 0.044232388 | K42: =IF(OR(G42="",G41=""),"",G42/G41-1) | L42: =IF(OR(H42="",H41=""),"",H42/H41-1) | M42: =IF(OR(E42="",E30=""),"",E42/E30-1) -> 0.50941634 | N42: =IF(OR(F42="",F30=""),"",F42/F30-1) -> 0.54869327 | O42: =IF(OR(E42="",E39=""),"",(E42/E39)^4-1) -> 0.47532438 | P42: =IF(OR(F42="",F39=""),"",(F42/F39)^4-1) -> 0.53295975 | Q42: =IF(E42="","",IFERROR(E42/INDEX($E:$E,MATCH(C42-1&"-12",$B:$B,0))-1,"")) -> 0.50941634
B43: 2022-01 | C43: 2022 | D43: 1 | E43: 605.0317 | F43: 625.1594 | G43: 512.3766 | H43: 658.2543 | I43: =IF(OR(E43="",E42=""),"",E43/E42-1) -> 0.038756819 | J43: =IF(OR(F43="",F42=""),"",F43/F42-1) -> 0.033020978 | K43: =IF(OR(G43="",G42=""),"",G43/G42-1) | L43: =IF(OR(H43="",H42=""),"",H43/H42-1) | M43: =IF(OR(E43="",E31=""),"",E43/E31-1) -> 0.50690162 | N43: =IF(OR(F43="",F31=""),"",F43/F31-1) -> 0.5395459 | O43: =IF(OR(E43="",E40=""),"",(E43/E40)^4-1) -> 0.49592056 | P43: =IF(OR(F43="",F40=""),"",(F43/F40)^4-1) -> 0.53897472 | Q43: =IF(E43="","",IFERROR(E43/INDEX($E:$E,MATCH(C43-1&"-12",$B:$B,0))-1,"")) -> 0.038756819
B44: 2022-02 | C44: 2022 | D44: 2 | E44: 633.4341 | F44: 652.9838 | G44: 528.2683 | H44: 713.7013 | I44: =IF(OR(E44="",E43=""),"",E44/E43-1) -> 0.046943656 | J44: =IF(OR(F44="",F43=""),"",F44/F43-1) -> 0.044507689 | K44: =IF(OR(G44="",G43=""),"",G44/G43-1) -> 0.031015663 | L44: =IF(OR(H44="",H43=""),"",H44/H43-1) -> 0.084233403 | M44: =IF(OR(E44="",E32=""),"",E44/E32-1) -> 0.52319257 | N44: =IF(OR(F44="",F32=""),"",F44/F32-1) -> 0.54518293 | O44: =IF(OR(E44="",E41=""),"",(E44/E41)^4-1) -> 0.62632377 | P44: =IF(OR(F44="",F41=""),"",(F44/F41)^4-1) -> 0.61165383 | Q44: =IF(E44="","",IFERROR(E44/INDEX($E:$E,MATCH(C44-1&"-12",$B:$B,0))-1,"")) -> 0.087519862
B45: 2022-03 | C45: 2022 | D45: 3 | E45: 676.0566 | F45: 694.7515 | G45: 572.7992 | H45: 757.8963 | I45: =IF(OR(E45="",E44=""),"",E45/E44-1) -> 0.067287978 | J45: =IF(OR(F45="",F44=""),"",F45/F44-1) -> 0.063964374 | K45: =IF(OR(G45="",G44=""),"",G45/G44-1) -> 0.084295991 | L45: =IF(OR(H45="",H44=""),"",H45/H44-1) -> 0.061923665 | M45: =IF(OR(E45="",E33=""),"",E45/E33-1) -> 0.5510663 | N45: =IF(OR(F45="",F33=""),"",F45/F33-1) -> 0.57283234 | O45: =IF(OR(E45="",E42=""),"",(E45/E42)^4-1) -> 0.81499428 | P45: =IF(OR(F45="",F42=""),"",(F45/F42)^4-1) -> 0.73696662 | Q45: =IF(E45="","",IFERROR(E45/INDEX($E:$E,MATCH(C45-1&"-12",$B:$B,0))-1,"")) -> 0.16069687
B46: 2022-04 | C46: 2022 | D46: 4 | E46: 716.9399 | F46: 741.3622 | G46: 595.2223 | H46: 799.0308 | I46: =IF(OR(E46="",E45=""),"",E46/E45-1) -> 0.060473191 | J46: =IF(OR(F46="",F45=""),"",F46/F45-1) -> 0.067089744 | K46: =IF(OR(G46="",G45=""),"",G46/G45-1) -> 0.039146528 | L46: =IF(OR(H46="",H45=""),"",H46/H45-1) -> 0.054274576 | M46: =IF(OR(E46="",E34=""),"",E46/E34-1) -> 0.58038009 | N46: =IF(OR(F46="",F34=""),"",F46/F34-1) -> 0.60517415 | O46: =IF(OR(E46="",E43=""),"",(E46/E43)^4-1) -> 0.97159853 | P46: =IF(OR(F46="",F43=""),"",(F46/F43)^4-1) -> 0.97769216 | Q46: =IF(E46="","",IFERROR(E46/INDEX($E:$E,MATCH(C46-1&"-12",$B:$B,0))-1,"")) -> 0.23088792
B47: 2022-05 | C47: 2022 | D47: 5 | E47: 753.147 | F47: 779.9267 | G47: 629.0029 | H47: 825.8088 | I47: =IF(OR(E47="",E46=""),"",E47/E46-1) -> 0.050502281 | J47: =IF(OR(F47="",F46=""),"",F47/F46-1) -> 0.052018433 | K47: =IF(OR(G47="",G46=""),"",G47/G46-1) -> 0.056752914 | L47: =IF(OR(H47="",H46=""),"",H47/H46-1) -> 0.033513101 | M47: =IF(OR(E47="",E35=""),"",E47/E35-1) -> 0.6067993 | N47: =IF(OR(F47="",F35=""),"",F47/F35-1) -> 0.63188718 | O47: =IF(OR(E47="",E44=""),"",(E47/E44)^4-1) -> 0.99854184 | P47: =IF(OR(F47="",F44=""),"",(F47/F44)^4-1) -> 1.0351926 | Q47: =IF(E47="","",IFERROR(E47/INDEX($E:$E,MATCH(C47-1&"-12",$B:$B,0))-1,"")) -> 0.29305057
B48: 2022-06 | C48: 2022 | D48: 6 | E48: 793.0278 | F48: 819.5734 | G48: 662.0938 | H48: 880.3186 | I48: =IF(OR(E48="",E47=""),"",E48/E47-1) -> 0.052952213 | J48: =IF(OR(F48="",F47=""),"",F48/F47-1) -> 0.05083388 | K48: =IF(OR(G48="",G47=""),"",G48/G47-1) -> 0.052608501 | L48: =IF(OR(H48="",H47=""),"",H48/H47-1) -> 0.066007773 | M48: =IF(OR(E48="",E36=""),"",E48/E36-1) -> 0.63982582 | N48: =IF(OR(F48="",F36=""),"",F48/F36-1) -> 0.65509897 | O48: =IF(OR(E48="",E45=""),"",(E48/E45)^4-1) -> 0.89330866 | P48: =IF(OR(F48="",F45=""),"",(F48/F45)^4-1) -> 0.9365711 | Q48: =IF(E48="","",IFERROR(E48/INDEX($E:$E,MATCH(C48-1&"-12",$B:$B,0))-1,"")) -> 0.36152045
B49: 2022-07 | C49: 2022 | D49: 7 | E49: 851.761 | F49: 879.6383 | G49: 694.6115 | H49: 979.7957 | I49: =IF(OR(E49="",E48=""),"",E49/E48-1) -> 0.074061969 | J49: =IF(OR(F49="",F48=""),"",F49/F48-1) -> 0.073288006 | K49: =IF(OR(G49="",G48=""),"",G49/G48-1) -> 0.049113434 | L49: =IF(OR(H49="",H48=""),"",H49/H48-1) -> 0.11300125 | M49: =IF(OR(E49="",E37=""),"",E49/E37-1) -> 0.71002454 | N49: =IF(OR(F49="",F37=""),"",F49/F37-1) -> 0.72242565 | O49: =IF(OR(E49="",E46=""),"",(E49/E46)^4-1) -> 0.99223241 | P49: =IF(OR(F49="",F46=""),"",(F49/F46)^4-1) -> 0.98195946 | Q49: =IF(E49="","",IFERROR(E49/INDEX($E:$E,MATCH(C49-1&"-12",$B:$B,0))-1,"")) -> 0.46235734
B50: 2022-08 | C50: 2022 | D50: 8 | E50: 911.1316 | F50: 939.4677 | G50: 738.3105 | H50: 1064.731 | I50: =IF(OR(E50="",E49=""),"",E50/E49-1) -> 0.069703356 | J50: =IF(OR(F50="",F49=""),"",F50/F49-1) -> 0.068015911 | K50: =IF(OR(G50="",G49=""),"",G50/G49-1) -> 0.062911426 | L50: =IF(OR(H50="",H49=""),"",H50/H49-1) -> 0.086686745 | M50: =IF(OR(E50="",E38=""),"",E50/E38-1) -> 0.78515273 | N50: =IF(OR(F50="",F38=""),"",F50/F38-1) -> 0.78370889 | O50: =IF(OR(E50="",E47=""),"",(E50/E47)^4-1) -> 1.1419308 | P50: =IF(OR(F50="",F47=""),"",(F50/F47)^4-1) -> 1.1052916 | Q50: =IF(E50="","",IFERROR(E50/INDEX($E:$E,MATCH(C50-1&"-12",$B:$B,0))-1,"")) -> 0.56428855
B51: 2022-09 | C51: 2022 | D51: 9 | E51: 967.3076 | F51: 991.2585 | G51: 771.8891 | H51: 1189.6609 | I51: =IF(OR(E51="",E50=""),"",E51/E50-1) -> 0.061655199 | J51: =IF(OR(F51="",F50=""),"",F51/F50-1) -> 0.055127813 | K51: =IF(OR(G51="",G50=""),"",G51/G50-1) -> 0.045480323 | L51: =IF(OR(H51="",H50=""),"",H51/H50-1) -> 0.11733471 | M51: =IF(OR(E51="",E39=""),"",E51/E39-1) -> 0.83029982 | N51: =IF(OR(F51="",F39=""),"",F51/F39-1) -> 0.82258582 | O51: =IF(OR(E51="",E48=""),"",(E51/E48)^4-1) -> 1.2136286 | P51: =IF(OR(F51="",F48=""),"",(F51/F48)^4-1) -> 1.1399138 | Q51: =IF(E51="","",IFERROR(E51/INDEX($E:$E,MATCH(C51-1&"-12",$B:$B,0))-1,"")) -> 0.66073508
B52: 2022-10 | C52: 2022 | D52: 10 | E52: 1028.706 | F52: 1046.265 | G52: 829.1011 | H52: 1297.2889 | I52: =IF(OR(E52="",E51=""),"",E52/E51-1) -> 0.063473501 | J52: =IF(OR(F52="",F51=""),"",F52/F51-1) -> 0.05549158 | K52: =IF(OR(G52="",G51=""),"",G52/G51-1) -> 0.074119456 | L52: =IF(OR(H52="",H51=""),"",H52/H51-1) -> 0.090469477 | M52: =IF(OR(E52="",E40=""),"",E52/E40-1) -> 0.88035685 | N52: =IF(OR(F52="",F40=""),"",F52/F40-1) -> 0.86405535 | O52: =IF(OR(E52="",E49=""),"",(E52/E49)^4-1) -> 1.1276201 | P52: =IF(OR(F52="",F49=""),"",(F52/F49)^4-1) -> 1.0014754 | Q52: =IF(E52="","",IFERROR(E52/INDEX($E:$E,MATCH(C52-1&"-12",$B:$B,0))-1,"")) -> 0.76614774
B53: 2022-11 | C53: 2022 | D53: 11 | E53: 1079.2787 | F53: 1096.024 | G53: 880.7676 | H53: 1350.5167 | I53: =IF(OR(E53="",E52=""),"",E53/E52-1) -> 0.049161471 | J53: =IF(OR(F53="",F52=""),"",F53/F52-1) -> 0.047558697 | K53: =IF(OR(G53="",G52=""),"",G53/G52-1) -> 0.062316284 | L53: =IF(OR(H53="",H52=""),"",H53/H52-1) -> 0.041030028 | M53: =IF(OR(E53="",E41=""),"",E53/E41-1) -> 0.92412782 | N53: =IF(OR(F53="",F41=""),"",F53/F41-1) -> 0.8911919 | O53: =IF(OR(E53="",E50=""),"",(E53/E50)^4-1) -> 0.96883802 | P53: =IF(OR(F53="",F50=""),"",(F53/F50)^4-1) -> 0.85247708 | Q53: =IF(E53="","",IFERROR(E53/INDEX($E:$E,MATCH(C53-1&"-12",$B:$B,0))-1,"")) -> 0.85297417
B54: 2022-12 | C54: 2022 | D54: 12 | E54: 1134.5875 | F54: 1153.5771 | G54: 925.7853 | H54: 1413.2059 | I54: =IF(OR(E54="",E53=""),"",E54/E53-1) -> 0.051246078 | J54: =IF(OR(F54="",F53=""),"",F54/F53-1) -> 0.052510803 | K54: =IF(OR(G54="",G53=""),"",G54/G53-1) -> 0.051111894 | L54: =IF(OR(H54="",H53=""),"",H54/H53-1) -> 0.046418678 | M54: =IF(OR(E54="",E42=""),"",E54/E42-1) -> 0.94793182 | N54: =IF(OR(F54="",F42=""),"",F54/F42-1) -> 0.9061848 | O54: =IF(OR(E54="",E51=""),"",(E54/E51)^4-1) -> 0.89275141 | P54: =IF(OR(F54="",F51=""),"",(F54/F51)^4-1) -> 0.83416671 | Q54: =IF(E54="","",IFERROR(E54/INDEX($E:$E,MATCH(C54-1&"-12",$B:$B,0))-1,"")) -> 0.94793182
...

Sheet Seasonality Headline
B2: Seasonality — IPC Nivel General (headline): month-on-month % by calendar year
B3: One line per calendar year, Jan-Dec on the x-axis. Recent years are drawn darker; 2026 in red.
B5: Month | C5: 2019 | D5: 2020 | E5: 2021 | F5: 2022 | G5: 2023 | H5: 2024 | I5: 2025 | J5: 2026
B6: Jan | C6: =IF(COUNTIFS(Data!$C$6:$C$114,C$5,Data!$D$6:$D$114,1,Data!$E$6:$E$114,">0")=0,"",SUMIFS(Data!$I$6:$I$114,Data!$C$6:$C$114,C$5,Data!$D$6:$D$114,1)) -> 0.029062409 | D6: =IF(COUNTIFS(Data!$C$6:$C$114,D$5,Data!$D$6:$D$114,1,Data!$E$6:$E$114,">0")=0,"",SUMIFS(Data!$I$6:$I$114,Data!$C$6:$C$114,D$5,Data!$D$6:$D$114,1)) -> 0.022528949 | E6: =IF(COUNTIFS(Data!$C$6:$C$114,E$5,Data!$D$6:$D$114,1,Data!$E$6:$E$114,">0")=0,"",SUMIFS(Data!$I$6:$I$114,Data!$C$6:$C$114,E$5,Data!$D$6:$D$114,1)) -> 0.040490294 | F6: =IF(COUNTIFS(Data!$C$6:$C$114,F$5,Data!$D$6:$D$114,1,Data!$E$6:$E$114,">0")=0,"",SUMIFS(Data!$I$6:$I$114,Data!$C$6:$C$114,F$5,Data!$D$6:$D$114,1)) -> 0.038756819 | G6: =IF(COUNTIFS(Data!$C$6:$C$114,G$5,Data!$D$6:$D$114,1,Data!$E$6:$E$114,">0")=0,"",SUMIFS(Data!$I$6:$I$114,Data!$C$6:$C$114,G$5,Data!$D$6:$D$114,1)) -> 0.060278736 | H6: =IF(COUNTIFS(Data!$C$6:$C$114,H$5,Data!$D$6:$D$114,1,Data!$E$6:$E$114,">0")=0,"",SUMIFS(Data!$I$6:$I$114,Data!$C$6:$C$114,H$5,Data!$D$6:$D$114,1)) -> 0.20614225 | I6: =IF(COUNTIFS(Data!$C$6:$C$114,I$5,Data!$D$6:$D$114,1,Data!$E$6:$E$114,">0")=0,"",SUMIFS(Data!$I$6:$I$114,Data!$C$6:$C$114,I$5,Data!$D$6:$D$114,1)) -> 0.02211048 | J6: =IF(COUNTIFS(Data!$C$6:$C$114,J$5,Data!$D$6:$D$114,1,Data!$E$6:$E$114,">0")=0,"",SUMIFS(Data!$I$6:$I$114,Data!$C$6:$C$114,J$5,Data!$D$6:$D$114,1)) -> 0.028816194
B7: Feb | C7: =IF(COUNTIFS(Data!$C$6:$C$114,C$5,Data!$D$6:$D$114,2,Data!$E$6:$E$114,">0")=0,"",SUMIFS(Data!$I$6:$I$114,Data!$C$6:$C$114,C$5,Data!$D$6:$D$114,2)) -> 0.037656222 | D7: =IF(COUNTIFS(Data!$C$6:$C$114,D$5,Data!$D$6:$D$114,2,Data!$E$6:$E$114,">0")=0,"",SUMIFS(Data!$I$6:$I$114,Data!$C$6:$C$114,D$5,Data!$D$6:$D$114,2)) -> 0.020136294 | E7: =IF(COUNTIFS(Data!$C$6:$C$114,E$5,Data!$D$6:$D$114,2,Data!$E$6:$E$114,">0")=0,"",SUMIFS(Data!$I$6:$I$114,Data!$C$6:$C$114,E$5,Data!$D$6:$D$114,2)) -> 0.035746317 | F7: =IF(COUNTIFS(Data!$C$6:$C$114,F$5,Data!$D$6:$D$114,2,Data!$E$6:$E$114,">0")=0,"",SUMIFS(Data!$I$6:$I$114,Data!$C$6:$C$114,F$5,Data!$D$6:$D$114,2)) -> 0.046943656 | G7: =IF(COUNTIFS(Data!$C$6:$C$114,G$5,Data!$D$6:$D$114,2,Data!$E$6:$E$114,">0")=0,"",SUMIFS(Data!$I$6:$I$114,Data!$C$6:$C$114,G$5,Data!$D$6:$D$114,2)) -> 0.066277217 | H7: =IF(COUNTIFS(Data!$C$6:$C$114,H$5,Data!$D$6:$D$114,2,Data!$E$6:$E$114,">0")=0,"",SUMIFS(Data!$I$6:$I$114,Data!$C$6:$C$114,H$5,Data!$D$6:$D$114,2)) -> 0.13240676 | I7: =IF(COUNTIFS(Data!$C$6:$C$114,I$5,Data!$D$6:$D$114,2,Data!$E$6:$E$114,">0")=0,"",SUMIFS(Data!$I$6:$I$114,Data!$C$6:$C$114,I$5,Data!$D$6:$D$114,2)) -> 0.024016274 | J7: =IF(COUNTIFS(Data!$C$6:$C$114,J$5,Data!$D$6:$D$114,2,Data!$E$6:$E$114,">0")=0,"",SUMIFS(Data!$I$6:$I$114,Data!$C$6:$C$114,J$5,Data!$D$6:$D$114,2)) -> 0.028963191
B8: Mar | C8: =IF(COUNTIFS(Data!$C$6:$C$114,C$5,Data!$D$6:$D$114,3,Data!$E$6:$E$114,">0")=0,"",SUMIFS(Data!$I$6:$I$114,Data!$C$6:$C$114,C$5,Data!$D$6:$D$114,3)) -> 0.046795402 | D8: =IF(COUNTIFS(Data!$C$6:$C$114,D$5,Data!$D$6:$D$114,3,Data!$E$6:$E$114,">0")=0,"",SUMIFS(Data!$I$6:$I$114,Data!$C$6:$C$114,D$5,Data!$D$6:$D$114,3)) -> 0.033434686 | E8: =IF(COUNTIFS(Data!$C$6:$C$114,E$5,Data!$D$6:$D$114,3,Data!$E$6:$E$114,">0")=0,"",SUMIFS(Data!$I$6:$I$114,Data!$C$6:$C$114,E$5,Data!$D$6:$D$114,3)) -> 0.048108075 | F8: =IF(COUNTIFS(Data!$C$6:$C$114,F$5,Data!$D$6:$D$114,3,Data!$E$6:$E$114,">0")=0,"",SUMIFS(Data!$I$6:$I$114,Data!$C$6:$C$114,F$5,Data!$D$6:$D$114,3)) -> 0.067287978 | G8: =IF(COUNTIFS(Data!$C$6:$C$114,G$5,Data!$D$6:$D$114,3,Data!$E$6:$E$114,">0")=0,"",SUMIFS(Data!$I$6:$I$114,Data!$C$6:$C$114,G$5,Data!$D$6:$D$114,3)) -> 0.076752398 | H8: =IF(COUNTIFS(Data!$C$6:$C$114,H$5,Data!$D$6:$D$114,3,Data!$E$6:$E$114,">0")=0,"",SUMIFS(Data!$I$6:$I$114,Data!$C$6:$C$114,H$5,Data!$D$6:$D$114,3)) -> 0.110097 | I8: =IF(COUNTIFS(Data!$C$6:$C$114,I$5,Data!$D$6:$D$114,3,Data!$E$6:$E$114,">0")=0,"",SUMIFS(Data!$I$6:$I$114,Data!$C$6:$C$114,I$5,Data!$D$6:$D$114,3)) -> 0.037293353 | J8: =IF(COUNTIFS(Data!$C$6:$C$114,J$5,Data!$D$6:$D$114,3,Data!$E$6:$E$114,">0")=0,"",SUMIFS(Data!$I$6:$I$114,Data!$C$6:$C$114,J$5,Data!$D$6:$D$114,3)) -> 0.033826222
B9: Apr | C9: =IF(COUNTIFS(Data!$C$6:$C$114,C$5,Data!$D$6:$D$114,4,Data!$E$6:$E$114,">0")=0,"",SUMIFS(Data!$I$6:$I$114,Data!$C$6:$C$114,C$5,Data!$D$6:$D$114,4)) -> 0.034 | D9: =IF(COUNTIFS(Data!$C$6:$C$114,D$5,Data!$D$6:$D$114,4,Data!$E$6:$E$114,">0")=0,"",SUMIFS(Data!$I$6:$I$114,Data!$C$6:$C$114,D$5,Data!$D$6:$D$114,4)) -> 0.014965726 | E9: =IF(COUNTIFS(Data!$C$6:$C$114,E$5,Data!$D$6:$D$114,4,Data!$E$6:$E$114,">0")=0,"",SUMIFS(Data!$I$6:$I$114,Data!$C$6:$C$114,E$5,Data!$D$6:$D$114,4)) -> 0.040802935 | F9: =IF(COUNTIFS(Data!$C$6:$C$114,F$5,Data!$D$6:$D$114,4,Data!$E$6:$E$114,">0")=0,"",SUMIFS(Data!$I$6:$I$114,Data!$C$6:$C$114,F$5,Data!$D$6:$D$114,4)) -> 0.060473191 | G9: =IF(COUNTIFS(Data!$C$6:$C$114,G$5,Data!$D$6:$D$114,4,Data!$E$6:$E$114,">0")=0,"",SUMIFS(Data!$I$6:$I$114,Data!$C$6:$C$114,G$5,Data!$D$6:$D$114,4)) -> 0.084026899 | H9: =IF(COUNTIFS(Data!$C$6:$C$114,H$5,Data!$D$6:$D$114,4,Data!$E$6:$E$114,">0")=0,"",SUMIFS(Data!$I$6:$I$114,Data!$C$6:$C$114,H$5,Data!$D$6:$D$114,4)) -> 0.088319208 | I9: =IF(COUNTIFS(Data!$C$6:$C$114,I$5,Data!$D$6:$D$114,4,Data!$E$6:$E$114,">0")=0,"",SUMIFS(Data!$I$6:$I$114,Data!$C$6:$C$114,I$5,Data!$D$6:$D$114,4)) -> 0.027808358 | J9: =IF(COUNTIFS(Data!$C$6:$C$114,J$5,Data!$D$6:$D$114,4,Data!$E$6:$E$114,">0")=0,"",SUMIFS(Data!$I$6:$I$114,Data!$C$6:$C$114,J$5,Data!$D$6:$D$114,4)) -> 0.025821796
B10: May | C10: =IF(COUNTIFS(Data!$C$6:$C$114,C$5,Data!$D$6:$D$114,5,Data!$E$6:$E$114,">0")=0,"",SUMIFS(Data!$I$6:$I$114,Data!$C$6:$C$114,C$5,Data!$D$6:$D$114,5)) -> 0.031036203 | D10: =IF(COUNTIFS(Data!$C$6:$C$114,D$5,Data!$D$6:$D$114,5,Data!$E$6:$E$114,">0")=0,"",SUMIFS(Data!$I$6:$I$114,Data!$C$6:$C$114,D$5,Data!$D$6:$D$114,5)) -> 0.015427363 | E10: =IF(COUNTIFS(Data!$C$6:$C$114,E$5,Data!$D$6:$D$114,5,Data!$E$6:$E$114,">0")=0,"",SUMIFS(Data!$I$6:$I$114,Data!$C$6:$C$114,E$5,Data!$D$6:$D$114,5)) -> 0.033229781 | F10: =IF(COUNTIFS(Data!$C$6:$C$114,F$5,Data!$D$6:$D$114,5,Data!$E$6:$E$114,">0")=0,"",SUMIFS(Data!$I$6:$I$114,Data!$C$6:$C$114,F$5,Data!$D$6:$D$114,5)) -> 0.050502281 | G10: =IF(COUNTIFS(Data!$C$6:$C$114,G$5,Data!$D$6:$D$114,5,Data!$E$6:$E$114,">0")=0,"",SUMIFS(Data!$I$6:$I$114,Data!$C$6:$C$114,G$5,Data!$D$6:$D$114,5)) -> 0.07772753 | H10: =IF(COUNTIFS(Data!$C$6:$C$114,H$5,Data!$D$6:$D$114,5,Data!$E$6:$E$114,">0")=0,"",SUMIFS(Data!$I$6:$I$114,Data!$C$6:$C$114,H$5,Data!$D$6:$D$114,5)) -> 0.041760449 | I10: =IF(COUNTIFS(Data!$C$6:$C$114,I$5,Data!$D$6:$D$114,5,Data!$E$6:$E$114,">0")=0,"",SUMIFS(Data!$I$6:$I$114,Data!$C$6:$C$114,I$5,Data!$D$6:$D$114,5)) -> 0.015011086 | J10: =IF(COUNTIFS(Data!$C$6:$C$114,J$5,Data!$D$6:$D$114,5,Data!$E$6:$E$114,">0")=0,"",SUMIFS(Data!$I$6:$I$114,Data!$C$6:$C$114,J$5,Data!$D$6:$D$114,5)) -> 0.021499723
B11: Jun | C11: =IF(COUNTIFS(Data!$C$6:$C$114,C$5,Data!$D$6:$D$114,6,Data!$E$6:$E$114,">0")=0,"",SUMIFS(Data!$I$6:$I$114,Data!$C$6:$C$114,C$5,Data!$D$6:$D$114,6)) -> 0.027180054 | D11: =IF(COUNTIFS(Data!$C$6:$C$114,D$5,Data!$D$6:$D$114,6,Data!$E$6:$E$114,">0")=0,"",SUMIFS(Data!$I$6:$I$114,Data!$C$6:$C$114,D$5,Data!$D$6:$D$114,6)) -> 0.022435392 | E11: =IF(COUNTIFS(Data!$C$6:$C$114,E$5,Data!$D$6:$D$114,6,Data!$E$6:$E$114,">0")=0,"",SUMIFS(Data!$I$6:$I$114,Data!$C$6:$C$114,E$5,Data!$D$6:$D$114,6)) -> 0.03174548 | F11: =IF(COUNTIFS(Data!$C$6:$C$114,F$5,Data!$D$6:$D$114,6,Data!$E$6:$E$114,">0")=0,"",SUMIFS(Data!$I$6:$I$114,Data!$C$6:$C$114,F$5,Data!$D$6:$D$114,6)) -> 0.052952213 | G11: =IF(COUNTIFS(Data!$C$6:$C$114,G$5,Data!$D$6:$D$114,6,Data!$E$6:$E$114,">0")=0,"",SUMIFS(Data!$I$6:$I$114,Data!$C$6:$C$114,G$5,Data!$D$6:$D$114,6)) -> 0.05950832 | H11: =IF(COUNTIFS(Data!$C$6:$C$114,H$5,Data!$D$6:$D$114,6,Data!$E$6:$E$114,">0")=0,"",SUMIFS(Data!$I$6:$I$114,Data!$C$6:$C$114,H$5,Data!$D$6:$D$114,6)) -> 0.045773499 | I11: =IF(COUNTIFS(Data!$C$6:$C$114,I$5,Data!$D$6:$D$114,6,Data!$E$6:$E$114,">0")=0,"",SUMIFS(Data!$I$6:$I$114,Data!$C$6:$C$114,I$5,Data!$D$6:$D$114,6)) -> 0.016189249 | J11: =IF(COUNTIFS(Data!$C$6:$C$114,J$5,Data!$D$6:$D$114,6,Data!$E$6:$E$114,">0")=0,"",SUMIFS(Data!$I$6:$I$114,Data!$C$6:$C$114,J$5,Data!$D$6:$D$114,6)) -> 0.018868715
B12: Jul | C12: =IF(COUNTIFS(Data!$C$6:$C$114,C$5,Data!$D$6:$D$114,7,Data!$E$6:$E$114,">0")=0,"",SUMIFS(Data!$I$6:$I$114,Data!$C$6:$C$114,C$5,Data!$D$6:$D$114,7)) -> 0.021978655 | D12: =IF(COUNTIFS(Data!$C$6:$C$114,D$5,Data!$D$6:$D$114,7,Data!$E$6:$E$114,">0")=0,"",SUMIFS(Data!$I$6:$I$114,Data!$C$6:$C$114,D$5,Data!$D$6:$D$114,7)) -> 0.019341946 | E12: =IF(COUNTIFS(Data!$C$6:$C$114,E$5,Data!$D$6:$D$114,7,Data!$E$6:$E$114,">0")=0,"",SUMIFS(Data!$I$6:$I$114,Data!$C$6:$C$114,E$5,Data!$D$6:$D$114,7)) -> 0.029970333 | F12: =IF(COUNTIFS(Data!$C$6:$C$114,F$5,Data!$D$6:$D$114,7,Data!$E$6:$E$114,">0")=0,"",SUMIFS(Data!$I$6:$I$114,Data!$C$6:$C$114,F$5,Data!$D$6:$D$114,7)) -> 0.074061969 | G12: =IF(COUNTIFS(Data!$C$6:$C$114,G$5,Data!$D$6:$D$114,7,Data!$E$6:$E$114,">0")=0,"",SUMIFS(Data!$I$6:$I$114,Data!$C$6:$C$114,G$5,Data!$D$6:$D$114,7)) -> 0.063448509 | H12: =IF(COUNTIFS(Data!$C$6:$C$114,H$5,Data!$D$6:$D$114,7,Data!$E$6:$E$114,">0")=0,"",SUMIFS(Data!$I$6:$I$114,Data!$C$6:$C$114,H$5,Data!$D$6:$D$114,7)) -> 0.040309337 | I12: =IF(COUNTIFS(Data!$C$6:$C$114,I$5,Data!$D$6:$D$114,7,Data!$E$6:$E$114,">0")=0,"",SUMIFS(Data!$I$6:$I$114,Data!$C$6:$C$114,I$5,Data!$D$6:$D$114,7)) -> 0.019016838 | J12: =IF(COUNTIFS(Data!$C$6:$C$114,J$5,Data!$D$6:$D$114,7,Data!$E$6:$E$114,">0")=0,"",SUMIFS(Data!$I$6:$I$114,Data!$C$6:$C$114,J$5,Data!$D$6:$D$114,7))
B13: Aug | C13: =IF(COUNTIFS(Data!$C$6:$C$114,C$5,Data!$D$6:$D$114,8,Data!$E$6:$E$114,">0")=0,"",SUMIFS(Data!$I$6:$I$114,Data!$C$6:$C$114,C$5,Data!$D$6:$D$114,8)) -> 0.039539858 | D13: =IF(COUNTIFS(Data!$C$6:$C$114,D$5,Data!$D$6:$D$114,8,Data!$E$6:$E$114,">0")=0,"",SUMIFS(Data!$I$6:$I$114,Data!$C$6:$C$114,D$5,Data!$D$6:$D$114,8)) -> 0.027001104 | E13: =IF(COUNTIFS(Data!$C$6:$C$114,E$5,Data!$D$6:$D$114,8,Data!$E$6:$E$114,">0")=0,"",SUMIFS(Data!$I$6:$I$114,Data!$C$6:$C$114,E$5,Data!$D$6:$D$114,8)) -> 0.024684867 | F13: =IF(COUNTIFS(Data!$C$6:$C$114,F$5,Data!$D$6:$D$114,8,Data!$E$6:$E$114,">0")=0,"",SUMIFS(Data!$I$6:$I$114,Data!$C$6:$C$114,F$5,Data!$D$6:$D$114,8)) -> 0.069703356 | G13: =IF(COUNTIFS(Data!$C$6:$C$114,G$5,Data!$D$6:$D$114,8,Data!$E$6:$E$114,">0")=0,"",SUMIFS(Data!$I$6:$I$114,Data!$C$6:$C$114,G$5,Data!$D$6:$D$114,8)) -> 0.12441638 | H13: =IF(COUNTIFS(Data!$C$6:$C$114,H$5,Data!$D$6:$D$114,8,Data!$E$6:$E$114,">0")=0,"",SUMIFS(Data!$I$6:$I$114,Data!$C$6:$C$114,H$5,Data!$D$6:$D$114,8)) -> 0.041722733 | I13: =IF(COUNTIFS(Data!$C$6:$C$114,I$5,Data!$D$6:$D$114,8,Data!$E$6:$E$114,">0")=0,"",SUMIFS(Data!$I$6:$I$114,Data!$C$6:$C$114,I$5,Data!$D$6:$D$114,8)) -> 0.018757935 | J13: =IF(COUNTIFS(Data!$C$6:$C$114,J$5,Data!$D$6:$D$114,8,Data!$E$6:$E$114,">0")=0,"",SUMIFS(Data!$I$6:$I$114,Data!$C$6:$C$114,J$5,Data!$D$6:$D$114,8))
B14: Sep | C14: =IF(COUNTIFS(Data!$C$6:$C$114,C$5,Data!$D$6:$D$114,9,Data!$E$6:$E$114,">0")=0,"",SUMIFS(Data!$I$6:$I$114,Data!$C$6:$C$114,C$5,Data!$D$6:$D$114,9)) -> 0.058856623 | D14: =IF(COUNTIFS(Data!$C$6:$C$114,D$5,Data!$D$6:$D$114,9,Data!$E$6:$E$114,">0")=0,"",SUMIFS(Data!$I$6:$I$114,Data!$C$6:$C$114,D$5,Data!$D$6:$D$114,9)) -> 0.028355216 | E14: =IF(COUNTIFS(Data!$C$6:$C$114,E$5,Data!$D$6:$D$114,9,Data!$E$6:$E$114,">0")=0,"",SUMIFS(Data!$I$6:$I$114,Data!$C$6:$C$114,E$5,Data!$D$6:$D$114,9)) -> 0.03546788 | F14: =IF(COUNTIFS(Data!$C$6:$C$114,F$5,Data!$D$6:$D$114,9,Data!$E$6:$E$114,">0")=0,"",SUMIFS(Data!$I$6:$I$114,Data!$C$6:$C$114,F$5,Data!$D$6:$D$114,9)) -> 0.061655199 | G14: =IF(COUNTIFS(Data!$C$6:$C$114,G$5,Data!$D$6:$D$114,9,Data!$E$6:$E$114,">0")=0,"",SUMIFS(Data!$I$6:$I$114,Data!$C$6:$C$114,G$5,Data!$D$6:$D$114,9)) -> 0.1274975 | H14: =IF(COUNTIFS(Data!$C$6:$C$114,H$5,Data!$D$6:$D$114,9,Data!$E$6:$E$114,">0")=0,"",SUMIFS(Data!$I$6:$I$114,Data!$C$6:$C$114,H$5,Data!$D$6:$D$114,9)) -> 0.034692081 | I14: =IF(COUNTIFS(Data!$C$6:$C$114,I$5,Data!$D$6:$D$114,9,Data!$E$6:$E$114,">0")=0,"",SUMIFS(Data!$I$6:$I$114,Data!$C$6:$C$114,I$5,Data!$D$6:$D$114,9)) -> 0.020759603 | J14: =IF(COUNTIFS(Data!$C$6:$C$114,J$5,Data!$D$6:$D$114,9,Data!$E$6:$E$114,">0")=0,"",SUMIFS(Data!$I$6:$I$114,Data!$C$6:$C$114,J$5,Data!$D$6:$D$114,9))
B15: Oct | C15: =IF(COUNTIFS(Data!$C$6:$C$114,C$5,Data!$D$6:$D$114,10,Data!$E$6:$E$114,">0")=0,"",SUMIFS(Data!$I$6:$I$114,Data!$C$6:$C$114,C$5,Data!$D$6:$D$114,10)) -> 0.032934821 | D15: =IF(COUNTIFS(Data!$C$6:$C$114,D$5,Data!$D$6:$D$114,10,Data!$E$6:$E$114,">0")=0,"",SUMIFS(Data!$I$6:$I$114,Data!$C$6:$C$114,D$5,Data!$D$6:$D$114,10)) -> 0.037609698 | E15: =IF(COUNTIFS(Data!$C$6:$C$114,E$5,Data!$D$6:$D$114,10,Data!$E$6:$E$114,">0")=0,"",SUMIFS(Data!$I$6:$I$114,Data!$C$6:$C$114,E$5,Data!$D$6:$D$114,10)) -> 0.035162748 | F15: =IF(COUNTIFS(Data!$C$6:$C$114,F$5,Data!$D$6:$D$114,10,Data!$E$6:$E$114,">0")=0,"",SUMIFS(Data!$I$6:$I$114,Data!$C$6:$C$114,F$5,Data!$D$6:$D$114,10)) -> 0.063473501 | G15: =IF(COUNTIFS(Data!$C$6:$C$114,G$5,Data!$D$6:$D$114,10,Data!$E$6:$E$114,">0")=0,"",SUMIFS(Data!$I$6:$I$114,Data!$C$6:$C$114,G$5,Data!$D$6:$D$114,10)) -> 0.083017394 | H15: =IF(COUNTIFS(Data!$C$6:$C$114,H$5,Data!$D$6:$D$114,10,Data!$E$6:$E$114,">0")=0,"",SUMIFS(Data!$I$6:$I$114,Data!$C$6:$C$114,H$5,Data!$D$6:$D$114,10)) -> 0.02691738 | I15: =IF(COUNTIFS(Data!$C$6:$C$114,I$5,Data!$D$6:$D$114,10,Data!$E$6:$E$114,">0")=0,"",SUMIFS(Data!$I$6:$I$114,Data!$C$6:$C$114,I$5,Data!$D$6:$D$114,10)) -> 0.023419431 | J15: =IF(COUNTIFS(Data!$C$6:$C$114,J$5,Data!$D$6:$D$114,10,Data!$E$6:$E$114,">0")=0,"",SUMIFS(Data!$I$6:$I$114,Data!$C$6:$C$114,J$5,Data!$D$6:$D$114,10))
B16: Nov | C16: =IF(COUNTIFS(Data!$C$6:$C$114,C$5,Data!$D$6:$D$114,11,Data!$E$6:$E$114,">0")=0,"",SUMIFS(Data!$I$6:$I$114,Data!$C$6:$C$114,C$5,Data!$D$6:$D$114,11)) -> 0.042545373 | D16: =IF(COUNTIFS(Data!$C$6:$C$114,D$5,Data!$D$6:$D$114,11,Data!$E$6:$E$114,">0")=0,"",SUMIFS(Data!$I$6:$I$114,Data!$C$6:$C$114,D$5,Data!$D$6:$D$114,11)) -> 0.031597049 | E16: =IF(COUNTIFS(Data!$C$6:$C$114,E$5,Data!$D$6:$D$114,11,Data!$E$6:$E$114,">0")=0,"",SUMIFS(Data!$I$6:$I$114,Data!$C$6:$C$114,E$5,Data!$D$6:$D$114,11)) -> 0.025294646 | F16: =IF(COUNTIFS(Data!$C$6:$C$114,F$5,Data!$D$6:$D$114,11,Data!$E$6:$E$114,">0")=0,"",SUMIFS(Data!$I$6:$I$114,Data!$C$6:$C$114,F$5,Data!$D$6:$D$114,11)) -> 0.049161471 | G16: =IF(COUNTIFS(Data!$C$6:$C$114,G$5,Data!$D$6:$D$114,11,Data!$E$6:$E$114,">0")=0,"",SUMIFS(Data!$I$6:$I$114,Data!$C$6:$C$114,G$5,Data!$D$6:$D$114,11)) -> 0.1281069 | H16: =IF(COUNTIFS(Data!$C$6:$C$114,H$5,Data!$D$6:$D$114,11,Data!$E$6:$E$114,">0")=0,"",SUMIFS(Data!$I$6:$I$114,Data!$C$6:$C$114,H$5,Data!$D$6:$D$114,11)) -> 0.024265561 | I16: =IF(COUNTIFS(Data!$C$6:$C$114,I$5,Data!$D$6:$D$114,11,Data!$E$6:$E$114,">0")=0,"",SUMIFS(Data!$I$6:$I$114,Data!$C$6:$C$114,I$5,Data!$D$6:$D$114,11)) -> 0.024729197 | J16: =IF(COUNTIFS(Data!$C$6:$C$114,J$5,Data!$D$6:$D$114,11,Data!$E$6:$E$114,">0")=0,"",SUMIFS(Data!$I$6:$I$114,Data!$C$6:$C$114,J$5,Data!$D$6:$D$114,11))
B17: Dec | C17: =IF(COUNTIFS(Data!$C$6:$C$114,C$5,Data!$D$6:$D$114,12,Data!$E$6:$E$114,">0")=0,"",SUMIFS(Data!$I$6:$I$114,Data!$C$6:$C$114,C$5,Data!$D$6:$D$114,12)) -> 0.037437074 | D17: =IF(COUNTIFS(Data!$C$6:$C$114,D$5,Data!$D$6:$D$114,12,Data!$E$6:$E$114,">0")=0,"",SUMIFS(Data!$I$6:$I$114,Data!$C$6:$C$114,D$5,Data!$D$6:$D$114,12)) -> 0.040055673 | E17: =IF(COUNTIFS(Data!$C$6:$C$114,E$5,Data!$D$6:$D$114,12,Data!$E$6:$E$114,">0")=0,"",SUMIFS(Data!$I$6:$I$114,Data!$C$6:$C$114,E$5,Data!$D$6:$D$114,12)) -> 0.038399703 | F17: =IF(COUNTIFS(Data!$C$6:$C$114,F$5,Data!$D$6:$D$114,12,Data!$E$6:$E$114,">0")=0,"",SUMIFS(Data!$I$6:$I$114,Data!$C$6:$C$114,F$5,Data!$D$6:$D$114,12)) -> 0.051246078 | G17: =IF(COUNTIFS(Data!$C$6:$C$114,G$5,Data!$D$6:$D$114,12,Data!$E$6:$E$114,">0")=0,"",SUMIFS(Data!$I$6:$I$114,Data!$C$6:$C$114,G$5,Data!$D$6:$D$114,12)) -> 0.25465675 | H17: =IF(COUNTIFS(Data!$C$6:$C$114,H$5,Data!$D$6:$D$114,12,Data!$E$6:$E$114,">0")=0,"",SUMIFS(Data!$I$6:$I$114,Data!$C$6:$C$114,H$5,Data!$D$6:$D$114,12)) -> 0.027041041 | I17: =IF(COUNTIFS(Data!$C$6:$C$114,I$5,Data!$D$6:$D$114,12,Data!$E$6:$E$114,">0")=0,"",SUMIFS(Data!$I$6:$I$114,Data!$C$6:$C$114,I$5,Data!$D$6:$D$114,12)) -> 0.028452719 | J17: =IF(COUNTIFS(Data!$C$6:$C$114,J$5,Data!$D$6:$D$114,12,Data!$E$6:$E$114,">0")=0,"",SUMIFS(Data!$I$6:$I$114,Data!$C$6:$C$114,J$5,Data!$D$6:$D$114,12))
B19: Dec/Dec* | C19: =IFERROR(INDEX(Data!$E:$E,MATCH("2019-12",Data!$B:$B,0))/INDEX(Data!$E:$E,MATCH("2018-12",Data!$B:$B,0))-1,"") -> 0.53832402 | D19: =IFERROR(INDEX(Data!$E:$E,MATCH("2020-12",Data!$B:$B,0))/INDEX(Data!$E:$E,MATCH("2019-12",Data!$B:$B,0))-1,"") -> 0.36140588 | E19: =IFERROR(INDEX(Data!$E:$E,MATCH("2021-12",Data!$B:$B,0))/INDEX(Data!$E:$E,MATCH("2020-12",Data!$B:$B,0))-1,"") -> 0.50941634 | F19: =IFERROR(INDEX(Data!$E:$E,MATCH("2022-12",Data!$B:$B,0))/INDEX(Data!$E:$E,MATCH("2021-12",Data!$B:$B,0))-1,"") -> 0.94793182 | G19: =IFERROR(INDEX(Data!$E:$E,MATCH("2023-12",Data!$B:$B,0))/INDEX(Data!$E:$E,MATCH("2022-12",Data!$B:$B,0))-1,"") -> 2.1140764 | H19: =IFERROR(INDEX(Data!$E:$E,MATCH("2024-12",Data!$B:$B,0))/INDEX(Data!$E:$E,MATCH("2023-12",Data!$B:$B,0))-1,"") -> 1.1776363 | I19: =IFERROR(INDEX(Data!$E:$E,MATCH("2025-12",Data!$B:$B,0))/INDEX(Data!$E:$E,MATCH("2024-12",Data!$B:$B,0))-1,"") -> 0.31548761 | J19: =IFERROR(INDEX(Data!$E:$E,MATCH("2026-06",Data!$B:$B,0))/INDEX(Data!$E:$E,MATCH("2025-12",Data!$B:$B,0))-1,"") -> 0.16845926
B20: Avg month | C20: =IFERROR(AVERAGE(C6:C17),"") -> 0.036585224 | D20: =IFERROR(AVERAGE(D6:D17),"") -> 0.026074091 | E20: =IFERROR(AVERAGE(E6:E17),"") -> 0.034925255 | F20: =IFERROR(AVERAGE(F6:F17),"") -> 0.057184809 | G20: =IFERROR(AVERAGE(G6:G17),"") -> 0.10047621 | H20: =IFERROR(AVERAGE(H6:H17),"") -> 0.068287275 | I20: =IFERROR(AVERAGE(I6:I17),"") -> 0.023130377 | J20: =IFERROR(AVERAGE(J6:J17),"") -> 0.026299307
B21: * 2026 column is year-to-date through 2026-06, not a full year.

Sheet Seasonality Core
B2: Seasonality — IPC Núcleo (core): month-on-month % by calendar year
B3: Core strips out regulated tariffs and seasonal items — the cleanest read on underlying momentum.
B5: Month | C5: 2019 | D5: 2020 | E5: 2021 | F5: 2022 | G5: 2023 | H5: 2024 | I5: 2025 | J5: 2026
B6: Jan | C6: =IF(COUNTIFS(Data!$C$6:$C$114,C$5,Data!$D$6:$D$114,1,Data!$F$6:$F$114,">0")=0,"",SUMIFS(Data!$J$6:$J$114,Data!$C$6:$C$114,C$5,Data!$D$6:$D$114,1)) -> 0.030028066 | D6: =IF(COUNTIFS(Data!$C$6:$C$114,D$5,Data!$D$6:$D$114,1,Data!$F$6:$F$114,">0")=0,"",SUMIFS(Data!$J$6:$J$114,Data!$C$6:$C$114,D$5,Data!$D$6:$D$114,1)) -> 0.024409343 | E6: =IF(COUNTIFS(Data!$C$6:$C$114,E$5,Data!$D$6:$D$114,1,Data!$F$6:$F$114,">0")=0,"",SUMIFS(Data!$J$6:$J$114,Data!$C$6:$C$114,E$5,Data!$D$6:$D$114,1)) -> 0.039158779 | F6: =IF(COUNTIFS(Data!$C$6:$C$114,F$5,Data!$D$6:$D$114,1,Data!$F$6:$F$114,">0")=0,"",SUMIFS(Data!$J$6:$J$114,Data!$C$6:$C$114,F$5,Data!$D$6:$D$114,1)) -> 0.033020978 | G6: =IF(COUNTIFS(Data!$C$6:$C$114,G$5,Data!$D$6:$D$114,1,Data!$F$6:$F$114,">0")=0,"",SUMIFS(Data!$J$6:$J$114,Data!$C$6:$C$114,G$5,Data!$D$6:$D$114,1)) -> 0.053521433 | H6: =IF(COUNTIFS(Data!$C$6:$C$114,H$5,Data!$D$6:$D$114,1,Data!$F$6:$F$114,">0")=0,"",SUMIFS(Data!$J$6:$J$114,Data!$C$6:$C$114,H$5,Data!$D$6:$D$114,1)) -> 0.20216489 | I6: =IF(COUNTIFS(Data!$C$6:$C$114,I$5,Data!$D$6:$D$114,1,Data!$F$6:$F$114,">0")=0,"",SUMIFS(Data!$J$6:$J$114,Data!$C$6:$C$114,I$5,Data!$D$6:$D$114,1)) -> 0.023976894 | J6: =IF(COUNTIFS(Data!$C$6:$C$114,J$5,Data!$D$6:$D$114,1,Data!$F$6:$F$114,">0")=0,"",SUMIFS(Data!$J$6:$J$114,Data!$C$6:$C$114,J$5,Data!$D$6:$D$114,1)) -> 0.026303691
B7: Feb | C7: =IF(COUNTIFS(Data!$C$6:$C$114,C$5,Data!$D$6:$D$114,2,Data!$F$6:$F$114,">0")=0,"",SUMIFS(Data!$J$6:$J$114,Data!$C$6:$C$114,C$5,Data!$D$6:$D$114,2)) -> 0.038554987 | D7: =IF(COUNTIFS(Data!$C$6:$C$114,D$5,Data!$D$6:$D$114,2,Data!$F$6:$F$114,">0")=0,"",SUMIFS(Data!$J$6:$J$114,Data!$C$6:$C$114,D$5,Data!$D$6:$D$114,2)) -> 0.023817625 | E7: =IF(COUNTIFS(Data!$C$6:$C$114,E$5,Data!$D$6:$D$114,2,Data!$F$6:$F$114,">0")=0,"",SUMIFS(Data!$J$6:$J$114,Data!$C$6:$C$114,E$5,Data!$D$6:$D$114,2)) -> 0.040697185 | F7: =IF(COUNTIFS(Data!$C$6:$C$114,F$5,Data!$D$6:$D$114,2,Data!$F$6:$F$114,">0")=0,"",SUMIFS(Data!$J$6:$J$114,Data!$C$6:$C$114,F$5,Data!$D$6:$D$114,2)) -> 0.044507689 | G7: =IF(COUNTIFS(Data!$C$6:$C$114,G$5,Data!$D$6:$D$114,2,Data!$F$6:$F$114,">0")=0,"",SUMIFS(Data!$J$6:$J$114,Data!$C$6:$C$114,G$5,Data!$D$6:$D$114,2)) -> 0.076902164 | H7: =IF(COUNTIFS(Data!$C$6:$C$114,H$5,Data!$D$6:$D$114,2,Data!$F$6:$F$114,">0")=0,"",SUMIFS(Data!$J$6:$J$114,Data!$C$6:$C$114,H$5,Data!$D$6:$D$114,2)) -> 0.12290141 | I7: =IF(COUNTIFS(Data!$C$6:$C$114,I$5,Data!$D$6:$D$114,2,Data!$F$6:$F$114,">0")=0,"",SUMIFS(Data!$J$6:$J$114,Data!$C$6:$C$114,I$5,Data!$D$6:$D$114,2)) -> 0.029203528 | J7: =IF(COUNTIFS(Data!$C$6:$C$114,J$5,Data!$D$6:$D$114,2,Data!$F$6:$F$114,">0")=0,"",SUMIFS(Data!$J$6:$J$114,Data!$C$6:$C$114,J$5,Data!$D$6:$D$114,2)) -> 0.030753752
B8: Mar | C8: =IF(COUNTIFS(Data!$C$6:$C$114,C$5,Data!$D$6:$D$114,3,Data!$F$6:$F$114,">0")=0,"",SUMIFS(Data!$J$6:$J$114,Data!$C$6:$C$114,C$5,Data!$D$6:$D$114,3)) -> 0.045794532 | D8: =IF(COUNTIFS(Data!$C$6:$C$114,D$5,Data!$D$6:$D$114,3,Data!$F$6:$F$114,">0")=0,"",SUMIFS(Data!$J$6:$J$114,Data!$C$6:$C$114,D$5,Data!$D$6:$D$114,3)) -> 0.03120593 | E8: =IF(COUNTIFS(Data!$C$6:$C$114,E$5,Data!$D$6:$D$114,3,Data!$F$6:$F$114,">0")=0,"",SUMIFS(Data!$J$6:$J$114,Data!$C$6:$C$114,E$5,Data!$D$6:$D$114,3)) -> 0.045260548 | F8: =IF(COUNTIFS(Data!$C$6:$C$114,F$5,Data!$D$6:$D$114,3,Data!$F$6:$F$114,">0")=0,"",SUMIFS(Data!$J$6:$J$114,Data!$C$6:$C$114,F$5,Data!$D$6:$D$114,3)) -> 0.063964374 | G8: =IF(COUNTIFS(Data!$C$6:$C$114,G$5,Data!$D$6:$D$114,3,Data!$F$6:$F$114,">0")=0,"",SUMIFS(Data!$J$6:$J$114,Data!$C$6:$C$114,G$5,Data!$D$6:$D$114,3)) -> 0.07210126 | H8: =IF(COUNTIFS(Data!$C$6:$C$114,H$5,Data!$D$6:$D$114,3,Data!$F$6:$F$114,">0")=0,"",SUMIFS(Data!$J$6:$J$114,Data!$C$6:$C$114,H$5,Data!$D$6:$D$114,3)) -> 0.09412048 | I8: =IF(COUNTIFS(Data!$C$6:$C$114,I$5,Data!$D$6:$D$114,3,Data!$F$6:$F$114,">0")=0,"",SUMIFS(Data!$J$6:$J$114,Data!$C$6:$C$114,I$5,Data!$D$6:$D$114,3)) -> 0.031927902 | J8: =IF(COUNTIFS(Data!$C$6:$C$114,J$5,Data!$D$6:$D$114,3,Data!$F$6:$F$114,">0")=0,"",SUMIFS(Data!$J$6:$J$114,Data!$C$6:$C$114,J$5,Data!$D$6:$D$114,3)) -> 0.031889458
B9: Apr | C9: =IF(COUNTIFS(Data!$C$6:$C$114,C$5,Data!$D$6:$D$114,4,Data!$F$6:$F$114,">0")=0,"",SUMIFS(Data!$J$6:$J$114,Data!$C$6:$C$114,C$5,Data!$D$6:$D$114,4)) -> 0.037670643 | D9: =IF(COUNTIFS(Data!$C$6:$C$114,D$5,Data!$D$6:$D$114,4,Data!$F$6:$F$114,">0")=0,"",SUMIFS(Data!$J$6:$J$114,Data!$C$6:$C$114,D$5,Data!$D$6:$D$114,4)) -> 0.017157569 | E9: =IF(COUNTIFS(Data!$C$6:$C$114,E$5,Data!$D$6:$D$114,4,Data!$F$6:$F$114,">0")=0,"",SUMIFS(Data!$J$6:$J$114,Data!$C$6:$C$114,E$5,Data!$D$6:$D$114,4)) -> 0.045589514 | F9: =IF(COUNTIFS(Data!$C$6:$C$114,F$5,Data!$D$6:$D$114,4,Data!$F$6:$F$114,">0")=0,"",SUMIFS(Data!$J$6:$J$114,Data!$C$6:$C$114,F$5,Data!$D$6:$D$114,4)) -> 0.067089744 | G9: =IF(COUNTIFS(Data!$C$6:$C$114,G$5,Data!$D$6:$D$114,4,Data!$F$6:$F$114,">0")=0,"",SUMIFS(Data!$J$6:$J$114,Data!$C$6:$C$114,G$5,Data!$D$6:$D$114,4)) -> 0.08400631 | H9: =IF(COUNTIFS(Data!$C$6:$C$114,H$5,Data!$D$6:$D$114,4,Data!$F$6:$F$114,">0")=0,"",SUMIFS(Data!$J$6:$J$114,Data!$C$6:$C$114,H$5,Data!$D$6:$D$114,4)) -> 0.062984384 | I9: =IF(COUNTIFS(Data!$C$6:$C$114,I$5,Data!$D$6:$D$114,4,Data!$F$6:$F$114,">0")=0,"",SUMIFS(Data!$J$6:$J$114,Data!$C$6:$C$114,I$5,Data!$D$6:$D$114,4)) -> 0.03214716 | J9: =IF(COUNTIFS(Data!$C$6:$C$114,J$5,Data!$D$6:$D$114,4,Data!$F$6:$F$114,">0")=0,"",SUMIFS(Data!$J$6:$J$114,Data!$C$6:$C$114,J$5,Data!$D$6:$D$114,4)) -> 0.022864744
B10: May | C10: =IF(COUNTIFS(Data!$C$6:$C$114,C$5,Data!$D$6:$D$114,5,Data!$F$6:$F$114,">0")=0,"",SUMIFS(Data!$J$6:$J$114,Data!$C$6:$C$114,C$5,Data!$D$6:$D$114,5)) -> 0.031775307 | D10: =IF(COUNTIFS(Data!$C$6:$C$114,D$5,Data!$D$6:$D$114,5,Data!$F$6:$F$114,">0")=0,"",SUMIFS(Data!$J$6:$J$114,Data!$C$6:$C$114,D$5,Data!$D$6:$D$114,5)) -> 0.016056784 | E10: =IF(COUNTIFS(Data!$C$6:$C$114,E$5,Data!$D$6:$D$114,5,Data!$F$6:$F$114,">0")=0,"",SUMIFS(Data!$J$6:$J$114,Data!$C$6:$C$114,E$5,Data!$D$6:$D$114,5)) -> 0.034797507 | F10: =IF(COUNTIFS(Data!$C$6:$C$114,F$5,Data!$D$6:$D$114,5,Data!$F$6:$F$114,">0")=0,"",SUMIFS(Data!$J$6:$J$114,Data!$C$6:$C$114,F$5,Data!$D$6:$D$114,5)) -> 0.052018433 | G10: =IF(COUNTIFS(Data!$C$6:$C$114,G$5,Data!$D$6:$D$114,5,Data!$F$6:$F$114,">0")=0,"",SUMIFS(Data!$J$6:$J$114,Data!$C$6:$C$114,G$5,Data!$D$6:$D$114,5)) -> 0.078417897 | H10: =IF(COUNTIFS(Data!$C$6:$C$114,H$5,Data!$D$6:$D$114,5,Data!$F$6:$F$114,">0")=0,"",SUMIFS(Data!$J$6:$J$114,Data!$C$6:$C$114,H$5,Data!$D$6:$D$114,5)) -> 0.037346867 | I10: =IF(COUNTIFS(Data!$C$6:$C$114,I$5,Data!$D$6:$D$114,5,Data!$F$6:$F$114,">0")=0,"",SUMIFS(Data!$J$6:$J$114,Data!$C$6:$C$114,I$5,Data!$D$6:$D$114,5)) -> 0.02197265 | J10: =IF(COUNTIFS(Data!$C$6:$C$114,J$5,Data!$D$6:$D$114,5,Data!$F$6:$F$114,">0")=0,"",SUMIFS(Data!$J$6:$J$114,Data!$C$6:$C$114,J$5,Data!$D$6:$D$114,5)) -> 0.019034777
B11: Jun | C11: =IF(COUNTIFS(Data!$C$6:$C$114,C$5,Data!$D$6:$D$114,6,Data!$F$6:$F$114,">0")=0,"",SUMIFS(Data!$J$6:$J$114,Data!$C$6:$C$114,C$5,Data!$D$6:$D$114,6)) -> 0.027315926 | D11: =IF(COUNTIFS(Data!$C$6:$C$114,D$5,Data!$D$6:$D$114,6,Data!$F$6:$F$114,">0")=0,"",SUMIFS(Data!$J$6:$J$114,Data!$C$6:$C$114,D$5,Data!$D$6:$D$114,6)) -> 0.023151448 | E11: =IF(COUNTIFS(Data!$C$6:$C$114,E$5,Data!$D$6:$D$114,6,Data!$F$6:$F$114,">0")=0,"",SUMIFS(Data!$J$6:$J$114,Data!$C$6:$C$114,E$5,Data!$D$6:$D$114,6)) -> 0.036096552 | F11: =IF(COUNTIFS(Data!$C$6:$C$114,F$5,Data!$D$6:$D$114,6,Data!$F$6:$F$114,">0")=0,"",SUMIFS(Data!$J$6:$J$114,Data!$C$6:$C$114,F$5,Data!$D$6:$D$114,6)) -> 0.05083388 | G11: =IF(COUNTIFS(Data!$C$6:$C$114,G$5,Data!$D$6:$D$114,6,Data!$F$6:$F$114,">0")=0,"",SUMIFS(Data!$J$6:$J$114,Data!$C$6:$C$114,G$5,Data!$D$6:$D$114,6)) -> 0.064922131 | H11: =IF(COUNTIFS(Data!$C$6:$C$114,H$5,Data!$D$6:$D$114,6,Data!$F$6:$F$114,">0")=0,"",SUMIFS(Data!$J$6:$J$114,Data!$C$6:$C$114,H$5,Data!$D$6:$D$114,6)) -> 0.036511303 | I11: =IF(COUNTIFS(Data!$C$6:$C$114,I$5,Data!$D$6:$D$114,6,Data!$F$6:$F$114,">0")=0,"",SUMIFS(Data!$J$6:$J$114,Data!$C$6:$C$114,I$5,Data!$D$6:$D$114,6)) -> 0.01713735 | J11: =IF(COUNTIFS(Data!$C$6:$C$114,J$5,Data!$D$6:$D$114,6,Data!$F$6:$F$114,">0")=0,"",SUMIFS(Data!$J$6:$J$114,Data!$C$6:$C$114,J$5,Data!$D$6:$D$114,6)) -> 0.015695812
B12: Jul | C12: =IF(COUNTIFS(Data!$C$6:$C$114,C$5,Data!$D$6:$D$114,7,Data!$F$6:$F$114,">0")=0,"",SUMIFS(Data!$J$6:$J$114,Data!$C$6:$C$114,C$5,Data!$D$6:$D$114,7)) -> 0.021476797 | D12: =IF(COUNTIFS(Data!$C$6:$C$114,D$5,Data!$D$6:$D$114,7,Data!$F$6:$F$114,">0")=0,"",SUMIFS(Data!$J$6:$J$114,Data!$C$6:$C$114,D$5,Data!$D$6:$D$114,7)) -> 0.02533274 | E12: =IF(COUNTIFS(Data!$C$6:$C$114,E$5,Data!$D$6:$D$114,7,Data!$F$6:$F$114,">0")=0,"",SUMIFS(Data!$J$6:$J$114,Data!$C$6:$C$114,E$5,Data!$D$6:$D$114,7)) -> 0.031335013 | F12: =IF(COUNTIFS(Data!$C$6:$C$114,F$5,Data!$D$6:$D$114,7,Data!$F$6:$F$114,">0")=0,"",SUMIFS(Data!$J$6:$J$114,Data!$C$6:$C$114,F$5,Data!$D$6:$D$114,7)) -> 0.073288006 | G12: =IF(COUNTIFS(Data!$C$6:$C$114,G$5,Data!$D$6:$D$114,7,Data!$F$6:$F$114,">0")=0,"",SUMIFS(Data!$J$6:$J$114,Data!$C$6:$C$114,G$5,Data!$D$6:$D$114,7)) -> 0.064975294 | H12: =IF(COUNTIFS(Data!$C$6:$C$114,H$5,Data!$D$6:$D$114,7,Data!$F$6:$F$114,">0")=0,"",SUMIFS(Data!$J$6:$J$114,Data!$C$6:$C$114,H$5,Data!$D$6:$D$114,7)) -> 0.037855879 | I12: =IF(COUNTIFS(Data!$C$6:$C$114,I$5,Data!$D$6:$D$114,7,Data!$F$6:$F$114,">0")=0,"",SUMIFS(Data!$J$6:$J$114,Data!$C$6:$C$114,I$5,Data!$D$6:$D$114,7)) -> 0.014791483 | J12: =IF(COUNTIFS(Data!$C$6:$C$114,J$5,Data!$D$6:$D$114,7,Data!$F$6:$F$114,">0")=0,"",SUMIFS(Data!$J$6:$J$114,Data!$C$6:$C$114,J$5,Data!$D$6:$D$114,7))
B13: Aug | C13: =IF(COUNTIFS(Data!$C$6:$C$114,C$5,Data!$D$6:$D$114,8,Data!$F$6:$F$114,">0")=0,"",SUMIFS(Data!$J$6:$J$114,Data!$C$6:$C$114,C$5,Data!$D$6:$D$114,8)) -> 0.046378608 | D13: =IF(COUNTIFS(Data!$C$6:$C$114,D$5,Data!$D$6:$D$114,8,Data!$F$6:$F$114,">0")=0,"",SUMIFS(Data!$J$6:$J$114,Data!$C$6:$C$114,D$5,Data!$D$6:$D$114,8)) -> 0.030332744 | E13: =IF(COUNTIFS(Data!$C$6:$C$114,E$5,Data!$D$6:$D$114,8,Data!$F$6:$F$114,">0")=0,"",SUMIFS(Data!$J$6:$J$114,Data!$C$6:$C$114,E$5,Data!$D$6:$D$114,8)) -> 0.031321875 | F13: =IF(COUNTIFS(Data!$C$6:$C$114,F$5,Data!$D$6:$D$114,8,Data!$F$6:$F$114,">0")=0,"",SUMIFS(Data!$J$6:$J$114,Data!$C$6:$C$114,F$5,Data!$D$6:$D$114,8)) -> 0.068015911 | G13: =IF(COUNTIFS(Data!$C$6:$C$114,G$5,Data!$D$6:$D$114,8,Data!$F$6:$F$114,">0")=0,"",SUMIFS(Data!$J$6:$J$114,Data!$C$6:$C$114,G$5,Data!$D$6:$D$114,8)) -> 0.13786682 | H13: =IF(COUNTIFS(Data!$C$6:$C$114,H$5,Data!$D$6:$D$114,8,Data!$F$6:$F$114,">0")=0,"",SUMIFS(Data!$J$6:$J$114,Data!$C$6:$C$114,H$5,Data!$D$6:$D$114,8)) -> 0.041202856 | I13: =IF(COUNTIFS(Data!$C$6:$C$114,I$5,Data!$D$6:$D$114,8,Data!$F$6:$F$114,">0")=0,"",SUMIFS(Data!$J$6:$J$114,Data!$C$6:$C$114,I$5,Data!$D$6:$D$114,8)) -> 0.020449004 | J13: =IF(COUNTIFS(Data!$C$6:$C$114,J$5,Data!$D$6:$D$114,8,Data!$F$6:$F$114,">0")=0,"",SUMIFS(Data!$J$6:$J$114,Data!$C$6:$C$114,J$5,Data!$D$6:$D$114,8))
B14: Sep | C14: =IF(COUNTIFS(Data!$C$6:$C$114,C$5,Data!$D$6:$D$114,9,Data!$F$6:$F$114,">0")=0,"",SUMIFS(Data!$J$6:$J$114,Data!$C$6:$C$114,C$5,Data!$D$6:$D$114,9)) -> 0.064377642 | D14: =IF(COUNTIFS(Data!$C$6:$C$114,D$5,Data!$D$6:$D$114,9,Data!$F$6:$F$114,">0")=0,"",SUMIFS(Data!$J$6:$J$114,Data!$C$6:$C$114,D$5,Data!$D$6:$D$114,9)) -> 0.023168947 | E14: =IF(COUNTIFS(Data!$C$6:$C$114,E$5,Data!$D$6:$D$114,9,Data!$F$6:$F$114,">0")=0,"",SUMIFS(Data!$J$6:$J$114,Data!$C$6:$C$114,E$5,Data!$D$6:$D$114,9)) -> 0.032621256 | F14: =IF(COUNTIFS(Data!$C$6:$C$114,F$5,Data!$D$6:$D$114,9,Data!$F$6:$F$114,">0")=0,"",SUMIFS(Data!$J$6:$J$114,Data!$C$6:$C$114,F$5,Data!$D$6:$D$114,9)) -> 0.055127813 | G14: =IF(COUNTIFS(Data!$C$6:$C$114,G$5,Data!$D$6:$D$114,9,Data!$F$6:$F$114,">0")=0,"",SUMIFS(Data!$J$6:$J$114,Data!$C$6:$C$114,G$5,Data!$D$6:$D$114,9)) -> 0.13428211 | H14: =IF(COUNTIFS(Data!$C$6:$C$114,H$5,Data!$D$6:$D$114,9,Data!$F$6:$F$114,">0")=0,"",SUMIFS(Data!$J$6:$J$114,Data!$C$6:$C$114,H$5,Data!$D$6:$D$114,9)) -> 0.032622058 | I14: =IF(COUNTIFS(Data!$C$6:$C$114,I$5,Data!$D$6:$D$114,9,Data!$F$6:$F$114,">0")=0,"",SUMIFS(Data!$J$6:$J$114,Data!$C$6:$C$114,I$5,Data!$D$6:$D$114,9)) -> 0.018958762 | J14: =IF(COUNTIFS(Data!$C$6:$C$114,J$5,Data!$D$6:$D$114,9,Data!$F$6:$F$114,">0")=0,"",SUMIFS(Data!$J$6:$J$114,Data!$C$6:$C$114,J$5,Data!$D$6:$D$114,9))
B15: Oct | C15: =IF(COUNTIFS(Data!$C$6:$C$114,C$5,Data!$D$6:$D$114,10,Data!$F$6:$F$114,">0")=0,"",SUMIFS(Data!$J$6:$J$114,Data!$C$6:$C$114,C$5,Data!$D$6:$D$114,10)) -> 0.038046676 | D15: =IF(COUNTIFS(Data!$C$6:$C$114,D$5,Data!$D$6:$D$114,10,Data!$F$6:$F$114,">0")=0,"",SUMIFS(Data!$J$6:$J$114,Data!$C$6:$C$114,D$5,Data!$D$6:$D$114,10)) -> 0.034596016 | E15: =IF(COUNTIFS(Data!$C$6:$C$114,E$5,Data!$D$6:$D$114,10,Data!$F$6:$F$114,">0")=0,"",SUMIFS(Data!$J$6:$J$114,Data!$C$6:$C$114,E$5,Data!$D$6:$D$114,10)) -> 0.032010124 | F15: =IF(COUNTIFS(Data!$C$6:$C$114,F$5,Data!$D$6:$D$114,10,Data!$F$6:$F$114,">0")=0,"",SUMIFS(Data!$J$6:$J$114,Data!$C$6:$C$114,F$5,Data!$D$6:$D$114,10)) -> 0.05549158 | G15: =IF(COUNTIFS(Data!$C$6:$C$114,G$5,Data!$D$6:$D$114,10,Data!$F$6:$F$114,">0")=0,"",SUMIFS(Data!$J$6:$J$114,Data!$C$6:$C$114,G$5,Data!$D$6:$D$114,10)) -> 0.088110343 | H15: =IF(COUNTIFS(Data!$C$6:$C$114,H$5,Data!$D$6:$D$114,10,Data!$F$6:$F$114,">0")=0,"",SUMIFS(Data!$J$6:$J$114,Data!$C$6:$C$114,H$5,Data!$D$6:$D$114,10)) -> 0.029178168 | I15: =IF(COUNTIFS(Data!$C$6:$C$114,I$5,Data!$D$6:$D$114,10,Data!$F$6:$F$114,">0")=0,"",SUMIFS(Data!$J$6:$J$114,Data!$C$6:$C$114,I$5,Data!$D$6:$D$114,10)) -> 0.022167187 | J15: =IF(COUNTIFS(Data!$C$6:$C$114,J$5,Data!$D$6:$D$114,10,Data!$F$6:$F$114,">0")=0,"",SUMIFS(Data!$J$6:$J$114,Data!$C$6:$C$114,J$5,Data!$D$6:$D$114,10))
B16: Nov | C16: =IF(COUNTIFS(Data!$C$6:$C$114,C$5,Data!$D$6:$D$114,11,Data!$F$6:$F$114,">0")=0,"",SUMIFS(Data!$J$6:$J$114,Data!$C$6:$C$114,C$5,Data!$D$6:$D$114,11)) -> 0.039781271 | D16: =IF(COUNTIFS(Data!$C$6:$C$114,D$5,Data!$D$6:$D$114,11,Data!$F$6:$F$114,">0")=0,"",SUMIFS(Data!$J$6:$J$114,Data!$C$6:$C$114,D$5,Data!$D$6:$D$114,11)) -> 0.03937669 | E16: =IF(COUNTIFS(Data!$C$6:$C$114,E$5,Data!$D$6:$D$114,11,Data!$F$6:$F$114,">0")=0,"",SUMIFS(Data!$J$6:$J$114,Data!$C$6:$C$114,E$5,Data!$D$6:$D$114,11)) -> 0.032527366 | F16: =IF(COUNTIFS(Data!$C$6:$C$114,F$5,Data!$D$6:$D$114,11,Data!$F$6:$F$114,">0")=0,"",SUMIFS(Data!$J$6:$J$114,Data!$C$6:$C$114,F$5,Data!$D$6:$D$114,11)) -> 0.047558697 | G16: =IF(COUNTIFS(Data!$C$6:$C$114,G$5,Data!$D$6:$D$114,11,Data!$F$6:$F$114,">0")=0,"",SUMIFS(Data!$J$6:$J$114,Data!$C$6:$C$114,G$5,Data!$D$6:$D$114,11)) -> 0.13403616 | H16: =IF(COUNTIFS(Data!$C$6:$C$114,H$5,Data!$D$6:$D$114,11,Data!$F$6:$F$114,">0")=0,"",SUMIFS(Data!$J$6:$J$114,Data!$C$6:$C$114,H$5,Data!$D$6:$D$114,11)) -> 0.027148339 | I16: =IF(COUNTIFS(Data!$C$6:$C$114,I$5,Data!$D$6:$D$114,11,Data!$F$6:$F$114,">0")=0,"",SUMIFS(Data!$J$6:$J$114,Data!$C$6:$C$114,I$5,Data!$D$6:$D$114,11)) -> 0.026389974 | J16: =IF(COUNTIFS(Data!$C$6:$C$114,J$5,Data!$D$6:$D$114,11,Data!$F$6:$F$114,">0")=0,"",SUMIFS(Data!$J$6:$J$114,Data!$C$6:$C$114,J$5,Data!$D$6:$D$114,11))
B17: Dec | C17: =IF(COUNTIFS(Data!$C$6:$C$114,C$5,Data!$D$6:$D$114,12,Data!$F$6:$F$114,">0")=0,"",SUMIFS(Data!$J$6:$J$114,Data!$C$6:$C$114,C$5,Data!$D$6:$D$114,12)) -> 0.036823011 | D17: =IF(COUNTIFS(Data!$C$6:$C$114,D$5,Data!$D$6:$D$114,12,Data!$F$6:$F$114,">0")=0,"",SUMIFS(Data!$J$6:$J$114,Data!$C$6:$C$114,D$5,Data!$D$6:$D$114,12)) -> 0.04871001 | E17: =IF(COUNTIFS(Data!$C$6:$C$114,E$5,Data!$D$6:$D$114,12,Data!$F$6:$F$114,">0")=0,"",SUMIFS(Data!$J$6:$J$114,Data!$C$6:$C$114,E$5,Data!$D$6:$D$114,12)) -> 0.044232388 | F17: =IF(COUNTIFS(Data!$C$6:$C$114,F$5,Data!$D$6:$D$114,12,Data!$F$6:$F$114,">0")=0,"",SUMIFS(Data!$J$6:$J$114,Data!$C$6:$C$114,F$5,Data!$D$6:$D$114,12)) -> 0.052510803 | G17: =IF(COUNTIFS(Data!$C$6:$C$114,G$5,Data!$D$6:$D$114,12,Data!$F$6:$F$114,">0")=0,"",SUMIFS(Data!$J$6:$J$114,Data!$C$6:$C$114,G$5,Data!$D$6:$D$114,12)) -> 0.2825876 | H17: =IF(COUNTIFS(Data!$C$6:$C$114,H$5,Data!$D$6:$D$114,12,Data!$F$6:$F$114,">0")=0,"",SUMIFS(Data!$J$6:$J$114,Data!$C$6:$C$114,H$5,Data!$D$6:$D$114,12)) -> 0.031972815 | I17: =IF(COUNTIFS(Data!$C$6:$C$114,I$5,Data!$D$6:$D$114,12,Data!$F$6:$F$114,">0")=0,"",SUMIFS(Data!$J$6:$J$114,Data!$C$6:$C$114,I$5,Data!$D$6:$D$114,12)) -> 0.030338921 | J17: =IF(COUNTIFS(Data!$C$6:$C$114,J$5,Data!$D$6:$D$114,12,Data!$F$6:$F$114,">0")=0,"",SUMIFS(Data!$J$6:$J$114,Data!$C$6:$C$114,J$5,Data!$D$6:$D$114,12))
B19: Dec/Dec* | C19: =IFERROR(INDEX(Data!$F:$F,MATCH("2019-12",Data!$B:$B,0))/INDEX(Data!$F:$F,MATCH("2018-12",Data!$B:$B,0))-1,"") -> 0.56657144 | D19: =IFERROR(INDEX(Data!$F:$F,MATCH("2020-12",Data!$B:$B,0))/INDEX(Data!$F:$F,MATCH("2019-12",Data!$B:$B,0))-1,"") -> 0.39404418 | E19: =IFERROR(INDEX(Data!$F:$F,MATCH("2021-12",Data!$B:$B,0))/INDEX(Data!$F:$F,MATCH("2020-12",Data!$B:$B,0))-1,"") -> 0.54869327 | F19: =IFERROR(INDEX(Data!$F:$F,MATCH("2022-12",Data!$B:$B,0))/INDEX(Data!$F:$F,MATCH("2021-12",Data!$B:$B,0))-1,"") -> 0.9061848 | G19: =IFERROR(INDEX(Data!$F:$F,MATCH("2023-12",Data!$B:$B,0))/INDEX(Data!$F:$F,MATCH("2022-12",Data!$B:$B,0))-1,"") -> 2.294057 | H19: =IFERROR(INDEX(Data!$F:$F,MATCH("2024-12",Data!$B:$B,0))/INDEX(Data!$F:$F,MATCH("2023-12",Data!$B:$B,0))-1,"") -> 1.0549513 | I19: =IFERROR(INDEX(Data!$F:$F,MATCH("2025-12",Data!$B:$B,0))/INDEX(Data!$F:$F,MATCH("2024-12",Data!$B:$B,0))-1,"") -> 0.33088474 | J19: =IFERROR(INDEX(Data!$F:$F,MATCH("2026-06",Data!$B:$B,0))/INDEX(Data!$F:$F,MATCH("2025-12",Data!$B:$B,0))-1,"") -> 0.15567274
B20: Avg month | C20: =IFERROR(AVERAGE(C6:C17),"") -> 0.038168622 | D20: =IFERROR(AVERAGE(D6:D17),"") -> 0.028109654 | E20: =IFERROR(AVERAGE(E6:E17),"") -> 0.037137342 | F20: =IFERROR(AVERAGE(F6:F17),"") -> 0.055285659 | G20: =IFERROR(AVERAGE(G6:G17),"") -> 0.10597746 | H20: =IFERROR(AVERAGE(H6:H17),"") -> 0.063000787 | I20: =IFERROR(AVERAGE(I6:I17),"") -> 0.024121735 | J20: =IFERROR(AVERAGE(J6:J17),"") -> 0.024423706
B21: * 2026 column is year-to-date through 2026-06, not a full year.

Sheet Heatmap
B2: Monthly inflation heatmap — year x month
