Workbook

Sheet Resumen Anual
A1: BCRA — Reservas y compras netas en MULC, 2016–2026
A2: Cifras en USD millones. Aproximaciones de informes públicos. Ver hoja 'Cómo usar'.
A4: Año | B4: Reservas Inicio | C4: Reservas Fin | D4: Δ Stock | E4: Compras Netas BCRA (MULC) | F4: Otros (FMI/valuación) | G4: Var % Stock | H4: Compras vs año previo
A5: 2016 | B5: 25500 | C5: 38800 | D5: =IFERROR(C5-B5,"") -> 13300 | E5: 3400 | F5: =IFERROR(D5-E5,"") -> 9900 | G5: =IFERROR(D5/B5,"") -> 0.52156863
A6: 2017 | B6: 38800 | C6: 55055 | D6: =IFERROR(C6-B6,"") -> 16255 | E6: 5900 | F6: =IFERROR(D6-E6,"") -> 10355 | G6: =IFERROR(D6/B6,"") -> 0.4189433 | H6: =IFERROR(E6-E5,"") -> 2500
A7: 2018 | B7: 55055 | C7: 65806 | D7: =IFERROR(C7-B7,"") -> 10751 | E7: -2200 | F7: =IFERROR(D7-E7,"") -> 12951 | G7: =IFERROR(D7/B7,"") -> 0.19527745 | H7: =IFERROR(E7-E6,"") -> -8100
A8: 2019 | B8: 65806 | C8: 44848 | D8: =IFERROR(C8-B8,"") -> -20958 | E8: -15000 | F8: =IFERROR(D8-E8,"") -> -5958 | G8: =IFERROR(D8/B8,"") -> -0.3184816 | H8: =IFERROR(E8-E7,"") -> -12800
A9: 2020 | B9: 44848 | C9: 39400 | D9: =IFERROR(C9-B9,"") -> -5448 | E9: 200 | F9: =IFERROR(D9-E9,"") -> -5648 | G9: =IFERROR(D9/B9,"") -> -0.12147699 | H9: =IFERROR(E9-E8,"") -> 15200
A10: 2021 | B10: 39400 | C10: 39662 | D10: =IFERROR(C10-B10,"") -> 262 | E10: 5000 | F10: =IFERROR(D10-E10,"") -> -4738 | G10: =IFERROR(D10/B10,"") -> 0.0066497462 | H10: =IFERROR(E10-E9,"") -> 4800
A11: 2022 | B11: 39662 | C11: 44538 | D11: =IFERROR(C11-B11,"") -> 4876 | E11: 5800 | F11: =IFERROR(D11-E11,"") -> -924 | G11: =IFERROR(D11/B11,"") -> 0.12293883 | H11: =IFERROR(E11-E10,"") -> 800
A12: 2023 | B12: 44538 | C12: 23073 | D12: =IFERROR(C12-B12,"") -> -21465 | E12: -1900 | F12: =IFERROR(D12-E12,"") -> -19565 | G12: =IFERROR(D12/B12,"") -> -0.481948 | H12: =IFERROR(E12-E11,"") -> -7700
A13: 2024 | B13: 23073 | C13: 29600 | D13: =IFERROR(C13-B13,"") -> 6527 | E13: 19000 | F13: =IFERROR(D13-E13,"") -> -12473 | G13: =IFERROR(D13/B13,"") -> 0.28288476 | H13: =IFERROR(E13-E12,"") -> 20900
A14: 2025 | B14: 29600 | C14: 41100 | D14: =IFERROR(C14-B14,"") -> 11500 | E14: 4500 | F14: =IFERROR(D14-E14,"") -> 7000 | G14: =IFERROR(D14/B14,"") -> 0.38851351 | H14: =IFERROR(E14-E13,"") -> -14500
A15: 2026 | B15: 41100 | C15: ='Detalle Diario 2026'!B85 -> 46286 | D15: =IFERROR(C15-B15,"") -> 5186 | E15: ='Detalle Diario 2026'!I85 -> 6491 | F15: =IFERROR(D15-E15,"") -> -1305 | G15: =IFERROR(D15/B15,"") -> 0.12618005 | H15: =IFERROR(E15-E14,"") -> 1991

Sheet YTD Comparativo
A1: Compras netas acumuladas (YTD) — comparativo año por año
A4: Año | B4: Ene | C4: Feb | D4: Mar | E4: Abr | F4: May | G4: Jun | H4: Jul | I4: Ago | J4: Sep | K4: Oct | L4: Nov | M4: Dic
A5: 2016 | B5: =ROUND('Resumen Anual'!E5*0.05,0) -> 170 | C5: =ROUND('Resumen Anual'!E5*0.11,0) -> 374 | D5: =ROUND('Resumen Anual'!E5*0.21,0) -> 714 | E5: =ROUND('Resumen Anual'!E5*0.34,0) -> 1156 | F5: =ROUND('Resumen Anual'!E5*0.47,0) -> 1598 | G5: =ROUND('Resumen Anual'!E5*0.59,0) -> 2006 | H5: =ROUND('Resumen Anual'!E5*0.7,0) -> 2380 | I5: =ROUND('Resumen Anual'!E5*0.79,0) -> 2686 | J5: =ROUND('Resumen Anual'!E5*0.87,0) -> 2958 | K5: =ROUND('Resumen Anual'!E5*0.93,0) -> 3162 | L5: =ROUND('Resumen Anual'!E5*0.97,0) -> 3298 | M5: =ROUND('Resumen Anual'!E5*1,0) -> 3400
A6: 2017 | B6: =ROUND('Resumen Anual'!E6*0.05,0) -> 295 | C6: =ROUND('Resumen Anual'!E6*0.11,0) -> 649 | D6: =ROUND('Resumen Anual'!E6*0.21,0) -> 1239 | E6: =ROUND('Resumen Anual'!E6*0.34,0) -> 2006 | F6: =ROUND('Resumen Anual'!E6*0.47,0) -> 2773 | G6: =ROUND('Resumen Anual'!E6*0.59,0) -> 3481 | H6: =ROUND('Resumen Anual'!E6*0.7,0) -> 4130 | I6: =ROUND('Resumen Anual'!E6*0.79,0) -> 4661 | J6: =ROUND('Resumen Anual'!E6*0.87,0) -> 5133 | K6: =ROUND('Resumen Anual'!E6*0.93,0) -> 5487 | L6: =ROUND('Resumen Anual'!E6*0.97,0) -> 5723 | M6: =ROUND('Resumen Anual'!E6*1,0) -> 5900
A7: 2018 | B7: =ROUND('Resumen Anual'!E7*0.05,0) -> -110 | C7: =ROUND('Resumen Anual'!E7*0.11,0) -> -242 | D7: =ROUND('Resumen Anual'!E7*0.21,0) -> -462 | E7: =ROUND('Resumen Anual'!E7*0.34,0) -> -748 | F7: =ROUND('Resumen Anual'!E7*0.47,0) -> -1034 | G7: =ROUND('Resumen Anual'!E7*0.59,0) -> -1298 | H7: =ROUND('Resumen Anual'!E7*0.7,0) -> -1540 | I7: =ROUND('Resumen Anual'!E7*0.79,0) -> -1738 | J7: =ROUND('Resumen Anual'!E7*0.87,0) -> -1914 | K7: =ROUND('Resumen Anual'!E7*0.93,0) -> -2046 | L7: =ROUND('Resumen Anual'!E7*0.97,0) -> -2134 | M7: =ROUND('Resumen Anual'!E7*1,0) -> -2200
A8: 2019 | B8: =ROUND('Resumen Anual'!E8*0.05,0) -> -750 | C8: =ROUND('Resumen Anual'!E8*0.11,0) -> -1650 | D8: =ROUND('Resumen Anual'!E8*0.21,0) -> -3150 | E8: =ROUND('Resumen Anual'!E8*0.34,0) -> -5100 | F8: =ROUND('Resumen Anual'!E8*0.47,0) -> -7050 | G8: =ROUND('Resumen Anual'!E8*0.59,0) -> -8850 | H8: =ROUND('Resumen Anual'!E8*0.7,0) -> -10500 | I8: =ROUND('Resumen Anual'!E8*0.79,0) -> -11850 | J8: =ROUND('Resumen Anual'!E8*0.87,0) -> -13050 | K8: =ROUND('Resumen Anual'!E8*0.93,0) -> -13950 | L8: =ROUND('Resumen Anual'!E8*0.97,0) -> -14550 | M8: =ROUND('Resumen Anual'!E8*1,0) -> -15000
A9: 2020 | B9: =ROUND('Resumen Anual'!E9*0.05,0) -> 10 | C9: =ROUND('Resumen Anual'!E9*0.11,0) -> 22 | D9: =ROUND('Resumen Anual'!E9*0.21,0) -> 42 | E9: =ROUND('Resumen Anual'!E9*0.34,0) -> 68 | F9: =ROUND('Resumen Anual'!E9*0.47,0) -> 94 | G9: =ROUND('Resumen Anual'!E9*0.59,0) -> 118 | H9: =ROUND('Resumen Anual'!E9*0.7,0) -> 140 | I9: =ROUND('Resumen Anual'!E9*0.79,0) -> 158 | J9: =ROUND('Resumen Anual'!E9*0.87,0) -> 174 | K9: =ROUND('Resumen Anual'!E9*0.93,0) -> 186 | L9: =ROUND('Resumen Anual'!E9*0.97,0) -> 194 | M9: =ROUND('Resumen Anual'!E9*1,0) -> 200
A10: 2021 | B10: =ROUND('Resumen Anual'!E10*0.05,0) -> 250 | C10: =ROUND('Resumen Anual'!E10*0.11,0) -> 550 | D10: =ROUND('Resumen Anual'!E10*0.21,0) -> 1050 | E10: =ROUND('Resumen Anual'!E10*0.34,0) -> 1700 | F10: =ROUND('Resumen Anual'!E10*0.47,0) -> 2350 | G10: =ROUND('Resumen Anual'!E10*0.59,0) -> 2950 | H10: =ROUND('Resumen Anual'!E10*0.7,0) -> 3500 | I10: =ROUND('Resumen Anual'!E10*0.79,0) -> 3950 | J10: =ROUND('Resumen Anual'!E10*0.87,0) -> 4350 | K10: =ROUND('Resumen Anual'!E10*0.93,0) -> 4650 | L10: =ROUND('Resumen Anual'!E10*0.97,0) -> 4850 | M10: =ROUND('Resumen Anual'!E10*1,0) -> 5000
A11: 2022 | B11: =ROUND('Resumen Anual'!E11*0.05,0) -> 290 | C11: =ROUND('Resumen Anual'!E11*0.11,0) -> 638 | D11: =ROUND('Resumen Anual'!E11*0.21,0) -> 1218 | E11: =ROUND('Resumen Anual'!E11*0.34,0) -> 1972 | F11: =ROUND('Resumen Anual'!E11*0.47,0) -> 2726 | G11: =ROUND('Resumen Anual'!E11*0.59,0) -> 3422 | H11: =ROUND('Resumen Anual'!E11*0.7,0) -> 4060 | I11: =ROUND('Resumen Anual'!E11*0.79,0) -> 4582 | J11: =ROUND('Resumen Anual'!E11*0.87,0) -> 5046 | K11: =ROUND('Resumen Anual'!E11*0.93,0) -> 5394 | L11: =ROUND('Resumen Anual'!E11*0.97,0) -> 5626 | M11: =ROUND('Resumen Anual'!E11*1,0) -> 5800
A12: 2023 | B12: =ROUND('Resumen Anual'!E12*0.05,0) -> -95 | C12: =ROUND('Resumen Anual'!E12*0.11,0) -> -209 | D12: =ROUND('Resumen Anual'!E12*0.21,0) -> -399 | E12: =ROUND('Resumen Anual'!E12*0.34,0) -> -646 | F12: =ROUND('Resumen Anual'!E12*0.47,0) -> -893 | G12: =ROUND('Resumen Anual'!E12*0.59,0) -> -1121 | H12: =ROUND('Resumen Anual'!E12*0.7,0) -> -1330 | I12: =ROUND('Resumen Anual'!E12*0.79,0) -> -1501 | J12: =ROUND('Resumen Anual'!E12*0.87,0) -> -1653 | K12: =ROUND('Resumen Anual'!E12*0.93,0) -> -1767 | L12: =ROUND('Resumen Anual'!E12*0.97,0) -> -1843 | M12: =ROUND('Resumen Anual'!E12*1,0) -> -1900
A13: 2024 | B13: =ROUND('Resumen Anual'!E13*0.05,0) -> 950 | C13: =ROUND('Resumen Anual'!E13*0.11,0) -> 2090 | D13: =ROUND('Resumen Anual'!E13*0.21,0) -> 3990 | E13: =ROUND('Resumen Anual'!E13*0.34,0) -> 6460 | F13: =ROUND('Resumen Anual'!E13*0.47,0) -> 8930 | G13: =ROUND('Resumen Anual'!E13*0.59,0) -> 11210 | H13: =ROUND('Resumen Anual'!E13*0.7,0) -> 13300 | I13: =ROUND('Resumen Anual'!E13*0.79,0) -> 15010 | J13: =ROUND('Resumen Anual'!E13*0.87,0) -> 16530 | K13: =ROUND('Resumen Anual'!E13*0.93,0) -> 17670 | L13: =ROUND('Resumen Anual'!E13*0.97,0) -> 18430 | M13: =ROUND('Resumen Anual'!E13*1,0) -> 19000
A14: 2025 | B14: =ROUND('Resumen Anual'!E14*0.05,0) -> 225 | C14: =ROUND('Resumen Anual'!E14*0.11,0) -> 495 | D14: =ROUND('Resumen Anual'!E14*0.21,0) -> 945 | E14: =ROUND('Resumen Anual'!E14*0.34,0) -> 1530 | F14: =ROUND('Resumen Anual'!E14*0.47,0) -> 2115 | G14: =ROUND('Resumen Anual'!E14*0.59,0) -> 2655 | H14: =ROUND('Resumen Anual'!E14*0.7,0) -> 3150 | I14: =ROUND('Resumen Anual'!E14*0.79,0) -> 3555 | J14: =ROUND('Resumen Anual'!E14*0.87,0) -> 3915 | K14: =ROUND('Resumen Anual'!E14*0.93,0) -> 4185 | L14: =ROUND('Resumen Anual'!E14*0.97,0) -> 4365 | M14: =ROUND('Resumen Anual'!E14*1,0) -> 4500
A15: 2026 | B15: 1400 | C15: 3200 | D15: 4900 | E15: 6500

Sheet Heatmap Compras
A1: Heatmap de compras mensuales del BCRA en MULC (USD mm)
A2: Verde = compras; rojo = ventas. Intensidad por monto. Lee hoja 'Rolling 12m' como fuente.
A4: Año | B4: Ene | C4: Feb | D4: Mar | E4: Abr | F4: May | G4: Jun | H4: Jul | I4: Ago | J4: Sep | K4: Oct | L4: Nov | M4: Dic
A5: 2016 | B5: ='Rolling 12m'!C5 -> 170 | C5: ='Rolling 12m'!C6 -> 204 | D5: ='Rolling 12m'!C7 -> 340 | E5: ='Rolling 12m'!C8 -> 442 | F5: ='Rolling 12m'!C9 -> 442 | G5: ='Rolling 12m'!C10 -> 408 | H5: ='Rolling 12m'!C11 -> 374 | I5: ='Rolling 12m'!C12 -> 306 | J5: ='Rolling 12m'!C13 -> 272 | K5: ='Rolling 12m'!C14 -> 204 | L5: ='Rolling 12m'!C15 -> 136 | M5: ='Rolling 12m'!C16 -> 102
A6: 2017 | B6: ='Rolling 12m'!C17 -> 295 | C6: ='Rolling 12m'!C18 -> 354 | D6: ='Rolling 12m'!C19 -> 590 | E6: ='Rolling 12m'!C20 -> 767 | F6: ='Rolling 12m'!C21 -> 767 | G6: ='Rolling 12m'!C22 -> 708 | H6: ='Rolling 12m'!C23 -> 649 | I6: ='Rolling 12m'!C24 -> 531 | J6: ='Rolling 12m'!C25 -> 472 | K6: ='Rolling 12m'!C26 -> 354 | L6: ='Rolling 12m'!C27 -> 236 | M6: ='Rolling 12m'!C28 -> 177
A7: 2018 | B7: ='Rolling 12m'!C29 -> -110 | C7: ='Rolling 12m'!C30 -> -132 | D7: ='Rolling 12m'!C31 -> -220 | E7: ='Rolling 12m'!C32 -> -286 | F7: ='Rolling 12m'!C33 -> -286 | G7: ='Rolling 12m'!C34 -> -264 | H7: ='Rolling 12m'!C35 -> -242 | I7: ='Rolling 12m'!C36 -> -198 | J7: ='Rolling 12m'!C37 -> -176 | K7: ='Rolling 12m'!C38 -> -132 | L7: ='Rolling 12m'!C39 -> -88 | M7: ='Rolling 12m'!C40 -> -66
A8: 2019 | B8: ='Rolling 12m'!C41 -> -750 | C8: ='Rolling 12m'!C42 -> -900 | D8: ='Rolling 12m'!C43 -> -1500 | E8: ='Rolling 12m'!C44 -> -1950 | F8: ='Rolling 12m'!C45 -> -1950 | G8: ='Rolling 12m'!C46 -> -1800 | H8: ='Rolling 12m'!C47 -> -1650 | I8: ='Rolling 12m'!C48 -> -1350 | J8: ='Rolling 12m'!C49 -> -1200 | K8: ='Rolling 12m'!C50 -> -900 | L8: ='Rolling 12m'!C51 -> -600 | M8: ='Rolling 12m'!C52 -> -450
A9: 2020 | B9: ='Rolling 12m'!C53 -> 10 | C9: ='Rolling 12m'!C54 -> 12 | D9: ='Rolling 12m'!C55 -> 20 | E9: ='Rolling 12m'!C56 -> 26 | F9: ='Rolling 12m'!C57 -> 26 | G9: ='Rolling 12m'!C58 -> 24 | H9: ='Rolling 12m'!C59 -> 22 | I9: ='Rolling 12m'!C60 -> 18 | J9: ='Rolling 12m'!C61 -> 16 | K9: ='Rolling 12m'!C62 -> 12 | L9: ='Rolling 12m'!C63 -> 8 | M9: ='Rolling 12m'!C64 -> 6
A10: 2021 | B10: ='Rolling 12m'!C65 -> 250 | C10: ='Rolling 12m'!C66 -> 300 | D10: ='Rolling 12m'!C67 -> 500 | E10: ='Rolling 12m'!C68 -> 650 | F10: ='Rolling 12m'!C69 -> 650 | G10: ='Rolling 12m'!C70 -> 600 | H10: ='Rolling 12m'!C71 -> 550 | I10: ='Rolling 12m'!C72 -> 450 | J10: ='Rolling 12m'!C73 -> 400 | K10: ='Rolling 12m'!C74 -> 300 | L10: ='Rolling 12m'!C75 -> 200 | M10: ='Rolling 12m'!C76 -> 150
A11: 2022 | B11: ='Rolling 12m'!C77 -> 290 | C11: ='Rolling 12m'!C78 -> 348 | D11: ='Rolling 12m'!C79 -> 580 | E11: ='Rolling 12m'!C80 -> 754 | F11: ='Rolling 12m'!C81 -> 754 | G11: ='Rolling 12m'!C82 -> 696 | H11: ='Rolling 12m'!C83 -> 638 | I11: ='Rolling 12m'!C84 -> 522 | J11: ='Rolling 12m'!C85 -> 464 | K11: ='Rolling 12m'!C86 -> 348 | L11: ='Rolling 12m'!C87 -> 232 | M11: ='Rolling 12m'!C88 -> 174
A12: 2023 | B12: ='Rolling 12m'!C89 -> -95 | C12: ='Rolling 12m'!C90 -> -114 | D12: ='Rolling 12m'!C91 -> -190 | E12: ='Rolling 12m'!C92 -> -247 | F12: ='Rolling 12m'!C93 -> -247 | G12: ='Rolling 12m'!C94 -> -228 | H12: ='Rolling 12m'!C95 -> -209 | I12: ='Rolling 12m'!C96 -> -171 | J12: ='Rolling 12m'!C97 -> -152 | K12: ='Rolling 12m'!C98 -> -114 | L12: ='Rolling 12m'!C99 -> -76 | M12: ='Rolling 12m'!C100 -> -57
A13: 2024 | B13: ='Rolling 12m'!C101 -> 950 | C13: ='Rolling 12m'!C102 -> 1140 | D13: ='Rolling 12m'!C103 -> 1900 | E13: ='Rolling 12m'!C104 -> 2470 | F13: ='Rolling 12m'!C105 -> 2470 | G13: ='Rolling 12m'!C106 -> 2280 | H13: ='Rolling 12m'!C107 -> 2090 | I13: ='Rolling 12m'!C108 -> 1710 | J13: ='Rolling 12m'!C109 -> 1520 | K13: ='Rolling 12m'!C110 -> 1140 | L13: ='Rolling 12m'!C111 -> 760 | M13: ='Rolling 12m'!C112 -> 570
A14: 2025 | B14: ='Rolling 12m'!C113 -> 225 | C14: ='Rolling 12m'!C114 -> 270 | D14: ='Rolling 12m'!C115 -> 450 | E14: ='Rolling 12m'!C116 -> 585 | F14: ='Rolling 12m'!C117 -> 585 | G14: ='Rolling 12m'!C118 -> 540 | H14: ='Rolling 12m'!C119 -> 495 | I14: ='Rolling 12m'!C120 -> 405 | J14: ='Rolling 12m'!C121 -> 360 | K14: ='Rolling 12m'!C122 -> 270 | L14: ='Rolling 12m'!C123 -> 180 | M14: ='Rolling 12m'!C124 -> 135
A15: 2026 | B15: ='Rolling 12m'!C125 -> 1400 | C15: ='Rolling 12m'!C126 -> 1800 | D15: ='Rolling 12m'!C127 -> 1700 | E15: ='Rolling 12m'!C128 -> 1600

Sheet Rolling 12m
A1: Compras mensuales y suma móvil de 12 meses
A4: Año | B4: Mes | C4: Compra Neta Mensual | D4: Rolling 12m
A5: 2016 | B5: Ene | C5: =ROUND('Resumen Anual'!E5*0.05,0) -> 170
A6: 2016 | B6: Feb | C6: =ROUND('Resumen Anual'!E5*0.06,0) -> 204
A7: 2016 | B7: Mar | C7: =ROUND('Resumen Anual'!E5*0.1,0) -> 340
A8: 2016 | B8: Abr | C8: =ROUND('Resumen Anual'!E5*0.13,0) -> 442
A9: 2016 | B9: May | C9: =ROUND('Resumen Anual'!E5*0.13,0) -> 442
A10: 2016 | B10: Jun | C10: =ROUND('Resumen Anual'!E5*0.12,0) -> 408
A11: 2016 | B11: Jul | C11: =ROUND('Resumen Anual'!E5*0.11,0) -> 374
A12: 2016 | B12: Ago | C12: =ROUND('Resumen Anual'!E5*0.09,0) -> 306
A13: 2016 | B13: Sep | C13: =ROUND('Resumen Anual'!E5*0.08,0) -> 272
A14: 2016 | B14: Oct | C14: =ROUND('Resumen Anual'!E5*0.06,0) -> 204
A15: 2016 | B15: Nov | C15: =ROUND('Resumen Anual'!E5*0.04,0) -> 136
A16: 2016 | B16: Dic | C16: =ROUND('Resumen Anual'!E5*0.03,0) -> 102 | D16: =SUM(C5:C16) -> 3400
A17: 2017 | B17: Ene | C17: =ROUND('Resumen Anual'!E6*0.05,0) -> 295 | D17: =SUM(C6:C17) -> 3525
A18: 2017 | B18: Feb | C18: =ROUND('Resumen Anual'!E6*0.06,0) -> 354 | D18: =SUM(C7:C18) -> 3675
A19: 2017 | B19: Mar | C19: =ROUND('Resumen Anual'!E6*0.1,0) -> 590 | D19: =SUM(C8:C19) -> 3925
A20: 2017 | B20: Abr | C20: =ROUND('Resumen Anual'!E6*0.13,0) -> 767 | D20: =SUM(C9:C20) -> 4250
A21: 2017 | B21: May | C21: =ROUND('Resumen Anual'!E6*0.13,0) -> 767 | D21: =SUM(C10:C21) -> 4575
A22: 2017 | B22: Jun | C22: =ROUND('Resumen Anual'!E6*0.12,0) -> 708 | D22: =SUM(C11:C22) -> 4875
A23: 2017 | B23: Jul | C23: =ROUND('Resumen Anual'!E6*0.11,0) -> 649 | D23: =SUM(C12:C23) -> 5150
A24: 2017 | B24: Ago | C24: =ROUND('Resumen Anual'!E6*0.09,0) -> 531 | D24: =SUM(C13:C24) -> 5375
A25: 2017 | B25: Sep | C25: =ROUND('Resumen Anual'!E6*0.08,0) -> 472 | D25: =SUM(C14:C25) -> 5575
A26: 2017 | B26: Oct | C26: =ROUND('Resumen Anual'!E6*0.06,0) -> 354 | D26: =SUM(C15:C26) -> 5725
A27: 2017 | B27: Nov | C27: =ROUND('Resumen Anual'!E6*0.04,0) -> 236 | D27: =SUM(C16:C27) -> 5825
A28: 2017 | B28: Dic | C28: =ROUND('Resumen Anual'!E6*0.03,0) -> 177 | D28: =SUM(C17:C28) -> 5900
A29: 2018 | B29: Ene | C29: =ROUND('Resumen Anual'!E7*0.05,0) -> -110 | D29: =SUM(C18:C29) -> 5495
A30: 2018 | B30: Feb | C30: =ROUND('Resumen Anual'!E7*0.06,0) -> -132 | D30: =SUM(C19:C30) -> 5009
A31: 2018 | B31: Mar | C31: =ROUND('Resumen Anual'!E7*0.1,0) -> -220 | D31: =SUM(C20:C31) -> 4199
A32: 2018 | B32: Abr | C32: =ROUND('Resumen Anual'!E7*0.13,0) -> -286 | D32: =SUM(C21:C32) -> 3146
A33: 2018 | B33: May | C33: =ROUND('Resumen Anual'!E7*0.13,0) -> -286 | D33: =SUM(C22:C33) -> 2093
A34: 2018 | B34: Jun | C34: =ROUND('Resumen Anual'!E7*0.12,0) -> -264 | D34: =SUM(C23:C34) -> 1121
A35: 2018 | B35: Jul | C35: =ROUND('Resumen Anual'!E7*0.11,0) -> -242 | D35: =SUM(C24:C35) -> 230
A36: 2018 | B36: Ago | C36: =ROUND('Resumen Anual'!E7*0.09,0) -> -198 | D36: =SUM(C25:C36) -> -499
A37: 2018 | B37: Sep | C37: =ROUND('Resumen Anual'!E7*0.08,0) -> -176 | D37: =SUM(C26:C37) -> -1147
A38: 2018 | B38: Oct | C38: =ROUND('Resumen Anual'!E7*0.06,0) -> -132 | D38: =SUM(C27:C38) -> -1633
A39: 2018 | B39: Nov | C39: =ROUND('Resumen Anual'!E7*0.04,0) -> -88 | D39: =SUM(C28:C39) -> -1957
A40: 2018 | B40: Dic | C40: =ROUND('Resumen Anual'!E7*0.03,0) -> -66 | D40: =SUM(C29:C40) -> -2200
A41: 2019 | B41: Ene | C41: =ROUND('Resumen Anual'!E8*0.05,0) -> -750 | D41: =SUM(C30:C41) -> -2840
A42: 2019 | B42: Feb | C42: =ROUND('Resumen Anual'!E8*0.06,0) -> -900 | D42: =SUM(C31:C42) -> -3608
...

Sheet Detalle Diario 2026
A1: Detalle diario 2026 — reconstrucción de compras BCRA en MULC
A2: YTD: 81 ruedas (2-ene a 4-may). Convenciones: azul=ingreso manual; negro=fórmula. USD mm.
A4: Fecha | B4: Reservas Brutas | C4: Δ Reservas | D4: Pagos Organismos | E4: Efecto Valuación | F4: Mov. Encajes | G4: Op. Tesoro | H4: Compra BCRA Estimada | I4: Compra Acumulada
A5: 46024 | B5: 40759 | C5: =IFERROR(B5-B4,0) -> 0 | D5: 0 | E5: -6 | F5: 0 | G5: 0 | H5: =C5+D5-E5-F5+G5 -> 6 | I5: =H5 -> 6
A6: 46027 | B6: 40836 | C6: =IFERROR(B6-B5,0) -> 77 | D6: 0 | E6: 13 | F6: 0 | G6: 0 | H6: =C6+D6-E6-F6+G6 -> 64 | I6: =I5+H6 -> 70
A7: 46028 | B7: 40896 | C7: =IFERROR(B7-B6,0) -> 60 | D7: 0 | E7: -6 | F7: 0 | G7: 0 | H7: =C7+D7-E7-F7+G7 -> 66 | I7: =I6+H7 -> 136
A8: 46029 | B8: 40983 | C8: =IFERROR(B8-B7,0) -> 87 | D8: 0 | E8: -8 | F8: 0 | G8: 0 | H8: =C8+D8-E8-F8+G8 -> 95 | I8: =I7+H8 -> 231
A9: 46030 | B9: 40971 | C9: =IFERROR(B9-B8,0) -> -12 | D9: 0 | E9: -23 | F9: 0 | G9: 0 | H9: =C9+D9-E9-F9+G9 -> 11 | I9: =I8+H9 -> 242
A10: 46031 | B10: 40984 | C10: =IFERROR(B10-B9,0) -> 13 | D10: 0 | E10: -5 | F10: 0 | G10: 0 | H10: =C10+D10-E10-F10+G10 -> 18 | I10: =I9+H10 -> 260
A11: 46034 | B11: 41094 | C11: =IFERROR(B11-B10,0) -> 110 | D11: 0 | E11: 28 | F11: 0 | G11: 0 | H11: =C11+D11-E11-F11+G11 -> 82 | I11: =I10+H11 -> 342
A12: 46035 | B12: 41166 | C12: =IFERROR(B12-B11,0) -> 72 | D12: 0 | E12: 11 | F12: 0 | G12: 0 | H12: =C12+D12-E12-F12+G12 -> 61 | I12: =I11+H12 -> 403
A13: 46036 | B13: 41254 | C13: =IFERROR(B13-B12,0) -> 88 | D13: 0 | E13: 26 | F13: 0 | G13: 0 | H13: =C13+D13-E13-F13+G13 -> 62 | I13: =I12+H13 -> 465
A14: 46037 | B14: 41334 | C14: =IFERROR(B14-B13,0) -> 80 | D14: 0 | E14: 6 | F14: 0 | G14: 0 | H14: =C14+D14-E14-F14+G14 -> 74 | I14: =I13+H14 -> 539
A15: 46038 | B15: 41400 | C15: =IFERROR(B15-B14,0) -> 66 | D15: 0 | E15: 10 | F15: 30 | G15: 0 | H15: =C15+D15-E15-F15+G15 -> 26 | I15: =I14+H15 -> 565
A16: 46041 | B16: 41516 | C16: =IFERROR(B16-B15,0) -> 116 | D16: 0 | E16: 5 | F16: 0 | G16: 0 | H16: =C16+D16-E16-F16+G16 -> 111 | I16: =I15+H16 -> 676
A17: 46042 | B17: 41567 | C17: =IFERROR(B17-B16,0) -> 51 | D17: 0 | E17: -42 | F17: 0 | G17: 0 | H17: =C17+D17-E17-F17+G17 -> 93 | I17: =I16+H17 -> 769
... A85: 46146 | B85: 46286 | C85: =IFERROR(B85-B84,0) -> 56 | D85: 0 | E85: 6 | F85: 0 | G85: 0 | H85: =C85+D85-E85-F85+G85 -> 50 | I85: =I84+H85 -> 6491

Sheet Streaks
A1: Días consecutivos con compras del BCRA
A2: Calcula la racha actual (en curso) y la racha máxima del año a partir del Detalle Diario 2026.
A4: Fecha | B4: Compra (USD mm) | C4: Racha (días con compra) | E4: Indicador | F4: Valor
A5: ='Detalle Diario 2026'!A5 -> 46024 | B5: ='Detalle Diario 2026'!H5 -> 6 | C5: =IF(B5>0,1,0) -> 1 | E5: Racha máxima del año | F5: =MAX(C5:C85) -> 30
A6: ='Detalle Diario 2026'!A6 -> 46027 | B6: ='Detalle Diario 2026'!H6 -> 64 | C6: =IF(B6>0,C5+1,0) -> 2 | E6: Racha actual (al último día) | F6: =C85 -> 4
A7: ='Detalle Diario 2026'!A7 -> 46028 | B7: ='Detalle Diario 2026'!H7 -> 66 | C7: =IF(B7>0,C6+1,0) -> 3 | E7: Total ruedas con compra positiva | F7: =COUNTIF(B5:B85,">0") -> 77
A8: ='Detalle Diario 2026'!A8 -> 46029 | B8: ='Detalle Diario 2026'!H8 -> 95 | C8: =IF(B8>0,C7+1,0) -> 4 | E8: Total ruedas con venta neta | F8: =COUNTIF(B5:B85,"<0") -> 3
A9: ='Detalle Diario 2026'!A9 -> 46030 | B9: ='Detalle Diario 2026'!H9 -> 11 | C9: =IF(B9>0,C8+1,0) -> 5 | E9: Total ruedas neutras | F9: =COUNTIF(B5:B85,0) -> 1
A10: ='Detalle Diario 2026'!A10 -> 46031 | B10: ='Detalle Diario 2026'!H10 -> 18 | C10: =IF(B10>0,C9+1,0) -> 6 | E10: % ruedas con compra | F10: =F7/COUNTA(A5:A85) -> 0.95061728
A11: ='Detalle Diario 2026'!A11 -> 46034 | B11: ='Detalle Diario 2026'!H11 -> 82 | C11: =IF(B11>0,C10+1,0) -> 7
A12: ='Detalle Diario 2026'!A12 -> 46035 | B12: ='Detalle Diario 2026'!H12 -> 61 | C12: =IF(B12>0,C11+1,0) -> 8
A13: ='Detalle Diario 2026'!A13 -> 46036 | B13: ='Detalle Diario 2026'!H13 -> 62 | C13: =IF(B13>0,C12+1,0) -> 9
A14: ='Detalle Diario 2026'!A14 -> 46037 | B14: ='Detalle Diario 2026'!H14 -> 74 | C14: =IF(B14>0,C13+1,0) -> 10
A15: ='Detalle Diario 2026'!A15 -> 46038 | B15: ='Detalle Diario 2026'!H15 -> 26 | C15: =IF(B15>0,C14+1,0) -> 11
A16: ='Detalle Diario 2026'!A16 -> 46041 | B16: ='Detalle Diario 2026'!H16 -> 111 | C16: =IF(B16>0,C15+1,0) -> 12
A17: ='Detalle Diario 2026'!A17 -> 46042 | B17: ='Detalle Diario 2026'!H17 -> 93 | C17: =IF(B17>0,C16+1,0) -> 13
A18: ='Detalle Diario 2026'!A18 -> 46043 | B18: ='Detalle Diario 2026'!H18 -> 74 | C18: =IF(B18>0,C17+1,0) -> 14
A19: ='Detalle Diario 2026'!A19 -> 46044 | B19: ='Detalle Diario 2026'!H19 -> 44 | C19: =IF(B19>0,C18+1,0) -> 15
A20: ='Detalle Diario 2026'!A20 -> 46045 | B20: ='Detalle Diario 2026'!H20 -> 34 | C20: =IF(B20>0,C19+1,0) -> 16
A21: ='Detalle Diario 2026'!A21 -> 46048 | B21: ='Detalle Diario 2026'!H21 -> 79 | C21: =IF(B21>0,C20+1,0) -> 17
A22: ='Detalle Diario 2026'!A22 -> 46049 | B22: ='Detalle Diario 2026'!H22 -> 116 | C22: =IF(B22>0,C21+1,0) -> 18
... A85: ='Detalle Diario 2026'!A85 -> 46146 | B85: ='Detalle Diario 2026'!H85 -> 50 | C85: =IF(B85>0,C84+1,0) -> 4

Sheet Validación
A1: Validación: Compra Estimada (mi reconstrucción) vs Compra Real (BCRA)
A2: La columna 'Real' tira de la hoja 'Datos Reales BCRA' que llena el script update_bcra.py. Si todavía no la corriste, queda vacía y el error se ve como N/A.
A4: Fecha | B4: Estimada | C4: Real (BCRA) | D4: Error | E4: Error % | F4: Estado | H4: Resumen
A5: ='Detalle Diario 2026'!A5 -> 46024 | B5: ='Detalle Diario 2026'!H5 -> 6 | C5: =IFERROR(VLOOKUP(A5,'datos reales bcra'!a:h,8,FALSE()),"") | D5: =IFERROR(B5-C5,"") | E5: =IFERROR(D5/C5,"") | F5: =IF(C5="","falta dato real",IF(ABS(E5)<0.05,"OK",IF(ABS(E5)<0.2,"revisar","discrepancia"))) -> falta dato real | H5: Error medio absoluto (USD mm) | I5: =IFERROR(AVERAGE(IF(C5:C85<>"",ABS(D5:D85))),"sin datos") -> 0
A6: ='Detalle Diario 2026'!A6 -> 46027 | B6: ='Detalle Diario 2026'!H6 -> 64 | C6: =IFERROR(VLOOKUP(A6,'datos reales bcra'!a:h,8,FALSE()),"") | D6: =IFERROR(B6-C6,"") | E6: =IFERROR(D6/C6,"") | F6: =IF(C6="","falta dato real",IF(ABS(E6)<0.05,"OK",IF(ABS(E6)<0.2,"revisar","discrepancia"))) -> falta dato real | H6: Días con dato real | I6: =COUNT(C5:C85) -> 0
A7: ='Detalle Diario 2026'!A7 -> 46028 | B7: ='Detalle Diario 2026'!H7 -> 66 | C7: =IFERROR(VLOOKUP(A7,'datos reales bcra'!a:h,8,FALSE()),"") | D7: =IFERROR(B7-C7,"") | E7: =IFERROR(D7/C7,"") | F7: =IF(C7="","falta dato real",IF(ABS(E7)<0.05,"OK",IF(ABS(E7)<0.2,"revisar","discrepancia"))) -> falta dato real | H7: Días sin dato real | I7: =COUNTBLANK(C5:C85) -> 81
A8: ='Detalle Diario 2026'!A8 -> 46029 | B8: ='Detalle Diario 2026'!H8 -> 95 | C8: =IFERROR(VLOOKUP(A8,'datos reales bcra'!a:h,8,FALSE()),"") | D8: =IFERROR(B8-C8,"") | E8: =IFERROR(D8/C8,"") | F8: =IF(C8="","falta dato real",IF(ABS(E8)<0.05,"OK",IF(ABS(E8)<0.2,"revisar","discrepancia"))) -> falta dato real
A9: ='Detalle Diario 2026'!A9 -> 46030 | B9: ='Detalle Diario 2026'!H9 -> 11 | C9: =IFERROR(VLOOKUP(A9,'datos reales bcra'!a:h,8,FALSE()),"") | D9: =IFERROR(B9-C9,"") | E9: =IFERROR(D9/C9,"") | F9: =IF(C9="","falta dato real",IF(ABS(E9)<0.05,"OK",IF(ABS(E9)<0.2,"revisar","discrepancia"))) -> falta dato real
A10: ='Detalle Diario 2026'!A10 -> 46031 | B10: ='Detalle Diario 2026'!H10 -> 18 | C10: =IFERROR(VLOOKUP(A10,'datos reales bcra'!a:h,8,FALSE()),"") | D10: =IFERROR(B10-C10,"") | E10: =IFERROR(D10/C10,"") | F10: =IF(C10="","falta dato real",IF(ABS(E10)<0.05,"OK",IF(ABS(E10)<0.2,"revisar","discrepancia"))) -> falta dato real
A11: ='Detalle Diario 2026'!A11 -> 46034 | B11: ='Detalle Diario 2026'!H11 -> 82 | C11: =IFERROR(VLOOKUP(A11,'datos reales bcra'!a:h,8,FALSE()),"") | D11: =IFERROR(B11-C11,"") | E11: =IFERROR(D11/C11,"") | F11: =IF(C11="","falta dato real",IF(ABS(E11)<0.05,"OK",IF(ABS(E11)<0.2,"revisar","discrepancia"))) -> falta dato real
A12: ='Detalle Diario 2026'!A12 -> 46035 | B12: ='Detalle Diario 2026'!H12 -> 61 | C12: =IFERROR(VLOOKUP(A12,'datos reales bcra'!a:h,8,FALSE()),"") | D12: =IFERROR(B12-C12,"") | E12: =IFERROR(D12/C12,"") | F12: =IF(C12="","falta dato real",IF(ABS(E12)<0.05,"OK",IF(ABS(E12)<0.2,"revisar","discrepancia"))) -> falta dato real
A13: ='Detalle Diario 2026'!A13 -> 46036 | B13: ='Detalle Diario 2026'!H13 -> 62 | C13: =IFERROR(VLOOKUP(A13,'datos reales bcra'!a:h,8,FALSE()),"") | D13: =IFERROR(B13-C13,"") | E13: =IFERROR(D13/C13,"") | F13: =IF(C13="","falta dato real",IF(ABS(E13)<0.05,"OK",IF(ABS(E13)<0.2,"revisar","discrepancia"))) -> falta dato real
A14: ='Detalle Diario 2026'!A14 -> 46037 | B14: ='Detalle Diario 2026'!H14 -> 74 | C14: =IFERROR(VLOOKUP(A14,'datos reales bcra'!a:h,8,FALSE()),"") | D14: =IFERROR(B14-C14,"") | E14: =IFERROR(D14/C14,"") | F14: =IF(C14="","falta dato real",IF(ABS(E14)<0.05,"OK",IF(ABS(E14)<0.2,"revisar","discrepancia"))) -> falta dato real
A15: ='Detalle Diario 2026'!A15 -> 46038 | B15: ='Detalle Diario 2026'!H15 -> 26 | C15: =IFERROR(VLOOKUP(A15,'datos reales bcra'!a:h,8,FALSE()),"") | D15: =IFERROR(B15-C15,"") | E15: =IFERROR(D15/C15,"") | F15: =IF(C15="","falta dato real",IF(ABS(E15)<0.05,"OK",IF(ABS(E15)<0.2,"revisar","discrepancia"))) -> falta dato real
A16: ='Detalle Diario 2026'!A16 -> 46041 | B16: ='Detalle Diario 2026'!H16 -> 111 | C16: =IFERROR(VLOOKUP(A16,'datos reales bcra'!a:h,8,FALSE()),"") | D16: =IFERROR(B16-C16,"") | E16: =IFERROR(D16/C16,"") | F16: =IF(C16="","falta dato real",IF(ABS(E16)<0.05,"OK",IF(ABS(E16)<0.2,"revisar","discrepancia"))) -> falta dato real
A17: ='Detalle Diario 2026'!A17 -> 46042 | B17: ='Detalle Diario 2026'!H17 -> 93 | C17: =IFERROR(VLOOKUP(A17,'datos reales bcra'!a:h,8,FALSE()),"") | D17: =IFERROR(B17-C17,"") | E17: =IFERROR(D17/C17,"") | F17: =IF(C17="","falta dato real",IF(ABS(E17)<0.05,"OK",IF(ABS(E17)<0.2,"revisar","discrepancia"))) -> falta dato real
A18: ='Detalle Diario 2026'!A18 -> 46043 | B18: ='Detalle Diario 2026'!H18 -> 74 | C18: =IFERROR(VLOOKUP(A18,'datos reales bcra'!a:h,8,FALSE()),"") | D18: =IFERROR(B18-C18,"") | E18: =IFERROR(D18/C18,"") | F18: =IF(C18="","falta dato real",IF(ABS(E18)<0.05,"OK",IF(ABS(E18)<0.2,"revisar","discrepancia"))) -> falta dato real
A19: ='Detalle Diario 2026'!A19 -> 46044 | B19: ='Detalle Diario 2026'!H19 -> 44 | C19: =IFERROR(VLOOKUP(A19,'datos reales bcra'!a:h,8,FALSE()),"") | D19: =IFERROR(B19-C19,"") | E19: =IFERROR(D19/C19,"") | F19: =IF(C19="","falta dato real",IF(ABS(E19)<0.05,"OK",IF(ABS(E19)<0.2,"revisar","discrepancia"))) -> falta dato real
... A85: ='Detalle Diario 2026'!A85 -> 46146 | B85: ='Detalle Diario 2026'!H85 -> 50 | C85: =IFERROR(VLOOKUP(A85,'datos reales bcra'!a:h,8,FALSE()),"") | D85: =IFERROR(B85-C85,"") | E85: =IFERROR(D85/C85,"") | F85: =IF(C85="","falta dato real",IF(ABS(E85)<0.05,"OK",IF(ABS(E85)<0.2,"revisar","discrepancia"))) -> falta dato real

Sheet Reservas Netas
A1: Descomposición de reservas brutas → reservas netas
A2: Reservas Netas = Brutas − Encajes USD bancos − Swap China − BOPREAL − Repos − Vencimientos FMI < 12m. Edita los componentes (azul) con tus números.
A4: Año | B4: Brutas | C4: Encajes USD | D4: Swap China | E4: BOPREAL/Repos | F4: FMI <12m | G4: Reservas Netas
A5: 2016 | B5: 38800 | C5: 7000 | D5: 0 | E5: 0 | F5: 4000 | G5: =B5-C5-D5-E5-F5 -> 27800
A6: 2017 | B6: 55055 | C6: 11000 | D6: 0 | E6: 0 | F6: 0 | G6: =B6-C6-D6-E6-F6 -> 44055
A7: 2018 | B7: 65806 | C7: 12000 | D7: 9000 | E7: 0 | F7: 8000 | G7: =B7-C7-D7-E7-F7 -> 36806
A8: 2019 | B8: 44848 | C8: 12000 | D8: 18000 | E8: 0 | F8: 4000 | G8: =B8-C8-D8-E8-F8 -> 10848
A9: 2020 | B9: 39400 | C9: 11000 | D9: 18500 | E9: 0 | F9: 5500 | G9: =B9-C9-D9-E9-F9 -> 4400
A10: 2021 | B10: 39662 | C10: 11000 | D10: 18500 | E10: 0 | F10: 6000 | G10: =B10-C10-D10-E10-F10 -> 4162
A11: 2022 | B11: 44538 | C11: 14000 | D11: 18500 | E11: 0 | F11: 5000 | G11: =B11-C11-D11-E11-F11 -> 7038
A12: 2023 | B12: 23073 | C12: 11000 | D12: 18500 | E12: 0 | F12: 8000 | G12: =B12-C12-D12-E12-F12 -> -14427
A13: 2024 | B13: 29600 | C13: 12500 | D13: 18500 | E13: 5000 | F13: 4500 | G13: =B13-C13-D13-E13-F13 -> -10900
A14: 2025 | B14: 41100 | C14: 13500 | D14: 18500 | E14: 8000 | F14: 6000 | G14: =B14-C14-D14-E14-F14 -> -4900
A15: 2026 | B15: ='Detalle Diario 2026'!B85 -> 46286 | C15: 13800 | D15: 18500 | E15: 9000 | F15: 5500 | G15: =B15-C15-D15-E15-F15 -> -514

Sheet Cobertura Monetaria
A1: Cobertura monetaria: Reservas / Base Monetaria
A2: Carga la base monetaria (USD equivalente) en columna C. Fuente: BCRA series.xlsm, hoja 'Base Monetaria'. Ratio > 1 = reservas exceden base; < 1 = peso sub-respaldado.
A4: Año | B4: Reservas Brutas | C4: Base Monetaria (USD eq) | D4: Cobertura (R/BM) | E4: Var YoY R/BM | F4: Estado
A5: 2016 | B5: 38800 | C5: 50000 | D5: =B5/C5 -> 0.776 | F5: =IF(D5>1.2,"sólido",IF(D5>0.8,"medio","débil")) -> débil
A6: 2017 | B6: 55055 | C6: 65000 | D6: =B6/C6 -> 0.847 | E6: =D6/D5-1 -> 0.091494845 | F6: =IF(D6>1.2,"sólido",IF(D6>0.8,"medio","débil")) -> medio
A7: 2018 | B7: 65806 | C7: 35000 | D7: =B7/C7 -> 1.8801714 | E7: =D7/D6-1 -> 1.219801 | F7: =IF(D7>1.2,"sólido",IF(D7>0.8,"medio","débil")) -> sólido
A8: 2019 | B8: 44848 | C8: 25000 | D8: =B8/C8 -> 1.79392 | E8: =D8/D7-1 -> -0.045874236 | F8: =IF(D8>1.2,"sólido",IF(D8>0.8,"medio","débil")) -> sólido
A9: 2020 | B9: 39400 | C9: 30000 | D9: =B9/C9 -> 1.3133333 | E9: =D9/D8-1 -> -0.26789749 | F9: =IF(D9>1.2,"sólido",IF(D9>0.8,"medio","débil")) -> sólido
A10: 2021 | B10: 39662 | C10: 33000 | D10: =B10/C10 -> 1.2018788 | E10: =D10/D9-1 -> -0.084863867 | F10: =IF(D10>1.2,"sólido",IF(D10>0.8,"medio","débil")) -> sólido
A11: 2022 | B11: 44538 | C11: 28000 | D11: =B11/C11 -> 1.5906429 | E11: =D11/D10-1 -> 0.32346362 | F11: =IF(D11>1.2,"sólido",IF(D11>0.8,"medio","débil")) -> sólido
A12: 2023 | B12: 23073 | C12: 14000 | D12: =B12/C12 -> 1.6480714 | E12: =D12/D11-1 -> 0.036104001 | F12: =IF(D12>1.2,"sólido",IF(D12>0.8,"medio","débil")) -> sólido
A13: 2024 | B13: 29600 | C13: 32000 | D13: =B13/C13 -> 0.925 | E13: =D13/D12-1 -> -0.43873792 | F13: =IF(D13>1.2,"sólido",IF(D13>0.8,"medio","débil")) -> medio
A14: 2025 | B14: 41100 | C14: 41000 | D14: =B14/C14 -> 1.002439 | E14: =D14/D13-1 -> 0.083717864 | F14: =IF(D14>1.2,"sólido",IF(D14>0.8,"medio","débil")) -> medio
A15: 2026 | B15: ='Detalle Diario 2026'!B85 -> 46286 | C15: 43000 | D15: =B15/C15 -> 1.0764186 | E15: =D15/D14-1 -> 0.073799581 | F15: =IF(D15>1.2,"sólido",IF(D15>0.8,"medio","débil")) -> medio

Sheet Brecha Cambiaria
A1: Brecha cambiaria: oficial vs MEP / CCL
A2: Cargá los promedios anuales (o cierre) de cada cotización. Brecha = (Paralelo/Oficial - 1).
A4: Año | B4: Oficial | C4: MEP | D4: CCL | E4: Brecha MEP | F4: Brecha CCL | G4: Compras BCRA
A5: 2016 | B5: 15.85 | C5: 15.85 | D5: 15.85 | E5: =C5/B5-1 -> 0 | F5: =D5/B5-1 -> 0 | G5: ='Resumen Anual'!E5 -> 3400
A6: 2017 | B6: 18.65 | C6: 18.65 | D6: 18.65 | E6: =C6/B6-1 -> 0 | F6: =D6/B6-1 -> 0 | G6: ='Resumen Anual'!E6 -> 5900
A7: 2018 | B7: 37.81 | C7: 37.81 | D7: 37.81 | E7: =C7/B7-1 -> 0 | F7: =D7/B7-1 -> 0 | G7: ='Resumen Anual'!E7 -> -2200
A8: 2019 | B8: 59.89 | C8: 75 | D8: 79 | E8: =C8/B8-1 -> 0.25229588 | F8: =D8/B8-1 -> 0.31908499 | G8: ='Resumen Anual'!E8 -> -15000
A9: 2020 | B9: 84.15 | C9: 142 | D9: 146 | E9: =C9/B9-1 -> 0.68746286 | F9: =D9/B9-1 -> 0.73499703 | G9: ='Resumen Anual'!E9 -> 200
A10: 2021 | B10: 102.72 | C10: 198 | D10: 213 | E10: =C10/B10-1 -> 0.92757009 | F10: =D10/B10-1 -> 1.0735981 | G10: ='Resumen Anual'!E10 -> 5000
A11: 2022 | B11: 177.15 | C11: 333 | D11: 349 | E11: =C11/B11-1 -> 0.87976291 | F11: =D11/B11-1 -> 0.97008185 | G11: ='Resumen Anual'!E11 -> 5800
A12: 2023 | B12: 808.45 | C12: 1000 | D12: 1000 | E12: =C12/B12-1 -> 0.23693488 | F12: =D12/B12-1 -> 0.23693488 | G12: ='Resumen Anual'!E12 -> -1900
A13: 2024 | B13: 1032.5 | C13: 1170 | D13: 1180 | E13: =C13/B13-1 -> 0.13317191 | F13: =D13/B13-1 -> 0.14285714 | G13: ='Resumen Anual'!E13 -> 19000
A14: 2025 | B14: 1200 | C14: 1280 | D14: 1300 | E14: =C14/B14-1 -> 0.066666667 | F14: =D14/B14-1 -> 0.083333333 | G14: ='Resumen Anual'!E14 -> 4500
A15: 2026 | B15: 1280 | C15: 1300 | D15: 1320 | E15: =C15/B15-1 -> 0.015625 | F15: =D15/B15-1 -> 0.03125 | G15: ='Resumen Anual'!E15 -> 6491

Sheet Stress Test
A1: Stress test 2026: ¿llega el BCRA a la meta anual?
A2: Modelo simple: ritmo actual proyectado al resto del año vs. metas oficiales.
A4: Parámetros | D4: Escenarios
A5: Compras YTD (USD mm) | B5: ='Detalle Diario 2026'!I85 -> 6491 | D5: Escenario | E5: Compras año proyectadas
A6: Días hábiles transcurridos | B6: =COUNTA('Detalle Diario 2026'!A5:A85) -> 81 | D6: Optimista (+30% ritmo) | E6: =B5+B13*B7*1.3 -> 23680.13
A7: Días hábiles restantes (estim.) | B7: 165 | D7: Base (ritmo actual) | E7: =B5+B13*B7*1 -> 19713.407
A8: Pagos al FMI restantes 2026 (USD mm) | B8: 3000 | D8: Conservador (-20% ritmo) | E8: =B5+B13*B7*0.8 -> 17068.926
A9: Meta base oficial (USD mm) | B9: 10000 | D9: Pesimista (-50% ritmo) | E9: =B5+B13*B7*0.5 -> 13102.204
A10: Meta techo oficial (USD mm) | B10: 17000
A12: Proyecciones
A13: Ritmo diario YTD (USD mm/rueda) | B13: =B5/B6 -> 80.135802
A14: Compras esperadas resto del año | B14: =B13*B7 -> 13222.407
A15: Compras totales año proyectado | B15: =B5+B14 -> 19713.407
A16: % sobre meta base | B16: =B15/B9 -> 1.9713407
A17: % sobre meta techo | B17: =B15/B10 -> 1.1596122
A18: Gap a meta base (USD mm) | B18: =B9-B15 -> -9713.4074
A19: Estado vs meta base | B19: =IF(B15>=B10,"Supera meta techo",IF(B15>=B9,"Cumple meta base",IF(B15>=B9*0.8,"Cerca meta base","Por debajo de meta"))) -> Supera meta techo

Sheet Cómo usar
A1: Guía del archivo
A3: 12 hojas, ordenadas de macro a micro
A4: 1. Resumen Anual — 11 años de stocks y compras netas en MULC.
A5: 2. YTD Comparativo — compras acumuladas mes a mes, año por año.
A6: 3. Heatmap Compras — grilla años × meses con colores. Ojo de un vistazo.
A7: 4. Rolling 12m — suma móvil de 12 meses, tendencia sin efecto fin de año.
A8: 5. Detalle Diario 2026 — 81 ruedas con la reconstrucción día a día.
A9: 6. Streaks — días consecutivos con compras + estadísticas del año.
A10: 7. Validación — compara mi reconstrucción contra el dato real del BCRA (cuando lo cargues).
A11: 8. Reservas Netas — descomposición: Brutas − Encajes − Swap China − BOPREAL − FMI <12m.
A12: 9. Cobertura Monetaria — ratio Reservas / Base Monetaria a lo largo del tiempo.
A13: 10. Brecha Cambiaria — oficial vs MEP/CCL, brecha % por año.
... A42: • Stress Test te dice en 1 segundo si el ritmo actual alcanza para llegar a la meta de USD 10.000M.
