Workbook

Sheet README
B2: CAS North + CIO LatAm | Central America, the Caribbean and Colombia
B3: INTERNAL DRAFT - NOT FOR DISTRIBUTION. Not investment research and not a recommendation. Company names appear as exposure examples and market context only. No buy, sell or hold view is expressed or implied, and no price targets are given. All figures carry the source and vintage shown; several are flagged as unverified or not found and must be confirmed before any client-facing use. Subject to compliance and supervisory review.
B7: What this is
B8: A response to Raphael Kirschstein's request of 3 September 2026, items (a) through (e). It is a working data pack, not a published CIO view. Everything here is sourced and dated so that an advisor can defend any number in front of a prospect, or discard it.
B11: How the request maps onto these tabs
B12: Request item | C12: Tab | D12: What you get
B13: (a) Economic standing | C13: Dashboard, Macro Data, Ratings | D13: GDP, FX, fiscal balance, debt, FDI, ratings and political stability for all seven
B14: (b) Government policies | C14: Tax Matrix, Incentives, Infrastructure | D14: Free zones, HQ regimes, PPPs and the named project pipeline with USD sizes and status
B15: (c) Main private industries | C15: Wealth Map | D15: What drives each economy, and the named local and family participants
B16: (d) El Salvador and Guyana | C16: Covered on every tab | D16: Treated as full members of the set, not an annex
B17: (e) Listed companies | C17: Equity Exposure | D17: Named exposure map. No valuation work, no recommendations - see the compliance note below
B18: Beyond the request | C18: Colombia Annex, Calendar, Risks | D18: Colombia is the priority target, and the calendar is what turns this into calls
B20: Colour convention
B21: Blue text | C21: A hardcoded figure taken from a named source. Every one is traceable on the Sources tab.
B22: Black text | C22: A formula. It recalculates if you change an input.
B23: Green text | C23: A link to another tab in this workbook.
B24: Red fill | C24: A figure or status that is unverified, stale, or a known trap. Do not put it in front of a client without checking.
B27: Three health warnings that will bite you if you do not know them
B28: Panama is absent from the IMF WEO database.
B29: Not a gap in this pack - Panama genuinely is not in the DataMapper dataset. Every Panama figure here comes from the World Bank Macro Poverty Outlook, Fitch or the IMF Article IV. Treat any Panama 'IMF WEO' number you meet elsewhere with suspicion.
B32: Fiscal and debt perimeters differ between the IMF and the World Bank.
B33: The IMF uses general government; the World Bank often uses central government or the non-financial public sector. The gap is ~12pp for Costa Rica. Both are shown on the Macro Data tab. Never mix them in one chart.
B36: Rating aggregators carry wrong data for this region.
B37: FXEmpire still shows a stale Moody's Ba3/Positive for the Dominican Republic; countryeconomy shows a stale Fitch 'RD' for El Salvador. The Ratings tab is built from agency releases wherever we could reach them. Verify before anything client-facing.
B40: Two Fitch lines in this workbook are UNRESOLVED.
B41: Our primary source has Fitch at BB- on Costa Rica (last action March 2023) and BB on Guatemala (February 2023). A second source has Fitch already at BB and BB+ respectively, acting in late 2025. We could not reach fitchratings.com to settle it. This matters: the whole 'Fitch is stale, a catch-up upgrade is coming' argument depends on which version is correct. Confirm against Fitch's own releases before either version is said to a client.
B44: Compliance
B45: Marked INTERNAL DRAFT throughout at Alberto Rojas's instruction. Company names on the Equity Exposure tab are there because a client asked where the money is, not as recommendations. There are no price targets, no multiples and no buy/sell language anywhere in this file. Route through compliance and supervisory review before any part of it goes outside the team.
B49: Prepared 4 September 2026.

Sheet Dashboard
B2: Cross-country dashboard
B3: Every cell on this tab is a formula pulling from 'Macro Data'. Change an input there and this updates.
B5: The one-screen comparison
B6: Market | C6: GDP 2025 (USD bn) | D6: GDP per cap. (USD) | E6: Growth 2026f (%) | F6: Policy rate (%) | G6: Real policy rate (pp) | H6: Fiscal bal. 2025 (%GDP) | I6: Public debt 2025 (%GDP) | J6: C/A 2025 (%GDP) | K6: FDI (%GDP) | L6: Remittances (%GDP) | M6: Composite rating
B7: Panama | C7: ='Macro Data'!C7 -> NF | D7: ='Macro Data'!C9 -> 19630 | E7: ='Macro Data'!C14 -> 3.9 | F7: =IF(ISNUMBER('Macro Data'!C49),'Macro Data'!C49,"n/a") -> n/a | G7: ='Macro Data'!C19 -> n/a | H7: ='Macro Data'!C23 -> -3.7 | I7: ='Macro Data'!C25 -> 65.6 | J7: ='Macro Data'!C28 -> 0.8 | K7: ='Macro Data'!C32 -> 2.4 | L7: ='Macro Data'!C34 -> NF | M7: =IFERROR(INDEX(Ratings!$I$6:$I$12,MATCH($B7,Ratings!$B$6:$B$12,0)),"n/a") -> 11.666667
B8: Costa Rica | C8: ='Macro Data'!D7 -> 102.9 | D8: ='Macro Data'!D9 -> 19162 | E8: ='Macro Data'!D14 -> 3.6 | F8: =IF(ISNUMBER('Macro Data'!D49),'Macro Data'!D49,"n/a") -> 3 | G8: ='Macro Data'!D19 -> 3.28 | H8: ='Macro Data'!D23 -> -3.4 | I8: ='Macro Data'!D25 -> 60.4 | J8: ='Macro Data'!D28 -> -0.7 | K8: ='Macro Data'!D32 -> 5 | L8: ='Macro Data'!D34 -> NF | M8: =IFERROR(INDEX(Ratings!$I$6:$I$12,MATCH($B8,Ratings!$B$6:$B$12,0)),"n/a") -> 9.6666667
B9: Guatemala | C9: ='Macro Data'!E7 -> 121.1 | D9: ='Macro Data'!E9 -> 6489 | E9: ='Macro Data'!E14 -> 3.7 | F9: =IF(ISNUMBER('Macro Data'!E49),'Macro Data'!E49,"n/a") -> 3.5 | G9: ='Macro Data'!E19 -> 0.64 | H9: ='Macro Data'!E23 -> -1.9 | I9: ='Macro Data'!E25 -> 26.7 | J9: ='Macro Data'!E28 -> 4.7 | K9: ='Macro Data'!E32 -> 1.6 | L9: ='Macro Data'!E34 -> 20.7 | M9: =IFERROR(INDEX(Ratings!$I$6:$I$12,MATCH($B9,Ratings!$B$6:$B$12,0)),"n/a") -> 10.666667
B10: Colombia | C10: ='Macro Data'!F7 -> 457.4 | D10: ='Macro Data'!F9 -> 8623 | E10: ='Macro Data'!F14 -> 2.5 | F10: =IF(ISNUMBER('Macro Data'!F49),'Macro Data'!F49,"n/a") -> 12 | G10: ='Macro Data'!F19 -> 5.97 | H10: ='Macro Data'!F23 -> -6.4 | I10: ='Macro Data'!F25 -> 64.7 | J10: ='Macro Data'!F28 -> -2.4 | K10: ='Macro Data'!F32 -> 3.3 | L10: ='Macro Data'!F34 -> 2.87 | M10: =IFERROR(INDEX(Ratings!$I$6:$I$12,MATCH($B10,Ratings!$B$6:$B$12,0)),"n/a") -> 10.333333
B11: Dominican Rep. | C11: ='Macro Data'!G7 -> 127.9 | D11: ='Macro Data'!G9 -> 11749 | E11: ='Macro Data'!G14 -> 3.6 | F11: =IF(ISNUMBER('Macro Data'!G49),'Macro Data'!G49,"n/a") -> 5.25 | G11: ='Macro Data'!G19 -> -0.22 | H11: ='Macro Data'!G23 -> -3.6 | I11: ='Macro Data'!G25 -> 57.9 | J11: ='Macro Data'!G28 -> -1.2 | K11: ='Macro Data'!G32 -> 3.9 | L11: ='Macro Data'!G34 -> 9.3 | M11: =IFERROR(INDEX(Ratings!$I$6:$I$12,MATCH($B11,Ratings!$B$6:$B$12,0)),"n/a") -> 9.6666667
B12: El Salvador | C12: ='Macro Data'!H7 -> 37.3 | D12: ='Macro Data'!H9 -> 5839 | E12: ='Macro Data'!H14 -> 4.5 | F12: =IF(ISNUMBER('Macro Data'!H49),'Macro Data'!H49,"n/a") -> n/a | G12: ='Macro Data'!H19 -> n/a | H12: ='Macro Data'!H23 -> -2.8 | I12: ='Macro Data'!H25 -> 87.2 | J12: ='Macro Data'!H28 -> -1.2 | K12: ='Macro Data'!H32 -> 3 | L12: ='Macro Data'!H34 -> 24 | M12: =IFERROR(INDEX(Ratings!$I$6:$I$12,MATCH($B12,Ratings!$B$6:$B$12,0)),"n/a") -> 6
B13: Guyana | C13: ='Macro Data'!I7 -> 27.1 | D13: ='Macro Data'!I9 -> 26994 | E13: ='Macro Data'!I14 -> 16.2 | F13: =IF(ISNUMBER('Macro Data'!I49),'Macro Data'!I49,"n/a") -> n/a | G13: ='Macro Data'!I19 -> n/a | H13: ='Macro Data'!I23 -> -5.4 | I13: ='Macro Data'!I25 -> 28.6 | J13: ='Macro Data'!I28 -> 12.9 | K13: ='Macro Data'!I32 -> 35 | L13: ='Macro Data'!I34 -> NF | M13: =IFERROR(INDEX(Ratings!$I$6:$I$12,MATCH($B13,Ratings!$B$6:$B$12,0)),"n/a") -> n/a
B15: Composite rating is the average of the three agencies on a 21-point scale where 21 = AAA and 12 = the lowest investment-grade notch (Baa3 / BBB-). Guyana is unrated by all three and returns n/a - that is a fact about the sovereign, not a missing number.
B19: Debt and growth
B37: External resilience
B55: What the dashboard says, in one line each
B56: Market | C56: Read
B57: Guatemala | C57: The best fundamentals-to-rating gap in the sample. Debt of 27% of GDP, a structural current-account surplus, reserves worth ~27% of GDP, and one notch from investment grade at two agencies. The binding constraint is a 12.6%-of-GDP tax take and 1.6%-of-GDP FDI, not solvency.
B58: Costa Rica | C58: The best rating momentum - upgrades from Moody's and S&P inside a single month in late 2025. But 39 consecutive months of deflation and a currency up 10% in a year are squeezing the export and tourism base.
B59: Dominican Rep. | C59: Boring in a good way. Debt down from 69% to 58.5% of GDP since 2020, record FDI, a real tourism and nearshoring franchise. A 15.6% tax take is the ceiling on further upgrades.
B60: Panama | C60: The knife-edge. Investment grade at two agencies, already sub-IG at Fitch, negative outlook at Moody's, a mine that has not reopened and a canal back on water restrictions. A fallen-angel-in-progress candidate.
B61: Colombia | C61: The highest-beta name here. A real policy rate near six points and the world's best-performing currency on one side; two downgrades in twelve months, a suspended fiscal rule, a 9.4%-of-GDP 2027 deficit and a president without a congressional majority on the other.
B62: El Salvador | C62: Best momentum, worst level. Caa3 to B3/positive in two years and a genuine 2.9%-of-GDP primary surplus, against 87% debt, USD 5,839 per capita and a quarter of GDP arriving as remittances.
B63: Guyana | C63: The highest-return, highest-tail-risk name. Per-capita income has already passed Costa Rica and Panama. It is also unrated, holds barely USD 1bn of central-bank reserves, and shares a border with a state that has pre-announced it will defy the World Court.

Sheet Macro Data
B2: Macro fundamentals - seven markets
B3: All figures hardcoded from the named source. Vintage per country in the last row. NF = not found / not published.
B5: Indicator | C5: Panama | D5: Costa Rica | E5: Guatemala | F5: Colombia | G5: Dominican Rep. | H5: El Salvador | I5: Guyana
B6: SIZE AND GROWTH
B7: Nominal GDP 2025 (USD bn) | C7: NF | D7: 102.9 | E7: 121.1 | F7: 457.4 | G7: 127.9 | H7: 37.3 | I7: 27.1
B8: Nominal GDP 2024 (USD bn) | C8: 86.5 | D8: 96.7 | E8: 113.2 | F8: 420.5 | G8: 124.3 | H8: 34.9 | I8: 24.7
B9: GDP per capita 2025 (USD) | C9: 19630 | D9: 19162 | E9: 6489 | F9: 8623 | G9: 11749 | H9: 5839 | I9: 26994
B10: Population 2025 (mn) | C10: 4.48 | D10: 5.37 | E10: 18.66 | F10: 53.05 | G10: 10.89 | H10: 6.38 | I10: 1
B11: Real GDP growth 2023 (%) | C11: 7.4 | D11: 4.8 | E11: 3.5 | F11: 0.8 | G11: 2.2 | H11: 3.5 | I11: 33.8
B12: Real GDP growth 2024 (%) | C12: 2.9 | D12: 4.1 | E12: 3.7 | F12: 1.6 | G12: 5 | H12: 2.6 | I12: 43.8
B13: Real GDP growth 2025e (%) | C13: 4.4 | D13: 4.6 | E13: 4.2 | F13: 2.6 | G13: 2.1 | H13: 3.9 | I13: 19.3
B14: Real GDP growth 2026f (%) | C14: 3.9 | D14: 3.6 | E14: 3.7 | F14: 2.5 | G14: 3.6 | H14: 4.5 | I14: 16.2
B15: Real GDP growth 2027f (%) | C15: 4.1 | D15: 3.7 | E15: 3.8 | F15: 2.6 | G15: 4.4 | H15: 3 | I15: 19.7
B16: PRICES AND POLICY
B17: CPI, latest print | C17: NF (2025e 0.9%) | D17: -0.28% (Jul-26) | E17: 2.86% (May-26) | F17: 6.03% (Jul-26) | G17: 5.47% (Jul-26) | H17: 0.3% (2025e) | I17: 3.9% (Jul-26)
B18: Policy rate | C18: Dollarised - no policy rate | D18: 3.00% | E18: 3.50% | F18: 12.00% | G18: 5.25% | H18: Dollarised - no policy rate | I18: No active policy rate
B19: Real policy rate (pp) | C19: =IF(ISNUMBER(C49),C49-C50,"n/a") -> n/a | D19: =IF(ISNUMBER(D49),D49-D50,"n/a") -> 3.28 | E19: =IF(ISNUMBER(E49),E49-E50,"n/a") -> 0.64 | F19: =IF(ISNUMBER(F49),F49-F50,"n/a") -> 5.97 | G19: =IF(ISNUMBER(G49),G49-G50,"n/a") -> -0.22 | H19: =IF(ISNUMBER(H49),H49-H50,"n/a") -> n/a | I19: =IF(ISNUMBER(I49),I49-I50,"n/a") -> n/a
B20: FX regime and level | C20: Dollarised (USD legal tender since 1904) | D20: Managed float (CRC 453.7) | E20: Managed float (GTQ 7.63) | F20: Free float (COP 3,141) | G20: Managed float (DOP 59.7) | H20: Dollarised (USD legal tender since 2001) | I20: De facto peg (GYD ~208.5)
B21: FX appreciation vs USD, 2026 (%) | C21: 0 | D21: 10.25 | E21: 0.5 | F21: 19.6 | G21: 4.7 | H21: 0 | I21: 0
B22: FISCAL AND DEBT
B23: Fiscal balance 2025 (% GDP) | C23: -3.7 | D23: -3.4 | E23: -1.9 | F23: -6.4 | G23: -3.6 | H23: -2.8 | I23: -5.4
B24: Fiscal balance 2026f (% GDP) | C24: -3.5 | D24: -3.6 | E24: -2.7 | F24: -7.4 | G24: -3.8 | H24: -2 | I24: -6.4
B25: Gross public debt 2025 (% GDP) | C25: 65.6 | D25: 60.4 | E25: 26.7 | F25: 64.7 | G25: 57.9 | H25: 87.2 | I25: 28.6
B26: Gross public debt 2026f (% GDP) | C26: 65.3 | D26: 61.1 | E26: 27.4 | F26: 66.5 | G26: 58.1 | H26: 84.5 | I26: 29.2
B27: EXTERNAL
B28: Current account 2025 (% GDP) | C28: 0.8 | D28: -0.7 | E28: 4.7 | F28: -2.4 | G28: -1.2 | H28: -1.2 | I28: 12.9
B29: FX reserves, latest (USD bn) | C29: NF | D29: 20.8 | E29: 32.8 | F29: 67 | G29: 15.3 | H29: 5.1 | I29: 1.06
B30: Reserves as % of GDP | C30: =IF(AND(ISNUMBER(C29),ISNUMBER(C7)),C29/C7*100,"n/a") -> n/a | D30: =IF(AND(ISNUMBER(D29),ISNUMBER(D7)),D29/D7*100,"n/a") -> 20.2138 | E30: =IF(AND(ISNUMBER(E29),ISNUMBER(E7)),E29/E7*100,"n/a") -> 27.085054 | F30: =IF(AND(ISNUMBER(F29),ISNUMBER(F7)),F29/F7*100,"n/a") -> 14.64801 | G30: =IF(AND(ISNUMBER(G29),ISNUMBER(G7)),G29/G7*100,"n/a") -> 11.962471 | H30: =IF(AND(ISNUMBER(H29),ISNUMBER(H7)),H29/H7*100,"n/a") -> 13.672922 | I30: =IF(AND(ISNUMBER(I29),ISNUMBER(I7)),I29/I7*100,"n/a") -> 3.9114391
B31: FDI 2024 (USD bn) | C31: 2.086 | D31: 5.114 | E31: 1.848 | F31: 13.684 | G31: 4.476 | H31: 1.051 | I31: 8.63
B32: FDI as % of GDP | C32: 2.4 | D32: 5 | E32: 1.6 | F32: 3.3 | G32: 3.9 | H32: 3 | I32: 35
B33: Remittances 2025 (USD bn) | C33: NF | D33: NF | E33: 25.53 | F33: 13.098 | G33: 11.866 | H33: 9.988 | I33: NF
B34: Remittances as % of GDP | C34: NF | D34: NF | E34: 20.7 | F34: 2.87 | G34: 9.3 | H34: 24 | I34: NF
B35: RATINGS AND POLITICS
B36: Moody's | C36: Baa3 | D36: Ba2 | E36: Ba1 | F36: Baa3 | G36: Ba2 | H36: B3 | I36: Unrated
B37: Moody's outlook | C37: Negative | D37: Stable | E37: Stable | F37: Stable | G37: Stable | H37: Positive | I37: -
B38: S&P | C38: BBB- | D38: BB | E38: BB+ | F38: BB- | G38: BB | H38: B- | I38: Unrated
B39: S&P outlook | C39: Stable | D39: Stable | E39: Stable | F39: Stable | G39: Stable | H39: Stable | I39: -
B40: Fitch | C40: BB+ | D40: BB- | E40: BB | F40: BB | G40: BB- | H40: B- | I40: Unrated
B41: Fitch outlook | C41: Stable | D41: Stable | E41: Stable | F41: Stable | G41: Stable | H41: Stable | I41: -
B42: Head of government | C42: José Raúl Mulino (Realizando Metas) | D42: Laura Fernández (Pueblo Soberano) | E42: Bernardo Arévalo (Semilla) | F42: Abelardo de la Espriella (Defensores de la Patria) | G42: Luis Abinader (PRM), 2nd term | H42: Nayib Bukele (Nuevas Ideas) | I42: Irfaan Ali (PPP/C), 2nd term
...

Sheet Ratings
B2: Sovereign ratings, composite scale and 2024-26 actions
B3: Built from agency releases, not aggregators. 21-point scale: 21 = AAA, 12 = the lowest investment-grade notch.
B5: Market | C5: Moody's | D5: S&P | E5: Fitch | F5: Moody's num. | G5: S&P num. | H5: Fitch num. | I5: Composite | J5: Notches to inv. grade | K5: Outlook flags | N5: Rating | O5: Score
B6: Panama | C6: Baa3 | D6: BBB- | E6: BB+ | F6: =IFERROR(INDEX($O$6:$O$46,MATCH(C6,$N$6:$N$46,0)),"") -> 12 | G6: =IFERROR(INDEX($O$6:$O$46,MATCH(D6,$N$6:$N$46,0)),"") -> 12 | H6: =IFERROR(INDEX($O$6:$O$46,MATCH(E6,$N$6:$N$46,0)),"") -> 11 | I6: =IF(COUNT(F6:H6)=0,"n/a",AVERAGE(F6:H6)) -> 11.666667 | J6: =IF(COUNT(F6:H6)=0,"n/a",12-I6) -> 0.33333333 | K6: Moody's: Negative | N6: AAA | O6: 21
B7: Costa Rica | C7: Ba2 | D7: BB | E7: BB- | F7: =IFERROR(INDEX($O$6:$O$46,MATCH(C7,$N$6:$N$46,0)),"") -> 10 | G7: =IFERROR(INDEX($O$6:$O$46,MATCH(D7,$N$6:$N$46,0)),"") -> 10 | H7: =IFERROR(INDEX($O$6:$O$46,MATCH(E7,$N$6:$N$46,0)),"") -> 9 | I7: =IF(COUNT(F7:H7)=0,"n/a",AVERAGE(F7:H7)) -> 9.6666667 | J7: =IF(COUNT(F7:H7)=0,"n/a",12-I7) -> 2.3333333 | K7: All stable | N7: Aaa | O7: 21
B8: Guatemala | C8: Ba1 | D8: BB+ | E8: BB | F8: =IFERROR(INDEX($O$6:$O$46,MATCH(C8,$N$6:$N$46,0)),"") -> 11 | G8: =IFERROR(INDEX($O$6:$O$46,MATCH(D8,$N$6:$N$46,0)),"") -> 11 | H8: =IFERROR(INDEX($O$6:$O$46,MATCH(E8,$N$6:$N$46,0)),"") -> 10 | I8: =IF(COUNT(F8:H8)=0,"n/a",AVERAGE(F8:H8)) -> 10.666667 | J8: =IF(COUNT(F8:H8)=0,"n/a",12-I8) -> 1.3333333 | K8: All stable | N8: AA+ | O8: 20
B9: Colombia | C9: Baa3 | D9: BB- | E9: BB | F9: =IFERROR(INDEX($O$6:$O$46,MATCH(C9,$N$6:$N$46,0)),"") -> 12 | G9: =IFERROR(INDEX($O$6:$O$46,MATCH(D9,$N$6:$N$46,0)),"") -> 9 | H9: =IFERROR(INDEX($O$6:$O$46,MATCH(E9,$N$6:$N$46,0)),"") -> 10 | I9: =IF(COUNT(F9:H9)=0,"n/a",AVERAGE(F9:H9)) -> 10.333333 | J9: =IF(COUNT(F9:H9)=0,"n/a",12-I9) -> 1.6666667 | K9: All stable | N9: Aa1 | O9: 20
B10: Dominican Rep. | C10: Ba2 | D10: BB | E10: BB- | F10: =IFERROR(INDEX($O$6:$O$46,MATCH(C10,$N$6:$N$46,0)),"") -> 10 | G10: =IFERROR(INDEX($O$6:$O$46,MATCH(D10,$N$6:$N$46,0)),"") -> 10 | H10: =IFERROR(INDEX($O$6:$O$46,MATCH(E10,$N$6:$N$46,0)),"") -> 9 | I10: =IF(COUNT(F10:H10)=0,"n/a",AVERAGE(F10:H10)) -> 9.6666667 | J10: =IF(COUNT(F10:H10)=0,"n/a",12-I10) -> 2.3333333 | K10: All stable | N10: AA | O10: 19
B11: El Salvador | C11: B3 | D11: B- | E11: B- | F11: =IFERROR(INDEX($O$6:$O$46,MATCH(C11,$N$6:$N$46,0)),"") -> 6 | G11: =IFERROR(INDEX($O$6:$O$46,MATCH(D11,$N$6:$N$46,0)),"") -> 6 | H11: =IFERROR(INDEX($O$6:$O$46,MATCH(E11,$N$6:$N$46,0)),"") -> 6 | I11: =IF(COUNT(F11:H11)=0,"n/a",AVERAGE(F11:H11)) -> 6 | J11: =IF(COUNT(F11:H11)=0,"n/a",12-I11) -> 6 | K11: Moody's: Positive | N11: Aa2 | O11: 19
B12: Guyana | C12: Unrated | D12: Unrated | E12: Unrated | F12: =IFERROR(INDEX($O$6:$O$46,MATCH(C12,$N$6:$N$46,0)),"") | G12: =IFERROR(INDEX($O$6:$O$46,MATCH(D12,$N$6:$N$46,0)),"") | H12: =IFERROR(INDEX($O$6:$O$46,MATCH(E12,$N$6:$N$46,0)),"") | I12: =IF(COUNT(F12:H12)=0,"n/a",AVERAGE(F12:H12)) -> n/a | J12: =IF(COUNT(F12:H12)=0,"n/a",12-I12) -> n/a | K12: All stable | N12: AA- | O12: 18
N13: Aa3 | O13: 18
B14: A positive 'notches to investment grade' figure is the distance still to travel; a negative figure means the composite already sits above the threshold. Colombia and Panama both average below the line despite each holding one investment-grade rating - that is the split-rating problem, and it is the number that decides index eligibility for IG-mandated portfolios. | N14: A+ | O14: 17
N15: A1 | O15: 17
N16: A | O16: 16
N17: A2 | O17: 16
B18: Rating actions, 2024 - September 2026 | N18: A- | O18: 15
B19: Date | C19: Market | D19: Agency | E19: Action | F19: From | G19: To | H19: Outlook | N19: A3 | O19: 15
B20: 27 Jun 2024 | C20: Colombia | D20: Moody's | E20: Outlook change | F20: Baa2 stable | G20: Baa2 | H20: Negative | N20: BBB+ | O20: 14
B21: 11 Jul 2024 | C21: Guatemala | D21: Moody's | E21: Affirmed | F21: Ba1 | G21: Ba1 | H21: Stable | N21: Baa1 | O21: 14
B22: 26 Nov 2024 | C22: Panama | D22: S&P | E22: Affirmed | F22: BBB- | G22: BBB- | H22: Stable | N22: BBB | O22: 13
B23: 29 Nov 2024 | C23: Panama | D23: Moody's | E23: Outlook change | F23: Baa3 | G23: Baa3 | H23: Negative | N23: Baa2 | O23: 13
B24: Nov 2024 | C24: El Salvador | D24: Moody's | E24: UPGRADE | F24: Caa3 | G24: B3 | H24: Stable | N24: BBB- | O24: 12
B25: 7 Jan 2025 | C25: El Salvador | D25: Fitch | E25: UPGRADE | F25: CCC+ | G25: B- | H25: Stable | N25: Baa3 | O25: 12
B26: 6 Mar 2025 | C26: Colombia | D26: Fitch | E26: Outlook change | F26: BB+ stable | G26: BB+ | H26: Negative | N26: BB+ | O26: 11
B27: 23 May 2025 | C27: Guatemala | D27: S&P | E27: UPGRADE | F27: BB | G27: BB+ | H27: Stable | N27: Ba1 | O27: 11
B28: 26 Jun 2025 | C28: Colombia | D28: Moody's | E28: DOWNGRADE | F28: Baa2 | G28: Baa3 | H28: Stable | N28: BB | O28: 10
B29: 26 Jun 2025 | C29: Colombia | D29: S&P | E29: DOWNGRADE | F29: BB+ | G29: BB | H29: Negative | N29: Ba2 | O29: 10
B30: 1 Aug 2025 | C30: Dominican Rep. | D30: Moody's | E30: UPGRADE | F30: Ba3 | G30: Ba2 | H30: Stable | N30: BB- | O30: 9
... B39: May 2026 | C39: Panama | D39: Moody's | E39: Periodic review | F39: Baa3 negative | G39: Baa3 | H39: Negative | N39: Caa1 | O39: 5
N40: CCC | O40: 4
N41: Caa2 | O41: 4
B42: Stale ratings - where a catch-up action is plausible | N42: CCC- | O42: 3
B43: Market | C43: Agency | D43: Rating | E43: Last action | F43: Why it matters | N43: Caa3 | O43: 3
B44: Costa Rica | C44: Fitch | D44: BB- (VERIFY) | E44: 2 Mar 2023 per our source | F44: CONFLICT: a second source puts Fitch at BB with a December 2025 action. If Fitch has already upgraded, the catch-up thesis falls away. Confirm against the Fitch release before any client use. | N44: CC | O44: 2
B45: Guatemala | C45: Fitch | D45: BB (VERIFY) | E45: 16 Feb 2023 per our source | F45: CONFLICT: a second source puts Fitch at BB+ with an October 2025 action. Same warning as Costa Rica. | N45: Ca | O45: 2
B46: Dominican Rep. | C46: S&P | D46: BB | E46: 19 Dec 2022 | F46: Moody's upgraded to Ba2 in Aug-2025; S&P silent since 2022. A catch-up action is plausible. | N46: C | O46: 1
B47: El Salvador | C47: S&P | D47: B- | E47: 7 Nov 2023 | F47: Moody's on positive outlook, Fitch upgraded Jan-2025. A catch-up action is plausible.

Sheet Tax Matrix
B2: Headline tax and the structural question
B3: PwC Worldwide Tax Summaries, reviewed Feb-Aug 2026, plus national gazettes. Rates are headline - confirm per client.
B5: Market | C5: Corporate income tax | D5: Dividend WHT (non-resident) | E5: Capital gains | F5: VAT | G5: PIT top rate | H5: Wealth tax | I5: Basis | J5: The thing that actually matters
B6: Panama | C6: 25% (territorial); CAIR AMT 4.67% of gross >USD1.5m | D6: 5 / 10 / 20% | E6: 10% securities (5% withheld); 10% real estate | F6: 7% ITBMS | G6: 25% | H6: None | I6: Territorial | J6: Law 526/2026 economic substance - passive foreign income taxed 15% from FY2027 unless substance met
B7: Costa Rica | C7: 30% (reduced bands for small cos) | D7: 5% or 15% | E7: 15% (2.25% of price elective, pre-Jul-2019 assets) | F7: 13% | G7: 25% | H7: None | I7: Territorial, plus 15% on non-qualified foreign passive income (2023 reform) | J7: Same substance logic as Panama - applies to the same client structures
B8: Guatemala | C8: 25% profit regime / 5-7% gross regime | D8: 5% | E8: n/a separate | F8: 12% | G8: 7% | H8: None | I8: Territorial | J8: Lowest PIT top rate in the sample at 7%
B9: Colombia | C9: 35% + sector surcharges (banks +5% to 2027; oil 5-15%) | D9: 20% (48% from untaxed profits) | E9: 15% | F9: 19% | G9: 39% | H9: 0.5-1.5% above 72,000 UVT (~COP 3.77bn / ~USD 1.2m) | I9: Worldwide income | J9: Wealth tax 1.5% top band scheduled to lapse after FY2026. GMF 0.4%. New govt promises abolition - no bill filed.
B10: Dominican Rep. | C10: 27%; 30% transitional for income >=RD$1bn, FY2026-28 (Ley 30-26) | D10: 10% final | E10: 27% corporate; 10% real estate from 2026 | F10: 18% ITBIS | G10: 25% (27% top band from 2027) | H10: None | I10: Territorial (foreign investment income taxed from year 3 of residence) | J10: Ley 30-26 (Jun-2026): real-estate CGT cut 25%->10%; mortgage tax phased out by 2028; free-zone & CONFOTUR untouched
B11: El Salvador | C11: 30% (25% if <=USD150k) | D11: 5% statutory | E11: 10% | F11: 13% | G11: 30% | H11: None | I11: Territorial | J11: Ley de Fomento a la Innovacion: 15-yr full exemption incl. capital gains - benefits extend to partners/shareholders
B12: Guyana | C12: 40% commercial / 25% non-commercial / 45% telecom | D12: 20% | E12: 20% | F12: 14% | G12: 35% | H12: None | I12: Territorial | J12: Cleanest capital account of the seven; highest headline CIT
B14: The two structural facts to lead with
B15: PANAMA - Law 526 of 2026 and Executive Decree 32
B16: Published 28 May 2026, effective FY2027, first declarations 2028. Applies to a Panamanian entity that is (i) domiciled in Panama, (ii) part of a multinational group and (iii) earning foreign-source PASSIVE income - dividends, interest, royalties, capital gains, rent. Qualifying entities keep territorial (zero) treatment. NON-QUALIFYING ENTITIES PAY A FLAT 15% ON NET FOREIGN-SOURCE PASSIVE INCOME, FINAL. Executive Decree 32, reported 3 September 2026, sets the minimum bar: at least one qualified employee, physical or leased premises in Panama, operating expenses proportionate to the activity, and at least two in-person board meetings a year in Panama. It covers corporations, LLCs, partnerships, TRUSTS AND FOUNDATIONS. Holding companies and non-habitual real-estate entities get a simplified regime, forfeited if they take on substantive commercial or investment activity. Banks, insurers, securities firms, investment managers and maritime operators are carved out where licensed. The stated objective is to exit the EU non-cooperative list, on which Panama currently sits in Annex I. PRACTICAL EFFECT: every Panamanian holding or foundation in the book that receives foreign passive income must be triaged before FY2027. The default outcome for a passive shell is 15% where there was previously zero.
B23: COLOMBIA - the wealth tax nobody can currently plan around
B24: Operative law is Ley 2277 de 2022: 0.5% to 1.5% on net wealth above 72,000 UVT (~COP 3.77bn, roughly USD 1.2m at 3,140), and the 1.5% top band is scheduled to lapse after the 2026 year of assessment absent new legislation. Layered on top: Decreto 1474 de 2026, issued under a declared economic emergency in January 2026, would cut the threshold to 40,000 UVT and raise the top rate to 5% - and it is under Constitutional Court review. Layered on top of that: the new government pledged outright abolition in the inaugural address of 7 August 2026 and has filed no bill. Meanwhile the revenue argument writes itself: the wealth and riqueza taxes have raised ~COP 49tn cumulatively since 2006, and H1-2026 collections were COP 776bn against a COP 1.37tn full-year target - under 0.1% of GDP. COLOMBIAN WEALTH-TAX PLANNING CANNOT BE CLOSED OUT UNTIL THE COURT RULES. That uncertainty is itself the client conversation.
B31: Colombia - current wealth-tax brackets (Ley 2277 de 2022, FY2026, 1 UVT = COP 52,347)
B32: Taxable base (UVT) | C32: COP equivalent | D32: Marginal rate
B33: 0 - 72,000 UVT | C33: up to COP 3,770,928,000 | D33: 0%
B34: 72,000 - 122,000 UVT | C34: to ~COP 6.39bn | D34: 0.5%
B35: 122,000 - 239,000 UVT | C35: to ~COP 12.51bn | D35: 1.0%
B36: Above 239,000 UVT | C36: above ~COP 12.51bn | D36: 1.5% (scheduled to lapse after FY2026)
B38: Transparency and list status
B39: None of the seven is on the FATF increased-monitoring (grey) list as of the 19 June 2026 plenary. PANAMA IS ON THE EU LIST OF NON-COOPERATIVE JURISDICTIONS FOR TAX PURPOSES (Annex I), per the Council update of 17 February 2026 - Law 526 of 2026 is the exit attempt. All seven participate in FATCA; Colombia additionally participates in CRS and the MLI, and its CFC regime bites at 10% ownership with investment vehicles automatically classified as controlled foreign entities.

Sheet Incentives
B2: Investment incentives and residency-by-investment
B3: Item (b) of the request. Named regimes, thresholds and statutory bases.
B5: Incentive regimes
B6: Market | C6: Regime | D6: What it gives | E6: Threshold / scale
B7: Panama | C7: SEM - Multinational HQ (Law 41/2007) | D7: 5% CIT on qualifying income; services abroad exempt from CIT and ITBMS; 2.5% remittance tax; 5-yr renewable visas; PR after 5 yrs | E7: Parent group capital >= USD 200m
B8: Panama | C8: EMMA - Manufacturing services (Law 159/2020) | D8: Parallel tax/labour/immigration package | E8: -
B9: Panama | C9: Panama Pacifico SEZ (Law 41/2004) | D9: 1,400 ha; 345+ companies incl. 8 Fortune 500 (3M, Dell, BASF, Caterpillar) | E9: -
B10: Costa Rica | C10: Régimen de Zona Franca | D10: Services & non-mfg: 0% CIT yrs 1-8, 15% yrs 9-12. Mfg outside GAM: 0% yrs 1-6. Megaproject outside GAM: 0% yrs 1-12. Plus VAT, duty, property-transfer and remittance-tax relief | E10: Min investment USD 100k-250k outside GAM; USD 10m megaproject; 100 staff for mfg megaproject
B11: Guatemala | C11: Zonas Francas / Ley de Simplificacion | D11: Duty and income-tax relief on qualifying export activity | E11: -
B12: Colombia | C12: Zonas Francas (Art. 240-1 ET) | D12: 20% CIT, but post-13-Dec-2022 users only qualify with an approved internationalisation/export plan (Decreto 047/2024). Pre-2022 users exempt from the export test per C-384/2023 | E12: 119 active zones, 20 departments, COP 54.8tn invested, 169,000+ formal jobs (ProColombia, Jan-2026)
B13: Colombia | C13: Renewables | D13: 15-year CIT exemption on wind, biomass and agricultural-waste electricity | E13: Running since 2017
B14: Colombia | C14: Obras por impuestos | D14: Discharge tax liability by building public infrastructure in conflict-affected zones | E14: -
B15: Dominican Rep. | C15: Law 8-90 free zones | D15: ~70% of Dominican export revenue; >USD 6bn/yr to the US; medical devices, apparel, cigars, electronics. 3.5% tax on local-market sales | E15: Survived Ley 30-26 untouched
B16: Dominican Rep. | C16: Law 158-01 CONFOTUR | D16: Full income-tax exemption up to 15 yrs; ITBIS exemption on construction; duty waiver; 3% transfer-tax exemption to the unit buyer | E16: Highest-conversion product in the pack for Caribbean wealth clients
B17: Dominican Rep. | C17: Law 28-01 border development | D17: 100% CIT and VAT exemption in the Dominican-Haitian border zone | E17: -
... B20: Guyana | C20: Investment framework + Local Content Act | D20: Sector incentives; local-content requirements on the oil supply chain | E20: -
B23: Residency by investment - the prospecting instrument
B24: Market | C24: Programme | D24: Threshold | E24: What it grants | F24: Note | G24: Legal basis
B25: Panama | C25: Qualified Investor Visa | D25: Real estate USD 300,000 / securities USD 500,000 / deposit USD 750,000 | E25: Immediate permanent residence; naturalisation after 5 yrs | F25: REAL-ESTATE THRESHOLD RISES TO USD 500,000 AFTER 15 OCTOBER 2026 | G25: Decree 722/2020 as modified by Decree 193
B26: Panama | C26: Friendly Nations Visa | D26: Real estate USD 200,000 / 3-yr deposit USD 200,000 / local employment | E26: 2 yrs provisional then permanent | F26: 50+ eligible nationalities | G26: Decree 226, Jul 2021
B27: Costa Rica | C27: Investor residency | D27: USD 150,000 (cut from 200,000) | E27: Permanent residency pathway then citizenship | F27: 7 qualifying categories incl. SUGEVAL-registered securities and VC funds | G27: Law 9996 (2021)
B28: Dominican Rep. | C28: CONFOTUR (project-level, not a visa) | D28: Purchase inside an approved tourism project | E28: Up to 15 yrs income-tax exemption; 3% transfer-tax exemption flows to the individual buyer | F28: Punta Cana, Samana, Miches, Puerto Plata, Pedernales | G28: Law 158-01 as amended by 195-13
B29: El Salvador | C29: Freedom / investor visa | D29: Thresholds NOT VERIFIED - confirm before use | E29: - | F29: Ley de Fomento benefits extend to shareholders | G29: Verify
B30: Colombia | C30: M / R visas | D30: Multiples of the minimum wage; 2026 multiples NOT VERIFIED | E30: No golden visa in the Panamanian sense | F30: - | G30: Verify with Bogotá practice
B31: Guatemala | C31: No dedicated investor visa identified | D31: - | E31: - | F31: - | G31: -
B32: Guyana | C32: No dedicated investor visa identified | D32: - | E32: - | F32: - | G32: -
B34: The Panamanian real-estate threshold rises permanently from USD 300,000 to USD 500,000 after 15 October 2026. As at the date of this pack that is a six-week window, and it is the most immediately actionable fact in the file - it works equally for Central American, Colombian and Venezuelan prospects. Note that Panamanian permanent residence does not by itself create Panamanian tax residency; Panama is territorial.

Sheet Infrastructure
B2: PPP and infrastructure pipeline
B3: Named projects with size and status as of 4 September 2026. NF = no financed cost or contract verified.
B5: Market | C5: Project | D5: Size | E5: Status at Sep-2026 | F5: Next milestone
B6: Panama | C6: Río Indio reservoir (ACP) | D6: USD 1.6bn | E6: RFQ for programme manager posted 18 Aug 2026 | F6: Submissions due 6 Oct 2026; EIA Dec-26/Jan-27; construction 2028, operations 2031
B7: Panama | C7: Metro Line 3 monorail (Panamá Oeste) | D7: USD 4.4bn (from ~2.8bn) | E7: 77% complete Jun-2026; dynamic monorail testing | F7: Realistic opening band 2027-2028 (not 2026)
B8: Panama | C8: Cobre Panamá (First Quantum) | D8: ~5% of GDP pre-closure | E8: NOT restarted. Milling pre-blasted stockpile only; first processed shipment Aug-2026 | F8: Presidential commission to report before Dec-2026
B9: Panama | C9: Corozal (Pacific) + Telfers (Atlantic) terminals | D9: NF | E9: ACP has signalled an international tender | F9: Once-a-generation concession auction
B10: Panama | C10: Panama-David / Chiriquí train | D10: NF | E10: Pre-investment / feasibility only - no financed cost or signed contract verified | F10: -
B11: Costa Rica | C11: GAM electric passenger train (INCOFER) | D11: USD 800m - fully financed | E11: CABEI USD 550m (incl. GCF 178.7m) + EIB USD 250m. Legally enabled | F11: Tender timing unconfirmed; 51+ km, 30 stations, 28 trainsets
B12: Guatemala | C12: ANADIE / ANI PPP pipeline | D12: NF | E12: Framework active | F12: 2027 election cycle likely to slow approvals
B13: Colombia | C13: Bogotá Metro Line 1 | D13: NF | E13: 77.53% complete Apr-2026; 10 of 30 trains delivered, testing at Bosa | F13: 23.9 km, 16 stations; no commercial-operation date stated
B14: Colombia | C14: Bogotá Metro Line 2 | D14: COP 34.9tn | E14: TENDER RECEIVED ZERO BIDS 20 Jan 2026 and was voided. Relaunched Feb-2026 | F14: Bids due Sep-2026, award Q1-2027; operations slip 2032 -> 2034
B15: Colombia | C15: 5G road concessions (ANI) | D15: COP 5.5tn (Villeta-Guaduas-El Korán alone) | E15: Nueva Malla Vial Valle 64%; Troncal Magdalena II 39%; Buenaventura-Loboguerrero-Buga 29% | F15: ALO Sur works started 5 Aug 2026
B16: Colombia | C16: Canal del Dique | D16: NF | E16: Pre-construction | F16: Construction from March 2027
... B24: Guyana | C24: Stabroek FPSO programme | D24: USD 55bn Exxon investment recovered ahead of schedule | E24: 5 FPSOs; Errea Wittu arrived 21 Aug 2026; ~900 kb/d Aug-2026 | F24: Past 1m bpd in Q4-2026; capacity 1.3m bpd after two more FPSOs in 2027
B26: Two cautionary entries are worth reading before you quote the pipeline to anyone. Bogota Metro Line 2 received ZERO bids at the 20 January 2026 deadline and was declared void after Acciona pulled its 40% stake from the sole remaining consortium; the relaunched tender's September 2026 deadline had not resolved as at the date of this pack, and operations have already slipped from 2032 to 2034. And Cobre Panama has NOT reopened - it is milling a pre-blasted stockpile of roughly 38m tonnes under a preservation licence, which is about twelve months of milling, and shipped its first processed concentrate in August 2026. Neither of these is a restart.

Sheet Wealth Map
B2: Where the wealth is made, and who holds it
B3: Item (c) of the request. Sector engines, named family groups and the liquidity events that create prospects.
B5: The engines
B6: Market | C6: Engine | D6: The hard number | E6: Why it mints wealth - and the caveat
B7: Panama | C7: Canal & logistics | D7: FY2025 revenue USD 5.7bn (+14.4%), 13,404 transits (+19.3%), USD 2.965bn to Treasury (+20%) | E7: Transport cluster ~15% of GDP; transport/storage grew +14.5% in 2025, ~40% of all growth
B8: Panama | C8: Banking (Centro Bancario Internacional) | D8: Banco General: assets USD 21.1bn, net income USD 844.6m (+5.8%), ROAE 21.2% | E8: Panamanian founding families; the plaza itself is the wealth pool
B9: Panama | C9: Copper optionality | D9: Cobre Panamá was ~5% of GDP and >75% of goods exports (~USD 2.8bn) | E9: A settlement is the largest single re-rating event available in the country
B10: Costa Rica | C10: Medical devices | D10: >USD 6.1bn exports = 44% of goods exports; 90+ medtech firms; 5th-largest US supplier | E10: But contracting in 2026: 12.5% US tariff, appreciating colon, Boston Scientific restructuring over a 10,000-person CR workforce
B11: Costa Rica | C11: FDI franchise | D11: 2025 FDI USD 5.12bn (2nd record year); US 54.8%, Switzerland 19.7% | E11: Warning: reinvestment at a record USD 4.33bn while new investment fell 18% to USD 895m
B12: Guatemala | C12: Remittance-driven consumption | D12: 2025 remittances USD 25.5bn, +19% = 20.7% of GDP | E12: Banguat projects deceleration to +5% in 2026 - the single largest macro risk in the sample
B13: Guatemala | C13: Family conglomerates | D13: CMI, Cementos Progreso, Cervecería Centroamericana, Pantaleón, Banco Industrial | E13: CMI Capital pivoted to 'Active Asset Management' and opened to outside investors, Dec-2025
B14: Colombia | C14: Banking / Grupo Cibest | D14: H1-2026 net income COP 4.19tn (+18.7%); NIM 7.94%; assets COP 363tn | E14: Sold Banistmo for USD 1.418bn (closed 30 Jun 2026); COP 1.35tn buyback + COP 1.2tn extraordinary dividend
B15: Colombia | C15: Oil & gas - in managed decline | D15: Jul-2026 crude 727,920 bpd (-2.5% y/y); gas 1,096 MMcfd (-8.4% y/y) | E15: Wealth is being harvested, not created. 2025 reserves still unpublished as of Jun-2026
B16: Colombia | C16: Public spending | D16: Q2-2026 public admin/education/health +10.0% y/y, +1.7pp of 3.5% growth | E16: Growth carried by the state, not by tradables - a wealth-creation warning
B17: Dominican Rep. | C17: Tourism + free zones | D17: Free zones ~70% of export revenue, >USD 6bn/yr to the US; 11.2m visitors in 2024 | E17: CONFOTUR gives a 15-yr shelter that flows through to the individual unit buyer
... B21: Guyana | C21: Oil | D21: ~900 kb/d Aug-2026; NRF USD 4.35bn at 31 Jul 2026; inflows ~USD 10.5bn since 2020 | E21: GDP/capita already USD 26,994 - above Costa Rica and Panama
B24: Named local and family participants
B25: Market | C25: Group | D25: Scale / status | E25: Ownership
B26: Panama | C26: Grupo Financiero BG / Banco General | D26: Largest private bank; assets USD 21.1bn, net income USD 844.6m, ROAE 21.2% | E26: Panamanian founding families (not independently verified)
B27: Panama | C27: Copa Holdings (NYSE: CPA) | D27: FY2025 revenue USD 3.617bn, net profit USD 671.6m, 14.85m pax, 126 aircraft | E27: Motta family control (widely reported, not verified)
B28: Panama | C28: Empresas Bern | D28: #1 domestic developer + Bern Hotels & Resorts; 160+ projects | E28: Bern family - Herman & Myriam Bern, four children on the board
B29: Panama | C29: Grupo Motta / Motta Internacional | D29: Duty-free (Attenza), Inversiones Bahia | E29: Motta family
B30: Panama | C30: Grupo Rey | D30: ~150 supermarkets/pharmacies | E30: CORRECTION: Corporación Favorita (Ecuador) holds 73% since 2019 - NOT a Panamanian family prospect
B31: Costa Rica | C31: FIFCO | D31: CORRECTION: no longer the beverage business - operating assets went to Heineken; FIFCO retains 25% stakes plus real estate | E31: Fernandez family
B32: Guatemala | C32: Corporacion Multi Inversiones (CMI) | D32: CMI Capital pivoted to Active Asset Management, Dec-2025, and opened to outside investors | E32: Bosch-Gutierrez family
B33: Guatemala | C33: Cementos Progreso / Cervecería Centroamericana / Pantaleón / Banco Industrial | D33: Financials NOT FOUND this pass | E33: Novella, Castillo, Herrera, Bicapital
B34: Colombia | C34: Grupo Argos | D34: Dec-2025 revenue COP 11.7tn, assets COP 37.6tn, market cap COP 11.1tn. Units: Argos Cementos, Celsia, Odinsa | E34: GEA / Antioquia group. 'ACE 1.0' programme to double DPS over 36 months
B35: Colombia | C35: Grupo Nutresa | D35: ~87% Gilinski Group (IHC-backed). Best 2025 COLCAP performer, >+250% | E35: Gilinski family + IHC
B36: Colombia | C36: Gilinski Group | D36: Has taken control of GeoPark and entered Venezuela - Orinoco Belt assets, 15.7bn bbl reserves, 11,000 bpd | E36: Gilinski family
... B42: Guyana | C42: Banks DIH, Demerara Distillers, GBTI, Republic Bank Guyana, ANSA McAL Guyana | D42: Financials NOT FOUND. ANSA McAL took a USD 500m IDB Invest facility Jul-2026 | E42: -
B45: Liquidity events 2024-2026 - who just got liquid, and when
B46: Date | C46: Market | D46: Event | E46: Size
B47: 22 Sep 2025 (close H1-2026) | C47: Costa Rica | D47: Heineken acquires FIFCO's beverage and retail businesses | E47: USD 3.2bn
B48: Announced 18 Dec 2025, closed 30 Jun 2026 | C48: Panama / Colombia / El Salvador | D48: Grupo Cibest sells Banistmo to Inversiones Cuscatlán | E48: USD 1.418bn
B49: Mar 2026 / Aug 2026 | C49: Colombia | D49: Grupo Cibest buyback + extraordinary dividend | E49: COP 1.35tn + COP 1.2tn
B50: 26 Jan 2024 (control since) | C50: El Salvador / Colombia | D50: Grupo Calleja takes control of Grupo Éxito | E50: EUR 400m for 34%, now >56%
B51: 1 Dec 2025 | C51: Colombia / Costa Rica / Panama | D51: Davivienda closes Scotiabank COL/CR/PAN; Scotiabank takes ~20% of Davivienda Group | E51: -
B52: 1 Sep 2026 | C52: Colombia | D52: Nequi spun out as an independent financing company | E52: 29m users
B53: 30 Jan - Mar 2026 | C53: Panama | D53: Supreme Court voids the CK Hutchison ports concession; Panama carved out of the USD 22.8bn global deal | E53: CKH arbitration >USD 1.5bn
B54: Jul 2026 | C54: Guyana / Trinidad | D54: IDB Invest facility to ANSA McAL — its largest ever | E54: USD 500m
...

Sheet Equity Exposure
B2: Listed-company exposure map
B3: Item (e) of the request. Exposure map only - no valuation metrics, no price targets, no recommendations.
B4: This tab exists to answer 'which listed companies actually have money in these markets'. It is not a screen and nothing here is a view. Several widely used names in this space have been acquired, delisted or restructured in the last eighteen months - the traps table at the bottom lists them.
B7: Bucket | C7: Company | D7: Ticker / exchange | E7: Sector | F7: Specific exposure | G7: Pure play?
B8: Energy & extractives - Guyana | C8: ExxonMobil | D8: XOM (NYSE) | E8: Energy | F8: Operator, 45% Stabroek; Guyana is its single largest growth engine | G8: Diversified
C9: Chevron | D9: CVX (NYSE) | E9: Energy | F9: 30% Stabroek via the Hess acquisition, completed 18 Jul 2025. REPLACES Hess | G9: Diversified
C10: CNOOC | D10: 0883.HK | E10: Energy | F10: 25% Stabroek; only non-China asset of this scale | G10: Diversified
C11: CGX Energy | D11: OYL.V (TSXV) | E11: Energy | F11: Corentyne block operator; Guyana-only | G11: PURE PLAY
C12: Noble Corp | D12: NE (NYSE) | E12: Energy services | F12: 4 drillships on Stabroek at ~USD 400k/day; largest single-country rig concentration | G12: Diversified (high torque)
C13: TechnipFMC | D13: FTI (NYSE) | E13: Energy services | F13: Substantial subsea contract for Hammerhead; 200th subsea tree delivered Sep-2026 | G13: Diversified
C14: Saipem | D14: SPM.MI | E14: Energy services | F14: ~USD 500m EPCI on Hammerhead; further ExxonMobil Guyana award Apr-2026 | G14: Diversified
B15: Energy & extractives - Colombia | C15: Ecopetrol | D15: EC (NYSE) / BVC | E15: Energy | F15: Colombian NOC; also controls ISA. Bought 51% of Brazil's Brava Energia (~USD 1.2bn) | G15: PURE PLAY
C16: Parex Resources | D16: PXT.TO | E16: Energy | F16: Colombia-only; enlarged by the Frontera E&P acquisition, Jun-2026 | G16: PURE PLAY
C17: GeoPark | D17: GPRK (NYSE) | E17: Energy | F17: Llanos 34 core plus Chile/Brazil/Argentina/Ecuador. Gilinski has taken control | G17: Majority Colombia
C18: Frontera Energy | D18: FEC.TO | E18: Infrastructure | F18: No longer an E&P. Colombia infrastructure (Puerto Bahia, ODL) + Guyana Corentyne via CGX | G18: PURE PLAY
C19: Gran Tierra | D19: GTE (NYSE/TSX) | E19: Energy | F19: Colombia + Ecuador being SOLD to Maurel & Prom (~USD 1.33bn, announced 4 Aug 2026, pending) | G19: Exposure ending
C20: Canacol | D20: CNNEQ (OTCID) / CNEC (BVC) | E20: Energy | F20: CCAA restructuring; TSX-delisted 29 Dec 2025, trading suspended | G20: DISTRESSED - not investable
B21: Mining | C21: Barrick Mining | D21: B (NYSE) / ABX (TSX) | E21: Materials | F21: 60% of Pueblo Viejo, DR; LOM beyond 2040, ~USD 1.3bn expansion capex | G21: Diversified
C22: Newmont | D22: NEM (NYSE) | E22: Materials | F22: 40% of Pueblo Viejo, DR - the other half of the country's largest mine | G22: Diversified
C23: First Quantum | D23: FM.TO | E23: Materials | F23: Cobre Panamá - idle since late 2023. Binary Panama optionality; was ~5% of Panamanian GDP | G23: Diversified (high torque)
C24: Aris Mining | D24: ARIS (NYSE-A/TSX) | E24: Materials | F24: Colombia (Segovia, Marmato) plus Guyana (Toroparu) | G24: Majority Colombia
C25: Pan American Silver | D25: PAAS (NYSE/TSX) | E25: Materials | F25: Escobal, Guatemala - suspended since 2017; ILO-169 consultation ongoing. Large embedded option, no production | G25: Diversified
C26: Aura Minerals | D26: AUGO (Nasdaq) | E26: Materials | F26: Era Dorada gold-copper, Guatemala - board approved construction 2026 | G26: Diversified
B27: Ports, logistics, aviation | C27: Copa Holdings | D27: CPA (NYSE) | E27: Industrials | F27: Panama City Tocumen 'Hub of the Americas'; 126 aircraft; Panama-domiciled. Cleanest listed Panama proxy | G27: PURE PLAY
C28: CK Hutchison | D28: 0001.HK | E28: Industrials | F28: Balboa & Cristobal concessions ANNULLED 24 Feb 2026; arbitration filed Aug-2026 for >USD 1.5bn | G28: Diversified
C29: A.P. Moller-Maersk | D29: MAERSK-B.CO | E29: Industrials | F29: APM Terminals Panama now operates Balboa under an 18-month temporary concession | G29: Diversified
C30: VINCI | D30: DG.PA | E30: Industrials | F30: AERODOM - concession for 6 DR airports, extended 30 years; plus Guanacaste (Liberia), Costa Rica | G30: Diversified
B31: Hotels, tourism, cruise | C31: Meliá Hotels | D31: MEL.MC | E31: Cons. Disc. | F31: Largest listed DR resort exposure - Punta Cana/Bavaro estate incl. the Grupo Puntacana JV; also Costa Rica | G31: Diversified
C32: Hyatt Hotels | D32: H (NYSE) | E32: Cons. Disc. | F32: Absorbed Playa's DR platform Jun-2025, then sold the real estate to Tortuga Dec-2025. Now fees, not assets | G32: Diversified
C33: Marriott / Hilton | D33: MAR / HLT | E33: Cons. Disc. | F33: Franchised and managed across DR, Panama, Costa Rica, Colombia, Guatemala; asset-light | G33: Diversified
C34: Carnival | D34: CCL (NYSE/LSE) | E34: Cons. Disc. | F34: Amber Cove, Puerto Plata, DR - a Carnival-developed destination port; also Colon, Panama | G34: Diversified
B35: Medical devices - Costa Rica | C35: Establishment Labs | D35: ESTA (Nasdaq) | E35: Healthcare | F35: The only Costa Rica pure play on any exchange. HQ and sole manufacturing in Alajuela; 2025 revenue USD 211m | G35: PURE PLAY
C36: Boston Scientific | D36: BSX (NYSE) | E36: Healthcare | F36: Among the largest CR medtech employers; multiple Coyol/Heredia plants. 2026 restructuring covers a 10,000-person CR workforce | G36: Diversified
C37: Medtronic / Abbott / Baxter / Edwards | D37: MDT / ABT / BAX / EW | E37: Healthcare | F37: Costa Rica manufacturing within the Coyol cluster | G37: Diversified
C38: Intel | D38: INTC (Nasdaq) | E38: Technology | F38: Costa Rica assembly/test and megalab - the anchor non-medtech FDI in CR | G38: Diversified
B39: Financials & payments | C39: Grupo Cibest (Bancolombia) | D39: CIB (NYSE) | E39: Financials | F39: Colombia's largest bank group. NOTE: sold Banistmo (Panama) Jun-2026. Retains Banco Agrícola (SV), BAM (GT). 15.8% of the COLO ETF | G39: PURE PLAY
C40: BAC Holding International | D40: BHI (BVC) | E40: Financials | F40: The closest thing to a CentAm pure-play bank. CR, SV, GT, HN, NI, PA via BAC Credomatic; ~20,600 staff | G40: PURE PLAY
C41: Davivienda Group | D41: PFDAVVNDA (BVC) | E41: Financials | F41: Enlarged 1 Dec 2025 by Scotiabank's Colombia/CR/Panama books | G41: PURE PLAY
C42: Grupo Aval | D42: AVAL (NYSE) | E42: Financials | F42: Colombia banking. CentAm exposure was spun off as BHI in 2022 - do not double-count | G42: Majority Colombia
C43: Bladex | D43: BLX (NYSE) | E43: Financials | F43: Panama-domiciled trade-finance bank founded by 23 LatAm/Caribbean central banks | G43: PURE PLAY (domicile)
...

Sheet Colombia Annex
B2: Colombia - deep dive
B3: The priority market. Everything below is dated; distinguish rigorously between enacted, proposed and speculation.
B5: The fact that reframes everything: the earthquake of 10 August 2026
B6: Item | C6: Value
B7: Magnitude / depth | C7: Mw 7.4-7.5, ~96-110 km deep
B8: Epicentre | C8: Near San Jose del Palmar, Choco
B9: Damage zone | C9: Cali, Pereira, Quibdo, Manizales, Armenia, Buenaventura
B10: Deaths / injured / missing | C10: 331 / 4,613 / 240
B11: Homes damaged / destroyed | C11: 178,555 / 31,540
B12: Government damage estimate | C12: USD 9.6bn
B13: Reconstruction cost estimate | C13: COP 30-40tn
B14: Share of 2026 public investment (COP 88.4tn) | C14: 34-45%
B15: Formal jobs in the affected zone | C15: 1.4m, ~15% of the national total
B16: 2026 GDP forecast revision | C16: 2.7% -> 2.5%
B17: It struck three days after the inauguration. It is why the 2027 budget jumped COP 59.3tn and why the fiscal picture below is materially worse than the June Marco Fiscal implied. A source conflict exists on the date - one outlet gives 25 August; USGS-referenced reporting gives 10 August, which is correct.
B21: The election, and why the mandate is thinner than the headline
B22: First round, 31 May 2026 | C22: Movement | D22: Votes | E22: %
B23: Abelardo de la Espriella | C23: Defensores de la Patria | D23: 10361499 | E23: 43.75
B24: Iván Cepeda | C24: Pacto Histórico | D24: 9688361 | E24: 40.9
B25: Paloma Valencia | C25: Centro Democrático | D25: 1639685 | E25: 6.92
B26: Sergio Fajardo | C26: Dignidad y Compromiso | D26: 1009073 | E26: 4.26
B28: Runoff, 21 June 2026 (turnout 63.60%, a record) | D28: Votes | E28: %
B29: Abelardo de la Espriella | D29: 12960166 | E29: 49.66
B30: Iván Cepeda | D30: 12708312 | E30: 48.7
B31: Margin | D31: 251854 | E31: 0.96
B32: 251,854 votes, 0.96 percentage points - the narrowest presidential margin in Colombian history.
B34: Senate after 8 March 2026 - the left won the plurality on the same day the right won the presidency
B35: Party | C35: Senate seats
B36: Pacto Histórico | C36: 25
B37: Centro Democrático | C37: 17
B38: Partido Liberal | C38: 13
B39: Alianza por Colombia | C39: 10
B40: Partido Conservador | C40: 10
B41: Partido de la U | C41: 9
B42: Cambio Radical-ALMA | C42: 7
B43: Ahora Colombia | C43: 5
B44: Salvación Nacional | C44: 4
B45: MAIS (indigenous) | C45: 1
B46: AICO (indigenous) | C46: 1
B47: Total | C47: =SUM(C36:C46) -> 102
...

Sheet Calendar
B2: Prospecting calendar - what turns this pack into calls
B3: Dated events between now and April 2027, ranked by how usable they are as a reason to pick up the phone.
B5: Date | C5: Market | D5: Event | E5: Priority | F5: Why it is a conversation
B6: FY2027 (first declarations 2028) | C6: Panama | D6: Law 526/2026 economic substance takes effect | E6: HIGHEST | F6: Every Panamanian holding or foundation receiving foreign dividends, interest or rent must be triaged before FY2027. Default outcome for a passive shell is 15% where there was zero. Executive Decree 32 (3 Sep 2026) sets the minimum: one qualified employee, premises, proportionate opex, two in-person board meetings a year in Panama. COVERS TRUSTS AND FOUNDATIONS.
B7: Unresolved | C7: Colombia | D7: Constitutional Court review of Decreto 1474 de 2026 (40,000 UVT threshold, rates to 5%) | E7: HIGHEST | F7: Colombian wealth-tax planning CANNOT be closed out until the Court rules. That uncertainty is itself the client conversation.
B8: Unresolved | C8: Colombia | D8: Moody's Baa3 - the last investment-grade notch | E8: HIGHEST | F8: A downgrade makes Colombia unambiguously sub-IG at all three, with forced-selling implications for IG-mandated portfolios. No agency has acted since either the election or the earthquake.
B9: 15 Oct 2026 | C9: Panama | D9: Qualified Investor Visa real-estate threshold rises USD 300,000 -> USD 500,000 | E9: HIGH | F9: A six-week window. The single most actionable date in the pack for prospecting.
B10: 15 Sep 2026 | C10: Colombia | D10: Congressional committees must fix the 2027 budget amount | E10: HIGH | F10: Full approval due 20 Oct 2026. Watch for a rating response.
B11: Sep 2026 | C11: Colombia | D11: 'Ley de rescate económico' promised to Congress | E11: HIGH | F11: The government's own fiscal bill. He does not control Congress - 1 Senate seat, 4 Chamber seats.
B12: 30 Sep 2026 | C12: Colombia | D12: BanRep rate decision | E12: HIGH | F12: Held 12.00% on 31 Jul on a 4-3 vote with three directors wanting +50bp.
B13: 26 Oct 2026 | C13: Colombia | D13: Individuals' deadline for the declaración de activos en el exterior | E13: HIGH | F13: Window opened 12 Aug. Threshold is only ~USD 33,000 of foreign assets. Penalties are punitive.
B14: 20 Oct 2026 | C14: Colombia | D14: 2027 budget full approval deadline | E14: HIGH | F14: COP 634.9tn; debt service is ~25% of the budget.
B15: Before Dec 2026 | C15: Panama | D15: Presidential commission to report on Cobre Panamá | E15: HIGH | F15: The largest single re-rating event available in Panama. Mulino has ruled out a congressional concession.
B16: 1 Apr 2027 | C16: Colombia | D16: Pension reform enters into force | E16: HIGH | F16: ~67% of new contributor flows move to the public system. AFPs hold ~41% of COLCAP.
... B22: 2027 | C22: Guatemala | D22: General election (June) | E22: MED | F22: Campaign begins during 2026; expect policy paralysis.
B25: The net-new-money plays, ranked
B26: Play | C26: The instrument | D26: What it actually says | E26: Why it opens a conversation | F26: Priority
B27: Panama structure triage | C27: Law 526/2026 economic substance | D27: Every Panamanian holding company, trust or foundation in a client's structure that receives foreign dividends, interest, royalties or rent is exposed to a 15% tax from FY2027 unless it meets the substance test. Executive Decree 32 (3 Sep 2026) sets the minimum bar. | E27: A defensible, dated, technical reason to open every existing Panamanian file and to be the adviser who called it first. | F27: HIGHEST
B28: Colombian wealth-tax uncertainty | C28: Ley 2277 vs Decreto 1474/2026 vs the abolition pledge | D28: Operative law is 0.5-1.5% above ~COP 3.77bn. Decreto 1474 would cut the threshold to 40,000 UVT and raise the top rate to 5% - it is under Constitutional Court review. The new government promises abolition but has filed no bill. | E28: The client cannot plan and knows it. The conversation is the product; the answer is not yet available to anyone. | F28: HIGHEST
B29: Colombian offshore compliance | C29: Form 160, cuenta de compensacion, CFC at 10% | D29: The foreign-asset reporting threshold is ~USD 33,000. Investment vehicles are AUTOMATICALLY classified as CFCs. Individuals' filing window closes 26 October 2026. | E29: A dated compliance deadline is the least resistible reason to call. It also surfaces every undeclared structure in the book. | F29: HIGH
B30: Panama residency window | C30: Qualified Investor Visa | D30: The real-estate threshold rises from USD 300,000 to USD 500,000 after 15 October 2026. | E30: Six weeks. Works for CentAm, Colombian and Venezuelan prospects alike. | F30: HIGH
B31: Liquidity events | C31: Banistmo USD 1.418bn; FIFCO/Heineken USD 3.2bn; Cibest COP 2.55tn returned | D31: Named, dated, closed transactions that put cash into identifiable family hands in 2025-26. | E31: Prospecting is easier when you know who just got liquid and when. | F31: HIGH
B32: Succession openings | C32: Grupo Poma (Ricardo Poma died 24 Aug 2025); Grupo Popular (Grullon moved to EVP, 2026); CMI Capital opened to outside investors (Dec-2025) | D32: Generational transitions at three of the region's largest family holdings. | E32: Succession is when a family reconsiders its banking relationships. | F32: HIGH
B33: The CONFOTUR product | C33: DR Law 158-01 | D33: Up to 15 years of income-tax exemption plus a 3% transfer-tax exemption that flows through to the individual buyer of a unit. Survived the June 2026 tax reform untouched. | E33: A concrete, legislated, tax-advantaged product to discuss with Caribbean real-asset buyers. | F33: MED
B34: Rating catch-up | C34: Fitch is 3+ years stale on Costa Rica and Guatemala; S&P is stale on the DR | D34: Costa Rica took two upgrades in a month (Sep/Oct 2025) and Fitch is two notches behind. Guatemala is one notch from IG at two agencies with 27% debt/GDP and a structural current-account surplus. | E34: A credible, differentiated CIO view that is not simply 'buy Colombia'. | F34: MED

Sheet Risks
B2: Risk register - the eight things that could embarrass you
B3: Read this before the pack, not after.
B5: Risk | C5: The number | D5: Why | E5: What to do about it
B6: The remittance cliff | C6: Guatemala 20.7% of GDP, El Salvador ~24%, DR 9.3% | D6: Record 2025 inflows were partly FRONT-RUNNING of US deportation policy and the 1% US cash-transfer tax effective 1 Jan 2026. Banguat's own forecast decelerates from +19% to +5%. | E6: Stress-test any thesis resting on remittance-driven consumption for a stop.
B7: The 2026 FX rally will not repeat | C7: COP +19.6% vs USD YTD, CRC +10.3% y/y, DOP +4.7% YTD, GTQ +0.5% | D7: For USD-based clients this was a large unhedged tailwind. Colombian analysts call the peso rally largely exhausted; DR consensus expects a full DOP reversal to 65.50 by year-end. BanRep is buying dollars. | E7: Revisit hedge ratios before the conversation, not after.
B8: Colombia's last IG notch | C8: Moody's Baa3, stable | D8: Sub-IG at both S&P (BB-, lowest since 1993) and Fitch (BB). Fiscal rule escape-claused through 2027. 2027 deficit revised to 9.4% of GDP by BanRep. CARF calls for a 3.7%-of-GDP adjustment in 2027. | E8: Size Colombian sovereign exposure for a forced-selling event, not for a base case.
B9: Panama's IG knife-edge | C9: Moody's Baa3 NEGATIVE, S&P BBB-, Fitch already BB+ | D9: Fitch: general-government debt 67.2% of GDP end-2025; interest/revenue 18.8% vs an 11.4% BB median. Moody's warns consolidation came from cutting public investment, not structural reform. Renewed canal drought - ACP cut to 34 daily slots for September 2026. | E9: Panama is a fallen-angel-in-progress candidate. IG index eligibility is fragile.
B10: Costa Rica's deflation-appreciation squeeze | C10: 39 consecutive months of negative y/y CPI; CRC +10.25% over 12m | D10: Persistent appreciation is the direct cause of the deflation and is squeezing exporters and tourism. FDI is reinvestment-driven - NEW investment fell 18% to USD 895m. The medtech cluster is contracting in 2026 on a 12.5% US tariff. | E10: The best-rated momentum story in the sample has a real-economy problem underneath it.
B11: Guyana concentration | C11: USD 1.06bn of central-bank reserves against a 13%-of-GDP current-account surplus | D11: Oil receipts accumulate in the Natural Resource Fund (USD 4.35bn), not at the central bank. Sovereign is UNRATED. One commodity, one operator consortium, a 1m population, an opposition leader under US sanctions, and a neighbour that has pre-announced it will defy the World Court. | E11: Never present reserves as a Guyana buffer metric without the NRF alongside it. Satellite allocation only.
B12: Panama structure risk | C12: Law 526/2026 + Executive Decree 32 | D12: The default outcome for a passive Panamanian shell holding foreign passive income is 15% tax from FY2027 where there was previously zero. Covers trusts and foundations. | E12: This is a book-wide triage, not a client-by-client one. It is also the highest-value advisory hook in the pack.
