Workbook
Name _DLX1: Employment!$B$3:$V$7
Name _DLX1: 'Inflation expectations'!$B$3:$I$7
Name _DLX1.USE: #REF!
Name _DLX1.USE: 'Current account'!$D$3:$I$24
Name _DLX10.USE: 'Net reserves'!$B$20:$G$37
Name _DLX13.USE: #REF!
Name _DLX2: 'Trade balance'!$B$2:$L$6
Name _DLX2.USE: #REF!
Name _DLX3: '12 month rolling fiscal'!#REF!
Name _DLX4: '12 month rolling fiscal'!$B$2:$G$6
Name _DLX5: '12 month rolling fiscal'!$I$2:$P$6
Name _DLX6: 'GDP contributions (HAVER)'!$B$3:$Z$7
Name _DLX7.USE: '[3]Monetary analysis'!#REF!
Name _DLX8: 'CPI MoM'!$B$2:$H$6
Name año2003: #REF!
Name dbBacktables: [4]dbBacktables!$A$2:$A$43
Name dbIndicators: [4]dbIndicators!$A$2:$A$230
Name dbSources: [4]dbSources!$A$2:$A$93
Name PRINT_TITLES_MI: #REF!
Name YesNo: [4]YesNo!$A$2:$A$3

Sheet Inflation expectations
C2: 12mo inflation expectations | D2: 24mo inflation expectations | E2: 30% annual mark
B3: 11606 !M | C3: N213VC1M@EMERGELA | D3: N213VC2M@EMERGELA
B4: .DESC | C4: Argentina: Median National CPI Inflation Expectations, 12 months (%) | D4: Argentina: Median National CPI Inflation Expectations, 24 months (%)
B5: .SOURCE | C5: BCRA | D5: BCRA
B6: .DATA_TYPE | C6: % | D6: %
B7: .MAG | C7: 0 | D7: 0
A8: 42522 | B8: 1606 | C8: 21.5 | D8: 15.9 | E8: 30
A9: 42552 | B9: 1607 | C9: 21.7 | D9: 16 | E9: 30
A10: 42583 | B10: 1608 | C10: 21.9 | D10: 16 | E10: 30
A11: 42614 | B11: 1609 | C11: 21.1 | D11: 15.4 | E11: 30
A12: 42644 | B12: 1610 | C12: 19.4 | D12: 14.9 | E12: 30
A13: 42675 | B13: 1611 | C13: 20 | D13: 15.4 | E13: 30
A14: 42705 | B14: 1612 | C14: 19.6 | D14: 14 | E14: 30
A15: 42736 | B15: 1701 | C15: 19.7 | D15: 14 | E15: 30
A16: 42767 | B16: 1702 | C16: 19.5 | D16: 13.1 | E16: 30
A17: 42795 | B17: 1703 | C17: 18.4 | D17: 13 | E17: 30
A18: 42826 | B18: 1704 | C18: 17.5 | D18: 13 | E18: 30
A19: 42856 | B19: 1705 | C19: 17 | D19: 13.1 | E19: 30
... A67: 44317 | B67: 2105 | C67: 43.3 | D67: 37.9 | E67: 30
A68: 44348 | B68: 2106 | C68: 43.1 | D68: #N/A | E68: 30
A69: 44378 | B69: 2107 | C69: 43.2 | D69: 38.5 | E69: 30
A70: 44409 | B70: 2108 | C70: 43.7 | D70: 38.5 | E70: 30
A71: 44440 | B71: 2109 | C71: 45.6 | D71: 38.6 | E71: 30
A72: 44470 | B72: 2110 | C72: 48.6 | D72: 40.1 | E72: 30
A73: 44501 | B73: 2111 | C73: 52.3 | D73: 41.1 | E73: 30
A74: 44531 | B74: 2112 | C74: 54.8 | D74: 43.4 | E74: 30
A75: 44562 | B75: 2201 | C75: 53.9 | D75: 44.3 | E75: 30
A76: 44593 | B76: 2202 | C76: 52.9 | D76: 44.6 | E76: 30
A77: 44621 | B77: 2203 | C77: 55.4 | D77: 45.8 | E77: 30
A78: 44652 | B78: 2204 | C78: 56.1 | D78: 50 | E78: 30
A79: 44682 | B79: 2205 | C79: 60.1 | D79: 55.2 | E79: 30
A80: 44713 | B80: 2206 | C80: 68.8 | D80: 60 | E80: 30
... A129: 46204 | B129: 2607 | C129: 21.8 | D129: 16.6 | E129: 30

Sheet Trade balance
C1: Trade balance | E1: Exports of energy | F1: Imports of energy
B2: 10501 !M | C2: N213IBD@EMERGELA | E2: N213IXFN@EMERGELA | F2: N213IMF@EMERGELA
B3: .DESC | C3: Argentina: Goods Trade Balance (NSA, Mil.US$) | E3: Argentina: Exports of Fuels & Energy (NSA, Mil.US$) | F3: Argentina: Imports: Manufacture Fuels and Lubricants (NSA, Mil.US$)
B4: .SOURCE | C4: INDEC | E4: INDEC | F4: INDEC
B5: .DATA_TYPE | C5: US$ | E5: US$ | F5: US$
B6: .MAG | C6: 6 | E6: 6 | F6: 6
B7: 0501 | C7: 880.1 | D7: =E7-F7 -> 455.8 | E7: 542 | F7: 86.2
B8: 0502 | C8: 739 | D8: =E8-F8 -> 350 | E8: 436 | F8: 86
B9: 0503 | C9: 856.9 | D9: =E9-F9 -> 430.9 | E9: 510 | F9: 79.1
B10: 0504 | C10: 1180.9 | D10: =E10-F10 -> 389.7 | E10: 574 | F10: 184.3
B11: 0505 | C11: 1219.3 | D11: =E11-F11 -> 354.6 | E11: 547 | F11: 192.4
B12: 0506 | C12: 726.6 | D12: =E12-F12 -> 397.7 | E12: 599 | F12: 201.3
B13: 0507 | C13: 1252 | D13: =E13-F13 -> 431.2 | E13: 585 | F13: 153.8
B14: 0508 | C14: 1211.7 | D14: =E14-F14 -> 574.9 | E14: 703 | F14: 128.1
B15: 0509 | C15: 1014.8 | D15: =E15-F15 -> 602.6 | E15: 713 | F15: 110.4
B16: 0510 | C16: 896.2 | D16: =E16-F16 -> 555.7 | E16: 654 | F16: 98.3
B17: 0511 | C17: 572.8 | D17: =E17-F17 -> 519 | E17: 617 | F17: 98 | G17: Full trade balance | H17: Energy trade balance | I17: Non-energy
A18: 38687 | B18: 0512 | C18: 1149.6 | D18: =E18-F18 -> 542.6 | E18: 670 | F18: 127.4 | G18: =SUM(C7:C18) -> 11699.9 | H18: =SUM(D7:D18) -> 5604.7 | I18: =G18-H18 -> 6095.2
A19: 38718 | B19: 0601 | C19: 863.9 | D19: =E19-F19 -> 549.4 | E19: 649 | F19: 99.6 | G19: =SUM(C8:C19) -> 11683.7 | H19: =SUM(D8:D19) -> 5698.3 | I19: =G19-H19 -> 5985.4
A20: 38749 | B20: 0602 | C20: 763.9 | D20: =E20-F20 -> 487.2 | E20: 587 | F20: 99.8 | G20: =SUM(C9:C20) -> 11708.6 | H20: =SUM(D9:D20) -> 5835.5 | I20: =G20-H20 -> 5873.1
A21: 38777 | B21: 0603 | C21: 925.9 | D21: =E21-F21 -> 474.3 | E21: 599 | F21: 124.7 | G21: =SUM(C10:C21) -> 11777.6 | H21: =SUM(D10:D21) -> 5878.9 | I21: =G21-H21 -> 5898.7
A22: 38808 | B22: 0604 | C22: 1379.9 | D22: =E22-F22 -> 577.5 | E22: 710 | F22: 132.5 | G22: =SUM(C11:C22) -> 11976.6 | H22: =SUM(D11:D22) -> 6066.7 | I22: =G22-H22 -> 5909.9
A23: 38838 | B23: 0605 | C23: 1355.4 | D23: =E23-F23 -> 467.7 | E23: 600 | F23: 132.3 | G23: =SUM(C12:C23) -> 12112.7 | H23: =SUM(D12:D23) -> 6179.8 | I23: =G23-H23 -> 5932.9
A24: 38869 | B24: 0606 | C24: 988.6 | D24: =E24-F24 -> 498.7 | E24: 716 | F24: 217.3 | G24: =SUM(C13:C24) -> 12374.7 | H24: =SUM(D13:D24) -> 6280.8 | I24: =G24-H24 -> 6093.9
A25: 38899 | B25: 0607 | C25: 964.5 | D25: =E25-F25 -> 477.5 | E25: 657 | F25: 179.5 | G25: =SUM(C14:C25) -> 12087.2 | H25: =SUM(D14:D25) -> 6327.1 | I25: =G25-H25 -> 5760.1
A26: 38930 | B26: 0608 | C26: 965.4 | D26: =E26-F26 -> 423.5 | E26: 646 | F26: 222.5 | G26: =SUM(C15:C26) -> 11840.9 | H26: =SUM(D15:D26) -> 6175.7 | I26: =G26-H26 -> 5665.2
A27: 38961 | B27: 0609 | C27: 878.7 | D27: =E27-F27 -> 455.7 | E27: 640 | F27: 184.3 | G27: =SUM(C16:C27) -> 11704.8 | H27: =SUM(D16:D27) -> 6028.8 | I27: =G27-H27 -> 5676
A28: 38991 | B28: 0610 | C28: 948.6 | D28: =E28-F28 -> 576.9 | E28: 717 | F28: 140.1 | G28: =SUM(C17:C28) -> 11757.2 | H28: =SUM(D17:D28) -> 6050 | I28: =G28-H28 -> 5707.2
A29: 39022 | B29: 0611 | C29: 872.9 | D29: =E29-F29 -> 502.5 | E29: 622 | F29: 119.5 | G29: =SUM(C18:C29) -> 12057.3 | H29: =SUM(D18:D29) -> 6033.5 | I29: =G29-H29 -> 6023.8
... A264: 46174 | B264: 2606 | C264: 2193.8 | D264: =E264-F264 -> 611.5 | E264: 1406 | F264: 794.5 | G264: =SUM(C253:C264) -> 22481.1 | H264: =SUM(D253:D264) -> 9951.3 | I264: =G264-H264 -> 12529.8

Sheet Current account
BI1: 4Q 2022 | BJ1: 1Q 2023 | BK1: 2Q 2023 | BL1: 3Q 2023 | BM1: 4Q 2023 | BN1: 1Q 2024 | BO1: 2Q 2024 | BP1: 3Q 2024 | BQ1: 4Q 2024 | BR1: 1Q 2025 | BS1: 2Q 2025 | BT1: 3Q 2025 | BU1: 4Q 2025 | BV1: 1Q 2026
J2: 40238 | K2: 40330 | L2: 40422 | M2: 40513 | N2: 40603 | O2: 40695 | P2: 40787 | Q2: 40878 | R2: 40969 | S2: 41061 | T2: 41153 | U2: 41244 | V2: 41334 | W2: 41426 | X2: 41518 | Y2: 41609 | Z2: 41699 | AA2: 41791 | AB2: 41883 | AC2: 41974 | AD2: 42064 | AE2: 42156 | AF2: 42248 | AG2: 42339 | AH2: 42430 | AI2: 42522 | AJ2: 42614 | AK2: 42705 | AL2: 42795 | AM2: 42887 | AN2: 42979 | AO2: 43070 | AP2: 43160 | AQ2: 43252 | AR2: 43344 | AS2: 43435 | AT2: 43525 | AU2: 43617 | AV2: 43709 | AW2: 43800 | AX2: 43891 | AY2: 43983 | AZ2: 44075 | BA2: 44166 | BB2: 44256 | BC2: 44348 | BD2: 44440 | BE2: 44531 | BF2: 44621 | BG2: 44713 | BH2: 44805 | BI2: 44896 | BJ2: 44986 | BK2: 45078 | BL2: 45170 | BM2: 45261 | BN2: 45352 | BO2: 45444 | BP2: 45536 | BQ2: 45627 | BR2: 45717 | BS2: 45809 | BT2: 45901 | BU2: 45992 | BV2: 46082
D3: 1101 !Q NA_ | E3: .DESC | F3: .T1 | G3: .SOURCE | H3: .AGG | I3: .DATA_TYPE | J3: 101 | K3: 102 | L3: 103 | M3: 104 | N3: 111 | O3: 112 | P3: 113 | Q3: 114 | R3: 121 | S3: 122 | T3: 123 | U3: 124 | V3: 131 | W3: 132 | X3: 133 | Y3: 134 | Z3: 141 | AA3: 142 | AB3: 143 | AC3: 144 | AD3: 151 | AE3: 152 | AF3: 153 | AG3: 154 | AH3: 161 | AI3: 162 | AJ3: 163 | AK3: 164 | AL3: 171 | AM3: 172 | AN3: 173 | AO3: 174 | AP3: 181 | AQ3: 182 | AR3: 183 | AS3: 184 | AT3: 191 | AU3: 192 | AV3: 193 | AW3: 194 | AX3: 201 | AY3: 202 | AZ3: 203 | BA3: 204 | BB3: 211 | BC3: 212 | BD3: 213 | BE3: 214 | BF3: 221 | BG3: 222 | BH3: 223 | BI3: 224 | BJ3: 231 | BK3: 232 | BL3: 233 | BM3: 234 | BN3: 241 | BO3: 242 | BP3: 243 | BQ3: 244 | BR3: 251 | BS3: 252 | BT3: 253 | BU3: 254 | BV3: 261
C4: CAB | D4: N213AC@EMERGELA | E4: Argentina: Balance of Payments: Current Account Balance (NSA, Mil.US$) | F4: Q1-1992 | G4: INDEC | H4: Sum | I4: US$ | J4: -1633 | K4: 2101 | L4: -529 | M4: -1563 | N4: -2242 | O4: 509 | P4: -1516 | Q4: -2091 | R4: -1782 | S4: 499 | T4: 66 | U4: -921 | V4: -3886 | W4: -326 | X4: -3022 | Y4: -5891 | Z4: -6048 | AA4: 646 | AB4: -1840 | AC4: -1938 | AD4: -5544 | AE4: -2469 | AF4: -4508 | AG4: -5101 | AH4: -4897 | AI4: -2931 | AJ4: -2967 | AK4: -4311 | AL4: -7235 | AM4: -6605 | AN4: -8149 | AO4: -9163 | AP4: -9396 | AQ4: -8434 | AR4: -7359 | AS4: -1894 | AT4: -3434 | AU4: -1812 | AV4: -808 | AW4: 2561 | AX4: 117 | AY4: 2863 | AZ4: 1150 | BA4: -1442 | BB4: 395 | BC4: 2547 | BD4: 3349 | BE4: 334 | BF4: -1243 | BG4: -953 | BH4: -3606 | BI4: 1837 | BJ4: -5874 | BK4: -6820 | BL4: -6401 | BM4: -3259 | BN4: 58 | BO4: 3503 | BP4: 625 | BQ4: 1705 | BR4: -5158 | BS4: -2452 | BT4: -2100 | BU4: 1922 | BV4: -1651
C5: Merchandise | D5: N213ACG@EMERGELA | E5: Argentina: Balance of Payments: Goods (NSA, Mil.US$) | F5: Q1-1986 | G5: INDEC | H5: Sum | I5: US$ | J5: 2521 | K5: 5937 | L5: 3532 | M5: 2157 | N5: 2083 | O5: 4900 | P5: 2810 | Q5: 2559 | R5: 3047 | S5: 4601 | T5: 4245 | U5: 3147 | V5: 1012 | W5: 3780 | X5: 1363 | Y5: -1519 | Z5: -2017 | AA5: 4303 | AB5: 1850 | AC5: 1406 | AD5: -866 | AE5: 1463 | AF5: -281 | AG5: -1101 | AH5: 176 | AI5: 1677 | AJ5: 1826 | AK5: 736 | AL5: -620 | AM5: -712 | AN5: -1679 | AO5: -2435 | AP5: -1665 | AQ5: -1696 | AR5: -746 | AS5: 3364 | AT5: 2550 | AU5: 4223 | AV5: 4471 | AW5: 6990 | AX5: 3926 | AY5: 5341 | AZ5: 4069 | BA5: 1295 | BB5: 3241 | BC5: 5168 | BD5: 6659 | BE5: 3627 | BF5: 2778 | BG5: 3214 | BH5: 925 | BI5: 5500 | BJ5: -312 | BK5: -2099 | BL5: -1284 | BM5: 937 | BN5: 5070 | BO5: 7109 | BP5: 5306 | BQ5: 4919 | BR5: 2060 | BS5: 2668 | BT5: 4348 | BU5: 6283 | BV5: 6339
C6: Services | D6: N213ACS@EMERGELA | E6: Argentina: Balance of Payments: Services (NSA, Mil.US$) | F6: Q1-1992 | G6: INDEC | H6: Sum | I6: US$ | J6: -571 | K6: -564 | L6: -534 | M6: -135 | N6: -852 | O6: -782 | P6: -883 | Q6: -636 | R6: -1223 | S6: -1029 | T6: -1016 | U6: -829 | V6: -1730 | W6: -1277 | X6: -1354 | Y6: -968 | Z6: -1551 | AA6: -1195 | AB6: -1121 | AC6: -775 | AD6: -1536 | AE6: -1247 | AF6: -1544 | AG6: -1489 | AH6: -2498 | AI6: -1927 | AJ6: -2225 | AK6: -1801 | AL6: -3061 | AM6: -2069 | AN6: -2549 | AO6: -2017 | AP6: -3397 | AQ6: -2537 | AR6: -1953 | AS6: -1049 | AT6: -1710 | AU6: -1291 | AV6: -1285 | AW6: -557 | AX6: -986 | AY6: -295 | AZ6: -602 | BA6: -654 | BB6: -659 | BC6: -641 | BD6: -1028 | BE6: -1373 | BF6: -1898 | BG6: -1781 | BH6: -1988 | BI6: -1108 | BJ6: -2317 | BK6: -1546 | BL6: -1638 | BM6: -875 | BN6: -1368 | BO6: -1054 | BP6: -1545 | BQ6: -971 | BR6: -4560 | BS6: -2433 | BT6: -2679 | BU6: -1930 | BV6: -4028
C7: Income | D7: N213ACY@EMERGELA | E7: Argentina: Balance of Payments: Primary Income (NSA, Mil.US$) | F7: Q1-1994 | G7: INDEC | H7: Sum | I7: US$ | J7: -3723 | K7: -3486 | L7: -3650 | M7: -3689 | N7: -3498 | O7: -3766 | P7: -3655 | Q7: -4154 | R7: -3756 | S7: -3271 | T7: -3329 | U7: -3397 | V7: -3343 | W7: -3281 | X7: -3263 | Y7: -3279 | Z7: -2783 | AA7: -2985 | AB7: -2992 | AC7: -2855 | AD7: -3223 | AE7: -3088 | AF7: -2886 | AG7: -2907 | AH7: -2895 | AI7: -2987 | AJ7: -2863 | AK7: -3448 | AL7: -3778 | AM7: -4033 | AN7: -3843 | AO7: -4726 | AP7: -4490 | AQ7: -4654 | AR7: -4898 | AS7: -4608 | AT7: -4558 | AU7: -4840 | AV7: -4219 | AW7: -4115 | AX7: -3088 | AY7: -2574 | AZ7: -2592 | BA7: -2251 | BB7: -2503 | BC7: -2414 | BD7: -2607 | BE7: -2249 | BF7: -2571 | BG7: -2972 | BH7: -2969 | BI7: -3065 | BJ7: -3719 | BK7: -3808 | BL7: -3967 | BM7: -3808 | BN7: -4140 | BO7: -3329 | BP7: -3503 | BQ7: -2848 | BR7: -3018 | BS7: -3566 | BT7: -4276 | BU7: -3219 | BV7: -4676
C8: Transfers | D8: N213ACT@EMERGELA | E8: Argentina: Balance of Payments: Secondary Income (NSA, Mil.US$) | F8: Q1-1994 | G8: INDEC | H8: Sum | I8: US$ | J8: 140 | K8: 215 | L8: 122 | M8: 104 | N8: 25 | O8: 158 | P8: 211 | Q8: 141 | R8: 150 | S8: 198 | T8: 167 | U8: 157 | V8: 176 | W8: 452 | X8: 231 | Y8: -125 | Z8: 303 | AA8: 523 | AB8: 423 | AC8: 286 | AD8: 81 | AE8: 403 | AF8: 203 | AG8: 396 | AH8: 321 | AI8: 306 | AJ8: 294 | AK8: 203 | AL8: 224 | AM8: 209 | AN8: -77 | AO8: 15 | AP8: 156 | AQ8: 452 | AR8: 238 | AS8: 399 | AT8: 285 | AU8: 96 | AV8: 224 | AW8: 244 | AX8: 265 | AY8: 392 | AZ8: 275 | BA8: 167 | BB8: 316 | BC8: 433 | BD8: 324 | BE8: 328 | BF8: 448 | BG8: 587 | BH8: 426 | BI8: 510 | BJ8: 473 | BK8: 633 | BL8: 488 | BM8: 486 | BN8: 496 | BO8: 776 | BP8: 367 | BQ8: 606 | BR8: 360 | BS8: 878 | BT8: 506 | BU8: 788 | BV8: 714
BD10: =BD11-BD12 -> -1145
C11: K account | D11: N213AK@EMERGELA | E11: Argentina: Balance of Payments: Capital Account (NSA, Mil.US$) | F11: Q1-2006 | G11: INDEC | H11: Sum | I11: US$ | J11: 17 | K11: 4 | L11: 55 | M11: 3 | N11: 16 | O11: 1 | P11: 45 | Q11: 1 | R11: 1 | S11: 22 | T11: 28 | U11: -4 | V11: 1 | W11: 0 | X11: 33 | Y11: -1 | Z11: 2 | AA11: 16 | AB11: 40 | AC11: -1 | AD11: 10 | AE11: 3 | AF11: 39 | AG11: 1 | AH11: 83 | AI11: 32 | AJ11: 109 | AK11: 141 | AL11: 45 | AM11: 44 | AN11: 79 | AO11: 6 | AP11: 24 | AQ11: 21 | AR11: 47 | AS11: 19 | AT11: 37 | AU11: 139 | AV11: 80 | AW11: 27 | AX11: 42 | AY11: 32 | AZ11: 40 | BA11: 50 | BB11: 46 | BC11: 94 | BD11: 70 | BE11: 43 | BF11: 34 | BG11: 27 | BH11: 81 | BI11: 49 | BJ11: 27 | BK11: 49 | BL11: 38 | BM11: 77 | BN11: 95 | BO11: 57 | BP11: 45 | BQ11: 81 | BR11: 59 | BS11: 172 | BT11: 137 | BU11: 86 | BV11: 63
C12: F. account | D12: N213AF@EMERGELA | E12: Argentina: Balance of Payments: Financial Account (NSA, Mil.US$) | F12: Q1-2006 | G12: INDEC | H12: Sum | I12: US$ | J12: -1661 | K12: 937 | L12: -817 | M12: -2262 | N12: -1876 | O12: 168 | P12: -3477 | Q12: -67 | R12: -2005 | S12: 259 | T12: -519 | U12: -523 | V12: -4668 | W12: -734 | X12: -4239 | Y12: -6524 | Z12: -4503 | AA12: 432 | AB12: -2167 | AC12: -3083 | AD12: -5612 | AE12: -2498 | AF12: -5404 | AG12: -4984 | AH12: -4731 | AI12: -3104 | AJ12: -4656 | AK12: -1473 | AL12: -6224 | AM12: -6971 | AN12: -8878 | AO12: -9200 | AP12: -9547 | AQ12: -9002 | AR12: -7853 | AS12: -1635 | AT12: -3639 | AU12: -2373 | AV12: -1538 | AW12: 2431 | AX12: -512 | AY12: 3825 | AZ12: -376 | BA12: -1576 | BB12: 1410 | BC12: 1305 | BD12: 1215 | BE12: 572 | BF12: -1739 | BG12: -3118 | BH12: -3456 | BI12: 876 | BJ12: -7538 | BK12: -7003 | BL12: -7307 | BM12: -4066 | BN12: -833 | BO12: 2578 | BP12: -814 | BQ12: 1388 | BR12: -7189 | BS12: -3348 | BT12: -3658 | BU12: 2193 | BV12: -2398
C13: Net FDI | D13: N213AFI@EMERGELA | E13: Argentina: BOP: Fin Acct, Total Direct Investment (NSA, Mil.US$) | F13: Q1-2006 | G13: INDEC | H13: Sum | I13: US$ | J13: -3159 | K13: -1899 | L13: -2906 | M13: -2404 | N13: -3214 | O13: -632 | P13: -1390 | Q13: -4116 | R13: -4154 | S13: -3612 | T13: -3106 | U13: -3397 | V13: -1941 | W13: -2920 | X13: -2513 | Y13: -1557 | Z13: -39 | AA13: 1744 | AB13: -2055 | AC13: -2795 | AD13: -3273 | AE13: -3175 | AF13: -2450 | AG13: -1985 | AH13: -1852 | AI13: 407 | AJ13: -703 | AK13: 674 | AL13: -3174 | AM13: -2021 | AN13: -3043 | AO13: -2124 | AP13: -2471 | AQ13: -2211 | AR13: -2656 | AS13: -2654 | AT13: -1969 | AU13: -381 | AV13: -1231 | AW13: -1546 | AX13: -1594 | AY13: 387 | AZ13: -1250 | BA13: -1250 | BB13: -2214 | BC13: -1583 | BD13: -339 | BE13: -979 | BF13: -3055 | BG13: -4290 | BH13: -5421 | BI13: -349 | BJ13: -4006 | BK13: -5631 | BL13: -6798 | BM13: -6809 | BN13: -5022 | BO13: -1670 | BP13: -3117 | BQ13: 218 | BR13: -313 | BS13: -1984 | BT13: -4302 | BU13: 4981 | BV13: -1291
C14: P. flows | D14: N213AFP@EMERGELA | E14: Argentina: BOP: Fin Accnt: Portfolio Investment (NSA, Mil.US$) | F14: Q1-2006 | G14: INDEC | H14: Sum | I14: US$ | J14: -211 | K14: -1083 | L14: -309 | M14: -1659 | N14: -695 | O14: -85 | P14: -143 | Q14: 780 | R14: -1906 | S14: 426 | T14: 1401 | U14: 229 | V14: -278 | W14: 945 | X14: 190 | Y14: -1289 | Z14: -1164 | AA14: 4127 | AB14: -445 | AC14: -179 | AD14: -1185 | AE14: -1308 | AF14: -414 | AG14: 2470 | AH14: -4678 | AI14: -10691 | AJ14: -7707 | AK14: -12178 | AL14: -14043 | AM14: -3760 | AN14: -7208 | AO14: -10910 | AP14: -12953 | AQ14: 1874 | AR14: 1902 | AS14: 2253 | AT14: 362 | AU14: 6026 | AV14: -111 | AW14: 831 | AX14: -676 | AY14: 1259 | AZ14: 2268 | BA14: -1281 | BB14: 1892 | BC14: 1246 | BD14: 986 | BE14: 818 | BF14: 2333 | BG14: 1854 | BH14: 2057 | BI14: 1219 | BJ14: 3001 | BK14: 966 | BL14: 2422 | BM14: 520 | BN14: -2755 | BO14: -583 | BP14: 4136 | BQ14: 3331 | BR14: 3251 | BS14: -1976 | BT14: 3471 | BU14: -4468 | BV14: 657
C15: F. derivatives | D15: N213AFV@EMERGELA | E15: Argentina: BOP: Fin Accnt: Financial Derivatives (NSA, Mil.US$) | F15: Q1-2006 | G15: INDEC | H15: Sum | I15: US$ | J15: 23 | K15: 84 | L15: -799 | M15: -21 | N15: 36 | O15: 161 | P15: 33 | Q15: 2126 | R15: 9 | S15: 1 | T15: 26 | U15: 2873 | V15: -12 | W15: -14 | X15: 2 | Y15: -7 | Z15: 36 | AA15: -163 | AB15: -34 | AC15: -6 | AD15: -12 | AE15: -5 | AF15: -1 | AG15: -7 | AH15: 32 | AI15: 366 | AJ15: -32 | AK15: -144 | AL15: -140 | AM15: 7 | AN15: 11 | AO15: 26 | AP15: -27 | AQ15: -4 | AR15: 30 | AS15: -32 | AT15: -24 | AU15: -45 | AV15: 33 | AW15: 11 | AX15: 0 | AY15: 3 | AZ15: -1 | BA15: 7 | BB15: -3 | BC15: 0 | BD15: 0 | BE15: -13 | BF15: 1 | BG15: 2 | BH15: -5 | BI15: 6 | BJ15: 3 | BK15: -2 | BL15: -2 | BM15: 10 | BN15: 1 | BO15: -6 | BP15: 18 | BQ15: 6 | BR15: -9 | BS15: -6 | BT15: -21 | BU15: 39 | BV15: -10
C16: O. investments | D16: N213AFO@EMERGELA | E16: Argentina: BOP: Financial Account, Other Investments (NSA, Mil.US$) | F16: Q1-2006 | G16: INDEC | H16: Sum | I16: US$ | J16: 1990 | K16: 1730 | L16: 1919 | M16: 744 | N16: 3156 | O16: 498 | P16: 1177 | Q16: 3164 | R16: 3376 | S16: 4143 | T16: 2886 | U16: 1322 | V16: 148 | W16: 3966 | X16: 668 | Y16: 274 | Z16: 397 | AA16: -7460 | AB16: 1350 | AC16: -3829 | AD16: -1481 | AE16: -309 | AF16: -2313 | AG16: 1856 | AH16: -1778 | AI16: 5741 | AJ16: 4356 | AK16: -87 | AL16: 194 | AM16: 1607 | AN16: -523 | AO16: -728 | AP16: -250 | AQ16: -9402 | AR16: 5157 | AS16: -17872 | AT16: -1964 | AU16: -6200 | AV16: 14594 | AW16: 7868 | AX16: 2847 | AY16: 2968 | AZ16: 1643 | BA16: 3758 | BB16: 1055 | BC16: -760 | BD16: 116 | BE16: 4386 | BF16: -4210 | BG16: -1967 | BH16: 3438 | BI16: -5968 | BJ16: -532 | BK16: 7721 | BL16: -2041 | BM16: 6937 | BN16: 2864 | BO16: 3143 | BP16: 1119 | BQ16: -5459 | BR16: -4490 | BS16: -13655 | BT16: -2351 | BU16: 2609 | BV16: -1764
C17: Change reserves | D17: N213AFRA@EMERGELA | E17: Argentina: Balance of Payments: Change in Intl Reserves (NSA, Mil.US$) | F17: Q1-2006 | G17: INDEC | H17: Sum | I17: US$ | J17: -304 | K17: 2104 | L17: 1279 | M17: 1078 | N17: -1159 | O17: 226 | P17: -3154 | Q17: -2021 | R17: 670 | S17: -699 | T17: -1726 | U17: -1549 | V17: -2583 | W17: -2711 | X17: -2585 | Y17: -3945 | Z17: -3733 | AA17: 2184 | AB17: -983 | AC17: 3727 | AD17: 339 | AE17: 2300 | AF17: -227 | AG17: -7318 | AH17: 3545 | AI17: 1074 | AJ17: -569 | AK17: 10262 | AL17: 10938 | AM17: -2804 | AN17: 1885 | AO17: 4537 | AP17: 6153 | AQ17: 741 | AR17: -12287 | AS17: 16670 | AT17: -45 | AU17: -1773 | AV17: -14823 | AW17: -4733 | AX17: -1089 | AY17: -793 | AZ17: -3036 | BA17: -2809 | BB17: 680 | BC17: 2403 | BD17: 452 | BE17: -3640 | BF17: 3192 | BG17: 1283 | BH17: -3525 | BI17: 5969 | BJ17: -6004 | BK17: -10058 | BL17: -889 | BM17: -4724 | BN17: 4078 | BO17: 1694 | BP17: -2971 | BQ17: 3292 | BR17: -5628 | BS17: 14271 | BT17: -454 | BU17: -968 | BV17: 11
C19: Errors and omission | D19: N213AERR@EMERGELA | E19: Argentina: Balance of Payments: Errors and Omissions (NSA, Mil.US$) | F19: Q1-2006 | G19: INDEC | H19: Sum | I19: US$ | J19: -46 | K19: -1168 | L19: -342 | M19: -702 | N19: 349 | O19: -342 | P19: -2006 | Q19: 2023 | R19: -223 | S19: -262 | T19: -614 | U19: 402 | V19: -783 | W19: -409 | X19: -1249 | Y19: -633 | Z19: 1543 | AA19: -231 | AB19: -367 | AC19: -1144 | AD19: -77 | AE19: -32 | AF19: -935 | AG19: 116 | AH19: 82 | AI19: -205 | AJ19: -1798 | AK19: 2697 | AL19: 965 | AM19: -409 | AN19: -809 | AO19: -42 | AP19: -175 | AQ19: -588 | AR19: -541 | AS19: 241 | AT19: -243 | AU19: -700 | AV19: -810 | AW19: -158 | AX19: -671 | AY19: 930 | AZ19: -1566 | BA19: -184 | BB19: 968 | BC19: -1336 | BD19: -2204 | BE19: 195 | BF19: -531 | BG19: -2193 | BH19: 68 | BI19: -1010 | BJ19: -1690 | BK19: -232 | BL19: -944 | BM19: -885 | BN19: -986 | BO19: -981 | BP19: -1485 | BQ19: -398 | BR19: -2091 | BS19: -1068 | BT19: -1694 | BU19: 184 | BV19: -811
C21: GDP | D21: N213NGPD@EMERGELA | E21: Argentina: GDP at Current Prices & Exchange Rates(NSA, Bil.US$) | F21: Q1-1993 | G21: INDEC/H | H21: Sum | I21: US$ | J21: 92.498 | K21: 108.599 | L21: 109.191 | M21: 115.847 | N21: 118.227 | O21: 137.686 | P21: 135.671 | Q21: 138.032 | R21: 135.5 | S21: 149.417 | T21: 147.097 | U21: 148.837 | V21: 144.477 | W21: 162.05 | X21: 154.289 | Y21: 152.224 | Z21: 129.177 | AA21: 146.844 | AB21: 141.936 | AC21: 148.064 | AD21: 147.289 | AE21: 166.789 | AF21: 168.968 | AG21: 161.183 | AH21: 121.31 | AI21: 147.808 | AJ21: 142.667 | AK21: 145.35 | AL21: 147.4 | AM21: 167.762 | AN21: 160.762 | AO21: 166.965 | AP21: 157.004 | AQ21: 153.567 | AR21: 119.255 | AS21: 113.529 | AT21: 112.069 | AU21: 121.039 | AV21: 110.536 | AW21: 106.315 | AX21: 101.797 | AY21: 88.88 | AZ21: 94.01 | BA21: 100.925 | BB21: 103.954 | BC21: 123.279 | BD21: 122.148 | BE21: 135.204 | BF21: 141.679 | BG21: 166.899 | BH21: 161.877 | BI21: 160.607 | BJ21: 158.949 | BK21: 172.575 | BL21: 166.808 | BM21: 158.881 | BN21: 129.61 | BO21: 158.098 | BP21: 169.36 | BQ21: 177.162 | BR21: 172.832 | BS21: 182.106 | BT21: 167.101 | BU21: 165.419 | BV21: 172.274
C23: CAB | M23: =SUM(J4:M4) -> -1624 | N23: =SUM(K4:N4) -> -2233 | O23: =SUM(L4:O4) -> -3825 | P23: =SUM(M4:P4) -> -4812 | Q23: =SUM(N4:Q4) -> -5340 | R23: =SUM(O4:R4) -> -4880 | S23: =SUM(P4:S4) -> -4890 | T23: =SUM(Q4:T4) -> -3308 | ... BV23: =SUM(BS4:BV4) -> -4281
C24: Merchandise | M24: =SUM(J5:M5) -> 14147 | N24: =SUM(K5:N5) -> 13709 | O24: =SUM(L5:O5) -> 12672 | P24: =SUM(M5:P5) -> 11950 | Q24: =SUM(N5:Q5) -> 12352 | R24: =SUM(O5:R5) -> 13316 | S24: =SUM(P5:S5) -> 13017 | T24: =SUM(Q5:T5) -> 14452 | ... BV24: =SUM(BS5:BV5) -> 19638
C25: Services | M25: =SUM(J6:M6) -> -1804 | N25: =SUM(K6:N6) -> -2085 | O25: =SUM(L6:O6) -> -2303 | P25: =SUM(M6:P6) -> -2652 | Q25: =SUM(N6:Q6) -> -3153 | R25: =SUM(O6:R6) -> -3524 | S25: =SUM(P6:S6) -> -3771 | T25: =SUM(Q6:T6) -> -3904 | ... BV25: =SUM(BS6:BV6) -> -11070
C26: Income | M26: =SUM(J7:M7) -> -14548 | N26: =SUM(K7:N7) -> -14323 | O26: =SUM(L7:O7) -> -14603 | P26: =SUM(M7:P7) -> -14608 | Q26: =SUM(N7:Q7) -> -15073 | R26: =SUM(O7:R7) -> -15331 | S26: =SUM(P7:S7) -> -14836 | T26: =SUM(Q7:T7) -> -14510 | ... BV26: =SUM(BS7:BV7) -> -15737
C27: Transfers | M27: =SUM(J8:M8) -> 581 | N27: =SUM(K8:N8) -> 466 | O27: =SUM(L8:O8) -> 409 | P27: =SUM(M8:P8) -> 498 | Q27: =SUM(N8:Q8) -> 535 | R27: =SUM(O8:R8) -> 660 | S27: =SUM(P8:S8) -> 700 | T27: =SUM(Q8:T8) -> 656 | ... BV27: =SUM(BS8:BV8) -> 2886
C30: K account | M30: =SUM(J11:M11) -> 79 | N30: =SUM(K11:N11) -> 78 | O30: =SUM(L11:O11) -> 75 | P30: =SUM(M11:P11) -> 65 | Q30: =SUM(N11:Q11) -> 63 | R30: =SUM(O11:R11) -> 48 | S30: =SUM(P11:S11) -> 69 | T30: =SUM(Q11:T11) -> 52 | ... BV30: =SUM(BS11:BV11) -> 458
C31: F. account | M31: =-SUM(J12:M12) -> 3803 | N31: =-SUM(K12:N12) -> 4018 | O31: =-SUM(L12:O12) -> 4787 | P31: =-SUM(M12:P12) -> 7447 | Q31: =-SUM(N12:Q12) -> 5252 | R31: =-SUM(O12:R12) -> 5381 | S31: =-SUM(P12:S12) -> 5290 | T31: =-SUM(Q12:T12) -> 2332 | ... BV31: =-SUM(BS12:BV12) -> 7211
C32: Net FDI | M32: =-SUM(J13:M13) -> 10368 | N32: =-SUM(K13:N13) -> 10423 | O32: =-SUM(L13:O13) -> 9156 | P32: =-SUM(M13:P13) -> 7640 | Q32: =-SUM(N13:Q13) -> 9352 | R32: =-SUM(O13:R13) -> 10292 | S32: =-SUM(P13:S13) -> 13272 | T32: =-SUM(Q13:T13) -> 14988 | ... BV32: =-SUM(BS13:BV13) -> 2596
C33: P. flows | M33: =-SUM(J14:M14) -> 3262 | N33: =-SUM(K14:N14) -> 3746 | O33: =-SUM(L14:O14) -> 2748 | P33: =-SUM(M14:P14) -> 2582 | Q33: =-SUM(N14:Q14) -> 143 | R33: =-SUM(O14:R14) -> 1354 | S33: =-SUM(P14:S14) -> 843 | T33: =-SUM(Q14:T14) -> -701 | ... BV33: =-SUM(BS14:BV14) -> 2316
C34: F. derivatives | M34: =-SUM(J15:M15) -> 713 | N34: =-SUM(K15:N15) -> 700 | O34: =-SUM(L15:O15) -> 623 | P34: =-SUM(M15:P15) -> -209 | Q34: =-SUM(N15:Q15) -> -2356 | R34: =-SUM(O15:R15) -> -2329 | S34: =-SUM(P15:S15) -> -2169 | T34: =-SUM(Q15:T15) -> -2162 | ... BV34: =-SUM(BS15:BV15) -> -2
C35: O. investments | M35: =-SUM(J16:M16) -> -6383 | N35: =-SUM(K16:N16) -> -7549 | O35: =-SUM(L16:O16) -> -6317 | P35: =-SUM(M16:P16) -> -5575 | Q35: =-SUM(N16:Q16) -> -7995 | R35: =-SUM(O16:R16) -> -8215 | S35: =-SUM(P16:S16) -> -11860 | T35: =-SUM(Q16:T16) -> -13569 | ... BV35: =-SUM(BS16:BV16) -> 15161
C36: Change reserves | M36: =-SUM(J17:M17) -> -4157 | N36: =-SUM(K17:N17) -> -3302 | O36: =-SUM(L17:O17) -> -1424 | P36: =-SUM(M17:P17) -> 3009 | Q36: =-SUM(N17:Q17) -> 6108 | R36: =-SUM(O17:R17) -> 4279 | S36: =-SUM(P17:S17) -> 5204 | T36: =-SUM(Q17:T17) -> 3776 | ... BV36: =-SUM(BS17:BV17) -> -12860
C38: Errors and omission | M38: =SUM(J19:M19) -> -2258 | N38: =SUM(K19:N19) -> -1863 | O38: =SUM(L19:O19) -> -1037 | P38: =SUM(M19:P19) -> -2701 | Q38: =SUM(N19:Q19) -> 24 | R38: =SUM(O19:R19) -> -548 | S38: =SUM(P19:S19) -> -468 | T38: =SUM(Q19:T19) -> 924 | ... BV38: =SUM(BS19:BV19) -> -3389
C40: GDP | M40: =SUM(J21:M21) -> 426.135 | N40: =SUM(K21:N21) -> 451.864 | O40: =SUM(L21:O21) -> 480.951 | P40: =SUM(M21:P21) -> 507.431 | Q40: =SUM(N21:Q21) -> 529.616 | R40: =SUM(O21:R21) -> 546.889 | S40: =SUM(P21:S21) -> 558.62 | T40: =SUM(Q21:T21) -> 570.046 | ... BV40: =SUM(BS21:BV21) -> 686.9
C43: % of GDP
C44: CAB | M44: =(M23/1000)/M$40*100 -> -0.38109989 | N44: =(N23/1000)/N$40*100 -> -0.49417524 | O44: =(O23/1000)/O$40*100 -> -0.79529931 | P44: =(P23/1000)/P$40*100 -> -0.94830627 | Q44: =(Q23/1000)/Q$40*100 -> -1.0082777 | R44: =(R23/1000)/R$40*100 -> -0.89232001 | S44: =(S23/1000)/S$40*100 -> -0.87537145 | T44: =(T23/1000)/T$40*100 -> -0.58030405 | ... BV44: =(BV23/1000)/BV$40*100 -> -0.62323482
C45: Merchandise | M45: =(M24/1000)/M$40*100 -> 3.31984 | N45: =(N24/1000)/N$40*100 -> 3.0338774 | O45: =(O24/1000)/O$40*100 -> 2.6347798 | P45: =(P24/1000)/P$40*100 -> 2.355 | Q45: =(Q24/1000)/Q$40*100 -> 2.3322558 | R45: =(R24/1000)/R$40*100 -> 2.4348634 | S45: =(S24/1000)/S$40*100 -> 2.3302066 | T45: =(T24/1000)/T$40*100 -> 2.535234 | ... BV45: =(BV24/1000)/BV$40*100 -> 2.8589314
C46: Services | M46: =(M25/1000)/M$40*100 -> -0.42334002 | N46: =(N25/1000)/N$40*100 -> -0.46142202 | O46: =(O25/1000)/O$40*100 -> -0.47884296 | P46: =(P25/1000)/P$40*100 -> -0.52263263 | Q46: =(Q25/1000)/Q$40*100 -> -0.595337 | R46: =(R25/1000)/R$40*100 -> -0.64437208 | S46: =(S25/1000)/S$40*100 -> -0.67505639 | T46: =(T25/1000)/T$40*100 -> -0.68485701 | ... BV46: =(BV25/1000)/BV$40*100 -> -1.6115883
C47: Income | M47: =(M26/1000)/M$40*100 -> -3.4139416 | N47: =(N26/1000)/N$40*100 -> -3.169759 | O47: =(O26/1000)/O$40*100 -> -3.036276 | P47: =(P26/1000)/P$40*100 -> -2.8788151 | Q47: =(Q26/1000)/Q$40*100 -> -2.8460243 | R47: =(R26/1000)/R$40*100 -> -2.8033111 | S47: =(S26/1000)/S$40*100 -> -2.6558304 | T47: =(T26/1000)/T$40*100 -> -2.5454086 | ... BV47: =(BV26/1000)/BV$40*100 -> -2.2910176
C48: Transfers | M48: =(M27/1000)/M$40*100 -> 0.13634177 | N48: =(N27/1000)/N$40*100 -> 0.10312837 | O48: =(O27/1000)/O$40*100 -> 0.085039848 | P48: =(P27/1000)/P$40*100 -> 0.098141422 | Q48: =(Q27/1000)/Q$40*100 -> 0.10101659 | R48: =(R27/1000)/R$40*100 -> 0.12068262 | S48: =(S27/1000)/S$40*100 -> 0.1253088 | T48: =(T27/1000)/T$40*100 -> 0.11507843 | ... BV48: =(BV27/1000)/BV$40*100 -> 0.42014849
C51: K account | M51: =(M30/1000)/M$40*100 -> 0.018538726 | N51: =(N30/1000)/N$40*100 -> 0.017261831 | O51: =(O30/1000)/O$40*100 -> 0.015594104 | P51: =(P30/1000)/P$40*100 -> 0.012809623 | Q51: =(Q30/1000)/Q$40*100 -> 0.011895411 | R51: =(R30/1000)/R$40*100 -> 0.0087769182 | S51: =(S30/1000)/S$40*100 -> 0.012351867 | T51: =(T30/1000)/T$40*100 -> 0.0091220709 | ... BV51: =(BV30/1000)/BV$40*100 -> 0.066676372
C52: F. account | M52: =-(M31/1000)/M$40*100 -> -0.89244019 | N52: =-(N31/1000)/N$40*100 -> -0.8892056 | O52: =-(O31/1000)/O$40*100 -> -0.99531969 | P52: =-(P31/1000)/P$40*100 -> -1.4675887 | Q52: =-(Q31/1000)/Q$40*100 -> -0.99166188 | R52: =-(R31/1000)/R$40*100 -> -0.9839291 | S52: =-(S31/1000)/S$40*100 -> -0.94697648 | T52: =-(T31/1000)/T$40*100 -> -0.40908979 | ... AH52: =-(AH31/1000)/AH$40*100 -> -2.8494945 | AI52: =(AI31/1000)/AI$40*100 -> 3.0408715 | AJ52: =(AJ31/1000)/AJ$40*100 -> 3.0499085 | AK52: =(AK31/1000)/AK$40*100 -> 2.5063943 | AL52: =(AL31/1000)/AL$40*100 -> 2.6502636 | AM52: =(AM31/1000)/AM$40*100 -> 3.2036924 | AN52: =(AN31/1000)/AN$40*100 -> 3.7899542 | AO52: =(AO31/1000)/AO$40*100 -> 4.8644478 | AP52: =(AP31/1000)/AP$40*100 -> 5.3021258 | ... BV52: =(BV31/1000)/BV$40*100 -> 1.0497889
...

Sheet Net reserves
H1: 2012 | I1: 2013 | J1: 2014 | K1: 2015 | L1: 2016 | M1: 2017 | N1: 2018 | O1: 2019 | P1: 2020 | Q1: 2021 | R1: 2022 | S1: 2023
A2: Central bank gross FX reserves ($bn) | H2: =OFFSET($S$11,0,12*(H8-1),1,1)/1000 -> 43.29 | I2: =OFFSET($S$11,0,12*(I8-1),1,1)/1000 -> 30.599 | J2: =OFFSET($S$11,0,12*(J8-1),1,1)/1000 -> 31.407 | K2: =OFFSET($S$11,0,12*(K8-1),1,1)/1000 -> 25.563 | L2: =OFFSET($S$11,0,12*(L8-1),1,1)/1000 -> 39.308 | M2: =OFFSET($S$11,0,12*(M8-1),1,1)/1000 -> 55.055 | N2: =OFFSET($S$11,0,12*(N8-1),1,1)/1000 -> 65.786 | O2: =OFFSET($S$11,0,12*(O8-1),1,1)/1000 -> 44.848 | ... S2: =OFFSET($S$11,0,12*(S8-1),1,1)/1000 -> 23.073
A3: Central bank net FX reserves ($bn) | H3: =OFFSET($S$12,0,12*(H8-1),1,1)/1000 -> 33.858245 | I3: =OFFSET($S$12,0,12*(I8-1),1,1)/1000 -> 16.190752 | J3: =OFFSET($S$12,0,12*(J8-1),1,1)/1000 -> 17.017012 | K3: =OFFSET($S$12,0,12*(K8-1),1,1)/1000 -> 0.51824404 | L3: =OFFSET($S$12,0,12*(L8-1),1,1)/1000 -> 10.199107 | M3: =OFFSET($S$12,0,12*(M8-1),1,1)/1000 -> 27.697552 | N3: =OFFSET($S$12,0,12*(N8-1),1,1)/1000 -> 29.260467 | O3: =OFFSET($S$12,0,12*(O8-1),1,1)/1000 -> 13.370597 | ... S3: =OFFSET($S$12,0,12*(S8-1),1,1)/1000 -> -10.458519 | EW3: Word
A4: Central bank gross non-gold FX reserves ($bn) | H4: =OFFSET($S$16,0,12*(H8-1),1,1)/1000 -> 39.963529 | I4: =OFFSET($S$16,0,12*(I8-1),1,1)/1000 -> 28.209528 | J4: =OFFSET($S$16,0,12*(J8-1),1,1)/1000 -> 29.052215 | K4: =OFFSET($S$16,0,12*(K8-1),1,1)/1000 -> 23.456067 | L4: =OFFSET($S$16,0,12*(L8-1),1,1)/1000 -> 37.206251 | M4: =OFFSET($S$16,0,12*(M8-1),1,1)/1000 -> 52.756225 | N4: =OFFSET($S$16,0,12*(N8-1),1,1)/1000 -> 63.530377 | O4: =OFFSET($S$16,0,12*(O8-1),1,1)/1000 -> 42.163534 | ... S4: =OFFSET($S$16,0,12*(S8-1),1,1)/1000 -> 18.977127
A6: Repos | H6: =OFFSET($S$13,0,12*(H8-1),1,1)/1000 -> 0.931857 | I6: =OFFSET($S$13,0,12*(I8-1),1,1)/1000 -> 1.046064 | J6: =OFFSET($S$13,0,12*(J8-1),1,1)/1000 -> 3.539621 | K6: =OFFSET($S$13,0,12*(K8-1),1,1)/1000 -> 11.855968 | L6: =OFFSET($S$13,0,12*(L8-1),1,1)/1000 -> 11.356553 | M6: =OFFSET($S$13,0,12*(M8-1),1,1)/1000 -> 12.032361 | N6: =OFFSET($S$13,0,12*(N8-1),1,1)/1000 -> 19.978878 | O6: =OFFSET($S$13,0,12*(O8-1),1,1)/1000 -> 19.831922 | P6: =OFFSET($S$13,0,12*(P8-1),1,1)/1000 -> 21.676752
A8: Counters | H8: 1 | I8: 2 | J8: 3 | K8: 4 | L8: 5 | M8: 6 | N8: 7 | O8: 8 | P8: 9 | Q8: 10 | R8: 11 | S8: 12 | DT8: 45500
DT9: =DT8-DS11+DS12 -> 8639.3738 | DW9: =DT9-5000 -> 3639.3738
H10: 40909 | I10: 40940 | J10: 40969 | K10: 41000 | L10: 41030 | M10: 41061 | N10: 41091 | O10: 41122 | P10: 41153 | Q10: 41183 | R10: 41214 | S10: 41244 | T10: 41275 | U10: 41306 | V10: 41334 | W10: 41365 | X10: 41395 | Y10: 41426 | Z10: 41456 | AA10: 41487 | AB10: 41518 | AC10: 41548 | AD10: 41579 | AE10: 41609 | AF10: 41640 | AG10: 41671 | AH10: 41699 | AI10: 41730 | AJ10: 41760 | AK10: 41791 | AL10: 41821 | AM10: 41852 | AN10: 41883 | AO10: 41913 | AP10: 41944 | AQ10: 41974 | AR10: 42005 | AS10: 42036 | AT10: 42064 | AU10: 42095 | AV10: 42125 | AW10: 42156 | AX10: 42186 | AY10: 42217 | AZ10: 42248 | BA10: 42278 | BB10: 42309 | BC10: 42339 | BD10: 42370 | BE10: 42401 | BF10: 42430 | BG10: 42461 | BH10: 42491 | BI10: 42522 | BJ10: 42552 | BK10: 42583 | BL10: 42614 | BM10: 42644 | BN10: 42675 | BO10: 42705 | BP10: 42736 | BQ10: 42767 | BR10: 42795 | BS10: 42826 | BT10: 42856 | BU10: 42887 | BV10: 42917 | BW10: 42948 | BX10: 42979 | BY10: 43009 | BZ10: 43040 | CA10: 43070 | CB10: 43101 | CC10: 43132 | CD10: 43160 | CE10: 43191 | CF10: 43221 | CG10: 43252 | CH10: 43282 | CI10: 43313 | CJ10: 43344 | CK10: 43374 | CL10: 43405 | CM10: 43435 | CN10: 43466 | CO10: 43497 | CP10: 43525 | CQ10: 43556 | CR10: 43586 | CS10: 43617 | CT10: 43647 | CU10: 43678 | CV10: 43709 | CW10: 43739 | CX10: 43770 | CY10: 43800 | CZ10: 43831 | DA10: 43862 | DB10: 43891 | DC10: 43922 | DD10: 43952 | DE10: 43983 | DF10: 44013 | DG10: 44044 | DH10: 44075 | DI10: 44105 | DJ10: 44136 | DK10: 44166 | DL10: 44197 | DM10: 44228 | DN10: 44256 | DO10: 44287 | DP10: 44317 | DQ10: 44348 | DR10: 44378 | DS10: 44409 | DT10: 44440 | DU10: 44470 | DV10: 44501 | DW10: 44531 | DX10: 44562 | DY10: 44593 | DZ10: 44621 | EA10: 44652 | EB10: 44682 | EC10: 44713 | ED10: 44743 | EE10: 44774 | EF10: 44805 | EG10: 44835 | EH10: 44866 | EI10: 44896 | EJ10: 44927 | EK10: 44958 | EL10: 44986 | EM10: 45017 | EN10: 45047 | EO10: 45078 | EP10: 45108 | EQ10: 45139 | ER10: 45170 | ES10: 45200 | ET10: 45231 | EU10: 45261 | EV10: 45292 | EW10: 45323 | EX10: 45352 | EY10: 45383 | EZ10: 45413 | FA10: 45444 | FB10: 45474 | FC10: 45505 | FD10: 45536 | FE10: 45566 | FF10: 45597 | FG10: 45627 | FH10: 45658 | FI10: 45689 | FJ10: 45717 | FK10: 45748 | FL10: 45778 | FM10: 45809 | FN10: 45839 | FO10: 45870 | FP10: 45901 | FQ10: 45931 | FR10: 45962 | FS10: 45992 | FT10: 46023 | FU10: 46054 | FV10: 46082 | FW10: 46113 | FX10: 46143 | FY10: 46174 | FZ10: 46204 | GA10: 46235
A11: Gross reserves | H11: =H21 -> 46594 | I11: =I21 -> 46668 | J11: =J21 -> 47291 | K11: =K21 -> 47844 | L11: =L21 -> 46978 | M11: =M21 -> 46348 | N11: =N21 -> 46818 | O11: =O21 -> 45152 | ... FY11: =FY21 -> 44870 | FZ11: 47500 | GA11: 49500
A12: Net reserves | H12: =H21-H13-H14 -> 38906.999 | I12: =I21-I13-I14 -> 39046.498 | J12: =J21-J13-J14 -> 39370.867 | K12: =K21-K13-K14 -> 40023.011 | L12: =L21-L13-L14 -> 39947.099 | M12: =M21-M13-M14 -> 40166.412 | N12: =N21-N13-N14 -> 40038.854 | O12: =O21-O13-O14 -> 37843.969 | ... Z12: =Z21-Z13-Z14 -> 27734.515 | AA12: =AA21-AA13-AA14-AA15 -> 24505.176 | AB12: =AB21-AB13-AB14-AB15 -> 22120.38 | AC12: =AC21-AC13-AC14-AC15 -> 20310.947 | AD12: =AD21-AD13-AD14-AD15 -> 17956.071 | AE12: =AE21-AE13-AE14-AE15 -> 16190.752 | AF12: =AF21-AF13-AF14-AF15 -> 13056.723 | AG12: =AG21-AG13-AG14-AG15 -> 14938.488 | AH12: =AH21-AH13-AH14-AH15 -> 15098.471 | ... GA12: =GA21-GA13-GA14-GA15 -> 1559.1251
A13: Repos | H13: =-H28 -> 946.603 | I13: =-I28 -> 966.99 | J13: =-J28 -> 881.431 | K13: =-K28 -> 860.152 | L13: =-L28 -> 911.31 | M13: =-M28 -> 946.472 | N13: =-N28 -> 957.157 | O13: =-O28 -> 951.102 | ... EH13: =-EH28 -> 20098.579 | EI13: =-EI28-EI29 -> 20624.514 | EJ13: =-EJ28-EJ29 -> 21036.054 | EK13: =-EK28-EK29 -> 20548.803 | EL13: =-EL28-EL29 -> 20743.813 | EM13: =-EM28-EM29 -> 20657.851 | EN13: =-EN28-EN29 -> 20161.339 | EO13: =-EO28-EO29 -> 19815.798 | EP13: =-EP28-EP29 -> 20037.231 | ... FY13: =-FY28-FY29 -> 27542.728 | FZ13: =FY13 -> 27542.728 | GA13: =FZ13 -> 27542.728
A14: Private USD deposits | H14: =H30 -> 6740.3984 | I14: =I30 -> 6654.5121 | J14: =J30 -> 7038.7015 | K14: =K30 -> 6960.8369 | L14: =L30 -> 6119.5911 | M14: =M30 -> 5235.116 | N14: =N30 -> 5821.9891 | O14: =O30 -> 6356.9294 | ... FY14: =FY30 -> 12397.85 | FZ14: =FY14 -> 12397.85 | GA14: =FZ14 -> 12397.85
A15: Gold | H15: =H24 -> 3433.639 | I15: =I24 -> 3419.784 | J15: =J24 -> 3311.107 | K15: =K24 -> 3300.428 | L15: =L24 -> 3096.593 | M15: =M24 -> 3175.038 | N15: =N24 -> 3201.359 | O15: =O24 -> 3346.499 | ... FY15: =FY24 -> 8000.297 | FZ15: =FY15 -> 8000.297 | GA15: =FZ15 -> 8000.297
A16: Non-gold reserves | H16: =H21-H24 -> 43160.361 | I16: =I21-I24 -> 43248.216 | J16: =J21-J24 -> 43979.893 | K16: =K21-K24 -> 44543.572 | L16: =L21-L24 -> 43881.407 | M16: =M21-M24 -> 43172.962 | N16: =N21-N24 -> 43616.641 | O16: =O21-O24 -> 41805.501 | ... FY16: =FY21-FY24 -> 36869.703 | FZ16: =FY16 -> 36869.703 | GA16: =FZ16 -> 36869.703
B20: 11201 !M NA_ | C20: .DESC | D20: .T1 | E20: .SOURCE | F20: .AGG | G20: .DATA_TYPE | H20: 1201 | I20: 1202 | J20: 1203 | K20: 1204 | L20: 1205 | M20: 1206 | N20: 1207 | O20: 1208 | P20: 1209 | Q20: 1210 | R20: 1211 | S20: 1212 | T20: 1301 | U20: 1302 | V20: 1303 | W20: 1304 | X20: 1305 | Y20: 1306 | Z20: 1307 | AA20: 1308 | AB20: 1309 | AC20: 1310 | AD20: 1311 | AE20: 1312 | AF20: 1401 | AG20: 1402 | AH20: 1403 | AI20: 1404 | AJ20: 1405 | AK20: 1406 | AL20: 1407 | AM20: 1408 | AN20: 1409 | AO20: 1410 | AP20: 1411 | AQ20: 1412 | AR20: 1501 | AS20: 1502 | AT20: 1503 | AU20: 1504 | AV20: 1505 | AW20: 1506 | AX20: 1507 | AY20: 1508 | AZ20: 1509 | BA20: 1510 | BB20: 1511 | BC20: 1512 | BD20: 1601 | BE20: 1602 | BF20: 1603 | BG20: 1604 | BH20: 1605 | BI20: 1606 | BJ20: 1607 | BK20: 1608 | BL20: 1609 | BM20: 1610 | BN20: 1611 | BO20: 1612 | BP20: 1701 | BQ20: 1702 | BR20: 1703 | BS20: 1704 | BT20: 1705 | BU20: 1706 | BV20: 1707 | BW20: 1708 | BX20: 1709 | BY20: 1710 | BZ20: 1711 | CA20: 1712 | CB20: 1801 | CC20: 1802 | CD20: 1803 | CE20: 1804 | CF20: 1805 | CG20: 1806 | CH20: 1807 | CI20: 1808 | CJ20: 1809 | CK20: 1810 | CL20: 1811 | CM20: 1812 | CN20: 1901 | CO20: 1902 | CP20: 1903 | CQ20: 1904 | CR20: 1905 | CS20: 1906 | CT20: 1907 | CU20: 1908 | CV20: 1909 | CW20: 1910 | CX20: 1911 | CY20: 1912 | CZ20: 2001 | DA20: 2002 | DB20: 2003 | DC20: 2004 | DD20: 2005 | DE20: 2006 | DF20: 2007 | DG20: 2008 | DH20: 2009 | DI20: 2010 | DJ20: 2011 | DK20: 2012 | DL20: 2101 | DM20: 2102 | DN20: 2103 | DO20: 2104 | DP20: 2105 | DQ20: 2106 | DR20: 2107 | DS20: 2108 | DT20: 2109 | DU20: 2110 | DV20: 2111 | DW20: 2112 | DX20: 2201 | DY20: 2202 | DZ20: 2203 | EA20: 2204 | EB20: 2205 | EC20: 2206 | ED20: 2207 | EE20: 2208 | EF20: 2209 | EG20: 2210 | EH20: 2211 | EI20: 2212 | EJ20: 2301 | EK20: 2302 | EL20: 2303 | EM20: 2304 | EN20: 2305 | EO20: 2306 | EP20: 2307 | EQ20: 2308 | ER20: 2309 | ES20: 2310 | ET20: 2311 | EU20: 2312 | EV20: 2401 | EW20: 2402 | EX20: 2403 | EY20: 2404 | EZ20: 2405 | FA20: 2406 | FB20: 2407 | FC20: 2408 | FD20: 2409 | FE20: 2410 | FF20: 2411 | FG20: 2412 | FH20: 2501 | FI20: 2502 | FJ20: 2503 | FK20: 2504 | FL20: 2505 | FM20: 2506 | FN20: 2507 | FO20: 2508 | FP20: 2509 | FQ20: 2510 | FR20: 2511 | FS20: 2512 | FT20: 2601 | FU20: 2602 | FV20: 2603 | FW20: 2604 | FX20: 2605 | FY20: 2606 | FZ20: 2607
A21: FX reserves | B21: N213LFRG@EMERGELA | C21: Argentina: BCRA International Reserves (EOP, Mil.US$) | D21: Jan-1940 | E21: BCRA | F21: End of Period | G21: US$ | H21: 46594 | I21: 46668 | J21: 47291 | K21: 47844 | L21: 46978 | M21: 46348 | N21: 46818 | O21: 45152 | P21: 45010 | Q21: 45274 | R21: 45238 | S21: 43290 | T21: 42531 | U21: 41609 | V21: 40446 | W21: 39532 | X21: 38551 | Y21: 37005 | Z21: 37049 | AA21: 36678 | AB21: 34741 | AC21: 33232 | AD21: 30799 | AE21: 30599 | AF21: 27748 | AG21: 27546 | AH21: 27007 | AI21: 28220 | AJ21: 28542 | AK21: 29278 | AL21: 29003 | AM21: 28620 | AN21: 27866 | AO21: 28111 | AP21: 28911 | AQ21: 31407 | AR21: 31452 | AS21: 31470 | AT21: 31490 | AU21: 33909 | AV21: 33283 | AW21: 33851 | AX21: 33943 | AY21: 33606 | AZ21: 33257 | BA21: 26970 | BB21: 25615 | BC21: 25563 | BD21: 30074 | BE21: 28399 | BF21: 29572 | BG21: 34380 | BH21: 30171 | BI21: 30507 | BJ21: 32511 | BK21: 31150 | BL21: 29902 | BM21: 37210 | BN21: 37378 | BO21: 39308 | BP21: 46887 | BQ21: 50608 | BR21: 50522 | BS21: 48217 | BT21: 46146 | BU21: 47995 | BV21: 47014 | BW21: 48877 | BX21: 50237 | BY21: 51810 | BZ21: 54563 | CA21: 55055 | CB21: 62024 | CC21: 61509 | CD21: 61726 | CE21: 56623 | CF21: 50098 | CG21: 61881 | CH21: 57996 | CI21: 52658 | CJ21: 49003 | CK21: 53955 | CL21: 51193 | CM21: 65786 | CN21: 66811 | CO21: 68015 | CP21: 66187 | CQ21: 71663 | CR21: 64779 | CS21: 64278 | CT21: 67899 | CU21: 54100 | CV21: 48703 | CW21: 43260 | CX21: 43772 | CY21: 44848 | CZ21: 44917 | DA21: 44791 | DB21: 43561 | DC21: 43568 | DD21: 42589 | DE21: 43242 | DF21: 43386 | DG21: 42842 | DH21: 41379 | DI21: 39856 | DJ21: 38652 | DK21: 39387 | DL21: 39515 | DM21: 39518 | DN21: 39593 | DO21: 40263 | DP21: 41872 | DQ21: 42437 | DR21: 42582 | DS21: 46180 | DT21: 42911 | DU21: 42817 | DV21: 41530 | DW21: 39662 | DX21: 37589 | DY21: 37018 | DZ21: 43137 | EA21: 42007 | EB21: 41561 | EC21: 42787 | ED21: 38232 | EE21: 36734 | EF21: 37625 | EG21: 38676 | EH21: 38009 | EI21: 44598 | EJ21: 41417 | EK21: 38709 | EL21: 39060 | EM21: 35001 | EN21: 33001 | EO21: 27926 | EP21: 24092 | EQ21: 27818 | ER21: 26925 | ES21: 22559 | ET21: 21513 | EU21: 23073 | EV21: 27642 | EW21: 26690 | EX21: 27127 | EY21: 27578 | EZ21: 28664 | FA21: 29022 | FB21: 26402 | FC21: 26719 | FD21: 27172 | FE21: 28618 | FF21: 30214 | FG21: 29640 | FH21: 28310 | FI21: 28117 | FJ21: 24986 | FK21: 38928 | FL21: 36919 | FM21: 39973 | FN21: 38866 | FO21: 39986 | FP21: 40374 | FQ21: 39382 | FR21: 40335 | FS21: 41167 | FT21: 44503 | FU21: 45566 | FV21: 42052 | FW21: 44516 | FX21: 48193 | FY21: 44870 | FZ21: 47599 | GA21: 49500
A22: Official reserve assets | B22: L213NAT@IFS | C22: Argentina: Official Reserve Assets (EOP, Mil.US$) | D22: Sep-2000 | E22: IMF | F22: End of Period | G22: US$ | H22: 46594.275 | I22: 46667.873 | J22: 47290.719 | K22: 47844.169 | L22: 46977.529 | M22: 46347.88 | N22: 46818.403 | O22: 45152.121 | P22: 45010.4 | Q22: 45274.313 | R22: 45237.537 | S22: 43290.268 | T22: 42530.591 | U22: 41609.108 | V22: 40445.772 | W22: 39531.944 | X22: 38551.071 | Y22: 37005.088 | Z22: 37048.577 | AA22: 36678.089 | AB22: 34741.175 | AC22: 33231.819 | AD22: 30798.711 | AE22: 30600.443 | AF22: 27748.151 | AG22: 27545.91 | AH22: 27007.323 | AI22: 28220.006 | AJ22: 28541.775 | AK22: 29278.334 | AL22: 29002.882 | AM22: 28619.651 | AN22: 27865.52 | AO22: 28111.41 | AP22: 28910.8 | AQ22: 31407.549 | AR22: 31451.545 | AS22: 31469.85 | AT22: 31489.55 | AU22: 33908.87 | AV22: 33283.236 | AW22: 33851.344 | AX22: 33942.957 | AY22: 33605.994 | AZ22: 33257.143 | BA22: 26969.611 | BB22: 25614.778 | BC22: 25563.482 | BD22: 30074.001 | BE22: 28398.536 | BF22: 29571.69 | BG22: 34379.757 | BH22: 30171.35 | BI22: 30507.284 | BJ22: 32511.207 | BK22: 31149.636 | BL22: 29901.568 | BM22: 37210.424 | BN22: 37377.698 | BO22: 39308.314 | BP22: 46886.711 | BQ22: 50607.995 | BR22: 50522.329 | BS22: 48216.717 | BT22: 46145.77 | BU22: 47994.546 | BV22: 47014.173 | BW22: 48876.535 | BX22: 50237.025 | BY22: 51809.938 | BZ22: 54563.421 | CA22: 55055.081 | CB22: 62023.844 | CC22: 61508.505 | CD22: 61725.912 | CE22: 56622.97 | CF22: 50098.112 | CG22: 61880.978 | CH22: 57996.156 | CI22: 52657.659 | CJ22: 49003.426 | CK22: 53955.088 | CL22: 51193.236 | CM22: 65785.763 | CN22: 66811.241 | CO22: 68014.865 | CP22: 66187.122 | CQ22: 71662.492 | CR22: 64779.384 | CS22: 64278.004 | CT22: 67899.418 | CU22: 54100.383 | CV22: 48703.345 | CW22: 43260.325 | CX22: 43772.256 | CY22: 44848.343 | CZ22: 44917.098 | DA22: 44790.678 | DB22: 43561.209 | DC22: 43568.382 | DD22: 42588.498 | DE22: 43241.495 | DF22: 43386.263 | DG22: 42842.069 | DH22: 41378.84 | DI22: 39856.341 | DJ22: 38651.953 | DK22: 39387.067 | DL22: 39515.179 | DM22: 39518.126 | DN22: 39593.339 | DO22: 40262.763 | DP22: 41871.81 | DQ22: 42436.914 | DR22: 42581.74 | DS22: 46180.316 | DT22: 42911.183 | DU22: 42817.083 | DV22: 41529.544 | DW22: 39662.442 | DX22: 37588.966 | DY22: 37017.463 | DZ22: 43137.397 | EA22: 42006.594 | EB22: 41561.079 | EC22: 42786.791 | ED22: 38231.739 | EE22: 36734.427 | EF22: 37625.012 | EG22: 38675.902 | EH22: 38008.871 | EI22: 44598.433 | EJ22: 41417.273 | EK22: 38709.357 | EL22: 39060.011 | EM22: 35001.285 | EN22: 33001.348 | EO22: 27925.947 | EP22: 24091.963 | EQ22: 27818.482 | ER22: 26924.696 | ES22: 22558.874 | ET22: 21513.117 | EU22: 23073.165 | EV22: 27641.526 | EW22: 26690.39 | EX22: 27127.076 | EY22: 27578.444 | EZ22: 28663.836 | FA22: 29021.796 | FB22: 26401.661 | FC22: 26718.641 | FD22: 27172.273 | FE22: 28617.946 | FF22: 30214.105 | FG22: 29639.73 | FH22: 28309.765 | FI22: 28117.311 | FJ22: 24986.329 | FK22: 38928.25 | FL22: 36919.129 | FM22: 39972.557 | FN22: 38865.967 | FO22: 39986.148 | FP22: 40373.564 | FQ22: 39381.591 | FR22: 40422.422 | FS22: 41094.284 | FT22: 44503.121 | FU22: 45565.581 | FV22: 42052.054 | FW22: 44515.839 | FX22: 48193.48 | FY22: 44870.205
A23: SDR | B23: L213NAS@IFS | C23: Argentina: Official Reserve Assets: SDRs (EOP, Mil.US$) | D23: Sep-2000 | E23: IMF | F23: End of Period | G23: US$ | H23: 3185.689 | I23: 3194.988 | J23: 3181.137 | K23: 3182.192 | L23: 3100.999 | M23: 3116.277 | N23: 3097.595 | O23: 3124.989 | P23: 3166.61 | Q23: 3167.159 | R23: 3151.26 | S23: 3155.766 | T23: 3163.595 | U23: 3110.275 | V23: 3072.202 | W23: 3098.743 | X23: 3077.25 | Y23: 3088.062 | Z23: 3107.356 | AA23: 3111.185 | AB23: 3149.954 | AC23: 3158.31 | AD23: 3152.151 | AE23: 3162.299 | AF23: 3150.719 | AG23: 3177.239 | AH23: 3173.941 | AI23: 3182.618 | AJ23: 3163.012 | AK23: 3174.372 | AL23: 3144.634 | AM23: 3117.564 | AN23: 3044.19 | AO23: 3035.55 | AP23: 3006.35 | AQ23: 2974.803 | AR23: 2894.831 | AS23: 2889.63 | AT23: 2832.47 | AU23: 2887.833 | AV23: 2854.923 | AW23: 2887.666 | AX23: 2863.785 | AY23: 2882.235 | AZ23: 2882.231 | BA23: 2868.243 | BB23: 2817.296 | BC23: 2845.257 | BD23: 2834.644 | BE23: 2836.077 | BF23: 2892.68 | BG23: 2910.275 | BH23: 2880.26 | BI23: 2872.088 | BJ23: 2860.991 | BK23: 2489.681 | BL23: 2492.408 | BM23: 2453.43 | BN23: 2417.445 | BO23: 2401.113 | BP23: 2427.648 | BQ23: 2419.69 | BR23: 2423.86 | BS23: 2450.108 | BT23: 2472.479 | BU23: 2486.327 | BV23: 2516.868 | BW23: 2524.326 | BX23: 2525.265 | BY23: 2511.183 | BZ23: 2528.04 | CA23: 2545.195 | CB23: 2605.889 | CC23: 2582.379 | CD23: 2604.915 | CE23: 2571.378 | CF23: 2530.279 | CG23: 3809.282 | CH23: 3807.861 | CI23: 3748.943 | CJ23: 3735.568 | CK23: 4174.842 | CL23: 3514.972 | CM23: 4360.37 | CN23: 3566.474 | CO23: 3348.657 | CP23: 3328.365 | CQ23: 3326.344 | CR23: 3034.828 | CS23: 3031.429 | CT23: 3345.915 | CU23: 2962.914 | CV23: 2954.253 | CW23: 2991.088 | CX23: 2584.585 | CY23: 2604.986 | CZ23: 2595.531 | DA23: 2210.386 | DB23: 2206.441 | DC23: 2199.831 | DD23: 1888.438 | DE23: 1864.877 | DF23: 1942.198 | DG23: 1642.988 | DH23: 1629.985 | DI23: 1634.821 | DJ23: 1344.718 | DK23: 1354.4 | DL23: 1354.974 | DM23: 1039.038 | DN23: 1023.156 | DO23: 1036.757 | DP23: 740.771 | DQ23: 853.196 | DR23: 854.638 | DS23: 4855.625 | DT23: 2934.164 | DU23: 2947.848 | DV23: 2532.043 | DW23: 673.096 | DX23: 376.7 | DY23: 10.919 | DZ23: 6781.894 | EA23: 5908.132 | EB23: 5563.303 | EC23: 6777.062 | ED23: 4792.507 | EE23: 4257.873 | EF23: 1614.614 | EG23: 2932.736 | EH23: 2429.315 | EI23: 5763.558 | EJ23: 3188.287 | EK23: 2411.598 | EL23: 5066.81 | EM23: 2423.519 | EN23: 1607.264 | EO23: 10.29 | EP23: 70.829 | EQ23: 2968.929 | ER23: 1860.917 | ES23: 68.15 | ET23: 0.134 | EU23: 0.104 | EV23: 2707.306 | EW23: 893.344 | EX23: 892.558 | EY23: 890.733 | EZ23: 30.194 | FA23: 817.402 | FB23: 854.926 | FC23: 8.591 | FD23: 8.679 | FE23: 845.686 | FF23: 42.847 | FG23: 42.645 | FH23: 708.861 | FI23: 63.117 | FJ23: 64.235 | FK23: 741.032 | FL23: 77.088 | FM23: 78.26 | FN23: 77.345 | FO23: 40.791 | FP23: 40.955 | FQ23: 912.257 | FR23: 67.442 | FS23: 68.139 | FT23: 878.312 | FU23: 40.407 | FV23: 39.961 | FW23: 856.763 | FX23: 48.284 | FY23: 47.955
A24: Gold | B24: L213NAG@IFS | C24: Argentina: Official Reserve Assets: Gold (EOP, Mil.US$) | D24: Sep-2000 | E24: IMF | F24: End of Period | G24: US$ | H24: 3433.639 | I24: 3419.784 | J24: 3311.107 | K24: 3300.428 | L24: 3096.593 | M24: 3175.038 | N24: 3201.359 | O24: 3346.499 | P24: 3514.148 | Q24: 3411.109 | R24: 3399.835 | S24: 3326.471 | T24: 3330.738 | U24: 3137.265 | V24: 3186.968 | W24: 2922.909 | X24: 2763.398 | Y24: 2432.764 | Z24: 2606.626 | AA24: 2769.571 | AB24: 2637.949 | AC24: 2625.523 | AD24: 2481.812 | AE24: 2389.472 | AF24: 2461.744 | AG24: 2623.657 | AH24: 2545.946 | AI24: 2569.587 | AJ24: 2470.041 | AK24: 2633.641 | AL24: 2542.234 | AM24: 2552.06 | AN24: 2399.34 | AO24: 2324.52 | AP24: 2316.17 | AQ24: 2354.785 | AR24: 2529.55 | AS24: 2406.96 | AT24: 2345.58 | AU24: 2348.343 | AV24: 2361.821 | AW24: 2325.933 | AX24: 2178.014 | AY24: 2249.096 | AZ24: 2214.398 | BA24: 2263.348 | BB24: 2110.625 | BC24: 2106.933 | BD24: 2215.272 | BE24: 2444.197 | BF24: 2444.44 | BG24: 2559.801 | BH24: 2413.03 | BI24: 2617.265 | BJ24: 2681.558 | BK24: 2594.438 | BL24: 2607.757 | BM24: 2322.99 | BN24: 2141.825 | BO24: 2101.749 | BP24: 2400.569 | BQ24: 2291.49 | BR24: 2202.13 | BS24: 2514.149 | BT24: 2522.781 | BU24: 2386.584 | BV24: 2514.067 | BW24: 2614.705 | BX24: 2545.529 | BY24: 2435.019 | BZ24: 2293.122 | CA24: 2298.775 | CB24: 2657.883 | CC24: 2616.789 | CD24: 2337.695 | CE24: 2623.718 | CF24: 2579.034 | CG24: 2486.436 | CH24: 2429.229 | CI24: 2383.834 | CJ24: 2296.958 | CK24: 2406.924 | CL24: 2435.609 | CM24: 2255.623 | CN24: 2622.26 | CO24: 2608.201 | CP24: 2280.853 | CQ24: 2547.164 | CR24: 2588.214 | CS24: 2486.031 | CT24: 2818.441 | CU24: 3011.884 | CV24: 2914.148 | CW24: 2999.439 | CX24: 2904.26 | CY24: 2684.466 | CZ24: 3140.234 | DA24: 3139.756 | DB24: 2940.878 | DC24: 3341.13 | DD24: 3440.716 | DE24: 3533.096 | DF24: 3910.815 | DG24: 3913.236 | DH24: 3753.824 | DI24: 3728.992 | DJ24: 3527.459 | DK24: 3758.25 | DL24: 3673.155 | DM24: 3424.241 | DN24: 3392.997 | DO24: 3510.864 | DP24: 3783.082 | DQ24: 3509.634 | DR24: 3600.406 | DS24: 3599.83 | DT24: 3483.452 | DU24: 3536.153 | DV24: 3521.762 | DW24: 3213.763 | DX24: 3564.319 | DY24: 3744.514 | DZ24: 3859.206 | EA24: 3789.156 | EB24: 3655.429 | EC24: 3587.94 | ED24: 3502.289 | EE24: 3398.376 | EF24: 3299.545 | EG24: 3243.926 | EH24: 3476.683 | EI24: 3617.973 | EJ24: 3827.942 | EK24: 3629.287 | EL24: 3905.435 | EM24: 3949.105 | EN24: 3900.89 | EO24: 3806.882 | EP24: 3468.944 | EQ24: 3849.896 | ER24: 3669.542 | ES24: 3936.798 | ET24: 4042.934 | EU24: 4095.873 | EV24: 4064.59 | EW24: 4058.258 | EX24: 4344.767 | EY24: 4554.201 | EZ24: 4614.008 | FA24: 4616.965 | FB24: 4806.688 | FC24: 4960.642 | FD24: 5234.802 | FE24: 5436.811 | FF24: 5277.643 | FG24: 5206.145 | FH24: 5572.628 | FI24: 5646.35 | FJ24: 6187.312 | FK24: 6560.286 | FL24: 6532.298 | FM24: 6535.891 | FN24: 6539.126 | FO24: 6835.005 | FP24: 7629.01 | FQ24: 7934.396 | FR24: 8368.309 | FS24: 8585.662 | FT24: 9644.6 | FU24: 10388.584 | FV24: 9236.571 | FW24: 9172.834 | FX24: 9037.023 | FY24: 8000.297
A25: FX loans, securities, deposits | B25: L213NC@IFS | C25: Argentina: Predetermined ST Drains: Fgn Curr Loans/Secur/Deposits (EOP, Mil.US$) | D25: Dec-2005 | E25: IMF | F25: End of Period | G25: US$ | H25: -20015.944 | I25: -19309.446 | J25: -19476.872 | K25: -21067.088 | L25: -18893.439 | M25: -17731.619 | N25: -22032.333 | O25: -17835.49 | P25: -19717.789 | Q25: -22539.909 | R25: -22008.06 | S25: -20150.833 | T25: -19642.446 | U25: -19152.599 | V25: -18849.108 | W25: -17695.106 | X25: -16746.723 | Y25: -16727.432 | Z25: -16963.437 | AA25: -26275.169 | AB25: -20886.119 | AC25: -20810.219 | AD25: -19032.784 | AE25: -19413.281 | AF25: -19072.719 | AG25: -17319.552 | AH25: -16672.677 | AI25: -15956.771 | AJ25: -15664.113 | AK25: -15509.167 | AL25: -15043.088 | AM25: -15326.908 | AN25: -15594.41 | AO25: -22271.57 | AP25: -22959.3 | AQ25: -26229.612 | AR25: -34688.225 | AS25: -25955.44 | AT25: -25142.006 | AU25: -25873.351 | AV25: -25593.512 | AW25: -24274.714 | AX25: -25122.496 | AY25: -24641.627 | AZ25: -31565.986 | BA25: -21635.803 | BB25: -23545.315 | BC25: -25563.839 | BD25: -25285.521 | BE25: -23942.231 | BF25: -26574.16 | BG25: -39075.137 | BH25: -34169.28 | BI25: -35658.4 | BJ25: -41045.769 | BK25: -39108.57 | BL25: -39014.807 | BM25: -44065.778 | BN25: -41472.422 | BO25: -45449.086 | BP25: -53678.348 | BQ25: -56049.031 | BR25: -58666.121 | BS25: -46755.531 | BT25: -43943.287 | BU25: -44797.758 | BV25: -43713.23 | BW25: -46079.733 | BX25: -44462.887 | BY25: -44228.012 | BZ25: -49684.071 | CA25: -52448.878 | CB25: -56862.578 | CC25: -53332.961 | CD25: -57401.04 | CE25: -61056.794 | CF25: -59684.202 | CG25: -74290.199 | CH25: -69539.078 | CI25: -67208.555 | CJ25: -66783.591 | CK25: -72263.547 | CL25: -62911.744 | CM25: -68172.982 | CN25: -67141.958 | CO25: -67479.617 | CP25: -65290.128 | CQ25: -72181.117 | CR25: -60511.331 | CS25: -61285.543 | CT25: -65026.97 | CU25: -52143.555 | CV25: -45679.43 | CW25: -48633.65 | CX25: -48041.503 | CY25: -52864.38 | CZ25: -53539.944 | DA25: -53911.126 | DB25: -55336.19 | DC25: -59180.286 | DD25: -58539.459 | DE25: -59861.602 | DF25: -56674.517 | DG25: -32447.842 | DH25: -34725.912 | DI25: -34525.579 | DJ25: -34341.277 | DK25: -36473.052 | DL25: -30289.272 | DM25: -30647.549 | DN25: -30600.607 | DO25: -36391.445 | DP25: -33617.058 | DQ25: -39488.294 | DR25: -44591.276 | DS25: -44501.213 | DT25: -45704.512 | DU25: -48716.447 | DV25: -48677.089 | DW25: -50031.822 | DX25: -59609.506 | DY25: -58630.526 | DZ25: -64633.161 | EA25: -60859.179 | EB25: -56218.581 | EC25: -54414.768 | ED25: -54211.083 | EE25: -55804.29 | EF25: -51776.124 | EG25: -55076.014 | EH25: -54844.282 | EI25: -56986.965 | EJ25: -55818.766 | EK25: -54407.533 | EL25: -54855.139 | EM25: -50892.591 | EN25: -49698.046 | EO25: -46689.11 | EP25: -49575.812 | EQ25: -51956.225 | ER25: -51811.865 | ES25: -48454.216 | ET25: -44553.209 | EU25: -44276.465 | EV25: -40896.343 | EW25: -38703.069 | EX25: -36926.052 | EY25: -34467.344 | EZ25: -33574.341 | FA25: -45157.868 | FB25: -45004.737 | FC25: -41487.95 | FD25: -43148.62 | FE25: -44421.491 | FF25: -48510.802 | FG25: -48903.526 | FH25: -46432.444 | FI25: -46248.428 | FJ25: -44295.399 | FK25: -60912.296 | FL25: -36781.099 | FM25: -37614.767 | FN25: -36624.925 | FO25: -35018.14 | FP25: -36588.889 | FQ25: -35942.571 | FR25: -37941.9 | FS25: -41129.766 | FT25: -41848.498 | FU25: -41188.218 | FV25: -38503.89 | FW25: -41494.125 | FX25: -42971.934 | FY25: -40884.988
A26: Outflow - principal | B26: L213NCOP@IFS | C26: Argentina: Predtrm ST Drain: Fgn Curr Loans/Sec/Dep: Princ Outflow (EOP,Mil.US$) | D26: Sep-2000 | E26: IMF | F26: End of Period | G26: US$ | H26: -16913.568 | I26: -16213.373 | J26: -16384.105 | K26: -17972.44 | L26: -15819.209 | M26: -14478.509 | N26: -18777.41 | O26: -14591.905 | P26: -16481.502 | Q26: -19141.324 | R26: -18628.905 | S26: -16777.982 | T26: -16272.218 | U26: -15787.326 | V26: -15559.297 | W26: -14417.262 | X26: -13482.018 | Y26: -13050.35 | Z26: -13288.056 | AA26: -22606.022 | AB26: -17302.35 | AC26: -16996.851 | AD26: -15223.051 | AE26: -15617.468 | AF26: -15278.113 | AG26: -13528.494 | AH26: -12856.307 | AI26: -12158.474 | AJ26: -11869.035 | AK26: -11728.291 | AL26: -11264.671 | AM26: -11467.136 | AN26: -11742.97 | AO26: -18428.91 | AP26: -19121.19 | AQ26: -21556.363 | AR26: -30017.78 | AS26: -30821.58 | AT26: -30013.286 | AU26: -30969.922 | AV26: -30736.014 | AW26: -29433.054 | AX26: -30282.621 | AY26: -29809.17 | AZ26: -36740.262 | BA26: -27017.631 | BB26: -28609.079 | BC26: -20037.48 | BD26: -19767.884 | BE26: -18436.27 | BF26: -20830.222 | BG26: -32179.647 | BH26: -27364.91 | BI26: -28770.666 | BJ26: -33486.816 | BK26: -32148.572 | BL26: -31850.27 | BM26: -37026.378 | BN26: -34434.575 | BO26: -38381.478 | BP26: -46022.604 | BQ26: -48392.273 | BR26: -51011.422 | BS26: -39230.45 | BT26: -36359.115 | BU26: -36836.727 | BV26: -35702.359 | BW26: -37589.356 | BX26: -35590.607 | BY26: -35026.997 | BZ26: -40373.044 | CA26: -43029.194 | CB26: -46769.917 | CC26: -43224.517 | CD26: -47312.347 | CE26: -50550.645 | CF26: -50805.294 | CG26: -64823.692 | CH26: -60230.45 | CI26: -57703.181 | CJ26: -57249.039 | CK26: -62748.827 | CL26: -52300.773 | CM26: -57423.273 | CN26: -57001.198 | CO26: -57168.853 | CP26: -54493.408 | CQ26: -61415.833 | CR26: -50374.157 | CS26: -50288.102 | CT26: -54139.988 | CU26: -41431.319 | CV26: -34996.502 | CW26: -36862.802 | CX26: -35926.966 | CY26: -40917.052 | CZ26: -43205.4 | DA26: -43752.817 | DB26: -45162.073 | DC26: -48861.046 | DD26: -48036.995 | DE26: -47896.775 | DF26: -44360.888 | DG26: -29775.373 | DH26: -32117.451 | DI26: -31966.453 | DJ26: -31678.984 | DK26: -33785.013 | DL26: -27110.263 | DM26: -27441.182 | DN26: -27484.27 | DO26: -33238.212 | DP26: -30661.041 | DQ26: -36562.54 | DR26: -40776.353 | DS26: -40761.095 | DT26: -41990.816 | DU26: -44987.809 | DV26: -45106.628 | DW26: -46467.256 | DX26: -55690.151 | DY26: -54882.957 | DZ26: -60845.802 | EA26: -56400.27 | EB26: -51838.957 | EC26: -50109.365 | ED26: -48747.551 | EE26: -50465.066 | EF26: -46144.61 | EG26: -49815.556 | EH26: -49677.494 | EI26: -51082.122 | EJ26: -48836.179 | EK26: -47725.222 | EL26: -47551.67 | EM26: -42924.308 | EN26: -41964.725 | EO26: -38891.782 | EP26: -41144.282 | EQ26: -43506.736 | ER26: -43211.496 | ES26: -39865.816 | ET26: -35985.763 | EU26: -35692.093 | EV26: -31916.718 | EW26: -30084.185 | EX26: -28153.368 | EY26: -25584.575 | EZ26: -24705.055 | FA26: -36205.455 | FB26: -35878.3 | FC26: -32292.573 | FD26: -34075.268 | FE26: -35473.225 | FF26: -39706.967 | FG26: -40625.068 | FH26: -38101.519 | FI26: -37963.249 | FJ26: -35997.838 | FK26: -51981.122 | FL26: -27966.708 | FM26: -28679.439 | FN26: -27777.176 | FO26: -26376.742 | FP26: -27970.367 | FQ26: -27206.377 | FR26: -29253.033 | FS26: -32037.933 | FT26: -32854.318 | FU26: -32215.309 | FV26: -29029.221 | FW26: -31915.205 | FX26: -33597.388 | FY26: -31254.812
