Workbook

Sheet README
B2: CHL USD Sovereign Curve — Credit Analyst Toolkit
B4: How to use
B5: 1. Paste your ISINs into the Bonds_Static sheet (column A, rows 2 onward). Everything else auto-pulls via Bloomberg BDP.
B6: 2. Open this file on a machine with Bloomberg Excel Add-in enabled. Hit F9 to refresh.
B7: 3. Bonds_Static fields are static (description, coupon, maturity, ratings, amount outstanding). Bonds_Live is live (prices, YTM, spreads, duration, convexity, DV01).
B8: 4. UST_Curve is the risk-free benchmark — used for spreads and as the anchor for the ΔUST scenarios.
B9: 5. Curve_Fit fits a model curve to your bonds. Residual (Actual YTM − Modeled YTM) is the rich/cheap signal: positive = cheap.
B10: 6. Liquidity_Gate scores every bond; only bonds that pass the gate feed into Rich_Cheap_Rank and Trade_Recos.
B11: 7. Carry_Roll computes 3M/6M/12M carry + roll-down assuming the fitted curve doesn't shift.
B12: 8. DTS_Carry — risk-adjusted carry per unit of DTS (Z-spread × Spread Duration), plus breakeven widening (bp of spread widening that offsets your 12M carry). Use this to size positions.
B13: 9. Spread_History — BDH-driven 1Y distribution stats: min/max/avg/stdev, current percentile, z-score, and a CHEAP/FAIR/RICH tag. Mean-reversion signal — independent of the curve-residual signal.
B14: 10. Implied_PD — back out the cumulative default probability priced in (given the recovery assumption on Settings!C53), plus the 'breakeven recovery' that would make each bond fair vs the cross-sectional average hazard. ARG-relevant; CHL acts as sanity check.
... B49: EMBI bucket ticker default is JPEIDIVR Index; if Bloomberg doesn't return INDEX_AVG_SPREAD, the formula falls back to YAS_BOND_SPRD. Adjust Settings!B27 if your firm uses a different benchmark.

Sheet Settings
B2: Settings & Assumptions
B4: Workbook
B5: Country | C5: CHL
B6: As-of date | C6: =TODAY()
B7: Curve-fit method | C7: POLY
B8: Number of bond slots | C8: 25
B9: Number of peer slots | C9: 15
B11: Curve-Fit Parameters — Cubic Polynomial (LINEST-driven)
B12: a0 (intercept) | C12: =Curve_Fit!H5 | E12: Coefficients come from LINEST. Read-only — they refit automatically when yields change.
B13: a1 (linear term) | C13: =Curve_Fit!H4
B14: a2 (quadratic term) | C14: =Curve_Fit!H3
B15: a3 (cubic term) | C15: =Curve_Fit!H2
B16: R² of fit | C16: =Curve_Fit!H7
B22: Scenario Grid — ΔUST and Δspread shocks (bp)
B23: ΔUST shocks (bp) | C23: -100 | D23: -50 | E23: -25 | F23: 0 | G23: 25 | H23: 50 | I23: 100
B24: Δspread shocks (bp) | C24: -100 | D24: -50 | E24: 0 | F24: 50 | G24: 100
B25: Horizons (months) | C25: 3 | D25: 6 | E25: 12
B27: Central View (drives Trade_Recos quantified TR)
B28: EMBI benchmark ticker | C28: JPEIDIVR Index | E28: These two cells drive the 'Central-view 12M TR' column on Trade_Recos. Update with your house view.
B29: EMBI rating bucket ticker (override) | C29: JBCDCOMP Index
B30: Central-view ΔUST 12M (bp) | C30: 0
B31: Central-view Δspread 12M (bp) | C31: -10
B33: Liquidity Gate Thresholds
B34: Min amount outstanding ($mm) | C34: 750
B35: Max bid-ask spread (pts) | C35: 0.4
B36: Min TRACE avg daily volume ($mm) | C36: 3
B37: Min Bloomberg LQA score (0-100) | C37: 60
B38: Min years to maturity | C38: 0.5
B39: Bonds must pass at least N criteria | C39: 3
B41: Rich/Cheap Composite — Z-Score Weights (sum to 1)
B42: Curve residual (cheap = +) | C42: 0.3
B43: 12M carry+roll | C43: 0.15
B44: DTS-adjusted carry | C44: 0.15
B45: YTM (absolute level) | C45: 0.05
B46: Spread vs peer basket | C46: 0.15
B47: Spread vs EMBI bucket | C47: 0.1
B48: 1Y spread percentile (high = +) | C48: 0.05
B49: Liquidity score (boost) | C49: 0.05
B50: Sum (should = 100%) | C50: =SUM(C42:C49)
B52: Risk Overlays
...

Sheet Bonds_Static
A1: ISIN | B1: Ticker | C1: Description | D1: Coupon (%) | E1: Maturity | F1: Issue Date | G1: Yrs to Maty | H1: Amt Outstanding ($mm) | I1: Currency | J1: Country | K1: S&P | L1: Moody's | M1: Fitch | N1: Composite | O1: Day Count | P1: Cpn Freq | Q1: Callable | R1: Manual flag
B2: =IFERROR(BDP("/isin/"&$A2,"TICKER"),"") | C2: =IFERROR(BDP("/isin/"&$A2,"SECURITY_DES"),"") | D2: =IFERROR(BDP("/isin/"&$A2,"CPN"),"") | E2: =IFERROR(BDP("/isin/"&$A2,"MATURITY"),"") | F2: =IFERROR(BDP("/isin/"&$A2,"ISSUE_DT"),"") | G2: =IFERROR(IF(E2="","",(E2-TODAY())/365.25),"") | H2: =IFERROR(BDP("/isin/"&$A2,"AMT_OUTSTANDING")/1000000,"") | I2: =IFERROR(BDP("/isin/"&$A2,"CRNCY"),"") | J2: =IFERROR(BDP("/isin/"&$A2,"CNTRY_OF_RISK"),"") | K2: =IFERROR(BDP("/isin/"&$A2,"RTG_SP_LT_FC"),"") | L2: =IFERROR(BDP("/isin/"&$A2,"RTG_MDY_LONG_TERM"),"") | M2: =IFERROR(BDP("/isin/"&$A2,"RTG_FITCH_LT_LC_DEBT"),"") | N2: =IFERROR(BDP("/isin/"&$A2,"BB_COMPOSITE"),"") | O2: =IFERROR(BDP("/isin/"&$A2,"DAY_CNT_DES"),"") | P2: =IFERROR(BDP("/isin/"&$A2,"CPN_FREQ"),"") | Q2: =IFERROR(BDP("/isin/"&$A2,"CALLABLE"),"")
B3: =IFERROR(BDP("/isin/"&$A3,"TICKER"),"") | C3: =IFERROR(BDP("/isin/"&$A3,"SECURITY_DES"),"") | D3: =IFERROR(BDP("/isin/"&$A3,"CPN"),"") | E3: =IFERROR(BDP("/isin/"&$A3,"MATURITY"),"") | F3: =IFERROR(BDP("/isin/"&$A3,"ISSUE_DT"),"") | G3: =IFERROR(IF(E3="","",(E3-TODAY())/365.25),"") | H3: =IFERROR(BDP("/isin/"&$A3,"AMT_OUTSTANDING")/1000000,"") | I3: =IFERROR(BDP("/isin/"&$A3,"CRNCY"),"") | J3: =IFERROR(BDP("/isin/"&$A3,"CNTRY_OF_RISK"),"") | K3: =IFERROR(BDP("/isin/"&$A3,"RTG_SP_LT_FC"),"") | L3: =IFERROR(BDP("/isin/"&$A3,"RTG_MDY_LONG_TERM"),"") | M3: =IFERROR(BDP("/isin/"&$A3,"RTG_FITCH_LT_LC_DEBT"),"") | N3: =IFERROR(BDP("/isin/"&$A3,"BB_COMPOSITE"),"") | O3: =IFERROR(BDP("/isin/"&$A3,"DAY_CNT_DES"),"") | P3: =IFERROR(BDP("/isin/"&$A3,"CPN_FREQ"),"") | Q3: =IFERROR(BDP("/isin/"&$A3,"CALLABLE"),"")
B4: =IFERROR(BDP("/isin/"&$A4,"TICKER"),"") | C4: =IFERROR(BDP("/isin/"&$A4,"SECURITY_DES"),"") | D4: =IFERROR(BDP("/isin/"&$A4,"CPN"),"") | E4: =IFERROR(BDP("/isin/"&$A4,"MATURITY"),"") | F4: =IFERROR(BDP("/isin/"&$A4,"ISSUE_DT"),"") | G4: =IFERROR(IF(E4="","",(E4-TODAY())/365.25),"") | H4: =IFERROR(BDP("/isin/"&$A4,"AMT_OUTSTANDING")/1000000,"") | I4: =IFERROR(BDP("/isin/"&$A4,"CRNCY"),"") | J4: =IFERROR(BDP("/isin/"&$A4,"CNTRY_OF_RISK"),"") | K4: =IFERROR(BDP("/isin/"&$A4,"RTG_SP_LT_FC"),"") | L4: =IFERROR(BDP("/isin/"&$A4,"RTG_MDY_LONG_TERM"),"") | M4: =IFERROR(BDP("/isin/"&$A4,"RTG_FITCH_LT_LC_DEBT"),"") | N4: =IFERROR(BDP("/isin/"&$A4,"BB_COMPOSITE"),"") | O4: =IFERROR(BDP("/isin/"&$A4,"DAY_CNT_DES"),"") | P4: =IFERROR(BDP("/isin/"&$A4,"CPN_FREQ"),"") | Q4: =IFERROR(BDP("/isin/"&$A4,"CALLABLE"),"")
B5: =IFERROR(BDP("/isin/"&$A5,"TICKER"),"") | C5: =IFERROR(BDP("/isin/"&$A5,"SECURITY_DES"),"") | D5: =IFERROR(BDP("/isin/"&$A5,"CPN"),"") | E5: =IFERROR(BDP("/isin/"&$A5,"MATURITY"),"") | F5: =IFERROR(BDP("/isin/"&$A5,"ISSUE_DT"),"") | G5: =IFERROR(IF(E5="","",(E5-TODAY())/365.25),"") | H5: =IFERROR(BDP("/isin/"&$A5,"AMT_OUTSTANDING")/1000000,"") | I5: =IFERROR(BDP("/isin/"&$A5,"CRNCY"),"") | J5: =IFERROR(BDP("/isin/"&$A5,"CNTRY_OF_RISK"),"") | K5: =IFERROR(BDP("/isin/"&$A5,"RTG_SP_LT_FC"),"") | L5: =IFERROR(BDP("/isin/"&$A5,"RTG_MDY_LONG_TERM"),"") | M5: =IFERROR(BDP("/isin/"&$A5,"RTG_FITCH_LT_LC_DEBT"),"") | N5: =IFERROR(BDP("/isin/"&$A5,"BB_COMPOSITE"),"") | O5: =IFERROR(BDP("/isin/"&$A5,"DAY_CNT_DES"),"") | P5: =IFERROR(BDP("/isin/"&$A5,"CPN_FREQ"),"") | Q5: =IFERROR(BDP("/isin/"&$A5,"CALLABLE"),"")
B6: =IFERROR(BDP("/isin/"&$A6,"TICKER"),"") | C6: =IFERROR(BDP("/isin/"&$A6,"SECURITY_DES"),"") | D6: =IFERROR(BDP("/isin/"&$A6,"CPN"),"") | E6: =IFERROR(BDP("/isin/"&$A6,"MATURITY"),"") | F6: =IFERROR(BDP("/isin/"&$A6,"ISSUE_DT"),"") | G6: =IFERROR(IF(E6="","",(E6-TODAY())/365.25),"") | H6: =IFERROR(BDP("/isin/"&$A6,"AMT_OUTSTANDING")/1000000,"") | I6: =IFERROR(BDP("/isin/"&$A6,"CRNCY"),"") | J6: =IFERROR(BDP("/isin/"&$A6,"CNTRY_OF_RISK"),"") | K6: =IFERROR(BDP("/isin/"&$A6,"RTG_SP_LT_FC"),"") | L6: =IFERROR(BDP("/isin/"&$A6,"RTG_MDY_LONG_TERM"),"") | M6: =IFERROR(BDP("/isin/"&$A6,"RTG_FITCH_LT_LC_DEBT"),"") | N6: =IFERROR(BDP("/isin/"&$A6,"BB_COMPOSITE"),"") | O6: =IFERROR(BDP("/isin/"&$A6,"DAY_CNT_DES"),"") | P6: =IFERROR(BDP("/isin/"&$A6,"CPN_FREQ"),"") | Q6: =IFERROR(BDP("/isin/"&$A6,"CALLABLE"),"")
B7: =IFERROR(BDP("/isin/"&$A7,"TICKER"),"") | C7: =IFERROR(BDP("/isin/"&$A7,"SECURITY_DES"),"") | D7: =IFERROR(BDP("/isin/"&$A7,"CPN"),"") | E7: =IFERROR(BDP("/isin/"&$A7,"MATURITY"),"") | F7: =IFERROR(BDP("/isin/"&$A7,"ISSUE_DT"),"") | G7: =IFERROR(IF(E7="","",(E7-TODAY())/365.25),"") | H7: =IFERROR(BDP("/isin/"&$A7,"AMT_OUTSTANDING")/1000000,"") | I7: =IFERROR(BDP("/isin/"&$A7,"CRNCY"),"") | J7: =IFERROR(BDP("/isin/"&$A7,"CNTRY_OF_RISK"),"") | K7: =IFERROR(BDP("/isin/"&$A7,"RTG_SP_LT_FC"),"") | L7: =IFERROR(BDP("/isin/"&$A7,"RTG_MDY_LONG_TERM"),"") | M7: =IFERROR(BDP("/isin/"&$A7,"RTG_FITCH_LT_LC_DEBT"),"") | N7: =IFERROR(BDP("/isin/"&$A7,"BB_COMPOSITE"),"") | O7: =IFERROR(BDP("/isin/"&$A7,"DAY_CNT_DES"),"") | P7: =IFERROR(BDP("/isin/"&$A7,"CPN_FREQ"),"") | Q7: =IFERROR(BDP("/isin/"&$A7,"CALLABLE"),"")
B8: =IFERROR(BDP("/isin/"&$A8,"TICKER"),"") | C8: =IFERROR(BDP("/isin/"&$A8,"SECURITY_DES"),"") | D8: =IFERROR(BDP("/isin/"&$A8,"CPN"),"") | E8: =IFERROR(BDP("/isin/"&$A8,"MATURITY"),"") | F8: =IFERROR(BDP("/isin/"&$A8,"ISSUE_DT"),"") | G8: =IFERROR(IF(E8="","",(E8-TODAY())/365.25),"") | H8: =IFERROR(BDP("/isin/"&$A8,"AMT_OUTSTANDING")/1000000,"") | I8: =IFERROR(BDP("/isin/"&$A8,"CRNCY"),"") | J8: =IFERROR(BDP("/isin/"&$A8,"CNTRY_OF_RISK"),"") | K8: =IFERROR(BDP("/isin/"&$A8,"RTG_SP_LT_FC"),"") | L8: =IFERROR(BDP("/isin/"&$A8,"RTG_MDY_LONG_TERM"),"") | M8: =IFERROR(BDP("/isin/"&$A8,"RTG_FITCH_LT_LC_DEBT"),"") | N8: =IFERROR(BDP("/isin/"&$A8,"BB_COMPOSITE"),"") | O8: =IFERROR(BDP("/isin/"&$A8,"DAY_CNT_DES"),"") | P8: =IFERROR(BDP("/isin/"&$A8,"CPN_FREQ"),"") | Q8: =IFERROR(BDP("/isin/"&$A8,"CALLABLE"),"")
B9: =IFERROR(BDP("/isin/"&$A9,"TICKER"),"") | C9: =IFERROR(BDP("/isin/"&$A9,"SECURITY_DES"),"") | D9: =IFERROR(BDP("/isin/"&$A9,"CPN"),"") | E9: =IFERROR(BDP("/isin/"&$A9,"MATURITY"),"") | F9: =IFERROR(BDP("/isin/"&$A9,"ISSUE_DT"),"") | G9: =IFERROR(IF(E9="","",(E9-TODAY())/365.25),"") | H9: =IFERROR(BDP("/isin/"&$A9,"AMT_OUTSTANDING")/1000000,"") | I9: =IFERROR(BDP("/isin/"&$A9,"CRNCY"),"") | J9: =IFERROR(BDP("/isin/"&$A9,"CNTRY_OF_RISK"),"") | K9: =IFERROR(BDP("/isin/"&$A9,"RTG_SP_LT_FC"),"") | L9: =IFERROR(BDP("/isin/"&$A9,"RTG_MDY_LONG_TERM"),"") | M9: =IFERROR(BDP("/isin/"&$A9,"RTG_FITCH_LT_LC_DEBT"),"") | N9: =IFERROR(BDP("/isin/"&$A9,"BB_COMPOSITE"),"") | O9: =IFERROR(BDP("/isin/"&$A9,"DAY_CNT_DES"),"") | P9: =IFERROR(BDP("/isin/"&$A9,"CPN_FREQ"),"") | Q9: =IFERROR(BDP("/isin/"&$A9,"CALLABLE"),"")
B10: =IFERROR(BDP("/isin/"&$A10,"TICKER"),"") | C10: =IFERROR(BDP("/isin/"&$A10,"SECURITY_DES"),"") | D10: =IFERROR(BDP("/isin/"&$A10,"CPN"),"") | E10: =IFERROR(BDP("/isin/"&$A10,"MATURITY"),"") | F10: =IFERROR(BDP("/isin/"&$A10,"ISSUE_DT"),"") | G10: =IFERROR(IF(E10="","",(E10-TODAY())/365.25),"") | H10: =IFERROR(BDP("/isin/"&$A10,"AMT_OUTSTANDING")/1000000,"") | I10: =IFERROR(BDP("/isin/"&$A10,"CRNCY"),"") | J10: =IFERROR(BDP("/isin/"&$A10,"CNTRY_OF_RISK"),"") | K10: =IFERROR(BDP("/isin/"&$A10,"RTG_SP_LT_FC"),"") | L10: =IFERROR(BDP("/isin/"&$A10,"RTG_MDY_LONG_TERM"),"") | M10: =IFERROR(BDP("/isin/"&$A10,"RTG_FITCH_LT_LC_DEBT"),"") | N10: =IFERROR(BDP("/isin/"&$A10,"BB_COMPOSITE"),"") | O10: =IFERROR(BDP("/isin/"&$A10,"DAY_CNT_DES"),"") | P10: =IFERROR(BDP("/isin/"&$A10,"CPN_FREQ"),"") | Q10: =IFERROR(BDP("/isin/"&$A10,"CALLABLE"),"")
B11: =IFERROR(BDP("/isin/"&$A11,"TICKER"),"") | C11: =IFERROR(BDP("/isin/"&$A11,"SECURITY_DES"),"") | D11: =IFERROR(BDP("/isin/"&$A11,"CPN"),"") | E11: =IFERROR(BDP("/isin/"&$A11,"MATURITY"),"") | F11: =IFERROR(BDP("/isin/"&$A11,"ISSUE_DT"),"") | G11: =IFERROR(IF(E11="","",(E11-TODAY())/365.25),"") | H11: =IFERROR(BDP("/isin/"&$A11,"AMT_OUTSTANDING")/1000000,"") | I11: =IFERROR(BDP("/isin/"&$A11,"CRNCY"),"") | J11: =IFERROR(BDP("/isin/"&$A11,"CNTRY_OF_RISK"),"") | K11: =IFERROR(BDP("/isin/"&$A11,"RTG_SP_LT_FC"),"") | L11: =IFERROR(BDP("/isin/"&$A11,"RTG_MDY_LONG_TERM"),"") | M11: =IFERROR(BDP("/isin/"&$A11,"RTG_FITCH_LT_LC_DEBT"),"") | N11: =IFERROR(BDP("/isin/"&$A11,"BB_COMPOSITE"),"") | O11: =IFERROR(BDP("/isin/"&$A11,"DAY_CNT_DES"),"") | P11: =IFERROR(BDP("/isin/"&$A11,"CPN_FREQ"),"") | Q11: =IFERROR(BDP("/isin/"&$A11,"CALLABLE"),"")
B12: =IFERROR(BDP("/isin/"&$A12,"TICKER"),"") | C12: =IFERROR(BDP("/isin/"&$A12,"SECURITY_DES"),"") | D12: =IFERROR(BDP("/isin/"&$A12,"CPN"),"") | E12: =IFERROR(BDP("/isin/"&$A12,"MATURITY"),"") | F12: =IFERROR(BDP("/isin/"&$A12,"ISSUE_DT"),"") | G12: =IFERROR(IF(E12="","",(E12-TODAY())/365.25),"") | H12: =IFERROR(BDP("/isin/"&$A12,"AMT_OUTSTANDING")/1000000,"") | I12: =IFERROR(BDP("/isin/"&$A12,"CRNCY"),"") | J12: =IFERROR(BDP("/isin/"&$A12,"CNTRY_OF_RISK"),"") | K12: =IFERROR(BDP("/isin/"&$A12,"RTG_SP_LT_FC"),"") | L12: =IFERROR(BDP("/isin/"&$A12,"RTG_MDY_LONG_TERM"),"") | M12: =IFERROR(BDP("/isin/"&$A12,"RTG_FITCH_LT_LC_DEBT"),"") | N12: =IFERROR(BDP("/isin/"&$A12,"BB_COMPOSITE"),"") | O12: =IFERROR(BDP("/isin/"&$A12,"DAY_CNT_DES"),"") | P12: =IFERROR(BDP("/isin/"&$A12,"CPN_FREQ"),"") | Q12: =IFERROR(BDP("/isin/"&$A12,"CALLABLE"),"")
B13: =IFERROR(BDP("/isin/"&$A13,"TICKER"),"") | C13: =IFERROR(BDP("/isin/"&$A13,"SECURITY_DES"),"") | D13: =IFERROR(BDP("/isin/"&$A13,"CPN"),"") | E13: =IFERROR(BDP("/isin/"&$A13,"MATURITY"),"") | F13: =IFERROR(BDP("/isin/"&$A13,"ISSUE_DT"),"") | G13: =IFERROR(IF(E13="","",(E13-TODAY())/365.25),"") | H13: =IFERROR(BDP("/isin/"&$A13,"AMT_OUTSTANDING")/1000000,"") | I13: =IFERROR(BDP("/isin/"&$A13,"CRNCY"),"") | J13: =IFERROR(BDP("/isin/"&$A13,"CNTRY_OF_RISK"),"") | K13: =IFERROR(BDP("/isin/"&$A13,"RTG_SP_LT_FC"),"") | L13: =IFERROR(BDP("/isin/"&$A13,"RTG_MDY_LONG_TERM"),"") | M13: =IFERROR(BDP("/isin/"&$A13,"RTG_FITCH_LT_LC_DEBT"),"") | N13: =IFERROR(BDP("/isin/"&$A13,"BB_COMPOSITE"),"") | O13: =IFERROR(BDP("/isin/"&$A13,"DAY_CNT_DES"),"") | P13: =IFERROR(BDP("/isin/"&$A13,"CPN_FREQ"),"") | Q13: =IFERROR(BDP("/isin/"&$A13,"CALLABLE"),"")
... B26: =IFERROR(BDP("/isin/"&$A26,"TICKER"),"") | C26: =IFERROR(BDP("/isin/"&$A26,"SECURITY_DES"),"") | D26: =IFERROR(BDP("/isin/"&$A26,"CPN"),"") | E26: =IFERROR(BDP("/isin/"&$A26,"MATURITY"),"") | F26: =IFERROR(BDP("/isin/"&$A26,"ISSUE_DT"),"") | G26: =IFERROR(IF(E26="","",(E26-TODAY())/365.25),"") | H26: =IFERROR(BDP("/isin/"&$A26,"AMT_OUTSTANDING")/1000000,"") | I26: =IFERROR(BDP("/isin/"&$A26,"CRNCY"),"") | J26: =IFERROR(BDP("/isin/"&$A26,"CNTRY_OF_RISK"),"") | K26: =IFERROR(BDP("/isin/"&$A26,"RTG_SP_LT_FC"),"") | L26: =IFERROR(BDP("/isin/"&$A26,"RTG_MDY_LONG_TERM"),"") | M26: =IFERROR(BDP("/isin/"&$A26,"RTG_FITCH_LT_LC_DEBT"),"") | N26: =IFERROR(BDP("/isin/"&$A26,"BB_COMPOSITE"),"") | O26: =IFERROR(BDP("/isin/"&$A26,"DAY_CNT_DES"),"") | P26: =IFERROR(BDP("/isin/"&$A26,"CPN_FREQ"),"") | Q26: =IFERROR(BDP("/isin/"&$A26,"CALLABLE"),"")

Sheet Bonds_Live
A1: ISIN | B1: Description | C1: Yrs to Maty | D1: Px Bid | E1: Px Ask | F1: Px Mid | G1: Px Last | H1: Bid-Ask (pts) | I1: YTM Bid (%) | J1: YTM Ask (%) | K1: YTM Mid (%) | L1: Z-Spread (bp) | M1: G-Spread (bp) | N1: I-Spread (bp) | O1: OAS (bp) | P1: ASW (bp) | Q1: Mod Duration | R1: Spread Duration | S1: Convexity | T1: DV01 ($/mm) | U1: 1D % | V1: 5D % | W1: 1M %
A2: =IFERROR(IF(Bonds_Static!A2="","",Bonds_Static!A2),"") | B2: =IFERROR(IF(Bonds_Static!C2="","",Bonds_Static!C2),"") | C2: =IFERROR(IF(Bonds_Static!G2="","",Bonds_Static!G2),"") | D2: =IFERROR(BDP("/isin/"&$A2,"PX_BID"),"") | E2: =IFERROR(BDP("/isin/"&$A2,"PX_ASK"),"") | F2: =IFERROR(BDP("/isin/"&$A2,"PX_MID"),"") | G2: =IFERROR(BDP("/isin/"&$A2,"PX_LAST"),"") | H2: =IFERROR(IF(OR(E2="",D2=""),"",E2-D2),"") | I2: =IFERROR(BDP("/isin/"&$A2,"YLD_YTM_BID"),"") | J2: =IFERROR(BDP("/isin/"&$A2,"YLD_YTM_ASK"),"") | K2: =IFERROR(BDP("/isin/"&$A2,"YLD_YTM_MID"),"") | L2: =IFERROR(BDP("/isin/"&$A2,"YAS_ZSPREAD"),"") | M2: =IFERROR(BDP("/isin/"&$A2,"YAS_BOND_SPRD"),"") | N2: =IFERROR(BDP("/isin/"&$A2,"YAS_ISPREAD"),"") | O2: =IFERROR(BDP("/isin/"&$A2,"YAS_OAS"),"") | P2: =IFERROR(BDP("/isin/"&$A2,"YAS_ASW_SPREAD"),"") | Q2: =IFERROR(BDP("/isin/"&$A2,"DUR_ADJ_MID"),"") | R2: =IFERROR(BDP("/isin/"&$A2,"DUR_SPRD_MID"),"") | S2: =IFERROR(BDP("/isin/"&$A2,"CONVEXITY_MID"),"") | T2: =IFERROR(BDP("/isin/"&$A2,"RISK_MID"),"") | U2: =IFERROR(BDP("/isin/"&$A2,"PX_CHG_PCT_1D"),"") | V2: =IFERROR(BDP("/isin/"&$A2,"PX_CHG_PCT_5D"),"") | W2: =IFERROR(BDP("/isin/"&$A2,"PX_CHG_PCT_1MO"),"")
A3: =IFERROR(IF(Bonds_Static!A3="","",Bonds_Static!A3),"") | B3: =IFERROR(IF(Bonds_Static!C3="","",Bonds_Static!C3),"") | C3: =IFERROR(IF(Bonds_Static!G3="","",Bonds_Static!G3),"") | D3: =IFERROR(BDP("/isin/"&$A3,"PX_BID"),"") | E3: =IFERROR(BDP("/isin/"&$A3,"PX_ASK"),"") | F3: =IFERROR(BDP("/isin/"&$A3,"PX_MID"),"") | G3: =IFERROR(BDP("/isin/"&$A3,"PX_LAST"),"") | H3: =IFERROR(IF(OR(E3="",D3=""),"",E3-D3),"") | I3: =IFERROR(BDP("/isin/"&$A3,"YLD_YTM_BID"),"") | J3: =IFERROR(BDP("/isin/"&$A3,"YLD_YTM_ASK"),"") | K3: =IFERROR(BDP("/isin/"&$A3,"YLD_YTM_MID"),"") | L3: =IFERROR(BDP("/isin/"&$A3,"YAS_ZSPREAD"),"") | M3: =IFERROR(BDP("/isin/"&$A3,"YAS_BOND_SPRD"),"") | N3: =IFERROR(BDP("/isin/"&$A3,"YAS_ISPREAD"),"") | O3: =IFERROR(BDP("/isin/"&$A3,"YAS_OAS"),"") | P3: =IFERROR(BDP("/isin/"&$A3,"YAS_ASW_SPREAD"),"") | Q3: =IFERROR(BDP("/isin/"&$A3,"DUR_ADJ_MID"),"") | R3: =IFERROR(BDP("/isin/"&$A3,"DUR_SPRD_MID"),"") | S3: =IFERROR(BDP("/isin/"&$A3,"CONVEXITY_MID"),"") | T3: =IFERROR(BDP("/isin/"&$A3,"RISK_MID"),"") | U3: =IFERROR(BDP("/isin/"&$A3,"PX_CHG_PCT_1D"),"") | V3: =IFERROR(BDP("/isin/"&$A3,"PX_CHG_PCT_5D"),"") | W3: =IFERROR(BDP("/isin/"&$A3,"PX_CHG_PCT_1MO"),"")
A4: =IFERROR(IF(Bonds_Static!A4="","",Bonds_Static!A4),"") | B4: =IFERROR(IF(Bonds_Static!C4="","",Bonds_Static!C4),"") | C4: =IFERROR(IF(Bonds_Static!G4="","",Bonds_Static!G4),"") | D4: =IFERROR(BDP("/isin/"&$A4,"PX_BID"),"") | E4: =IFERROR(BDP("/isin/"&$A4,"PX_ASK"),"") | F4: =IFERROR(BDP("/isin/"&$A4,"PX_MID"),"") | G4: =IFERROR(BDP("/isin/"&$A4,"PX_LAST"),"") | H4: =IFERROR(IF(OR(E4="",D4=""),"",E4-D4),"") | I4: =IFERROR(BDP("/isin/"&$A4,"YLD_YTM_BID"),"") | J4: =IFERROR(BDP("/isin/"&$A4,"YLD_YTM_ASK"),"") | K4: =IFERROR(BDP("/isin/"&$A4,"YLD_YTM_MID"),"") | L4: =IFERROR(BDP("/isin/"&$A4,"YAS_ZSPREAD"),"") | M4: =IFERROR(BDP("/isin/"&$A4,"YAS_BOND_SPRD"),"") | N4: =IFERROR(BDP("/isin/"&$A4,"YAS_ISPREAD"),"") | O4: =IFERROR(BDP("/isin/"&$A4,"YAS_OAS"),"") | P4: =IFERROR(BDP("/isin/"&$A4,"YAS_ASW_SPREAD"),"") | Q4: =IFERROR(BDP("/isin/"&$A4,"DUR_ADJ_MID"),"") | R4: =IFERROR(BDP("/isin/"&$A4,"DUR_SPRD_MID"),"") | S4: =IFERROR(BDP("/isin/"&$A4,"CONVEXITY_MID"),"") | T4: =IFERROR(BDP("/isin/"&$A4,"RISK_MID"),"") | U4: =IFERROR(BDP("/isin/"&$A4,"PX_CHG_PCT_1D"),"") | V4: =IFERROR(BDP("/isin/"&$A4,"PX_CHG_PCT_5D"),"") | W4: =IFERROR(BDP("/isin/"&$A4,"PX_CHG_PCT_1MO"),"")
A5: =IFERROR(IF(Bonds_Static!A5="","",Bonds_Static!A5),"") | B5: =IFERROR(IF(Bonds_Static!C5="","",Bonds_Static!C5),"") | C5: =IFERROR(IF(Bonds_Static!G5="","",Bonds_Static!G5),"") | D5: =IFERROR(BDP("/isin/"&$A5,"PX_BID"),"") | E5: =IFERROR(BDP("/isin/"&$A5,"PX_ASK"),"") | F5: =IFERROR(BDP("/isin/"&$A5,"PX_MID"),"") | G5: =IFERROR(BDP("/isin/"&$A5,"PX_LAST"),"") | H5: =IFERROR(IF(OR(E5="",D5=""),"",E5-D5),"") | I5: =IFERROR(BDP("/isin/"&$A5,"YLD_YTM_BID"),"") | J5: =IFERROR(BDP("/isin/"&$A5,"YLD_YTM_ASK"),"") | K5: =IFERROR(BDP("/isin/"&$A5,"YLD_YTM_MID"),"") | L5: =IFERROR(BDP("/isin/"&$A5,"YAS_ZSPREAD"),"") | M5: =IFERROR(BDP("/isin/"&$A5,"YAS_BOND_SPRD"),"") | N5: =IFERROR(BDP("/isin/"&$A5,"YAS_ISPREAD"),"") | O5: =IFERROR(BDP("/isin/"&$A5,"YAS_OAS"),"") | P5: =IFERROR(BDP("/isin/"&$A5,"YAS_ASW_SPREAD"),"") | Q5: =IFERROR(BDP("/isin/"&$A5,"DUR_ADJ_MID"),"") | R5: =IFERROR(BDP("/isin/"&$A5,"DUR_SPRD_MID"),"") | S5: =IFERROR(BDP("/isin/"&$A5,"CONVEXITY_MID"),"") | T5: =IFERROR(BDP("/isin/"&$A5,"RISK_MID"),"") | U5: =IFERROR(BDP("/isin/"&$A5,"PX_CHG_PCT_1D"),"") | V5: =IFERROR(BDP("/isin/"&$A5,"PX_CHG_PCT_5D"),"") | W5: =IFERROR(BDP("/isin/"&$A5,"PX_CHG_PCT_1MO"),"")
A6: =IFERROR(IF(Bonds_Static!A6="","",Bonds_Static!A6),"") | B6: =IFERROR(IF(Bonds_Static!C6="","",Bonds_Static!C6),"") | C6: =IFERROR(IF(Bonds_Static!G6="","",Bonds_Static!G6),"") | D6: =IFERROR(BDP("/isin/"&$A6,"PX_BID"),"") | E6: =IFERROR(BDP("/isin/"&$A6,"PX_ASK"),"") | F6: =IFERROR(BDP("/isin/"&$A6,"PX_MID"),"") | G6: =IFERROR(BDP("/isin/"&$A6,"PX_LAST"),"") | H6: =IFERROR(IF(OR(E6="",D6=""),"",E6-D6),"") | I6: =IFERROR(BDP("/isin/"&$A6,"YLD_YTM_BID"),"") | J6: =IFERROR(BDP("/isin/"&$A6,"YLD_YTM_ASK"),"") | K6: =IFERROR(BDP("/isin/"&$A6,"YLD_YTM_MID"),"") | L6: =IFERROR(BDP("/isin/"&$A6,"YAS_ZSPREAD"),"") | M6: =IFERROR(BDP("/isin/"&$A6,"YAS_BOND_SPRD"),"") | N6: =IFERROR(BDP("/isin/"&$A6,"YAS_ISPREAD"),"") | O6: =IFERROR(BDP("/isin/"&$A6,"YAS_OAS"),"") | P6: =IFERROR(BDP("/isin/"&$A6,"YAS_ASW_SPREAD"),"") | Q6: =IFERROR(BDP("/isin/"&$A6,"DUR_ADJ_MID"),"") | R6: =IFERROR(BDP("/isin/"&$A6,"DUR_SPRD_MID"),"") | S6: =IFERROR(BDP("/isin/"&$A6,"CONVEXITY_MID"),"") | T6: =IFERROR(BDP("/isin/"&$A6,"RISK_MID"),"") | U6: =IFERROR(BDP("/isin/"&$A6,"PX_CHG_PCT_1D"),"") | V6: =IFERROR(BDP("/isin/"&$A6,"PX_CHG_PCT_5D"),"") | W6: =IFERROR(BDP("/isin/"&$A6,"PX_CHG_PCT_1MO"),"")
A7: =IFERROR(IF(Bonds_Static!A7="","",Bonds_Static!A7),"") | B7: =IFERROR(IF(Bonds_Static!C7="","",Bonds_Static!C7),"") | C7: =IFERROR(IF(Bonds_Static!G7="","",Bonds_Static!G7),"") | D7: =IFERROR(BDP("/isin/"&$A7,"PX_BID"),"") | E7: =IFERROR(BDP("/isin/"&$A7,"PX_ASK"),"") | F7: =IFERROR(BDP("/isin/"&$A7,"PX_MID"),"") | G7: =IFERROR(BDP("/isin/"&$A7,"PX_LAST"),"") | H7: =IFERROR(IF(OR(E7="",D7=""),"",E7-D7),"") | I7: =IFERROR(BDP("/isin/"&$A7,"YLD_YTM_BID"),"") | J7: =IFERROR(BDP("/isin/"&$A7,"YLD_YTM_ASK"),"") | K7: =IFERROR(BDP("/isin/"&$A7,"YLD_YTM_MID"),"") | L7: =IFERROR(BDP("/isin/"&$A7,"YAS_ZSPREAD"),"") | M7: =IFERROR(BDP("/isin/"&$A7,"YAS_BOND_SPRD"),"") | N7: =IFERROR(BDP("/isin/"&$A7,"YAS_ISPREAD"),"") | O7: =IFERROR(BDP("/isin/"&$A7,"YAS_OAS"),"") | P7: =IFERROR(BDP("/isin/"&$A7,"YAS_ASW_SPREAD"),"") | Q7: =IFERROR(BDP("/isin/"&$A7,"DUR_ADJ_MID"),"") | R7: =IFERROR(BDP("/isin/"&$A7,"DUR_SPRD_MID"),"") | S7: =IFERROR(BDP("/isin/"&$A7,"CONVEXITY_MID"),"") | T7: =IFERROR(BDP("/isin/"&$A7,"RISK_MID"),"") | U7: =IFERROR(BDP("/isin/"&$A7,"PX_CHG_PCT_1D"),"") | V7: =IFERROR(BDP("/isin/"&$A7,"PX_CHG_PCT_5D"),"") | W7: =IFERROR(BDP("/isin/"&$A7,"PX_CHG_PCT_1MO"),"")
A8: =IFERROR(IF(Bonds_Static!A8="","",Bonds_Static!A8),"") | B8: =IFERROR(IF(Bonds_Static!C8="","",Bonds_Static!C8),"") | C8: =IFERROR(IF(Bonds_Static!G8="","",Bonds_Static!G8),"") | D8: =IFERROR(BDP("/isin/"&$A8,"PX_BID"),"") | E8: =IFERROR(BDP("/isin/"&$A8,"PX_ASK"),"") | F8: =IFERROR(BDP("/isin/"&$A8,"PX_MID"),"") | G8: =IFERROR(BDP("/isin/"&$A8,"PX_LAST"),"") | H8: =IFERROR(IF(OR(E8="",D8=""),"",E8-D8),"") | I8: =IFERROR(BDP("/isin/"&$A8,"YLD_YTM_BID"),"") | J8: =IFERROR(BDP("/isin/"&$A8,"YLD_YTM_ASK"),"") | K8: =IFERROR(BDP("/isin/"&$A8,"YLD_YTM_MID"),"") | L8: =IFERROR(BDP("/isin/"&$A8,"YAS_ZSPREAD"),"") | M8: =IFERROR(BDP("/isin/"&$A8,"YAS_BOND_SPRD"),"") | N8: =IFERROR(BDP("/isin/"&$A8,"YAS_ISPREAD"),"") | O8: =IFERROR(BDP("/isin/"&$A8,"YAS_OAS"),"") | P8: =IFERROR(BDP("/isin/"&$A8,"YAS_ASW_SPREAD"),"") | Q8: =IFERROR(BDP("/isin/"&$A8,"DUR_ADJ_MID"),"") | R8: =IFERROR(BDP("/isin/"&$A8,"DUR_SPRD_MID"),"") | S8: =IFERROR(BDP("/isin/"&$A8,"CONVEXITY_MID"),"") | T8: =IFERROR(BDP("/isin/"&$A8,"RISK_MID"),"") | U8: =IFERROR(BDP("/isin/"&$A8,"PX_CHG_PCT_1D"),"") | V8: =IFERROR(BDP("/isin/"&$A8,"PX_CHG_PCT_5D"),"") | W8: =IFERROR(BDP("/isin/"&$A8,"PX_CHG_PCT_1MO"),"")
A9: =IFERROR(IF(Bonds_Static!A9="","",Bonds_Static!A9),"") | B9: =IFERROR(IF(Bonds_Static!C9="","",Bonds_Static!C9),"") | C9: =IFERROR(IF(Bonds_Static!G9="","",Bonds_Static!G9),"") | D9: =IFERROR(BDP("/isin/"&$A9,"PX_BID"),"") | E9: =IFERROR(BDP("/isin/"&$A9,"PX_ASK"),"") | F9: =IFERROR(BDP("/isin/"&$A9,"PX_MID"),"") | G9: =IFERROR(BDP("/isin/"&$A9,"PX_LAST"),"") | H9: =IFERROR(IF(OR(E9="",D9=""),"",E9-D9),"") | I9: =IFERROR(BDP("/isin/"&$A9,"YLD_YTM_BID"),"") | J9: =IFERROR(BDP("/isin/"&$A9,"YLD_YTM_ASK"),"") | K9: =IFERROR(BDP("/isin/"&$A9,"YLD_YTM_MID"),"") | L9: =IFERROR(BDP("/isin/"&$A9,"YAS_ZSPREAD"),"") | M9: =IFERROR(BDP("/isin/"&$A9,"YAS_BOND_SPRD"),"") | N9: =IFERROR(BDP("/isin/"&$A9,"YAS_ISPREAD"),"") | O9: =IFERROR(BDP("/isin/"&$A9,"YAS_OAS"),"") | P9: =IFERROR(BDP("/isin/"&$A9,"YAS_ASW_SPREAD"),"") | Q9: =IFERROR(BDP("/isin/"&$A9,"DUR_ADJ_MID"),"") | R9: =IFERROR(BDP("/isin/"&$A9,"DUR_SPRD_MID"),"") | S9: =IFERROR(BDP("/isin/"&$A9,"CONVEXITY_MID"),"") | T9: =IFERROR(BDP("/isin/"&$A9,"RISK_MID"),"") | U9: =IFERROR(BDP("/isin/"&$A9,"PX_CHG_PCT_1D"),"") | V9: =IFERROR(BDP("/isin/"&$A9,"PX_CHG_PCT_5D"),"") | W9: =IFERROR(BDP("/isin/"&$A9,"PX_CHG_PCT_1MO"),"")
A10: =IFERROR(IF(Bonds_Static!A10="","",Bonds_Static!A10),"") | B10: =IFERROR(IF(Bonds_Static!C10="","",Bonds_Static!C10),"") | C10: =IFERROR(IF(Bonds_Static!G10="","",Bonds_Static!G10),"") | D10: =IFERROR(BDP("/isin/"&$A10,"PX_BID"),"") | E10: =IFERROR(BDP("/isin/"&$A10,"PX_ASK"),"") | F10: =IFERROR(BDP("/isin/"&$A10,"PX_MID"),"") | G10: =IFERROR(BDP("/isin/"&$A10,"PX_LAST"),"") | H10: =IFERROR(IF(OR(E10="",D10=""),"",E10-D10),"") | I10: =IFERROR(BDP("/isin/"&$A10,"YLD_YTM_BID"),"") | J10: =IFERROR(BDP("/isin/"&$A10,"YLD_YTM_ASK"),"") | K10: =IFERROR(BDP("/isin/"&$A10,"YLD_YTM_MID"),"") | L10: =IFERROR(BDP("/isin/"&$A10,"YAS_ZSPREAD"),"") | M10: =IFERROR(BDP("/isin/"&$A10,"YAS_BOND_SPRD"),"") | N10: =IFERROR(BDP("/isin/"&$A10,"YAS_ISPREAD"),"") | O10: =IFERROR(BDP("/isin/"&$A10,"YAS_OAS"),"") | P10: =IFERROR(BDP("/isin/"&$A10,"YAS_ASW_SPREAD"),"") | Q10: =IFERROR(BDP("/isin/"&$A10,"DUR_ADJ_MID"),"") | R10: =IFERROR(BDP("/isin/"&$A10,"DUR_SPRD_MID"),"") | S10: =IFERROR(BDP("/isin/"&$A10,"CONVEXITY_MID"),"") | T10: =IFERROR(BDP("/isin/"&$A10,"RISK_MID"),"") | U10: =IFERROR(BDP("/isin/"&$A10,"PX_CHG_PCT_1D"),"") | V10: =IFERROR(BDP("/isin/"&$A10,"PX_CHG_PCT_5D"),"") | W10: =IFERROR(BDP("/isin/"&$A10,"PX_CHG_PCT_1MO"),"")
A11: =IFERROR(IF(Bonds_Static!A11="","",Bonds_Static!A11),"") | B11: =IFERROR(IF(Bonds_Static!C11="","",Bonds_Static!C11),"") | C11: =IFERROR(IF(Bonds_Static!G11="","",Bonds_Static!G11),"") | D11: =IFERROR(BDP("/isin/"&$A11,"PX_BID"),"") | E11: =IFERROR(BDP("/isin/"&$A11,"PX_ASK"),"") | F11: =IFERROR(BDP("/isin/"&$A11,"PX_MID"),"") | G11: =IFERROR(BDP("/isin/"&$A11,"PX_LAST"),"") | H11: =IFERROR(IF(OR(E11="",D11=""),"",E11-D11),"") | I11: =IFERROR(BDP("/isin/"&$A11,"YLD_YTM_BID"),"") | J11: =IFERROR(BDP("/isin/"&$A11,"YLD_YTM_ASK"),"") | K11: =IFERROR(BDP("/isin/"&$A11,"YLD_YTM_MID"),"") | L11: =IFERROR(BDP("/isin/"&$A11,"YAS_ZSPREAD"),"") | M11: =IFERROR(BDP("/isin/"&$A11,"YAS_BOND_SPRD"),"") | N11: =IFERROR(BDP("/isin/"&$A11,"YAS_ISPREAD"),"") | O11: =IFERROR(BDP("/isin/"&$A11,"YAS_OAS"),"") | P11: =IFERROR(BDP("/isin/"&$A11,"YAS_ASW_SPREAD"),"") | Q11: =IFERROR(BDP("/isin/"&$A11,"DUR_ADJ_MID"),"") | R11: =IFERROR(BDP("/isin/"&$A11,"DUR_SPRD_MID"),"") | S11: =IFERROR(BDP("/isin/"&$A11,"CONVEXITY_MID"),"") | T11: =IFERROR(BDP("/isin/"&$A11,"RISK_MID"),"") | U11: =IFERROR(BDP("/isin/"&$A11,"PX_CHG_PCT_1D"),"") | V11: =IFERROR(BDP("/isin/"&$A11,"PX_CHG_PCT_5D"),"") | W11: =IFERROR(BDP("/isin/"&$A11,"PX_CHG_PCT_1MO"),"")
A12: =IFERROR(IF(Bonds_Static!A12="","",Bonds_Static!A12),"") | B12: =IFERROR(IF(Bonds_Static!C12="","",Bonds_Static!C12),"") | C12: =IFERROR(IF(Bonds_Static!G12="","",Bonds_Static!G12),"") | D12: =IFERROR(BDP("/isin/"&$A12,"PX_BID"),"") | E12: =IFERROR(BDP("/isin/"&$A12,"PX_ASK"),"") | F12: =IFERROR(BDP("/isin/"&$A12,"PX_MID"),"") | G12: =IFERROR(BDP("/isin/"&$A12,"PX_LAST"),"") | H12: =IFERROR(IF(OR(E12="",D12=""),"",E12-D12),"") | I12: =IFERROR(BDP("/isin/"&$A12,"YLD_YTM_BID"),"") | J12: =IFERROR(BDP("/isin/"&$A12,"YLD_YTM_ASK"),"") | K12: =IFERROR(BDP("/isin/"&$A12,"YLD_YTM_MID"),"") | L12: =IFERROR(BDP("/isin/"&$A12,"YAS_ZSPREAD"),"") | M12: =IFERROR(BDP("/isin/"&$A12,"YAS_BOND_SPRD"),"") | N12: =IFERROR(BDP("/isin/"&$A12,"YAS_ISPREAD"),"") | O12: =IFERROR(BDP("/isin/"&$A12,"YAS_OAS"),"") | P12: =IFERROR(BDP("/isin/"&$A12,"YAS_ASW_SPREAD"),"") | Q12: =IFERROR(BDP("/isin/"&$A12,"DUR_ADJ_MID"),"") | R12: =IFERROR(BDP("/isin/"&$A12,"DUR_SPRD_MID"),"") | S12: =IFERROR(BDP("/isin/"&$A12,"CONVEXITY_MID"),"") | T12: =IFERROR(BDP("/isin/"&$A12,"RISK_MID"),"") | U12: =IFERROR(BDP("/isin/"&$A12,"PX_CHG_PCT_1D"),"") | V12: =IFERROR(BDP("/isin/"&$A12,"PX_CHG_PCT_5D"),"") | W12: =IFERROR(BDP("/isin/"&$A12,"PX_CHG_PCT_1MO"),"")
A13: =IFERROR(IF(Bonds_Static!A13="","",Bonds_Static!A13),"") | B13: =IFERROR(IF(Bonds_Static!C13="","",Bonds_Static!C13),"") | C13: =IFERROR(IF(Bonds_Static!G13="","",Bonds_Static!G13),"") | D13: =IFERROR(BDP("/isin/"&$A13,"PX_BID"),"") | E13: =IFERROR(BDP("/isin/"&$A13,"PX_ASK"),"") | F13: =IFERROR(BDP("/isin/"&$A13,"PX_MID"),"") | G13: =IFERROR(BDP("/isin/"&$A13,"PX_LAST"),"") | H13: =IFERROR(IF(OR(E13="",D13=""),"",E13-D13),"") | I13: =IFERROR(BDP("/isin/"&$A13,"YLD_YTM_BID"),"") | J13: =IFERROR(BDP("/isin/"&$A13,"YLD_YTM_ASK"),"") | K13: =IFERROR(BDP("/isin/"&$A13,"YLD_YTM_MID"),"") | L13: =IFERROR(BDP("/isin/"&$A13,"YAS_ZSPREAD"),"") | M13: =IFERROR(BDP("/isin/"&$A13,"YAS_BOND_SPRD"),"") | N13: =IFERROR(BDP("/isin/"&$A13,"YAS_ISPREAD"),"") | O13: =IFERROR(BDP("/isin/"&$A13,"YAS_OAS"),"") | P13: =IFERROR(BDP("/isin/"&$A13,"YAS_ASW_SPREAD"),"") | Q13: =IFERROR(BDP("/isin/"&$A13,"DUR_ADJ_MID"),"") | R13: =IFERROR(BDP("/isin/"&$A13,"DUR_SPRD_MID"),"") | S13: =IFERROR(BDP("/isin/"&$A13,"CONVEXITY_MID"),"") | T13: =IFERROR(BDP("/isin/"&$A13,"RISK_MID"),"") | U13: =IFERROR(BDP("/isin/"&$A13,"PX_CHG_PCT_1D"),"") | V13: =IFERROR(BDP("/isin/"&$A13,"PX_CHG_PCT_5D"),"") | W13: =IFERROR(BDP("/isin/"&$A13,"PX_CHG_PCT_1MO"),"")
... A26: =IFERROR(IF(Bonds_Static!A26="","",Bonds_Static!A26),"") | B26: =IFERROR(IF(Bonds_Static!C26="","",Bonds_Static!C26),"") | C26: =IFERROR(IF(Bonds_Static!G26="","",Bonds_Static!G26),"") | D26: =IFERROR(BDP("/isin/"&$A26,"PX_BID"),"") | E26: =IFERROR(BDP("/isin/"&$A26,"PX_ASK"),"") | F26: =IFERROR(BDP("/isin/"&$A26,"PX_MID"),"") | G26: =IFERROR(BDP("/isin/"&$A26,"PX_LAST"),"") | H26: =IFERROR(IF(OR(E26="",D26=""),"",E26-D26),"") | I26: =IFERROR(BDP("/isin/"&$A26,"YLD_YTM_BID"),"") | J26: =IFERROR(BDP("/isin/"&$A26,"YLD_YTM_ASK"),"") | K26: =IFERROR(BDP("/isin/"&$A26,"YLD_YTM_MID"),"") | L26: =IFERROR(BDP("/isin/"&$A26,"YAS_ZSPREAD"),"") | M26: =IFERROR(BDP("/isin/"&$A26,"YAS_BOND_SPRD"),"") | N26: =IFERROR(BDP("/isin/"&$A26,"YAS_ISPREAD"),"") | O26: =IFERROR(BDP("/isin/"&$A26,"YAS_OAS"),"") | P26: =IFERROR(BDP("/isin/"&$A26,"YAS_ASW_SPREAD"),"") | Q26: =IFERROR(BDP("/isin/"&$A26,"DUR_ADJ_MID"),"") | R26: =IFERROR(BDP("/isin/"&$A26,"DUR_SPRD_MID"),"") | S26: =IFERROR(BDP("/isin/"&$A26,"CONVEXITY_MID"),"") | T26: =IFERROR(BDP("/isin/"&$A26,"RISK_MID"),"") | U26: =IFERROR(BDP("/isin/"&$A26,"PX_CHG_PCT_1D"),"") | V26: =IFERROR(BDP("/isin/"&$A26,"PX_CHG_PCT_5D"),"") | W26: =IFERROR(BDP("/isin/"&$A26,"PX_CHG_PCT_1MO"),"")

Sheet UST_Curve
A1: Tenor | B1: BBG Ticker | C1: Yield (%) | D1: 1D Δ (bp) | E1: 5D Δ (bp) | F1: 1M Δ (bp)
A2: 3M | B2: USGG3M Index | C2: =IFERROR(BDP("USGG3M Index","PX_LAST"),"") | D2: =IFERROR(BDP("USGG3M Index","CHG_PCT_1D")*100,"") | E2: =IFERROR(BDP("USGG3M Index","CHG_PCT_5D")*100,"") | F2: =IFERROR(BDP("USGG3M Index","CHG_PCT_1M")*100,"")
A3: 6M | B3: USGG6M Index | C3: =IFERROR(BDP("USGG6M Index","PX_LAST"),"") | D3: =IFERROR(BDP("USGG6M Index","CHG_PCT_1D")*100,"") | E3: =IFERROR(BDP("USGG6M Index","CHG_PCT_5D")*100,"") | F3: =IFERROR(BDP("USGG6M Index","CHG_PCT_1M")*100,"")
A4: 1Y | B4: USGG12M Index | C4: =IFERROR(BDP("USGG12M Index","PX_LAST"),"") | D4: =IFERROR(BDP("USGG12M Index","CHG_PCT_1D")*100,"") | E4: =IFERROR(BDP("USGG12M Index","CHG_PCT_5D")*100,"") | F4: =IFERROR(BDP("USGG12M Index","CHG_PCT_1M")*100,"")
A5: 2Y | B5: USGG2YR Index | C5: =IFERROR(BDP("USGG2YR Index","PX_LAST"),"") | D5: =IFERROR(BDP("USGG2YR Index","CHG_PCT_1D")*100,"") | E5: =IFERROR(BDP("USGG2YR Index","CHG_PCT_5D")*100,"") | F5: =IFERROR(BDP("USGG2YR Index","CHG_PCT_1M")*100,"")
A6: 3Y | B6: USGG3YR Index | C6: =IFERROR(BDP("USGG3YR Index","PX_LAST"),"") | D6: =IFERROR(BDP("USGG3YR Index","CHG_PCT_1D")*100,"") | E6: =IFERROR(BDP("USGG3YR Index","CHG_PCT_5D")*100,"") | F6: =IFERROR(BDP("USGG3YR Index","CHG_PCT_1M")*100,"")
A7: 5Y | B7: USGG5YR Index | C7: =IFERROR(BDP("USGG5YR Index","PX_LAST"),"") | D7: =IFERROR(BDP("USGG5YR Index","CHG_PCT_1D")*100,"") | E7: =IFERROR(BDP("USGG5YR Index","CHG_PCT_5D")*100,"") | F7: =IFERROR(BDP("USGG5YR Index","CHG_PCT_1M")*100,"")
A8: 7Y | B8: USGG7YR Index | C8: =IFERROR(BDP("USGG7YR Index","PX_LAST"),"") | D8: =IFERROR(BDP("USGG7YR Index","CHG_PCT_1D")*100,"") | E8: =IFERROR(BDP("USGG7YR Index","CHG_PCT_5D")*100,"") | F8: =IFERROR(BDP("USGG7YR Index","CHG_PCT_1M")*100,"")
A9: 10Y | B9: USGG10YR Index | C9: =IFERROR(BDP("USGG10YR Index","PX_LAST"),"") | D9: =IFERROR(BDP("USGG10YR Index","CHG_PCT_1D")*100,"") | E9: =IFERROR(BDP("USGG10YR Index","CHG_PCT_5D")*100,"") | F9: =IFERROR(BDP("USGG10YR Index","CHG_PCT_1M")*100,"")
A10: 20Y | B10: USGG20YR Index | C10: =IFERROR(BDP("USGG20YR Index","PX_LAST"),"") | D10: =IFERROR(BDP("USGG20YR Index","CHG_PCT_1D")*100,"") | E10: =IFERROR(BDP("USGG20YR Index","CHG_PCT_5D")*100,"") | F10: =IFERROR(BDP("USGG20YR Index","CHG_PCT_1M")*100,"")
A11: 30Y | B11: USGG30YR Index | C11: =IFERROR(BDP("USGG30YR Index","PX_LAST"),"") | D11: =IFERROR(BDP("USGG30YR Index","CHG_PCT_1D")*100,"") | E11: =IFERROR(BDP("USGG30YR Index","CHG_PCT_5D")*100,"") | F11: =IFERROR(BDP("USGG30YR Index","CHG_PCT_1M")*100,"")
A14: Curve slopes (bp)
A15: 2s10s | C15: =IFERROR((C8-C5)*100,"")
A16: 5s30s | C16: =IFERROR((C11-C7)*100,"")
A17: 2s30s | C17: =IFERROR((C11-C5)*100,"")
A18: 10s30s | C18: =IFERROR((C11-C8)*100,"")
A21: Rates Volatility Regime (MOVE Index)
A22: MOVE level | B22: MOVE Index | C22: =IFERROR(BDP("MOVE Index","PX_LAST"),"")
A23: 1Y avg | C23: =IFERROR(AVERAGE(INDEX(BDH("MOVE Index","PX_LAST","-1Y","0D"),0,2)),"")
A24: 1Y stdev | C24: =IFERROR(STDEV(INDEX(BDH("MOVE Index","PX_LAST","-1Y","0D"),0,2)),"")
A25: 1Y percentile (current) | C25: =IFERROR(PERCENTRANK.INC(INDEX(BDH("MOVE Index","PX_LAST","-1Y","0D"),0,2),C22)*100,"")
A26: Regime | C26: =IFERROR(IF(C25="","",IF(C25>=Settings!$C$55,"EXTREME",IF(C25>=Settings!$C$54,"HIGH","NORMAL"))),"")
A27: Position size scalar | C27: =IFERROR(IF(C26="","",IF(C26="EXTREME",Settings!$C$57,IF(C26="HIGH",Settings!$C$56,1))),"")

Sheet Curve_Fit
A1: ISIN | B1: Description | C1: τ (yrs) | D1: Actual YTM | E1: Modeled YTM | F1: Residual (bp) | H1: LINEST coefficient block
A2: =Bonds_Static!A2 | B2: =Bonds_Static!C2 | C2: =IFERROR(Bonds_Static!G2,"") | D2: =IFERROR(Bonds_Live!K2/100,"") | E2: =IFERROR(IF(C2="","",$H$5 + $H$4*C2 + $H$3*C2^2 + $H$2*C2^3),"") | F2: =IFERROR(IF(OR(D2="",E2=""),"",(D2-E2)*10000),"") | H2: =IFERROR(INDEX(LINEST(D2:D26,C2:C26^{1,2,3},TRUE,TRUE),1,1),"") | I2: a3 (τ³ coeff)
A3: =Bonds_Static!A3 | B3: =Bonds_Static!C3 | C3: =IFERROR(Bonds_Static!G3,"") | D3: =IFERROR(Bonds_Live!K3/100,"") | E3: =IFERROR(IF(C3="","",$H$5 + $H$4*C3 + $H$3*C3^2 + $H$2*C3^3),"") | F3: =IFERROR(IF(OR(D3="",E3=""),"",(D3-E3)*10000),"") | H3: =IFERROR(INDEX(LINEST(D2:D26,C2:C26^{1,2,3},TRUE,TRUE),1,2),"") | I3: a2 (τ² coeff)
A4: =Bonds_Static!A4 | B4: =Bonds_Static!C4 | C4: =IFERROR(Bonds_Static!G4,"") | D4: =IFERROR(Bonds_Live!K4/100,"") | E4: =IFERROR(IF(C4="","",$H$5 + $H$4*C4 + $H$3*C4^2 + $H$2*C4^3),"") | F4: =IFERROR(IF(OR(D4="",E4=""),"",(D4-E4)*10000),"") | H4: =IFERROR(INDEX(LINEST(D2:D26,C2:C26^{1,2,3},TRUE,TRUE),1,3),"") | I4: a1 (τ coeff)
A5: =Bonds_Static!A5 | B5: =Bonds_Static!C5 | C5: =IFERROR(Bonds_Static!G5,"") | D5: =IFERROR(Bonds_Live!K5/100,"") | E5: =IFERROR(IF(C5="","",$H$5 + $H$4*C5 + $H$3*C5^2 + $H$2*C5^3),"") | F5: =IFERROR(IF(OR(D5="",E5=""),"",(D5-E5)*10000),"") | H5: =IFERROR(INDEX(LINEST(D2:D26,C2:C26^{1,2,3},TRUE,TRUE),1,4),"") | I5: a0 (intercept)
A6: =Bonds_Static!A6 | B6: =Bonds_Static!C6 | C6: =IFERROR(Bonds_Static!G6,"") | D6: =IFERROR(Bonds_Live!K6/100,"") | E6: =IFERROR(IF(C6="","",$H$5 + $H$4*C6 + $H$3*C6^2 + $H$2*C6^3),"") | F6: =IFERROR(IF(OR(D6="",E6=""),"",(D6-E6)*10000),"")
A7: =Bonds_Static!A7 | B7: =Bonds_Static!C7 | C7: =IFERROR(Bonds_Static!G7,"") | D7: =IFERROR(Bonds_Live!K7/100,"") | E7: =IFERROR(IF(C7="","",$H$5 + $H$4*C7 + $H$3*C7^2 + $H$2*C7^3),"") | F7: =IFERROR(IF(OR(D7="",E7=""),"",(D7-E7)*10000),"") | H7: =IFERROR(INDEX(LINEST(D2:D26,C2:C26^{1,2,3},TRUE,TRUE),3,1),"") | I7: R²
A8: =Bonds_Static!A8 | B8: =Bonds_Static!C8 | C8: =IFERROR(Bonds_Static!G8,"") | D8: =IFERROR(Bonds_Live!K8/100,"") | E8: =IFERROR(IF(C8="","",$H$5 + $H$4*C8 + $H$3*C8^2 + $H$2*C8^3),"") | F8: =IFERROR(IF(OR(D8="",E8=""),"",(D8-E8)*10000),"")
A9: =Bonds_Static!A9 | B9: =Bonds_Static!C9 | C9: =IFERROR(Bonds_Static!G9,"") | D9: =IFERROR(Bonds_Live!K9/100,"") | E9: =IFERROR(IF(C9="","",$H$5 + $H$4*C9 + $H$3*C9^2 + $H$2*C9^3),"") | F9: =IFERROR(IF(OR(D9="",E9=""),"",(D9-E9)*10000),"") | H9: Coefficients refit automatically each time yields refresh — no Solver needed.
A10: =Bonds_Static!A10 | B10: =Bonds_Static!C10 | C10: =IFERROR(Bonds_Static!G10,"") | D10: =IFERROR(Bonds_Live!K10/100,"") | E10: =IFERROR(IF(C10="","",$H$5 + $H$4*C10 + $H$3*C10^2 + $H$2*C10^3),"") | F10: =IFERROR(IF(OR(D10="",E10=""),"",(D10-E10)*10000),"")
A11: =Bonds_Static!A11 | B11: =Bonds_Static!C11 | C11: =IFERROR(Bonds_Static!G11,"") | D11: =IFERROR(Bonds_Live!K11/100,"") | E11: =IFERROR(IF(C11="","",$H$5 + $H$4*C11 + $H$3*C11^2 + $H$2*C11^3),"") | F11: =IFERROR(IF(OR(D11="",E11=""),"",(D11-E11)*10000),"")
A12: =Bonds_Static!A12 | B12: =Bonds_Static!C12 | C12: =IFERROR(Bonds_Static!G12,"") | D12: =IFERROR(Bonds_Live!K12/100,"") | E12: =IFERROR(IF(C12="","",$H$5 + $H$4*C12 + $H$3*C12^2 + $H$2*C12^3),"") | F12: =IFERROR(IF(OR(D12="",E12=""),"",(D12-E12)*10000),"")
A13: =Bonds_Static!A13 | B13: =Bonds_Static!C13 | C13: =IFERROR(Bonds_Static!G13,"") | D13: =IFERROR(Bonds_Live!K13/100,"") | E13: =IFERROR(IF(C13="","",$H$5 + $H$4*C13 + $H$3*C13^2 + $H$2*C13^3),"") | F13: =IFERROR(IF(OR(D13="",E13=""),"",(D13-E13)*10000),"")
A14: =Bonds_Static!A14 | B14: =Bonds_Static!C14 | C14: =IFERROR(Bonds_Static!G14,"") | D14: =IFERROR(Bonds_Live!K14/100,"") | E14: =IFERROR(IF(C14="","",$H$5 + $H$4*C14 + $H$3*C14^2 + $H$2*C14^3),"") | F14: =IFERROR(IF(OR(D14="",E14=""),"",(D14-E14)*10000),"")
A15: =Bonds_Static!A15 | B15: =Bonds_Static!C15 | C15: =IFERROR(Bonds_Static!G15,"") | D15: =IFERROR(Bonds_Live!K15/100,"") | E15: =IFERROR(IF(C15="","",$H$5 + $H$4*C15 + $H$3*C15^2 + $H$2*C15^3),"") | F15: =IFERROR(IF(OR(D15="",E15=""),"",(D15-E15)*10000),"")
A16: =Bonds_Static!A16 | B16: =Bonds_Static!C16 | C16: =IFERROR(Bonds_Static!G16,"") | D16: =IFERROR(Bonds_Live!K16/100,"") | E16: =IFERROR(IF(C16="","",$H$5 + $H$4*C16 + $H$3*C16^2 + $H$2*C16^3),"") | F16: =IFERROR(IF(OR(D16="",E16=""),"",(D16-E16)*10000),"")
A17: =Bonds_Static!A17 | B17: =Bonds_Static!C17 | C17: =IFERROR(Bonds_Static!G17,"") | D17: =IFERROR(Bonds_Live!K17/100,"") | E17: =IFERROR(IF(C17="","",$H$5 + $H$4*C17 + $H$3*C17^2 + $H$2*C17^3),"") | F17: =IFERROR(IF(OR(D17="",E17=""),"",(D17-E17)*10000),"")
A18: =Bonds_Static!A18 | B18: =Bonds_Static!C18 | C18: =IFERROR(Bonds_Static!G18,"") | D18: =IFERROR(Bonds_Live!K18/100,"") | E18: =IFERROR(IF(C18="","",$H$5 + $H$4*C18 + $H$3*C18^2 + $H$2*C18^3),"") | F18: =IFERROR(IF(OR(D18="",E18=""),"",(D18-E18)*10000),"")
A19: =Bonds_Static!A19 | B19: =Bonds_Static!C19 | C19: =IFERROR(Bonds_Static!G19,"") | D19: =IFERROR(Bonds_Live!K19/100,"") | E19: =IFERROR(IF(C19="","",$H$5 + $H$4*C19 + $H$3*C19^2 + $H$2*C19^3),"") | F19: =IFERROR(IF(OR(D19="",E19=""),"",(D19-E19)*10000),"")
A20: =Bonds_Static!A20 | B20: =Bonds_Static!C20 | C20: =IFERROR(Bonds_Static!G20,"") | D20: =IFERROR(Bonds_Live!K20/100,"") | E20: =IFERROR(IF(C20="","",$H$5 + $H$4*C20 + $H$3*C20^2 + $H$2*C20^3),"") | F20: =IFERROR(IF(OR(D20="",E20=""),"",(D20-E20)*10000),"")
A21: =Bonds_Static!A21 | B21: =Bonds_Static!C21 | C21: =IFERROR(Bonds_Static!G21,"") | D21: =IFERROR(Bonds_Live!K21/100,"") | E21: =IFERROR(IF(C21="","",$H$5 + $H$4*C21 + $H$3*C21^2 + $H$2*C21^3),"") | F21: =IFERROR(IF(OR(D21="",E21=""),"",(D21-E21)*10000),"")
... A26: =Bonds_Static!A26 | B26: =Bonds_Static!C26 | C26: =IFERROR(Bonds_Static!G26,"") | D26: =IFERROR(Bonds_Live!K26/100,"") | E26: =IFERROR(IF(C26="","",$H$5 + $H$4*C26 + $H$3*C26^2 + $H$2*C26^3),"") | F26: =IFERROR(IF(OR(D26="",E26=""),"",(D26-E26)*10000),"")

Sheet Liquidity_Gate
A1: ISIN | B1: Description | C1: Amt Out ($mm) | D1: Bid-Ask (pts) | E1: TRACE Avg Vol ($mm) | F1: LQA Score | G1: Yrs to Maty | H1: Criteria Passed | I1: Liquidity Score | J1: Liquid?
A2: =Bonds_Static!A2 | B2: =Bonds_Static!C2 | C2: =IFERROR(Bonds_Static!H2,"") | D2: =IFERROR(Bonds_Live!H2,"") | E2: =IFERROR(BDP("/isin/"&$A2,"TRACE_AVG_DAILY_VOL")/1000000,"") | F2: =IFERROR(BDP("/isin/"&$A2,"LIQUIDITY_SCORE_BB"),"") | G2: =IFERROR(Bonds_Static!G2,"") | H2: =IFERROR((IF(ISNUMBER(C2),IF(C2>=Settings!$C$34,1,0),0))+(IF(ISNUMBER(D2),IF(D2<=Settings!$C$35,1,0),0))+(IF(ISNUMBER(E2),IF(E2>=Settings!$C$36,1,0),0))+(IF(ISNUMBER(F2),IF(F2>=Settings!$C$37,1,0),0))+(IF(ISNUMBER(G2),IF(G2>=Settings!$C$38,1,0),0)),"") | I2: =IFERROR(100*(0.40*MIN(IF(ISNUMBER(C2),C2/2000,0),1)+0.20*MAX(IF(ISNUMBER(D2),1-D2/1.5,0),0)+0.20*MIN(IF(ISNUMBER(E2),E2/20,0),1)+0.20*IF(ISNUMBER(F2),F2/100,0)),"") | J2: =IFERROR(IF(H2="","",IF(H2>=Settings!$C$39,"PASS","FAIL")),"")
A3: =Bonds_Static!A3 | B3: =Bonds_Static!C3 | C3: =IFERROR(Bonds_Static!H3,"") | D3: =IFERROR(Bonds_Live!H3,"") | E3: =IFERROR(BDP("/isin/"&$A3,"TRACE_AVG_DAILY_VOL")/1000000,"") | F3: =IFERROR(BDP("/isin/"&$A3,"LIQUIDITY_SCORE_BB"),"") | G3: =IFERROR(Bonds_Static!G3,"") | H3: =IFERROR((IF(ISNUMBER(C3),IF(C3>=Settings!$C$34,1,0),0))+(IF(ISNUMBER(D3),IF(D3<=Settings!$C$35,1,0),0))+(IF(ISNUMBER(E3),IF(E3>=Settings!$C$36,1,0),0))+(IF(ISNUMBER(F3),IF(F3>=Settings!$C$37,1,0),0))+(IF(ISNUMBER(G3),IF(G3>=Settings!$C$38,1,0),0)),"") | I3: =IFERROR(100*(0.40*MIN(IF(ISNUMBER(C3),C3/2000,0),1)+0.20*MAX(IF(ISNUMBER(D3),1-D3/1.5,0),0)+0.20*MIN(IF(ISNUMBER(E3),E3/20,0),1)+0.20*IF(ISNUMBER(F3),F3/100,0)),"") | J3: =IFERROR(IF(H3="","",IF(H3>=Settings!$C$39,"PASS","FAIL")),"")
A4: =Bonds_Static!A4 | B4: =Bonds_Static!C4 | C4: =IFERROR(Bonds_Static!H4,"") | D4: =IFERROR(Bonds_Live!H4,"") | E4: =IFERROR(BDP("/isin/"&$A4,"TRACE_AVG_DAILY_VOL")/1000000,"") | F4: =IFERROR(BDP("/isin/"&$A4,"LIQUIDITY_SCORE_BB"),"") | G4: =IFERROR(Bonds_Static!G4,"") | H4: =IFERROR((IF(ISNUMBER(C4),IF(C4>=Settings!$C$34,1,0),0))+(IF(ISNUMBER(D4),IF(D4<=Settings!$C$35,1,0),0))+(IF(ISNUMBER(E4),IF(E4>=Settings!$C$36,1,0),0))+(IF(ISNUMBER(F4),IF(F4>=Settings!$C$37,1,0),0))+(IF(ISNUMBER(G4),IF(G4>=Settings!$C$38,1,0),0)),"") | I4: =IFERROR(100*(0.40*MIN(IF(ISNUMBER(C4),C4/2000,0),1)+0.20*MAX(IF(ISNUMBER(D4),1-D4/1.5,0),0)+0.20*MIN(IF(ISNUMBER(E4),E4/20,0),1)+0.20*IF(ISNUMBER(F4),F4/100,0)),"") | J4: =IFERROR(IF(H4="","",IF(H4>=Settings!$C$39,"PASS","FAIL")),"")
A5: =Bonds_Static!A5 | B5: =Bonds_Static!C5 | C5: =IFERROR(Bonds_Static!H5,"") | D5: =IFERROR(Bonds_Live!H5,"") | E5: =IFERROR(BDP("/isin/"&$A5,"TRACE_AVG_DAILY_VOL")/1000000,"") | F5: =IFERROR(BDP("/isin/"&$A5,"LIQUIDITY_SCORE_BB"),"") | G5: =IFERROR(Bonds_Static!G5,"") | H5: =IFERROR((IF(ISNUMBER(C5),IF(C5>=Settings!$C$34,1,0),0))+(IF(ISNUMBER(D5),IF(D5<=Settings!$C$35,1,0),0))+(IF(ISNUMBER(E5),IF(E5>=Settings!$C$36,1,0),0))+(IF(ISNUMBER(F5),IF(F5>=Settings!$C$37,1,0),0))+(IF(ISNUMBER(G5),IF(G5>=Settings!$C$38,1,0),0)),"") | I5: =IFERROR(100*(0.40*MIN(IF(ISNUMBER(C5),C5/2000,0),1)+0.20*MAX(IF(ISNUMBER(D5),1-D5/1.5,0),0)+0.20*MIN(IF(ISNUMBER(E5),E5/20,0),1)+0.20*IF(ISNUMBER(F5),F5/100,0)),"") | J5: =IFERROR(IF(H5="","",IF(H5>=Settings!$C$39,"PASS","FAIL")),"")
A6: =Bonds_Static!A6 | B6: =Bonds_Static!C6 | C6: =IFERROR(Bonds_Static!H6,"") | D6: =IFERROR(Bonds_Live!H6,"") | E6: =IFERROR(BDP("/isin/"&$A6,"TRACE_AVG_DAILY_VOL")/1000000,"") | F6: =IFERROR(BDP("/isin/"&$A6,"LIQUIDITY_SCORE_BB"),"") | G6: =IFERROR(Bonds_Static!G6,"") | H6: =IFERROR((IF(ISNUMBER(C6),IF(C6>=Settings!$C$34,1,0),0))+(IF(ISNUMBER(D6),IF(D6<=Settings!$C$35,1,0),0))+(IF(ISNUMBER(E6),IF(E6>=Settings!$C$36,1,0),0))+(IF(ISNUMBER(F6),IF(F6>=Settings!$C$37,1,0),0))+(IF(ISNUMBER(G6),IF(G6>=Settings!$C$38,1,0),0)),"") | I6: =IFERROR(100*(0.40*MIN(IF(ISNUMBER(C6),C6/2000,0),1)+0.20*MAX(IF(ISNUMBER(D6),1-D6/1.5,0),0)+0.20*MIN(IF(ISNUMBER(E6),E6/20,0),1)+0.20*IF(ISNUMBER(F6),F6/100,0)),"") | J6: =IFERROR(IF(H6="","",IF(H6>=Settings!$C$39,"PASS","FAIL")),"")
A7: =Bonds_Static!A7 | B7: =Bonds_Static!C7 | C7: =IFERROR(Bonds_Static!H7,"") | D7: =IFERROR(Bonds_Live!H7,"") | E7: =IFERROR(BDP("/isin/"&$A7,"TRACE_AVG_DAILY_VOL")/1000000,"") | F7: =IFERROR(BDP("/isin/"&$A7,"LIQUIDITY_SCORE_BB"),"") | G7: =IFERROR(Bonds_Static!G7,"") | H7: =IFERROR((IF(ISNUMBER(C7),IF(C7>=Settings!$C$34,1,0),0))+(IF(ISNUMBER(D7),IF(D7<=Settings!$C$35,1,0),0))+(IF(ISNUMBER(E7),IF(E7>=Settings!$C$36,1,0),0))+(IF(ISNUMBER(F7),IF(F7>=Settings!$C$37,1,0),0))+(IF(ISNUMBER(G7),IF(G7>=Settings!$C$38,1,0),0)),"") | I7: =IFERROR(100*(0.40*MIN(IF(ISNUMBER(C7),C7/2000,0),1)+0.20*MAX(IF(ISNUMBER(D7),1-D7/1.5,0),0)+0.20*MIN(IF(ISNUMBER(E7),E7/20,0),1)+0.20*IF(ISNUMBER(F7),F7/100,0)),"") | J7: =IFERROR(IF(H7="","",IF(H7>=Settings!$C$39,"PASS","FAIL")),"")
A8: =Bonds_Static!A8 | B8: =Bonds_Static!C8 | C8: =IFERROR(Bonds_Static!H8,"") | D8: =IFERROR(Bonds_Live!H8,"") | E8: =IFERROR(BDP("/isin/"&$A8,"TRACE_AVG_DAILY_VOL")/1000000,"") | F8: =IFERROR(BDP("/isin/"&$A8,"LIQUIDITY_SCORE_BB"),"") | G8: =IFERROR(Bonds_Static!G8,"") | H8: =IFERROR((IF(ISNUMBER(C8),IF(C8>=Settings!$C$34,1,0),0))+(IF(ISNUMBER(D8),IF(D8<=Settings!$C$35,1,0),0))+(IF(ISNUMBER(E8),IF(E8>=Settings!$C$36,1,0),0))+(IF(ISNUMBER(F8),IF(F8>=Settings!$C$37,1,0),0))+(IF(ISNUMBER(G8),IF(G8>=Settings!$C$38,1,0),0)),"") | I8: =IFERROR(100*(0.40*MIN(IF(ISNUMBER(C8),C8/2000,0),1)+0.20*MAX(IF(ISNUMBER(D8),1-D8/1.5,0),0)+0.20*MIN(IF(ISNUMBER(E8),E8/20,0),1)+0.20*IF(ISNUMBER(F8),F8/100,0)),"") | J8: =IFERROR(IF(H8="","",IF(H8>=Settings!$C$39,"PASS","FAIL")),"")
A9: =Bonds_Static!A9 | B9: =Bonds_Static!C9 | C9: =IFERROR(Bonds_Static!H9,"") | D9: =IFERROR(Bonds_Live!H9,"") | E9: =IFERROR(BDP("/isin/"&$A9,"TRACE_AVG_DAILY_VOL")/1000000,"") | F9: =IFERROR(BDP("/isin/"&$A9,"LIQUIDITY_SCORE_BB"),"") | G9: =IFERROR(Bonds_Static!G9,"") | H9: =IFERROR((IF(ISNUMBER(C9),IF(C9>=Settings!$C$34,1,0),0))+(IF(ISNUMBER(D9),IF(D9<=Settings!$C$35,1,0),0))+(IF(ISNUMBER(E9),IF(E9>=Settings!$C$36,1,0),0))+(IF(ISNUMBER(F9),IF(F9>=Settings!$C$37,1,0),0))+(IF(ISNUMBER(G9),IF(G9>=Settings!$C$38,1,0),0)),"") | I9: =IFERROR(100*(0.40*MIN(IF(ISNUMBER(C9),C9/2000,0),1)+0.20*MAX(IF(ISNUMBER(D9),1-D9/1.5,0),0)+0.20*MIN(IF(ISNUMBER(E9),E9/20,0),1)+0.20*IF(ISNUMBER(F9),F9/100,0)),"") | J9: =IFERROR(IF(H9="","",IF(H9>=Settings!$C$39,"PASS","FAIL")),"")
A10: =Bonds_Static!A10 | B10: =Bonds_Static!C10 | C10: =IFERROR(Bonds_Static!H10,"") | D10: =IFERROR(Bonds_Live!H10,"") | E10: =IFERROR(BDP("/isin/"&$A10,"TRACE_AVG_DAILY_VOL")/1000000,"") | F10: =IFERROR(BDP("/isin/"&$A10,"LIQUIDITY_SCORE_BB"),"") | G10: =IFERROR(Bonds_Static!G10,"") | H10: =IFERROR((IF(ISNUMBER(C10),IF(C10>=Settings!$C$34,1,0),0))+(IF(ISNUMBER(D10),IF(D10<=Settings!$C$35,1,0),0))+(IF(ISNUMBER(E10),IF(E10>=Settings!$C$36,1,0),0))+(IF(ISNUMBER(F10),IF(F10>=Settings!$C$37,1,0),0))+(IF(ISNUMBER(G10),IF(G10>=Settings!$C$38,1,0),0)),"") | I10: =IFERROR(100*(0.40*MIN(IF(ISNUMBER(C10),C10/2000,0),1)+0.20*MAX(IF(ISNUMBER(D10),1-D10/1.5,0),0)+0.20*MIN(IF(ISNUMBER(E10),E10/20,0),1)+0.20*IF(ISNUMBER(F10),F10/100,0)),"") | J10: =IFERROR(IF(H10="","",IF(H10>=Settings!$C$39,"PASS","FAIL")),"")
A11: =Bonds_Static!A11 | B11: =Bonds_Static!C11 | C11: =IFERROR(Bonds_Static!H11,"") | D11: =IFERROR(Bonds_Live!H11,"") | E11: =IFERROR(BDP("/isin/"&$A11,"TRACE_AVG_DAILY_VOL")/1000000,"") | F11: =IFERROR(BDP("/isin/"&$A11,"LIQUIDITY_SCORE_BB"),"") | G11: =IFERROR(Bonds_Static!G11,"") | H11: =IFERROR((IF(ISNUMBER(C11),IF(C11>=Settings!$C$34,1,0),0))+(IF(ISNUMBER(D11),IF(D11<=Settings!$C$35,1,0),0))+(IF(ISNUMBER(E11),IF(E11>=Settings!$C$36,1,0),0))+(IF(ISNUMBER(F11),IF(F11>=Settings!$C$37,1,0),0))+(IF(ISNUMBER(G11),IF(G11>=Settings!$C$38,1,0),0)),"") | I11: =IFERROR(100*(0.40*MIN(IF(ISNUMBER(C11),C11/2000,0),1)+0.20*MAX(IF(ISNUMBER(D11),1-D11/1.5,0),0)+0.20*MIN(IF(ISNUMBER(E11),E11/20,0),1)+0.20*IF(ISNUMBER(F11),F11/100,0)),"") | J11: =IFERROR(IF(H11="","",IF(H11>=Settings!$C$39,"PASS","FAIL")),"")
A12: =Bonds_Static!A12 | B12: =Bonds_Static!C12 | C12: =IFERROR(Bonds_Static!H12,"") | D12: =IFERROR(Bonds_Live!H12,"") | E12: =IFERROR(BDP("/isin/"&$A12,"TRACE_AVG_DAILY_VOL")/1000000,"") | F12: =IFERROR(BDP("/isin/"&$A12,"LIQUIDITY_SCORE_BB"),"") | G12: =IFERROR(Bonds_Static!G12,"") | H12: =IFERROR((IF(ISNUMBER(C12),IF(C12>=Settings!$C$34,1,0),0))+(IF(ISNUMBER(D12),IF(D12<=Settings!$C$35,1,0),0))+(IF(ISNUMBER(E12),IF(E12>=Settings!$C$36,1,0),0))+(IF(ISNUMBER(F12),IF(F12>=Settings!$C$37,1,0),0))+(IF(ISNUMBER(G12),IF(G12>=Settings!$C$38,1,0),0)),"") | I12: =IFERROR(100*(0.40*MIN(IF(ISNUMBER(C12),C12/2000,0),1)+0.20*MAX(IF(ISNUMBER(D12),1-D12/1.5,0),0)+0.20*MIN(IF(ISNUMBER(E12),E12/20,0),1)+0.20*IF(ISNUMBER(F12),F12/100,0)),"") | J12: =IFERROR(IF(H12="","",IF(H12>=Settings!$C$39,"PASS","FAIL")),"")
A13: =Bonds_Static!A13 | B13: =Bonds_Static!C13 | C13: =IFERROR(Bonds_Static!H13,"") | D13: =IFERROR(Bonds_Live!H13,"") | E13: =IFERROR(BDP("/isin/"&$A13,"TRACE_AVG_DAILY_VOL")/1000000,"") | F13: =IFERROR(BDP("/isin/"&$A13,"LIQUIDITY_SCORE_BB"),"") | G13: =IFERROR(Bonds_Static!G13,"") | H13: =IFERROR((IF(ISNUMBER(C13),IF(C13>=Settings!$C$34,1,0),0))+(IF(ISNUMBER(D13),IF(D13<=Settings!$C$35,1,0),0))+(IF(ISNUMBER(E13),IF(E13>=Settings!$C$36,1,0),0))+(IF(ISNUMBER(F13),IF(F13>=Settings!$C$37,1,0),0))+(IF(ISNUMBER(G13),IF(G13>=Settings!$C$38,1,0),0)),"") | I13: =IFERROR(100*(0.40*MIN(IF(ISNUMBER(C13),C13/2000,0),1)+0.20*MAX(IF(ISNUMBER(D13),1-D13/1.5,0),0)+0.20*MIN(IF(ISNUMBER(E13),E13/20,0),1)+0.20*IF(ISNUMBER(F13),F13/100,0)),"") | J13: =IFERROR(IF(H13="","",IF(H13>=Settings!$C$39,"PASS","FAIL")),"")
... A26: =Bonds_Static!A26 | B26: =Bonds_Static!C26 | C26: =IFERROR(Bonds_Static!H26,"") | D26: =IFERROR(Bonds_Live!H26,"") | E26: =IFERROR(BDP("/isin/"&$A26,"TRACE_AVG_DAILY_VOL")/1000000,"") | F26: =IFERROR(BDP("/isin/"&$A26,"LIQUIDITY_SCORE_BB"),"") | G26: =IFERROR(Bonds_Static!G26,"") | H26: =IFERROR((IF(ISNUMBER(C26),IF(C26>=Settings!$C$34,1,0),0))+(IF(ISNUMBER(D26),IF(D26<=Settings!$C$35,1,0),0))+(IF(ISNUMBER(E26),IF(E26>=Settings!$C$36,1,0),0))+(IF(ISNUMBER(F26),IF(F26>=Settings!$C$37,1,0),0))+(IF(ISNUMBER(G26),IF(G26>=Settings!$C$38,1,0),0)),"") | I26: =IFERROR(100*(0.40*MIN(IF(ISNUMBER(C26),C26/2000,0),1)+0.20*MAX(IF(ISNUMBER(D26),1-D26/1.5,0),0)+0.20*MIN(IF(ISNUMBER(E26),E26/20,0),1)+0.20*IF(ISNUMBER(F26),F26/100,0)),"") | J26: =IFERROR(IF(H26="","",IF(H26>=Settings!$C$39,"PASS","FAIL")),"")

Sheet Carry_Roll
A1: ISIN | B1: Description | C1: τ (yrs) | D1: Mod Dur | E1: Coupon (%) | F1: YTM (%) | G1: Cpn Carry 3M | H1: Cpn Carry 6M | I1: Cpn Carry 12M | J1: Roll 3M | K1: Roll 6M | L1: Roll 12M | M1: C+R 12M
A2: =Bonds_Static!A2 | B2: =Bonds_Static!C2 | C2: =IFERROR(Bonds_Static!G2,"") | D2: =IFERROR(Bonds_Live!Q2,"") | E2: =IFERROR(Bonds_Static!D2,"") | F2: =IFERROR(Bonds_Live!K2,"") | G2: =IFERROR(IF(E2="","",E2*100/Bonds_Live!F2*3/12),"") | H2: =IFERROR(IF(E2="","",E2*100/Bonds_Live!F2*6/12),"") | I2: =IFERROR(IF(E2="","",E2*100/Bonds_Live!F2*12/12),"") | J2: =IFERROR(IF(OR(C2="",D2=""),"",-D2*((Curve_Fit!$H$5 + Curve_Fit!$H$4*MAX(C2-3/12,0.01) + Curve_Fit!$H$3*MAX(C2-3/12,0.01)^2 + Curve_Fit!$H$2*MAX(C2-3/12,0.01)^3) - (Curve_Fit!$H$5 + Curve_Fit!$H$4*C2 + Curve_Fit!$H$3*C2^2 + Curve_Fit!$H$2*C2^3))*100),"") | K2: =IFERROR(IF(OR(C2="",D2=""),"",-D2*((Curve_Fit!$H$5 + Curve_Fit!$H$4*MAX(C2-6/12,0.01) + Curve_Fit!$H$3*MAX(C2-6/12,0.01)^2 + Curve_Fit!$H$2*MAX(C2-6/12,0.01)^3) - (Curve_Fit!$H$5 + Curve_Fit!$H$4*C2 + Curve_Fit!$H$3*C2^2 + Curve_Fit!$H$2*C2^3))*100),"") | L2: =IFERROR(IF(OR(C2="",D2=""),"",-D2*((Curve_Fit!$H$5 + Curve_Fit!$H$4*MAX(C2-12/12,0.01) + Curve_Fit!$H$3*MAX(C2-12/12,0.01)^2 + Curve_Fit!$H$2*MAX(C2-12/12,0.01)^3) - (Curve_Fit!$H$5 + Curve_Fit!$H$4*C2 + Curve_Fit!$H$3*C2^2 + Curve_Fit!$H$2*C2^3))*100),"") | M2: =IFERROR(IF(OR(I2="",L2=""),"",I2+L2),"")
A3: =Bonds_Static!A3 | B3: =Bonds_Static!C3 | C3: =IFERROR(Bonds_Static!G3,"") | D3: =IFERROR(Bonds_Live!Q3,"") | E3: =IFERROR(Bonds_Static!D3,"") | F3: =IFERROR(Bonds_Live!K3,"") | G3: =IFERROR(IF(E3="","",E3*100/Bonds_Live!F3*3/12),"") | H3: =IFERROR(IF(E3="","",E3*100/Bonds_Live!F3*6/12),"") | I3: =IFERROR(IF(E3="","",E3*100/Bonds_Live!F3*12/12),"") | J3: =IFERROR(IF(OR(C3="",D3=""),"",-D3*((Curve_Fit!$H$5 + Curve_Fit!$H$4*MAX(C3-3/12,0.01) + Curve_Fit!$H$3*MAX(C3-3/12,0.01)^2 + Curve_Fit!$H$2*MAX(C3-3/12,0.01)^3) - (Curve_Fit!$H$5 + Curve_Fit!$H$4*C3 + Curve_Fit!$H$3*C3^2 + Curve_Fit!$H$2*C3^3))*100),"") | K3: =IFERROR(IF(OR(C3="",D3=""),"",-D3*((Curve_Fit!$H$5 + Curve_Fit!$H$4*MAX(C3-6/12,0.01) + Curve_Fit!$H$3*MAX(C3-6/12,0.01)^2 + Curve_Fit!$H$2*MAX(C3-6/12,0.01)^3) - (Curve_Fit!$H$5 + Curve_Fit!$H$4*C3 + Curve_Fit!$H$3*C3^2 + Curve_Fit!$H$2*C3^3))*100),"") | L3: =IFERROR(IF(OR(C3="",D3=""),"",-D3*((Curve_Fit!$H$5 + Curve_Fit!$H$4*MAX(C3-12/12,0.01) + Curve_Fit!$H$3*MAX(C3-12/12,0.01)^2 + Curve_Fit!$H$2*MAX(C3-12/12,0.01)^3) - (Curve_Fit!$H$5 + Curve_Fit!$H$4*C3 + Curve_Fit!$H$3*C3^2 + Curve_Fit!$H$2*C3^3))*100),"") | M3: =IFERROR(IF(OR(I3="",L3=""),"",I3+L3),"")
A4: =Bonds_Static!A4 | B4: =Bonds_Static!C4 | C4: =IFERROR(Bonds_Static!G4,"") | D4: =IFERROR(Bonds_Live!Q4,"") | E4: =IFERROR(Bonds_Static!D4,"") | F4: =IFERROR(Bonds_Live!K4,"") | G4: =IFERROR(IF(E4="","",E4*100/Bonds_Live!F4*3/12),"") | H4: =IFERROR(IF(E4="","",E4*100/Bonds_Live!F4*6/12),"") | I4: =IFERROR(IF(E4="","",E4*100/Bonds_Live!F4*12/12),"") | J4: =IFERROR(IF(OR(C4="",D4=""),"",-D4*((Curve_Fit!$H$5 + Curve_Fit!$H$4*MAX(C4-3/12,0.01) + Curve_Fit!$H$3*MAX(C4-3/12,0.01)^2 + Curve_Fit!$H$2*MAX(C4-3/12,0.01)^3) - (Curve_Fit!$H$5 + Curve_Fit!$H$4*C4 + Curve_Fit!$H$3*C4^2 + Curve_Fit!$H$2*C4^3))*100),"") | K4: =IFERROR(IF(OR(C4="",D4=""),"",-D4*((Curve_Fit!$H$5 + Curve_Fit!$H$4*MAX(C4-6/12,0.01) + Curve_Fit!$H$3*MAX(C4-6/12,0.01)^2 + Curve_Fit!$H$2*MAX(C4-6/12,0.01)^3) - (Curve_Fit!$H$5 + Curve_Fit!$H$4*C4 + Curve_Fit!$H$3*C4^2 + Curve_Fit!$H$2*C4^3))*100),"") | L4: =IFERROR(IF(OR(C4="",D4=""),"",-D4*((Curve_Fit!$H$5 + Curve_Fit!$H$4*MAX(C4-12/12,0.01) + Curve_Fit!$H$3*MAX(C4-12/12,0.01)^2 + Curve_Fit!$H$2*MAX(C4-12/12,0.01)^3) - (Curve_Fit!$H$5 + Curve_Fit!$H$4*C4 + Curve_Fit!$H$3*C4^2 + Curve_Fit!$H$2*C4^3))*100),"") | M4: =IFERROR(IF(OR(I4="",L4=""),"",I4+L4),"")
A5: =Bonds_Static!A5 | B5: =Bonds_Static!C5 | C5: =IFERROR(Bonds_Static!G5,"") | D5: =IFERROR(Bonds_Live!Q5,"") | E5: =IFERROR(Bonds_Static!D5,"") | F5: =IFERROR(Bonds_Live!K5,"") | G5: =IFERROR(IF(E5="","",E5*100/Bonds_Live!F5*3/12),"") | H5: =IFERROR(IF(E5="","",E5*100/Bonds_Live!F5*6/12),"") | I5: =IFERROR(IF(E5="","",E5*100/Bonds_Live!F5*12/12),"") | J5: =IFERROR(IF(OR(C5="",D5=""),"",-D5*((Curve_Fit!$H$5 + Curve_Fit!$H$4*MAX(C5-3/12,0.01) + Curve_Fit!$H$3*MAX(C5-3/12,0.01)^2 + Curve_Fit!$H$2*MAX(C5-3/12,0.01)^3) - (Curve_Fit!$H$5 + Curve_Fit!$H$4*C5 + Curve_Fit!$H$3*C5^2 + Curve_Fit!$H$2*C5^3))*100),"") | K5: =IFERROR(IF(OR(C5="",D5=""),"",-D5*((Curve_Fit!$H$5 + Curve_Fit!$H$4*MAX(C5-6/12,0.01) + Curve_Fit!$H$3*MAX(C5-6/12,0.01)^2 + Curve_Fit!$H$2*MAX(C5-6/12,0.01)^3) - (Curve_Fit!$H$5 + Curve_Fit!$H$4*C5 + Curve_Fit!$H$3*C5^2 + Curve_Fit!$H$2*C5^3))*100),"") | L5: =IFERROR(IF(OR(C5="",D5=""),"",-D5*((Curve_Fit!$H$5 + Curve_Fit!$H$4*MAX(C5-12/12,0.01) + Curve_Fit!$H$3*MAX(C5-12/12,0.01)^2 + Curve_Fit!$H$2*MAX(C5-12/12,0.01)^3) - (Curve_Fit!$H$5 + Curve_Fit!$H$4*C5 + Curve_Fit!$H$3*C5^2 + Curve_Fit!$H$2*C5^3))*100),"") | M5: =IFERROR(IF(OR(I5="",L5=""),"",I5+L5),"")
A6: =Bonds_Static!A6 | B6: =Bonds_Static!C6 | C6: =IFERROR(Bonds_Static!G6,"") | D6: =IFERROR(Bonds_Live!Q6,"") | E6: =IFERROR(Bonds_Static!D6,"") | F6: =IFERROR(Bonds_Live!K6,"") | G6: =IFERROR(IF(E6="","",E6*100/Bonds_Live!F6*3/12),"") | H6: =IFERROR(IF(E6="","",E6*100/Bonds_Live!F6*6/12),"") | I6: =IFERROR(IF(E6="","",E6*100/Bonds_Live!F6*12/12),"") | J6: =IFERROR(IF(OR(C6="",D6=""),"",-D6*((Curve_Fit!$H$5 + Curve_Fit!$H$4*MAX(C6-3/12,0.01) + Curve_Fit!$H$3*MAX(C6-3/12,0.01)^2 + Curve_Fit!$H$2*MAX(C6-3/12,0.01)^3) - (Curve_Fit!$H$5 + Curve_Fit!$H$4*C6 + Curve_Fit!$H$3*C6^2 + Curve_Fit!$H$2*C6^3))*100),"") | K6: =IFERROR(IF(OR(C6="",D6=""),"",-D6*((Curve_Fit!$H$5 + Curve_Fit!$H$4*MAX(C6-6/12,0.01) + Curve_Fit!$H$3*MAX(C6-6/12,0.01)^2 + Curve_Fit!$H$2*MAX(C6-6/12,0.01)^3) - (Curve_Fit!$H$5 + Curve_Fit!$H$4*C6 + Curve_Fit!$H$3*C6^2 + Curve_Fit!$H$2*C6^3))*100),"") | L6: =IFERROR(IF(OR(C6="",D6=""),"",-D6*((Curve_Fit!$H$5 + Curve_Fit!$H$4*MAX(C6-12/12,0.01) + Curve_Fit!$H$3*MAX(C6-12/12,0.01)^2 + Curve_Fit!$H$2*MAX(C6-12/12,0.01)^3) - (Curve_Fit!$H$5 + Curve_Fit!$H$4*C6 + Curve_Fit!$H$3*C6^2 + Curve_Fit!$H$2*C6^3))*100),"") | M6: =IFERROR(IF(OR(I6="",L6=""),"",I6+L6),"")
A7: =Bonds_Static!A7 | B7: =Bonds_Static!C7 | C7: =IFERROR(Bonds_Static!G7,"") | D7: =IFERROR(Bonds_Live!Q7,"") | E7: =IFERROR(Bonds_Static!D7,"") | F7: =IFERROR(Bonds_Live!K7,"") | G7: =IFERROR(IF(E7="","",E7*100/Bonds_Live!F7*3/12),"") | H7: =IFERROR(IF(E7="","",E7*100/Bonds_Live!F7*6/12),"") | I7: =IFERROR(IF(E7="","",E7*100/Bonds_Live!F7*12/12),"") | J7: =IFERROR(IF(OR(C7="",D7=""),"",-D7*((Curve_Fit!$H$5 + Curve_Fit!$H$4*MAX(C7-3/12,0.01) + Curve_Fit!$H$3*MAX(C7-3/12,0.01)^2 + Curve_Fit!$H$2*MAX(C7-3/12,0.01)^3) - (Curve_Fit!$H$5 + Curve_Fit!$H$4*C7 + Curve_Fit!$H$3*C7^2 + Curve_Fit!$H$2*C7^3))*100),"") | K7: =IFERROR(IF(OR(C7="",D7=""),"",-D7*((Curve_Fit!$H$5 + Curve_Fit!$H$4*MAX(C7-6/12,0.01) + Curve_Fit!$H$3*MAX(C7-6/12,0.01)^2 + Curve_Fit!$H$2*MAX(C7-6/12,0.01)^3) - (Curve_Fit!$H$5 + Curve_Fit!$H$4*C7 + Curve_Fit!$H$3*C7^2 + Curve_Fit!$H$2*C7^3))*100),"") | L7: =IFERROR(IF(OR(C7="",D7=""),"",-D7*((Curve_Fit!$H$5 + Curve_Fit!$H$4*MAX(C7-12/12,0.01) + Curve_Fit!$H$3*MAX(C7-12/12,0.01)^2 + Curve_Fit!$H$2*MAX(C7-12/12,0.01)^3) - (Curve_Fit!$H$5 + Curve_Fit!$H$4*C7 + Curve_Fit!$H$3*C7^2 + Curve_Fit!$H$2*C7^3))*100),"") | M7: =IFERROR(IF(OR(I7="",L7=""),"",I7+L7),"")
A8: =Bonds_Static!A8 | B8: =Bonds_Static!C8 | C8: =IFERROR(Bonds_Static!G8,"") | D8: =IFERROR(Bonds_Live!Q8,"") | E8: =IFERROR(Bonds_Static!D8,"") | F8: =IFERROR(Bonds_Live!K8,"") | G8: =IFERROR(IF(E8="","",E8*100/Bonds_Live!F8*3/12),"") | H8: =IFERROR(IF(E8="","",E8*100/Bonds_Live!F8*6/12),"") | I8: =IFERROR(IF(E8="","",E8*100/Bonds_Live!F8*12/12),"") | J8: =IFERROR(IF(OR(C8="",D8=""),"",-D8*((Curve_Fit!$H$5 + Curve_Fit!$H$4*MAX(C8-3/12,0.01) + Curve_Fit!$H$3*MAX(C8-3/12,0.01)^2 + Curve_Fit!$H$2*MAX(C8-3/12,0.01)^3) - (Curve_Fit!$H$5 + Curve_Fit!$H$4*C8 + Curve_Fit!$H$3*C8^2 + Curve_Fit!$H$2*C8^3))*100),"") | K8: =IFERROR(IF(OR(C8="",D8=""),"",-D8*((Curve_Fit!$H$5 + Curve_Fit!$H$4*MAX(C8-6/12,0.01) + Curve_Fit!$H$3*MAX(C8-6/12,0.01)^2 + Curve_Fit!$H$2*MAX(C8-6/12,0.01)^3) - (Curve_Fit!$H$5 + Curve_Fit!$H$4*C8 + Curve_Fit!$H$3*C8^2 + Curve_Fit!$H$2*C8^3))*100),"") | L8: =IFERROR(IF(OR(C8="",D8=""),"",-D8*((Curve_Fit!$H$5 + Curve_Fit!$H$4*MAX(C8-12/12,0.01) + Curve_Fit!$H$3*MAX(C8-12/12,0.01)^2 + Curve_Fit!$H$2*MAX(C8-12/12,0.01)^3) - (Curve_Fit!$H$5 + Curve_Fit!$H$4*C8 + Curve_Fit!$H$3*C8^2 + Curve_Fit!$H$2*C8^3))*100),"") | M8: =IFERROR(IF(OR(I8="",L8=""),"",I8+L8),"")
