Workbook

Sheet README
A1: Simplified Deep Value Strategy — Bloomberg workbook
A2: Implements the mechanics described in Appendix B of "Building a Better Deep Value Portfolio" (Kupersmith, Ross, Thapar, AQR, March 2017).
A4: What this is
A5: A working implementation of the Appendix B engine on two of the fourteen sub-strategies: Emerging Currencies
A6: (signal: real exchange rate) and Interest Rate Futures (signal: adjusted real short rate). The engine is generic —
A7: the Template sheet explains how to add Global Bonds, Developed Currencies, Inflation Breakevens or any other sleeve.
A9: The mechanics, step by step
A10: 1. Each sub-strategy is divided into SUBSETS. For non-stock-selection strategies a subset is a PAIR of assets.
A11: 7 assets gives 21 pairs per sleeve.
A12: 2. Within each subset, assets are sorted on the valuation metric: long the top third, short the bottom third.
A13: In a two-asset subset that reduces to long the cheap one and short the rich one.
A14: 3. The VALUATION SPREAD of the subset is the gap between the long and short legs' valuation. Always positive.
... A53: each data sheet.

Sheet Config
A1: Configuration
A2: Blue = input. Change these and the whole workbook recalculates.
A4: Parameter | B4: Value | C4: Notes
A5: Entry / step-1 z threshold | B5: 2 | C5: Subset is included when the expanding z-score of its valuation spread exceeds this.
A6: Step-2 z threshold | B6: 3 | C6: Position steps up at this z.
A7: Step-3 z threshold | B7: 4 | C7: Position steps up again at this z.
A8: Exit z threshold | B8: 2 | C8: Subset is removed when z falls below this. Appendix B uses 2. Set to 1 for the footnote variant.
A9: Weight at step 1 | B9: 1 | C9: Risk multiplier once included.
A10: Weight at step 2 | B10: 1.5 | C10: Risk multiplier at the step-2 threshold.
A11: Weight at step 3 | B11: 2 | C11: Risk multiplier at the step-3 threshold.
A12: Min obs for z-score | B12: 60 | C12: Months of history required before an expanding z-score is produced.
A13: Vol lookback (months) | B13: 36 | C13: Trailing window for subset and portfolio volatility.
A14: Target vol per subset | B14: 0.02 | C14: Annualised risk target for each included subset before portfolio scaling.
A15: Portfolio vol cap | B15: 0.1 | C15: Annualised. If trailing portfolio vol exceeds this, all subsets scale down proportionally.
A16: Max subset scalar | B16: 5 | C16: Cap on the vol-targeting multiplier, to stop a quiet subset being levered absurdly.
... A18: Sleeves in portfolio | B18: 2 | C18: Used for the equal-risk-contribution split across sleeves.
A20: All thresholds and multipliers above are taken from Appendix B as supplied by the user. Risk-targeting parameters are implementation choices.

Sheet Tickers
A1: Bloomberg pull sheet
A2: Verify every ticker on the terminal before trusting it. Column F is the formula to paste into the matching yellow block.
A4: Start date | B4: 37987
A5: End date | B5: 46295
A6: BDH options | B6: "Per=M","Dts=H","Days=A","Fill=P" | C6: Monthly periodicity, dates hidden so one column comes back, all calendar days, previous value carried.
A8: Sleeve | B8: Series needed | C8: Suggested ticker | D8: Confidence | E8: How to verify on the terminal | F8: BDH formula to paste
A9: EM currencies | B9: BRL spot per USD | C9: USDBRL Curncy | D9: High | E9: Standard spot ticker. Confirm quoting convention is units per USD. | F9: =IF($C9="<verify>","-- fill in the ticker first --","=BDH("""&$C9&""",""PX_LAST"","""&TEXT($B$4,"yyyymmdd")&""","""&TEXT($B$5,"yyyymmdd")&""","&$B$6&")") -> =BDH("USDBRL Curncy","PX_LAST","20040101","20260930","Per=M","Dts=H","Days=A","Fill=P")
A10: EM currencies | B10: MXN spot per USD | C10: USDMXN Curncy | D10: High | E10: Standard spot ticker. Confirm quoting convention is units per USD. | F10: =IF($C10="<verify>","-- fill in the ticker first --","=BDH("""&$C10&""",""PX_LAST"","""&TEXT($B$4,"yyyymmdd")&""","""&TEXT($B$5,"yyyymmdd")&""","&$B$6&")") -> =BDH("USDMXN Curncy","PX_LAST","20040101","20260930","Per=M","Dts=H","Days=A","Fill=P")
A11: EM currencies | B11: CLP spot per USD | C11: USDCLP Curncy | D11: High | E11: Standard spot ticker. Confirm quoting convention is units per USD. | F11: =IF($C11="<verify>","-- fill in the ticker first --","=BDH("""&$C11&""",""PX_LAST"","""&TEXT($B$4,"yyyymmdd")&""","""&TEXT($B$5,"yyyymmdd")&""","&$B$6&")") -> =BDH("USDCLP Curncy","PX_LAST","20040101","20260930","Per=M","Dts=H","Days=A","Fill=P")
A12: EM currencies | B12: COP spot per USD | C12: USDCOP Curncy | D12: High | E12: Standard spot ticker. Confirm quoting convention is units per USD. | F12: =IF($C12="<verify>","-- fill in the ticker first --","=BDH("""&$C12&""",""PX_LAST"","""&TEXT($B$4,"yyyymmdd")&""","""&TEXT($B$5,"yyyymmdd")&""","&$B$6&")") -> =BDH("USDCOP Curncy","PX_LAST","20040101","20260930","Per=M","Dts=H","Days=A","Fill=P")
A13: EM currencies | B13: ZAR spot per USD | C13: USDZAR Curncy | D13: High | E13: Standard spot ticker. Confirm quoting convention is units per USD. | F13: =IF($C13="<verify>","-- fill in the ticker first --","=BDH("""&$C13&""",""PX_LAST"","""&TEXT($B$4,"yyyymmdd")&""","""&TEXT($B$5,"yyyymmdd")&""","&$B$6&")") -> =BDH("USDZAR Curncy","PX_LAST","20040101","20260930","Per=M","Dts=H","Days=A","Fill=P")
A14: EM currencies | B14: TRY spot per USD | C14: USDTRY Curncy | D14: High | E14: Standard spot ticker. Confirm quoting convention is units per USD. | F14: =IF($C14="<verify>","-- fill in the ticker first --","=BDH("""&$C14&""",""PX_LAST"","""&TEXT($B$4,"yyyymmdd")&""","""&TEXT($B$5,"yyyymmdd")&""","&$B$6&")") -> =BDH("USDTRY Curncy","PX_LAST","20040101","20260930","Per=M","Dts=H","Days=A","Fill=P")
A15: EM currencies | B15: PLN spot per USD | C15: USDPLN Curncy | D15: High | E15: Standard spot ticker. Confirm quoting convention is units per USD. | F15: =IF($C15="<verify>","-- fill in the ticker first --","=BDH("""&$C15&""",""PX_LAST"","""&TEXT($B$4,"yyyymmdd")&""","""&TEXT($B$5,"yyyymmdd")&""","&$B$6&")") -> =BDH("USDPLN Curncy","PX_LAST","20040101","20260930","Per=M","Dts=H","Days=A","Fill=P")
A16: EM currencies | B16: BRL country CPI index | C16: <verify> | D16: Find it | E16: ECO <GO> > country > Consumer Price Index > copy the index-level (not YoY) ticker. | F16: =IF($C16="<verify>","-- fill in the ticker first --","=BDH("""&$C16&""",""PX_LAST"","""&TEXT($B$4,"yyyymmdd")&""","""&TEXT($B$5,"yyyymmdd")&""","&$B$6&")") -> -- fill in the ticker first --
A17: EM currencies | B17: MXN country CPI index | C17: <verify> | D17: Find it | E17: ECO <GO> > country > Consumer Price Index > copy the index-level (not YoY) ticker. | F17: =IF($C17="<verify>","-- fill in the ticker first --","=BDH("""&$C17&""",""PX_LAST"","""&TEXT($B$4,"yyyymmdd")&""","""&TEXT($B$5,"yyyymmdd")&""","&$B$6&")") -> -- fill in the ticker first --
A18: EM currencies | B18: CLP country CPI index | C18: <verify> | D18: Find it | E18: ECO <GO> > country > Consumer Price Index > copy the index-level (not YoY) ticker. | F18: =IF($C18="<verify>","-- fill in the ticker first --","=BDH("""&$C18&""",""PX_LAST"","""&TEXT($B$4,"yyyymmdd")&""","""&TEXT($B$5,"yyyymmdd")&""","&$B$6&")") -> -- fill in the ticker first --
A19: EM currencies | B19: COP country CPI index | C19: <verify> | D19: Find it | E19: ECO <GO> > country > Consumer Price Index > copy the index-level (not YoY) ticker. | F19: =IF($C19="<verify>","-- fill in the ticker first --","=BDH("""&$C19&""",""PX_LAST"","""&TEXT($B$4,"yyyymmdd")&""","""&TEXT($B$5,"yyyymmdd")&""","&$B$6&")") -> -- fill in the ticker first --
A20: EM currencies | B20: ZAR country CPI index | C20: <verify> | D20: Find it | E20: ECO <GO> > country > Consumer Price Index > copy the index-level (not YoY) ticker. | F20: =IF($C20="<verify>","-- fill in the ticker first --","=BDH("""&$C20&""",""PX_LAST"","""&TEXT($B$4,"yyyymmdd")&""","""&TEXT($B$5,"yyyymmdd")&""","&$B$6&")") -> -- fill in the ticker first --
... A44: Rate futures | B44: NZ 2-year government yield | C44: <verify> | D44: Find it | E44: Generic 2y sovereign yield. Confirm it is the on-the-run generic, not a specific bond. | F44: =IF($C44="<verify>","-- fill in the ticker first --","=BDH("""&$C44&""",""PX_LAST"","""&TEXT($B$4,"yyyymmdd")&""","""&TEXT($B$5,"yyyymmdd")&""","&$B$6&")") -> -- fill in the ticker first --
A46: Confidence column is mine, not Bloomberg's. "High" means the ticker follows a standard convention I am confident in; "Find it" means look it up rather than trust a guess.

Sheet EMFX_Data
A1: EMFX Data
A2: Signal: real exchange rate. RER = (country CPI / US CPI) / spot, indexed to 100 at the first observation. Cheapness = minus the log deviation of RER from its own EXPANDING mean, so a higher number means cheaper. Yellow = paste BDH here. | B2: Spot, units per USD — INPUT | I2: CPI index — INPUT | Q2: Real exchange rate (100 = first obs) | X2: Valuation: cheapness vs own history | AE2: Monthly return to a long position
A3: Date | B3: BRL | C3: MXN | D3: CLP | E3: COP | F3: ZAR | G3: TRY | H3: PLN | I3: BRL | J3: MXN | K3: CLP | L3: COP | M3: ZAR | N3: TRY | O3: PLN | P3: US | Q3: BRL | R3: MXN | S3: CLP | T3: COP | U3: ZAR | V3: TRY | W3: PLN | X3: BRL | Y3: MXN | Z3: CLP | AA3: COP | AB3: ZAR | AC3: TRY | AD3: PLN | AE3: BRL | AF3: MXN | AG3: CLP | AH3: COP | AI3: ZAR | AJ3: TRY | AK3: PLN
A4: 38017 | B4: 3.0823 | C4: 10.9023 | D4: 652.5266 | E4: 2270.9169 | F4: 6.1991 | G4: 1.3872 | H4: 4.0673 | I4: 100.526 | J4: 100.406 | K4: 100.278 | L4: 100.314 | M4: 100.486 | N4: 100.943 | O4: 100.266 | P4: 100.203 | Q4: =(I4/$P4)/(I$4/$P$4)/(B4/B$4)*100 -> 100 | R4: =(J4/$P4)/(J$4/$P$4)/(C4/C$4)*100 -> 100 | S4: =(K4/$P4)/(K$4/$P$4)/(D4/D$4)*100 -> 100 | T4: =(L4/$P4)/(L$4/$P$4)/(E4/E$4)*100 -> 100 | U4: =(M4/$P4)/(M$4/$P$4)/(F4/F$4)*100 -> 100 | V4: =(N4/$P4)/(N$4/$P$4)/(G4/G$4)*100 -> 100 | W4: =(O4/$P4)/(O$4/$P$4)/(H4/H$4)*100 -> 100 | X4: =-(LN(Q4)-LN(AVERAGE(Q$4:Q4))) -> 0 | Y4: =-(LN(R4)-LN(AVERAGE(R$4:R4))) -> 0 | Z4: =-(LN(S4)-LN(AVERAGE(S$4:S4))) -> 0 | AA4: =-(LN(T4)-LN(AVERAGE(T$4:T4))) -> 0 | AB4: =-(LN(U4)-LN(AVERAGE(U$4:U4))) -> 0 | AC4: =-(LN(V4)-LN(AVERAGE(V$4:V4))) -> 0 | AD4: =-(LN(w4)-LN(AVERAGE(W$4:W4))) -> 3.912023
A5: 38046 | B5: 3.0631 | C5: 10.9988 | D5: 678.2575 | E5: 2265.5455 | F5: 6.4573 | G5: 1.3666 | H5: 3.9147 | I5: 100.984 | J5: 100.864 | K5: 100.418 | L5: 100.397 | M5: 100.812 | N5: 102.036 | O5: 100.354 | P5: 100.54 | Q5: =(I5/$P5)/(I$4/$P$4)/(B5/B$4)*100 -> 100.74645 | R5: =(J5/$P5)/(J$4/$P$4)/(C5/C$4)*100 -> 99.241013 | S5: =(K5/$P5)/(K$4/$P$4)/(D5/D$4)*100 -> 96.017714 | T5: =(L5/$P5)/(L$4/$P$4)/(E5/E$4)*100 -> 99.983764 | U5: =(M5/$P5)/(M$4/$P$4)/(F5/F$4)*100 -> 95.990045 | V5: =(N5/$P5)/(N$4/$P$4)/(G5/G$4)*100 -> 102.26258 | W5: =(O5/$P5)/(O$4/$P$4)/(H5/H$4)*100 -> 103.64075 | X5: =-(LN(Q5)-LN(AVERAGE(Q$4:Q5))) -> -0.0037114641 | Y5: =-(LN(R5)-LN(AVERAGE(R$4:R5))) -> 0.0038166665 | Z5: =-(LN(S5)-LN(AVERAGE(S$4:S5))) -> 0.020525156 | AA5: =-(LN(T5)-LN(AVERAGE(T$4:T5))) -> 8.1187415e-05 | AB5: =-(LN(U5)-LN(AVERAGE(U$4:U5))) -> 0.0206722 | AC5: =-(LN(V5)-LN(AVERAGE(V$4:V5))) -> -0.011124222 | AD5: =-(LN(W5)-LN(AVERAGE(W$4:W5))) -> -0.017720378 | AE5: =LN(B4/B5) -> 0.0062485965 | AF5: =LN(C4/C5) -> -0.0088123998 | AG5: =LN(D4/D5) -> -0.038675105 | AH5: =LN(E4/E5) -> 0.0023681019 | AI5: =LN(F4/F5) -> -0.040807154 | AJ5: =LN(G4/G5) -> 0.014961424 | AK5: =LN(H4/H5) -> 0.03824069
A6: 38077 | B6: 3.012 | C6: 10.8222 | D6: 685.6233 | E6: 2327.7761 | F6: 6.6255 | G6: 1.3612 | H6: 3.8341 | I6: 101.413 | J6: 101.273 | K6: 100.806 | L6: 100.874 | M6: 101.25 | N6: 103.463 | O6: 100.394 | P6: 100.864 | Q6: =(I6/$P6)/(I$4/$P$4)/(B6/B$4)*100 -> 102.5604 | R6: =(J6/$P6)/(J$4/$P$4)/(C6/C$4)*100 -> 100.94414 | S6: =(K6/$P6)/(K$4/$P$4)/(D6/D$4)*100 -> 95.046889 | T6: =(L6/$P6)/(L$4/$P$4)/(E6/E$4)*100 -> 97.459071 | U6: =(M6/$P6)/(M$4/$P$4)/(F6/F$4)*100 -> 93.657809 | V6: =(N6/$P6)/(N$4/$P$4)/(G6/G$4)*100 -> 103.76969 | W6: =(O6/$P6)/(O$4/$P$4)/(H6/H$4)*100 -> 105.5216 | X6: =-(LN(Q6)-LN(AVERAGE(Q$4:Q6))) -> -0.014319188 | Y6: =-(LN(R6)-LN(AVERAGE(R$4:R6))) -> -0.0087801331 | Z6: =-(LN(S6)-LN(AVERAGE(S$4:S6))) -> 0.020562617 | AA6: =-(LN(T6)-LN(AVERAGE(T$4:T6))) -> 0.017177261 | AB6: =-(LN(U6)-LN(AVERAGE(U$4:U6))) -> 0.030405788 | AC6: =-(LN(V6)-LN(AVERAGE(V$4:V6))) -> -0.017095701 | AD6: =-(LN(W6)-LN(AVERAGE(W$4:W6))) -> -0.023661418 | AE6: =LN(B5/B6) -> 0.016823165 | AF6: =LN(C5/C6) -> 0.016186596 | AG6: =LN(D5/D6) -> -0.010801342 | AH6: =LN(E5/E6) -> -0.027097779 | AI6: =LN(F5/F6) -> -0.025714567 | AJ6: =LN(G5/G6) -> 0.0039592397 | AK6: =LN(H5/H6) -> 0.020803971
A7: 38107 | B7: 2.897 | C7: 11.0535 | D7: 691.3283 | E7: 2466.8603 | F7: 6.6192 | G7: 1.3152 | H7: 3.9423 | I7: 101.887 | J7: 101.637 | K7: 101.157 | L7: 101.031 | M7: 101.712 | N7: 104.739 | O7: 100.58 | P7: 101.015 | Q7: =(I7/$P7)/(I$4/$P$4)/(B7/B$4)*100 -> 106.96991 | R7: =(J7/$P7)/(J$4/$P$4)/(C7/C$4)*100 -> 99.038793 | S7: =(K7/$P7)/(K$4/$P$4)/(D7/D$4)*100 -> 94.44936 | T7: =(L7/$P7)/(L$4/$P$4)/(E7/E$4)*100 -> 91.969674 | U7: =(M7/$P7)/(M$4/$P$4)/(F7/F$4)*100 -> 94.033939 | V7: =(N7/$P7)/(N$4/$P$4)/(G7/G$4)*100 -> 108.56113 | W7: =(O7/$P7)/(O$4/$P$4)/(H7/H$4)*100 -> 102.66191 | X7: =-(LN(Q7)-LN(AVERAGE(Q$4:Q7))) -> -0.042010008 | Y7: =-(LN(R7)-LN(AVERAGE(R$4:R7))) -> 0.0077165453 | Z7: =-(LN(S7)-LN(AVERAGE(S$4:S7))) -> 0.020219237 | AA7: =-(LN(T7)-LN(AVERAGE(T$4:T7))) -> 0.056885967 | AB7: =-(LN(U7)-LN(AVERAGE(U$4:U7))) -> 0.019863411 | AC7: =-(LN(V7)-LN(AVERAGE(V$4:V7))) -> -0.0463095 | AD7: =-(LN(W7)-LN(AVERAGE(W$4:W7))) -> 0.0028612053 | AE7: =LN(B6/B7) -> 0.038928591 | AF7: =LN(C6/C7) -> -0.02114754 | AG7: =LN(D6/D7) -> -0.0082864679 | AH7: =LN(E6/E7) -> -0.05803286 | AI7: =LN(F6/F7) -> 0.000951324 | AJ7: =LN(G6/G7) -> 0.034377918 | AK7: =LN(H6/H7) -> -0.027829583
A8: 38138 | B8: 2.878 | C8: 10.9931 | D8: 651.5512 | E8: 2592.9368 | F8: 6.5974 | G8: 1.3482 | H8: 3.9813 | I8: 102.412 | J8: 101.914 | K8: 101.584 | L8: 101.464 | M8: 102.311 | N8: 105.742 | O8: 100.755 | P8: 101.186 | Q8: =(I8/$P8)/(I$4/$P$4)/(B8/B$4)*100 -> 108.04803 | R8: =(J8/$P8)/(J$4/$P$4)/(C8/C$4)*100 -> 99.6856 | S8: =(K8/$P8)/(K$4/$P$4)/(D8/D$4)*100 -> 100.46843 | T8: =(L8/$P8)/(L$4/$P$4)/(E8/E$4)*100 -> 87.724326 | U8: =(M8/$P8)/(M$4/$P$4)/(F8/F$4)*100 -> 94.739894 | V8: =(N8/$P8)/(N$4/$P$4)/(G8/G$4)*100 -> 106.73734 | W8: =(O8/$P8)/(O$4/$P$4)/(H8/H$4)*100 -> 101.66103 | X8: =-(LN(Q8)-LN(AVERAGE(Q$4:Q8))) -> -0.04141172 | Y8: =-(LN(R8)-LN(AVERAGE(R$4:R8))) -> 0.00096566617 | Z8: =-(LN(S8)-LN(AVERAGE(S$4:S8))) -> -0.033109062 | AA8: =-(LN(T8)-LN(AVERAGE(T$4:T8))) -> 0.08416617 | AB8: =-(LN(U8)-LN(AVERAGE(U$4:U8))) -> 0.0099194457 | AC8: =-(LN(V8)-LN(AVERAGE(V$4:V8))) -> -0.023424291 | AD8: =-(LN(W8)-LN(AVERAGE(W$4:W8))) -> 0.010139414 | AE8: =LN(B7/B8) -> 0.0065801103 | AF8: =LN(C7/C8) -> 0.0054793166 | AG8: =LN(D7/D8) -> 0.059258838 | AH8: =LN(E7/E8) -> -0.049844924 | AI8: =LN(F7/F8) -> 0.0032988847 | AJ8: =LN(G7/G8) -> -0.024781624 | AK8: =LN(H7/H8) -> -0.0098440898
A9: 38168 | B9: 2.9946 | C9: 11.4654 | D9: 619.8892 | E9: 2504.1313 | F9: 6.2382 | G9: 1.3051 | H9: 4.0561 | I9: 102.786 | J9: 102.288 | K9: 102.009 | L9: 102.188 | M9: 102.827 | N9: 106.867 | O9: 100.963 | P9: 101.335 | Q9: =(I9/$P9)/(I$4/$P$4)/(B9/B$4)*100 -> 104.06697 | R9: =(J9/$P9)/(J$4/$P$4)/(C9/C$4)*100 -> 95.788901 | S9: =(K9/$P9)/(K$4/$P$4)/(D9/D$4)*100 -> 105.88592 | T9: =(L9/$P9)/(L$4/$P$4)/(E9/E$4)*100 -> 91.34899 | U9: =(M9/$P9)/(M$4/$P$4)/(F9/F$4)*100 -> 100.55235 | V9: =(N9/$P9)/(N$4/$P$4)/(G9/G$4)*100 -> 111.2715 | W9: =(O9/$P9)/(O$4/$P$4)/(H9/H$4)*100 -> 99.845239 | X9: =-(LN(Q9)-LN(AVERAGE(Q$4:Q9))) -> -0.003224353 | Y9: =-(LN(R9)-LN(AVERAGE(R$4:R9))) -> 0.034148176 | Z9: =-(LN(S9)-LN(AVERAGE(S$4:S9))) -> -0.07083762 | AA9: =-(LN(T9)-LN(AVERAGE(T$4:T9))) -> 0.036529685 | AB9: =-(LN(U9)-LN(AVERAGE(U$4:U9))) -> -0.041180287 | AC9: =-(LN(V9)-LN(AVERAGE(V$4:V9))) -> -0.053890805 | AD9: =-(LN(W9)-LN(AVERAGE(W$4:W9))) -> 0.023523152 | AE9: =LN(B8/B9) -> -0.039715058 | AF9: =LN(C8/C9) -> -0.042066001 | AG9: =LN(D8/D9) -> 0.049815229 | AH9: =LN(E8/E9) -> 0.034849245 | AI9: =LN(F8/F9) -> 0.055983953 | AJ9: =LN(G8/G9) -> 0.032490703 | AK9: =LN(H8/H9) -> -0.018613522
A10: 38199 | B10: 2.8438 | C10: 11.0978 | D10: 656.3564 | E10: 2384.2895 | F10: 6.0916 | G10: 1.3179 | H10: 4.0834 | I10: 103.29 | J10: 102.725 | K10: 102.434 | L10: 102.415 | M10: 103.212 | N10: 107.995 | O10: 100.99 | P10: 101.596 | Q10: =(I10/$P10)/(I$4/$P$4)/(B10/B$4)*100 -> 109.83983 | R10: =(J10/$P10)/(J$4/$P$4)/(C10/C$4)*100 -> 99.129253 | S10: =(K10/$P10)/(K$4/$P$4)/(D10/D$4)*100 -> 100.16156 | T10: =(L10/$P10)/(L$4/$P$4)/(E10/E$4)*100 -> 95.906577 | U10: =(M10/$P10)/(M$4/$P$4)/(F10/F$4)*100 -> 103.09225 | V10: =(N10/$P10)/(N$4/$P$4)/(G10/G$4)*100 -> 111.0678 | W10: =(O10/$P10)/(O$4/$P$4)/(H10/H$4)*100 -> 98.949381 | X10: =-(LN(Q10)-LN(AVERAGE(Q$4:Q10))) -> -0.04883651 | Y10: =-(LN(R10)-LN(AVERAGE(R$4:R10))) -> -0.00011107157 | Z10: =-(LN(S10)-LN(AVERAGE(S$4:S10))) -> -0.013065501 | AA10: =-(LN(T10)-LN(AVERAGE(T$4:T10))) -> -0.010411771 | AB10: =-(LN(U10)-LN(AVERAGE(U$4:U10))) -> -0.056407518 | AC10: =-(LN(V10)-LN(AVERAGE(V$4:V10))) -> -0.044453551 | AD10: =-(LN(W10)-LN(AVERAGE(W$4:W10))) -> 0.027952415 | AE10: =LN(B9/B10) -> 0.051669481 | AF10: =LN(C9/C10) -> 0.032586914 | AG10: =LN(D9/D10) -> -0.057163182 | AH10: =LN(E9/E10) -> 0.049040712 | AI10: =LN(F9/F10) -> 0.023780906 | AJ10: =LN(G9/G10) -> -0.0097598945 | AK10: =LN(H9/H10) -> -0.0067080539
A11: 38230 | B11: 2.8835 | C11: 10.9373 | D11: 647.7642 | E11: 2598.7366 | F11: 6.3668 | G11: 1.3334 | H11: 4.2852 | I11: 103.797 | J11: 103.147 | K11: 102.695 | L11: 102.847 | M11: 103.719 | N11: 109.495 | O11: 101.187 | P11: 101.793 | Q11: =(I11/$P11)/(I$4/$P$4)/(B11/B$4)*100 -> 108.64861 | R11: =(J11/$P11)/(J$4/$P$4)/(C11/C$4)*100 -> 100.80168 | S11: =(K11/$P11)/(K$4/$P$4)/(D11/D$4)*100 -> 101.55182 | T11: =(L11/$P11)/(L$4/$P$4)/(E11/E$4)*100 -> 88.192544 | U11: =(M11/$P11)/(M$4/$P$4)/(F11/F$4)*100 -> 98.928861 | V11: =(N11/$P11)/(N$4/$P$4)/(G11/G$4)*100 -> 111.08605 | W11: =(O11/$P11)/(O$4/$P$4)/(H11/H$4)*100 -> 94.29072 | X11: =-(LN(Q11)-LN(AVERAGE(Q$4:Q11))) -> -0.033111229 | Y11: =-(LN(R11)-LN(AVERAGE(R$4:R11))) -> -0.014720702 | Z11: =-(LN(S11)-LN(AVERAGE(S$4:S11))) -> -0.023454286 | AA11: =-(LN(T11)-LN(AVERAGE(T$4:T11))) -> 0.064549912 | AB11: =-(LN(U11)-LN(AVERAGE(U$4:U11))) -> -0.013273624 | AC11: =-(LN(V11)-LN(AVERAGE(V$4:V11))) -> -0.038930505 | AD11: =-(LN(W11)-LN(AVERAGE(W$4:W11))) -> 0.066967163 | AE11: =LN(B10/B11) -> -0.013863648 | AF11: =LN(C10/C11) -> 0.014567925 | AG11: =LN(D10/D11) -> 0.013177193 | AH11: =LN(E10/E11) -> -0.086124227 | AI11: =LN(F10/F11) -> -0.044186216 | AJ11: =LN(G10/G11) -> -0.011692511 | AK11: =LN(H10/H11) -> -0.048237251
A12: 38260 | B12: 2.9407 | C12: 10.0125 | D12: 670.2438 | E12: 2502.9242 | F12: 6.3827 | G12: 1.3634 | H12: 4.2023 | I12: 104.299 | J12: 103.54 | K12: 102.777 | L12: 103.063 | M12: 104.261 | N12: 110.663 | O12: 101.559 | P12: 102.073 | Q12: =(I12/$P12)/(I$4/$P$4)/(B12/B$4)*100 -> 106.75686 | R12: =(J12/$P12)/(J$4/$P$4)/(C12/C$4)*100 -> 110.22851 | S12: =(K12/$P12)/(K$4/$P$4)/(D12/D$4)*100 -> 97.954757 | T12: =(L12/$P12)/(L$4/$P$4)/(E12/E$4)*100 -> 91.509171 | U12: =(M12/$P12)/(M$4/$P$4)/(F12/F$4)*100 -> 98.925985 | V12: =(N12/$P12)/(N$4/$P$4)/(G12/G$4)*100 -> 109.49943 | W12: =(O12/$P12)/(O$4/$P$4)/(H12/H$4)*100 -> 96.239581 | X12: =-(LN(Q12)-LN(AVERAGE(Q$4:Q12))) -> -0.013806876 | Y12: =-(LN(R12)-LN(AVERAGE(R$4:R12))) -> -0.092002256 | Z12: =-(LN(S12)-LN(AVERAGE(S$4:S12))) -> 0.01121604 | AA12: =-(LN(T12)-LN(AVERAGE(T$4:T12))) -> 0.024600226 | AB12: =-(LN(U12)-LN(AVERAGE(U$4:U12))) -> -0.011764245 | AC12: =-(LN(V12)-LN(AVERAGE(V$4:V12))) -> -0.021787618 | AD12: =-(LN(W12)-LN(AVERAGE(W$4:W12))) -> 0.041447065 | AE12: =LN(B11/B12) -> -0.019642814 | AF12: =LN(C11/C12) -> 0.088344653 | AG12: =LN(D11/D12) -> -0.034114786 | AH12: =LN(E11/E12) -> 0.037565676 | AI12: =LN(F11/F12) -> -0.0024942168 | AJ12: =LN(G11/G12) -> -0.022249509 | AK12: =LN(H11/H12) -> 0.019535231
A13: 38291 | B13: 3.0247 | C13: 9.7433 | D13: 696.5507 | E13: 2560.383 | F13: 6.8653 | G13: 1.3729 | H13: 3.808 | I13: 104.802 | J13: 104.146 | K13: 103.052 | L13: 103.424 | M13: 105.036 | N13: 111.918 | O13: 101.823 | P13: 102.089 | Q13: =(I13/$P13)/(I$4/$P$4)/(B13/B$4)*100 -> 104.27628 | R13: =(J13/$P13)/(J$4/$P$4)/(C13/C$4)*100 -> 113.91916 | S13: =(K13/$P13)/(K$4/$P$4)/(D13/D$4)*100 -> 94.492649 | T13: =(L13/$P13)/(L$4/$P$4)/(E13/E$4)*100 -> 89.754837 | U13: =(M13/$P13)/(M$4/$P$4)/(F13/F$4)*100 -> 92.641059 | V13: =(N13/$P13)/(N$4/$P$4)/(G13/G$4)*100 -> 109.95771 | W13: =(O13/$P13)/(O$4/$P$4)/(H13/H$4)*100 -> 106.46411 | X13: =-(LN(Q13)-LN(AVERAGE(Q$4:Q13))) -> 0.0087369671 | Y13: =-(LN(R13)-LN(AVERAGE(R$4:R13))) -> -0.11171592 | Z13: =-(LN(S13)-LN(AVERAGE(S$4:S13))) -> 0.042578739 | AA13: =-(LN(T13)-LN(AVERAGE(T$4:T13))) -> 0.03964769 | AB13: =-(LN(U13)-LN(AVERAGE(U$4:U13))) -> 0.048616476 | AC13: =-(LN(V13)-LN(AVERAGE(V$4:V13))) -> -0.023337127 | AD13: =-(LN(W13)-LN(AVERAGE(W$4:W13))) -> -0.053406187 | AE13: =LN(B12/B13) -> -0.028164265 | AF13: =LN(C12/C13) -> 0.027254443 | AG13: =LN(D12/D13) -> -0.038499056 | AH13: =LN(E12/E13) -> -0.022697128 | AI13: =LN(F12/F13) -> -0.072888533 | AJ13: =LN(G12/G13) -> -0.006943711 | AK13: =LN(H12/H13) -> 0.098527878
A14: 38321 | B14: 3.2031 | C14: 9.7711 | D14: 721.6297 | E14: 2558.9509 | F14: 7.1808 | G14: 1.444 | H14: 3.9158 | I14: 105.441 | J14: 104.543 | K14: 103.229 | L14: 103.821 | M14: 105.481 | N14: 112.911 | O14: 102.097 | P14: 102.453 | Q14: =(I14/$P14)/(I$4/$P$4)/(B14/B$4)*100 -> 98.716913 | R14: =(J14/$P14)/(J$4/$P$4)/(C14/C$4)*100 -> 113.62294 | S14: =(K14/$P14)/(K$4/$P$4)/(D14/D$4)*100 -> 91.04077 | T14: =(L14/$P14)/(L$4/$P$4)/(E14/E$4)*100 -> 89.829502 | U14: =(M14/$P14)/(M$4/$P$4)/(F14/F$4)*100 -> 88.629956 | V14: =(N14/$P14)/(N$4/$P$4)/(G14/G$4)*100 -> 105.09643 | W14: =(O14/$P14)/(O$4/$P$4)/(H14/H$4)*100 -> 103.44298 | X14: =-(LN(Q14)-LN(AVERAGE(Q$4:Q14))) -> 0.057913546 | Y14: =-(LN(R14)-LN(AVERAGE(R$4:R14))) -> -0.098686126 | Z14: =-(LN(S14)-LN(AVERAGE(S$4:S14))) -> 0.072796854 | AA14: =-(LN(T14)-LN(AVERAGE(T$4:T14))) -> 0.035349022 | AB14: =-(LN(U14)-LN(AVERAGE(U$4:U14))) -> 0.084783037 | AC14: =-(LN(V14)-LN(AVERAGE(V$4:V14))) -> 0.019910902 | AD14: =-(LN(W14)-LN(AVERAGE(W$4:W14))) -> -0.022355521 | AE14: =LN(B13/B14) -> -0.057307178 | AF14: =LN(C13/C14) -> -0.00284918 | AG14: =LN(D13/D14) -> -0.035371543 | AH14: =LN(E13/E14) -> 0.00055948687 | AI14: =LN(F13/F14) -> -0.044931059 | AJ14: =LN(G13/G14) -> -0.05049175 | AK14: =LN(H13/H14) -> -0.027915534
A15: 38352 | B15: 3.257 | C15: 9.4961 | D15: 734.8981 | E15: 2522.2839 | F15: 6.9257 | G15: 1.4896 | H15: 3.8287 | I15: 105.716 | J15: 105.121 | K15: 103.59 | L15: 104.374 | M15: 105.747 | N15: 114.123 | O15: 102.366 | P15: 102.648 | Q15: =(I15/$P15)/(I$4/$P$4)/(B15/B$4)*100 -> 97.151542 | R15: =(J15/$P15)/(J$4/$P$4)/(C15/C$4)*100 -> 117.33644 | S15: =(K15/$P15)/(K$4/$P$4)/(D15/D$4)*100 -> 89.539259 | T15: =(L15/$P15)/(L$4/$P$4)/(E15/E$4)*100 -> 91.446752 | U15: =(M15/$P15)/(M$4/$P$4)/(F15/F$4)*100 -> 91.951262 | V15: =(N15/$P15)/(N$4/$P$4)/(G15/G$4)*100 -> 102.77716 | W15: =(O15/$P15)/(O$4/$P$4)/(H15/H$4)*100 -> 105.87347 | X15: =-(LN(Q15)-LN(AVERAGE(Q$4:Q15))) -> 0.067943982 | Y15: =-(LN(R15)-LN(AVERAGE(R$4:R15))) -> -0.11926405 | Z15: =-(LN(S15)-LN(AVERAGE(S$4:S15))) -> 0.082272814 | AA15: =-(LN(T15)-LN(AVERAGE(T$4:T15))) -> 0.016058462 | AB15: =-(LN(U15)-LN(AVERAGE(U$4:U15))) -> 0.044081559 | AC15: =-(LN(V15)-LN(AVERAGE(V$4:V15))) -> 0.038774545 | AD15: =-(LN(W15)-LN(AVERAGE(W$4:W15))) -> -0.04170097 | AE15: =LN(B14/B15) -> -0.016687435 | AF15: =LN(C14/C15) -> 0.028547861 | AG15: =LN(D14/D15) -> -0.018219724 | AH15: =LN(E14/E15) -> 0.014432569 | AI15: =LN(F14/F15) -> 0.036171667 | AJ15: =LN(G14/G15) -> -0.031090587 | AK15: =LN(H14/H15) -> 0.022494331
A16: 38383 | B16: 3.2791 | C16: 9.4543 | D16: 738.3999 | E16: 2523.1447 | F16: 7.0499 | G16: 1.5443 | H16: 3.9762 | I16: 106.144 | J16: 105.535 | K16: 103.852 | L16: 104.893 | M16: 105.933 | N16: 115.24 | O16: 102.607 | P16: 102.923 | Q16: =(I16/$P16)/(I$4/$P$4)/(B16/B$4)*100 -> 96.628576 | R16: =(J16/$P16)/(J$4/$P$4)/(C16/C$4)*100 -> 118.00323 | S16: =(K16/$P16)/(K$4/$P$4)/(D16/D$4)*100 -> 89.101308 | T16: =(L16/$P16)/(L$4/$P$4)/(E16/E$4)*100 -> 91.62465 | U16: =(M16/$P16)/(M$4/$P$4)/(F16/F$4)*100 -> 90.248436 | V16: =(N16/$P16)/(N$4/$P$4)/(G16/G$4)*100 -> 99.839578 | W16: =(O16/$P16)/(O$4/$P$4)/(H16/H$4)*100 -> 101.913 | X16: =-(LN(Q16)-LN(AVERAGE(Q$4:Q16))) -> 0.06788693 | Y16: =-(LN(R16)-LN(AVERAGE(R$4:R16))) -> -0.11474657 | Z16: =-(LN(S16)-LN(AVERAGE(S$4:S16))) -> 0.080733408 | AA16: =-(LN(T16)-LN(AVERAGE(T$4:T16))) -> 0.013036255 | AB16: =-(LN(U16)-LN(AVERAGE(U$4:U16))) -> 0.058082652 | AC16: =-(LN(V16)-LN(AVERAGE(V$4:V16))) -> 0.062719711 | AD16: =-(LN(W16)-LN(AVERAGE(W$4:W16))) -> -0.0033002418 | AE16: =LN(B15/B16) -> -0.0067624682 | AF16: =LN(C15/C16) -> 0.0044115235 | AG16: =LN(D15/D16) -> -0.0047536976 | AH16: =LN(E15/E16) -> -0.00034121978 | AI16: =LN(F15/F16) -> -0.017774302 | AJ16: =LN(G15/G16) -> -0.036063106 | AK16: =LN(H15/H16) -> -0.037801269
... A276: 46295 | B276: 5.6154 | C276: 18.5313 | D276: 616.6608 | E276: 4850.8656 | F276: 11.6312 | G276: 14.7348 | H276: 5.0772 | I276: 335.878 | J276: 258.586 | K276: 204.864 | L276: 297.689 | M276: 325.903 | N276: 1908.363 | O276: 196.186 | P276: 173.73 | Q276: =(I276/$P276)/(I$4/$P$4)/(B276/B$4)*100 -> 105.77993 | R276: =(J276/$P276)/(J$4/$P$4)/(C276/C$4)*100 -> 87.390352 | S276: =(K276/$P276)/(K$4/$P$4)/(D276/D$4)*100 -> 124.68602 | T276: =(L276/$P276)/(L$4/$P$4)/(E276/E$4)*100 -> 80.128893 | U276: =(M276/$P276)/(M$4/$P$4)/(F276/F$4)*100 -> 99.699464 | V276: =(N276/$P276)/(N$4/$P$4)/(G276/G$4)*100 -> 102.65628 | W276: =(O276/$P276)/(O$4/$P$4)/(H276/H$4)*100 -> 90.407022 | X276: =-(LN(Q276)-LN(AVERAGE(Q$4:Q276))) -> 0.039396313 | Y276: =-(LN(R276)-LN(AVERAGE(R$4:R276))) -> 0.12502047 | Z276: =-(LN(S276)-LN(AVERAGE(S$4:S276))) -> -0.099500725 | AA276: =-(LN(T276)-LN(AVERAGE(T$4:T276))) -> 0.15889029 | AB276: =-(LN(U276)-LN(AVERAGE(U$4:U276))) -> 0.01156223 | AC276: =-(LN(V276)-LN(AVERAGE(V$4:V276))) -> -0.020444761 | AD276: =-(LN(W276)-LN(AVERAGE(W$4:W276))) -> 0.18777428 | AE276: =LN(B275/B276) -> -0.034071051 | AF276: =LN(C275/C276) -> 0.061705515 | AG276: =LN(D275/D276) -> 0.053266444 | AH276: =LN(E275/E276) -> -0.0044929689 | AI276: =LN(F275/F276) -> 0.039373804 | AJ276: =LN(G275/G276) -> 0.020035742 | AK276: =LN(H275/H276) -> -0.016262458
A278: Synthetic placeholder data. Replace the yellow blocks with BDH pulls from Tickers. Formula columns update automatically.
A279: Placeholder spot is generated from a mean-reverting real exchange rate, which is the premise the signal rests on. Real data will not be this well behaved.

Sheet Rates_Data
A1: Rates Data
A2: Signal: adjusted real short rate = 3-month rate less expected inflation 12 months ahead, then measured against each market's OWN expanding mean. Higher = cheaper. Return approximated as minus duration times the change in the 2-year yield. Yellow = paste BDH here. | B2: 3-month rate, % — INPUT | I2: Expected inflation 12m ahead, % — INPUT | P2: 2-year government yield, % — INPUT | W2: Real short rate, % | AD2: Valuation: cheapness vs own history | AK2: Monthly return to a long position
A3: Date | B3: US | C3: DE | D3: GB | E3: CA | F3: AU | G3: JP | H3: NZ | I3: US | J3: DE | K3: GB | L3: CA | M3: AU | N3: JP | O3: NZ | P3: US | Q3: DE | R3: GB | S3: CA | T3: AU | U3: JP | V3: NZ | W3: US | X3: DE | Y3: GB | Z3: CA | AA3: AU | AB3: JP | AC3: NZ | AD3: US | AE3: DE | AF3: GB | AG3: CA | AH3: AU | AI3: JP | AJ3: NZ | AK3: US | AL3: DE | AM3: GB | AN3: CA | AO3: AU | AP3: JP | AQ3: NZ
A4: 38017 | B4: 2.48 | C4: 1.673 | D4: 2.773 | E4: 2.018 | F4: 3.365 | G4: 0.297 | H4: 4.049 | I4: 2.035 | J4: 1.699 | K4: 2.134 | L4: 1.834 | M4: 2.5 | N4: 0.297 | O4: 2.173 | P4: 2.69 | Q4: 1.962 | R4: 2.965 | S4: 2.332 | T4: 3.465 | U4: 0.586 | V4: 4.346 | W4: =B4-I4 -> 0.445 | X4: =C4-J4 -> -0.026 | Y4: =D4-K4 -> 0.639 | Z4: =E4-L4 -> 0.184 | AA4: =F4-M4 -> 0.865 | AB4: =G4-N4 -> 0 | AC4: =H4-O4 -> 1.876 | AD4: =w4-AVERAGE(W$4:W4) -> 1.555 | AE4: =X4-AVERAGE(X$4:X4) -> 0 | AF4: =Y4-AVERAGE(Y$4:Y4) -> 0 | AG4: =z4-AVERAGE(Z$4:Z4) -> 3.816 | AH4: =AA4-AVERAGE(AA$4:AA4) -> 0 | AI4: =AB4-AVERAGE(AB$4:AB4) -> 0 | AJ4: =AC4-AVERAGE(AC$4:AC4) -> 0
A5: 38046 | B5: 2.681 | C5: 1.838 | D5: 2.56 | E5: 2.007 | F5: 3.545 | G5: -0.05 | H5: 4.035 | I5: 2.143 | J5: 1.835 | K5: 2.18 | L5: 1.929 | M5: 2.434 | N5: 0.293 | O5: 2.082 | P5: 2.834 | Q5: 2.255 | R5: 2.807 | S5: 2.399 | T5: 3.846 | U5: 0.163 | V5: 4.348 | W5: =B5-I5 -> 0.538 | X5: =C5-J5 -> 0.003 | Y5: =D5-K5 -> 0.38 | Z5: =E5-L5 -> 0.078 | AA5: =F5-M5 -> 1.111 | AB5: =G5-N5 -> -0.343 | AC5: =H5-O5 -> 1.953 | AD5: =W5-AVERAGE(W$4:W5) -> 0.0465 | AE5: =X5-AVERAGE(X$4:X5) -> 0.0145 | AF5: =Y5-AVERAGE(Y$4:Y5) -> -0.1295 | AG5: =Z5-AVERAGE(Z$4:Z5) -> -0.053 | AH5: =AA5-AVERAGE(AA$4:AA5) -> 0.123 | AI5: =AB5-AVERAGE(AB$4:AB5) -> -0.1715 | AJ5: =AC5-AVERAGE(AC$4:AC5) -> 0.0385 | AK5: =-RateDur*(P5-P4)/100 -> -0.002736 | AL5: =-RateDur*(Q5-Q4)/100 -> -0.005567 | AM5: =-RateDur*(R5-R4)/100 -> 0.003002 | AN5: =-RateDur*(S5-S4)/100 -> -0.001273 | AO5: =-RateDur*(T5-T4)/100 -> -0.007239 | AP5: =-RateDur*(U5-U4)/100 -> 0.008037 | AQ5: =-RateDur*(V5-V4)/100 -> -3.8e-05
A6: 38077 | B6: 2.99 | C6: 1.886 | D6: 2.694 | E6: 2.08 | F6: 3.451 | G6: -0.161 | H6: 4.202 | I6: 2.216 | J6: 1.801 | K6: 2.262 | L6: 2.015 | M6: 2.379 | N6: 0.311 | O6: 2.105 | P6: 3.093 | Q6: 2.016 | R6: 3.029 | S6: 2.441 | T6: 4.023 | U6: -0.034 | V6: 4.508 | W6: =B6-I6 -> 0.774 | X6: =C6-J6 -> 0.085 | Y6: =D6-K6 -> 0.432 | Z6: =E6-L6 -> 0.065 | AA6: =F6-M6 -> 1.072 | AB6: =G6-N6 -> -0.472 | AC6: =H6-O6 -> 2.097 | AD6: =W6-AVERAGE(W$4:W6) -> 0.18833333 | AE6: =X6-AVERAGE(X$4:X6) -> 0.064333333 | AF6: =Y6-AVERAGE(Y$4:Y6) -> -0.051666667 | AG6: =Z6-AVERAGE(Z$4:Z6) -> -0.044 | AH6: =AA6-AVERAGE(AA$4:AA6) -> 0.056 | AI6: =AB6-AVERAGE(AB$4:AB6) -> -0.20033333 | AJ6: =AC6-AVERAGE(AC$4:AC6) -> 0.12166667 | AK6: =-RateDur*(P6-P5)/100 -> -0.004921 | AL6: =-RateDur*(Q6-Q5)/100 -> 0.004541 | AM6: =-RateDur*(R6-R5)/100 -> -0.004218 | AN6: =-RateDur*(S6-S5)/100 -> -0.000798 | AO6: =-RateDur*(T6-T5)/100 -> -0.003363 | AP6: =-RateDur*(U6-U5)/100 -> 0.003743 | AQ6: =-RateDur*(V6-V5)/100 -> -0.00304
A7: 38107 | B7: 3.23 | C7: 2.025 | D7: 2.865 | E7: 2.349 | F7: 3.336 | G7: -0.181 | H7: 4.36 | I7: 2.107 | J7: 1.833 | K7: 2.339 | L7: 1.979 | M7: 2.277 | N7: 0.134 | O7: 2.152 | P7: 3.547 | Q7: 2.249 | R7: 3.109 | S7: 2.669 | T7: 3.53 | U7: 0.049 | V7: 4.599 | W7: =B7-I7 -> 1.123 | X7: =C7-J7 -> 0.192 | Y7: =D7-K7 -> 0.526 | Z7: =E7-L7 -> 0.37 | AA7: =F7-M7 -> 1.059 | AB7: =G7-N7 -> -0.315 | AC7: =H7-O7 -> 2.208 | AD7: =W7-AVERAGE(W$4:W7) -> 0.403 | AE7: =X7-AVERAGE(X$4:X7) -> 0.1285 | AF7: =Y7-AVERAGE(Y$4:Y7) -> 0.03175 | AG7: =Z7-AVERAGE(Z$4:Z7) -> 0.19575 | AH7: =AA7-AVERAGE(AA$4:AA7) -> 0.03225 | AI7: =AB7-AVERAGE(AB$4:AB7) -> -0.0325 | AJ7: =AC7-AVERAGE(AC$4:AC7) -> 0.1745 | AK7: =-RateDur*(P7-P6)/100 -> -0.008626 | AL7: =-RateDur*(Q7-Q6)/100 -> -0.004427 | AM7: =-RateDur*(R7-R6)/100 -> -0.00152 | AN7: =-RateDur*(S7-S6)/100 -> -0.004332 | AO7: =-RateDur*(T7-T6)/100 -> 0.009367 | AP7: =-RateDur*(U7-U6)/100 -> -0.001577 | AQ7: =-RateDur*(V7-V6)/100 -> -0.001729
A8: 38138 | B8: 2.954 | C8: 1.983 | D8: 2.703 | E8: 2.658 | F8: 3.164 | G8: -0.274 | H8: 4.04 | I8: 1.983 | J8: 1.818 | K8: 2.262 | L8: 2.026 | M8: 2.364 | N8: 0.265 | O8: 2.096 | P8: 3.289 | Q8: 1.974 | R8: 3.033 | S8: 2.873 | T8: 3.454 | U8: -0.004 | V8: 4.215 | W8: =B8-I8 -> 0.971 | X8: =C8-J8 -> 0.165 | Y8: =D8-K8 -> 0.441 | Z8: =E8-L8 -> 0.632 | AA8: =F8-M8 -> 0.8 | AB8: =G8-N8 -> -0.539 | AC8: =H8-O8 -> 1.944 | AD8: =W8-AVERAGE(W$4:W8) -> 0.2008 | AE8: =X8-AVERAGE(X$4:X8) -> 0.0812 | AF8: =Y8-AVERAGE(Y$4:Y8) -> -0.0426 | AG8: =Z8-AVERAGE(Z$4:Z8) -> 0.3662 | AH8: =AA8-AVERAGE(AA$4:AA8) -> -0.1814 | AI8: =AB8-AVERAGE(AB$4:AB8) -> -0.2052 | AJ8: =AC8-AVERAGE(AC$4:AC8) -> -0.0716 | AK8: =-RateDur*(P8-P7)/100 -> 0.004902 | AL8: =-RateDur*(Q8-Q7)/100 -> 0.005225 | AM8: =-RateDur*(R8-R7)/100 -> 0.001444 | AN8: =-RateDur*(S8-S7)/100 -> -0.003876 | AO8: =-RateDur*(T8-T7)/100 -> 0.001444 | AP8: =-RateDur*(U8-U7)/100 -> 0.001007 | AQ8: =-RateDur*(V8-V7)/100 -> 0.007296
A9: 38168 | B9: 2.965 | C9: 1.962 | D9: 2.59 | E9: 2.669 | F9: 2.972 | G9: -0.142 | H9: 4.152 | I9: 1.985 | J9: 1.836 | K9: 2.19 | L9: 2.186 | M9: 2.493 | N9: 0.064 | O9: 2.197 | P9: 3.234 | Q9: 2.202 | R9: 2.756 | S9: 2.888 | T9: 3.195 | U9: 0.065 | V9: 4.405 | W9: =B9-I9 -> 0.98 | X9: =C9-J9 -> 0.126 | Y9: =D9-K9 -> 0.4 | Z9: =E9-L9 -> 0.483 | AA9: =F9-M9 -> 0.479 | AB9: =G9-N9 -> -0.206 | AC9: =H9-O9 -> 1.955 | AD9: =W9-AVERAGE(W$4:W9) -> 0.17483333 | AE9: =X9-AVERAGE(X$4:X9) -> 0.035166667 | AF9: =Y9-AVERAGE(Y$4:Y9) -> -0.069666667 | AG9: =Z9-AVERAGE(Z$4:Z9) -> 0.181 | AH9: =AA9-AVERAGE(AA$4:AA9) -> -0.41866667 | AI9: =AB9-AVERAGE(AB$4:AB9) -> 0.1065 | AJ9: =AC9-AVERAGE(AC$4:AC9) -> -0.0505 | AK9: =-RateDur*(P9-P8)/100 -> 0.001045 | AL9: =-RateDur*(Q9-Q8)/100 -> -0.004332 | AM9: =-RateDur*(R9-R8)/100 -> 0.005263 | AN9: =-RateDur*(S9-S8)/100 -> -0.000285 | AO9: =-RateDur*(T9-T8)/100 -> 0.004921 | AP9: =-RateDur*(U9-U8)/100 -> -0.001311 | AQ9: =-RateDur*(V9-V8)/100 -> -0.00361
A10: 38199 | B10: 2.887 | C10: 1.77 | D10: 2.54 | E10: 2.53 | F10: 2.774 | G10: -0.32 | H10: 4.295 | I10: 1.974 | J10: 1.833 | K10: 2.208 | L10: 2.239 | M10: 2.567 | N10: 0.169 | O10: 2.031 | P10: 3.031 | Q10: 2.071 | R10: 2.765 | S10: 2.752 | T10: 3.086 | U10: 0.026 | V10: 4.575 | W10: =B10-I10 -> 0.913 | X10: =C10-J10 -> -0.063 | Y10: =D10-K10 -> 0.332 | Z10: =E10-L10 -> 0.291 | AA10: =F10-M10 -> 0.207 | AB10: =G10-N10 -> -0.489 | AC10: =H10-O10 -> 2.264 | AD10: =W10-AVERAGE(W$4:W10) -> 0.092428571 | AE10: =X10-AVERAGE(X$4:X10) -> -0.13185714 | AF10: =Y10-AVERAGE(Y$4:Y10) -> -0.118 | AG10: =Z10-AVERAGE(Z$4:Z10) -> -0.0094285714 | AH10: =AA10-AVERAGE(AA$4:AA10) -> -0.592 | AI10: =AB10-AVERAGE(AB$4:AB10) -> -0.15128571 | AJ10: =AC10-AVERAGE(AC$4:AC10) -> 0.22157143 | AK10: =-RateDur*(P10-P9)/100 -> 0.003857 | AL10: =-RateDur*(Q10-Q9)/100 -> 0.002489 | AM10: =-RateDur*(R10-R9)/100 -> -0.000171 | AN10: =-RateDur*(S10-S9)/100 -> 0.002584 | AO10: =-RateDur*(T10-T9)/100 -> 0.002071 | AP10: =-RateDur*(U10-U9)/100 -> 0.000741 | AQ10: =-RateDur*(V10-V9)/100 -> -0.00323
A11: 38230 | B11: 2.93 | C11: 2.087 | D11: 2.351 | E11: 2.242 | F11: 2.642 | G11: -0.267 | H11: 4.058 | I11: 1.983 | J11: 1.902 | K11: 2.247 | L11: 2.113 | M11: 2.48 | N11: 0.188 | O11: 2.108 | P11: 3.156 | Q11: 2.399 | R11: 2.372 | S11: 2.503 | T11: 2.872 | U11: -0.007 | V11: 4.437 | W11: =B11-I11 -> 0.947 | X11: =C11-J11 -> 0.185 | Y11: =D11-K11 -> 0.104 | Z11: =E11-L11 -> 0.129 | AA11: =F11-M11 -> 0.162 | AB11: =G11-N11 -> -0.455 | AC11: =H11-O11 -> 1.95 | AD11: =W11-AVERAGE(W$4:W11) -> 0.110625 | AE11: =X11-AVERAGE(X$4:X11) -> 0.101625 | AF11: =Y11-AVERAGE(Y$4:Y11) -> -0.30275 | AG11: =Z11-AVERAGE(Z$4:Z11) -> -0.15 | AH11: =AA11-AVERAGE(AA$4:AA11) -> -0.557375 | AI11: =AB11-AVERAGE(AB$4:AB11) -> -0.102625 | AJ11: =AC11-AVERAGE(AC$4:AC11) -> -0.080875 | AK11: =-RateDur*(P11-P10)/100 -> -0.002375 | AL11: =-RateDur*(Q11-Q10)/100 -> -0.006232 | AM11: =-RateDur*(R11-R10)/100 -> 0.007467 | AN11: =-RateDur*(S11-S10)/100 -> 0.004731 | AO11: =-RateDur*(T11-T10)/100 -> 0.004066 | AP11: =-RateDur*(U11-U10)/100 -> 0.000627 | AQ11: =-RateDur*(V11-V10)/100 -> 0.002622
A12: 38260 | B12: 2.777 | C12: 2.059 | D12: 2.298 | E12: 2.139 | F12: 2.579 | G12: -0.248 | H12: 4.234 | I12: 1.971 | J12: 1.796 | K12: 2.319 | L12: 2.211 | M12: 2.517 | N12: 0.239 | O12: 2.172 | P12: 2.876 | Q12: 2.264 | R12: 2.575 | S12: 2.337 | T12: 2.853 | U12: 0.059 | V12: 4.601 | W12: =B12-I12 -> 0.806 | X12: =C12-J12 -> 0.263 | Y12: =D12-K12 -> -0.021 | Z12: =E12-L12 -> -0.072 | AA12: =F12-M12 -> 0.062 | AB12: =G12-N12 -> -0.487 | AC12: =H12-O12 -> 2.062 | AD12: =W12-AVERAGE(W$4:W12) -> -0.027 | AE12: =X12-AVERAGE(X$4:X12) -> 0.15966667 | AF12: =Y12-AVERAGE(Y$4:Y12) -> -0.38022222 | AG12: =Z12-AVERAGE(Z$4:Z12) -> -0.312 | AH12: =AA12-AVERAGE(AA$4:AA12) -> -0.58433333 | AI12: =AB12-AVERAGE(AB$4:AB12) -> -0.11966667 | AJ12: =AC12-AVERAGE(AC$4:AC12) -> 0.027666667 | AK12: =-RateDur*(P12-P11)/100 -> 0.00532 | AL12: =-RateDur*(Q12-Q11)/100 -> 0.002565 | AM12: =-RateDur*(R12-R11)/100 -> -0.003857 | AN12: =-RateDur*(S12-S11)/100 -> 0.003154 | AO12: =-RateDur*(T12-T11)/100 -> 0.000361 | AP12: =-RateDur*(U12-U11)/100 -> -0.001254 | AQ12: =-RateDur*(V12-V11)/100 -> -0.003116
A13: 38291 | B13: 2.678 | C13: 1.807 | D13: 2.512 | E13: 1.913 | F13: 2.432 | G13: -0.248 | H13: 4.511 | I13: 1.91 | J13: 1.785 | K13: 2.318 | L13: 2.144 | M13: 2.435 | N13: 0.192 | O13: 2.14 | P13: 3.056 | Q13: 2.167 | R13: 2.82 | S13: 2.047 | T13: 2.652 | U13: 0.162 | V13: 4.923 | W13: =B13-I13 -> 0.768 | X13: =C13-J13 -> 0.022 | Y13: =D13-K13 -> 0.194 | Z13: =E13-L13 -> -0.231 | AA13: =F13-M13 -> -0.003 | AB13: =G13-N13 -> -0.44 | AC13: =H13-O13 -> 2.371 | AD13: =W13-AVERAGE(W$4:W13) -> -0.0585 | AE13: =X13-AVERAGE(X$4:X13) -> -0.0732 | AF13: =Y13-AVERAGE(Y$4:Y13) -> -0.1487 | AG13: =Z13-AVERAGE(Z$4:Z13) -> -0.4239 | AH13: =AA13-AVERAGE(AA$4:AA13) -> -0.5844 | AI13: =AB13-AVERAGE(AB$4:AB13) -> -0.0654 | AJ13: =AC13-AVERAGE(AC$4:AC13) -> 0.303 | AK13: =-RateDur*(P13-P12)/100 -> -0.00342 | AL13: =-RateDur*(Q13-Q12)/100 -> 0.001843 | AM13: =-RateDur*(R13-R12)/100 -> -0.004655 | AN13: =-RateDur*(S13-S12)/100 -> 0.00551 | AO13: =-RateDur*(T13-T12)/100 -> 0.003819 | AP13: =-RateDur*(U13-U12)/100 -> -0.001957 | AQ13: =-RateDur*(V13-V12)/100 -> -0.006118
A14: 38321 | B14: 2.48 | C14: 1.991 | D14: 2.508 | E14: 2.145 | F14: 2.724 | G14: -0.294 | H14: 4.408 | I14: 1.89 | J14: 1.846 | K14: 2.279 | L14: 2.08 | M14: 2.39 | N14: 0.147 | O14: 2.052 | P14: 2.732 | Q14: 2.245 | R14: 2.794 | S14: 2.557 | T14: 3.029 | U14: 0.186 | V14: 4.724 | W14: =B14-I14 -> 0.59 | X14: =C14-J14 -> 0.145 | Y14: =D14-K14 -> 0.229 | Z14: =E14-L14 -> 0.065 | AA14: =F14-M14 -> 0.334 | AB14: =G14-N14 -> -0.441 | AC14: =H14-O14 -> 2.356 | AD14: =W14-AVERAGE(W$4:W14) -> -0.215 | AE14: =X14-AVERAGE(X$4:X14) -> 0.045272727 | AF14: =Y14-AVERAGE(Y$4:Y14) -> -0.10336364 | AG14: =Z14-AVERAGE(Z$4:Z14) -> -0.11627273 | AH14: =AA14-AVERAGE(AA$4:AA14) -> -0.22490909 | AI14: =AB14-AVERAGE(AB$4:AB14) -> -0.060363636 | AJ14: =AC14-AVERAGE(AC$4:AC14) -> 0.26181818 | AK14: =-RateDur*(P14-P13)/100 -> 0.006156 | AL14: =-RateDur*(Q14-Q13)/100 -> -0.001482 | AM14: =-RateDur*(R14-R13)/100 -> 0.000494 | AN14: =-RateDur*(S14-S13)/100 -> -0.00969 | AO14: =-RateDur*(T14-T13)/100 -> -0.007163 | AP14: =-RateDur*(U14-U13)/100 -> -0.000456 | AQ14: =-RateDur*(V14-V13)/100 -> 0.003781
A15: 38352 | B15: 2.592 | C15: 2.15 | D15: 2.664 | E15: 2.255 | F15: 2.658 | G15: -0.245 | H15: 4.5 | I15: 1.935 | J15: 1.819 | K15: 2.131 | L15: 2.22 | M15: 2.424 | N15: 0.146 | O15: 2.088 | P15: 2.843 | Q15: 2.204 | R15: 2.828 | S15: 2.504 | T15: 2.845 | U15: -0.13 | V15: 4.693 | W15: =B15-I15 -> 0.657 | X15: =C15-J15 -> 0.331 | Y15: =D15-K15 -> 0.533 | Z15: =E15-L15 -> 0.035 | AA15: =F15-M15 -> 0.234 | AB15: =G15-N15 -> -0.391 | AC15: =H15-O15 -> 2.412 | AD15: =W15-AVERAGE(W$4:W15) -> -0.13566667 | AE15: =X15-AVERAGE(X$4:X15) -> 0.212 | AF15: =Y15-AVERAGE(Y$4:Y15) -> 0.18391667 | AG15: =Z15-AVERAGE(Z$4:Z15) -> -0.13408333 | AH15: =AA15-AVERAGE(AA$4:AA15) -> -0.29783333 | AI15: =AB15-AVERAGE(AB$4:AB15) -> -0.0095 | AJ15: =AC15-AVERAGE(AC$4:AC15) -> 0.29133333 | AK15: =-RateDur*(P15-P14)/100 -> -0.002109 | AL15: =-RateDur*(Q15-Q14)/100 -> 0.000779 | AM15: =-RateDur*(R15-R14)/100 -> -0.000646 | AN15: =-RateDur*(S15-S14)/100 -> 0.001007 | AO15: =-RateDur*(T15-T14)/100 -> 0.003496 | AP15: =-RateDur*(U15-U14)/100 -> 0.006004 | AQ15: =-RateDur*(V15-V14)/100 -> 0.000589
A16: 38383 | B16: 2.925 | C16: 2.15 | D16: 2.272 | E16: 2.405 | F16: 2.781 | G16: -0.392 | H16: 4.56 | I16: 1.944 | J16: 1.817 | K16: 2.065 | L16: 2.06 | M16: 2.362 | N16: 0.251 | O16: 2.084 | P16: 3.207 | Q16: 2.226 | R16: 2.386 | S16: 2.617 | T16: 2.95 | U16: -0.173 | V16: 5.063 | W16: =B16-I16 -> 0.981 | X16: =C16-J16 -> 0.333 | Y16: =D16-K16 -> 0.207 | Z16: =E16-L16 -> 0.345 | AA16: =F16-M16 -> 0.419 | AB16: =G16-N16 -> -0.643 | AC16: =H16-O16 -> 2.476 | AD16: =W16-AVERAGE(W$4:W16) -> 0.17384615 | AE16: =X16-AVERAGE(X$4:X16) -> 0.19753846 | AF16: =Y16-AVERAGE(Y$4:Y16) -> -0.13115385 | AG16: =Z16-AVERAGE(Z$4:Z16) -> 0.16238462 | AH16: =AA16-AVERAGE(AA$4:AA16) -> -0.10415385 | AI16: =AB16-AVERAGE(AB$4:AB16) -> -0.24138462 | AJ16: =AC16-AVERAGE(AC$4:AC16) -> 0.328 | AK16: =-RateDur*(P16-P15)/100 -> -0.006916 | AL16: =-RateDur*(Q16-Q15)/100 -> -0.000418 | AM16: =-RateDur*(R16-R15)/100 -> 0.008398 | AN16: =-RateDur*(S16-S15)/100 -> -0.002147 | AO16: =-RateDur*(T16-T15)/100 -> -0.001995 | AP16: =-RateDur*(U16-U15)/100 -> 0.000817 | AQ16: =-RateDur*(V16-V15)/100 -> -0.00703
... A276: 46295 | B276: 3.127 | C276: 2.17 | D276: 2.554 | E276: 2.202 | F276: 3.686 | G276: -0.428 | H276: 4.116 | I276: 1.884 | J276: 1.714 | K276: 2.264 | L276: 1.782 | M276: 2.772 | N276: 0.333 | O276: 2.365 | P276: 3.283 | Q276: 2.391 | R276: 2.7 | S276: 2.32 | T276: 3.91 | U276: -0.358 | V276: 4.376 | W276: =B276-I276 -> 1.243 | X276: =C276-J276 -> 0.456 | Y276: =D276-K276 -> 0.29 | Z276: =E276-L276 -> 0.42 | AA276: =F276-M276 -> 0.914 | AB276: =G276-N276 -> -0.761 | AC276: =H276-O276 -> 1.751 | AD276: =W276-AVERAGE(W$4:W276) -> 0.86494505 | AE276: =X276-AVERAGE(X$4:X276) -> 0.24174725 | AF276: =Y276-AVERAGE(Y$4:Y276) -> 0.13683516 | AG276: =Z276-AVERAGE(Z$4:Z276) -> 0.1169304 | AH276: =AA276-AVERAGE(AA$4:AA276) -> -0.13205128 | AI276: =AB276-AVERAGE(AB$4:AB276) -> -0.76060073 | AJ276: =AC276-AVERAGE(AC$4:AC276) -> 0.29982784 | AK276: =-RateDur*(P276-P275)/100 -> 0.000703 | AL276: =-RateDur*(Q276-Q275)/100 -> 0.001007 | AM276: =-RateDur*(R276-R275)/100 -> -0.002261 | AN276: =-RateDur*(S276-S275)/100 -> -0.009329 | AO276: =-RateDur*(T276-T275)/100 -> -0.001862 | AP276: =-RateDur*(U276-U275)/100 -> 0.012958 | AQ276: =-RateDur*(V276-V275)/100 -> -0.005263
A278: Synthetic placeholder data. Replace the yellow blocks with BDH pulls from Tickers. Formula columns update automatically.
A279: Note on the signal: the raw real-rate LEVEL across markets is largely a carry signal, because structural real-rate gaps between countries persist for decades.
A280: Measuring each market against its own expanding mean is what turns it into a value signal, which is what this framework is trying to harvest. Delete the AVERAGE term to run the raw-level version.

Sheet EMFX_Pairs
A1: EMFX Pairs
A2: One column per pair. Long the cheaper currency, short the richer, direction set by the previous month's valuation so there is no look-ahead. | B2: Valuation spread | W2: Expanding z-score | AR2: Risk multiplier (ladder) | BM2: Pair return (long cheap / short rich) | CH2: Trailing vol, annualised | DC2: Position | DX2: Weighted return | ES2: Sleeve
A3: Date | B3: BRL/MXN | C3: BRL/CLP | D3: BRL/COP | E3: BRL/ZAR | F3: BRL/TRY | G3: BRL/PLN | H3: MXN/CLP | I3: MXN/COP | J3: MXN/ZAR | K3: MXN/TRY | L3: MXN/PLN | M3: CLP/COP | N3: CLP/ZAR | O3: CLP/TRY | P3: CLP/PLN | Q3: COP/ZAR | R3: COP/TRY | S3: COP/PLN | T3: ZAR/TRY | U3: ZAR/PLN | V3: TRY/PLN | W3: BRL/MXN | X3: BRL/CLP | Y3: BRL/COP | Z3: BRL/ZAR | AA3: BRL/TRY | AB3: BRL/PLN | AC3: MXN/CLP | AD3: MXN/COP | AE3: MXN/ZAR | AF3: MXN/TRY | AG3: MXN/PLN | AH3: CLP/COP | AI3: CLP/ZAR | AJ3: CLP/TRY | AK3: CLP/PLN | AL3: COP/ZAR | AM3: COP/TRY | AN3: COP/PLN | AO3: ZAR/TRY | AP3: ZAR/PLN | AQ3: TRY/PLN | AR3: BRL/MXN | AS3: BRL/CLP | AT3: BRL/COP | AU3: BRL/ZAR | AV3: BRL/TRY | AW3: BRL/PLN | AX3: MXN/CLP | AY3: MXN/COP | AZ3: MXN/ZAR | BA3: MXN/TRY | BB3: MXN/PLN | BC3: CLP/COP | BD3: CLP/ZAR | BE3: CLP/TRY | BF3: CLP/PLN | BG3: COP/ZAR | BH3: COP/TRY | BI3: COP/PLN | BJ3: ZAR/TRY | BK3: ZAR/PLN | BL3: TRY/PLN | BM3: BRL/MXN | BN3: BRL/CLP | BO3: BRL/COP | BP3: BRL/ZAR | BQ3: BRL/TRY | BR3: BRL/PLN | BS3: MXN/CLP | BT3: MXN/COP | BU3: MXN/ZAR | BV3: MXN/TRY | BW3: MXN/PLN | BX3: CLP/COP | BY3: CLP/ZAR | BZ3: CLP/TRY | CA3: CLP/PLN | CB3: COP/ZAR | CC3: COP/TRY | CD3: COP/PLN | CE3: ZAR/TRY | CF3: ZAR/PLN | CG3: TRY/PLN | CH3: BRL/MXN | CI3: BRL/CLP | CJ3: BRL/COP | CK3: BRL/ZAR | CL3: BRL/TRY | CM3: BRL/PLN | CN3: MXN/CLP | CO3: MXN/COP | CP3: MXN/ZAR | CQ3: MXN/TRY | CR3: MXN/PLN | CS3: CLP/COP | CT3: CLP/ZAR | CU3: CLP/TRY | CV3: CLP/PLN | CW3: COP/ZAR | CX3: COP/TRY | CY3: COP/PLN | CZ3: ZAR/TRY | DA3: ZAR/PLN | DB3: TRY/PLN | DC3: BRL/MXN | DD3: BRL/CLP | DE3: BRL/COP | DF3: BRL/ZAR | DG3: BRL/TRY | DH3: BRL/PLN | DI3: MXN/CLP | DJ3: MXN/COP | DK3: MXN/ZAR | DL3: MXN/TRY | DM3: MXN/PLN | DN3: CLP/COP | DO3: CLP/ZAR | DP3: CLP/TRY | DQ3: CLP/PLN | DR3: COP/ZAR | DS3: COP/TRY | DT3: COP/PLN | DU3: ZAR/TRY | DV3: ZAR/PLN | DW3: TRY/PLN | DX3: BRL/MXN | DY3: BRL/CLP | DZ3: BRL/COP | EA3: BRL/ZAR | EB3: BRL/TRY | EC3: BRL/PLN | ED3: MXN/CLP | EE3: MXN/COP | EF3: MXN/ZAR | EG3: MXN/TRY | EH3: MXN/PLN | EI3: CLP/COP | EJ3: CLP/ZAR | EK3: CLP/TRY | EL3: CLP/PLN | EM3: COP/ZAR | EN3: COP/TRY | EO3: COP/PLN | EP3: ZAR/TRY | EQ3: ZAR/PLN | ER3: TRY/PLN | ES3: Gross ret | ET3: # included
A4: 38017 | B4: =ABS(EMFX_Data!X4-EMFX_Data!Y4) -> 0 | C4: =ABS(EMFX_Data!X4-EMFX_Data!Z4) -> 0 | D4: =ABS(EMFX_Data!X4-EMFX_Data!AA4) -> 0 | E4: =ABS(EMFX_Data!X4-EMFX_Data!AB4) -> 0 | F4: =ABS(EMFX_Data!X4-EMFX_Data!AC4) -> 0 | G4: =ABS(EMFX_Data!X4-EMFX_Data!AD4) -> 3.912023 | H4: =ABS(EMFX_Data!Y4-EMFX_Data!Z4) -> 0 | I4: =ABS(EMFX_Data!Y4-EMFX_Data!AA4) -> 0 | J4: =ABS(EMFX_Data!Y4-EMFX_Data!AB4) -> 0 | K4: =ABS(EMFX_Data!Y4-EMFX_Data!AC4) -> 0 | L4: =ABS(EMFX_Data!Y4-EMFX_Data!AD4) -> 3.912023 | M4: =ABS(EMFX_Data!Z4-EMFX_Data!AA4) -> 0 | N4: =ABS(EMFX_Data!Z4-EMFX_Data!AB4) -> 0 | O4: =ABS(EMFX_Data!Z4-EMFX_Data!AC4) -> 0 | P4: =ABS(EMFX_Data!Z4-EMFX_Data!AD4) -> 3.912023 | Q4: =ABS(EMFX_Data!AA4-EMFX_Data!AB4) -> 0 | R4: =ABS(EMFX_Data!AA4-EMFX_Data!AC4) -> 0 | S4: =ABS(EMFX_Data!AA4-EMFX_Data!AD4) -> 3.912023 | T4: =ABS(EMFX_Data!AB4-EMFX_Data!AC4) -> 0 | U4: =ABS(EMFX_Data!AB4-EMFX_Data!AD4) -> 3.912023 | V4: =ABS(EMFX_Data!AC4-EMFX_Data!AD4) -> 3.912023 | W4: =IF(ROW()<4+MinObs-1,"",IFERROR((B4-AVERAGE(B$4:B4))/STDEV(B$4:B4),"")) | X4: =IF(ROW()<4+MinObs-1,"",IFERROR((C4-AVERAGE(C$4:C4))/STDEV(C$4:C4),"")) | Y4: =IF(ROW()<4+MinObs-1,"",IFERROR((D4-AVERAGE(D$4:D4))/STDEV(D$4:D4),"")) | Z4: =IF(ROW()<4+MinObs-1,"",IFERROR((E4-AVERAGE(E$4:E4))/STDEV(E$4:E4),"")) | AA4: =IF(ROW()<4+MinObs-1,"",IFERROR((F4-AVERAGE(F$4:F4))/STDEV(F$4:F4),"")) | AB4: =IF(ROW()<4+MinObs-1,"",IFERROR((G4-AVERAGE(G$4:G4))/STDEV(G$4:G4),"")) | AC4: =IF(ROW()<4+MinObs-1,"",IFERROR((H4-AVERAGE(H$4:H4))/STDEV(H$4:H4),"")) | AD4: =IF(ROW()<4+MinObs-1,"",IFERROR((I4-AVERAGE(I$4:I4))/STDEV(I$4:I4),"")) | ... AQ4: =IF(ROW()<4+MinObs-1,"",IFERROR((V4-AVERAGE(V$4:V4))/STDEV(V$4:V4),"")) | AR4: =IF(w4="",0,IF(w4>=z4,w4,IF(w4>=z3,w3,IF(w4>=zEntry,w2,IF(AND(w4>=ExitZ,0>0),w2,0))))) -> 1 | AS4: =IF(X4="",0,IF(X4>=z4,w4,IF(X4>=z3,w3,IF(X4>=zEntry,w2,IF(AND(X4>=ExitZ,0>0),w2,0))))) -> 0 | AT4: =IF(Y4="",0,IF(Y4>=z4,w4,IF(Y4>=z3,w3,IF(Y4>=zEntry,w2,IF(AND(Y4>=ExitZ,0>0),w2,0))))) -> 0 | AU4: =IF(z4="",0,IF(z4>=z4,w4,IF(z4>=z3,w3,IF(z4>=zEntry,w2,IF(AND(z4>=ExitZ,0>0),w2,0))))) -> 2 | AV4: =IF(AA4="",0,IF(AA4>=z4,w4,IF(AA4>=z3,w3,IF(AA4>=zEntry,w2,IF(AND(AA4>=ExitZ,0>0),w2,0))))) -> 0 | AW4: =IF(AB4="",0,IF(AB4>=z4,w4,IF(AB4>=z3,w3,IF(AB4>=zEntry,w2,IF(AND(AB4>=ExitZ,0>0),w2,0))))) -> 0 | AX4: =IF(AC4="",0,IF(AC4>=z4,w4,IF(AC4>=z3,w3,IF(AC4>=zEntry,w2,IF(AND(AC4>=ExitZ,0>0),w2,0))))) -> 0 | AY4: =IF(AD4="",0,IF(AD4>=z4,w4,IF(AD4>=z3,w3,IF(AD4>=zEntry,w2,IF(AND(AD4>=ExitZ,0>0),w2,0))))) -> 0 | AZ4: =IF(AE4="",0,IF(AE4>=z4,w4,IF(AE4>=z3,w3,IF(AE4>=zEntry,w2,IF(AND(AE4>=ExitZ,0>0),w2,0))))) -> 0 | BA4: =IF(AF4="",0,IF(AF4>=z4,w4,IF(AF4>=z3,w3,IF(AF4>=zEntry,w2,IF(AND(AF4>=ExitZ,0>0),w2,0))))) -> 0 | BB4: =IF(AG4="",0,IF(AG4>=z4,w4,IF(AG4>=z3,w3,IF(AG4>=zEntry,w2,IF(AND(AG4>=ExitZ,0>0),w2,0))))) -> 0 | BC4: =IF(AH4="",0,IF(AH4>=z4,w4,IF(AH4>=z3,w3,IF(AH4>=zEntry,w2,IF(AND(AH4>=ExitZ,0>0),w2,0))))) -> 0 | ... BL4: =IF(AQ4="",0,IF(AQ4>=z4,w4,IF(AQ4>=z3,w3,IF(AQ4>=zEntry,w2,IF(AND(AQ4>=ExitZ,0>0),w2,0))))) -> 0 | DC4: =IF(OR(AR4=0,CH4="",CH4=0),0,AR4*MIN(MaxScal,TgtVol/CH4)) -> 0 | DD4: =IF(OR(AS4=0,CI4="",CI4=0),0,AS4*MIN(MaxScal,TgtVol/CI4)) -> 0 | DE4: =IF(OR(AT4=0,CJ4="",CJ4=0),0,AT4*MIN(MaxScal,TgtVol/CJ4)) -> 0 | DF4: =IF(OR(AU4=0,CK4="",CK4=0),0,AU4*MIN(MaxScal,TgtVol/CK4)) -> 0 | DG4: =IF(OR(AV4=0,CL4="",CL4=0),0,AV4*MIN(MaxScal,TgtVol/CL4)) -> 0 | DH4: =IF(OR(AW4=0,CM4="",CM4=0),0,AW4*MIN(MaxScal,TgtVol/CM4)) -> 0 | DI4: =IF(OR(AX4=0,CN4="",CN4=0),0,AX4*MIN(MaxScal,TgtVol/CN4)) -> 0 | DJ4: =IF(OR(AY4=0,CO4="",CO4=0),0,AY4*MIN(MaxScal,TgtVol/CO4)) -> 0 | ... DW4: =IF(OR(BL4=0,DB4="",DB4=0),0,BL4*MIN(MaxScal,TgtVol/DB4)) -> 0 | ES4: =IF(ROW()=4,"",SUM(DX4:ER4)) | ET4: =COUNTIF(AR4:BL4,">0") -> 2
A5: 38046 | B5: =ABS(EMFX_Data!X5-EMFX_Data!Y5) -> 0.0075281306 | C5: =ABS(EMFX_Data!X5-EMFX_Data!Z5) -> 0.02423662 | D5: =ABS(EMFX_Data!X5-EMFX_Data!AA5) -> 0.0037926515 | E5: =ABS(EMFX_Data!X5-EMFX_Data!AB5) -> 0.024383664 | F5: =ABS(EMFX_Data!X5-EMFX_Data!AC5) -> 0.0074127575 | G5: =ABS(EMFX_Data!X5-EMFX_Data!AD5) -> 0.014008914 | H5: =ABS(EMFX_Data!Y5-EMFX_Data!Z5) -> 0.01670849 | I5: =ABS(EMFX_Data!Y5-EMFX_Data!AA5) -> 0.0037354791 | J5: =ABS(EMFX_Data!Y5-EMFX_Data!AB5) -> 0.016855534 | K5: =ABS(EMFX_Data!Y5-EMFX_Data!AC5) -> 0.014940888 | L5: =ABS(EMFX_Data!Y5-EMFX_Data!AD5) -> 0.021537044 | M5: =ABS(EMFX_Data!Z5-EMFX_Data!AA5) -> 0.020443969 | N5: =ABS(EMFX_Data!Z5-EMFX_Data!AB5) -> 0.00014704409 | O5: =ABS(EMFX_Data!Z5-EMFX_Data!AC5) -> 0.031649378 | P5: =ABS(EMFX_Data!Z5-EMFX_Data!AD5) -> 0.038245534 | Q5: =ABS(EMFX_Data!AA5-EMFX_Data!AB5) -> 0.020591013 | R5: =ABS(EMFX_Data!AA5-EMFX_Data!AC5) -> 0.011205409 | S5: =ABS(EMFX_Data!AA5-EMFX_Data!AD5) -> 0.017801565 | T5: =ABS(EMFX_Data!AB5-EMFX_Data!AC5) -> 0.031796422 | U5: =ABS(EMFX_Data!AB5-EMFX_Data!AD5) -> 0.038392578 | V5: =ABS(EMFX_Data!AC5-EMFX_Data!AD5) -> 0.0065961563 | W5: =IF(ROW()<4+MinObs-1,"",IFERROR((B5-AVERAGE(B$4:B5))/STDEV(B$4:B5),"")) | X5: =IF(ROW()<4+MinObs-1,"",IFERROR((C5-AVERAGE(C$4:C5))/STDEV(C$4:C5),"")) | Y5: =IF(ROW()<4+MinObs-1,"",IFERROR((D5-AVERAGE(D$4:D5))/STDEV(D$4:D5),"")) | Z5: =IF(ROW()<4+MinObs-1,"",IFERROR((E5-AVERAGE(E$4:E5))/STDEV(E$4:E5),"")) | AA5: =IF(ROW()<4+MinObs-1,"",IFERROR((F5-AVERAGE(F$4:F5))/STDEV(F$4:F5),"")) | AB5: =IF(ROW()<4+MinObs-1,"",IFERROR((G5-AVERAGE(G$4:G5))/STDEV(G$4:G5),"")) | AC5: =IF(ROW()<4+MinObs-1,"",IFERROR((H5-AVERAGE(H$4:H5))/STDEV(H$4:H5),"")) | AD5: =IF(ROW()<4+MinObs-1,"",IFERROR((I5-AVERAGE(I$4:I5))/STDEV(I$4:I5),"")) | ... AQ5: =IF(ROW()<4+MinObs-1,"",IFERROR((V5-AVERAGE(V$4:V5))/STDEV(V$4:V5),"")) | AR5: =IF(W5="",0,IF(W5>=z4,w4,IF(W5>=z3,w3,IF(W5>=zEntry,w2,IF(AND(W5>=ExitZ,AR4>0),w2,0))))) -> 0 | AS5: =IF(X5="",0,IF(X5>=z4,w4,IF(X5>=z3,w3,IF(X5>=zEntry,w2,IF(AND(X5>=ExitZ,AS4>0),w2,0))))) -> 0 | AT5: =IF(Y5="",0,IF(Y5>=z4,w4,IF(Y5>=z3,w3,IF(Y5>=zEntry,w2,IF(AND(Y5>=ExitZ,AT4>0),w2,0))))) -> 0 | AU5: =IF(Z5="",0,IF(Z5>=z4,w4,IF(Z5>=z3,w3,IF(Z5>=zEntry,w2,IF(AND(Z5>=ExitZ,AU4>0),w2,0))))) -> 0 | AV5: =IF(AA5="",0,IF(AA5>=z4,w4,IF(AA5>=z3,w3,IF(AA5>=zEntry,w2,IF(AND(AA5>=ExitZ,AV4>0),w2,0))))) -> 0 | AW5: =IF(AB5="",0,IF(AB5>=z4,w4,IF(AB5>=z3,w3,IF(AB5>=zEntry,w2,IF(AND(AB5>=ExitZ,AW4>0),w2,0))))) -> 0 | AX5: =IF(AC5="",0,IF(AC5>=z4,w4,IF(AC5>=z3,w3,IF(AC5>=zEntry,w2,IF(AND(AC5>=ExitZ,AX4>0),w2,0))))) -> 0 | AY5: =IF(AD5="",0,IF(AD5>=z4,w4,IF(AD5>=z3,w3,IF(AD5>=zEntry,w2,IF(AND(AD5>=ExitZ,AY4>0),w2,0))))) -> 0 | ... BL5: =IF(AQ5="",0,IF(AQ5>=z4,w4,IF(AQ5>=z3,w3,IF(AQ5>=zEntry,w2,IF(AND(AQ5>=ExitZ,BL4>0),w2,0))))) -> 0 | BM5: =IF(EMFX_Data!X4>=EMFX_Data!Y4,EMFX_Data!AE5-EMFX_Data!AF5,EMFX_Data!AF5-EMFX_Data!AE5) -> 0.015060996 | BN5: =IF(EMFX_Data!X4>=EMFX_Data!Z4,EMFX_Data!AE5-EMFX_Data!AG5,EMFX_Data!AG5-EMFX_Data!AE5) -> 0.044923701 | BO5: =IF(EMFX_Data!X4>=EMFX_Data!AA4,EMFX_Data!AE5-EMFX_Data!AH5,EMFX_Data!AH5-EMFX_Data!AE5) -> 0.0038804946 | BP5: =IF(EMFX_Data!X4>=EMFX_Data!AB4,EMFX_Data!AE5-EMFX_Data!AI5,EMFX_Data!AI5-EMFX_Data!AE5) -> 0.04705575 | BQ5: =IF(EMFX_Data!X4>=EMFX_Data!AC4,EMFX_Data!AE5-EMFX_Data!AJ5,EMFX_Data!AJ5-EMFX_Data!AE5) -> -0.0087128272 | BR5: =IF(EMFX_Data!X4>=EMFX_Data!AD4,EMFX_Data!AE5-EMFX_Data!AK5,EMFX_Data!AK5-EMFX_Data!AE5) -> 0.031992094 | BS5: =IF(EMFX_Data!Y4>=EMFX_Data!Z4,EMFX_Data!AF5-EMFX_Data!AG5,EMFX_Data!AG5-EMFX_Data!AF5) -> 0.029862705 | BT5: =IF(EMFX_Data!Y4>=EMFX_Data!AA4,EMFX_Data!AF5-EMFX_Data!AH5,EMFX_Data!AH5-EMFX_Data!AF5) -> -0.011180502 | BU5: =IF(EMFX_Data!Y4>=EMFX_Data!AB4,EMFX_Data!AF5-EMFX_Data!AI5,EMFX_Data!AI5-EMFX_Data!AF5) -> 0.031994754 | BV5: =IF(EMFX_Data!Y4>=EMFX_Data!AC4,EMFX_Data!AF5-EMFX_Data!AJ5,EMFX_Data!AJ5-EMFX_Data!AF5) -> -0.023773823 | BW5: =IF(EMFX_Data!Y4>=EMFX_Data!AD4,EMFX_Data!AF5-EMFX_Data!AK5,EMFX_Data!AK5-EMFX_Data!AF5) -> 0.04705309 | BX5: =IF(EMFX_Data!Z4>=EMFX_Data!AA4,EMFX_Data!AG5-EMFX_Data!AH5,EMFX_Data!AH5-EMFX_Data!AG5) -> -0.041043207 | BY5: =IF(EMFX_Data!Z4>=EMFX_Data!AB4,EMFX_Data!AG5-EMFX_Data!AI5,EMFX_Data!AI5-EMFX_Data!AG5) -> 0.0021320488 | BZ5: =IF(EMFX_Data!Z4>=EMFX_Data!AC4,EMFX_Data!AG5-EMFX_Data!AJ5,EMFX_Data!AJ5-EMFX_Data!AG5) -> -0.053636528 | CA5: =IF(EMFX_Data!Z4>=EMFX_Data!AD4,EMFX_Data!AG5-EMFX_Data!AK5,EMFX_Data!AK5-EMFX_Data!AG5) -> 0.076915795 | CB5: =IF(EMFX_Data!AA4>=EMFX_Data!AB4,EMFX_Data!AH5-EMFX_Data!AI5,EMFX_Data!AI5-EMFX_Data!AH5) -> 0.043175255 | CC5: =IF(EMFX_Data!AA4>=EMFX_Data!AC4,EMFX_Data!AH5-EMFX_Data!AJ5,EMFX_Data!AJ5-EMFX_Data!AH5) -> -0.012593322 | CD5: =IF(EMFX_Data!AA4>=EMFX_Data!AD4,EMFX_Data!AH5-EMFX_Data!AK5,EMFX_Data!AK5-EMFX_Data!AH5) -> 0.035872589 | CE5: =IF(EMFX_Data!AB4>=EMFX_Data!AC4,EMFX_Data!AI5-EMFX_Data!AJ5,EMFX_Data!AJ5-EMFX_Data!AI5) -> -0.055768577 | CF5: =IF(EMFX_Data!AB4>=EMFX_Data!AD4,EMFX_Data!AI5-EMFX_Data!AK5,EMFX_Data!AK5-EMFX_Data!AI5) -> 0.079047844 | CG5: =IF(EMFX_Data!AC4>=EMFX_Data!AD4,EMFX_Data!AJ5-EMFX_Data!AK5,EMFX_Data!AK5-EMFX_Data!AJ5) -> 0.023279267 | CH5: =IF(ROW()<4+VolLB,"",STDEV(INDEX($BM:$BM,ROW()-VolLB+1):INDEX($BM:$BM,ROW()))*SQRT(12)) | CI5: =IF(ROW()<4+VolLB,"",STDEV(INDEX($BN:$BN,ROW()-VolLB+1):INDEX($BN:$BN,ROW()))*SQRT(12)) | CJ5: =IF(ROW()<4+VolLB,"",STDEV(INDEX($BO:$BO,ROW()-VolLB+1):INDEX($BO:$BO,ROW()))*SQRT(12)) | CK5: =IF(ROW()<4+VolLB,"",STDEV(INDEX($BP:$BP,ROW()-VolLB+1):INDEX($BP:$BP,ROW()))*SQRT(12)) | CL5: =IF(ROW()<4+VolLB,"",STDEV(INDEX($BQ:$BQ,ROW()-VolLB+1):INDEX($BQ:$BQ,ROW()))*SQRT(12)) | CM5: =IF(ROW()<4+VolLB,"",STDEV(INDEX($BR:$BR,ROW()-VolLB+1):INDEX($BR:$BR,ROW()))*SQRT(12)) | CN5: =IF(ROW()<4+VolLB,"",STDEV(INDEX($BS:$BS,ROW()-VolLB+1):INDEX($BS:$BS,ROW()))*SQRT(12)) | CO5: =IF(ROW()<4+VolLB,"",STDEV(INDEX($BT:$BT,ROW()-VolLB+1):INDEX($BT:$BT,ROW()))*SQRT(12)) | CP5: =IF(ROW()<4+VolLB,"",STDEV(INDEX($BU:$BU,ROW()-VolLB+1):INDEX($BU:$BU,ROW()))*SQRT(12)) | CQ5: =IF(ROW()<4+VolLB,"",STDEV(INDEX($BV:$BV,ROW()-VolLB+1):INDEX($BV:$BV,ROW()))*SQRT(12)) | CR5: =IF(ROW()<4+VolLB,"",STDEV(INDEX($BW:$BW,ROW()-VolLB+1):INDEX($BW:$BW,ROW()))*SQRT(12)) | CS5: =IF(ROW()<4+VolLB,"",STDEV(INDEX($BX:$BX,ROW()-VolLB+1):INDEX($BX:$BX,ROW()))*SQRT(12)) | CT5: =IF(ROW()<4+VolLB,"",STDEV(INDEX($BY:$BY,ROW()-VolLB+1):INDEX($BY:$BY,ROW()))*SQRT(12)) | CU5: =IF(ROW()<4+VolLB,"",STDEV(INDEX($BZ:$BZ,ROW()-VolLB+1):INDEX($BZ:$BZ,ROW()))*SQRT(12)) | CV5: =IF(ROW()<4+VolLB,"",STDEV(INDEX($CA:$CA,ROW()-VolLB+1):INDEX($CA:$CA,ROW()))*SQRT(12)) | CW5: =IF(ROW()<4+VolLB,"",STDEV(INDEX($CB:$CB,ROW()-VolLB+1):INDEX($CB:$CB,ROW()))*SQRT(12)) | CX5: =IF(ROW()<4+VolLB,"",STDEV(INDEX($CC:$CC,ROW()-VolLB+1):INDEX($CC:$CC,ROW()))*SQRT(12)) | CY5: =IF(ROW()<4+VolLB,"",STDEV(INDEX($CD:$CD,ROW()-VolLB+1):INDEX($CD:$CD,ROW()))*SQRT(12)) | CZ5: =IF(ROW()<4+VolLB,"",STDEV(INDEX($CE:$CE,ROW()-VolLB+1):INDEX($CE:$CE,ROW()))*SQRT(12)) | DA5: =IF(ROW()<4+VolLB,"",STDEV(INDEX($CF:$CF,ROW()-VolLB+1):INDEX($CF:$CF,ROW()))*SQRT(12)) | DB5: =IF(ROW()<4+VolLB,"",STDEV(INDEX($CG:$CG,ROW()-VolLB+1):INDEX($CG:$CG,ROW()))*SQRT(12)) | DC5: =IF(OR(AR5=0,CH5="",CH5=0),0,AR5*MIN(MaxScal,TgtVol/CH5)) -> 0 | DD5: =IF(OR(AS5=0,CI5="",CI5=0),0,AS5*MIN(MaxScal,TgtVol/CI5)) -> 0 | DE5: =IF(OR(AT5=0,CJ5="",CJ5=0),0,AT5*MIN(MaxScal,TgtVol/CJ5)) -> 0 | DF5: =IF(OR(AU5=0,CK5="",CK5=0),0,AU5*MIN(MaxScal,TgtVol/CK5)) -> 0 | DG5: =IF(OR(AV5=0,CL5="",CL5=0),0,AV5*MIN(MaxScal,TgtVol/CL5)) -> 0 | DH5: =IF(OR(AW5=0,CM5="",CM5=0),0,AW5*MIN(MaxScal,TgtVol/CM5)) -> 0 | DI5: =IF(OR(AX5=0,CN5="",CN5=0),0,AX5*MIN(MaxScal,TgtVol/CN5)) -> 0 | DJ5: =IF(OR(AY5=0,CO5="",CO5=0),0,AY5*MIN(MaxScal,TgtVol/CO5)) -> 0 | ... DW5: =IF(OR(BL5=0,DB5="",DB5=0),0,BL5*MIN(MaxScal,TgtVol/DB5)) -> 0 | DX5: =IFERROR(DC4*BM5,"") -> 0 | DY5: =IFERROR(DD4*BN5,"") -> 0 | DZ5: =IFERROR(DE4*BO5,"") -> 0 | EA5: =IFERROR(DF4*BP5,"") -> 0 | EB5: =IFERROR(DG4*BQ5,"") -> 0 | EC5: =IFERROR(DH4*BR5,"") -> 0 | ED5: =IFERROR(DI4*BS5,"") -> 0 | EE5: =IFERROR(DJ4*BT5,"") -> 0 | ... ER5: =IFERROR(DW4*CG5,"") -> 0 | ES5: =IF(ROW()=4,"",SUM(DX5:ER5)) -> 0 | ET5: =COUNTIF(AR5:BL5,">0") -> 0
