Workbook

Sheet Summary
B2: Dominican Republic - macro snapshot
B3: As of 1-Sep-2026. Blue = hardcoded source input; black = formula; green = link to another tab. Sources on each tab and in 'Sources'.
B5: Key indicators
B6: Indicator | C6: Unit | D6: 2024 | E6: 2025 | F6: 2026 latest / YTD | G6: 2026 forecast | H6: Source
B7: Real GDP growth | C7: % y/y | D7: 5 | E7: 2.1 | F7: 4.5% (Jan-Jul IMAE avg) | G7: 4.5% BCRD / 3.75% MHE / 3.7% IMF | H7: BCRD; MHE MFMP; IMF WEO Apr-26
B8: Headline CPI (Dec/latest) | C8: % y/y | D8: 3.35 | E8: 4.95 | F8: 5.47% (Jul-26) | G8: 4.5% Dec (MHE); BCRD: back in 4%±1% in 4Q26 | H8: BCRD IPC
B9: Core CPI | C9: % y/y | D9: 4.01 | E9: 4.85 | F9: 4.96% (Jul-26) | G9: n.a. | H9: BCRD IPC
B10: Policy rate (TPM) | C10: % | D10: 5.75 | E10: 5.25 | F10: 5.25% (held 31-Aug-26) | G10: n.a. | H10: BCRD, Comunicado de politica monetaria, 31-Aug-2026
B11: Central govt balance | C11: % GDP | D11: -3.1 | E11: -3.6 | F11: -3.24% budget (rev. Jul-26) | G11: -3.1% MFMP | H11: BCRD; MHE MFMP; Acento 28-Jul-26
B12: Central govt primary balance | C12: % GDP | D12: 0.3 | E12: -0.1 | F12: n.a. | G12: +0.5% MFMP | H12: MHE MFMP
B13: SPNF balance | C13: % GDP | D13: -3.2 | E13: -3.3 | F13: n.a. | G13: n.a. | H13: BCRD
B14: SPNF debt | C14: % GDP | D14: 47.6 (calc) | E14: 48.1 | F14: 48.2% (Jul-26, US$67.8bn) | G14: 48.4% MFMP | H14: DGCP (creditopublico.gob.do), saldo deuda SPNF, Jul-2026 (17-Aug-2026)
B15: Consolidated public debt (SPNF+BCRD) | C15: % GDP | D15: n.a. | E15: n.a. | F15: 59.5% (Jun-26, US$83.8bn) | G15: n.a. | H15: DGCP via press, Jun-26
B16: Interest / central govt revenue | C16: % | D16: 20.7 | E16: 21.9 | F16: n.a. | G16: 23.1% (2026 budget) | H16: BCRD (calc); MHE MFMP
B17: Current account | C17: % GDP | D17: -3.1 | E17: -1.2 | F17: n.a. | G17: -1.3% BCRD / -1.5% IMF | H17: BCRD; IMF WEO Apr-26
B18: Current account | C18: US$ mn | D18: -3804.7 | E18: -1508.2 | F18: n.a. | G18: n.a. | H18: BCRD, Resultados preliminares de la economia dominicana, ene-dic 2025 (Feb-2026)
B19: FDI (net inflow) | C19: US$ mn | D19: 4523.2 | E19: 5032.3 | F19: 3,276.5 (H1-26, +7.7%) | G19: >5,300 BCRD | H19: BCRD
B20: Remittances | C20: US$ mn | D20: 10756 | E20: 11866.3 | F20: 6,291.3 (H1-26, +6.7%) | G20: n.a. | H20: BCRD
B21: Tourism receipts | C21: US$ mn | D21: 10972.4 | E21: 11318.5 | F21: 6,716.0 (H1-26, +15.3%) | G21: n.a. | H21: BCRD
B22: Gross international reserves | C22: US$ mn | D22: 13387.6 | E22: 14691.2 | F22: >15,000 (Aug-26) | G22: n.a. | H22: BCRD
B23: Reserves | C23: % GDP / months imports | D23: 10.8% (calc) / n.a. | E23: 11.5% / 5.6 | F23: ~11% / ~5 | G23: n.a. | H23: BCRD
B24: RD$/US$ (end-period, sell) | C24: RD$ | D24: 60.94 | E24: 63.64 | F24: ~58.5 (Aug-26; peso +7-8% YTD) | G24: 63.95 avg (MHE, Mar-26 - stale) | H24: BCRD; MHE
B25: Sovereign ratings (FC LT) | E25: Moody's Ba2 stb (upgr. 2025); S&P BB stb; Fitch BB- pos | F25: Fitch outlook to Stable (Apr-26); others unchanged | H25: MHE MFMP; agencies
B26: 2024 remittances and tourism receipts derived: 2025 level less reported y/y increase (US$1,110.3mn and US$346.1mn). 2024 SPNF debt/GDP and interest/revenue computed from BCRD RD$ tables and MHE GDP.
B27: 2024/2025 FX is BCRD end-Dec sell rate. 2026 level is approximate (BCRD reports +8% appreciation vs end-2025 at end-Jul, >7% at end-Aug); pull spot from Bloomberg (DOP Curncy) before publication.
B29: Bottom line
B30: - Growth has re-accelerated: IMAE +4.5% Jan-Jul 2026 after 2.1% in 2025, led by construction (public + private investment), mining (gold) and tourism. BCRD now guides ~4.5% for 2026; MHE/IMF are at 3.7-3.8%.
B31: - Inflation breached the 4%±1% band from Apr-26 (oil shock from the Middle East conflict) but peaked in June (5.67%) and is turning down (5.47% Jul); core is inside the band (4.96%). Fuel subsidies are absorbing part of the shock.
B32: - BCRD on hold at 5.25% since Nov-2025; it guides headline back in band in 4Q26. Ex-ante real rate is thin (~0.3pp vs core) - no rush to cut, no reason to hike while the peso is appreciating.
B33: - Fiscal: CG deficit 3.6% of GDP in 2025 (primary deficit 0.1%), budgeted 3.1-3.2% for 2026. Ley 30-26 (Jun-26) adds ~0.4-0.5% of GDP via a temporary 30% CIT on large firms and other measures; July budget reformulation added RD$41bn spending. Interest is the binding constraint: 23% of revenue in 2026 - highest in LatAm ex-Mexico per MHE's own peer chart.
B34: - External accounts are the strong leg: CA deficit ~1.2-1.5% of GDP fully FDI-financed (FDI ~4% of GDP), reserves >US$15bn (~11% GDP), peso +7-8% YTD. Watch: overvaluation debate and reversal risk if oil stays high or US remittances slow.
B35: - Politics: Abinader (PRM) second term to Aug-2028, cannot run again. Approval ~50-58% depending on pollster. 2028 succession: Collado (PRM) vs Leonel/Omar Fernández (FP). Policy continuity risk is low near-term; reform depth (tax base, electricity) remains the medium-term gap.

Sheet GDP
B2: Real activity
B3: Sectoral GDP growth (BCRD) and 2026 monthly IMAE. Blue = source input; black = formula.
B5: Real GDP by activity (% y/y)
B6: Activity | C6: 2024 | D6: 2025 | E6: Change (pp) | F6: 2025 contribution (pp)
B7: Agriculture & livestock | C7: 4.9 | D7: 3.7 | E7: =D7-C7 | F7: 0.2
B8: Mining & quarrying | C8: -5.2 | D8: 4.6 | E8: =D8-C8 | F8: 0.1
B9: Local manufacturing | C9: 4.3 | D9: 1.4 | E9: =D9-C9 | F9: 0.2
B10: Free-zone manufacturing | C10: 4.3 | D10: 1.8 | E10: =D10-C10 | F10: 0.1
B11: Construction | C11: 2.1 | D11: -1.8 | E11: =D11-C11 | F11: -0.2
B12: Services (total) | C12: 5.5 | D12: 2.8 | E12: =D12-C12 | F12: 1.7
B13: Energy & water | C13: 7 | D13: 2.8 | E13: =D13-C13 | F13: 0
B14: Commerce | C14: 5.6 | D14: 2.1 | E14: =D14-C14 | F14: 0.2
B15: Hotels, bars & restaurants | C15: 9.5 | D15: 3.5 | E15: =D15-C15 | F15: 0.3
B16: Transport & storage | C16: 5.7 | D16: 4.1 | E16: =D16-C16 | F16: 0.3
B17: Communications | C17: 3.2 | D17: 0.4 | E17: =D17-C17 | F17: 0
B18: Financial services | C18: 8.1 | D18: 7.5 | E18: =D18-C18 | F18: 0.3
... B24: Other market services | C24: 3.7 | D24: 1.6 | E24: =D24-C24 | F24: 0
B25: Gross value added | C25: 4.7 | D25: 2.2 | E25: =D25-C25
B26: Net taxes on production | C26: 8.7 | D26: 1.5 | E26: =D26-C26
B27: GDP | C27: 5 | D27: 2.1 | E27: =D27-C27 | F27: 2.1
B28: Source: BCRD, Resultados preliminares de la economia dominicana, ene-dic 2025 (Feb-2026); contributions from MHE MFMP Cuadro 1. Construction is 12.5% of GDP, services 61.8% of value added (MHE).
B30: 2026 monthly activity (IMAE, % y/y)
B31: Period | C31: IMAE % y/y | D31: Construction | E31: Mining | F31: Hotels/bars/rest. | G31: Fin. services | H31: Note
B32: 1Q 2026 (avg) | C32: 4.1 | D32: 6.6 | E32: 7.7 | F32: 6.2 | G32: 5.9 | H32: MHE MFMP citing BCRD; tourist arrivals +12.2% in 1Q
B33: Mar-26 | C33: 5.1 | H33: MHE MFMP chart label
B34: Apr-26 | C34: 3.7 | D34: -1.8 | H34: Derived: Jan-Apr avg 4.0% less 1Q avg 4.1%. Construction -1.8% in April per BCRD
B35: May-26 | C35: 4.7 | D35: 7.1 | E35: 6.4 | F35: 6.2 | H35: BCRD 25-Jun-26; services +5.3%, local mfg +2.9%
B36: Jun-26 | C36: 6.4 | E36: 18.1 | H36: BCRD 23-Jul-26; strongest print of the year; trend-cycle 5.5%; FZ mfg +5.8%
B37: 2Q 2026 (avg) | C37: 5 | H37: BCRD
B38: Jul-26 | C38: 4.6 | D38: 8.1 | E38: -15.9 | F38: 5.6 | G38: 8.4 | H38: BCRD 25-Aug-26; FZ mfg +5.5%, local mfg +3.7%, agro +1.9%, services +4.8%
B39: Jan-Jul 2026 (avg) | C39: 4.5 | H39: BCRD
B40: Mining swing (Jun +18.1% / Jul -15.9%) reflects gold extraction timing at the main mine; treat monthly mining as noise. 2025 comparators: 1H25 +2.2%, Jan-Oct25 +2.0%.
B42: Growth forecasts 2026-2027 (% y/y)
B43: Source | C43: 2026 | D43: 2027 | E43: Date | F43: Comment
B44: BCRD (Aug-26 communique) | C44: 4.5 | E44: 31-Aug-26 | F44: Raised from ~4.0% (Jan-26) on investment impulse and external resilience
B45: MHE Panorama Macroeconomico / MFMP | C45: 3.75 | D45: 5 | E45: Mar/Apr-26 | F45: Converges to ~5% potential from 2027; conditional on Middle East conflict
B46: IMF WEO | C46: 3.7 | D46: 4.4 | E46: Apr-26 | F46: Nov-25 Article IV had 4.5% for 2026 before the oil shock
B47: Potential growth (BCRD) | C47: 4.5 | D47: 5 | F47: BCRD cites 4.0-5.0% range as potential
B49: Labour market 2025 (MHE): +117,948 employed (85,764 formal / 32,184 informal); open unemployment 5.1% at year-end.
I51: Chart helper
...

Sheet CPI
B2: Prices
B3: Headline and core inflation (BCRD). Target 4.0% +/- 1.0%. Blue = source input; black = formula.
B5: Monthly inflation (%)
B6: Month | C6: Headline m/m | D6: Headline y/y | E6: Core y/y | F6: Target upper | G6: Target lower | H6: Gap to upper (pp) | I6: Note
B7: Dec-24 | C7: 0.7 | D7: 3.35 | E7: 4.01 | F7: 5 | G7: 3 | H7: =D7-F7
B8: Jan-25 | C8: 0.37 | D8: 3.32 | E8: 4.03 | F8: 5 | G8: 3 | H8: =D8-F8
B9: Feb-25 | C9: 0.32 | D9: 3.56 | E9: 4.21 | F9: 5 | G9: 3 | H9: =D9-F9
B10: Mar-25 | C10: 0.31 | D10: 3.58 | E10: 4.24 | F10: 5 | G10: 3 | H10: =D10-F10
B11: Apr-25 | C11: 0.03 | D11: 3.71 | E11: 4.13 | F11: 5 | G11: 3 | H11: =D11-F11
B12: May-25 | C12: 0.08 | D12: 3.84 | E12: 4.22 | F12: 5 | G12: 3 | H12: =D12-F12
B13: Jun-25 | C13: 0.21 | D13: 3.56 | E13: 4.15 | F13: 5 | G13: 3 | H13: =D13-F13
B14: Jul-25 | C14: 0.38 | D14: 3.4 | E14: 4.19 | F14: 5 | G14: 3 | H14: =D14-F14
B15: Aug-25 | C15: 0.71 | D15: 3.71 | E15: 4.32 | F15: 5 | G15: 3 | H15: =D15-F15
B16: Sep-25 | C16: 0.34 | D16: 3.76 | E16: 4.35 | F16: 5 | G16: 3 | H16: =D16-F16
B17: Oct-25 | C17: 0.55 | D17: 4.23 | E17: 4.67 | F17: 5 | G17: 3 | H17: =D17-F17 | I17: Tormenta Melissa food shock begins
B18: Nov-25 | C18: 0.71 | D18: 4.81 | E18: 4.74 | F18: 5 | G18: 3 | H18: =D18-F18
B19: Dec-25 | C19: 0.84 | D19: 4.95 | E19: 4.85 | F19: 5 | G19: 3 | H19: =D19-F19 | I19: Food & non-alc. beverages +8.19% in 2025 (42.8% of headline)
B20: Jan-26 | C20: 0.4 | D20: 4.98 | F20: 5 | G20: 3 | H20: =D20-F20
B21: Feb-26 | C21: 0.03 | D21: 4.67 | E21: 4.76 | F21: 5 | G21: 3 | H21: =D21-F21 | I21: Food -0.56% m/m
B22: Mar-26 | C22: 0.27 | D22: 4.63 | F22: 5 | G22: 3 | H22: =D22-F22 | I22: m/m derived from Jan-May cumulative 1.50%
B23: Apr-26 | C23: 0.49 | D23: 5.11 | F23: 5 | G23: 3 | H23: =D23-F23 | I23: Fuel price adjustments (Middle East conflict from Feb-26); above band
B24: May-26 | C24: 0.31 | D24: 5.35 | F24: 5 | G24: 3 | H24: =D24-F24 | I24: Transport +2.16% m/m; chicken -6.6%, plantain -3.9%
B25: Jun-26 | C25: 0.48 | D25: 5.67 | E25: 4.96 | F25: 5 | G25: 3 | H25: =D25-F25 | I25: Peak; m/m derived from 1H avg 0.33%
B26: Jul-26 | C26: 0.19 | D26: 5.47 | E26: 4.96 | F26: 5 | G26: 3 | H26: =D26-F26 | I26: Transport -0.14% m/m on fuel cuts; tradables -0.11%; FX appreciation lowers car prices
B27: Source: BCRD, Resultados preliminares de la economia dominicana, ene-dic 2025 (Feb-2026) (2025 series); BCRD, Informe IPC mensual 2026 and BCRD monthly press releases (2026). Core y/y for Jan/Mar/Apr/May-26 not captured - fill from BCRD Informe IPC.
B28: 2025 annual average inflation 3.87%; MHE projects 5.0% average / 4.5% Dec for 2026 (Mar-26 revision). BCRD (Aug-26): headline returns to band in 4Q26.
B30: 2025 inflation by group (Dec/Dec)
B31: Group | C31: Weight (%) | D31: Index Dec-24 | E31: Index Dec-25 | F31: Change (%) | G31: Incidence (pp) | H31: Share of headline (%)
B32: CPI general | C32: 100 | D32: 130.72 | E32: 137.2 | F32: =E32/D32-1 | G32: =F32*100 | H32: 1
B33: Food & non-alcoholic beverages | C33: 23.84 | D33: 141.84 | E33: 153.46 | F33: =E33/D33-1 | G33: =C33/100*F33*100 | H33: =G33/$G$32
B34: Alcoholic beverages & tobacco | C34: 2.36 | D34: 133.22 | E34: 140.03 | F34: =E34/D34-1 | G34: =C34/100*F34*100 | H34: =G34/$G$32
B35: Clothing & footwear | C35: 4.19 | D35: 98.39 | E35: 96.99 | F35: =E35/D35-1 | G35: =C35/100*F35*100 | H35: =G35/$G$32
B36: Housing | C36: 12.98 | D36: 123.25 | E36: 126.29 | F36: =E36/D36-1 | G36: =C36/100*F36*100 | H36: =G36/$G$32
B37: Furnishings & household | C37: 5.17 | D37: 122.6 | E37: 124.85 | F37: =E37/D37-1 | G37: =C37/100*F37*100 | H37: =G37/$G$32
B38: Health | C38: 4.74 | D38: 127.56 | E38: 134.06 | F38: =E38/D38-1 | G38: =C38/100*F38*100 | H38: =G38/$G$32
B39: Transport | C39: 16.65 | D39: 135.97 | E39: 140.66 | F39: =E39/D39-1 | G39: =C39/100*F39*100 | H39: =G39/$G$32
B40: Communications | C40: 5.06 | D40: 97.52 | E40: 98.29 | F40: =E40/D40-1 | G40: =C40/100*F40*100 | H40: =G40/$G$32
B41: Recreation & culture | C41: 3.03 | D41: 118.2 | E41: 121.41 | F41: =E41/D41-1 | G41: =C41/100*F41*100 | H41: =G41/$G$32
B42: Education | C42: 3.06 | D42: 123.18 | E42: 130.36 | F42: =E42/D42-1 | G42: =C42/100*F42*100 | H42: =G42/$G$32
B43: Restaurants & hotels | C43: 8.62 | D43: 140.69 | E43: 149.87 | F43: =E43/D43-1 | G43: =C43/100*F43*100 | H43: =G43/$G$32
...

Sheet Policy rate
B2: Monetary policy
B3: BCRD policy rate (TPM), corridor, market rates and real-rate arithmetic. Blue = source input; black = formula.
B5: TPM path (%, end of month, effective)
B6: Month | C6: TPM | D6: Decision | E6: Headline CPI y/y | F6: Core CPI y/y | G6: Real TPM ex-post (vs core) | H6: Note
B7: Dec-24 | C7: 5.75 | D7: cum. -125bp in 2024 | E7: 3.35 | F7: 4.01 | G7: =(1+C7/100)/(1+F7/100)-1 | H7: 2024 easing cycle from 7.00% - verify dates on BCRD before publication
B8: Jan-25 | C8: 5.75 | D8: hold | E8: 3.32 | F8: 4.03 | G8: =(1+C8/100)/(1+F8/100)-1
B9: Jun-25 | C9: 5.75 | D9: hold | E9: 3.56 | F9: 4.15 | G9: =(1+C9/100)/(1+F9/100)-1 | H9: JM approves RD$81bn liquidity programme for productive sectors
B10: Sep-25 | C10: 5.75 | D10: hold (cut announced, eff. Oct) | E10: 3.76 | F10: 4.35 | G10: =(1+C10/100)/(1+F10/100)-1 | H10: Sep meeting cut 25bp, effective 1st business day of Oct
B11: Oct-25 | C11: 5.5 | D11: -25bp effective | E11: 4.23 | F11: 4.67 | G11: =(1+C11/100)/(1+F11/100)-1
B12: Nov-25 | C12: 5.25 | D12: -25bp effective | E12: 4.81 | F12: 4.74 | G12: =(1+C12/100)/(1+F12/100)-1 | H12: Oct meeting cut 25bp
B13: Dec-25 | C13: 5.25 | D13: hold | E13: 4.95 | F13: 4.85 | G13: =(1+C13/100)/(1+F13/100)-1 | H13: Repo 5.75% / overnight 4.50%; interbank 1-7d 7.92% (-635bp since Jun)
B14: Mar-26 | C14: 5.25 | D14: hold | E14: 4.63 | H14: Oil shock begins (Feb-26)
B15: May-26 | C15: 5.25 | D15: hold | E15: 5.35 | H15: JM postpones to 2027 the repayment of liquidity facilities (May-26)
B16: Jul-26 | C16: 5.25 | D16: hold | E16: 5.47 | F16: 4.96 | G16: =(1+C16/100)/(1+F16/100)-1 | H16: Critics (Jul-26) accuse BCRD of restricting liquidity
B17: Aug-26 | C17: 5.25 | D17: hold (31-Aug) | E17: 5.47 | F17: 4.96 | G17: =(1+C17/100)/(1+F17/100)-1 | H17: Guides convergence to band in 4Q26; private credit MN ~+8% y/y in Jul. Valdez Albizu ratified governor for 2 more years (Decreto 575-26, 19-Aug)
B18: Sources: BCRD, Resultados preliminares de la economia dominicana, ene-dic 2025 (Feb-2026); BCRD, Comunicado de politica monetaria, 31-Aug-2026; BCRD monthly communiques. Corridor: repo (expansion facility) TPM+50bp, overnight deposit TPM-75bp.
B20: Market rates and credit (Dec-2025, %)
B21: Item | C21: Dec-24 | D21: Dec-25 | E21: Change (pp) | F21: Note
B22: Interbank 1-7 day | D22: 7.92 | F22: -635bp since Jun-25; peak 4Q24 was decade high
B23: Multiple banks lending rate (wtd avg) | C23: 15.05 | D23: 13.28 | E23: =D23-C23 | F23: -1.77pp y/y
B24: Multiple banks deposit rate (wtd avg) | C24: 9.81 | D24: 6.08 | E24: =D24-C24 | F24: -3.73pp y/y
B25: Private credit MN growth (% y/y) | D25: 8.3 | F25: Jul-26: ~8%; total private credit +9.8% in 2025
B26: M3 growth (% y/y) | D26: 12 | F26: M1 +10.6%, M2 +9.9%; BCRD securities outstanding -6.5%
B27: NPL ratio, financial system (%) | C27: 1.4 | D27: 1.7 | E27: =D27-C27 | F27: Coverage 174%; ROE 21.0%, ROA 2.5%
B29: Real policy rate arithmetic (Aug-2026)
B30: TPM (%) | C30: 5.25
B31: Core CPI y/y, Jul-26 (%) | C31: 4.96
B32: Expected Dec-26 headline (MHE) (%) | C32: 4.5
B33: Target midpoint (%) | C33: 4
B34: Real TPM vs core (pp) | C34: =C30-C31
B35: Real TPM vs expected Dec-26 (pp) | C35: =C30-C32
B36: Real TPM vs target midpoint (pp) | C36: =C30-C33
B37: Fed funds (upper, Dec-25) (%) | C37: 3.75
B38: TPM - Fed funds (pp) | C38: =C30-C37
B39: MHE (MFMP) estimated the real interbank rate below neutral in 4Q25 (financial conditions index negative for first time since mid-2024) - i.e. stance is mildly accommodative on their measure. Fed funds from BCRD report (Dec-25 range 3.50-3.75%); update from Bloomberg.

Sheet Fiscal
B2: Public finances
B3: Central government operations (GFSM 2014, accrual), MFMP 2026-2030 projections, debt. Blue = source input; black = formula.
B5: Nominal GDP (for ratios)
B6: Item | C6: 2024 | D6: 2025 | E6: 2026 (Mar-26 rev.) | F6: 2026 (Jun-26 rev.) | G6: Note
B7: Nominal GDP, RD$ mn | C7: 7403037 | D7: 7897551.3 | E7: 8619782.4 | F7: 8677138.3 | G7: 2024 back-solved from 2025 level and MHE nominal growth 6.68%; 2026 Jun revision used by DGCP for debt ratios
B8: Nominal GDP, US$ mn | C8: 124254.4 | D8: 127861.4 | E8: 134789.4 | F8: 140737.2 | G8: 2024 per BCRD (press, El Nacional Dec-25); 2025-26 per MHE MFMP / DGCP. Jun-26 rev. reflects peso appreciation.
B10: Central government operations, RD$ mn (accrual)
B11: Line | C11: 2024 | D11: 2025 | E11: % chg | F11: 2025 % GDP | G11: 2026 budget (MFMP) | H11: 2026 % GDP
B12: Revenue | C12: 1212472.6 | D12: 1246302.1 | E12: =IF(C12=0,"",D12/C12-1) | F12: =D12/$D$7 | G12: 1342258.2 | H12: =G12/$E$7
B13: Taxes | C13: 1074304.7 | D13: 1134472.9 | E13: =IF(C13=0,"",D13/C13-1) | F13: =D13/$D$7 | G13: 1236961.3 | H13: =G13/$E$7
B14: Income, profits & capital gains | C14: 380171.5 | D14: 415498 | E14: =IF(C14=0,"",D14/C14-1) | F14: =D14/$D$7
B15: Property | C15: 16589.6 | D15: 18231.7 | E15: =IF(C15=0,"",D15/C15-1) | F15: =D15/$D$7
B16: Goods & services | C16: 606729.3 | D16: 627982 | E16: =IF(C16=0,"",D16/C16-1) | F16: =D16/$D$7
B17: of which ITBIS (VAT) | C17: 375087.6 | D17: 389676.8 | E17: =IF(C17=0,"",D17/C17-1) | F17: =D17/$D$7
B18: International trade | C18: 70737.2 | D18: 72686.4 | E18: =IF(C18=0,"",D18/C18-1) | F18: =D18/$D$7
B19: Social contributions | C19: 7372.3 | D19: 6681.3 | E19: =IF(C19=0,"",D19/C19-1) | F19: =D19/$D$7
B20: Grants | C20: 49284.8 | D20: 9403.4 | E20: =IF(C20=0,"",D20/C20-1) | F20: =D20/$D$7 | G20: 2133.7 | H20: =G20/$E$7
B21: Other revenue | C21: 81510.8 | D21: 95744.5 | E21: =IF(C21=0,"",D21/C21-1) | F21: =D21/$D$7
B22: Expense | C22: 1299291.5 | D22: 1378268.6 | E22: =IF(C22=0,"",D22/C22-1) | F22: =D22/$D$7
B23: Compensation of employees | C23: 338305.9 | D23: 360961.3 | E23: =IF(C23=0,"",D23/C23-1) | F23: =D23/$D$7
B24: Use of goods & services | C24: 147634.9 | D24: 159226.9 | E24: =IF(C24=0,"",D24/C24-1) | F24: =D24/$D$7
B25: Interest | C25: 250443 | D25: 272521.3 | E25: =IF(C25=0,"",D25/C25-1) | F25: =D25/$D$7 | G25: 310214.3 | H25: =G25/$E$7
B26: Subsidies | C26: 137521.1 | D26: 134278.6 | E26: =IF(C26=0,"",D26/C26-1) | F26: =D26/$D$7
B27: Grants (transfers) | C27: 212348.1 | D27: 223324.3 | E27: =IF(C27=0,"",D27/C27-1) | F27: =D27/$D$7
B28: Social benefits | C28: 133093.9 | D28: 139081.1 | E28: =IF(C28=0,"",D28/C28-1) | F28: =D28/$D$7
B29: Other expense | C29: 79944.5 | D29: 88875.1 | E29: =IF(C29=0,"",D29/C29-1) | F29: =D29/$D$7
B30: Net investment in non-financial assets | C30: 136809.7 | D30: 161160 | E30: =IF(C30=0,"",D30/C30-1) | F30: =D30/$D$7
B31: Total outlays (expense + NFA) | C31: 1436101.2 | D31: 1539428.6 | E31: =IF(C31=0,"",D31/C31-1) | F31: =D31/$D$7 | G31: 1608790.6 | H31: =G31/$E$7
B32: Primary outlays (ex interest) | C32: =C31-C25 | D32: =D31-D25 | E32: =IF(C32=0,"",D32/C32-1) | F32: =D32/$D$7 | G32: 1298576.3 | H32: =G32/$E$7
B33: Net lending / borrowing (CG) | C33: -228549.9 | D33: -283643.5 | E33: =IF(C33=0,"",D33/C33-1) | F33: =D33/$D$7 | G33: -266532.5 | H33: =G33/$E$7
B34: Primary balance (CG) | C34: =C33+C25 | D34: =D33+D25 | E34: =IF(C34=0,"",D34/C34-1) | F34: =D34/$D$7 | G34: 43681.9 | H34: =G34/$E$7
B35: Rest of SPNF balance | C35: -4796.7 | D35: 20906.5 | E35: =IF(C35=0,"",D35/C35-1) | F35: =D35/$D$7
B36: SPNF net lending / borrowing | C36: -233346.6 | D36: -262737 | E36: =IF(C36=0,"",D36/C36-1) | F36: =D36/$D$7
B37: Source: BCRD, Resultados preliminares de la economia dominicana, ene-dic 2025 (Feb-2026) (Estado de operaciones GC y SPNF); 2026 budget lines from MHE, Marco Fiscal de Mediano Plazo 2026-2030 (Abr-2026) Cuadro 6 (Ley 99-25 as adjusted for interest re-estimate). Net investment in NFA = 'inversion bruta en activos no financieros'.
B38: MHE reports 2025 CG primary deficit RD$11,115.7mn (-0.14% GDP) vs the -11,122 implied here (rounding). MHE structural primary balance 2025: +0.44% GDP; fiscal impulse 2025: -0.83% (contractionary).
B40: Key fiscal ratios (% of GDP) - central government
B41: Ratio | C41: 2021 | D41: 2022 | E41: 2023 | F41: 2024 | G41: 2025 | H41: 2026B | I41: 2027 | J41: 2028 | K41: 2029 | L41: 2030
B42: Revenue | C42: 15.6 | D42: 15.3 | E42: 15.7 | F42: 16.4 | G42: 15.8 | H42: 15.6 | I42: 15.5 | J42: 15.5 | K42: 15.5 | L42: 15.5
B43: Taxes | C43: 14.4 | D43: 13.8 | E43: 14.2 | F43: 14.5 | G43: 14.4 | H43: 14.4 | I43: 14.4 | J43: 14.5 | K43: 14.5 | L43: 14.6
B44: Expense (ex NFA) | C44: 16.8 | D44: 17 | E44: 16.9 | F44: 17.6 | G44: 17.5
...

Sheet External
B2: External accounts
B3: Balance of payments (BPM6), trade, FX inflows, reserves, exchange rate. Blue = source input; black = formula.
B5: Balance of payments, US$ mn
B6: Line | C6: 2024 | D6: 2025 | E6: Change | F6: 2025 % GDP | G6: Note
B7: Current account | C7: -3804.7 | D7: -1508.2 | E7: =D7-C7 | F7: =D7/Fiscal!$D$8
B8: Goods balance | C8: -15870.4 | D8: -13857.7 | E8: =D8-C8 | F8: =D8/Fiscal!$D$8 | G8: Exports +14.4%, imports flat
B9: Services balance | C9: 8354.6 | D9: 8806.7 | E9: =D9-C9 | F9: =D9/Fiscal!$D$8 | G9: Tourism +US$346mn
B10: Primary income | C10: -6426 | D10: -7759.5 | E10: =D10-C10 | F10: =D10/Fiscal!$D$8 | G10: Widening: FDI stock returns + external interest (US$2.8bn public)
B11: Secondary income | C11: 10137.1 | D11: 11302.3 | E11: =D11-C11 | F11: =D11/Fiscal!$D$8 | G11: Remittances +10.3%; >80% from US
B12: Financial account (net lending) | C12: -3615.3 | D12: -3663.2 | E12: =D12-C12 | F12: =D12/Fiscal!$D$8 | G12: Negative = net borrowing from RoW
B13: Direct investment | C13: -4523.2 | D13: -5032.3 | E13: =D13-C13 | F13: =D13/Fiscal!$D$8 | G13: Liabilities +4,906.8; mining, telecoms, commerce
B14: Portfolio investment | C14: -2432 | D14: -3174.9 | E14: =D14-C14 | F14: =D14/Fiscal!$D$8 | G14: Liabilities +3,530 (sovereign bonds)
B15: Other investment | C15: 3339.9 | D15: 4544 | E15: =D15-C15 | F15: =D15/Fiscal!$D$8 | G15: Assets: currency & deposits +4,028 (resident FX accumulation abroad)
B16: Errors and omissions | C16: -1573.8 | D16: -563.6 | E16: =D16-C16 | F16: =D16/Fiscal!$D$8
B17: Reserve assets (change) | C17: -2085.9 | D17: 1264 | E17: =D17-C17 | F17: =D17/Fiscal!$D$8 | G17: Sign per BCRD table ('Financiamiento'); gross reserves rose US$1,304mn in 2025
B18: FDI / current account deficit (x) | C18: =-C13/C7 | D18: =-D13/D7 | G18: BCRD (Aug-26): 2026 CA deficit ~1.3% GDP, covered ~3x by FDI
B19: Source: BCRD, Resultados preliminares de la economia dominicana, ene-dic 2025 (Feb-2026). Primary income deficit is the structural drain: 6.1% of GDP in 2025 and widening with the FDI stock (compare Argentina thesis).
B21: Trade, US$ mn
B22: Line | C22: 2024 | D22: 2025 | E22: % chg | F22: H1-2026 | G22: H1 % y/y | H22: Note
B23: Total goods exports | C23: 13927.4 | D23: 15930.6 | E23: =D23/C23-1 | F23: 8745.7 | G23: 0.166
B24: National (non-FZ) | C24: 5427.1 | D24: 7382 | E24: =D24/C24-1 | H24: +36% in 2025
B25: Minerals | C25: 1712.7 | D25: 2648.7 | E25: =D25/C25-1 | H25: Gold +60.9% to US$2,413mn; H1-26 gold US$1,591.9mn (+68.8%)
B26: Agricultural | C26: 774.4 | D26: 961.5 | E26: =D26/C26-1 | H26: Cocoa beans +37.7%
B27: Industrial | C27: 2940 | D27: 3771.8 | E27: =D27/C27-1 | H27: Steel rebar +72%, jet fuel re-exports US$646mn
B28: Free zones | C28: 8500.3 | D28: 8548.6 | E28: =D28/C28-1 | F28: 4359.7 | G28: 0.032 | H28: Medical devices US$2,859mn, tobacco 1,337, electrical 1,169, textiles 855
B29: Total goods imports | C29: 29797.8 | D29: 29788.3 | E29: =D29/C29-1 | H29: Flat in 2025
B30: Oil imports | C30: 4731.7 | D30: 4616.7 | E30: =D30/C30-1 | H30: -2.4% on -8.1% avg price in 2025; 2026 bill rising with WTI ~US$80-90
B31: Non-oil imports | C31: 25066.1 | D31: 25171.6 | E31: =D31/C31-1
B32: Capital goods (national) | C32: 4416.7 | D32: 4050.2 | E32: =D32/C32-1 | H32: -8.3%: investment postponement in 2025
B34: FX-generating flows, US$ mn
B35: Flow | C35: 2024 | D35: 2025 | E35: % chg | F35: H1-2026 | G35: H1 % y/y | H35: Note
B36: Goods exports | C36: 13927.4 | D36: 15930.6 | E36: =D36/C36-1 | F36: 8745.7 | G36: 0.166
B37: Tourism receipts | C37: 10972.4 | D37: 11318.5 | E37: =D37/C37-1 | F37: 6716 | G37: 0.153 | H37: 2025: 11.64mn non-resident visitors (8.86mn air + 2.77mn cruise); H1-26 arrivals >6.5mn (+7.9%); Mar-26 first month >900k air
B38: Remittances | C38: 10756 | D38: 11866.3 | E38: =D38/C38-1 | F38: 6291.3 | G38: 0.067 | H38: 1Q26 +1.9% only (US labour market); recovered to +6.7% by H1
B39: FDI (net inflow) | C39: 4523.2 | D39: 5032.3 | E39: =D39/C39-1 | F39: 3276.5 | G39: 0.077 | H39: H1-26 sectors: energy 27.8%, tourism 20.1%, real estate 12.4%, mining 12.4%; 2Q26 US$1,604.6mn; BCRD FY guide >US$5,300mn
B40: Total FX inflows (BCRD aggregate) | C40: 43897.7 | D40: 47355.7 | E40: =D40/C40-1 | F40: 26500 | G40: =(26500-23700)/23700 | H40: Incl. other services; H1-26 +US$2,800mn y/y
B41: Tourism + remittances, % GDP (2025) | D41: =(D37+D38)/Fiscal!$D$8
B42: Sources: BCRD, Resultados preliminares de la economia dominicana, ene-dic 2025 (Feb-2026); BCRD, IED y flujos de divisas ene-jun 2026 (28-Jul-2026); BCRD FX analysis 5-Aug-26. 2024 tourism/remittances derived from reported y/y increments. H1-26 aggregate y/y uses 'about +2,800mn' - approximate.
B44: Reserves and exchange rate
B45: Item | C45: Dec-24 | D45: Dec-25 | E45: Change | F45: Latest 2026 | G45: Note
...

Sheet Politics
B2: Politics and policy calendar
B3: Institutional set-up, approval, 2028 succession, legislative agenda, risk register.
B5: Institutional set-up
B6: Item | C6: Detail
B7: President | C7: Luis Abinader (PRM), second term 16-Aug-2024 to 16-Aug-2028; re-elected May-2024 in first round with 57%. Constitutionally barred from a third term (2024 constitutional reform locked two-term limit).
B8: Congress | C8: PRM and allies control both chambers (Senate and Chamber of Deputies) after the 2024 elections; Ley 30-26 and the July-2026 budget modification both passed under urgent procedure over FP objections.
B9: Economic team | C9: Ministry of Hacienda y Economia (MHE): Magin Diaz (minister). BCRD: Hector Valdez Albizu (governor since 2004, also 1994-2000; ratified 19-Aug-2026 for two more years with vice-governor Clarissa de la Rocha, Decreto 575-26). Cabinet reshuffle announced Aug-2026. Fiscal Responsibility Law 35-24 in force since 2024.
B10: Next elections | C10: General elections May-2028 (presidential, congressional, municipal in Feb-2028). Party primaries expected 2027.
B11: Opposition | C11: Fuerza del Pueblo (FP, Leonel Fernandez, ex-president 1996-2000, 2004-2012) is the main opposition; PLD (Danilo Medina's party) third. Both opposed Ley 30-26 tax measures and the budget modification.
B13: Approval and 2028 preferences (latest polls)
B14: Poll / date | C14: Finding
B15: ACD Media, Aug-2026 | C15: Government approval 51.3% / disapproval 47.0%; Abinader personal 50.2% positive / 48.2% negative. Officials rated worse than the president.
B16: CID Latinoamerica, 16-24 May-2026 | C16: Abinader approval 58% / disapproval 39%. PRM internal: David Collado (Tourism minister) 62% vs Carolina Mejia (Santo Domingo mayor) 21%. FP internal: Leonel Fernandez 52% vs Omar Fernandez (senator, DN) 42%. PLD: Gonzalo Castillo / Abel Martinez lead. Party sympathy: PRM 31.6%, FP 26.5%, PLD 21.1%.
B17: Unnamed national poll, Jun-2026 | C17: Abinader approval 53% / 45%; management of officials 57.3% negative. PRM leads 2028 vote intention, FP second. Confidence in FP: 17.5% 'much'; PLD 17.2%.
B18: Polls are from press reports; methodologies differ. Treat as directional. No single pollster is the Dominican equivalent of Datafolha.
B20: 2026 legislative and policy events
B21: Date | C21: Event | D21: Market relevance
B22: Feb-2026 | C22: US$2.75bn Eurobond (8y 5.75%, 12.25y 6.15%), 2.6x covered | D22: Front-loaded 2026 external financing; budget contemplates US$8.5bn bonds 2026-28
B23: Feb-2026 | C23: Middle East conflict escalates; oil >US$90 WTI in March | D23: Terms-of-trade shock for a net energy importer; fuel subsidies re-activated
B24: Apr-2026 | C24: Fitch revises outlook to Stable from Positive (BB-) | D24: Removes near-term upgrade path; Moody's Ba2 and S&P BB unchanged
B25: 11-Jun-2026 | C25: Executive submits 'Medidas Pro-Crecimiento...' bill; Leonel Fernandez (FP) calls for withdrawal of new taxes and budget reformulation | D25: Opposition positions ahead of 2028: anti-tax, pro-indexation of salaries (RD$52k threshold)
B26: 18-Jun-2026 | C26: Ley 30-26 promulgated after urgent passage; opposition amendments all rejected | D26: Temporary CIT surcharge (30% for 3 yrs, firms >RD$1bn), real-estate CGT 10%, exit tax, amnesty; ~0.4-0.5% GDP. Not the structural reform (Oct-2024 attempt was withdrawn)
B27: Jul-2026 | C27: Congress approves 2026 budget modification (+RD$41.0bn) and US$465mn loans | D27: Deficit-neutral per MHE (3.24% GDP) using Ley 30-26 revenue + 2025 cash carry-over; FP questions execution (border wall ~15% executed)
B28: Jul/Aug-2026 | C28: Peso overvaluation debate; economists criticise BCRD liquidity restriction | D28: BCRD defends appreciation as fundamentals-driven; watch for political pressure on exporters/tourism margins
B29: Oct-2026 (expected) | C29: 2027 budget submission | D29: First test of MFMP path (deficit 3.0%, primary +0.7%) and of Ley 35-24 spending cap
B30: 2027 | C30: Party primaries; pre-campaign | D30: Spending pressure into 2028; FP/PLD platform likely anti-tax, pro-subsidy
B32: Risk register
B33: Risk | C33: Channel | D33: Assessment
B34: Oil shock persistence | C34: Import bill, fuel subsidies (fiscal), CPI above band, CA widening | D34: Main 2026 macro risk. Every US$10/bbl ~US$0.5bn on the 2025 oil bill (US$4.6bn at avg ~US$65). Subsidy cost is the fiscal leak.
B35: US slowdown / remittances | C35: >80% of remittances from US; tourism ~40%+ US-sourced | D35: 1Q26 remittances +1.9% was the warning; recovered to +6.7% H1. Deportation policy and US labour market are the variables.
B36: Peso overvaluation reversal | C36: Carry/portfolio inflows (US$3.5bn portfolio liabilities in 2025) reverse; exporters/FZ margins | D36: BCRD not intervening; reserves >US$15bn buffer; TPM-FFR spread ~150bp only.
B37: Interest burden | C37: Interest 23% of revenue (2026), 3.6-3.8% GDP through 2030 per MFMP | D37: Binding constraint on rating trajectory (same framing as Panama). Requires tax base widening; Ley 30-26 is temporary.
B38: Electricity sector | C38: Subsidy 1.3% GDP (2025); distribution losses; Karpowership dependence | D38: Chronic fiscal drain; no structural fix in the 2026 agenda.
B39: Haiti | C39: Border security, migration, informal trade; spending on border wall/deportations | D39: Low direct macro impact; reputational/security tail risk. Execution of border projects is a political issue.
B40: 2028 election cycle | C40: Pre-electoral spending 2027; opposition anti-tax platform | D40: PRM succession orderly (Collado leads); FP competitive. Policy continuity likely under either main party; fiscal reform depth is the question.
B41: Climate | C41: Hurricanes (Melissa Oct-25 drove food CPI +8.2%); tourism infrastructure | D41: Recurrent; insured via CCRIF and contingent lines; drives CPI volatility rather than growth.

Sheet Sources
B2: Sources and verification notes
B3: Primary official sources first. teleSUR excluded.
B5: Source | C5: Used for | D5: URL / reference
B6: BCRD, Resultados preliminares de la economia dominicana, ene-dic 2025 (Feb-2026) | C6: 2025 GDP by sector, CPI, BoP, trade, external debt, reserves, FX, fiscal operations, monetary | D6: https://cdn.bancentral.gov.do/documents/publicaciones-economicas/resultados-preliminares-de-la-economia-dominicana/documents/infeco_preliminar2025-12.pdf
B7: MHE, Marco Fiscal de Mediano Plazo 2026-2030 (Abr-2026) | C7: Fiscal ratios 2021-25, 2026 budget, MFMP 2026-30, macro framework, ratings, structural balance, Ley 35-24 compliance | D7: https://www.hacienda.gob.do/wp-content/uploads/2026/06/MFMP-2026-2030-Abril-2026-vf.pdf
B8: BCRD, Comunicado de politica monetaria, 31-Aug-2026 | C8: TPM 5.25%, inflation guidance, growth 4.5%, reserves >US$15bn, peso +7% | D8: BCRD press release via Diario Libre 31-Aug-2026
B9: DGCP (creditopublico.gob.do), saldo deuda SPNF, Jul-2026 (17-Aug-2026) | C9: SPNF debt US$67,827.8mn (48.2% GDP) Jul-26; May-26 breakdown; GDP Jun-26 revision | D9: https://www.creditopublico.gob.do/
B10: BCRD, IED y flujos de divisas ene-jun 2026 (28-Jul-2026) | C10: H1-2026 FDI, tourism, remittances, exports, total FX inflows | D10: BCRD press release 28-Jul-2026
B11: BCRD FX analysis (E. Vilorio de Painter), 5-Aug-2026 | C11: Peso +8% YTD end-Jul, +4.4% y/y; CA 2026 ~1.3% GDP; USD -5.28% since Apr-25 | D11: Diario Libre 5-Aug-2026
B12: BCRD, IMAE comunicados mensuales 2026 | C12: Monthly IMAE Jan-Jul 2026 and sector detail | D12: BCRD press releases (25-Jun, 23-Jul, 25-Aug 2026)
B13: BCRD, Informe IPC mensual 2026 | C13: Monthly CPI 2026 (Feb report PDF; Apr, May, Jul press) | D13: https://cdn.bancentral.gov.do/documents/publicaciones-economicas/indice-de-precios-al-consumidor-informe-mensual/documents/Informe-IPC-2026-02.pdf
B14: MHE press, 11-Feb-2026 | C14: Eurobond US$2.75bn terms | D14: https://www.hacienda.gob.do/rd-completa-exitosa-emision-externa-por-us2750-millones/
B15: Ley 30-26 summaries (CEF, Ulises Cabrera, Revista Mercado), Jun-2026 | C15: Tax measures | D15: Secondary legal summaries; verify against Gaceta Oficial text
B16: Acento, 28-Jul-2026 | C16: Budget modification RD$40,978mn; deficit accounting debate | D16: https://acento.com.do/economia/el-congreso-aprobo-mas-gasto-y-mas-deuda-aumento-realmente-el-deficit-del-presupuesto-2026-9726588.html
... B18: IMF WEO Apr-2026 (as cited by MHE) | C18: Growth 3.7% 2026 / 4.4% 2027; CA -1.5%; peer comparisons | D18: Via MFMP; pull WEO database directly for publication
B20: Items to verify before client distribution
B21: - 2024 TPM decision dates (workbook shows Dec-24 level 5.75% and cumulative -125bp; confirm on BCRD 'Comunicados de Politica Monetaria').
B22: - Exact gross reserves at end-Aug-2026 (BCRD says '>US$15,000mn').
B23: - Spot RD$/US$ from Bloomberg (DOP Curncy); workbook uses BCRD's '+8%' statement to imply ~58.4.
B24: - Core inflation y/y for Jan, Mar, Apr, May 2026 (BCRD Informe IPC).
B25: - 2024 SPNF debt level (back-solved from '+4.1%'); pull DGCP Dec-2024 report.
B26: - IMAE Jan and Feb 2026 individually (only 1Q average 4.1% and Mar 5.1% captured).
B27: - Fitch Apr-2026 RAC text for exact rationale; S&P 2026 affirmation date.
B28: - Ley 30-26 revenue yield: EMFI estimate 0.4-0.5% GDP; MHE used RD$19,830.8mn (0.23% GDP) in the July budget modification - reconcile.
