Workbook

Sheet Control
A1: EM ASSET MONITOR — FX / EQUITIES / EM USD CREDIT
A2: Bloomberg-linked. Every cell is a formula; nothing is pasted as a value. Companion to US_Rates_Credit_Monitor.xlsx. Built for A. Rojas, UBS CIO Americas.
A4: SETTINGS — every pull and every calculation on every tab points at these cells
E5: Horizon | F5: Obs back (rows)
A6: History start — daily block | B6: =EDATE(TODAY(),-126) | E6: 1D | F6: 2 | H6: 10.5y buffer so the 10y window is always full
A7: History end | B7: =TODAY() | E7: 1W | F7: 6 | H7: BDH end date
A8: Daily observations pulled | B8: 2610 | E8: 1M | F8: 23 | H8: weekdays; block is HIST_D rows 8:2617
A9: bp per 1% | B9: 100 | E9: 3M | F9: 66 | H9: scaling constant used by every change column
A10: Total-return horizon (years) | B10: 1 | E10: 6M | F10: 131 | H10: used on Scenario
A11: Cash hurdle (%) | B11: 4.5 | E11: 1Y | F11: 262 | H11: your stated hurdle for 'EM debt still attractive vs cash'
A12: EM USD index modified duration (yrs) | B12: 6.6 | E12: 2Y | F12: 523 | H12: INPUT — from embi_tracker.py / Bbg DUR_ADJ_MID
A13: EM USD index YTW (%) | B13: 6.55 | E13: 3Y | F13: 784 | H13: INPUT — from embi_tracker.py / Bbg INDEX_YIELD_TO_WORST
A14: EMBIGD stripped spread (bp) | B14: 208 | E14: 5Y | F14: 1305 | H14: INPUT — embi_tracker.py, 'Dur Wgt STW (Trsy)'. Chain-link across the 04-Sep-26 JPM break.
A15: UST 10Y mod duration proxy (yrs) | B15: 7.9 | E15: 10Y | F15: 2610 | H15: INPUT — par-bond duration at the current 10Y; used for the rates leg only
A16: Point-in-time: 1M ago date | B16: =WORKDAY(TODAY(),-22) | E16: YTD | F16: =NETWORKDAYS(DATE(YEAR(TODAY())-1,12,31),TODAY()) | H16: single-point BDP/BDH pulls
A17: Point-in-time: prior year-end | B17: =DATE(YEAR(TODAY())-1,12,31) | H17: same
A20: HOW TO READ THIS WORKBOOK
A21: 1. Row n of HIST_D is n-1 weekdays ago. Every lookback is INDEX(range, <offset on this sheet>); every window is range_start:INDEX(range, N).
A22: Change one cell in column F and the whole workbook re-windows.
A23: 2. If a history column shows one number instead of a full column, you are on pre-dynamic-array Excel: select the block and re-enter the BDH with Ctrl+Shift+Enter.
A24: 3. FX is quoted EM per USD throughout. Every FX return shown in this workbook is the return ON the EM currency = prior/current - 1. A positive number is EM strength.
A25: 4. The rates leg and the spread leg of EM USD credit are shown separately everywhere. There is no cell that collapses them into one undecomposed number.
A26: 5. Pass-through on the Passthrough tab is d(local 10Y) / d(UST 10Y) over the same window. Below 1.0 means the EM curve absorbed less than the US move.
A27: 6. Uncertain pulls use IFERROR(live, fallback input) with a LIVE/FALLBACK status beside them. Nothing is silently substituted with a modelled proxy.
A28: 7. Anything on Tickers flagged Verify has NOT been confirmed in SECF/FLDS. Confirm before publishing a number that depends on it.
A30: COLOUR LEGEND
A31: Blue text | E31: Hardcoded input or scenario lever — yours to change
A32: Green text | E32: Link to another tab in this workbook
A33: Purple text | E33: Live Bloomberg pull (BDH / BDP)
A34: Black text | E34: Formula computed inside this workbook

Sheet Dashboard
A1: EM ASSET MONITOR — DASHBOARD
A2: Everything on this sheet is a link. Nothing is computed here that is not computed somewhere else first.
A3: ="As of "&TEXT(INDEX(HIST_D!$A$8:$A$2617,1),"d mmm yyyy")&" | built "&TEXT(TODAY(),"d mmm yyyy")
A5: THE US SIDE — what EM is being asked to absorb
A6: Series | B6: Unit | C6: Level | D6: 1W | E6: 1M | F6: 3M | G6: YTD | H6: 1Y | I6: %ile 1y | J6: %ile 5y
A7: UST 2Y | B7: bp | C7: =INDEX(HIST_D!$B$8:$B$2617,1) | D7: =IFERROR((INDEX(HIST_D!$B$8:$B$2617,1)-INDEX(HIST_D!$B$8:$B$2617,Control!$F$7))*100,"") | E7: =IFERROR((INDEX(HIST_D!$B$8:$B$2617,1)-INDEX(HIST_D!$B$8:$B$2617,Control!$F$8))*100,"") | F7: =IFERROR((INDEX(HIST_D!$B$8:$B$2617,1)-INDEX(HIST_D!$B$8:$B$2617,Control!$F$9))*100,"") | G7: =IFERROR((INDEX(HIST_D!$B$8:$B$2617,1)-INDEX(HIST_D!$B$8:$B$2617,Control!$F$16))*100,"") | H7: =IFERROR((INDEX(HIST_D!$B$8:$B$2617,1)-INDEX(HIST_D!$B$8:$B$2617,Control!$F$11))*100,"") | I7: =IFERROR(PERCENTRANK(HIST_D!$B$8:INDEX(HIST_D!$B$8:$B$2617,Control!$F$11),INDEX(HIST_D!$B$8:$B$2617,1)),"") | J7: =IFERROR(PERCENTRANK(HIST_D!$B$8:INDEX(HIST_D!$B$8:$B$2617,Control!$F$14),INDEX(HIST_D!$B$8:$B$2617,1)),"")
A8: UST 10Y | B8: bp | C8: =INDEX(HIST_D!$D$8:$D$2617,1) | D8: =IFERROR((INDEX(HIST_D!$D$8:$D$2617,1)-INDEX(HIST_D!$D$8:$D$2617,Control!$F$7))*100,"") | E8: =IFERROR((INDEX(HIST_D!$D$8:$D$2617,1)-INDEX(HIST_D!$D$8:$D$2617,Control!$F$8))*100,"") | F8: =IFERROR((INDEX(HIST_D!$D$8:$D$2617,1)-INDEX(HIST_D!$D$8:$D$2617,Control!$F$9))*100,"") | G8: =IFERROR((INDEX(HIST_D!$D$8:$D$2617,1)-INDEX(HIST_D!$D$8:$D$2617,Control!$F$16))*100,"") | H8: =IFERROR((INDEX(HIST_D!$D$8:$D$2617,1)-INDEX(HIST_D!$D$8:$D$2617,Control!$F$11))*100,"") | I8: =IFERROR(PERCENTRANK(HIST_D!$D$8:INDEX(HIST_D!$D$8:$D$2617,Control!$F$11),INDEX(HIST_D!$D$8:$D$2617,1)),"") | J8: =IFERROR(PERCENTRANK(HIST_D!$D$8:INDEX(HIST_D!$D$8:$D$2617,Control!$F$14),INDEX(HIST_D!$D$8:$D$2617,1)),"")
A9: UST 30Y | B9: bp | C9: =INDEX(HIST_D!$E$8:$E$2617,1) | D9: =IFERROR((INDEX(HIST_D!$E$8:$E$2617,1)-INDEX(HIST_D!$E$8:$E$2617,Control!$F$7))*100,"") | E9: =IFERROR((INDEX(HIST_D!$E$8:$E$2617,1)-INDEX(HIST_D!$E$8:$E$2617,Control!$F$8))*100,"") | F9: =IFERROR((INDEX(HIST_D!$E$8:$E$2617,1)-INDEX(HIST_D!$E$8:$E$2617,Control!$F$9))*100,"") | G9: =IFERROR((INDEX(HIST_D!$E$8:$E$2617,1)-INDEX(HIST_D!$E$8:$E$2617,Control!$F$16))*100,"") | H9: =IFERROR((INDEX(HIST_D!$E$8:$E$2617,1)-INDEX(HIST_D!$E$8:$E$2617,Control!$F$11))*100,"") | I9: =IFERROR(PERCENTRANK(HIST_D!$E$8:INDEX(HIST_D!$E$8:$E$2617,Control!$F$11),INDEX(HIST_D!$E$8:$E$2617,1)),"") | J9: =IFERROR(PERCENTRANK(HIST_D!$E$8:INDEX(HIST_D!$E$8:$E$2617,Control!$F$14),INDEX(HIST_D!$E$8:$E$2617,1)),"")
A10: UST 10Y real | B10: bp | C10: =INDEX(HIST_D!$F$8:$F$2617,1) | D10: =IFERROR((INDEX(HIST_D!$F$8:$F$2617,1)-INDEX(HIST_D!$F$8:$F$2617,Control!$F$7))*100,"") | E10: =IFERROR((INDEX(HIST_D!$F$8:$F$2617,1)-INDEX(HIST_D!$F$8:$F$2617,Control!$F$8))*100,"") | F10: =IFERROR((INDEX(HIST_D!$F$8:$F$2617,1)-INDEX(HIST_D!$F$8:$F$2617,Control!$F$9))*100,"") | G10: =IFERROR((INDEX(HIST_D!$F$8:$F$2617,1)-INDEX(HIST_D!$F$8:$F$2617,Control!$F$16))*100,"") | H10: =IFERROR((INDEX(HIST_D!$F$8:$F$2617,1)-INDEX(HIST_D!$F$8:$F$2617,Control!$F$11))*100,"") | I10: =IFERROR(PERCENTRANK(HIST_D!$F$8:INDEX(HIST_D!$F$8:$F$2617,Control!$F$11),INDEX(HIST_D!$F$8:$F$2617,1)),"") | J10: =IFERROR(PERCENTRANK(HIST_D!$F$8:INDEX(HIST_D!$F$8:$F$2617,Control!$F$14),INDEX(HIST_D!$F$8:$F$2617,1)),"")
A11: ACM term premium 10Y | B11: bp | C11: =INDEX(HIST_D!$H$8:$H$2617,1) | D11: =IFERROR((INDEX(HIST_D!$H$8:$H$2617,1)-INDEX(HIST_D!$H$8:$H$2617,Control!$F$7))*100,"") | E11: =IFERROR((INDEX(HIST_D!$H$8:$H$2617,1)-INDEX(HIST_D!$H$8:$H$2617,Control!$F$8))*100,"") | F11: =IFERROR((INDEX(HIST_D!$H$8:$H$2617,1)-INDEX(HIST_D!$H$8:$H$2617,Control!$F$9))*100,"") | G11: =IFERROR((INDEX(HIST_D!$H$8:$H$2617,1)-INDEX(HIST_D!$H$8:$H$2617,Control!$F$16))*100,"") | H11: =IFERROR((INDEX(HIST_D!$H$8:$H$2617,1)-INDEX(HIST_D!$H$8:$H$2617,Control!$F$11))*100,"") | I11: =IFERROR(PERCENTRANK(HIST_D!$H$8:INDEX(HIST_D!$H$8:$H$2617,Control!$F$11),INDEX(HIST_D!$H$8:$H$2617,1)),"") | J11: =IFERROR(PERCENTRANK(HIST_D!$H$8:INDEX(HIST_D!$H$8:$H$2617,Control!$F$14),INDEX(HIST_D!$H$8:$H$2617,1)),"")
A12: DXY | B12: pt | C12: =INDEX(HIST_D!$J$8:$J$2617,1) | D12: =IFERROR(IFERROR(INDEX(HIST_D!$J$8:$J$2617,1)/INDEX(HIST_D!$J$8:$J$2617,Control!$F$7)-1,""),"") | E12: =IFERROR(IFERROR(INDEX(HIST_D!$J$8:$J$2617,1)/INDEX(HIST_D!$J$8:$J$2617,Control!$F$8)-1,""),"") | F12: =IFERROR(IFERROR(INDEX(HIST_D!$J$8:$J$2617,1)/INDEX(HIST_D!$J$8:$J$2617,Control!$F$9)-1,""),"") | G12: =IFERROR(IFERROR(INDEX(HIST_D!$J$8:$J$2617,1)/INDEX(HIST_D!$J$8:$J$2617,Control!$F$16)-1,""),"") | H12: =IFERROR(IFERROR(INDEX(HIST_D!$J$8:$J$2617,1)/INDEX(HIST_D!$J$8:$J$2617,Control!$F$11)-1,""),"") | I12: =IFERROR(PERCENTRANK(HIST_D!$J$8:INDEX(HIST_D!$J$8:$J$2617,Control!$F$11),INDEX(HIST_D!$J$8:$J$2617,1)),"") | J12: =IFERROR(PERCENTRANK(HIST_D!$J$8:INDEX(HIST_D!$J$8:$J$2617,Control!$F$14),INDEX(HIST_D!$J$8:$J$2617,1)),"")
A13: Brent | B13: px | C13: =INDEX(HIST_D!$N$8:$N$2617,1) | D13: =IFERROR(IFERROR(INDEX(HIST_D!$N$8:$N$2617,1)/INDEX(HIST_D!$N$8:$N$2617,Control!$F$7)-1,""),"") | E13: =IFERROR(IFERROR(INDEX(HIST_D!$N$8:$N$2617,1)/INDEX(HIST_D!$N$8:$N$2617,Control!$F$8)-1,""),"") | F13: =IFERROR(IFERROR(INDEX(HIST_D!$N$8:$N$2617,1)/INDEX(HIST_D!$N$8:$N$2617,Control!$F$9)-1,""),"") | G13: =IFERROR(IFERROR(INDEX(HIST_D!$N$8:$N$2617,1)/INDEX(HIST_D!$N$8:$N$2617,Control!$F$16)-1,""),"") | H13: =IFERROR(IFERROR(INDEX(HIST_D!$N$8:$N$2617,1)/INDEX(HIST_D!$N$8:$N$2617,Control!$F$11)-1,""),"") | I13: =IFERROR(PERCENTRANK(HIST_D!$N$8:INDEX(HIST_D!$N$8:$N$2617,Control!$F$11),INDEX(HIST_D!$N$8:$N$2617,1)),"") | J13: =IFERROR(PERCENTRANK(HIST_D!$N$8:INDEX(HIST_D!$N$8:$N$2617,Control!$F$14),INDEX(HIST_D!$N$8:$N$2617,1)),"")
A14: MOVE | B14: bp | C14: =INDEX(HIST_D!$K$8:$K$2617,1) | D14: =IFERROR((INDEX(HIST_D!$K$8:$K$2617,1)-INDEX(HIST_D!$K$8:$K$2617,Control!$F$7)),"") | E14: =IFERROR((INDEX(HIST_D!$K$8:$K$2617,1)-INDEX(HIST_D!$K$8:$K$2617,Control!$F$8)),"") | F14: =IFERROR((INDEX(HIST_D!$K$8:$K$2617,1)-INDEX(HIST_D!$K$8:$K$2617,Control!$F$9)),"") | G14: =IFERROR((INDEX(HIST_D!$K$8:$K$2617,1)-INDEX(HIST_D!$K$8:$K$2617,Control!$F$16)),"") | H14: =IFERROR((INDEX(HIST_D!$K$8:$K$2617,1)-INDEX(HIST_D!$K$8:$K$2617,Control!$F$11)),"") | I14: =IFERROR(PERCENTRANK(HIST_D!$K$8:INDEX(HIST_D!$K$8:$K$2617,Control!$F$11),INDEX(HIST_D!$K$8:$K$2617,1)),"") | J14: =IFERROR(PERCENTRANK(HIST_D!$K$8:INDEX(HIST_D!$K$8:$K$2617,Control!$F$14),INDEX(HIST_D!$K$8:$K$2617,1)),"")
A15: VIX | B15: pt | C15: =INDEX(HIST_D!$L$8:$L$2617,1) | D15: =IFERROR((INDEX(HIST_D!$L$8:$L$2617,1)-INDEX(HIST_D!$L$8:$L$2617,Control!$F$7)),"") | E15: =IFERROR((INDEX(HIST_D!$L$8:$L$2617,1)-INDEX(HIST_D!$L$8:$L$2617,Control!$F$8)),"") | F15: =IFERROR((INDEX(HIST_D!$L$8:$L$2617,1)-INDEX(HIST_D!$L$8:$L$2617,Control!$F$9)),"") | G15: =IFERROR((INDEX(HIST_D!$L$8:$L$2617,1)-INDEX(HIST_D!$L$8:$L$2617,Control!$F$16)),"") | H15: =IFERROR((INDEX(HIST_D!$L$8:$L$2617,1)-INDEX(HIST_D!$L$8:$L$2617,Control!$F$11)),"") | I15: =IFERROR(PERCENTRANK(HIST_D!$L$8:INDEX(HIST_D!$L$8:$L$2617,Control!$F$11),INDEX(HIST_D!$L$8:$L$2617,1)),"") | J15: =IFERROR(PERCENTRANK(HIST_D!$L$8:INDEX(HIST_D!$L$8:$L$2617,Control!$F$14),INDEX(HIST_D!$L$8:$L$2617,1)),"")
A17: THE EM RESPONSE — the three legs side by side
A18: Series | B18: Unit | C18: Level | D18: 1W | E18: 1M | F18: 3M | G18: YTD | H18: 1Y | I18: %ile 1y | J18: %ile 5y
A19: EM FX basket (return on EM ccy) | B19: % | D19: =FX!E51 | E19: =FX!F51 | F19: =FX!G51 | G19: =FX!I51 | H19: =FX!J51
A20: EM FX basket ex-USD | B20: % | D20: =FX!K51 | E20: =FX!L51 | F20: =FX!M51 | G20: =FX!M51 | H20: =FX!M51
A21: MSCI EM (USD) | B21: idx | C21: =INDEX(HIST_D!$AZ$8:$AZ$2617,1) | D21: =IFERROR(IFERROR(INDEX(HIST_D!$AZ$8:$AZ$2617,1)/INDEX(HIST_D!$AZ$8:$AZ$2617,Control!$F$7)-1,""),"") | E21: =IFERROR(IFERROR(INDEX(HIST_D!$AZ$8:$AZ$2617,1)/INDEX(HIST_D!$AZ$8:$AZ$2617,Control!$F$8)-1,""),"") | F21: =IFERROR(IFERROR(INDEX(HIST_D!$AZ$8:$AZ$2617,1)/INDEX(HIST_D!$AZ$8:$AZ$2617,Control!$F$9)-1,""),"") | G21: =IFERROR(IFERROR(INDEX(HIST_D!$AZ$8:$AZ$2617,1)/INDEX(HIST_D!$AZ$8:$AZ$2617,Control!$F$16)-1,""),"") | H21: =IFERROR(IFERROR(INDEX(HIST_D!$AZ$8:$AZ$2617,1)/INDEX(HIST_D!$AZ$8:$AZ$2617,Control!$F$11)-1,""),"") | I21: =IFERROR(PERCENTRANK(HIST_D!$AZ$8:INDEX(HIST_D!$AZ$8:$AZ$2617,Control!$F$11),INDEX(HIST_D!$AZ$8:$AZ$2617,1)),"") | J21: =IFERROR(PERCENTRANK(HIST_D!$AZ$8:INDEX(HIST_D!$AZ$8:$AZ$2617,Control!$F$14),INDEX(HIST_D!$AZ$8:$AZ$2617,1)),"")
A22: MSCI World (USD) | B22: idx | C22: =INDEX(HIST_D!$BA$8:$BA$2617,1) | D22: =IFERROR(IFERROR(INDEX(HIST_D!$BA$8:$BA$2617,1)/INDEX(HIST_D!$BA$8:$BA$2617,Control!$F$7)-1,""),"") | E22: =IFERROR(IFERROR(INDEX(HIST_D!$BA$8:$BA$2617,1)/INDEX(HIST_D!$BA$8:$BA$2617,Control!$F$8)-1,""),"") | F22: =IFERROR(IFERROR(INDEX(HIST_D!$BA$8:$BA$2617,1)/INDEX(HIST_D!$BA$8:$BA$2617,Control!$F$9)-1,""),"") | G22: =IFERROR(IFERROR(INDEX(HIST_D!$BA$8:$BA$2617,1)/INDEX(HIST_D!$BA$8:$BA$2617,Control!$F$16)-1,""),"") | H22: =IFERROR(IFERROR(INDEX(HIST_D!$BA$8:$BA$2617,1)/INDEX(HIST_D!$BA$8:$BA$2617,Control!$F$11)-1,""),"") | I22: =IFERROR(PERCENTRANK(HIST_D!$BA$8:INDEX(HIST_D!$BA$8:$BA$2617,Control!$F$11),INDEX(HIST_D!$BA$8:$BA$2617,1)),"") | J22: =IFERROR(PERCENTRANK(HIST_D!$BA$8:INDEX(HIST_D!$BA$8:$BA$2617,Control!$F$14),INDEX(HIST_D!$BA$8:$BA$2617,1)),"")
A23: EM USD Agg OAS | B23: bp | C23: =INDEX(HIST_D!$Q$8:$Q$2617,1) | D23: =IFERROR((INDEX(HIST_D!$Q$8:$Q$2617,1)-INDEX(HIST_D!$Q$8:$Q$2617,Control!$F$7)),"") | E23: =IFERROR((INDEX(HIST_D!$Q$8:$Q$2617,1)-INDEX(HIST_D!$Q$8:$Q$2617,Control!$F$8)),"") | F23: =IFERROR((INDEX(HIST_D!$Q$8:$Q$2617,1)-INDEX(HIST_D!$Q$8:$Q$2617,Control!$F$9)),"") | G23: =IFERROR((INDEX(HIST_D!$Q$8:$Q$2617,1)-INDEX(HIST_D!$Q$8:$Q$2617,Control!$F$16)),"") | H23: =IFERROR((INDEX(HIST_D!$Q$8:$Q$2617,1)-INDEX(HIST_D!$Q$8:$Q$2617,Control!$F$11)),"") | I23: =IFERROR(PERCENTRANK(HIST_D!$Q$8:INDEX(HIST_D!$Q$8:$Q$2617,Control!$F$11),INDEX(HIST_D!$Q$8:$Q$2617,1)),"") | J23: =IFERROR(PERCENTRANK(HIST_D!$Q$8:INDEX(HIST_D!$Q$8:$Q$2617,Control!$F$14),INDEX(HIST_D!$Q$8:$Q$2617,1)),"")
A24: EM USD Sovereign OAS | B24: bp | C24: =INDEX(HIST_D!$S$8:$S$2617,1) | D24: =IFERROR((INDEX(HIST_D!$S$8:$S$2617,1)-INDEX(HIST_D!$S$8:$S$2617,Control!$F$7)),"") | E24: =IFERROR((INDEX(HIST_D!$S$8:$S$2617,1)-INDEX(HIST_D!$S$8:$S$2617,Control!$F$8)),"") | F24: =IFERROR((INDEX(HIST_D!$S$8:$S$2617,1)-INDEX(HIST_D!$S$8:$S$2617,Control!$F$9)),"") | G24: =IFERROR((INDEX(HIST_D!$S$8:$S$2617,1)-INDEX(HIST_D!$S$8:$S$2617,Control!$F$16)),"") | H24: =IFERROR((INDEX(HIST_D!$S$8:$S$2617,1)-INDEX(HIST_D!$S$8:$S$2617,Control!$F$11)),"") | I24: =IFERROR(PERCENTRANK(HIST_D!$S$8:INDEX(HIST_D!$S$8:$S$2617,Control!$F$11),INDEX(HIST_D!$S$8:$S$2617,1)),"") | J24: =IFERROR(PERCENTRANK(HIST_D!$S$8:INDEX(HIST_D!$S$8:$S$2617,Control!$F$14),INDEX(HIST_D!$S$8:$S$2617,1)),"")
A25: US IG OAS | B25: bp | C25: =INDEX(HIST_D!$O$8:$O$2617,1) | D25: =IFERROR((INDEX(HIST_D!$O$8:$O$2617,1)-INDEX(HIST_D!$O$8:$O$2617,Control!$F$7)),"") | E25: =IFERROR((INDEX(HIST_D!$O$8:$O$2617,1)-INDEX(HIST_D!$O$8:$O$2617,Control!$F$8)),"") | F25: =IFERROR((INDEX(HIST_D!$O$8:$O$2617,1)-INDEX(HIST_D!$O$8:$O$2617,Control!$F$9)),"") | G25: =IFERROR((INDEX(HIST_D!$O$8:$O$2617,1)-INDEX(HIST_D!$O$8:$O$2617,Control!$F$16)),"") | H25: =IFERROR((INDEX(HIST_D!$O$8:$O$2617,1)-INDEX(HIST_D!$O$8:$O$2617,Control!$F$11)),"") | I25: =IFERROR(PERCENTRANK(HIST_D!$O$8:INDEX(HIST_D!$O$8:$O$2617,Control!$F$11),INDEX(HIST_D!$O$8:$O$2617,1)),"") | J25: =IFERROR(PERCENTRANK(HIST_D!$O$8:INDEX(HIST_D!$O$8:$O$2617,Control!$F$14),INDEX(HIST_D!$O$8:$O$2617,1)),"")
A26: US HY OAS | B26: bp | C26: =INDEX(HIST_D!$P$8:$P$2617,1) | D26: =IFERROR((INDEX(HIST_D!$P$8:$P$2617,1)-INDEX(HIST_D!$P$8:$P$2617,Control!$F$7)),"") | E26: =IFERROR((INDEX(HIST_D!$P$8:$P$2617,1)-INDEX(HIST_D!$P$8:$P$2617,Control!$F$8)),"") | F26: =IFERROR((INDEX(HIST_D!$P$8:$P$2617,1)-INDEX(HIST_D!$P$8:$P$2617,Control!$F$9)),"") | G26: =IFERROR((INDEX(HIST_D!$P$8:$P$2617,1)-INDEX(HIST_D!$P$8:$P$2617,Control!$F$16)),"") | H26: =IFERROR((INDEX(HIST_D!$P$8:$P$2617,1)-INDEX(HIST_D!$P$8:$P$2617,Control!$F$11)),"") | I26: =IFERROR(PERCENTRANK(HIST_D!$P$8:INDEX(HIST_D!$P$8:$P$2617,Control!$F$11),INDEX(HIST_D!$P$8:$P$2617,1)),"") | J26: =IFERROR(PERCENTRANK(HIST_D!$P$8:INDEX(HIST_D!$P$8:$P$2617,Control!$F$14),INDEX(HIST_D!$P$8:$P$2617,1)),"")
A27: EM local 10Y, eq-wgt | B27: bp | C27: =INDEX(HIST_D!$DW$8:$DW$2617,1) | D27: =IFERROR((INDEX(HIST_D!$DW$8:$DW$2617,1)-INDEX(HIST_D!$DW$8:$DW$2617,Control!$F$7))*100,"") | E27: =IFERROR((INDEX(HIST_D!$DW$8:$DW$2617,1)-INDEX(HIST_D!$DW$8:$DW$2617,Control!$F$8))*100,"") | F27: =IFERROR((INDEX(HIST_D!$DW$8:$DW$2617,1)-INDEX(HIST_D!$DW$8:$DW$2617,Control!$F$9))*100,"") | G27: =IFERROR((INDEX(HIST_D!$DW$8:$DW$2617,1)-INDEX(HIST_D!$DW$8:$DW$2617,Control!$F$16))*100,"") | H27: =IFERROR((INDEX(HIST_D!$DW$8:$DW$2617,1)-INDEX(HIST_D!$DW$8:$DW$2617,Control!$F$11))*100,"") | I27: =IFERROR(PERCENTRANK(HIST_D!$DW$8:INDEX(HIST_D!$DW$8:$DW$2617,Control!$F$11),INDEX(HIST_D!$DW$8:$DW$2617,1)),"") | J27: =IFERROR(PERCENTRANK(HIST_D!$DW$8:INDEX(HIST_D!$DW$8:$DW$2617,Control!$F$14),INDEX(HIST_D!$DW$8:$DW$2617,1)),"")
A28: EM local 10Y less UST 10Y | B28: bp | C28: =INDEX(HIST_D!$EA$8:$EA$2617,1) | D28: =IFERROR((INDEX(HIST_D!$EA$8:$EA$2617,1)-INDEX(HIST_D!$EA$8:$EA$2617,Control!$F$7)),"") | E28: =IFERROR((INDEX(HIST_D!$EA$8:$EA$2617,1)-INDEX(HIST_D!$EA$8:$EA$2617,Control!$F$8)),"") | F28: =IFERROR((INDEX(HIST_D!$EA$8:$EA$2617,1)-INDEX(HIST_D!$EA$8:$EA$2617,Control!$F$9)),"") | G28: =IFERROR((INDEX(HIST_D!$EA$8:$EA$2617,1)-INDEX(HIST_D!$EA$8:$EA$2617,Control!$F$16)),"") | H28: =IFERROR((INDEX(HIST_D!$EA$8:$EA$2617,1)-INDEX(HIST_D!$EA$8:$EA$2617,Control!$F$11)),"") | I28: =IFERROR(PERCENTRANK(HIST_D!$EA$8:INDEX(HIST_D!$EA$8:$EA$2617,Control!$F$11),INDEX(HIST_D!$EA$8:$EA$2617,1)),"") | J28: =IFERROR(PERCENTRANK(HIST_D!$EA$8:INDEX(HIST_D!$EA$8:$EA$2617,Control!$F$14),INDEX(HIST_D!$EA$8:$EA$2617,1)),"")
A30: BY REGION — the three legs side by side
A31: Region | B31: FX 1M | C31: FX YTD | D31: FX 1M ex-USD | E31: Equity USD 1M | F31: Equity USD YTD | G31: Equity vs World 1M | H31: Credit d spread 1M (bp) | I31: Credit TR 1M (%)
A32: LatAm | B32: =FX!$F$12 | C32: =FX!$I$12 | D32: =FX!$K$12 | E32: =Equities!$F$17 | F32: =Equities!$L$17 | G32: =Equities!$N$17 | H32: =IF(Credit!$E$39="","",Credit!$E$39) | I32: =IF(Credit!$F$39="","",Credit!$F$39)
A33: EM Europe | B33: =FX!$F$22 | C33: =FX!$I$22 | D33: =FX!$K$22 | E33: =Equities!$F$27 | F33: =Equities!$L$27 | G33: =Equities!$N$27 | H33: =IF(Credit!$E$40="","",Credit!$E$40) | I33: =IF(Credit!$F$40="","",Credit!$F$40)
A34: Middle East & Africa | B34: =FX!$F$33 | C34: =FX!$I$33 | D34: =FX!$K$33 | E34: =Equities!$F$38 | F34: =Equities!$L$38 | G34: =Equities!$N$38 | H34: =IF(Credit!$E$41="","",Credit!$E$41) | I34: =IF(Credit!$F$41="","",Credit!$F$41)
A35: Asia | B35: =FX!$F$46 | C35: =FX!$I$46 | D35: =FX!$K$46 | E35: =Equities!$F$52 | F35: =Equities!$L$52 | G35: =Equities!$N$52 | H35: =IF(Credit!$E$42="","",Credit!$E$42) | I35: =IF(Credit!$F$42="","",Credit!$F$42)
A37: Per-region read — generated, not typed
A38: =IFERROR("LatAm: FX "&TEXT($B32,"+0.0%;-0.0%")&" ("&TEXT($D32,"+0.0%;-0.0%")&" ex-dollar), equity "&TEXT($E32,"+0.0%;-0.0%")&" USD ("&TEXT($G32,"+0.0%;-0.0%")&" vs World), credit "&IF(ISNUMBER($H32),TEXT($H32,"+0;-0")&"bp","n/a")&". "&IF(AND($B32>=-0.005,$E32>=0),"Both market legs holding — the region is absorbing the US move rather than importing it.",IF(AND($B32<-0.005,$E32<0),"Both market legs are soft; this region is importing the US move and is where the digestion argument breaks first.",IF($B32<-0.005,"The currency is the weak leg while equity holds — an FX problem, not a growth or credit problem.","Equity is the weak leg while the currency holds — a sector or earnings story rather than a rates transmission story."))),"")
A39: =IFERROR("EM Europe: FX "&TEXT($B33,"+0.0%;-0.0%")&" ("&TEXT($D33,"+0.0%;-0.0%")&" ex-dollar), equity "&TEXT($E33,"+0.0%;-0.0%")&" USD ("&TEXT($G33,"+0.0%;-0.0%")&" vs World), credit "&IF(ISNUMBER($H33),TEXT($H33,"+0;-0")&"bp","n/a")&". "&IF(AND($B33>=-0.005,$E33>=0),"Both market legs holding — the region is absorbing the US move rather than importing it.",IF(AND($B33<-0.005,$E33<0),"Both market legs are soft; this region is importing the US move and is where the digestion argument breaks first.",IF($B33<-0.005,"The currency is the weak leg while equity holds — an FX problem, not a growth or credit problem.","Equity is the weak leg while the currency holds — a sector or earnings story rather than a rates transmission story."))),"")
A40: =IFERROR("Middle East & Africa: FX "&TEXT($B34,"+0.0%;-0.0%")&" ("&TEXT($D34,"+0.0%;-0.0%")&" ex-dollar), equity "&TEXT($E34,"+0.0%;-0.0%")&" USD ("&TEXT($G34,"+0.0%;-0.0%")&" vs World), credit "&IF(ISNUMBER($H34),TEXT($H34,"+0;-0")&"bp","n/a")&". "&IF(AND($B34>=-0.005,$E34>=0),"Both market legs holding — the region is absorbing the US move rather than importing it.",IF(AND($B34<-0.005,$E34<0),"Both market legs are soft; this region is importing the US move and is where the digestion argument breaks first.",IF($B34<-0.005,"The currency is the weak leg while equity holds — an FX problem, not a growth or credit problem.","Equity is the weak leg while the currency holds — a sector or earnings story rather than a rates transmission story."))),"")
A41: =IFERROR("Asia: FX "&TEXT($B35,"+0.0%;-0.0%")&" ("&TEXT($D35,"+0.0%;-0.0%")&" ex-dollar), equity "&TEXT($E35,"+0.0%;-0.0%")&" USD ("&TEXT($G35,"+0.0%;-0.0%")&" vs World), credit "&IF(ISNUMBER($H35),TEXT($H35,"+0;-0")&"bp","n/a")&". "&IF(AND($B35>=-0.005,$E35>=0),"Both market legs holding — the region is absorbing the US move rather than importing it.",IF(AND($B35<-0.005,$E35<0),"Both market legs are soft; this region is importing the US move and is where the digestion argument breaks first.",IF($B35<-0.005,"The currency is the weak leg while equity holds — an FX problem, not a growth or credit problem.","Equity is the weak leg while the currency holds — a sector or earnings story rather than a rates transmission story."))),"")
A44: DIGESTION — the three numbers the story rests on
A45: Measure | C45: 1M | D45: 3M | E45: 1Y | F45: 5Y
A46: Pass-through: EM local 10Y / UST 10Y | C46: =Passthrough!$G$48 | D46: =Passthrough!$H$48 | E46: =Passthrough!$J$48 | F46: =Passthrough!$K$48
...

Sheet FX
A1: EM FX — by region. Return on the currency, not the pair.
A2: Every pair is quoted EM per USD; the columns are the return ON the EM currency (prior/current - 1), so positive = EM strength. 'ex-USD' adds back the DXY move over the same window and isolates what is regional rather than dollar. Region baskets are equal-weighted across floating currencies only.
A4: LATAM
A5: Currency | B5: Peg | C5: Spot (EM/USD) | D5: 1D | E5: 1W | F5: 1M | G5: 3M | H5: 6M | I5: YTD | J5: 1Y | K5: 1M ex-USD | L5: 3M ex-USD | M5: YTD ex-USD | N5: %ile 1y (spot) | O5: %ile 5y (spot)
A6: Brazil BRL | B6: float | C6: =INDEX(HIST_D!$AA$8:$AA$2617,1) | D6: =IFERROR(INDEX(HIST_D!$AA$8:$AA$2617,Control!$F$6)/INDEX(HIST_D!$AA$8:$AA$2617,1)-1,"") | E6: =IFERROR(INDEX(HIST_D!$AA$8:$AA$2617,Control!$F$7)/INDEX(HIST_D!$AA$8:$AA$2617,1)-1,"") | F6: =IFERROR(INDEX(HIST_D!$AA$8:$AA$2617,Control!$F$8)/INDEX(HIST_D!$AA$8:$AA$2617,1)-1,"") | G6: =IFERROR(INDEX(HIST_D!$AA$8:$AA$2617,Control!$F$9)/INDEX(HIST_D!$AA$8:$AA$2617,1)-1,"") | H6: =IFERROR(INDEX(HIST_D!$AA$8:$AA$2617,Control!$F$10)/INDEX(HIST_D!$AA$8:$AA$2617,1)-1,"") | I6: =IFERROR(INDEX(HIST_D!$AA$8:$AA$2617,Control!$F$16)/INDEX(HIST_D!$AA$8:$AA$2617,1)-1,"") | J6: =IFERROR(INDEX(HIST_D!$AA$8:$AA$2617,Control!$F$11)/INDEX(HIST_D!$AA$8:$AA$2617,1)-1,"") | K6: =IFERROR(IFERROR(INDEX(HIST_D!$AA$8:$AA$2617,Control!$F$8)/INDEX(HIST_D!$AA$8:$AA$2617,1)-1,"")+IFERROR(INDEX(HIST_D!$J$8:$J$2617,1)/INDEX(HIST_D!$J$8:$J$2617,Control!$F$8)-1,""),"") | L6: =IFERROR(IFERROR(INDEX(HIST_D!$AA$8:$AA$2617,Control!$F$9)/INDEX(HIST_D!$AA$8:$AA$2617,1)-1,"")+IFERROR(INDEX(HIST_D!$J$8:$J$2617,1)/INDEX(HIST_D!$J$8:$J$2617,Control!$F$9)-1,""),"") | M6: =IFERROR(IFERROR(INDEX(HIST_D!$AA$8:$AA$2617,Control!$F$16)/INDEX(HIST_D!$AA$8:$AA$2617,1)-1,"")+IFERROR(INDEX(HIST_D!$J$8:$J$2617,1)/INDEX(HIST_D!$J$8:$J$2617,Control!$F$16)-1,""),"") | N6: =IFERROR(PERCENTRANK(HIST_D!$AA$8:INDEX(HIST_D!$AA$8:$AA$2617,Control!$F$11),INDEX(HIST_D!$AA$8:$AA$2617,1)),"") | O6: =IFERROR(PERCENTRANK(HIST_D!$AA$8:INDEX(HIST_D!$AA$8:$AA$2617,Control!$F$14),INDEX(HIST_D!$AA$8:$AA$2617,1)),"")
A7: Mexico MXN | B7: float | C7: =INDEX(HIST_D!$AB$8:$AB$2617,1) | D7: =IFERROR(INDEX(HIST_D!$AB$8:$AB$2617,Control!$F$6)/INDEX(HIST_D!$AB$8:$AB$2617,1)-1,"") | E7: =IFERROR(INDEX(HIST_D!$AB$8:$AB$2617,Control!$F$7)/INDEX(HIST_D!$AB$8:$AB$2617,1)-1,"") | F7: =IFERROR(INDEX(HIST_D!$AB$8:$AB$2617,Control!$F$8)/INDEX(HIST_D!$AB$8:$AB$2617,1)-1,"") | G7: =IFERROR(INDEX(HIST_D!$AB$8:$AB$2617,Control!$F$9)/INDEX(HIST_D!$AB$8:$AB$2617,1)-1,"") | H7: =IFERROR(INDEX(HIST_D!$AB$8:$AB$2617,Control!$F$10)/INDEX(HIST_D!$AB$8:$AB$2617,1)-1,"") | I7: =IFERROR(INDEX(HIST_D!$AB$8:$AB$2617,Control!$F$16)/INDEX(HIST_D!$AB$8:$AB$2617,1)-1,"") | J7: =IFERROR(INDEX(HIST_D!$AB$8:$AB$2617,Control!$F$11)/INDEX(HIST_D!$AB$8:$AB$2617,1)-1,"") | K7: =IFERROR(IFERROR(INDEX(HIST_D!$AB$8:$AB$2617,Control!$F$8)/INDEX(HIST_D!$AB$8:$AB$2617,1)-1,"")+IFERROR(INDEX(HIST_D!$J$8:$J$2617,1)/INDEX(HIST_D!$J$8:$J$2617,Control!$F$8)-1,""),"") | L7: =IFERROR(IFERROR(INDEX(HIST_D!$AB$8:$AB$2617,Control!$F$9)/INDEX(HIST_D!$AB$8:$AB$2617,1)-1,"")+IFERROR(INDEX(HIST_D!$J$8:$J$2617,1)/INDEX(HIST_D!$J$8:$J$2617,Control!$F$9)-1,""),"") | M7: =IFERROR(IFERROR(INDEX(HIST_D!$AB$8:$AB$2617,Control!$F$16)/INDEX(HIST_D!$AB$8:$AB$2617,1)-1,"")+IFERROR(INDEX(HIST_D!$J$8:$J$2617,1)/INDEX(HIST_D!$J$8:$J$2617,Control!$F$16)-1,""),"") | N7: =IFERROR(PERCENTRANK(HIST_D!$AB$8:INDEX(HIST_D!$AB$8:$AB$2617,Control!$F$11),INDEX(HIST_D!$AB$8:$AB$2617,1)),"") | O7: =IFERROR(PERCENTRANK(HIST_D!$AB$8:INDEX(HIST_D!$AB$8:$AB$2617,Control!$F$14),INDEX(HIST_D!$AB$8:$AB$2617,1)),"")
A8: Chile CLP | B8: float | C8: =INDEX(HIST_D!$AC$8:$AC$2617,1) | D8: =IFERROR(INDEX(HIST_D!$AC$8:$AC$2617,Control!$F$6)/INDEX(HIST_D!$AC$8:$AC$2617,1)-1,"") | E8: =IFERROR(INDEX(HIST_D!$AC$8:$AC$2617,Control!$F$7)/INDEX(HIST_D!$AC$8:$AC$2617,1)-1,"") | F8: =IFERROR(INDEX(HIST_D!$AC$8:$AC$2617,Control!$F$8)/INDEX(HIST_D!$AC$8:$AC$2617,1)-1,"") | G8: =IFERROR(INDEX(HIST_D!$AC$8:$AC$2617,Control!$F$9)/INDEX(HIST_D!$AC$8:$AC$2617,1)-1,"") | H8: =IFERROR(INDEX(HIST_D!$AC$8:$AC$2617,Control!$F$10)/INDEX(HIST_D!$AC$8:$AC$2617,1)-1,"") | I8: =IFERROR(INDEX(HIST_D!$AC$8:$AC$2617,Control!$F$16)/INDEX(HIST_D!$AC$8:$AC$2617,1)-1,"") | J8: =IFERROR(INDEX(HIST_D!$AC$8:$AC$2617,Control!$F$11)/INDEX(HIST_D!$AC$8:$AC$2617,1)-1,"") | K8: =IFERROR(IFERROR(INDEX(HIST_D!$AC$8:$AC$2617,Control!$F$8)/INDEX(HIST_D!$AC$8:$AC$2617,1)-1,"")+IFERROR(INDEX(HIST_D!$J$8:$J$2617,1)/INDEX(HIST_D!$J$8:$J$2617,Control!$F$8)-1,""),"") | L8: =IFERROR(IFERROR(INDEX(HIST_D!$AC$8:$AC$2617,Control!$F$9)/INDEX(HIST_D!$AC$8:$AC$2617,1)-1,"")+IFERROR(INDEX(HIST_D!$J$8:$J$2617,1)/INDEX(HIST_D!$J$8:$J$2617,Control!$F$9)-1,""),"") | M8: =IFERROR(IFERROR(INDEX(HIST_D!$AC$8:$AC$2617,Control!$F$16)/INDEX(HIST_D!$AC$8:$AC$2617,1)-1,"")+IFERROR(INDEX(HIST_D!$J$8:$J$2617,1)/INDEX(HIST_D!$J$8:$J$2617,Control!$F$16)-1,""),"") | N8: =IFERROR(PERCENTRANK(HIST_D!$AC$8:INDEX(HIST_D!$AC$8:$AC$2617,Control!$F$11),INDEX(HIST_D!$AC$8:$AC$2617,1)),"") | O8: =IFERROR(PERCENTRANK(HIST_D!$AC$8:INDEX(HIST_D!$AC$8:$AC$2617,Control!$F$14),INDEX(HIST_D!$AC$8:$AC$2617,1)),"")
A9: Colombia COP | B9: float | C9: =INDEX(HIST_D!$AD$8:$AD$2617,1) | D9: =IFERROR(INDEX(HIST_D!$AD$8:$AD$2617,Control!$F$6)/INDEX(HIST_D!$AD$8:$AD$2617,1)-1,"") | E9: =IFERROR(INDEX(HIST_D!$AD$8:$AD$2617,Control!$F$7)/INDEX(HIST_D!$AD$8:$AD$2617,1)-1,"") | F9: =IFERROR(INDEX(HIST_D!$AD$8:$AD$2617,Control!$F$8)/INDEX(HIST_D!$AD$8:$AD$2617,1)-1,"") | G9: =IFERROR(INDEX(HIST_D!$AD$8:$AD$2617,Control!$F$9)/INDEX(HIST_D!$AD$8:$AD$2617,1)-1,"") | H9: =IFERROR(INDEX(HIST_D!$AD$8:$AD$2617,Control!$F$10)/INDEX(HIST_D!$AD$8:$AD$2617,1)-1,"") | I9: =IFERROR(INDEX(HIST_D!$AD$8:$AD$2617,Control!$F$16)/INDEX(HIST_D!$AD$8:$AD$2617,1)-1,"") | J9: =IFERROR(INDEX(HIST_D!$AD$8:$AD$2617,Control!$F$11)/INDEX(HIST_D!$AD$8:$AD$2617,1)-1,"") | K9: =IFERROR(IFERROR(INDEX(HIST_D!$AD$8:$AD$2617,Control!$F$8)/INDEX(HIST_D!$AD$8:$AD$2617,1)-1,"")+IFERROR(INDEX(HIST_D!$J$8:$J$2617,1)/INDEX(HIST_D!$J$8:$J$2617,Control!$F$8)-1,""),"") | L9: =IFERROR(IFERROR(INDEX(HIST_D!$AD$8:$AD$2617,Control!$F$9)/INDEX(HIST_D!$AD$8:$AD$2617,1)-1,"")+IFERROR(INDEX(HIST_D!$J$8:$J$2617,1)/INDEX(HIST_D!$J$8:$J$2617,Control!$F$9)-1,""),"") | M9: =IFERROR(IFERROR(INDEX(HIST_D!$AD$8:$AD$2617,Control!$F$16)/INDEX(HIST_D!$AD$8:$AD$2617,1)-1,"")+IFERROR(INDEX(HIST_D!$J$8:$J$2617,1)/INDEX(HIST_D!$J$8:$J$2617,Control!$F$16)-1,""),"") | N9: =IFERROR(PERCENTRANK(HIST_D!$AD$8:INDEX(HIST_D!$AD$8:$AD$2617,Control!$F$11),INDEX(HIST_D!$AD$8:$AD$2617,1)),"") | O9: =IFERROR(PERCENTRANK(HIST_D!$AD$8:INDEX(HIST_D!$AD$8:$AD$2617,Control!$F$14),INDEX(HIST_D!$AD$8:$AD$2617,1)),"")
A10: Peru PEN | B10: float | C10: =INDEX(HIST_D!$AE$8:$AE$2617,1) | D10: =IFERROR(INDEX(HIST_D!$AE$8:$AE$2617,Control!$F$6)/INDEX(HIST_D!$AE$8:$AE$2617,1)-1,"") | E10: =IFERROR(INDEX(HIST_D!$AE$8:$AE$2617,Control!$F$7)/INDEX(HIST_D!$AE$8:$AE$2617,1)-1,"") | F10: =IFERROR(INDEX(HIST_D!$AE$8:$AE$2617,Control!$F$8)/INDEX(HIST_D!$AE$8:$AE$2617,1)-1,"") | G10: =IFERROR(INDEX(HIST_D!$AE$8:$AE$2617,Control!$F$9)/INDEX(HIST_D!$AE$8:$AE$2617,1)-1,"") | H10: =IFERROR(INDEX(HIST_D!$AE$8:$AE$2617,Control!$F$10)/INDEX(HIST_D!$AE$8:$AE$2617,1)-1,"") | I10: =IFERROR(INDEX(HIST_D!$AE$8:$AE$2617,Control!$F$16)/INDEX(HIST_D!$AE$8:$AE$2617,1)-1,"") | J10: =IFERROR(INDEX(HIST_D!$AE$8:$AE$2617,Control!$F$11)/INDEX(HIST_D!$AE$8:$AE$2617,1)-1,"") | K10: =IFERROR(IFERROR(INDEX(HIST_D!$AE$8:$AE$2617,Control!$F$8)/INDEX(HIST_D!$AE$8:$AE$2617,1)-1,"")+IFERROR(INDEX(HIST_D!$J$8:$J$2617,1)/INDEX(HIST_D!$J$8:$J$2617,Control!$F$8)-1,""),"") | L10: =IFERROR(IFERROR(INDEX(HIST_D!$AE$8:$AE$2617,Control!$F$9)/INDEX(HIST_D!$AE$8:$AE$2617,1)-1,"")+IFERROR(INDEX(HIST_D!$J$8:$J$2617,1)/INDEX(HIST_D!$J$8:$J$2617,Control!$F$9)-1,""),"") | M10: =IFERROR(IFERROR(INDEX(HIST_D!$AE$8:$AE$2617,Control!$F$16)/INDEX(HIST_D!$AE$8:$AE$2617,1)-1,"")+IFERROR(INDEX(HIST_D!$J$8:$J$2617,1)/INDEX(HIST_D!$J$8:$J$2617,Control!$F$16)-1,""),"") | N10: =IFERROR(PERCENTRANK(HIST_D!$AE$8:INDEX(HIST_D!$AE$8:$AE$2617,Control!$F$11),INDEX(HIST_D!$AE$8:$AE$2617,1)),"") | O10: =IFERROR(PERCENTRANK(HIST_D!$AE$8:INDEX(HIST_D!$AE$8:$AE$2617,Control!$F$14),INDEX(HIST_D!$AE$8:$AE$2617,1)),"")
A11: Argentina ARS | B11: float | C11: =INDEX(HIST_D!$AF$8:$AF$2617,1) | D11: =IFERROR(INDEX(HIST_D!$AF$8:$AF$2617,Control!$F$6)/INDEX(HIST_D!$AF$8:$AF$2617,1)-1,"") | E11: =IFERROR(INDEX(HIST_D!$AF$8:$AF$2617,Control!$F$7)/INDEX(HIST_D!$AF$8:$AF$2617,1)-1,"") | F11: =IFERROR(INDEX(HIST_D!$AF$8:$AF$2617,Control!$F$8)/INDEX(HIST_D!$AF$8:$AF$2617,1)-1,"") | G11: =IFERROR(INDEX(HIST_D!$AF$8:$AF$2617,Control!$F$9)/INDEX(HIST_D!$AF$8:$AF$2617,1)-1,"") | H11: =IFERROR(INDEX(HIST_D!$AF$8:$AF$2617,Control!$F$10)/INDEX(HIST_D!$AF$8:$AF$2617,1)-1,"") | I11: =IFERROR(INDEX(HIST_D!$AF$8:$AF$2617,Control!$F$16)/INDEX(HIST_D!$AF$8:$AF$2617,1)-1,"") | J11: =IFERROR(INDEX(HIST_D!$AF$8:$AF$2617,Control!$F$11)/INDEX(HIST_D!$AF$8:$AF$2617,1)-1,"") | K11: =IFERROR(IFERROR(INDEX(HIST_D!$AF$8:$AF$2617,Control!$F$8)/INDEX(HIST_D!$AF$8:$AF$2617,1)-1,"")+IFERROR(INDEX(HIST_D!$J$8:$J$2617,1)/INDEX(HIST_D!$J$8:$J$2617,Control!$F$8)-1,""),"") | L11: =IFERROR(IFERROR(INDEX(HIST_D!$AF$8:$AF$2617,Control!$F$9)/INDEX(HIST_D!$AF$8:$AF$2617,1)-1,"")+IFERROR(INDEX(HIST_D!$J$8:$J$2617,1)/INDEX(HIST_D!$J$8:$J$2617,Control!$F$9)-1,""),"") | M11: =IFERROR(IFERROR(INDEX(HIST_D!$AF$8:$AF$2617,Control!$F$16)/INDEX(HIST_D!$AF$8:$AF$2617,1)-1,"")+IFERROR(INDEX(HIST_D!$J$8:$J$2617,1)/INDEX(HIST_D!$J$8:$J$2617,Control!$F$16)-1,""),"") | N11: =IFERROR(PERCENTRANK(HIST_D!$AF$8:INDEX(HIST_D!$AF$8:$AF$2617,Control!$F$11),INDEX(HIST_D!$AF$8:$AF$2617,1)),"") | O11: =IFERROR(PERCENTRANK(HIST_D!$AF$8:INDEX(HIST_D!$AF$8:$AF$2617,Control!$F$14),INDEX(HIST_D!$AF$8:$AF$2617,1)),"")
A12: LatAm basket (floating, n=6) | D12: =IFERROR(AVERAGE(D6,D7,D8,D9,D10,D11),"") | E12: =IFERROR(AVERAGE(E6,E7,E8,E9,E10,E11),"") | F12: =IFERROR(AVERAGE(F6,F7,F8,F9,F10,F11),"") | G12: =IFERROR(AVERAGE(G6,G7,G8,G9,G10,G11),"") | H12: =IFERROR(AVERAGE(H6,H7,H8,H9,H10,H11),"") | I12: =IFERROR(AVERAGE(I6,I7,I8,I9,I10,I11),"") | J12: =IFERROR(AVERAGE(J6,J7,J8,J9,J10,J11),"") | K12: =IFERROR(AVERAGE(K6,K7,K8,K9,K10,K11),"") | ... O12: =IFERROR(AVERAGE(O6,O7,O8,O9,O10,O11),"")
A13: =IFERROR("LatAm: "&TEXT($F$12,"+0.0%;-0.0%")&" on the month, "&TEXT($I$12,"+0.0%;-0.0%")&" YTD, "&TEXT($K$12,"+0.0%;-0.0%")&" ex-dollar. "&IF($F$12>$F$51,"Ahead of","Behind")&" the EM basket at "&TEXT($F$51,"+0.0%;-0.0%")&". "&IF($K$12>0.005,"Regional support beyond the dollar.",IF($K$12<-0.005,"Lagging even after adjusting for the dollar.","Tracking the dollar; no regional signal.")),"")
A15: EM EUROPE
A16: Currency | B16: Peg | C16: Spot (EM/USD) | D16: 1D | E16: 1W | F16: 1M | G16: 3M | H16: 6M | I16: YTD | J16: 1Y | K16: 1M ex-USD | L16: 3M ex-USD | M16: YTD ex-USD | N16: %ile 1y (spot) | O16: %ile 5y (spot)
A17: Poland PLN | B17: float | C17: =INDEX(HIST_D!$AG$8:$AG$2617,1) | D17: =IFERROR(INDEX(HIST_D!$AG$8:$AG$2617,Control!$F$6)/INDEX(HIST_D!$AG$8:$AG$2617,1)-1,"") | E17: =IFERROR(INDEX(HIST_D!$AG$8:$AG$2617,Control!$F$7)/INDEX(HIST_D!$AG$8:$AG$2617,1)-1,"") | F17: =IFERROR(INDEX(HIST_D!$AG$8:$AG$2617,Control!$F$8)/INDEX(HIST_D!$AG$8:$AG$2617,1)-1,"") | G17: =IFERROR(INDEX(HIST_D!$AG$8:$AG$2617,Control!$F$9)/INDEX(HIST_D!$AG$8:$AG$2617,1)-1,"") | H17: =IFERROR(INDEX(HIST_D!$AG$8:$AG$2617,Control!$F$10)/INDEX(HIST_D!$AG$8:$AG$2617,1)-1,"") | I17: =IFERROR(INDEX(HIST_D!$AG$8:$AG$2617,Control!$F$16)/INDEX(HIST_D!$AG$8:$AG$2617,1)-1,"") | J17: =IFERROR(INDEX(HIST_D!$AG$8:$AG$2617,Control!$F$11)/INDEX(HIST_D!$AG$8:$AG$2617,1)-1,"") | K17: =IFERROR(IFERROR(INDEX(HIST_D!$AG$8:$AG$2617,Control!$F$8)/INDEX(HIST_D!$AG$8:$AG$2617,1)-1,"")+IFERROR(INDEX(HIST_D!$J$8:$J$2617,1)/INDEX(HIST_D!$J$8:$J$2617,Control!$F$8)-1,""),"") | L17: =IFERROR(IFERROR(INDEX(HIST_D!$AG$8:$AG$2617,Control!$F$9)/INDEX(HIST_D!$AG$8:$AG$2617,1)-1,"")+IFERROR(INDEX(HIST_D!$J$8:$J$2617,1)/INDEX(HIST_D!$J$8:$J$2617,Control!$F$9)-1,""),"") | M17: =IFERROR(IFERROR(INDEX(HIST_D!$AG$8:$AG$2617,Control!$F$16)/INDEX(HIST_D!$AG$8:$AG$2617,1)-1,"")+IFERROR(INDEX(HIST_D!$J$8:$J$2617,1)/INDEX(HIST_D!$J$8:$J$2617,Control!$F$16)-1,""),"") | N17: =IFERROR(PERCENTRANK(HIST_D!$AG$8:INDEX(HIST_D!$AG$8:$AG$2617,Control!$F$11),INDEX(HIST_D!$AG$8:$AG$2617,1)),"") | O17: =IFERROR(PERCENTRANK(HIST_D!$AG$8:INDEX(HIST_D!$AG$8:$AG$2617,Control!$F$14),INDEX(HIST_D!$AG$8:$AG$2617,1)),"")
A18: Hungary HUF | B18: float | C18: =INDEX(HIST_D!$AH$8:$AH$2617,1) | D18: =IFERROR(INDEX(HIST_D!$AH$8:$AH$2617,Control!$F$6)/INDEX(HIST_D!$AH$8:$AH$2617,1)-1,"") | E18: =IFERROR(INDEX(HIST_D!$AH$8:$AH$2617,Control!$F$7)/INDEX(HIST_D!$AH$8:$AH$2617,1)-1,"") | F18: =IFERROR(INDEX(HIST_D!$AH$8:$AH$2617,Control!$F$8)/INDEX(HIST_D!$AH$8:$AH$2617,1)-1,"") | G18: =IFERROR(INDEX(HIST_D!$AH$8:$AH$2617,Control!$F$9)/INDEX(HIST_D!$AH$8:$AH$2617,1)-1,"") | H18: =IFERROR(INDEX(HIST_D!$AH$8:$AH$2617,Control!$F$10)/INDEX(HIST_D!$AH$8:$AH$2617,1)-1,"") | I18: =IFERROR(INDEX(HIST_D!$AH$8:$AH$2617,Control!$F$16)/INDEX(HIST_D!$AH$8:$AH$2617,1)-1,"") | J18: =IFERROR(INDEX(HIST_D!$AH$8:$AH$2617,Control!$F$11)/INDEX(HIST_D!$AH$8:$AH$2617,1)-1,"") | K18: =IFERROR(IFERROR(INDEX(HIST_D!$AH$8:$AH$2617,Control!$F$8)/INDEX(HIST_D!$AH$8:$AH$2617,1)-1,"")+IFERROR(INDEX(HIST_D!$J$8:$J$2617,1)/INDEX(HIST_D!$J$8:$J$2617,Control!$F$8)-1,""),"") | L18: =IFERROR(IFERROR(INDEX(HIST_D!$AH$8:$AH$2617,Control!$F$9)/INDEX(HIST_D!$AH$8:$AH$2617,1)-1,"")+IFERROR(INDEX(HIST_D!$J$8:$J$2617,1)/INDEX(HIST_D!$J$8:$J$2617,Control!$F$9)-1,""),"") | M18: =IFERROR(IFERROR(INDEX(HIST_D!$AH$8:$AH$2617,Control!$F$16)/INDEX(HIST_D!$AH$8:$AH$2617,1)-1,"")+IFERROR(INDEX(HIST_D!$J$8:$J$2617,1)/INDEX(HIST_D!$J$8:$J$2617,Control!$F$16)-1,""),"") | N18: =IFERROR(PERCENTRANK(HIST_D!$AH$8:INDEX(HIST_D!$AH$8:$AH$2617,Control!$F$11),INDEX(HIST_D!$AH$8:$AH$2617,1)),"") | O18: =IFERROR(PERCENTRANK(HIST_D!$AH$8:INDEX(HIST_D!$AH$8:$AH$2617,Control!$F$14),INDEX(HIST_D!$AH$8:$AH$2617,1)),"")
A19: Czechia CZK | B19: float | C19: =INDEX(HIST_D!$AI$8:$AI$2617,1) | D19: =IFERROR(INDEX(HIST_D!$AI$8:$AI$2617,Control!$F$6)/INDEX(HIST_D!$AI$8:$AI$2617,1)-1,"") | E19: =IFERROR(INDEX(HIST_D!$AI$8:$AI$2617,Control!$F$7)/INDEX(HIST_D!$AI$8:$AI$2617,1)-1,"") | F19: =IFERROR(INDEX(HIST_D!$AI$8:$AI$2617,Control!$F$8)/INDEX(HIST_D!$AI$8:$AI$2617,1)-1,"") | G19: =IFERROR(INDEX(HIST_D!$AI$8:$AI$2617,Control!$F$9)/INDEX(HIST_D!$AI$8:$AI$2617,1)-1,"") | H19: =IFERROR(INDEX(HIST_D!$AI$8:$AI$2617,Control!$F$10)/INDEX(HIST_D!$AI$8:$AI$2617,1)-1,"") | I19: =IFERROR(INDEX(HIST_D!$AI$8:$AI$2617,Control!$F$16)/INDEX(HIST_D!$AI$8:$AI$2617,1)-1,"") | J19: =IFERROR(INDEX(HIST_D!$AI$8:$AI$2617,Control!$F$11)/INDEX(HIST_D!$AI$8:$AI$2617,1)-1,"") | K19: =IFERROR(IFERROR(INDEX(HIST_D!$AI$8:$AI$2617,Control!$F$8)/INDEX(HIST_D!$AI$8:$AI$2617,1)-1,"")+IFERROR(INDEX(HIST_D!$J$8:$J$2617,1)/INDEX(HIST_D!$J$8:$J$2617,Control!$F$8)-1,""),"") | L19: =IFERROR(IFERROR(INDEX(HIST_D!$AI$8:$AI$2617,Control!$F$9)/INDEX(HIST_D!$AI$8:$AI$2617,1)-1,"")+IFERROR(INDEX(HIST_D!$J$8:$J$2617,1)/INDEX(HIST_D!$J$8:$J$2617,Control!$F$9)-1,""),"") | M19: =IFERROR(IFERROR(INDEX(HIST_D!$AI$8:$AI$2617,Control!$F$16)/INDEX(HIST_D!$AI$8:$AI$2617,1)-1,"")+IFERROR(INDEX(HIST_D!$J$8:$J$2617,1)/INDEX(HIST_D!$J$8:$J$2617,Control!$F$16)-1,""),"") | N19: =IFERROR(PERCENTRANK(HIST_D!$AI$8:INDEX(HIST_D!$AI$8:$AI$2617,Control!$F$11),INDEX(HIST_D!$AI$8:$AI$2617,1)),"") | O19: =IFERROR(PERCENTRANK(HIST_D!$AI$8:INDEX(HIST_D!$AI$8:$AI$2617,Control!$F$14),INDEX(HIST_D!$AI$8:$AI$2617,1)),"")
A20: Romania RON | B20: float | C20: =INDEX(HIST_D!$AJ$8:$AJ$2617,1) | D20: =IFERROR(INDEX(HIST_D!$AJ$8:$AJ$2617,Control!$F$6)/INDEX(HIST_D!$AJ$8:$AJ$2617,1)-1,"") | E20: =IFERROR(INDEX(HIST_D!$AJ$8:$AJ$2617,Control!$F$7)/INDEX(HIST_D!$AJ$8:$AJ$2617,1)-1,"") | F20: =IFERROR(INDEX(HIST_D!$AJ$8:$AJ$2617,Control!$F$8)/INDEX(HIST_D!$AJ$8:$AJ$2617,1)-1,"") | G20: =IFERROR(INDEX(HIST_D!$AJ$8:$AJ$2617,Control!$F$9)/INDEX(HIST_D!$AJ$8:$AJ$2617,1)-1,"") | H20: =IFERROR(INDEX(HIST_D!$AJ$8:$AJ$2617,Control!$F$10)/INDEX(HIST_D!$AJ$8:$AJ$2617,1)-1,"") | I20: =IFERROR(INDEX(HIST_D!$AJ$8:$AJ$2617,Control!$F$16)/INDEX(HIST_D!$AJ$8:$AJ$2617,1)-1,"") | J20: =IFERROR(INDEX(HIST_D!$AJ$8:$AJ$2617,Control!$F$11)/INDEX(HIST_D!$AJ$8:$AJ$2617,1)-1,"") | K20: =IFERROR(IFERROR(INDEX(HIST_D!$AJ$8:$AJ$2617,Control!$F$8)/INDEX(HIST_D!$AJ$8:$AJ$2617,1)-1,"")+IFERROR(INDEX(HIST_D!$J$8:$J$2617,1)/INDEX(HIST_D!$J$8:$J$2617,Control!$F$8)-1,""),"") | L20: =IFERROR(IFERROR(INDEX(HIST_D!$AJ$8:$AJ$2617,Control!$F$9)/INDEX(HIST_D!$AJ$8:$AJ$2617,1)-1,"")+IFERROR(INDEX(HIST_D!$J$8:$J$2617,1)/INDEX(HIST_D!$J$8:$J$2617,Control!$F$9)-1,""),"") | M20: =IFERROR(IFERROR(INDEX(HIST_D!$AJ$8:$AJ$2617,Control!$F$16)/INDEX(HIST_D!$AJ$8:$AJ$2617,1)-1,"")+IFERROR(INDEX(HIST_D!$J$8:$J$2617,1)/INDEX(HIST_D!$J$8:$J$2617,Control!$F$16)-1,""),"") | N20: =IFERROR(PERCENTRANK(HIST_D!$AJ$8:INDEX(HIST_D!$AJ$8:$AJ$2617,Control!$F$11),INDEX(HIST_D!$AJ$8:$AJ$2617,1)),"") | O20: =IFERROR(PERCENTRANK(HIST_D!$AJ$8:INDEX(HIST_D!$AJ$8:$AJ$2617,Control!$F$14),INDEX(HIST_D!$AJ$8:$AJ$2617,1)),"")
A21: Turkiye TRY | B21: float | C21: =INDEX(HIST_D!$AK$8:$AK$2617,1) | D21: =IFERROR(INDEX(HIST_D!$AK$8:$AK$2617,Control!$F$6)/INDEX(HIST_D!$AK$8:$AK$2617,1)-1,"") | E21: =IFERROR(INDEX(HIST_D!$AK$8:$AK$2617,Control!$F$7)/INDEX(HIST_D!$AK$8:$AK$2617,1)-1,"") | F21: =IFERROR(INDEX(HIST_D!$AK$8:$AK$2617,Control!$F$8)/INDEX(HIST_D!$AK$8:$AK$2617,1)-1,"") | G21: =IFERROR(INDEX(HIST_D!$AK$8:$AK$2617,Control!$F$9)/INDEX(HIST_D!$AK$8:$AK$2617,1)-1,"") | H21: =IFERROR(INDEX(HIST_D!$AK$8:$AK$2617,Control!$F$10)/INDEX(HIST_D!$AK$8:$AK$2617,1)-1,"") | I21: =IFERROR(INDEX(HIST_D!$AK$8:$AK$2617,Control!$F$16)/INDEX(HIST_D!$AK$8:$AK$2617,1)-1,"") | J21: =IFERROR(INDEX(HIST_D!$AK$8:$AK$2617,Control!$F$11)/INDEX(HIST_D!$AK$8:$AK$2617,1)-1,"") | K21: =IFERROR(IFERROR(INDEX(HIST_D!$AK$8:$AK$2617,Control!$F$8)/INDEX(HIST_D!$AK$8:$AK$2617,1)-1,"")+IFERROR(INDEX(HIST_D!$J$8:$J$2617,1)/INDEX(HIST_D!$J$8:$J$2617,Control!$F$8)-1,""),"") | L21: =IFERROR(IFERROR(INDEX(HIST_D!$AK$8:$AK$2617,Control!$F$9)/INDEX(HIST_D!$AK$8:$AK$2617,1)-1,"")+IFERROR(INDEX(HIST_D!$J$8:$J$2617,1)/INDEX(HIST_D!$J$8:$J$2617,Control!$F$9)-1,""),"") | M21: =IFERROR(IFERROR(INDEX(HIST_D!$AK$8:$AK$2617,Control!$F$16)/INDEX(HIST_D!$AK$8:$AK$2617,1)-1,"")+IFERROR(INDEX(HIST_D!$J$8:$J$2617,1)/INDEX(HIST_D!$J$8:$J$2617,Control!$F$16)-1,""),"") | N21: =IFERROR(PERCENTRANK(HIST_D!$AK$8:INDEX(HIST_D!$AK$8:$AK$2617,Control!$F$11),INDEX(HIST_D!$AK$8:$AK$2617,1)),"") | O21: =IFERROR(PERCENTRANK(HIST_D!$AK$8:INDEX(HIST_D!$AK$8:$AK$2617,Control!$F$14),INDEX(HIST_D!$AK$8:$AK$2617,1)),"")
A22: EM Europe basket (floating, n=5) | D22: =IFERROR(AVERAGE(D17,D18,D19,D20,D21),"") | E22: =IFERROR(AVERAGE(E17,E18,E19,E20,E21),"") | F22: =IFERROR(AVERAGE(F17,F18,F19,F20,F21),"") | G22: =IFERROR(AVERAGE(G17,G18,G19,G20,G21),"") | H22: =IFERROR(AVERAGE(H17,H18,H19,H20,H21),"") | I22: =IFERROR(AVERAGE(I17,I18,I19,I20,I21),"") | J22: =IFERROR(AVERAGE(J17,J18,J19,J20,J21),"") | K22: =IFERROR(AVERAGE(K17,K18,K19,K20,K21),"") | ... O22: =IFERROR(AVERAGE(O17,O18,O19,O20,O21),"")
A23: =IFERROR("EM Europe: "&TEXT($F$22,"+0.0%;-0.0%")&" on the month, "&TEXT($I$22,"+0.0%;-0.0%")&" YTD, "&TEXT($K$22,"+0.0%;-0.0%")&" ex-dollar. "&IF($F$22>$F$51,"Ahead of","Behind")&" the EM basket at "&TEXT($F$51,"+0.0%;-0.0%")&". "&IF($K$22>0.005,"Regional support beyond the dollar.",IF($K$22<-0.005,"Lagging even after adjusting for the dollar.","Tracking the dollar; no regional signal.")),"")
A25: MIDDLE EAST & AFRICA
A26: Currency | B26: Peg | C26: Spot (EM/USD) | D26: 1D | E26: 1W | F26: 1M | G26: 3M | H26: 6M | I26: YTD | J26: 1Y | K26: 1M ex-USD | L26: 3M ex-USD | M26: YTD ex-USD | N26: %ile 1y (spot) | O26: %ile 5y (spot)
A27: Israel ILS | B27: float | C27: =INDEX(HIST_D!$AL$8:$AL$2617,1) | D27: =IFERROR(INDEX(HIST_D!$AL$8:$AL$2617,Control!$F$6)/INDEX(HIST_D!$AL$8:$AL$2617,1)-1,"") | E27: =IFERROR(INDEX(HIST_D!$AL$8:$AL$2617,Control!$F$7)/INDEX(HIST_D!$AL$8:$AL$2617,1)-1,"") | F27: =IFERROR(INDEX(HIST_D!$AL$8:$AL$2617,Control!$F$8)/INDEX(HIST_D!$AL$8:$AL$2617,1)-1,"") | G27: =IFERROR(INDEX(HIST_D!$AL$8:$AL$2617,Control!$F$9)/INDEX(HIST_D!$AL$8:$AL$2617,1)-1,"") | H27: =IFERROR(INDEX(HIST_D!$AL$8:$AL$2617,Control!$F$10)/INDEX(HIST_D!$AL$8:$AL$2617,1)-1,"") | I27: =IFERROR(INDEX(HIST_D!$AL$8:$AL$2617,Control!$F$16)/INDEX(HIST_D!$AL$8:$AL$2617,1)-1,"") | J27: =IFERROR(INDEX(HIST_D!$AL$8:$AL$2617,Control!$F$11)/INDEX(HIST_D!$AL$8:$AL$2617,1)-1,"") | K27: =IFERROR(IFERROR(INDEX(HIST_D!$AL$8:$AL$2617,Control!$F$8)/INDEX(HIST_D!$AL$8:$AL$2617,1)-1,"")+IFERROR(INDEX(HIST_D!$J$8:$J$2617,1)/INDEX(HIST_D!$J$8:$J$2617,Control!$F$8)-1,""),"") | L27: =IFERROR(IFERROR(INDEX(HIST_D!$AL$8:$AL$2617,Control!$F$9)/INDEX(HIST_D!$AL$8:$AL$2617,1)-1,"")+IFERROR(INDEX(HIST_D!$J$8:$J$2617,1)/INDEX(HIST_D!$J$8:$J$2617,Control!$F$9)-1,""),"") | M27: =IFERROR(IFERROR(INDEX(HIST_D!$AL$8:$AL$2617,Control!$F$16)/INDEX(HIST_D!$AL$8:$AL$2617,1)-1,"")+IFERROR(INDEX(HIST_D!$J$8:$J$2617,1)/INDEX(HIST_D!$J$8:$J$2617,Control!$F$16)-1,""),"") | N27: =IFERROR(PERCENTRANK(HIST_D!$AL$8:INDEX(HIST_D!$AL$8:$AL$2617,Control!$F$11),INDEX(HIST_D!$AL$8:$AL$2617,1)),"") | O27: =IFERROR(PERCENTRANK(HIST_D!$AL$8:INDEX(HIST_D!$AL$8:$AL$2617,Control!$F$14),INDEX(HIST_D!$AL$8:$AL$2617,1)),"")
A28: South Africa ZAR | B28: float | C28: =INDEX(HIST_D!$AM$8:$AM$2617,1) | D28: =IFERROR(INDEX(HIST_D!$AM$8:$AM$2617,Control!$F$6)/INDEX(HIST_D!$AM$8:$AM$2617,1)-1,"") | E28: =IFERROR(INDEX(HIST_D!$AM$8:$AM$2617,Control!$F$7)/INDEX(HIST_D!$AM$8:$AM$2617,1)-1,"") | F28: =IFERROR(INDEX(HIST_D!$AM$8:$AM$2617,Control!$F$8)/INDEX(HIST_D!$AM$8:$AM$2617,1)-1,"") | G28: =IFERROR(INDEX(HIST_D!$AM$8:$AM$2617,Control!$F$9)/INDEX(HIST_D!$AM$8:$AM$2617,1)-1,"") | H28: =IFERROR(INDEX(HIST_D!$AM$8:$AM$2617,Control!$F$10)/INDEX(HIST_D!$AM$8:$AM$2617,1)-1,"") | I28: =IFERROR(INDEX(HIST_D!$AM$8:$AM$2617,Control!$F$16)/INDEX(HIST_D!$AM$8:$AM$2617,1)-1,"") | J28: =IFERROR(INDEX(HIST_D!$AM$8:$AM$2617,Control!$F$11)/INDEX(HIST_D!$AM$8:$AM$2617,1)-1,"") | K28: =IFERROR(IFERROR(INDEX(HIST_D!$AM$8:$AM$2617,Control!$F$8)/INDEX(HIST_D!$AM$8:$AM$2617,1)-1,"")+IFERROR(INDEX(HIST_D!$J$8:$J$2617,1)/INDEX(HIST_D!$J$8:$J$2617,Control!$F$8)-1,""),"") | L28: =IFERROR(IFERROR(INDEX(HIST_D!$AM$8:$AM$2617,Control!$F$9)/INDEX(HIST_D!$AM$8:$AM$2617,1)-1,"")+IFERROR(INDEX(HIST_D!$J$8:$J$2617,1)/INDEX(HIST_D!$J$8:$J$2617,Control!$F$9)-1,""),"") | M28: =IFERROR(IFERROR(INDEX(HIST_D!$AM$8:$AM$2617,Control!$F$16)/INDEX(HIST_D!$AM$8:$AM$2617,1)-1,"")+IFERROR(INDEX(HIST_D!$J$8:$J$2617,1)/INDEX(HIST_D!$J$8:$J$2617,Control!$F$16)-1,""),"") | N28: =IFERROR(PERCENTRANK(HIST_D!$AM$8:INDEX(HIST_D!$AM$8:$AM$2617,Control!$F$11),INDEX(HIST_D!$AM$8:$AM$2617,1)),"") | O28: =IFERROR(PERCENTRANK(HIST_D!$AM$8:INDEX(HIST_D!$AM$8:$AM$2617,Control!$F$14),INDEX(HIST_D!$AM$8:$AM$2617,1)),"")
A29: Egypt EGP | B29: float | C29: =INDEX(HIST_D!$AN$8:$AN$2617,1) | D29: =IFERROR(INDEX(HIST_D!$AN$8:$AN$2617,Control!$F$6)/INDEX(HIST_D!$AN$8:$AN$2617,1)-1,"") | E29: =IFERROR(INDEX(HIST_D!$AN$8:$AN$2617,Control!$F$7)/INDEX(HIST_D!$AN$8:$AN$2617,1)-1,"") | F29: =IFERROR(INDEX(HIST_D!$AN$8:$AN$2617,Control!$F$8)/INDEX(HIST_D!$AN$8:$AN$2617,1)-1,"") | G29: =IFERROR(INDEX(HIST_D!$AN$8:$AN$2617,Control!$F$9)/INDEX(HIST_D!$AN$8:$AN$2617,1)-1,"") | H29: =IFERROR(INDEX(HIST_D!$AN$8:$AN$2617,Control!$F$10)/INDEX(HIST_D!$AN$8:$AN$2617,1)-1,"") | I29: =IFERROR(INDEX(HIST_D!$AN$8:$AN$2617,Control!$F$16)/INDEX(HIST_D!$AN$8:$AN$2617,1)-1,"") | J29: =IFERROR(INDEX(HIST_D!$AN$8:$AN$2617,Control!$F$11)/INDEX(HIST_D!$AN$8:$AN$2617,1)-1,"") | K29: =IFERROR(IFERROR(INDEX(HIST_D!$AN$8:$AN$2617,Control!$F$8)/INDEX(HIST_D!$AN$8:$AN$2617,1)-1,"")+IFERROR(INDEX(HIST_D!$J$8:$J$2617,1)/INDEX(HIST_D!$J$8:$J$2617,Control!$F$8)-1,""),"") | L29: =IFERROR(IFERROR(INDEX(HIST_D!$AN$8:$AN$2617,Control!$F$9)/INDEX(HIST_D!$AN$8:$AN$2617,1)-1,"")+IFERROR(INDEX(HIST_D!$J$8:$J$2617,1)/INDEX(HIST_D!$J$8:$J$2617,Control!$F$9)-1,""),"") | M29: =IFERROR(IFERROR(INDEX(HIST_D!$AN$8:$AN$2617,Control!$F$16)/INDEX(HIST_D!$AN$8:$AN$2617,1)-1,"")+IFERROR(INDEX(HIST_D!$J$8:$J$2617,1)/INDEX(HIST_D!$J$8:$J$2617,Control!$F$16)-1,""),"") | N29: =IFERROR(PERCENTRANK(HIST_D!$AN$8:INDEX(HIST_D!$AN$8:$AN$2617,Control!$F$11),INDEX(HIST_D!$AN$8:$AN$2617,1)),"") | O29: =IFERROR(PERCENTRANK(HIST_D!$AN$8:INDEX(HIST_D!$AN$8:$AN$2617,Control!$F$14),INDEX(HIST_D!$AN$8:$AN$2617,1)),"")
A30: Saudi SAR (pegged) | B30: peg | C30: =INDEX(HIST_D!$AO$8:$AO$2617,1) | D30: =IFERROR(INDEX(HIST_D!$AO$8:$AO$2617,Control!$F$6)/INDEX(HIST_D!$AO$8:$AO$2617,1)-1,"") | E30: =IFERROR(INDEX(HIST_D!$AO$8:$AO$2617,Control!$F$7)/INDEX(HIST_D!$AO$8:$AO$2617,1)-1,"") | F30: =IFERROR(INDEX(HIST_D!$AO$8:$AO$2617,Control!$F$8)/INDEX(HIST_D!$AO$8:$AO$2617,1)-1,"") | G30: =IFERROR(INDEX(HIST_D!$AO$8:$AO$2617,Control!$F$9)/INDEX(HIST_D!$AO$8:$AO$2617,1)-1,"") | H30: =IFERROR(INDEX(HIST_D!$AO$8:$AO$2617,Control!$F$10)/INDEX(HIST_D!$AO$8:$AO$2617,1)-1,"") | I30: =IFERROR(INDEX(HIST_D!$AO$8:$AO$2617,Control!$F$16)/INDEX(HIST_D!$AO$8:$AO$2617,1)-1,"") | J30: =IFERROR(INDEX(HIST_D!$AO$8:$AO$2617,Control!$F$11)/INDEX(HIST_D!$AO$8:$AO$2617,1)-1,"") | K30: =IFERROR(IFERROR(INDEX(HIST_D!$AO$8:$AO$2617,Control!$F$8)/INDEX(HIST_D!$AO$8:$AO$2617,1)-1,"")+IFERROR(INDEX(HIST_D!$J$8:$J$2617,1)/INDEX(HIST_D!$J$8:$J$2617,Control!$F$8)-1,""),"") | L30: =IFERROR(IFERROR(INDEX(HIST_D!$AO$8:$AO$2617,Control!$F$9)/INDEX(HIST_D!$AO$8:$AO$2617,1)-1,"")+IFERROR(INDEX(HIST_D!$J$8:$J$2617,1)/INDEX(HIST_D!$J$8:$J$2617,Control!$F$9)-1,""),"") | M30: =IFERROR(IFERROR(INDEX(HIST_D!$AO$8:$AO$2617,Control!$F$16)/INDEX(HIST_D!$AO$8:$AO$2617,1)-1,"")+IFERROR(INDEX(HIST_D!$J$8:$J$2617,1)/INDEX(HIST_D!$J$8:$J$2617,Control!$F$16)-1,""),"") | N30: =IFERROR(PERCENTRANK(HIST_D!$AO$8:INDEX(HIST_D!$AO$8:$AO$2617,Control!$F$11),INDEX(HIST_D!$AO$8:$AO$2617,1)),"") | O30: =IFERROR(PERCENTRANK(HIST_D!$AO$8:INDEX(HIST_D!$AO$8:$AO$2617,Control!$F$14),INDEX(HIST_D!$AO$8:$AO$2617,1)),"")
A31: UAE AED (pegged) | B31: peg | C31: =INDEX(HIST_D!$AP$8:$AP$2617,1) | D31: =IFERROR(INDEX(HIST_D!$AP$8:$AP$2617,Control!$F$6)/INDEX(HIST_D!$AP$8:$AP$2617,1)-1,"") | E31: =IFERROR(INDEX(HIST_D!$AP$8:$AP$2617,Control!$F$7)/INDEX(HIST_D!$AP$8:$AP$2617,1)-1,"") | F31: =IFERROR(INDEX(HIST_D!$AP$8:$AP$2617,Control!$F$8)/INDEX(HIST_D!$AP$8:$AP$2617,1)-1,"") | G31: =IFERROR(INDEX(HIST_D!$AP$8:$AP$2617,Control!$F$9)/INDEX(HIST_D!$AP$8:$AP$2617,1)-1,"") | H31: =IFERROR(INDEX(HIST_D!$AP$8:$AP$2617,Control!$F$10)/INDEX(HIST_D!$AP$8:$AP$2617,1)-1,"") | I31: =IFERROR(INDEX(HIST_D!$AP$8:$AP$2617,Control!$F$16)/INDEX(HIST_D!$AP$8:$AP$2617,1)-1,"") | J31: =IFERROR(INDEX(HIST_D!$AP$8:$AP$2617,Control!$F$11)/INDEX(HIST_D!$AP$8:$AP$2617,1)-1,"") | K31: =IFERROR(IFERROR(INDEX(HIST_D!$AP$8:$AP$2617,Control!$F$8)/INDEX(HIST_D!$AP$8:$AP$2617,1)-1,"")+IFERROR(INDEX(HIST_D!$J$8:$J$2617,1)/INDEX(HIST_D!$J$8:$J$2617,Control!$F$8)-1,""),"") | L31: =IFERROR(IFERROR(INDEX(HIST_D!$AP$8:$AP$2617,Control!$F$9)/INDEX(HIST_D!$AP$8:$AP$2617,1)-1,"")+IFERROR(INDEX(HIST_D!$J$8:$J$2617,1)/INDEX(HIST_D!$J$8:$J$2617,Control!$F$9)-1,""),"") | M31: =IFERROR(IFERROR(INDEX(HIST_D!$AP$8:$AP$2617,Control!$F$16)/INDEX(HIST_D!$AP$8:$AP$2617,1)-1,"")+IFERROR(INDEX(HIST_D!$J$8:$J$2617,1)/INDEX(HIST_D!$J$8:$J$2617,Control!$F$16)-1,""),"") | N31: =IFERROR(PERCENTRANK(HIST_D!$AP$8:INDEX(HIST_D!$AP$8:$AP$2617,Control!$F$11),INDEX(HIST_D!$AP$8:$AP$2617,1)),"") | O31: =IFERROR(PERCENTRANK(HIST_D!$AP$8:INDEX(HIST_D!$AP$8:$AP$2617,Control!$F$14),INDEX(HIST_D!$AP$8:$AP$2617,1)),"")
A32: Qatar QAR (pegged) | B32: peg | C32: =INDEX(HIST_D!$AQ$8:$AQ$2617,1) | D32: =IFERROR(INDEX(HIST_D!$AQ$8:$AQ$2617,Control!$F$6)/INDEX(HIST_D!$AQ$8:$AQ$2617,1)-1,"") | E32: =IFERROR(INDEX(HIST_D!$AQ$8:$AQ$2617,Control!$F$7)/INDEX(HIST_D!$AQ$8:$AQ$2617,1)-1,"") | F32: =IFERROR(INDEX(HIST_D!$AQ$8:$AQ$2617,Control!$F$8)/INDEX(HIST_D!$AQ$8:$AQ$2617,1)-1,"") | G32: =IFERROR(INDEX(HIST_D!$AQ$8:$AQ$2617,Control!$F$9)/INDEX(HIST_D!$AQ$8:$AQ$2617,1)-1,"") | H32: =IFERROR(INDEX(HIST_D!$AQ$8:$AQ$2617,Control!$F$10)/INDEX(HIST_D!$AQ$8:$AQ$2617,1)-1,"") | I32: =IFERROR(INDEX(HIST_D!$AQ$8:$AQ$2617,Control!$F$16)/INDEX(HIST_D!$AQ$8:$AQ$2617,1)-1,"") | J32: =IFERROR(INDEX(HIST_D!$AQ$8:$AQ$2617,Control!$F$11)/INDEX(HIST_D!$AQ$8:$AQ$2617,1)-1,"") | K32: =IFERROR(IFERROR(INDEX(HIST_D!$AQ$8:$AQ$2617,Control!$F$8)/INDEX(HIST_D!$AQ$8:$AQ$2617,1)-1,"")+IFERROR(INDEX(HIST_D!$J$8:$J$2617,1)/INDEX(HIST_D!$J$8:$J$2617,Control!$F$8)-1,""),"") | L32: =IFERROR(IFERROR(INDEX(HIST_D!$AQ$8:$AQ$2617,Control!$F$9)/INDEX(HIST_D!$AQ$8:$AQ$2617,1)-1,"")+IFERROR(INDEX(HIST_D!$J$8:$J$2617,1)/INDEX(HIST_D!$J$8:$J$2617,Control!$F$9)-1,""),"") | M32: =IFERROR(IFERROR(INDEX(HIST_D!$AQ$8:$AQ$2617,Control!$F$16)/INDEX(HIST_D!$AQ$8:$AQ$2617,1)-1,"")+IFERROR(INDEX(HIST_D!$J$8:$J$2617,1)/INDEX(HIST_D!$J$8:$J$2617,Control!$F$16)-1,""),"") | N32: =IFERROR(PERCENTRANK(HIST_D!$AQ$8:INDEX(HIST_D!$AQ$8:$AQ$2617,Control!$F$11),INDEX(HIST_D!$AQ$8:$AQ$2617,1)),"") | O32: =IFERROR(PERCENTRANK(HIST_D!$AQ$8:INDEX(HIST_D!$AQ$8:$AQ$2617,Control!$F$14),INDEX(HIST_D!$AQ$8:$AQ$2617,1)),"")
A33: Middle East & Africa basket (floating, n=3) | D33: =IFERROR(AVERAGE(D27,D28,D29),"") | E33: =IFERROR(AVERAGE(E27,E28,E29),"") | F33: =IFERROR(AVERAGE(F27,F28,F29),"") | G33: =IFERROR(AVERAGE(G27,G28,G29),"") | H33: =IFERROR(AVERAGE(H27,H28,H29),"") | I33: =IFERROR(AVERAGE(I27,I28,I29),"") | J33: =IFERROR(AVERAGE(J27,J28,J29),"") | K33: =IFERROR(AVERAGE(K27,K28,K29),"") | ... O33: =IFERROR(AVERAGE(O27,O28,O29),"")
A34: =IFERROR("Middle East & Africa: "&TEXT($F$33,"+0.0%;-0.0%")&" on the month, "&TEXT($I$33,"+0.0%;-0.0%")&" YTD, "&TEXT($K$33,"+0.0%;-0.0%")&" ex-dollar. "&IF($F$33>$F$51,"Ahead of","Behind")&" the EM basket at "&TEXT($F$51,"+0.0%;-0.0%")&". "&IF($K$33>0.005,"Regional support beyond the dollar.",IF($K$33<-0.005,"Lagging even after adjusting for the dollar.","Tracking the dollar; no regional signal.")),"")
A36: ASIA
A37: Currency | B37: Peg | C37: Spot (EM/USD) | D37: 1D | E37: 1W | F37: 1M | G37: 3M | H37: 6M | I37: YTD | J37: 1Y | K37: 1M ex-USD | L37: 3M ex-USD | M37: YTD ex-USD | N37: %ile 1y (spot) | O37: %ile 5y (spot)
A38: China CNH | B38: float | C38: =INDEX(HIST_D!$AR$8:$AR$2617,1) | D38: =IFERROR(INDEX(HIST_D!$AR$8:$AR$2617,Control!$F$6)/INDEX(HIST_D!$AR$8:$AR$2617,1)-1,"") | E38: =IFERROR(INDEX(HIST_D!$AR$8:$AR$2617,Control!$F$7)/INDEX(HIST_D!$AR$8:$AR$2617,1)-1,"") | F38: =IFERROR(INDEX(HIST_D!$AR$8:$AR$2617,Control!$F$8)/INDEX(HIST_D!$AR$8:$AR$2617,1)-1,"") | G38: =IFERROR(INDEX(HIST_D!$AR$8:$AR$2617,Control!$F$9)/INDEX(HIST_D!$AR$8:$AR$2617,1)-1,"") | H38: =IFERROR(INDEX(HIST_D!$AR$8:$AR$2617,Control!$F$10)/INDEX(HIST_D!$AR$8:$AR$2617,1)-1,"") | I38: =IFERROR(INDEX(HIST_D!$AR$8:$AR$2617,Control!$F$16)/INDEX(HIST_D!$AR$8:$AR$2617,1)-1,"") | J38: =IFERROR(INDEX(HIST_D!$AR$8:$AR$2617,Control!$F$11)/INDEX(HIST_D!$AR$8:$AR$2617,1)-1,"") | K38: =IFERROR(IFERROR(INDEX(HIST_D!$AR$8:$AR$2617,Control!$F$8)/INDEX(HIST_D!$AR$8:$AR$2617,1)-1,"")+IFERROR(INDEX(HIST_D!$J$8:$J$2617,1)/INDEX(HIST_D!$J$8:$J$2617,Control!$F$8)-1,""),"") | L38: =IFERROR(IFERROR(INDEX(HIST_D!$AR$8:$AR$2617,Control!$F$9)/INDEX(HIST_D!$AR$8:$AR$2617,1)-1,"")+IFERROR(INDEX(HIST_D!$J$8:$J$2617,1)/INDEX(HIST_D!$J$8:$J$2617,Control!$F$9)-1,""),"") | M38: =IFERROR(IFERROR(INDEX(HIST_D!$AR$8:$AR$2617,Control!$F$16)/INDEX(HIST_D!$AR$8:$AR$2617,1)-1,"")+IFERROR(INDEX(HIST_D!$J$8:$J$2617,1)/INDEX(HIST_D!$J$8:$J$2617,Control!$F$16)-1,""),"") | N38: =IFERROR(PERCENTRANK(HIST_D!$AR$8:INDEX(HIST_D!$AR$8:$AR$2617,Control!$F$11),INDEX(HIST_D!$AR$8:$AR$2617,1)),"") | O38: =IFERROR(PERCENTRANK(HIST_D!$AR$8:INDEX(HIST_D!$AR$8:$AR$2617,Control!$F$14),INDEX(HIST_D!$AR$8:$AR$2617,1)),"")
A39: India INR | B39: float | C39: =INDEX(HIST_D!$AS$8:$AS$2617,1) | D39: =IFERROR(INDEX(HIST_D!$AS$8:$AS$2617,Control!$F$6)/INDEX(HIST_D!$AS$8:$AS$2617,1)-1,"") | E39: =IFERROR(INDEX(HIST_D!$AS$8:$AS$2617,Control!$F$7)/INDEX(HIST_D!$AS$8:$AS$2617,1)-1,"") | F39: =IFERROR(INDEX(HIST_D!$AS$8:$AS$2617,Control!$F$8)/INDEX(HIST_D!$AS$8:$AS$2617,1)-1,"") | G39: =IFERROR(INDEX(HIST_D!$AS$8:$AS$2617,Control!$F$9)/INDEX(HIST_D!$AS$8:$AS$2617,1)-1,"") | H39: =IFERROR(INDEX(HIST_D!$AS$8:$AS$2617,Control!$F$10)/INDEX(HIST_D!$AS$8:$AS$2617,1)-1,"") | I39: =IFERROR(INDEX(HIST_D!$AS$8:$AS$2617,Control!$F$16)/INDEX(HIST_D!$AS$8:$AS$2617,1)-1,"") | J39: =IFERROR(INDEX(HIST_D!$AS$8:$AS$2617,Control!$F$11)/INDEX(HIST_D!$AS$8:$AS$2617,1)-1,"") | K39: =IFERROR(IFERROR(INDEX(HIST_D!$AS$8:$AS$2617,Control!$F$8)/INDEX(HIST_D!$AS$8:$AS$2617,1)-1,"")+IFERROR(INDEX(HIST_D!$J$8:$J$2617,1)/INDEX(HIST_D!$J$8:$J$2617,Control!$F$8)-1,""),"") | L39: =IFERROR(IFERROR(INDEX(HIST_D!$AS$8:$AS$2617,Control!$F$9)/INDEX(HIST_D!$AS$8:$AS$2617,1)-1,"")+IFERROR(INDEX(HIST_D!$J$8:$J$2617,1)/INDEX(HIST_D!$J$8:$J$2617,Control!$F$9)-1,""),"") | M39: =IFERROR(IFERROR(INDEX(HIST_D!$AS$8:$AS$2617,Control!$F$16)/INDEX(HIST_D!$AS$8:$AS$2617,1)-1,"")+IFERROR(INDEX(HIST_D!$J$8:$J$2617,1)/INDEX(HIST_D!$J$8:$J$2617,Control!$F$16)-1,""),"") | N39: =IFERROR(PERCENTRANK(HIST_D!$AS$8:INDEX(HIST_D!$AS$8:$AS$2617,Control!$F$11),INDEX(HIST_D!$AS$8:$AS$2617,1)),"") | O39: =IFERROR(PERCENTRANK(HIST_D!$AS$8:INDEX(HIST_D!$AS$8:$AS$2617,Control!$F$14),INDEX(HIST_D!$AS$8:$AS$2617,1)),"")
A40: Indonesia IDR | B40: float | C40: =INDEX(HIST_D!$AT$8:$AT$2617,1) | D40: =IFERROR(INDEX(HIST_D!$AT$8:$AT$2617,Control!$F$6)/INDEX(HIST_D!$AT$8:$AT$2617,1)-1,"") | E40: =IFERROR(INDEX(HIST_D!$AT$8:$AT$2617,Control!$F$7)/INDEX(HIST_D!$AT$8:$AT$2617,1)-1,"") | F40: =IFERROR(INDEX(HIST_D!$AT$8:$AT$2617,Control!$F$8)/INDEX(HIST_D!$AT$8:$AT$2617,1)-1,"") | G40: =IFERROR(INDEX(HIST_D!$AT$8:$AT$2617,Control!$F$9)/INDEX(HIST_D!$AT$8:$AT$2617,1)-1,"") | H40: =IFERROR(INDEX(HIST_D!$AT$8:$AT$2617,Control!$F$10)/INDEX(HIST_D!$AT$8:$AT$2617,1)-1,"") | I40: =IFERROR(INDEX(HIST_D!$AT$8:$AT$2617,Control!$F$16)/INDEX(HIST_D!$AT$8:$AT$2617,1)-1,"") | J40: =IFERROR(INDEX(HIST_D!$AT$8:$AT$2617,Control!$F$11)/INDEX(HIST_D!$AT$8:$AT$2617,1)-1,"") | K40: =IFERROR(IFERROR(INDEX(HIST_D!$AT$8:$AT$2617,Control!$F$8)/INDEX(HIST_D!$AT$8:$AT$2617,1)-1,"")+IFERROR(INDEX(HIST_D!$J$8:$J$2617,1)/INDEX(HIST_D!$J$8:$J$2617,Control!$F$8)-1,""),"") | L40: =IFERROR(IFERROR(INDEX(HIST_D!$AT$8:$AT$2617,Control!$F$9)/INDEX(HIST_D!$AT$8:$AT$2617,1)-1,"")+IFERROR(INDEX(HIST_D!$J$8:$J$2617,1)/INDEX(HIST_D!$J$8:$J$2617,Control!$F$9)-1,""),"") | M40: =IFERROR(IFERROR(INDEX(HIST_D!$AT$8:$AT$2617,Control!$F$16)/INDEX(HIST_D!$AT$8:$AT$2617,1)-1,"")+IFERROR(INDEX(HIST_D!$J$8:$J$2617,1)/INDEX(HIST_D!$J$8:$J$2617,Control!$F$16)-1,""),"") | N40: =IFERROR(PERCENTRANK(HIST_D!$AT$8:INDEX(HIST_D!$AT$8:$AT$2617,Control!$F$11),INDEX(HIST_D!$AT$8:$AT$2617,1)),"") | O40: =IFERROR(PERCENTRANK(HIST_D!$AT$8:INDEX(HIST_D!$AT$8:$AT$2617,Control!$F$14),INDEX(HIST_D!$AT$8:$AT$2617,1)),"")
A41: Korea KRW | B41: float | C41: =INDEX(HIST_D!$AU$8:$AU$2617,1) | D41: =IFERROR(INDEX(HIST_D!$AU$8:$AU$2617,Control!$F$6)/INDEX(HIST_D!$AU$8:$AU$2617,1)-1,"") | E41: =IFERROR(INDEX(HIST_D!$AU$8:$AU$2617,Control!$F$7)/INDEX(HIST_D!$AU$8:$AU$2617,1)-1,"") | F41: =IFERROR(INDEX(HIST_D!$AU$8:$AU$2617,Control!$F$8)/INDEX(HIST_D!$AU$8:$AU$2617,1)-1,"") | G41: =IFERROR(INDEX(HIST_D!$AU$8:$AU$2617,Control!$F$9)/INDEX(HIST_D!$AU$8:$AU$2617,1)-1,"") | H41: =IFERROR(INDEX(HIST_D!$AU$8:$AU$2617,Control!$F$10)/INDEX(HIST_D!$AU$8:$AU$2617,1)-1,"") | I41: =IFERROR(INDEX(HIST_D!$AU$8:$AU$2617,Control!$F$16)/INDEX(HIST_D!$AU$8:$AU$2617,1)-1,"") | J41: =IFERROR(INDEX(HIST_D!$AU$8:$AU$2617,Control!$F$11)/INDEX(HIST_D!$AU$8:$AU$2617,1)-1,"") | K41: =IFERROR(IFERROR(INDEX(HIST_D!$AU$8:$AU$2617,Control!$F$8)/INDEX(HIST_D!$AU$8:$AU$2617,1)-1,"")+IFERROR(INDEX(HIST_D!$J$8:$J$2617,1)/INDEX(HIST_D!$J$8:$J$2617,Control!$F$8)-1,""),"") | L41: =IFERROR(IFERROR(INDEX(HIST_D!$AU$8:$AU$2617,Control!$F$9)/INDEX(HIST_D!$AU$8:$AU$2617,1)-1,"")+IFERROR(INDEX(HIST_D!$J$8:$J$2617,1)/INDEX(HIST_D!$J$8:$J$2617,Control!$F$9)-1,""),"") | M41: =IFERROR(IFERROR(INDEX(HIST_D!$AU$8:$AU$2617,Control!$F$16)/INDEX(HIST_D!$AU$8:$AU$2617,1)-1,"")+IFERROR(INDEX(HIST_D!$J$8:$J$2617,1)/INDEX(HIST_D!$J$8:$J$2617,Control!$F$16)-1,""),"") | N41: =IFERROR(PERCENTRANK(HIST_D!$AU$8:INDEX(HIST_D!$AU$8:$AU$2617,Control!$F$11),INDEX(HIST_D!$AU$8:$AU$2617,1)),"") | O41: =IFERROR(PERCENTRANK(HIST_D!$AU$8:INDEX(HIST_D!$AU$8:$AU$2617,Control!$F$14),INDEX(HIST_D!$AU$8:$AU$2617,1)),"")
A42: Taiwan TWD | B42: float | C42: =INDEX(HIST_D!$AV$8:$AV$2617,1) | D42: =IFERROR(INDEX(HIST_D!$AV$8:$AV$2617,Control!$F$6)/INDEX(HIST_D!$AV$8:$AV$2617,1)-1,"") | E42: =IFERROR(INDEX(HIST_D!$AV$8:$AV$2617,Control!$F$7)/INDEX(HIST_D!$AV$8:$AV$2617,1)-1,"") | F42: =IFERROR(INDEX(HIST_D!$AV$8:$AV$2617,Control!$F$8)/INDEX(HIST_D!$AV$8:$AV$2617,1)-1,"") | G42: =IFERROR(INDEX(HIST_D!$AV$8:$AV$2617,Control!$F$9)/INDEX(HIST_D!$AV$8:$AV$2617,1)-1,"") | H42: =IFERROR(INDEX(HIST_D!$AV$8:$AV$2617,Control!$F$10)/INDEX(HIST_D!$AV$8:$AV$2617,1)-1,"") | I42: =IFERROR(INDEX(HIST_D!$AV$8:$AV$2617,Control!$F$16)/INDEX(HIST_D!$AV$8:$AV$2617,1)-1,"") | J42: =IFERROR(INDEX(HIST_D!$AV$8:$AV$2617,Control!$F$11)/INDEX(HIST_D!$AV$8:$AV$2617,1)-1,"") | K42: =IFERROR(IFERROR(INDEX(HIST_D!$AV$8:$AV$2617,Control!$F$8)/INDEX(HIST_D!$AV$8:$AV$2617,1)-1,"")+IFERROR(INDEX(HIST_D!$J$8:$J$2617,1)/INDEX(HIST_D!$J$8:$J$2617,Control!$F$8)-1,""),"") | L42: =IFERROR(IFERROR(INDEX(HIST_D!$AV$8:$AV$2617,Control!$F$9)/INDEX(HIST_D!$AV$8:$AV$2617,1)-1,"")+IFERROR(INDEX(HIST_D!$J$8:$J$2617,1)/INDEX(HIST_D!$J$8:$J$2617,Control!$F$9)-1,""),"") | M42: =IFERROR(IFERROR(INDEX(HIST_D!$AV$8:$AV$2617,Control!$F$16)/INDEX(HIST_D!$AV$8:$AV$2617,1)-1,"")+IFERROR(INDEX(HIST_D!$J$8:$J$2617,1)/INDEX(HIST_D!$J$8:$J$2617,Control!$F$16)-1,""),"") | N42: =IFERROR(PERCENTRANK(HIST_D!$AV$8:INDEX(HIST_D!$AV$8:$AV$2617,Control!$F$11),INDEX(HIST_D!$AV$8:$AV$2617,1)),"") | O42: =IFERROR(PERCENTRANK(HIST_D!$AV$8:INDEX(HIST_D!$AV$8:$AV$2617,Control!$F$14),INDEX(HIST_D!$AV$8:$AV$2617,1)),"")
