Workbook

Sheet Control
A1: EM DECOMPOSITION — US factor vs intrinsic EM
A2: Bloomberg-linked; every cell is a formula. Built for A. Rojas, UBS CIO Americas.
A4: SETTINGS
A6: History start | B6: =EDATE(TODAY(),-38) | D6: 3y buffer so the 2y beta window is always full
A7: History end | B7: =TODAY()
A8: Daily observations pulled | B8: 784 | D8: HIST_D rows 8:791, newest first
A9: bp per 1% | B9: 100
A10: 1M window (weekday obs back) | B10: 23 | D10: row offset in HIST_D; 23 = one calendar month
A11: YTD window (weekday obs back) | B11: =NETWORKDAYS(DATE(YEAR(TODAY())-1,12,31),TODAY()) | D11: row offset to the prior year-end
A12: Beta window (weekday obs) | B12: 523 | D12: 2y of daily changes for every measured beta
A13: Minimum US move to form a ratio (bp) | B13: 15 | D13: pass-through is suppressed as n/m below this
A14: EM USD index modified duration (yrs) | B14: 6.6 | D14: INPUT — embi_tracker.py or Bbg DUR_ADJ_MID
A15: EM USD index YTW (%) | B15: 6.55 | D15: INPUT — embi_tracker.py or INDEX_YIELD_TO_WORST
A16: EMBIGD stripped spread now (bp) | B16: 208 | D16: INPUT — embi_tracker.py 'Dur Wgt STW (Trsy)'
A17: EMBIGD stripped spread 1M ago (bp) | B17: 218 | D17: INPUT — chain-link across the 04-Sep-26 JPM break
A18: EMBIGD stripped spread at prior year-end (bp) | D18: INPUT — from EMBI_global_history.xlsx
A21: THE ONE IDEA, APPLIED THREE TIMES
A22: total move = US-driven + intrinsic EM. Same split on every tab.
A23: Local rates: d(local 10Y) = d(UST 10Y) + d(local less UST). US-driven is the UST move; intrinsic is the change in the gap.
A24: FX: return on the EM currency = -(DXY return) + return ex-dollar. US-driven is the dollar; intrinsic is what is left after the dollar.
A25: USD credit: d(UST 5Y + CDS 5Y) = d(UST 5Y) + d(CDS 5Y). US-driven is Treasuries; intrinsic is the spread. This is exact.
A26: The identity assumes a beta of one. Next to it, a measured 2y beta gives the move history would have predicted, and surprise = actual less predicted.
A27: Pass-through (rates, FX) = total / US-driven: how much of the US move the market took. Under 1 = absorbed. US share (credit) = Treasuries / total yield move.
A28: Region averages are equal-weighted over the flagged members only. Ratios on average rows are ratios of the averages, not averages of the ratios.
A29: Turkiye is out of the rates and FX averages; Egypt out of FX; India has no CDS; the GCC has no local curve or floating currency. Each is shown, and each exclusion is written on the row.
A30: South Africa is not in any of the four regions you named. It is a memo line in no average.
A31: Blue = input. Green = link. Purple = Bloomberg pull. Black = computed here.

Sheet Summary
A1: EM DECOMPOSITION — SUMMARY
A2: ="As of "&TEXT(INDEX(HIST_D!$A$8:$A$791,1),"d mmm yyyy")&". Every cell here is a link to the asset tabs."
A4: THE US MOVE — what EM was asked to absorb
A5: Series | B5: Level | C5: d 1M | D5: d YTD
A6: UST 2Y | B6: =INDEX(HIST_D!$B$8:$B$791,1) | C6: =IFERROR((INDEX(HIST_D!$B$8:$B$791,1)-INDEX(HIST_D!$B$8:$B$791,Control!$B$10))*100,"") | D6: =IFERROR((INDEX(HIST_D!$B$8:$B$791,1)-INDEX(HIST_D!$B$8:$B$791,Control!$B$11))*100,"")
A7: UST 5Y | B7: =INDEX(HIST_D!$C$8:$C$791,1) | C7: =IFERROR((INDEX(HIST_D!$C$8:$C$791,1)-INDEX(HIST_D!$C$8:$C$791,Control!$B$10))*100,"") | D7: =IFERROR((INDEX(HIST_D!$C$8:$C$791,1)-INDEX(HIST_D!$C$8:$C$791,Control!$B$11))*100,"")
A8: UST 10Y | B8: =INDEX(HIST_D!$D$8:$D$791,1) | C8: =IFERROR((INDEX(HIST_D!$D$8:$D$791,1)-INDEX(HIST_D!$D$8:$D$791,Control!$B$10))*100,"") | D8: =IFERROR((INDEX(HIST_D!$D$8:$D$791,1)-INDEX(HIST_D!$D$8:$D$791,Control!$B$11))*100,"")
A9: UST 30Y | B9: =INDEX(HIST_D!$E$8:$E$791,1) | C9: =IFERROR((INDEX(HIST_D!$E$8:$E$791,1)-INDEX(HIST_D!$E$8:$E$791,Control!$B$10))*100,"") | D9: =IFERROR((INDEX(HIST_D!$E$8:$E$791,1)-INDEX(HIST_D!$E$8:$E$791,Control!$B$11))*100,"")
A10: UST 10Y real | B10: =INDEX(HIST_D!$F$8:$F$791,1) | C10: =IFERROR((INDEX(HIST_D!$F$8:$F$791,1)-INDEX(HIST_D!$F$8:$F$791,Control!$B$10))*100,"") | D10: =IFERROR((INDEX(HIST_D!$F$8:$F$791,1)-INDEX(HIST_D!$F$8:$F$791,Control!$B$11))*100,"")
A11: Breakeven 10Y | B11: =INDEX(HIST_D!$G$8:$G$791,1) | C11: =IFERROR((INDEX(HIST_D!$G$8:$G$791,1)-INDEX(HIST_D!$G$8:$G$791,Control!$B$10))*100,"") | D11: =IFERROR((INDEX(HIST_D!$G$8:$G$791,1)-INDEX(HIST_D!$G$8:$G$791,Control!$B$11))*100,"")
A12: ACM term premium 10Y | B12: =INDEX(HIST_D!$H$8:$H$791,1) | C12: =IFERROR((INDEX(HIST_D!$H$8:$H$791,1)-INDEX(HIST_D!$H$8:$H$791,Control!$B$10))*100,"") | D12: =IFERROR((INDEX(HIST_D!$H$8:$H$791,1)-INDEX(HIST_D!$H$8:$H$791,Control!$B$11))*100,"")
A13: DXY | B13: =INDEX(HIST_D!$I$8:$I$791,1) | C13: =IFERROR(INDEX(HIST_D!$I$8:$I$791,1)/INDEX(HIST_D!$I$8:$I$791,Control!$B$10)-1,"") | D13: =IFERROR(INDEX(HIST_D!$I$8:$I$791,1)/INDEX(HIST_D!$I$8:$I$791,Control!$B$11)-1,"")
A14: EM USD Aggregate OAS (Bbg) | B14: =INDEX(HIST_D!$J$8:$J$791,1) | C14: =IFERROR(INDEX(HIST_D!$J$8:$J$791,1)-INDEX(HIST_D!$J$8:$J$791,Control!$B$10),"") | D14: =IFERROR(INDEX(HIST_D!$J$8:$J$791,1)-INDEX(HIST_D!$J$8:$J$791,Control!$B$11),"")
A16: PAST MONTH — total = US-driven + intrinsic, by region
A17: Region | B17: Rates: total (bp) | C17: Rates: US (bp) | D17: Rates: intrinsic (bp) | E17: Rates: pass-through | F17: FX: total | G17: FX: US | H17: FX: intrinsic | I17: FX: pass-through | J17: Credit: total (bp) | K17: Credit: US (bp) | L17: Credit: spread (bp) | M17: Credit: US share
A18: LatAm | B18: =Rates!$E$11 | C18: =Rates!$F$11 | D18: =Rates!$G$11 | E18: =Rates!$H$11 | F18: =FX!$E$11 | G18: =FX!$F$11 | H18: =FX!$G$11 | I18: =FX!$H$11 | J18: =Credit!$E$11 | K18: =Credit!$F$11 | L18: =Credit!$G$11 | M18: =Credit!$H$11
A19: EM Europe | B19: =Rates!$E$21 | C19: =Rates!$F$21 | D19: =Rates!$G$21 | E19: =Rates!$H$21 | F19: =FX!$E$21 | G19: =FX!$F$21 | H19: =FX!$G$21 | I19: =FX!$H$21 | J19: =Credit!$E$21 | K19: =Credit!$F$21 | L19: =Credit!$G$21 | M19: =Credit!$H$21
A20: Middle East | B20: =Rates!$E$28 | C20: =Rates!$F$28 | D20: =Rates!$G$28 | E20: =Rates!$H$28 | F20: =FX!$E$28 | G20: =FX!$F$28 | H20: =FX!$G$28 | I20: =FX!$H$28 | J20: =Credit!$E$31 | K20: =Credit!$F$31 | L20: =Credit!$G$31 | M20: =Credit!$H$31
A21: EM Asia | B21: =Rates!$E$40 | C21: =Rates!$F$40 | D21: =Rates!$G$40 | E21: =Rates!$H$40 | F21: =FX!$E$40 | G21: =FX!$F$40 | H21: =FX!$G$40 | I21: =FX!$H$40 | J21: =Credit!$E$42 | K21: =Credit!$F$42 | L21: =Credit!$G$42 | M21: =Credit!$H$42
A22: EM average | B22: =Rates!$E$45 | C22: =Rates!$F$45 | D22: =Rates!$G$45 | E22: =Rates!$H$45 | F22: =FX!$E$45 | G22: =FX!$F$45 | H22: =FX!$G$45 | I22: =FX!$H$45 | J22: =Credit!$E$47 | K22: =Credit!$F$47 | L22: =Credit!$G$47 | M22: =Credit!$H$47
A23: South Africa (memo) | B23: =Rates!$E$46 | C23: =Rates!$F$46 | D23: =Rates!$G$46 | E23: =Rates!$H$46 | F23: =FX!$E$46 | G23: =FX!$F$46 | H23: =FX!$G$46 | I23: =FX!$H$46 | J23: =Credit!$E$48 | K23: =Credit!$F$48 | L23: =Credit!$G$48 | M23: =Credit!$H$48
A25: YEAR TO DATE — total = US-driven + intrinsic, by region
A26: Region | B26: Rates: total (bp) | C26: Rates: US (bp) | D26: Rates: intrinsic (bp) | E26: Rates: pass-through | F26: FX: total | G26: FX: US | H26: FX: intrinsic | I26: FX: pass-through | J26: Credit: total (bp) | K26: Credit: US (bp) | L26: Credit: spread (bp) | M26: Credit: US share
A27: LatAm | B27: =Rates!$L$11 | C27: =Rates!$M$11 | D27: =Rates!$N$11 | E27: =Rates!$O$11 | F27: =FX!$L$11 | G27: =FX!$M$11 | H27: =FX!$N$11 | I27: =FX!$O$11 | J27: =Credit!$L$11 | K27: =Credit!$M$11 | L27: =Credit!$N$11 | M27: =Credit!$O$11
A28: EM Europe | B28: =Rates!$L$21 | C28: =Rates!$M$21 | D28: =Rates!$N$21 | E28: =Rates!$O$21 | F28: =FX!$L$21 | G28: =FX!$M$21 | H28: =FX!$N$21 | I28: =FX!$O$21 | J28: =Credit!$L$21 | K28: =Credit!$M$21 | L28: =Credit!$N$21 | M28: =Credit!$O$21
A29: Middle East | B29: =Rates!$L$28 | C29: =Rates!$M$28 | D29: =Rates!$N$28 | E29: =Rates!$O$28 | F29: =FX!$L$28 | G29: =FX!$M$28 | H29: =FX!$N$28 | I29: =FX!$O$28 | J29: =Credit!$L$31 | K29: =Credit!$M$31 | L29: =Credit!$N$31 | M29: =Credit!$O$31
A30: EM Asia | B30: =Rates!$L$40 | C30: =Rates!$M$40 | D30: =Rates!$N$40 | E30: =Rates!$O$40 | F30: =FX!$L$40 | G30: =FX!$M$40 | H30: =FX!$N$40 | I30: =FX!$O$40 | J30: =Credit!$L$42 | K30: =Credit!$M$42 | L30: =Credit!$N$42 | M30: =Credit!$O$42
A31: EM average | B31: =Rates!$L$45 | C31: =Rates!$M$45 | D31: =Rates!$N$45 | E31: =Rates!$O$45 | F31: =FX!$L$45 | G31: =FX!$M$45 | H31: =FX!$N$45 | I31: =FX!$O$45 | J31: =Credit!$L$47 | K31: =Credit!$M$47 | L31: =Credit!$N$47 | M31: =Credit!$O$47
A32: South Africa (memo) | B32: =Rates!$L$46 | C32: =Rates!$M$46 | D32: =Rates!$N$46 | E32: =Rates!$O$46 | F32: =FX!$L$46 | G32: =FX!$M$46 | H32: =FX!$N$46 | I32: =FX!$O$46 | J32: =Credit!$L$48 | K32: =Credit!$M$48 | L32: =Credit!$N$48 | M32: =Credit!$O$48
A34: WHERE THE US MOVE LANDED — pass-through by asset class and region (1M | YTD)
A35: Region | B35: Rates 1M | C35: FX 1M | D35: Credit US share 1M | F35: Rates YTD | G35: FX YTD | H35: Credit US share YTD
A36: LatAm | B36: =$E$18 | C36: =$I$18 | D36: =$M$18 | F36: =$E$27 | G36: =$I$27 | H36: =$M$27
A37: EM Europe | B37: =$E$19 | C37: =$I$19 | D37: =$M$19 | F37: =$E$28 | G37: =$I$28 | H37: =$M$28
A38: Middle East | B38: =$E$20 | C38: =$I$20 | D38: =$M$20 | F38: =$E$29 | G38: =$I$29 | H38: =$M$29
A39: EM Asia | B39: =$E$21 | C39: =$I$21 | D39: =$M$21 | F39: =$E$30 | G39: =$I$30 | H39: =$M$30
A40: EM average | B40: =$E$22 | C40: =$I$22 | D40: =$M$22 | F40: =$E$31 | G40: =$I$31 | H40: =$M$31
A41: Read across a row: the asset class with the lower pass-through is the one that absorbed more. Read down a column: the region with the lower number absorbed more. Rates and FX are pass-through (under 1 = absorbed). Credit is the share of the yield move that is Treasuries (near 100% = all US, spreads did nothing).
A43: EM USD CREDIT — the index return, leg by leg. Never netted.
A44: Component | B44: 1M | C44: YTD | D44: Note
A45: Carry (YTW x window / 262) | B45: =IFERROR(Control!$B$15/100*(Control!$B$10-1)/262,"") | C45: =IFERROR(Control!$B$15/100*(Control!$B$11-1)/262,"") | D45: YTW from Control
...

Sheet Charts
A1: CHARTS — the decomposition, by region and EM average
A2: Each bar is the total move; the two segments are the US-driven part (grey) and the intrinsic EM part (blue). Segments with opposite signs sit on either side of zero, so a short bar with two long segments means EM offset the US. Data blocks on the left are links to Summary; the charts read the blocks.
A4: Local rates — past month (bp)
A5: Region | B5: US-driven | C5: Intrinsic EM | D5: Total
A6: LatAm | B6: =IF(ISNUMBER(Summary!$C$18),Summary!$C$18,0) | C6: =IF(ISNUMBER(Summary!$D$18),Summary!$D$18,0) | D6: =B6+C6
A7: EM Europe | B7: =IF(ISNUMBER(Summary!$C$19),Summary!$C$19,0) | C7: =IF(ISNUMBER(Summary!$D$19),Summary!$D$19,0) | D7: =B7+C7
A8: Middle East | B8: =IF(ISNUMBER(Summary!$C$20),Summary!$C$20,0) | C8: =IF(ISNUMBER(Summary!$D$20),Summary!$D$20,0) | D8: =B8+C8
A9: EM Asia | B9: =IF(ISNUMBER(Summary!$C$21),Summary!$C$21,0) | C9: =IF(ISNUMBER(Summary!$D$21),Summary!$D$21,0) | D9: =B9+C9
A10: EM average | B10: =IF(ISNUMBER(Summary!$C$22),Summary!$C$22,0) | C10: =IF(ISNUMBER(Summary!$D$22),Summary!$D$22,0) | D10: =B10+C10
A13: Local rates — year to date (bp)
A14: Region | B14: US-driven | C14: Intrinsic EM | D14: Total
A15: LatAm | B15: =IF(ISNUMBER(Summary!$C$27),Summary!$C$27,0) | C15: =IF(ISNUMBER(Summary!$D$27),Summary!$D$27,0) | D15: =B15+C15
A16: EM Europe | B16: =IF(ISNUMBER(Summary!$C$28),Summary!$C$28,0) | C16: =IF(ISNUMBER(Summary!$D$28),Summary!$D$28,0) | D16: =B16+C16
A17: Middle East | B17: =IF(ISNUMBER(Summary!$C$29),Summary!$C$29,0) | C17: =IF(ISNUMBER(Summary!$D$29),Summary!$D$29,0) | D17: =B17+C17
A18: EM Asia | B18: =IF(ISNUMBER(Summary!$C$30),Summary!$C$30,0) | C18: =IF(ISNUMBER(Summary!$D$30),Summary!$D$30,0) | D18: =B18+C18
A19: EM average | B19: =IF(ISNUMBER(Summary!$C$31),Summary!$C$31,0) | C19: =IF(ISNUMBER(Summary!$D$31),Summary!$D$31,0) | D19: =B19+C19
A22: FX — past month (return on EM ccy)
A23: Region | B23: US-driven | C23: Intrinsic EM | D23: Total
A24: LatAm | B24: =IF(ISNUMBER(Summary!$G$18),Summary!$G$18,0) | C24: =IF(ISNUMBER(Summary!$H$18),Summary!$H$18,0) | D24: =B24+C24
A25: EM Europe | B25: =IF(ISNUMBER(Summary!$G$19),Summary!$G$19,0) | C25: =IF(ISNUMBER(Summary!$H$19),Summary!$H$19,0) | D25: =B25+C25
A26: Middle East | B26: =IF(ISNUMBER(Summary!$G$20),Summary!$G$20,0) | C26: =IF(ISNUMBER(Summary!$H$20),Summary!$H$20,0) | D26: =B26+C26
A27: EM Asia | B27: =IF(ISNUMBER(Summary!$G$21),Summary!$G$21,0) | C27: =IF(ISNUMBER(Summary!$H$21),Summary!$H$21,0) | D27: =B27+C27
A28: EM average | B28: =IF(ISNUMBER(Summary!$G$22),Summary!$G$22,0) | C28: =IF(ISNUMBER(Summary!$H$22),Summary!$H$22,0) | D28: =B28+C28
A31: FX — year to date (return on EM ccy)
A32: Region | B32: US-driven | C32: Intrinsic EM | D32: Total
A33: LatAm | B33: =IF(ISNUMBER(Summary!$G$27),Summary!$G$27,0) | C33: =IF(ISNUMBER(Summary!$H$27),Summary!$H$27,0) | D33: =B33+C33
A34: EM Europe | B34: =IF(ISNUMBER(Summary!$G$28),Summary!$G$28,0) | C34: =IF(ISNUMBER(Summary!$H$28),Summary!$H$28,0) | D34: =B34+C34
A35: Middle East | B35: =IF(ISNUMBER(Summary!$G$29),Summary!$G$29,0) | C35: =IF(ISNUMBER(Summary!$H$29),Summary!$H$29,0) | D35: =B35+C35
A36: EM Asia | B36: =IF(ISNUMBER(Summary!$G$30),Summary!$G$30,0) | C36: =IF(ISNUMBER(Summary!$H$30),Summary!$H$30,0) | D36: =B36+C36
A37: EM average | B37: =IF(ISNUMBER(Summary!$G$31),Summary!$G$31,0) | C37: =IF(ISNUMBER(Summary!$H$31),Summary!$H$31,0) | D37: =B37+C37
A40: USD credit — past month (bp)
A41: Region | B41: US-driven | C41: Intrinsic EM | D41: Total
A42: LatAm | B42: =IF(ISNUMBER(Summary!$K$18),Summary!$K$18,0) | C42: =IF(ISNUMBER(Summary!$L$18),Summary!$L$18,0) | D42: =B42+C42
A43: EM Europe | B43: =IF(ISNUMBER(Summary!$K$19),Summary!$K$19,0) | C43: =IF(ISNUMBER(Summary!$L$19),Summary!$L$19,0) | D43: =B43+C43
A44: Middle East | B44: =IF(ISNUMBER(Summary!$K$20),Summary!$K$20,0) | C44: =IF(ISNUMBER(Summary!$L$20),Summary!$L$20,0) | D44: =B44+C44
A45: EM Asia | B45: =IF(ISNUMBER(Summary!$K$21),Summary!$K$21,0) | C45: =IF(ISNUMBER(Summary!$L$21),Summary!$L$21,0) | D45: =B45+C45
A46: EM average | B46: =IF(ISNUMBER(Summary!$K$22),Summary!$K$22,0) | C46: =IF(ISNUMBER(Summary!$L$22),Summary!$L$22,0) | D46: =B46+C46
A49: USD credit — year to date (bp)
A50: Region | B50: US-driven | C50: Intrinsic EM | D50: Total
A51: LatAm | B51: =IF(ISNUMBER(Summary!$K$27),Summary!$K$27,0) | C51: =IF(ISNUMBER(Summary!$L$27),Summary!$L$27,0) | D51: =B51+C51
...

Sheet Rates
A1: EM LOCAL RATES — 10Y generic, by country and region
A2: d(local 10Y) = d(UST 10Y) + d(local less UST). US-driven is the Treasury move; intrinsic is the change in the gap to Treasuries. Pass-through = total / US-driven: how much of the US move the local curve took. Under 1.0 = absorbed.
A4: LATAM
A5: Country | B5: Region | C5: Level | D5: In avg | E5: 1M: Total move (bp) | F5: 1M: US-driven: d UST 10Y (bp) | G5: 1M: Intrinsic: d gap to UST (bp) | H5: 1M: Pass-through (total / US) | I5: 1M: Beta to UST 10Y (2y) | J5: 1M: Predicted by beta (bp) | K5: 1M: Surprise: actual less predicted (bp) | L5: YTD: Total move (bp) | M5: YTD: US-driven: d UST 10Y (bp) | N5: YTD: Intrinsic: d gap to UST (bp) | O5: YTD: Pass-through (total / US) | P5: YTD: Beta to UST 10Y (2y) | Q5: YTD: Predicted by beta (bp) | R5: YTD: Surprise: actual less predicted (bp)
A6: Brazil | B6: LatAm | C6: =INDEX(HIST_D!$AF$8:$AF$791,1) | D6: yes | E6: =IFERROR((INDEX(HIST_D!$AF$8:$AF$791,1)-INDEX(HIST_D!$AF$8:$AF$791,Control!$B$10))*100,"") | F6: =IFERROR((INDEX(HIST_D!$D$8:$D$791,1)-INDEX(HIST_D!$D$8:$D$791,Control!$B$10))*100,"") | G6: =IFERROR(E6-F6,"") | H6: =IFERROR(IF(ABS(F6)<Control!$B$13,"n/m",E6/F6),"n/m") | I6: =IFERROR(SLOPE(HIST_D!$BY$8:INDEX(HIST_D!$BY$8:$BY$791,Control!$B$12),HIST_D!$BV$8:INDEX(HIST_D!$BV$8:$BV$791,Control!$B$12)),"") | J6: =IFERROR(I6*(INDEX(HIST_D!$D$8:$D$791,1)-INDEX(HIST_D!$D$8:$D$791,Control!$B$10))*100,"") | K6: =IFERROR(E6-J6,"") | L6: =IFERROR((INDEX(HIST_D!$AF$8:$AF$791,1)-INDEX(HIST_D!$AF$8:$AF$791,Control!$B$11))*100,"") | M6: =IFERROR((INDEX(HIST_D!$D$8:$D$791,1)-INDEX(HIST_D!$D$8:$D$791,Control!$B$11))*100,"") | N6: =IFERROR(L6-M6,"") | O6: =IFERROR(IF(ABS(M6)<Control!$B$13,"n/m",L6/M6),"n/m") | P6: =IFERROR(SLOPE(HIST_D!$BY$8:INDEX(HIST_D!$BY$8:$BY$791,Control!$B$12),HIST_D!$BV$8:INDEX(HIST_D!$BV$8:$BV$791,Control!$B$12)),"") | Q6: =IFERROR(P6*(INDEX(HIST_D!$D$8:$D$791,1)-INDEX(HIST_D!$D$8:$D$791,Control!$B$11))*100,"") | R6: =IFERROR(L6-Q6,"")
A7: Mexico | B7: LatAm | C7: =INDEX(HIST_D!$AG$8:$AG$791,1) | D7: yes | E7: =IFERROR((INDEX(HIST_D!$AG$8:$AG$791,1)-INDEX(HIST_D!$AG$8:$AG$791,Control!$B$10))*100,"") | F7: =IFERROR((INDEX(HIST_D!$D$8:$D$791,1)-INDEX(HIST_D!$D$8:$D$791,Control!$B$10))*100,"") | G7: =IFERROR(E7-F7,"") | H7: =IFERROR(IF(ABS(F7)<Control!$B$13,"n/m",E7/F7),"n/m") | I7: =IFERROR(SLOPE(HIST_D!$BZ$8:INDEX(HIST_D!$BZ$8:$BZ$791,Control!$B$12),HIST_D!$BV$8:INDEX(HIST_D!$BV$8:$BV$791,Control!$B$12)),"") | J7: =IFERROR(I7*(INDEX(HIST_D!$D$8:$D$791,1)-INDEX(HIST_D!$D$8:$D$791,Control!$B$10))*100,"") | K7: =IFERROR(E7-J7,"") | L7: =IFERROR((INDEX(HIST_D!$AG$8:$AG$791,1)-INDEX(HIST_D!$AG$8:$AG$791,Control!$B$11))*100,"") | M7: =IFERROR((INDEX(HIST_D!$D$8:$D$791,1)-INDEX(HIST_D!$D$8:$D$791,Control!$B$11))*100,"") | N7: =IFERROR(L7-M7,"") | O7: =IFERROR(IF(ABS(M7)<Control!$B$13,"n/m",L7/M7),"n/m") | P7: =IFERROR(SLOPE(HIST_D!$BZ$8:INDEX(HIST_D!$BZ$8:$BZ$791,Control!$B$12),HIST_D!$BV$8:INDEX(HIST_D!$BV$8:$BV$791,Control!$B$12)),"") | Q7: =IFERROR(P7*(INDEX(HIST_D!$D$8:$D$791,1)-INDEX(HIST_D!$D$8:$D$791,Control!$B$11))*100,"") | R7: =IFERROR(L7-Q7,"")
A8: Chile | B8: LatAm | C8: =INDEX(HIST_D!$AH$8:$AH$791,1) | D8: yes | E8: =IFERROR((INDEX(HIST_D!$AH$8:$AH$791,1)-INDEX(HIST_D!$AH$8:$AH$791,Control!$B$10))*100,"") | F8: =IFERROR((INDEX(HIST_D!$D$8:$D$791,1)-INDEX(HIST_D!$D$8:$D$791,Control!$B$10))*100,"") | G8: =IFERROR(E8-F8,"") | H8: =IFERROR(IF(ABS(F8)<Control!$B$13,"n/m",E8/F8),"n/m") | I8: =IFERROR(SLOPE(HIST_D!$CA$8:INDEX(HIST_D!$CA$8:$CA$791,Control!$B$12),HIST_D!$BV$8:INDEX(HIST_D!$BV$8:$BV$791,Control!$B$12)),"") | J8: =IFERROR(I8*(INDEX(HIST_D!$D$8:$D$791,1)-INDEX(HIST_D!$D$8:$D$791,Control!$B$10))*100,"") | K8: =IFERROR(E8-J8,"") | L8: =IFERROR((INDEX(HIST_D!$AH$8:$AH$791,1)-INDEX(HIST_D!$AH$8:$AH$791,Control!$B$11))*100,"") | M8: =IFERROR((INDEX(HIST_D!$D$8:$D$791,1)-INDEX(HIST_D!$D$8:$D$791,Control!$B$11))*100,"") | N8: =IFERROR(L8-M8,"") | O8: =IFERROR(IF(ABS(M8)<Control!$B$13,"n/m",L8/M8),"n/m") | P8: =IFERROR(SLOPE(HIST_D!$CA$8:INDEX(HIST_D!$CA$8:$CA$791,Control!$B$12),HIST_D!$BV$8:INDEX(HIST_D!$BV$8:$BV$791,Control!$B$12)),"") | Q8: =IFERROR(P8*(INDEX(HIST_D!$D$8:$D$791,1)-INDEX(HIST_D!$D$8:$D$791,Control!$B$11))*100,"") | R8: =IFERROR(L8-Q8,"")
A9: Colombia | B9: LatAm | C9: =INDEX(HIST_D!$AI$8:$AI$791,1) | D9: yes | E9: =IFERROR((INDEX(HIST_D!$AI$8:$AI$791,1)-INDEX(HIST_D!$AI$8:$AI$791,Control!$B$10))*100,"") | F9: =IFERROR((INDEX(HIST_D!$D$8:$D$791,1)-INDEX(HIST_D!$D$8:$D$791,Control!$B$10))*100,"") | G9: =IFERROR(E9-F9,"") | H9: =IFERROR(IF(ABS(F9)<Control!$B$13,"n/m",E9/F9),"n/m") | I9: =IFERROR(SLOPE(HIST_D!$CB$8:INDEX(HIST_D!$CB$8:$CB$791,Control!$B$12),HIST_D!$BV$8:INDEX(HIST_D!$BV$8:$BV$791,Control!$B$12)),"") | J9: =IFERROR(I9*(INDEX(HIST_D!$D$8:$D$791,1)-INDEX(HIST_D!$D$8:$D$791,Control!$B$10))*100,"") | K9: =IFERROR(E9-J9,"") | L9: =IFERROR((INDEX(HIST_D!$AI$8:$AI$791,1)-INDEX(HIST_D!$AI$8:$AI$791,Control!$B$11))*100,"") | M9: =IFERROR((INDEX(HIST_D!$D$8:$D$791,1)-INDEX(HIST_D!$D$8:$D$791,Control!$B$11))*100,"") | N9: =IFERROR(L9-M9,"") | O9: =IFERROR(IF(ABS(M9)<Control!$B$13,"n/m",L9/M9),"n/m") | P9: =IFERROR(SLOPE(HIST_D!$CB$8:INDEX(HIST_D!$CB$8:$CB$791,Control!$B$12),HIST_D!$BV$8:INDEX(HIST_D!$BV$8:$BV$791,Control!$B$12)),"") | Q9: =IFERROR(P9*(INDEX(HIST_D!$D$8:$D$791,1)-INDEX(HIST_D!$D$8:$D$791,Control!$B$11))*100,"") | R9: =IFERROR(L9-Q9,"")
A10: Peru | B10: LatAm | C10: =INDEX(HIST_D!$AJ$8:$AJ$791,1) | D10: yes | E10: =IFERROR((INDEX(HIST_D!$AJ$8:$AJ$791,1)-INDEX(HIST_D!$AJ$8:$AJ$791,Control!$B$10))*100,"") | F10: =IFERROR((INDEX(HIST_D!$D$8:$D$791,1)-INDEX(HIST_D!$D$8:$D$791,Control!$B$10))*100,"") | G10: =IFERROR(E10-F10,"") | H10: =IFERROR(IF(ABS(F10)<Control!$B$13,"n/m",E10/F10),"n/m") | I10: =IFERROR(SLOPE(HIST_D!$CC$8:INDEX(HIST_D!$CC$8:$CC$791,Control!$B$12),HIST_D!$BV$8:INDEX(HIST_D!$BV$8:$BV$791,Control!$B$12)),"") | J10: =IFERROR(I10*(INDEX(HIST_D!$D$8:$D$791,1)-INDEX(HIST_D!$D$8:$D$791,Control!$B$10))*100,"") | K10: =IFERROR(E10-J10,"") | L10: =IFERROR((INDEX(HIST_D!$AJ$8:$AJ$791,1)-INDEX(HIST_D!$AJ$8:$AJ$791,Control!$B$11))*100,"") | M10: =IFERROR((INDEX(HIST_D!$D$8:$D$791,1)-INDEX(HIST_D!$D$8:$D$791,Control!$B$11))*100,"") | N10: =IFERROR(L10-M10,"") | O10: =IFERROR(IF(ABS(M10)<Control!$B$13,"n/m",L10/M10),"n/m") | P10: =IFERROR(SLOPE(HIST_D!$CC$8:INDEX(HIST_D!$CC$8:$CC$791,Control!$B$12),HIST_D!$BV$8:INDEX(HIST_D!$BV$8:$BV$791,Control!$B$12)),"") | Q10: =IFERROR(P10*(INDEX(HIST_D!$D$8:$D$791,1)-INDEX(HIST_D!$D$8:$D$791,Control!$B$11))*100,"") | R10: =IFERROR(L10-Q10,"")
A11: LatAm average | B11: n=5 | E11: =IFERROR(AVERAGE(E6,E7,E8,E9,E10),"") | F11: =IFERROR(AVERAGE(F6,F7,F8,F9,F10),"") | G11: =IFERROR(AVERAGE(G6,G7,G8,G9,G10),"") | H11: =IFERROR(IF(ABS(F11)<Control!$B$13,"n/m",E11/F11),"n/m") | I11: =IFERROR(AVERAGE(I6,I7,I8,I9,I10),"") | J11: =IFERROR(AVERAGE(J6,J7,J8,J9,J10),"") | K11: =IFERROR(AVERAGE(K6,K7,K8,K9,K10),"") | L11: =IFERROR(AVERAGE(L6,L7,L8,L9,L10),"") | M11: =IFERROR(AVERAGE(M6,M7,M8,M9,M10),"") | N11: =IFERROR(AVERAGE(N6,N7,N8,N9,N10),"") | O11: =IFERROR(IF(ABS(M11)<Control!$B$13,"n/m",L11/M11),"n/m") | P11: =IFERROR(AVERAGE(P6,P7,P8,P9,P10),"") | Q11: =IFERROR(AVERAGE(Q6,Q7,Q8,Q9,Q10),"") | R11: =IFERROR(AVERAGE(R6,R7,R8,R9,R10),"")
A12: =IFERROR("LatAm: local 10Y "&TEXT($E$11,"+0;-0")&"bp on the month against UST 10Y "&TEXT($F$11,"+0;-0")&"bp, so the gap to Treasuries moved "&TEXT($G$11,"+0;-0")&"bp"&IF(ISNUMBER($H$11)," (pass-through "&TEXT($H$11,"0.00")&"x)","")&". History (2y beta "&TEXT($I$11,"0.00")&") would have predicted "&TEXT($J$11,"+0;-0")&"bp; the surprise is "&TEXT($K$11,"+0;-0")&"bp. YTD: "&TEXT($L$11,"+0;-0")&"bp against "&TEXT($M$11,"+0;-0")&"bp, gap "&TEXT($N$11,"+0;-0")&"bp"&IF(ISNUMBER($O$11)," (pass-through "&TEXT($O$11,"0.00")&"x)","")&". "&IF($K$11<-5,"The curve did better than its own history — absorbed.",IF($K$11>5,"The curve did worse than its own history — imported.","Moved in line with its own history.")),"")
A14: EM EUROPE
A15: Country | B15: Region | C15: Level | D15: In avg | E15: 1M: Total move (bp) | F15: 1M: US-driven: d UST 10Y (bp) | G15: 1M: Intrinsic: d gap to UST (bp) | H15: 1M: Pass-through (total / US) | I15: 1M: Beta to UST 10Y (2y) | J15: 1M: Predicted by beta (bp) | K15: 1M: Surprise: actual less predicted (bp) | L15: YTD: Total move (bp) | M15: YTD: US-driven: d UST 10Y (bp) | N15: YTD: Intrinsic: d gap to UST (bp) | O15: YTD: Pass-through (total / US) | P15: YTD: Beta to UST 10Y (2y) | Q15: YTD: Predicted by beta (bp) | R15: YTD: Surprise: actual less predicted (bp)
A16: Poland | B16: EM Europe | C16: =INDEX(HIST_D!$AK$8:$AK$791,1) | D16: yes | E16: =IFERROR((INDEX(HIST_D!$AK$8:$AK$791,1)-INDEX(HIST_D!$AK$8:$AK$791,Control!$B$10))*100,"") | F16: =IFERROR((INDEX(HIST_D!$D$8:$D$791,1)-INDEX(HIST_D!$D$8:$D$791,Control!$B$10))*100,"") | G16: =IFERROR(E16-F16,"") | H16: =IFERROR(IF(ABS(F16)<Control!$B$13,"n/m",E16/F16),"n/m") | I16: =IFERROR(SLOPE(HIST_D!$CD$8:INDEX(HIST_D!$CD$8:$CD$791,Control!$B$12),HIST_D!$BV$8:INDEX(HIST_D!$BV$8:$BV$791,Control!$B$12)),"") | J16: =IFERROR(I16*(INDEX(HIST_D!$D$8:$D$791,1)-INDEX(HIST_D!$D$8:$D$791,Control!$B$10))*100,"") | K16: =IFERROR(E16-J16,"") | L16: =IFERROR((INDEX(HIST_D!$AK$8:$AK$791,1)-INDEX(HIST_D!$AK$8:$AK$791,Control!$B$11))*100,"") | M16: =IFERROR((INDEX(HIST_D!$D$8:$D$791,1)-INDEX(HIST_D!$D$8:$D$791,Control!$B$11))*100,"") | N16: =IFERROR(L16-M16,"") | O16: =IFERROR(IF(ABS(M16)<Control!$B$13,"n/m",L16/M16),"n/m") | P16: =IFERROR(SLOPE(HIST_D!$CD$8:INDEX(HIST_D!$CD$8:$CD$791,Control!$B$12),HIST_D!$BV$8:INDEX(HIST_D!$BV$8:$BV$791,Control!$B$12)),"") | Q16: =IFERROR(P16*(INDEX(HIST_D!$D$8:$D$791,1)-INDEX(HIST_D!$D$8:$D$791,Control!$B$11))*100,"") | R16: =IFERROR(L16-Q16,"")
A17: Hungary | B17: EM Europe | C17: =INDEX(HIST_D!$AL$8:$AL$791,1) | D17: yes | E17: =IFERROR((INDEX(HIST_D!$AL$8:$AL$791,1)-INDEX(HIST_D!$AL$8:$AL$791,Control!$B$10))*100,"") | F17: =IFERROR((INDEX(HIST_D!$D$8:$D$791,1)-INDEX(HIST_D!$D$8:$D$791,Control!$B$10))*100,"") | G17: =IFERROR(E17-F17,"") | H17: =IFERROR(IF(ABS(F17)<Control!$B$13,"n/m",E17/F17),"n/m") | I17: =IFERROR(SLOPE(HIST_D!$CE$8:INDEX(HIST_D!$CE$8:$CE$791,Control!$B$12),HIST_D!$BV$8:INDEX(HIST_D!$BV$8:$BV$791,Control!$B$12)),"") | J17: =IFERROR(I17*(INDEX(HIST_D!$D$8:$D$791,1)-INDEX(HIST_D!$D$8:$D$791,Control!$B$10))*100,"") | K17: =IFERROR(E17-J17,"") | L17: =IFERROR((INDEX(HIST_D!$AL$8:$AL$791,1)-INDEX(HIST_D!$AL$8:$AL$791,Control!$B$11))*100,"") | M17: =IFERROR((INDEX(HIST_D!$D$8:$D$791,1)-INDEX(HIST_D!$D$8:$D$791,Control!$B$11))*100,"") | N17: =IFERROR(L17-M17,"") | O17: =IFERROR(IF(ABS(M17)<Control!$B$13,"n/m",L17/M17),"n/m") | P17: =IFERROR(SLOPE(HIST_D!$CE$8:INDEX(HIST_D!$CE$8:$CE$791,Control!$B$12),HIST_D!$BV$8:INDEX(HIST_D!$BV$8:$BV$791,Control!$B$12)),"") | Q17: =IFERROR(P17*(INDEX(HIST_D!$D$8:$D$791,1)-INDEX(HIST_D!$D$8:$D$791,Control!$B$11))*100,"") | R17: =IFERROR(L17-Q17,"")
A18: Czechia | B18: EM Europe | C18: =INDEX(HIST_D!$AM$8:$AM$791,1) | D18: yes | E18: =IFERROR((INDEX(HIST_D!$AM$8:$AM$791,1)-INDEX(HIST_D!$AM$8:$AM$791,Control!$B$10))*100,"") | F18: =IFERROR((INDEX(HIST_D!$D$8:$D$791,1)-INDEX(HIST_D!$D$8:$D$791,Control!$B$10))*100,"") | G18: =IFERROR(E18-F18,"") | H18: =IFERROR(IF(ABS(F18)<Control!$B$13,"n/m",E18/F18),"n/m") | I18: =IFERROR(SLOPE(HIST_D!$CF$8:INDEX(HIST_D!$CF$8:$CF$791,Control!$B$12),HIST_D!$BV$8:INDEX(HIST_D!$BV$8:$BV$791,Control!$B$12)),"") | J18: =IFERROR(I18*(INDEX(HIST_D!$D$8:$D$791,1)-INDEX(HIST_D!$D$8:$D$791,Control!$B$10))*100,"") | K18: =IFERROR(E18-J18,"") | L18: =IFERROR((INDEX(HIST_D!$AM$8:$AM$791,1)-INDEX(HIST_D!$AM$8:$AM$791,Control!$B$11))*100,"") | M18: =IFERROR((INDEX(HIST_D!$D$8:$D$791,1)-INDEX(HIST_D!$D$8:$D$791,Control!$B$11))*100,"") | N18: =IFERROR(L18-M18,"") | O18: =IFERROR(IF(ABS(M18)<Control!$B$13,"n/m",L18/M18),"n/m") | P18: =IFERROR(SLOPE(HIST_D!$CF$8:INDEX(HIST_D!$CF$8:$CF$791,Control!$B$12),HIST_D!$BV$8:INDEX(HIST_D!$BV$8:$BV$791,Control!$B$12)),"") | Q18: =IFERROR(P18*(INDEX(HIST_D!$D$8:$D$791,1)-INDEX(HIST_D!$D$8:$D$791,Control!$B$11))*100,"") | R18: =IFERROR(L18-Q18,"")
A19: Romania | B19: EM Europe | C19: =INDEX(HIST_D!$AN$8:$AN$791,1) | D19: yes | E19: =IFERROR((INDEX(HIST_D!$AN$8:$AN$791,1)-INDEX(HIST_D!$AN$8:$AN$791,Control!$B$10))*100,"") | F19: =IFERROR((INDEX(HIST_D!$D$8:$D$791,1)-INDEX(HIST_D!$D$8:$D$791,Control!$B$10))*100,"") | G19: =IFERROR(E19-F19,"") | H19: =IFERROR(IF(ABS(F19)<Control!$B$13,"n/m",E19/F19),"n/m") | I19: =IFERROR(SLOPE(HIST_D!$CG$8:INDEX(HIST_D!$CG$8:$CG$791,Control!$B$12),HIST_D!$BV$8:INDEX(HIST_D!$BV$8:$BV$791,Control!$B$12)),"") | J19: =IFERROR(I19*(INDEX(HIST_D!$D$8:$D$791,1)-INDEX(HIST_D!$D$8:$D$791,Control!$B$10))*100,"") | K19: =IFERROR(E19-J19,"") | L19: =IFERROR((INDEX(HIST_D!$AN$8:$AN$791,1)-INDEX(HIST_D!$AN$8:$AN$791,Control!$B$11))*100,"") | M19: =IFERROR((INDEX(HIST_D!$D$8:$D$791,1)-INDEX(HIST_D!$D$8:$D$791,Control!$B$11))*100,"") | N19: =IFERROR(L19-M19,"") | O19: =IFERROR(IF(ABS(M19)<Control!$B$13,"n/m",L19/M19),"n/m") | P19: =IFERROR(SLOPE(HIST_D!$CG$8:INDEX(HIST_D!$CG$8:$CG$791,Control!$B$12),HIST_D!$BV$8:INDEX(HIST_D!$BV$8:$BV$791,Control!$B$12)),"") | Q19: =IFERROR(P19*(INDEX(HIST_D!$D$8:$D$791,1)-INDEX(HIST_D!$D$8:$D$791,Control!$B$11))*100,"") | R19: =IFERROR(L19-Q19,"")
A20: Turkiye | B20: EM Europe | C20: =INDEX(HIST_D!$AO$8:$AO$791,1) | D20: no | E20: =IFERROR((INDEX(HIST_D!$AO$8:$AO$791,1)-INDEX(HIST_D!$AO$8:$AO$791,Control!$B$10))*100,"") | F20: =IFERROR((INDEX(HIST_D!$D$8:$D$791,1)-INDEX(HIST_D!$D$8:$D$791,Control!$B$10))*100,"") | G20: =IFERROR(E20-F20,"") | H20: =IFERROR(IF(ABS(F20)<Control!$B$13,"n/m",E20/F20),"n/m") | I20: =IFERROR(SLOPE(HIST_D!$CH$8:INDEX(HIST_D!$CH$8:$CH$791,Control!$B$12),HIST_D!$BV$8:INDEX(HIST_D!$BV$8:$BV$791,Control!$B$12)),"") | J20: =IFERROR(I20*(INDEX(HIST_D!$D$8:$D$791,1)-INDEX(HIST_D!$D$8:$D$791,Control!$B$10))*100,"") | K20: =IFERROR(E20-J20,"") | L20: =IFERROR((INDEX(HIST_D!$AO$8:$AO$791,1)-INDEX(HIST_D!$AO$8:$AO$791,Control!$B$11))*100,"") | M20: =IFERROR((INDEX(HIST_D!$D$8:$D$791,1)-INDEX(HIST_D!$D$8:$D$791,Control!$B$11))*100,"") | N20: =IFERROR(L20-M20,"") | O20: =IFERROR(IF(ABS(M20)<Control!$B$13,"n/m",L20/M20),"n/m") | P20: =IFERROR(SLOPE(HIST_D!$CH$8:INDEX(HIST_D!$CH$8:$CH$791,Control!$B$12),HIST_D!$BV$8:INDEX(HIST_D!$BV$8:$BV$791,Control!$B$12)),"") | Q20: =IFERROR(P20*(INDEX(HIST_D!$D$8:$D$791,1)-INDEX(HIST_D!$D$8:$D$791,Control!$B$11))*100,"") | R20: =IFERROR(L20-Q20,"") | S20: excluded from rates and FX averages: structural depreciation and a 30% curve swamp an equal weight
A21: EM Europe average | B21: n=4 | E21: =IFERROR(AVERAGE(E16,E17,E18,E19),"") | F21: =IFERROR(AVERAGE(F16,F17,F18,F19),"") | G21: =IFERROR(AVERAGE(G16,G17,G18,G19),"") | H21: =IFERROR(IF(ABS(F21)<Control!$B$13,"n/m",E21/F21),"n/m") | I21: =IFERROR(AVERAGE(I16,I17,I18,I19),"") | J21: =IFERROR(AVERAGE(J16,J17,J18,J19),"") | K21: =IFERROR(AVERAGE(K16,K17,K18,K19),"") | L21: =IFERROR(AVERAGE(L16,L17,L18,L19),"") | M21: =IFERROR(AVERAGE(M16,M17,M18,M19),"") | N21: =IFERROR(AVERAGE(N16,N17,N18,N19),"") | O21: =IFERROR(IF(ABS(M21)<Control!$B$13,"n/m",L21/M21),"n/m") | P21: =IFERROR(AVERAGE(P16,P17,P18,P19),"") | Q21: =IFERROR(AVERAGE(Q16,Q17,Q18,Q19),"") | R21: =IFERROR(AVERAGE(R16,R17,R18,R19),"")
A22: =IFERROR("EM Europe: local 10Y "&TEXT($E$21,"+0;-0")&"bp on the month against UST 10Y "&TEXT($F$21,"+0;-0")&"bp, so the gap to Treasuries moved "&TEXT($G$21,"+0;-0")&"bp"&IF(ISNUMBER($H$21)," (pass-through "&TEXT($H$21,"0.00")&"x)","")&". History (2y beta "&TEXT($I$21,"0.00")&") would have predicted "&TEXT($J$21,"+0;-0")&"bp; the surprise is "&TEXT($K$21,"+0;-0")&"bp. YTD: "&TEXT($L$21,"+0;-0")&"bp against "&TEXT($M$21,"+0;-0")&"bp, gap "&TEXT($N$21,"+0;-0")&"bp"&IF(ISNUMBER($O$21)," (pass-through "&TEXT($O$21,"0.00")&"x)","")&". "&IF($K$21<-5,"The curve did better than its own history — absorbed.",IF($K$21>5,"The curve did worse than its own history — imported.","Moved in line with its own history.")),"")
A24: MIDDLE EAST
A25: Country | B25: Region | C25: Level | D25: In avg | E25: 1M: Total move (bp) | F25: 1M: US-driven: d UST 10Y (bp) | G25: 1M: Intrinsic: d gap to UST (bp) | H25: 1M: Pass-through (total / US) | I25: 1M: Beta to UST 10Y (2y) | J25: 1M: Predicted by beta (bp) | K25: 1M: Surprise: actual less predicted (bp) | L25: YTD: Total move (bp) | M25: YTD: US-driven: d UST 10Y (bp) | N25: YTD: Intrinsic: d gap to UST (bp) | O25: YTD: Pass-through (total / US) | P25: YTD: Beta to UST 10Y (2y) | Q25: YTD: Predicted by beta (bp) | R25: YTD: Surprise: actual less predicted (bp)
A26: Israel | B26: Middle East | C26: =INDEX(HIST_D!$AP$8:$AP$791,1) | D26: yes | E26: =IFERROR((INDEX(HIST_D!$AP$8:$AP$791,1)-INDEX(HIST_D!$AP$8:$AP$791,Control!$B$10))*100,"") | F26: =IFERROR((INDEX(HIST_D!$D$8:$D$791,1)-INDEX(HIST_D!$D$8:$D$791,Control!$B$10))*100,"") | G26: =IFERROR(E26-F26,"") | H26: =IFERROR(IF(ABS(F26)<Control!$B$13,"n/m",E26/F26),"n/m") | I26: =IFERROR(SLOPE(HIST_D!$CI$8:INDEX(HIST_D!$CI$8:$CI$791,Control!$B$12),HIST_D!$BV$8:INDEX(HIST_D!$BV$8:$BV$791,Control!$B$12)),"") | J26: =IFERROR(I26*(INDEX(HIST_D!$D$8:$D$791,1)-INDEX(HIST_D!$D$8:$D$791,Control!$B$10))*100,"") | K26: =IFERROR(E26-J26,"") | L26: =IFERROR((INDEX(HIST_D!$AP$8:$AP$791,1)-INDEX(HIST_D!$AP$8:$AP$791,Control!$B$11))*100,"") | M26: =IFERROR((INDEX(HIST_D!$D$8:$D$791,1)-INDEX(HIST_D!$D$8:$D$791,Control!$B$11))*100,"") | N26: =IFERROR(L26-M26,"") | O26: =IFERROR(IF(ABS(M26)<Control!$B$13,"n/m",L26/M26),"n/m") | P26: =IFERROR(SLOPE(HIST_D!$CI$8:INDEX(HIST_D!$CI$8:$CI$791,Control!$B$12),HIST_D!$BV$8:INDEX(HIST_D!$BV$8:$BV$791,Control!$B$12)),"") | Q26: =IFERROR(P26*(INDEX(HIST_D!$D$8:$D$791,1)-INDEX(HIST_D!$D$8:$D$791,Control!$B$11))*100,"") | R26: =IFERROR(L26-Q26,"")
A27: Egypt | B27: Middle East | C27: =INDEX(HIST_D!$AQ$8:$AQ$791,1) | D27: yes | E27: =IFERROR((INDEX(HIST_D!$AQ$8:$AQ$791,1)-INDEX(HIST_D!$AQ$8:$AQ$791,Control!$B$10))*100,"") | F27: =IFERROR((INDEX(HIST_D!$D$8:$D$791,1)-INDEX(HIST_D!$D$8:$D$791,Control!$B$10))*100,"") | G27: =IFERROR(E27-F27,"") | H27: =IFERROR(IF(ABS(F27)<Control!$B$13,"n/m",E27/F27),"n/m") | I27: =IFERROR(SLOPE(HIST_D!$CJ$8:INDEX(HIST_D!$CJ$8:$CJ$791,Control!$B$12),HIST_D!$BV$8:INDEX(HIST_D!$BV$8:$BV$791,Control!$B$12)),"") | J27: =IFERROR(I27*(INDEX(HIST_D!$D$8:$D$791,1)-INDEX(HIST_D!$D$8:$D$791,Control!$B$10))*100,"") | K27: =IFERROR(E27-J27,"") | L27: =IFERROR((INDEX(HIST_D!$AQ$8:$AQ$791,1)-INDEX(HIST_D!$AQ$8:$AQ$791,Control!$B$11))*100,"") | M27: =IFERROR((INDEX(HIST_D!$D$8:$D$791,1)-INDEX(HIST_D!$D$8:$D$791,Control!$B$11))*100,"") | N27: =IFERROR(L27-M27,"") | O27: =IFERROR(IF(ABS(M27)<Control!$B$13,"n/m",L27/M27),"n/m") | P27: =IFERROR(SLOPE(HIST_D!$CJ$8:INDEX(HIST_D!$CJ$8:$CJ$791,Control!$B$12),HIST_D!$BV$8:INDEX(HIST_D!$BV$8:$BV$791,Control!$B$12)),"") | Q27: =IFERROR(P27*(INDEX(HIST_D!$D$8:$D$791,1)-INDEX(HIST_D!$D$8:$D$791,Control!$B$11))*100,"") | R27: =IFERROR(L27-Q27,"") | S27: excluded from FX average: managed float with step devaluations; GTEGP10Y is Verify
A28: Middle East average | B28: n=2 | E28: =IFERROR(AVERAGE(E26,E27),"") | F28: =IFERROR(AVERAGE(F26,F27),"") | G28: =IFERROR(AVERAGE(G26,G27),"") | H28: =IFERROR(IF(ABS(F28)<Control!$B$13,"n/m",E28/F28),"n/m") | I28: =IFERROR(AVERAGE(I26,I27),"") | J28: =IFERROR(AVERAGE(J26,J27),"") | K28: =IFERROR(AVERAGE(K26,K27),"") | L28: =IFERROR(AVERAGE(L26,L27),"") | M28: =IFERROR(AVERAGE(M26,M27),"") | N28: =IFERROR(AVERAGE(N26,N27),"") | O28: =IFERROR(IF(ABS(M28)<Control!$B$13,"n/m",L28/M28),"n/m") | P28: =IFERROR(AVERAGE(P26,P27),"") | Q28: =IFERROR(AVERAGE(Q26,Q27),"") | R28: =IFERROR(AVERAGE(R26,R27),"")
A29: =IFERROR("Middle East: local 10Y "&TEXT($E$28,"+0;-0")&"bp on the month against UST 10Y "&TEXT($F$28,"+0;-0")&"bp, so the gap to Treasuries moved "&TEXT($G$28,"+0;-0")&"bp"&IF(ISNUMBER($H$28)," (pass-through "&TEXT($H$28,"0.00")&"x)","")&". History (2y beta "&TEXT($I$28,"0.00")&") would have predicted "&TEXT($J$28,"+0;-0")&"bp; the surprise is "&TEXT($K$28,"+0;-0")&"bp. YTD: "&TEXT($L$28,"+0;-0")&"bp against "&TEXT($M$28,"+0;-0")&"bp, gap "&TEXT($N$28,"+0;-0")&"bp"&IF(ISNUMBER($O$28)," (pass-through "&TEXT($O$28,"0.00")&"x)","")&". "&IF($K$28<-5,"The curve did better than its own history — absorbed.",IF($K$28>5,"The curve did worse than its own history — imported.","Moved in line with its own history.")),"")
A31: EM ASIA
A32: Country | B32: Region | C32: Level | D32: In avg | E32: 1M: Total move (bp) | F32: 1M: US-driven: d UST 10Y (bp) | G32: 1M: Intrinsic: d gap to UST (bp) | H32: 1M: Pass-through (total / US) | I32: 1M: Beta to UST 10Y (2y) | J32: 1M: Predicted by beta (bp) | K32: 1M: Surprise: actual less predicted (bp) | L32: YTD: Total move (bp) | M32: YTD: US-driven: d UST 10Y (bp) | N32: YTD: Intrinsic: d gap to UST (bp) | O32: YTD: Pass-through (total / US) | P32: YTD: Beta to UST 10Y (2y) | Q32: YTD: Predicted by beta (bp) | R32: YTD: Surprise: actual less predicted (bp)
A33: China | B33: EM Asia | C33: =INDEX(HIST_D!$AR$8:$AR$791,1) | D33: yes | E33: =IFERROR((INDEX(HIST_D!$AR$8:$AR$791,1)-INDEX(HIST_D!$AR$8:$AR$791,Control!$B$10))*100,"") | F33: =IFERROR((INDEX(HIST_D!$D$8:$D$791,1)-INDEX(HIST_D!$D$8:$D$791,Control!$B$10))*100,"") | G33: =IFERROR(E33-F33,"") | H33: =IFERROR(IF(ABS(F33)<Control!$B$13,"n/m",E33/F33),"n/m") | I33: =IFERROR(SLOPE(HIST_D!$CK$8:INDEX(HIST_D!$CK$8:$CK$791,Control!$B$12),HIST_D!$BV$8:INDEX(HIST_D!$BV$8:$BV$791,Control!$B$12)),"") | J33: =IFERROR(I33*(INDEX(HIST_D!$D$8:$D$791,1)-INDEX(HIST_D!$D$8:$D$791,Control!$B$10))*100,"") | K33: =IFERROR(E33-J33,"") | L33: =IFERROR((INDEX(HIST_D!$AR$8:$AR$791,1)-INDEX(HIST_D!$AR$8:$AR$791,Control!$B$11))*100,"") | M33: =IFERROR((INDEX(HIST_D!$D$8:$D$791,1)-INDEX(HIST_D!$D$8:$D$791,Control!$B$11))*100,"") | N33: =IFERROR(L33-M33,"") | O33: =IFERROR(IF(ABS(M33)<Control!$B$13,"n/m",L33/M33),"n/m") | P33: =IFERROR(SLOPE(HIST_D!$CK$8:INDEX(HIST_D!$CK$8:$CK$791,Control!$B$12),HIST_D!$BV$8:INDEX(HIST_D!$BV$8:$BV$791,Control!$B$12)),"") | Q33: =IFERROR(P33*(INDEX(HIST_D!$D$8:$D$791,1)-INDEX(HIST_D!$D$8:$D$791,Control!$B$11))*100,"") | R33: =IFERROR(L33-Q33,"")
A34: India | B34: EM Asia | C34: =INDEX(HIST_D!$AS$8:$AS$791,1) | D34: yes | E34: =IFERROR((INDEX(HIST_D!$AS$8:$AS$791,1)-INDEX(HIST_D!$AS$8:$AS$791,Control!$B$10))*100,"") | F34: =IFERROR((INDEX(HIST_D!$D$8:$D$791,1)-INDEX(HIST_D!$D$8:$D$791,Control!$B$10))*100,"") | G34: =IFERROR(E34-F34,"") | H34: =IFERROR(IF(ABS(F34)<Control!$B$13,"n/m",E34/F34),"n/m") | I34: =IFERROR(SLOPE(HIST_D!$CL$8:INDEX(HIST_D!$CL$8:$CL$791,Control!$B$12),HIST_D!$BV$8:INDEX(HIST_D!$BV$8:$BV$791,Control!$B$12)),"") | J34: =IFERROR(I34*(INDEX(HIST_D!$D$8:$D$791,1)-INDEX(HIST_D!$D$8:$D$791,Control!$B$10))*100,"") | K34: =IFERROR(E34-J34,"") | L34: =IFERROR((INDEX(HIST_D!$AS$8:$AS$791,1)-INDEX(HIST_D!$AS$8:$AS$791,Control!$B$11))*100,"") | M34: =IFERROR((INDEX(HIST_D!$D$8:$D$791,1)-INDEX(HIST_D!$D$8:$D$791,Control!$B$11))*100,"") | N34: =IFERROR(L34-M34,"") | O34: =IFERROR(IF(ABS(M34)<Control!$B$13,"n/m",L34/M34),"n/m") | P34: =IFERROR(SLOPE(HIST_D!$CL$8:INDEX(HIST_D!$CL$8:$CL$791,Control!$B$12),HIST_D!$BV$8:INDEX(HIST_D!$BV$8:$BV$791,Control!$B$12)),"") | Q34: =IFERROR(P34*(INDEX(HIST_D!$D$8:$D$791,1)-INDEX(HIST_D!$D$8:$D$791,Control!$B$11))*100,"") | R34: =IFERROR(L34-Q34,"") | S34: no sovereign USD debt, no CDS — rates and FX only
A35: Indonesia | B35: EM Asia | C35: =INDEX(HIST_D!$AT$8:$AT$791,1) | D35: yes | E35: =IFERROR((INDEX(HIST_D!$AT$8:$AT$791,1)-INDEX(HIST_D!$AT$8:$AT$791,Control!$B$10))*100,"") | F35: =IFERROR((INDEX(HIST_D!$D$8:$D$791,1)-INDEX(HIST_D!$D$8:$D$791,Control!$B$10))*100,"") | G35: =IFERROR(E35-F35,"") | H35: =IFERROR(IF(ABS(F35)<Control!$B$13,"n/m",E35/F35),"n/m") | I35: =IFERROR(SLOPE(HIST_D!$CM$8:INDEX(HIST_D!$CM$8:$CM$791,Control!$B$12),HIST_D!$BV$8:INDEX(HIST_D!$BV$8:$BV$791,Control!$B$12)),"") | J35: =IFERROR(I35*(INDEX(HIST_D!$D$8:$D$791,1)-INDEX(HIST_D!$D$8:$D$791,Control!$B$10))*100,"") | K35: =IFERROR(E35-J35,"") | L35: =IFERROR((INDEX(HIST_D!$AT$8:$AT$791,1)-INDEX(HIST_D!$AT$8:$AT$791,Control!$B$11))*100,"") | M35: =IFERROR((INDEX(HIST_D!$D$8:$D$791,1)-INDEX(HIST_D!$D$8:$D$791,Control!$B$11))*100,"") | N35: =IFERROR(L35-M35,"") | O35: =IFERROR(IF(ABS(M35)<Control!$B$13,"n/m",L35/M35),"n/m") | P35: =IFERROR(SLOPE(HIST_D!$CM$8:INDEX(HIST_D!$CM$8:$CM$791,Control!$B$12),HIST_D!$BV$8:INDEX(HIST_D!$BV$8:$BV$791,Control!$B$12)),"") | Q35: =IFERROR(P35*(INDEX(HIST_D!$D$8:$D$791,1)-INDEX(HIST_D!$D$8:$D$791,Control!$B$11))*100,"") | R35: =IFERROR(L35-Q35,"")
A36: Korea | B36: EM Asia | C36: =INDEX(HIST_D!$AU$8:$AU$791,1) | D36: yes | E36: =IFERROR((INDEX(HIST_D!$AU$8:$AU$791,1)-INDEX(HIST_D!$AU$8:$AU$791,Control!$B$10))*100,"") | F36: =IFERROR((INDEX(HIST_D!$D$8:$D$791,1)-INDEX(HIST_D!$D$8:$D$791,Control!$B$10))*100,"") | G36: =IFERROR(E36-F36,"") | H36: =IFERROR(IF(ABS(F36)<Control!$B$13,"n/m",E36/F36),"n/m") | I36: =IFERROR(SLOPE(HIST_D!$CN$8:INDEX(HIST_D!$CN$8:$CN$791,Control!$B$12),HIST_D!$BV$8:INDEX(HIST_D!$BV$8:$BV$791,Control!$B$12)),"") | J36: =IFERROR(I36*(INDEX(HIST_D!$D$8:$D$791,1)-INDEX(HIST_D!$D$8:$D$791,Control!$B$10))*100,"") | K36: =IFERROR(E36-J36,"") | L36: =IFERROR((INDEX(HIST_D!$AU$8:$AU$791,1)-INDEX(HIST_D!$AU$8:$AU$791,Control!$B$11))*100,"") | M36: =IFERROR((INDEX(HIST_D!$D$8:$D$791,1)-INDEX(HIST_D!$D$8:$D$791,Control!$B$11))*100,"") | N36: =IFERROR(L36-M36,"") | O36: =IFERROR(IF(ABS(M36)<Control!$B$13,"n/m",L36/M36),"n/m") | P36: =IFERROR(SLOPE(HIST_D!$CN$8:INDEX(HIST_D!$CN$8:$CN$791,Control!$B$12),HIST_D!$BV$8:INDEX(HIST_D!$BV$8:$BV$791,Control!$B$12)),"") | Q36: =IFERROR(P36*(INDEX(HIST_D!$D$8:$D$791,1)-INDEX(HIST_D!$D$8:$D$791,Control!$B$11))*100,"") | R36: =IFERROR(L36-Q36,"")
A37: Thailand | B37: EM Asia | C37: =INDEX(HIST_D!$AV$8:$AV$791,1) | D37: yes | E37: =IFERROR((INDEX(HIST_D!$AV$8:$AV$791,1)-INDEX(HIST_D!$AV$8:$AV$791,Control!$B$10))*100,"") | F37: =IFERROR((INDEX(HIST_D!$D$8:$D$791,1)-INDEX(HIST_D!$D$8:$D$791,Control!$B$10))*100,"") | G37: =IFERROR(E37-F37,"") | H37: =IFERROR(IF(ABS(F37)<Control!$B$13,"n/m",E37/F37),"n/m") | I37: =IFERROR(SLOPE(HIST_D!$CO$8:INDEX(HIST_D!$CO$8:$CO$791,Control!$B$12),HIST_D!$BV$8:INDEX(HIST_D!$BV$8:$BV$791,Control!$B$12)),"") | J37: =IFERROR(I37*(INDEX(HIST_D!$D$8:$D$791,1)-INDEX(HIST_D!$D$8:$D$791,Control!$B$10))*100,"") | K37: =IFERROR(E37-J37,"") | L37: =IFERROR((INDEX(HIST_D!$AV$8:$AV$791,1)-INDEX(HIST_D!$AV$8:$AV$791,Control!$B$11))*100,"") | M37: =IFERROR((INDEX(HIST_D!$D$8:$D$791,1)-INDEX(HIST_D!$D$8:$D$791,Control!$B$11))*100,"") | N37: =IFERROR(L37-M37,"") | O37: =IFERROR(IF(ABS(M37)<Control!$B$13,"n/m",L37/M37),"n/m") | P37: =IFERROR(SLOPE(HIST_D!$CO$8:INDEX(HIST_D!$CO$8:$CO$791,Control!$B$12),HIST_D!$BV$8:INDEX(HIST_D!$BV$8:$BV$791,Control!$B$12)),"") | Q37: =IFERROR(P37*(INDEX(HIST_D!$D$8:$D$791,1)-INDEX(HIST_D!$D$8:$D$791,Control!$B$11))*100,"") | R37: =IFERROR(L37-Q37,"")
A38: Malaysia | B38: EM Asia | C38: =INDEX(HIST_D!$AW$8:$AW$791,1) | D38: yes | E38: =IFERROR((INDEX(HIST_D!$AW$8:$AW$791,1)-INDEX(HIST_D!$AW$8:$AW$791,Control!$B$10))*100,"") | F38: =IFERROR((INDEX(HIST_D!$D$8:$D$791,1)-INDEX(HIST_D!$D$8:$D$791,Control!$B$10))*100,"") | G38: =IFERROR(E38-F38,"") | H38: =IFERROR(IF(ABS(F38)<Control!$B$13,"n/m",E38/F38),"n/m") | I38: =IFERROR(SLOPE(HIST_D!$CP$8:INDEX(HIST_D!$CP$8:$CP$791,Control!$B$12),HIST_D!$BV$8:INDEX(HIST_D!$BV$8:$BV$791,Control!$B$12)),"") | J38: =IFERROR(I38*(INDEX(HIST_D!$D$8:$D$791,1)-INDEX(HIST_D!$D$8:$D$791,Control!$B$10))*100,"") | K38: =IFERROR(E38-J38,"") | L38: =IFERROR((INDEX(HIST_D!$AW$8:$AW$791,1)-INDEX(HIST_D!$AW$8:$AW$791,Control!$B$11))*100,"") | M38: =IFERROR((INDEX(HIST_D!$D$8:$D$791,1)-INDEX(HIST_D!$D$8:$D$791,Control!$B$11))*100,"") | N38: =IFERROR(L38-M38,"") | O38: =IFERROR(IF(ABS(M38)<Control!$B$13,"n/m",L38/M38),"n/m") | P38: =IFERROR(SLOPE(HIST_D!$CP$8:INDEX(HIST_D!$CP$8:$CP$791,Control!$B$12),HIST_D!$BV$8:INDEX(HIST_D!$BV$8:$BV$791,Control!$B$12)),"") | Q38: =IFERROR(P38*(INDEX(HIST_D!$D$8:$D$791,1)-INDEX(HIST_D!$D$8:$D$791,Control!$B$11))*100,"") | R38: =IFERROR(L38-Q38,"")
A39: Philippines | B39: EM Asia | C39: =INDEX(HIST_D!$AX$8:$AX$791,1) | D39: yes | E39: =IFERROR((INDEX(HIST_D!$AX$8:$AX$791,1)-INDEX(HIST_D!$AX$8:$AX$791,Control!$B$10))*100,"") | F39: =IFERROR((INDEX(HIST_D!$D$8:$D$791,1)-INDEX(HIST_D!$D$8:$D$791,Control!$B$10))*100,"") | G39: =IFERROR(E39-F39,"") | H39: =IFERROR(IF(ABS(F39)<Control!$B$13,"n/m",E39/F39),"n/m") | I39: =IFERROR(SLOPE(HIST_D!$CQ$8:INDEX(HIST_D!$CQ$8:$CQ$791,Control!$B$12),HIST_D!$BV$8:INDEX(HIST_D!$BV$8:$BV$791,Control!$B$12)),"") | J39: =IFERROR(I39*(INDEX(HIST_D!$D$8:$D$791,1)-INDEX(HIST_D!$D$8:$D$791,Control!$B$10))*100,"") | K39: =IFERROR(E39-J39,"") | L39: =IFERROR((INDEX(HIST_D!$AX$8:$AX$791,1)-INDEX(HIST_D!$AX$8:$AX$791,Control!$B$11))*100,"") | M39: =IFERROR((INDEX(HIST_D!$D$8:$D$791,1)-INDEX(HIST_D!$D$8:$D$791,Control!$B$11))*100,"") | N39: =IFERROR(L39-M39,"") | O39: =IFERROR(IF(ABS(M39)<Control!$B$13,"n/m",L39/M39),"n/m") | P39: =IFERROR(SLOPE(HIST_D!$CQ$8:INDEX(HIST_D!$CQ$8:$CQ$791,Control!$B$12),HIST_D!$BV$8:INDEX(HIST_D!$BV$8:$BV$791,Control!$B$12)),"") | Q39: =IFERROR(P39*(INDEX(HIST_D!$D$8:$D$791,1)-INDEX(HIST_D!$D$8:$D$791,Control!$B$11))*100,"") | R39: =IFERROR(L39-Q39,"")
A40: EM Asia average | B40: n=7 | E40: =IFERROR(AVERAGE(E33,E34,E35,E36,E37,E38,E39),"") | F40: =IFERROR(AVERAGE(F33,F34,F35,F36,F37,F38,F39),"") | G40: =IFERROR(AVERAGE(G33,G34,G35,G36,G37,G38,G39),"") | H40: =IFERROR(IF(ABS(F40)<Control!$B$13,"n/m",E40/F40),"n/m") | I40: =IFERROR(AVERAGE(I33,I34,I35,I36,I37,I38,I39),"") | J40: =IFERROR(AVERAGE(J33,J34,J35,J36,J37,J38,J39),"") | K40: =IFERROR(AVERAGE(K33,K34,K35,K36,K37,K38,K39),"") | L40: =IFERROR(AVERAGE(L33,L34,L35,L36,L37,L38,L39),"") | M40: =IFERROR(AVERAGE(M33,M34,M35,M36,M37,M38,M39),"") | N40: =IFERROR(AVERAGE(N33,N34,N35,N36,N37,N38,N39),"") | O40: =IFERROR(IF(ABS(M40)<Control!$B$13,"n/m",L40/M40),"n/m") | P40: =IFERROR(AVERAGE(P33,P34,P35,P36,P37,P38,P39),"") | Q40: =IFERROR(AVERAGE(Q33,Q34,Q35,Q36,Q37,Q38,Q39),"") | R40: =IFERROR(AVERAGE(R33,R34,R35,R36,R37,R38,R39),"")
A41: =IFERROR("EM Asia: local 10Y "&TEXT($E$40,"+0;-0")&"bp on the month against UST 10Y "&TEXT($F$40,"+0;-0")&"bp, so the gap to Treasuries moved "&TEXT($G$40,"+0;-0")&"bp"&IF(ISNUMBER($H$40)," (pass-through "&TEXT($H$40,"0.00")&"x)","")&". History (2y beta "&TEXT($I$40,"0.00")&") would have predicted "&TEXT($J$40,"+0;-0")&"bp; the surprise is "&TEXT($K$40,"+0;-0")&"bp. YTD: "&TEXT($L$40,"+0;-0")&"bp against "&TEXT($M$40,"+0;-0")&"bp, gap "&TEXT($N$40,"+0;-0")&"bp"&IF(ISNUMBER($O$40)," (pass-through "&TEXT($O$40,"0.00")&"x)","")&". "&IF($K$40<-5,"The curve did better than its own history — absorbed.",IF($K$40>5,"The curve did worse than its own history — imported.","Moved in line with its own history.")),"")
A43: EM AVERAGE AND MEMO
A44: Country | B44: Region | C44: Level | D44: In avg | E44: 1M: Total move (bp) | F44: 1M: US-driven: d UST 10Y (bp) | G44: 1M: Intrinsic: d gap to UST (bp) | H44: 1M: Pass-through (total / US) | I44: 1M: Beta to UST 10Y (2y) | J44: 1M: Predicted by beta (bp) | K44: 1M: Surprise: actual less predicted (bp) | L44: YTD: Total move (bp) | M44: YTD: US-driven: d UST 10Y (bp) | N44: YTD: Intrinsic: d gap to UST (bp) | O44: YTD: Pass-through (total / US) | P44: YTD: Beta to UST 10Y (2y) | Q44: YTD: Predicted by beta (bp) | R44: YTD: Surprise: actual less predicted (bp)
A45: EM average (all flagged) | B45: n=18 | E45: =IFERROR(AVERAGE(E6,E7,E8,E9,E10,E16,E17,E18,E19,E26,E27,E33,E34,E35,E36,E37,E38,E39),"") | F45: =IFERROR(AVERAGE(F6,F7,F8,F9,F10,F16,F17,F18,F19,F26,F27,F33,F34,F35,F36,F37,F38,F39),"") | G45: =IFERROR(AVERAGE(G6,G7,G8,G9,G10,G16,G17,G18,G19,G26,G27,G33,G34,G35,G36,G37,G38,G39),"") | H45: =IFERROR(IF(ABS(F45)<Control!$B$13,"n/m",E45/F45),"n/m") | I45: =IFERROR(AVERAGE(I6,I7,I8,I9,I10,I16,I17,I18,I19,I26,I27,I33,I34,I35,I36,I37,I38,I39),"") | J45: =IFERROR(AVERAGE(J6,J7,J8,J9,J10,J16,J17,J18,J19,J26,J27,J33,J34,J35,J36,J37,J38,J39),"") | K45: =IFERROR(AVERAGE(K6,K7,K8,K9,K10,K16,K17,K18,K19,K26,K27,K33,K34,K35,K36,K37,K38,K39),"") | L45: =IFERROR(AVERAGE(L6,L7,L8,L9,L10,L16,L17,L18,L19,L26,L27,L33,L34,L35,L36,L37,L38,L39),"") | M45: =IFERROR(AVERAGE(M6,M7,M8,M9,M10,M16,M17,M18,M19,M26,M27,M33,M34,M35,M36,M37,M38,M39),"") | N45: =IFERROR(AVERAGE(N6,N7,N8,N9,N10,N16,N17,N18,N19,N26,N27,N33,N34,N35,N36,N37,N38,N39),"") | O45: =IFERROR(IF(ABS(M45)<Control!$B$13,"n/m",L45/M45),"n/m") | P45: =IFERROR(AVERAGE(P6,P7,P8,P9,P10,P16,P17,P18,P19,P26,P27,P33,P34,P35,P36,P37,P38,P39),"") | Q45: =IFERROR(AVERAGE(Q6,Q7,Q8,Q9,Q10,Q16,Q17,Q18,Q19,Q26,Q27,Q33,Q34,Q35,Q36,Q37,Q38,Q39),"") | R45: =IFERROR(AVERAGE(R6,R7,R8,R9,R10,R16,R17,R18,R19,R26,R27,R33,R34,R35,R36,R37,R38,R39),"")
...

Sheet FX
A1: EM CURRENCIES — return on the currency, by country and region
A2: Return on the EM currency (prior/current - 1, so positive = EM strength) = -(DXY return) + return ex-dollar. US-driven is the dollar under a beta of one; intrinsic is what is left after the dollar. Pass-through = total / US-driven.
A4: LATAM
A5: Country | B5: Region | C5: Level | D5: In avg | E5: 1M: Total: return on EM ccy | F5: 1M: US-driven: -(DXY return) | G5: 1M: Intrinsic: return ex-dollar | H5: 1M: Pass-through (total / US) | I5: 1M: Beta to DXY (2y) | J5: 1M: Predicted by beta | K5: 1M: Surprise: actual less predicted | L5: YTD: Total: return on EM ccy | M5: YTD: US-driven: -(DXY return) | N5: YTD: Intrinsic: return ex-dollar | O5: YTD: Pass-through (total / US) | P5: YTD: Beta to DXY (2y) | Q5: YTD: Predicted by beta | R5: YTD: Surprise: actual less predicted
A6: Brazil | B6: LatAm | C6: =INDEX(HIST_D!$L$8:$L$791,1) | D6: yes | E6: =IFERROR((INDEX(HIST_D!$L$8:$L$791,Control!$B$10)/INDEX(HIST_D!$L$8:$L$791,1)-1),"") | F6: =IFERROR(-(INDEX(HIST_D!$I$8:$I$791,1)/INDEX(HIST_D!$I$8:$I$791,Control!$B$10)-1),"") | G6: =IFERROR(E6-F6,"") | H6: =IFERROR(IF(ABS(F6)<0.005,"n/m",E6/F6),"n/m") | I6: =IFERROR(SLOPE(HIST_D!$CS$8:INDEX(HIST_D!$CS$8:$CS$791,Control!$B$12),HIST_D!$BX$8:INDEX(HIST_D!$BX$8:$BX$791,Control!$B$12)),"") | J6: =IFERROR(I6*(INDEX(HIST_D!$I$8:$I$791,1)/INDEX(HIST_D!$I$8:$I$791,Control!$B$10)-1),"") | K6: =IFERROR(E6-J6,"") | L6: =IFERROR((INDEX(HIST_D!$L$8:$L$791,Control!$B$11)/INDEX(HIST_D!$L$8:$L$791,1)-1),"") | M6: =IFERROR(-(INDEX(HIST_D!$I$8:$I$791,1)/INDEX(HIST_D!$I$8:$I$791,Control!$B$11)-1),"") | N6: =IFERROR(L6-M6,"") | O6: =IFERROR(IF(ABS(M6)<0.005,"n/m",L6/M6),"n/m") | P6: =IFERROR(SLOPE(HIST_D!$CS$8:INDEX(HIST_D!$CS$8:$CS$791,Control!$B$12),HIST_D!$BX$8:INDEX(HIST_D!$BX$8:$BX$791,Control!$B$12)),"") | Q6: =IFERROR(P6*(INDEX(HIST_D!$I$8:$I$791,1)/INDEX(HIST_D!$I$8:$I$791,Control!$B$11)-1),"") | R6: =IFERROR(L6-Q6,"")
A7: Mexico | B7: LatAm | C7: =INDEX(HIST_D!$M$8:$M$791,1) | D7: yes | E7: =IFERROR((INDEX(HIST_D!$M$8:$M$791,Control!$B$10)/INDEX(HIST_D!$M$8:$M$791,1)-1),"") | F7: =IFERROR(-(INDEX(HIST_D!$I$8:$I$791,1)/INDEX(HIST_D!$I$8:$I$791,Control!$B$10)-1),"") | G7: =IFERROR(E7-F7,"") | H7: =IFERROR(IF(ABS(F7)<0.005,"n/m",E7/F7),"n/m") | I7: =IFERROR(SLOPE(HIST_D!$CT$8:INDEX(HIST_D!$CT$8:$CT$791,Control!$B$12),HIST_D!$BX$8:INDEX(HIST_D!$BX$8:$BX$791,Control!$B$12)),"") | J7: =IFERROR(I7*(INDEX(HIST_D!$I$8:$I$791,1)/INDEX(HIST_D!$I$8:$I$791,Control!$B$10)-1),"") | K7: =IFERROR(E7-J7,"") | L7: =IFERROR((INDEX(HIST_D!$M$8:$M$791,Control!$B$11)/INDEX(HIST_D!$M$8:$M$791,1)-1),"") | M7: =IFERROR(-(INDEX(HIST_D!$I$8:$I$791,1)/INDEX(HIST_D!$I$8:$I$791,Control!$B$11)-1),"") | N7: =IFERROR(L7-M7,"") | O7: =IFERROR(IF(ABS(M7)<0.005,"n/m",L7/M7),"n/m") | P7: =IFERROR(SLOPE(HIST_D!$CT$8:INDEX(HIST_D!$CT$8:$CT$791,Control!$B$12),HIST_D!$BX$8:INDEX(HIST_D!$BX$8:$BX$791,Control!$B$12)),"") | Q7: =IFERROR(P7*(INDEX(HIST_D!$I$8:$I$791,1)/INDEX(HIST_D!$I$8:$I$791,Control!$B$11)-1),"") | R7: =IFERROR(L7-Q7,"")
A8: Chile | B8: LatAm | C8: =INDEX(HIST_D!$N$8:$N$791,1) | D8: yes | E8: =IFERROR((INDEX(HIST_D!$N$8:$N$791,Control!$B$10)/INDEX(HIST_D!$N$8:$N$791,1)-1),"") | F8: =IFERROR(-(INDEX(HIST_D!$I$8:$I$791,1)/INDEX(HIST_D!$I$8:$I$791,Control!$B$10)-1),"") | G8: =IFERROR(E8-F8,"") | H8: =IFERROR(IF(ABS(F8)<0.005,"n/m",E8/F8),"n/m") | I8: =IFERROR(SLOPE(HIST_D!$CU$8:INDEX(HIST_D!$CU$8:$CU$791,Control!$B$12),HIST_D!$BX$8:INDEX(HIST_D!$BX$8:$BX$791,Control!$B$12)),"") | J8: =IFERROR(I8*(INDEX(HIST_D!$I$8:$I$791,1)/INDEX(HIST_D!$I$8:$I$791,Control!$B$10)-1),"") | K8: =IFERROR(E8-J8,"") | L8: =IFERROR((INDEX(HIST_D!$N$8:$N$791,Control!$B$11)/INDEX(HIST_D!$N$8:$N$791,1)-1),"") | M8: =IFERROR(-(INDEX(HIST_D!$I$8:$I$791,1)/INDEX(HIST_D!$I$8:$I$791,Control!$B$11)-1),"") | N8: =IFERROR(L8-M8,"") | O8: =IFERROR(IF(ABS(M8)<0.005,"n/m",L8/M8),"n/m") | P8: =IFERROR(SLOPE(HIST_D!$CU$8:INDEX(HIST_D!$CU$8:$CU$791,Control!$B$12),HIST_D!$BX$8:INDEX(HIST_D!$BX$8:$BX$791,Control!$B$12)),"") | Q8: =IFERROR(P8*(INDEX(HIST_D!$I$8:$I$791,1)/INDEX(HIST_D!$I$8:$I$791,Control!$B$11)-1),"") | R8: =IFERROR(L8-Q8,"")
A9: Colombia | B9: LatAm | C9: =INDEX(HIST_D!$O$8:$O$791,1) | D9: yes | E9: =IFERROR((INDEX(HIST_D!$O$8:$O$791,Control!$B$10)/INDEX(HIST_D!$O$8:$O$791,1)-1),"") | F9: =IFERROR(-(INDEX(HIST_D!$I$8:$I$791,1)/INDEX(HIST_D!$I$8:$I$791,Control!$B$10)-1),"") | G9: =IFERROR(E9-F9,"") | H9: =IFERROR(IF(ABS(F9)<0.005,"n/m",E9/F9),"n/m") | I9: =IFERROR(SLOPE(HIST_D!$CV$8:INDEX(HIST_D!$CV$8:$CV$791,Control!$B$12),HIST_D!$BX$8:INDEX(HIST_D!$BX$8:$BX$791,Control!$B$12)),"") | J9: =IFERROR(I9*(INDEX(HIST_D!$I$8:$I$791,1)/INDEX(HIST_D!$I$8:$I$791,Control!$B$10)-1),"") | K9: =IFERROR(E9-J9,"") | L9: =IFERROR((INDEX(HIST_D!$O$8:$O$791,Control!$B$11)/INDEX(HIST_D!$O$8:$O$791,1)-1),"") | M9: =IFERROR(-(INDEX(HIST_D!$I$8:$I$791,1)/INDEX(HIST_D!$I$8:$I$791,Control!$B$11)-1),"") | N9: =IFERROR(L9-M9,"") | O9: =IFERROR(IF(ABS(M9)<0.005,"n/m",L9/M9),"n/m") | P9: =IFERROR(SLOPE(HIST_D!$CV$8:INDEX(HIST_D!$CV$8:$CV$791,Control!$B$12),HIST_D!$BX$8:INDEX(HIST_D!$BX$8:$BX$791,Control!$B$12)),"") | Q9: =IFERROR(P9*(INDEX(HIST_D!$I$8:$I$791,1)/INDEX(HIST_D!$I$8:$I$791,Control!$B$11)-1),"") | R9: =IFERROR(L9-Q9,"")
A10: Peru | B10: LatAm | C10: =INDEX(HIST_D!$P$8:$P$791,1) | D10: yes | E10: =IFERROR((INDEX(HIST_D!$P$8:$P$791,Control!$B$10)/INDEX(HIST_D!$P$8:$P$791,1)-1),"") | F10: =IFERROR(-(INDEX(HIST_D!$I$8:$I$791,1)/INDEX(HIST_D!$I$8:$I$791,Control!$B$10)-1),"") | G10: =IFERROR(E10-F10,"") | H10: =IFERROR(IF(ABS(F10)<0.005,"n/m",E10/F10),"n/m") | I10: =IFERROR(SLOPE(HIST_D!$CW$8:INDEX(HIST_D!$CW$8:$CW$791,Control!$B$12),HIST_D!$BX$8:INDEX(HIST_D!$BX$8:$BX$791,Control!$B$12)),"") | J10: =IFERROR(I10*(INDEX(HIST_D!$I$8:$I$791,1)/INDEX(HIST_D!$I$8:$I$791,Control!$B$10)-1),"") | K10: =IFERROR(E10-J10,"") | L10: =IFERROR((INDEX(HIST_D!$P$8:$P$791,Control!$B$11)/INDEX(HIST_D!$P$8:$P$791,1)-1),"") | M10: =IFERROR(-(INDEX(HIST_D!$I$8:$I$791,1)/INDEX(HIST_D!$I$8:$I$791,Control!$B$11)-1),"") | N10: =IFERROR(L10-M10,"") | O10: =IFERROR(IF(ABS(M10)<0.005,"n/m",L10/M10),"n/m") | P10: =IFERROR(SLOPE(HIST_D!$CW$8:INDEX(HIST_D!$CW$8:$CW$791,Control!$B$12),HIST_D!$BX$8:INDEX(HIST_D!$BX$8:$BX$791,Control!$B$12)),"") | Q10: =IFERROR(P10*(INDEX(HIST_D!$I$8:$I$791,1)/INDEX(HIST_D!$I$8:$I$791,Control!$B$11)-1),"") | R10: =IFERROR(L10-Q10,"")
A11: LatAm average | B11: n=5 | E11: =IFERROR(AVERAGE(E6,E7,E8,E9,E10),"") | F11: =IFERROR(AVERAGE(F6,F7,F8,F9,F10),"") | G11: =IFERROR(AVERAGE(G6,G7,G8,G9,G10),"") | H11: =IFERROR(IF(ABS(F11)<0.005,"n/m",E11/F11),"n/m") | I11: =IFERROR(AVERAGE(I6,I7,I8,I9,I10),"") | J11: =IFERROR(AVERAGE(J6,J7,J8,J9,J10),"") | K11: =IFERROR(AVERAGE(K6,K7,K8,K9,K10),"") | L11: =IFERROR(AVERAGE(L6,L7,L8,L9,L10),"") | M11: =IFERROR(AVERAGE(M6,M7,M8,M9,M10),"") | N11: =IFERROR(AVERAGE(N6,N7,N8,N9,N10),"") | O11: =IFERROR(IF(ABS(M11)<0.005,"n/m",L11/M11),"n/m") | P11: =IFERROR(AVERAGE(P6,P7,P8,P9,P10),"") | Q11: =IFERROR(AVERAGE(Q6,Q7,Q8,Q9,Q10),"") | R11: =IFERROR(AVERAGE(R6,R7,R8,R9,R10),"")
A12: =IFERROR("LatAm: the currency returned "&TEXT($E$11,"+0.0%;-0.0%")&" on the month; a beta-of-one to the dollar implies "&TEXT($F$11,"+0.0%;-0.0%")&", so "&TEXT($G$11,"+0.0%;-0.0%")&" is ex-dollar"&IF(ISNUMBER($H$11)," (pass-through "&TEXT($H$11,"0.00")&"x)","")&". Against its 2y beta to DXY of "&TEXT($I$11,"0.00")&" the surprise is "&TEXT($K$11,"+0.0%;-0.0%")&". YTD: "&TEXT($L$11,"+0.0%;-0.0%")&", of which "&TEXT($N$11,"+0.0%;-0.0%")&" ex-dollar. "&IF($K$11>0.005,"Stronger than the dollar relationship implies — intrinsic support.",IF($K$11<-0.005,"Weaker than the dollar relationship implies — intrinsic pressure.","In line with the dollar; nothing EM-specific here.")),"")
A14: EM EUROPE
A15: Country | B15: Region | C15: Level | D15: In avg | E15: 1M: Total: return on EM ccy | F15: 1M: US-driven: -(DXY return) | G15: 1M: Intrinsic: return ex-dollar | H15: 1M: Pass-through (total / US) | I15: 1M: Beta to DXY (2y) | J15: 1M: Predicted by beta | K15: 1M: Surprise: actual less predicted | L15: YTD: Total: return on EM ccy | M15: YTD: US-driven: -(DXY return) | N15: YTD: Intrinsic: return ex-dollar | O15: YTD: Pass-through (total / US) | P15: YTD: Beta to DXY (2y) | Q15: YTD: Predicted by beta | R15: YTD: Surprise: actual less predicted
A16: Poland | B16: EM Europe | C16: =INDEX(HIST_D!$Q$8:$Q$791,1) | D16: yes | E16: =IFERROR((INDEX(HIST_D!$Q$8:$Q$791,Control!$B$10)/INDEX(HIST_D!$Q$8:$Q$791,1)-1),"") | F16: =IFERROR(-(INDEX(HIST_D!$I$8:$I$791,1)/INDEX(HIST_D!$I$8:$I$791,Control!$B$10)-1),"") | G16: =IFERROR(E16-F16,"") | H16: =IFERROR(IF(ABS(F16)<0.005,"n/m",E16/F16),"n/m") | I16: =IFERROR(SLOPE(HIST_D!$CX$8:INDEX(HIST_D!$CX$8:$CX$791,Control!$B$12),HIST_D!$BX$8:INDEX(HIST_D!$BX$8:$BX$791,Control!$B$12)),"") | J16: =IFERROR(I16*(INDEX(HIST_D!$I$8:$I$791,1)/INDEX(HIST_D!$I$8:$I$791,Control!$B$10)-1),"") | K16: =IFERROR(E16-J16,"") | L16: =IFERROR((INDEX(HIST_D!$Q$8:$Q$791,Control!$B$11)/INDEX(HIST_D!$Q$8:$Q$791,1)-1),"") | M16: =IFERROR(-(INDEX(HIST_D!$I$8:$I$791,1)/INDEX(HIST_D!$I$8:$I$791,Control!$B$11)-1),"") | N16: =IFERROR(L16-M16,"") | O16: =IFERROR(IF(ABS(M16)<0.005,"n/m",L16/M16),"n/m") | P16: =IFERROR(SLOPE(HIST_D!$CX$8:INDEX(HIST_D!$CX$8:$CX$791,Control!$B$12),HIST_D!$BX$8:INDEX(HIST_D!$BX$8:$BX$791,Control!$B$12)),"") | Q16: =IFERROR(P16*(INDEX(HIST_D!$I$8:$I$791,1)/INDEX(HIST_D!$I$8:$I$791,Control!$B$11)-1),"") | R16: =IFERROR(L16-Q16,"")
A17: Hungary | B17: EM Europe | C17: =INDEX(HIST_D!$R$8:$R$791,1) | D17: yes | E17: =IFERROR((INDEX(HIST_D!$R$8:$R$791,Control!$B$10)/INDEX(HIST_D!$R$8:$R$791,1)-1),"") | F17: =IFERROR(-(INDEX(HIST_D!$I$8:$I$791,1)/INDEX(HIST_D!$I$8:$I$791,Control!$B$10)-1),"") | G17: =IFERROR(E17-F17,"") | H17: =IFERROR(IF(ABS(F17)<0.005,"n/m",E17/F17),"n/m") | I17: =IFERROR(SLOPE(HIST_D!$CY$8:INDEX(HIST_D!$CY$8:$CY$791,Control!$B$12),HIST_D!$BX$8:INDEX(HIST_D!$BX$8:$BX$791,Control!$B$12)),"") | J17: =IFERROR(I17*(INDEX(HIST_D!$I$8:$I$791,1)/INDEX(HIST_D!$I$8:$I$791,Control!$B$10)-1),"") | K17: =IFERROR(E17-J17,"") | L17: =IFERROR((INDEX(HIST_D!$R$8:$R$791,Control!$B$11)/INDEX(HIST_D!$R$8:$R$791,1)-1),"") | M17: =IFERROR(-(INDEX(HIST_D!$I$8:$I$791,1)/INDEX(HIST_D!$I$8:$I$791,Control!$B$11)-1),"") | N17: =IFERROR(L17-M17,"") | O17: =IFERROR(IF(ABS(M17)<0.005,"n/m",L17/M17),"n/m") | P17: =IFERROR(SLOPE(HIST_D!$CY$8:INDEX(HIST_D!$CY$8:$CY$791,Control!$B$12),HIST_D!$BX$8:INDEX(HIST_D!$BX$8:$BX$791,Control!$B$12)),"") | Q17: =IFERROR(P17*(INDEX(HIST_D!$I$8:$I$791,1)/INDEX(HIST_D!$I$8:$I$791,Control!$B$11)-1),"") | R17: =IFERROR(L17-Q17,"")
A18: Czechia | B18: EM Europe | C18: =INDEX(HIST_D!$S$8:$S$791,1) | D18: yes | E18: =IFERROR((INDEX(HIST_D!$S$8:$S$791,Control!$B$10)/INDEX(HIST_D!$S$8:$S$791,1)-1),"") | F18: =IFERROR(-(INDEX(HIST_D!$I$8:$I$791,1)/INDEX(HIST_D!$I$8:$I$791,Control!$B$10)-1),"") | G18: =IFERROR(E18-F18,"") | H18: =IFERROR(IF(ABS(F18)<0.005,"n/m",E18/F18),"n/m") | I18: =IFERROR(SLOPE(HIST_D!$CZ$8:INDEX(HIST_D!$CZ$8:$CZ$791,Control!$B$12),HIST_D!$BX$8:INDEX(HIST_D!$BX$8:$BX$791,Control!$B$12)),"") | J18: =IFERROR(I18*(INDEX(HIST_D!$I$8:$I$791,1)/INDEX(HIST_D!$I$8:$I$791,Control!$B$10)-1),"") | K18: =IFERROR(E18-J18,"") | L18: =IFERROR((INDEX(HIST_D!$S$8:$S$791,Control!$B$11)/INDEX(HIST_D!$S$8:$S$791,1)-1),"") | M18: =IFERROR(-(INDEX(HIST_D!$I$8:$I$791,1)/INDEX(HIST_D!$I$8:$I$791,Control!$B$11)-1),"") | N18: =IFERROR(L18-M18,"") | O18: =IFERROR(IF(ABS(M18)<0.005,"n/m",L18/M18),"n/m") | P18: =IFERROR(SLOPE(HIST_D!$CZ$8:INDEX(HIST_D!$CZ$8:$CZ$791,Control!$B$12),HIST_D!$BX$8:INDEX(HIST_D!$BX$8:$BX$791,Control!$B$12)),"") | Q18: =IFERROR(P18*(INDEX(HIST_D!$I$8:$I$791,1)/INDEX(HIST_D!$I$8:$I$791,Control!$B$11)-1),"") | R18: =IFERROR(L18-Q18,"")
A19: Romania | B19: EM Europe | C19: =INDEX(HIST_D!$T$8:$T$791,1) | D19: yes | E19: =IFERROR((INDEX(HIST_D!$T$8:$T$791,Control!$B$10)/INDEX(HIST_D!$T$8:$T$791,1)-1),"") | F19: =IFERROR(-(INDEX(HIST_D!$I$8:$I$791,1)/INDEX(HIST_D!$I$8:$I$791,Control!$B$10)-1),"") | G19: =IFERROR(E19-F19,"") | H19: =IFERROR(IF(ABS(F19)<0.005,"n/m",E19/F19),"n/m") | I19: =IFERROR(SLOPE(HIST_D!$DA$8:INDEX(HIST_D!$DA$8:$DA$791,Control!$B$12),HIST_D!$BX$8:INDEX(HIST_D!$BX$8:$BX$791,Control!$B$12)),"") | J19: =IFERROR(I19*(INDEX(HIST_D!$I$8:$I$791,1)/INDEX(HIST_D!$I$8:$I$791,Control!$B$10)-1),"") | K19: =IFERROR(E19-J19,"") | L19: =IFERROR((INDEX(HIST_D!$T$8:$T$791,Control!$B$11)/INDEX(HIST_D!$T$8:$T$791,1)-1),"") | M19: =IFERROR(-(INDEX(HIST_D!$I$8:$I$791,1)/INDEX(HIST_D!$I$8:$I$791,Control!$B$11)-1),"") | N19: =IFERROR(L19-M19,"") | O19: =IFERROR(IF(ABS(M19)<0.005,"n/m",L19/M19),"n/m") | P19: =IFERROR(SLOPE(HIST_D!$DA$8:INDEX(HIST_D!$DA$8:$DA$791,Control!$B$12),HIST_D!$BX$8:INDEX(HIST_D!$BX$8:$BX$791,Control!$B$12)),"") | Q19: =IFERROR(P19*(INDEX(HIST_D!$I$8:$I$791,1)/INDEX(HIST_D!$I$8:$I$791,Control!$B$11)-1),"") | R19: =IFERROR(L19-Q19,"")
