Workbook

Sheet Data
A1: MSCI EM Country Indices (USD) — Total Return Performance
A3: Refresh | B3: =Settings!B4 | D3: Custom date | E3: =Settings!B8
A5: Bloomberg Ticker | B5: Country | C5: Region | D5: Price | E5: TR YTD | F5: TR 1M | G5: TR 3M | H5: TR vs Custom
A6: Aggregate
A7: MXEF Index | B7: MSCI Emerging Markets (USD) | C7: Aggregate | D7: =IFERROR(BDP(A7,"PX_LAST"),"") | E7: =IFERROR(BDP(A7,"CUST_TRR_RETURN_HOLDING_PER","CUST_TRR_START_DT",Settings!$C$5,"CUST_TRR_END_DT",Settings!$C$4)/100,"") | F7: =IFERROR(BDP(A7,"CUST_TRR_RETURN_HOLDING_PER","CUST_TRR_START_DT",Settings!$C$6,"CUST_TRR_END_DT",Settings!$C$4)/100,"") | G7: =IFERROR(BDP(A7,"CUST_TRR_RETURN_HOLDING_PER","CUST_TRR_START_DT",Settings!$C$7,"CUST_TRR_END_DT",Settings!$C$4)/100,"") | H7: =IFERROR(BDP(A7,"CUST_TRR_RETURN_HOLDING_PER","CUST_TRR_START_DT",Settings!$C$8,"CUST_TRR_END_DT",Settings!$C$4)/100,"")
A8: MXEM Index | B8: MSCI EM IMI (USD) | C8: Aggregate | D8: =IFERROR(BDP(A8,"PX_LAST"),"") | E8: =IFERROR(BDP(A8,"CUST_TRR_RETURN_HOLDING_PER","CUST_TRR_START_DT",Settings!$C$5,"CUST_TRR_END_DT",Settings!$C$4)/100,"") | F8: =IFERROR(BDP(A8,"CUST_TRR_RETURN_HOLDING_PER","CUST_TRR_START_DT",Settings!$C$6,"CUST_TRR_END_DT",Settings!$C$4)/100,"") | G8: =IFERROR(BDP(A8,"CUST_TRR_RETURN_HOLDING_PER","CUST_TRR_START_DT",Settings!$C$7,"CUST_TRR_END_DT",Settings!$C$4)/100,"") | H8: =IFERROR(BDP(A8,"CUST_TRR_RETURN_HOLDING_PER","CUST_TRR_START_DT",Settings!$C$8,"CUST_TRR_END_DT",Settings!$C$4)/100,"")
A9: MXFM Index | B9: MSCI Frontier Markets (USD) | C9: Aggregate | D9: =IFERROR(BDP(A9,"PX_LAST"),"") | E9: =IFERROR(BDP(A9,"CUST_TRR_RETURN_HOLDING_PER","CUST_TRR_START_DT",Settings!$C$5,"CUST_TRR_END_DT",Settings!$C$4)/100,"") | F9: =IFERROR(BDP(A9,"CUST_TRR_RETURN_HOLDING_PER","CUST_TRR_START_DT",Settings!$C$6,"CUST_TRR_END_DT",Settings!$C$4)/100,"") | G9: =IFERROR(BDP(A9,"CUST_TRR_RETURN_HOLDING_PER","CUST_TRR_START_DT",Settings!$C$7,"CUST_TRR_END_DT",Settings!$C$4)/100,"") | H9: =IFERROR(BDP(A9,"CUST_TRR_RETURN_HOLDING_PER","CUST_TRR_START_DT",Settings!$C$8,"CUST_TRR_END_DT",Settings!$C$4)/100,"")
A10: EMEA Europe
A11: MXPO Index | B11: MSCI Poland (USD) | C11: EMEA Europe | D11: =IFERROR(BDP(A11,"PX_LAST"),"") | E11: =IFERROR(BDP(A11,"CUST_TRR_RETURN_HOLDING_PER","CUST_TRR_START_DT",Settings!$C$5,"CUST_TRR_END_DT",Settings!$C$4)/100,"") | F11: =IFERROR(BDP(A11,"CUST_TRR_RETURN_HOLDING_PER","CUST_TRR_START_DT",Settings!$C$6,"CUST_TRR_END_DT",Settings!$C$4)/100,"") | G11: =IFERROR(BDP(A11,"CUST_TRR_RETURN_HOLDING_PER","CUST_TRR_START_DT",Settings!$C$7,"CUST_TRR_END_DT",Settings!$C$4)/100,"") | H11: =IFERROR(BDP(A11,"CUST_TRR_RETURN_HOLDING_PER","CUST_TRR_START_DT",Settings!$C$8,"CUST_TRR_END_DT",Settings!$C$4)/100,"")
A12: MXHU Index | B12: MSCI Hungary (USD) | C12: EMEA Europe | D12: =IFERROR(BDP(A12,"PX_LAST"),"") | E12: =IFERROR(BDP(A12,"CUST_TRR_RETURN_HOLDING_PER","CUST_TRR_START_DT",Settings!$C$5,"CUST_TRR_END_DT",Settings!$C$4)/100,"") | F12: =IFERROR(BDP(A12,"CUST_TRR_RETURN_HOLDING_PER","CUST_TRR_START_DT",Settings!$C$6,"CUST_TRR_END_DT",Settings!$C$4)/100,"") | G12: =IFERROR(BDP(A12,"CUST_TRR_RETURN_HOLDING_PER","CUST_TRR_START_DT",Settings!$C$7,"CUST_TRR_END_DT",Settings!$C$4)/100,"") | H12: =IFERROR(BDP(A12,"CUST_TRR_RETURN_HOLDING_PER","CUST_TRR_START_DT",Settings!$C$8,"CUST_TRR_END_DT",Settings!$C$4)/100,"")
A13: MXCZ Index | B13: MSCI Czech Republic (USD) | C13: EMEA Europe | D13: =IFERROR(BDP(A13,"PX_LAST"),"") | E13: =IFERROR(BDP(A13,"CUST_TRR_RETURN_HOLDING_PER","CUST_TRR_START_DT",Settings!$C$5,"CUST_TRR_END_DT",Settings!$C$4)/100,"") | F13: =IFERROR(BDP(A13,"CUST_TRR_RETURN_HOLDING_PER","CUST_TRR_START_DT",Settings!$C$6,"CUST_TRR_END_DT",Settings!$C$4)/100,"") | G13: =IFERROR(BDP(A13,"CUST_TRR_RETURN_HOLDING_PER","CUST_TRR_START_DT",Settings!$C$7,"CUST_TRR_END_DT",Settings!$C$4)/100,"") | H13: =IFERROR(BDP(A13,"CUST_TRR_RETURN_HOLDING_PER","CUST_TRR_START_DT",Settings!$C$8,"CUST_TRR_END_DT",Settings!$C$4)/100,"")
A14: MXGR Index | B14: MSCI Greece (USD) | C14: EMEA Europe | D14: =IFERROR(BDP(A14,"PX_LAST"),"") | E14: =IFERROR(BDP(A14,"CUST_TRR_RETURN_HOLDING_PER","CUST_TRR_START_DT",Settings!$C$5,"CUST_TRR_END_DT",Settings!$C$4)/100,"") | F14: =IFERROR(BDP(A14,"CUST_TRR_RETURN_HOLDING_PER","CUST_TRR_START_DT",Settings!$C$6,"CUST_TRR_END_DT",Settings!$C$4)/100,"") | G14: =IFERROR(BDP(A14,"CUST_TRR_RETURN_HOLDING_PER","CUST_TRR_START_DT",Settings!$C$7,"CUST_TRR_END_DT",Settings!$C$4)/100,"") | H14: =IFERROR(BDP(A14,"CUST_TRR_RETURN_HOLDING_PER","CUST_TRR_START_DT",Settings!$C$8,"CUST_TRR_END_DT",Settings!$C$4)/100,"")
A15: MXTR Index | B15: MSCI Turkey (USD) | C15: EMEA Europe | D15: =IFERROR(BDP(A15,"PX_LAST"),"") | E15: =IFERROR(BDP(A15,"CUST_TRR_RETURN_HOLDING_PER","CUST_TRR_START_DT",Settings!$C$5,"CUST_TRR_END_DT",Settings!$C$4)/100,"") | F15: =IFERROR(BDP(A15,"CUST_TRR_RETURN_HOLDING_PER","CUST_TRR_START_DT",Settings!$C$6,"CUST_TRR_END_DT",Settings!$C$4)/100,"") | G15: =IFERROR(BDP(A15,"CUST_TRR_RETURN_HOLDING_PER","CUST_TRR_START_DT",Settings!$C$7,"CUST_TRR_END_DT",Settings!$C$4)/100,"") | H15: =IFERROR(BDP(A15,"CUST_TRR_RETURN_HOLDING_PER","CUST_TRR_START_DT",Settings!$C$8,"CUST_TRR_END_DT",Settings!$C$4)/100,"")
A16: MENA / GCC
A17: MXSA Index | B17: MSCI Saudi Arabia (USD) | C17: MENA / GCC | D17: =IFERROR(BDP(A17,"PX_LAST"),"") | E17: =IFERROR(BDP(A17,"CUST_TRR_RETURN_HOLDING_PER","CUST_TRR_START_DT",Settings!$C$5,"CUST_TRR_END_DT",Settings!$C$4)/100,"") | F17: =IFERROR(BDP(A17,"CUST_TRR_RETURN_HOLDING_PER","CUST_TRR_START_DT",Settings!$C$6,"CUST_TRR_END_DT",Settings!$C$4)/100,"") | G17: =IFERROR(BDP(A17,"CUST_TRR_RETURN_HOLDING_PER","CUST_TRR_START_DT",Settings!$C$7,"CUST_TRR_END_DT",Settings!$C$4)/100,"") | H17: =IFERROR(BDP(A17,"CUST_TRR_RETURN_HOLDING_PER","CUST_TRR_START_DT",Settings!$C$8,"CUST_TRR_END_DT",Settings!$C$4)/100,"")
A18: MXAE Index | B18: MSCI UAE (USD) | C18: MENA / GCC | D18: =IFERROR(BDP(A18,"PX_LAST"),"") | E18: =IFERROR(BDP(A18,"CUST_TRR_RETURN_HOLDING_PER","CUST_TRR_START_DT",Settings!$C$5,"CUST_TRR_END_DT",Settings!$C$4)/100,"") | F18: =IFERROR(BDP(A18,"CUST_TRR_RETURN_HOLDING_PER","CUST_TRR_START_DT",Settings!$C$6,"CUST_TRR_END_DT",Settings!$C$4)/100,"") | G18: =IFERROR(BDP(A18,"CUST_TRR_RETURN_HOLDING_PER","CUST_TRR_START_DT",Settings!$C$7,"CUST_TRR_END_DT",Settings!$C$4)/100,"") | H18: =IFERROR(BDP(A18,"CUST_TRR_RETURN_HOLDING_PER","CUST_TRR_START_DT",Settings!$C$8,"CUST_TRR_END_DT",Settings!$C$4)/100,"")
A19: MXQA Index | B19: MSCI Qatar (USD) | C19: MENA / GCC | D19: =IFERROR(BDP(A19,"PX_LAST"),"") | E19: =IFERROR(BDP(A19,"CUST_TRR_RETURN_HOLDING_PER","CUST_TRR_START_DT",Settings!$C$5,"CUST_TRR_END_DT",Settings!$C$4)/100,"") | F19: =IFERROR(BDP(A19,"CUST_TRR_RETURN_HOLDING_PER","CUST_TRR_START_DT",Settings!$C$6,"CUST_TRR_END_DT",Settings!$C$4)/100,"") | G19: =IFERROR(BDP(A19,"CUST_TRR_RETURN_HOLDING_PER","CUST_TRR_START_DT",Settings!$C$7,"CUST_TRR_END_DT",Settings!$C$4)/100,"") | H19: =IFERROR(BDP(A19,"CUST_TRR_RETURN_HOLDING_PER","CUST_TRR_START_DT",Settings!$C$8,"CUST_TRR_END_DT",Settings!$C$4)/100,"")
A20: MXKW Index | B20: MSCI Kuwait (USD) | C20: MENA / GCC | D20: =IFERROR(BDP(A20,"PX_LAST"),"") | E20: =IFERROR(BDP(A20,"CUST_TRR_RETURN_HOLDING_PER","CUST_TRR_START_DT",Settings!$C$5,"CUST_TRR_END_DT",Settings!$C$4)/100,"") | F20: =IFERROR(BDP(A20,"CUST_TRR_RETURN_HOLDING_PER","CUST_TRR_START_DT",Settings!$C$6,"CUST_TRR_END_DT",Settings!$C$4)/100,"") | G20: =IFERROR(BDP(A20,"CUST_TRR_RETURN_HOLDING_PER","CUST_TRR_START_DT",Settings!$C$7,"CUST_TRR_END_DT",Settings!$C$4)/100,"") | H20: =IFERROR(BDP(A20,"CUST_TRR_RETURN_HOLDING_PER","CUST_TRR_START_DT",Settings!$C$8,"CUST_TRR_END_DT",Settings!$C$4)/100,"")
A21: MXEG Index | B21: MSCI Egypt (USD) | C21: MENA / GCC | D21: =IFERROR(BDP(A21,"PX_LAST"),"") | E21: =IFERROR(BDP(A21,"CUST_TRR_RETURN_HOLDING_PER","CUST_TRR_START_DT",Settings!$C$5,"CUST_TRR_END_DT",Settings!$C$4)/100,"") | F21: =IFERROR(BDP(A21,"CUST_TRR_RETURN_HOLDING_PER","CUST_TRR_START_DT",Settings!$C$6,"CUST_TRR_END_DT",Settings!$C$4)/100,"") | G21: =IFERROR(BDP(A21,"CUST_TRR_RETURN_HOLDING_PER","CUST_TRR_START_DT",Settings!$C$7,"CUST_TRR_END_DT",Settings!$C$4)/100,"") | H21: =IFERROR(BDP(A21,"CUST_TRR_RETURN_HOLDING_PER","CUST_TRR_START_DT",Settings!$C$8,"CUST_TRR_END_DT",Settings!$C$4)/100,"")
A22: Africa
A23: MXZA Index | B23: MSCI South Africa (USD) | C23: Africa | D23: =IFERROR(BDP(A23,"PX_LAST"),"") | E23: =IFERROR(BDP(A23,"CUST_TRR_RETURN_HOLDING_PER","CUST_TRR_START_DT",Settings!$C$5,"CUST_TRR_END_DT",Settings!$C$4)/100,"") | F23: =IFERROR(BDP(A23,"CUST_TRR_RETURN_HOLDING_PER","CUST_TRR_START_DT",Settings!$C$6,"CUST_TRR_END_DT",Settings!$C$4)/100,"") | G23: =IFERROR(BDP(A23,"CUST_TRR_RETURN_HOLDING_PER","CUST_TRR_START_DT",Settings!$C$7,"CUST_TRR_END_DT",Settings!$C$4)/100,"") | H23: =IFERROR(BDP(A23,"CUST_TRR_RETURN_HOLDING_PER","CUST_TRR_START_DT",Settings!$C$8,"CUST_TRR_END_DT",Settings!$C$4)/100,"")
A24: LatAm
A25: MXBR Index | B25: MSCI Brazil (USD) | C25: LatAm | D25: =IFERROR(BDP(A25,"PX_LAST"),"") | E25: =IFERROR(BDP(A25,"CUST_TRR_RETURN_HOLDING_PER","CUST_TRR_START_DT",Settings!$C$5,"CUST_TRR_END_DT",Settings!$C$4)/100,"") | F25: =IFERROR(BDP(A25,"CUST_TRR_RETURN_HOLDING_PER","CUST_TRR_START_DT",Settings!$C$6,"CUST_TRR_END_DT",Settings!$C$4)/100,"") | G25: =IFERROR(BDP(A25,"CUST_TRR_RETURN_HOLDING_PER","CUST_TRR_START_DT",Settings!$C$7,"CUST_TRR_END_DT",Settings!$C$4)/100,"") | H25: =IFERROR(BDP(A25,"CUST_TRR_RETURN_HOLDING_PER","CUST_TRR_START_DT",Settings!$C$8,"CUST_TRR_END_DT",Settings!$C$4)/100,"")
A26: MXMX Index | B26: MSCI Mexico (USD) | C26: LatAm | D26: =IFERROR(BDP(A26,"PX_LAST"),"") | E26: =IFERROR(BDP(A26,"CUST_TRR_RETURN_HOLDING_PER","CUST_TRR_START_DT",Settings!$C$5,"CUST_TRR_END_DT",Settings!$C$4)/100,"") | F26: =IFERROR(BDP(A26,"CUST_TRR_RETURN_HOLDING_PER","CUST_TRR_START_DT",Settings!$C$6,"CUST_TRR_END_DT",Settings!$C$4)/100,"") | G26: =IFERROR(BDP(A26,"CUST_TRR_RETURN_HOLDING_PER","CUST_TRR_START_DT",Settings!$C$7,"CUST_TRR_END_DT",Settings!$C$4)/100,"") | H26: =IFERROR(BDP(A26,"CUST_TRR_RETURN_HOLDING_PER","CUST_TRR_START_DT",Settings!$C$8,"CUST_TRR_END_DT",Settings!$C$4)/100,"")
A27: MXCL Index | B27: MSCI Chile (USD) | C27: LatAm | D27: =IFERROR(BDP(A27,"PX_LAST"),"") | E27: =IFERROR(BDP(A27,"CUST_TRR_RETURN_HOLDING_PER","CUST_TRR_START_DT",Settings!$C$5,"CUST_TRR_END_DT",Settings!$C$4)/100,"") | F27: =IFERROR(BDP(A27,"CUST_TRR_RETURN_HOLDING_PER","CUST_TRR_START_DT",Settings!$C$6,"CUST_TRR_END_DT",Settings!$C$4)/100,"") | G27: =IFERROR(BDP(A27,"CUST_TRR_RETURN_HOLDING_PER","CUST_TRR_START_DT",Settings!$C$7,"CUST_TRR_END_DT",Settings!$C$4)/100,"") | H27: =IFERROR(BDP(A27,"CUST_TRR_RETURN_HOLDING_PER","CUST_TRR_START_DT",Settings!$C$8,"CUST_TRR_END_DT",Settings!$C$4)/100,"")
A28: MXCO Index | B28: MSCI Colombia (USD) | C28: LatAm | D28: =IFERROR(BDP(A28,"PX_LAST"),"") | E28: =IFERROR(BDP(A28,"CUST_TRR_RETURN_HOLDING_PER","CUST_TRR_START_DT",Settings!$C$5,"CUST_TRR_END_DT",Settings!$C$4)/100,"") | F28: =IFERROR(BDP(A28,"CUST_TRR_RETURN_HOLDING_PER","CUST_TRR_START_DT",Settings!$C$6,"CUST_TRR_END_DT",Settings!$C$4)/100,"") | G28: =IFERROR(BDP(A28,"CUST_TRR_RETURN_HOLDING_PER","CUST_TRR_START_DT",Settings!$C$7,"CUST_TRR_END_DT",Settings!$C$4)/100,"") | H28: =IFERROR(BDP(A28,"CUST_TRR_RETURN_HOLDING_PER","CUST_TRR_START_DT",Settings!$C$8,"CUST_TRR_END_DT",Settings!$C$4)/100,"")
A29: MXPE Index | B29: MSCI Peru (USD) | C29: LatAm | D29: =IFERROR(BDP(A29,"PX_LAST"),"") | E29: =IFERROR(BDP(A29,"CUST_TRR_RETURN_HOLDING_PER","CUST_TRR_START_DT",Settings!$C$5,"CUST_TRR_END_DT",Settings!$C$4)/100,"") | F29: =IFERROR(BDP(A29,"CUST_TRR_RETURN_HOLDING_PER","CUST_TRR_START_DT",Settings!$C$6,"CUST_TRR_END_DT",Settings!$C$4)/100,"") | G29: =IFERROR(BDP(A29,"CUST_TRR_RETURN_HOLDING_PER","CUST_TRR_START_DT",Settings!$C$7,"CUST_TRR_END_DT",Settings!$C$4)/100,"") | H29: =IFERROR(BDP(A29,"CUST_TRR_RETURN_HOLDING_PER","CUST_TRR_START_DT",Settings!$C$8,"CUST_TRR_END_DT",Settings!$C$4)/100,"")
A30: MXAR Index | B30: MSCI Argentina (USD) | C30: LatAm | D30: =IFERROR(BDP(A30,"PX_LAST"),"") | E30: =IFERROR(BDP(A30,"CUST_TRR_RETURN_HOLDING_PER","CUST_TRR_START_DT",Settings!$C$5,"CUST_TRR_END_DT",Settings!$C$4)/100,"") | F30: =IFERROR(BDP(A30,"CUST_TRR_RETURN_HOLDING_PER","CUST_TRR_START_DT",Settings!$C$6,"CUST_TRR_END_DT",Settings!$C$4)/100,"") | G30: =IFERROR(BDP(A30,"CUST_TRR_RETURN_HOLDING_PER","CUST_TRR_START_DT",Settings!$C$7,"CUST_TRR_END_DT",Settings!$C$4)/100,"") | H30: =IFERROR(BDP(A30,"CUST_TRR_RETURN_HOLDING_PER","CUST_TRR_START_DT",Settings!$C$8,"CUST_TRR_END_DT",Settings!$C$4)/100,"")
A31: EM Asia
A32: MXCN Index | B32: MSCI China (USD) | C32: EM Asia | D32: =IFERROR(BDP(A32,"PX_LAST"),"") | E32: =IFERROR(BDP(A32,"CUST_TRR_RETURN_HOLDING_PER","CUST_TRR_START_DT",Settings!$C$5,"CUST_TRR_END_DT",Settings!$C$4)/100,"") | F32: =IFERROR(BDP(A32,"CUST_TRR_RETURN_HOLDING_PER","CUST_TRR_START_DT",Settings!$C$6,"CUST_TRR_END_DT",Settings!$C$4)/100,"") | G32: =IFERROR(BDP(A32,"CUST_TRR_RETURN_HOLDING_PER","CUST_TRR_START_DT",Settings!$C$7,"CUST_TRR_END_DT",Settings!$C$4)/100,"") | H32: =IFERROR(BDP(A32,"CUST_TRR_RETURN_HOLDING_PER","CUST_TRR_START_DT",Settings!$C$8,"CUST_TRR_END_DT",Settings!$C$4)/100,"")
A33: MXIN Index | B33: MSCI India (USD) | C33: EM Asia | D33: =IFERROR(BDP(A33,"PX_LAST"),"") | E33: =IFERROR(BDP(A33,"CUST_TRR_RETURN_HOLDING_PER","CUST_TRR_START_DT",Settings!$C$5,"CUST_TRR_END_DT",Settings!$C$4)/100,"") | F33: =IFERROR(BDP(A33,"CUST_TRR_RETURN_HOLDING_PER","CUST_TRR_START_DT",Settings!$C$6,"CUST_TRR_END_DT",Settings!$C$4)/100,"") | G33: =IFERROR(BDP(A33,"CUST_TRR_RETURN_HOLDING_PER","CUST_TRR_START_DT",Settings!$C$7,"CUST_TRR_END_DT",Settings!$C$4)/100,"") | H33: =IFERROR(BDP(A33,"CUST_TRR_RETURN_HOLDING_PER","CUST_TRR_START_DT",Settings!$C$8,"CUST_TRR_END_DT",Settings!$C$4)/100,"")
A34: MXKR Index | B34: MSCI Korea (USD) | C34: EM Asia | D34: =IFERROR(BDP(A34,"PX_LAST"),"") | E34: =IFERROR(BDP(A34,"CUST_TRR_RETURN_HOLDING_PER","CUST_TRR_START_DT",Settings!$C$5,"CUST_TRR_END_DT",Settings!$C$4)/100,"") | F34: =IFERROR(BDP(A34,"CUST_TRR_RETURN_HOLDING_PER","CUST_TRR_START_DT",Settings!$C$6,"CUST_TRR_END_DT",Settings!$C$4)/100,"") | G34: =IFERROR(BDP(A34,"CUST_TRR_RETURN_HOLDING_PER","CUST_TRR_START_DT",Settings!$C$7,"CUST_TRR_END_DT",Settings!$C$4)/100,"") | H34: =IFERROR(BDP(A34,"CUST_TRR_RETURN_HOLDING_PER","CUST_TRR_START_DT",Settings!$C$8,"CUST_TRR_END_DT",Settings!$C$4)/100,"")
A35: MXTW Index | B35: MSCI Taiwan (USD) | C35: EM Asia | D35: =IFERROR(BDP(A35,"PX_LAST"),"") | E35: =IFERROR(BDP(A35,"CUST_TRR_RETURN_HOLDING_PER","CUST_TRR_START_DT",Settings!$C$5,"CUST_TRR_END_DT",Settings!$C$4)/100,"") | F35: =IFERROR(BDP(A35,"CUST_TRR_RETURN_HOLDING_PER","CUST_TRR_START_DT",Settings!$C$6,"CUST_TRR_END_DT",Settings!$C$4)/100,"") | G35: =IFERROR(BDP(A35,"CUST_TRR_RETURN_HOLDING_PER","CUST_TRR_START_DT",Settings!$C$7,"CUST_TRR_END_DT",Settings!$C$4)/100,"") | H35: =IFERROR(BDP(A35,"CUST_TRR_RETURN_HOLDING_PER","CUST_TRR_START_DT",Settings!$C$8,"CUST_TRR_END_DT",Settings!$C$4)/100,"")
A36: MXTH Index | B36: MSCI Thailand (USD) | C36: EM Asia | D36: =IFERROR(BDP(A36,"PX_LAST"),"") | E36: =IFERROR(BDP(A36,"CUST_TRR_RETURN_HOLDING_PER","CUST_TRR_START_DT",Settings!$C$5,"CUST_TRR_END_DT",Settings!$C$4)/100,"") | F36: =IFERROR(BDP(A36,"CUST_TRR_RETURN_HOLDING_PER","CUST_TRR_START_DT",Settings!$C$6,"CUST_TRR_END_DT",Settings!$C$4)/100,"") | G36: =IFERROR(BDP(A36,"CUST_TRR_RETURN_HOLDING_PER","CUST_TRR_START_DT",Settings!$C$7,"CUST_TRR_END_DT",Settings!$C$4)/100,"") | H36: =IFERROR(BDP(A36,"CUST_TRR_RETURN_HOLDING_PER","CUST_TRR_START_DT",Settings!$C$8,"CUST_TRR_END_DT",Settings!$C$4)/100,"")
A37: MXID Index | B37: MSCI Indonesia (USD) | C37: EM Asia | D37: =IFERROR(BDP(A37,"PX_LAST"),"") | E37: =IFERROR(BDP(A37,"CUST_TRR_RETURN_HOLDING_PER","CUST_TRR_START_DT",Settings!$C$5,"CUST_TRR_END_DT",Settings!$C$4)/100,"") | F37: =IFERROR(BDP(A37,"CUST_TRR_RETURN_HOLDING_PER","CUST_TRR_START_DT",Settings!$C$6,"CUST_TRR_END_DT",Settings!$C$4)/100,"") | G37: =IFERROR(BDP(A37,"CUST_TRR_RETURN_HOLDING_PER","CUST_TRR_START_DT",Settings!$C$7,"CUST_TRR_END_DT",Settings!$C$4)/100,"") | H37: =IFERROR(BDP(A37,"CUST_TRR_RETURN_HOLDING_PER","CUST_TRR_START_DT",Settings!$C$8,"CUST_TRR_END_DT",Settings!$C$4)/100,"")
A38: MXMY Index | B38: MSCI Malaysia (USD) | C38: EM Asia | D38: =IFERROR(BDP(A38,"PX_LAST"),"") | E38: =IFERROR(BDP(A38,"CUST_TRR_RETURN_HOLDING_PER","CUST_TRR_START_DT",Settings!$C$5,"CUST_TRR_END_DT",Settings!$C$4)/100,"") | F38: =IFERROR(BDP(A38,"CUST_TRR_RETURN_HOLDING_PER","CUST_TRR_START_DT",Settings!$C$6,"CUST_TRR_END_DT",Settings!$C$4)/100,"") | G38: =IFERROR(BDP(A38,"CUST_TRR_RETURN_HOLDING_PER","CUST_TRR_START_DT",Settings!$C$7,"CUST_TRR_END_DT",Settings!$C$4)/100,"") | H38: =IFERROR(BDP(A38,"CUST_TRR_RETURN_HOLDING_PER","CUST_TRR_START_DT",Settings!$C$8,"CUST_TRR_END_DT",Settings!$C$4)/100,"")
A39: MXPH Index | B39: MSCI Philippines (USD) | C39: EM Asia | D39: =IFERROR(BDP(A39,"PX_LAST"),"") | E39: =IFERROR(BDP(A39,"CUST_TRR_RETURN_HOLDING_PER","CUST_TRR_START_DT",Settings!$C$5,"CUST_TRR_END_DT",Settings!$C$4)/100,"") | F39: =IFERROR(BDP(A39,"CUST_TRR_RETURN_HOLDING_PER","CUST_TRR_START_DT",Settings!$C$6,"CUST_TRR_END_DT",Settings!$C$4)/100,"") | G39: =IFERROR(BDP(A39,"CUST_TRR_RETURN_HOLDING_PER","CUST_TRR_START_DT",Settings!$C$7,"CUST_TRR_END_DT",Settings!$C$4)/100,"") | H39: =IFERROR(BDP(A39,"CUST_TRR_RETURN_HOLDING_PER","CUST_TRR_START_DT",Settings!$C$8,"CUST_TRR_END_DT",Settings!$C$4)/100,"")
A40: MXPK Index | B40: MSCI Pakistan (USD) | C40: EM Asia | D40: =IFERROR(BDP(A40,"PX_LAST"),"") | E40: =IFERROR(BDP(A40,"CUST_TRR_RETURN_HOLDING_PER","CUST_TRR_START_DT",Settings!$C$5,"CUST_TRR_END_DT",Settings!$C$4)/100,"") | F40: =IFERROR(BDP(A40,"CUST_TRR_RETURN_HOLDING_PER","CUST_TRR_START_DT",Settings!$C$6,"CUST_TRR_END_DT",Settings!$C$4)/100,"") | G40: =IFERROR(BDP(A40,"CUST_TRR_RETURN_HOLDING_PER","CUST_TRR_START_DT",Settings!$C$7,"CUST_TRR_END_DT",Settings!$C$4)/100,"") | H40: =IFERROR(BDP(A40,"CUST_TRR_RETURN_HOLDING_PER","CUST_TRR_START_DT",Settings!$C$8,"CUST_TRR_END_DT",Settings!$C$4)/100,"")
A41: MXVT Index | B41: MSCI Vietnam (USD) | C41: EM Asia | D41: =IFERROR(BDP(A41,"PX_LAST"),"") | E41: =IFERROR(BDP(A41,"CUST_TRR_RETURN_HOLDING_PER","CUST_TRR_START_DT",Settings!$C$5,"CUST_TRR_END_DT",Settings!$C$4)/100,"") | F41: =IFERROR(BDP(A41,"CUST_TRR_RETURN_HOLDING_PER","CUST_TRR_START_DT",Settings!$C$6,"CUST_TRR_END_DT",Settings!$C$4)/100,"") | G41: =IFERROR(BDP(A41,"CUST_TRR_RETURN_HOLDING_PER","CUST_TRR_START_DT",Settings!$C$7,"CUST_TRR_END_DT",Settings!$C$4)/100,"") | H41: =IFERROR(BDP(A41,"CUST_TRR_RETURN_HOLDING_PER","CUST_TRR_START_DT",Settings!$C$8,"CUST_TRR_END_DT",Settings!$C$4)/100,"")
A43: Notes:
...

Sheet Settings
A1: MSCI EM Country Performance — Date Settings
A3: Label | B3: Date | C3: YYYYMMDD (Bloomberg) | D3: Used for
A4: Today | B4: =TODAY() | C4: =TEXT(B4,"yyyymmdd") | D4: End date
A5: YTD baseline | B5: =DATE(YEAR(TODAY())-1,12,31) | C5: =TEXT(B5,"yyyymmdd") | D5: Prior year-end close
A6: 1M ago | B6: =EDATE(TODAY(),-1) | C6: =TEXT(B6,"yyyymmdd") | D6: One month trailing
A7: 3M ago | B7: =EDATE(TODAY(),-3) | C7: =TEXT(B7,"yyyymmdd") | D7: Three months trailing
A8: Custom date | B8: =EDATE(TODAY(),-6) | C8: =TEXT(B8,"yyyymmdd") | D8: EDIT ME — pick any reference date
