Workbook

Sheet Dashboard
B2: EM Sovereign Credit
B6: Cross-section fair value across the EMBI universe · re-fits every Bloomberg refresh · no frozen anything
B8: Snapshot | E8: Universe | H8: EM median spread | K8: HIGH-conf | N8: Live R² | Q8: Live β (slope) | V8: k | W8: country | X8: z-resid
B9: =TODAY() | E9: =COUNTA(Model!$B$15:$B$85) | H9: =IFERROR(ROUND(MEDIAN(Model!$E$15:$E$85),0),NA()) | K9: =COUNTIF(Model!$Y$15:$Y$85,"HIGH") | N9: =IFERROR(RSQ(Model!$S$15:$S$85,Model!$R$15:$R$85),NA()) | Q9: =IFERROR(SLOPE(Model!$S$15:$S$85,Model!$R$15:$R$85),NA()) | V9: 1 | W9: =IFERROR(INDEX(Model!$B$15:$B$85,MATCH(X9,Model!$V$15:$V$85,0)),"") | X9: =IFERROR(LARGE(Model!$V$15:$V$85,1),"")
V10: 2 | W10: =IFERROR(INDEX(Model!$B$15:$B$85,MATCH(X10,Model!$V$15:$V$85,0)),"") | X10: =IFERROR(LARGE(Model!$V$15:$V$85,2),"")
V11: 3 | W11: =IFERROR(INDEX(Model!$B$15:$B$85,MATCH(X11,Model!$V$15:$V$85,0)),"") | X11: =IFERROR(LARGE(Model!$V$15:$V$85,3),"")
V12: 4 | W12: =IFERROR(INDEX(Model!$B$15:$B$85,MATCH(X12,Model!$V$15:$V$85,0)),"") | X12: =IFERROR(LARGE(Model!$V$15:$V$85,4),"")
B13: Cheap / Rich distribution | V13: 5 | W13: =IFERROR(INDEX(Model!$B$15:$B$85,MATCH(X13,Model!$V$15:$V$85,0)),"") | X13: =IFERROR(LARGE(Model!$V$15:$V$85,5),"")
B14: CHEAP | F14: Slightly cheap | J14: Fair | N14: Slightly rich | Q14: RICH | V14: 6 | W14: =IFERROR(INDEX(Model!$B$15:$B$85,MATCH(X14,Model!$V$15:$V$85,0)),"") | X14: =IFERROR(LARGE(Model!$V$15:$V$85,6),"")
B15: =COUNTIF(Model!$W$15:$W$85,"CHEAP") | F15: =COUNTIF(Model!$W$15:$W$85,"slightly cheap") | J15: =COUNTIF(Model!$W$15:$W$85,"fair") | N15: =COUNTIF(Model!$W$15:$W$85,"slightly rich") | Q15: =COUNTIF(Model!$W$15:$W$85,"RICH") | V15: 7 | W15: =IFERROR(INDEX(Model!$B$15:$B$85,MATCH(X15,Model!$V$15:$V$85,0)),"") | X15: =IFERROR(LARGE(Model!$V$15:$V$85,7),"")
V16: 8 | W16: =IFERROR(INDEX(Model!$B$15:$B$85,MATCH(X16,Model!$V$15:$V$85,0)),"") | X16: =IFERROR(LARGE(Model!$V$15:$V$85,8),"")
B17: Data Coverage · countries by confidence tier | V17: 9 | W17: =IFERROR(INDEX(Model!$B$15:$B$85,MATCH(X17,Model!$V$15:$V$85,0)),"") | X17: =IFERROR(LARGE(Model!$V$15:$V$85,9),"")
B18: HIGH (5-6 vars) | H18: MED (3-4 vars) | N18: LOW (0-2 vars) | V18: 10 | W18: =IFERROR(INDEX(Model!$B$15:$B$85,MATCH(X18,Model!$V$15:$V$85,0)),"") | X18: =IFERROR(LARGE(Model!$V$15:$V$85,10),"")
B19: =COUNTIF(Model!$Y$15:$Y$85,"HIGH") | H19: =COUNTIF(Model!$Y$15:$Y$85,"MED") | N19: =COUNTIF(Model!$Y$15:$Y$85,"LOW") | V19: 11 | W19: =IFERROR(INDEX(Model!$B$15:$B$85,MATCH(X19,Model!$V$15:$V$85,0)),"") | X19: =IFERROR(LARGE(Model!$V$15:$V$85,11),"")
B20: Rank | C20: Country | D20: Spread | E20: Fund Z | F20: Resid | G20: Z-resid | H20: Signal | K20: Rank | L20: Country | M20: Spread | N20: Fund Z | O20: Resid | P20: Z-resid | Q20: Signal | V20: 12 | W20: =IFERROR(INDEX(Model!$B$15:$B$85,MATCH(X20,Model!$V$15:$V$85,0)),"") | X20: =IFERROR(LARGE(Model!$V$15:$V$85,12),"")
B21: 1 | C21: =IFERROR(INDEX(Model!$B$15:$B$85,MATCH(G21,Model!$V$15:$V$85,0)),"") | D21: =IFERROR(INDEX(Model!$E$15:$E$85,MATCH(G21,Model!$V$15:$V$85,0)),"") | E21: =IFERROR(INDEX(Model!$R$15:$R$85,MATCH(G21,Model!$V$15:$V$85,0)),"") | F21: =IFERROR(INDEX(Model!$U$15:$U$85,MATCH(G21,Model!$V$15:$V$85,0)),"") | G21: =IFERROR(LARGE(Model!$V$15:$V$85,1),"") | H21: =IFERROR(INDEX(Model!$W$15:$W$85,MATCH(G21,Model!$V$15:$V$85,0)),"") | K21: 1 | L21: =IFERROR(INDEX(Model!$B$15:$B$85,MATCH(P21,Model!$V$15:$V$85,0)),"") | M21: =IFERROR(INDEX(Model!$E$15:$E$85,MATCH(P21,Model!$V$15:$V$85,0)),"") | N21: =IFERROR(INDEX(Model!$R$15:$R$85,MATCH(P21,Model!$V$15:$V$85,0)),"") | O21: =IFERROR(INDEX(Model!$U$15:$U$85,MATCH(P21,Model!$V$15:$V$85,0)),"") | P21: =IFERROR(SMALL(Model!$V$15:$V$85,1),"") | Q21: =IFERROR(INDEX(Model!$W$15:$W$85,MATCH(P21,Model!$V$15:$V$85,0)),"") | V21: 13 | W21: =IFERROR(INDEX(Model!$B$15:$B$85,MATCH(X21,Model!$V$15:$V$85,0)),"") | X21: =IFERROR(LARGE(Model!$V$15:$V$85,13),"")
B22: 2 | C22: =IFERROR(INDEX(Model!$B$15:$B$85,MATCH(G22,Model!$V$15:$V$85,0)),"") | D22: =IFERROR(INDEX(Model!$E$15:$E$85,MATCH(G22,Model!$V$15:$V$85,0)),"") | E22: =IFERROR(INDEX(Model!$R$15:$R$85,MATCH(G22,Model!$V$15:$V$85,0)),"") | F22: =IFERROR(INDEX(Model!$U$15:$U$85,MATCH(G22,Model!$V$15:$V$85,0)),"") | G22: =IFERROR(LARGE(Model!$V$15:$V$85,2),"") | H22: =IFERROR(INDEX(Model!$W$15:$W$85,MATCH(G22,Model!$V$15:$V$85,0)),"") | K22: 2 | L22: =IFERROR(INDEX(Model!$B$15:$B$85,MATCH(P22,Model!$V$15:$V$85,0)),"") | M22: =IFERROR(INDEX(Model!$E$15:$E$85,MATCH(P22,Model!$V$15:$V$85,0)),"") | N22: =IFERROR(INDEX(Model!$R$15:$R$85,MATCH(P22,Model!$V$15:$V$85,0)),"") | O22: =IFERROR(INDEX(Model!$U$15:$U$85,MATCH(P22,Model!$V$15:$V$85,0)),"") | P22: =IFERROR(SMALL(Model!$V$15:$V$85,2),"") | Q22: =IFERROR(INDEX(Model!$W$15:$W$85,MATCH(P22,Model!$V$15:$V$85,0)),"") | V22: 14 | W22: =IFERROR(INDEX(Model!$B$15:$B$85,MATCH(X22,Model!$V$15:$V$85,0)),"") | X22: =IFERROR(LARGE(Model!$V$15:$V$85,14),"")
B23: 3 | C23: =IFERROR(INDEX(Model!$B$15:$B$85,MATCH(G23,Model!$V$15:$V$85,0)),"") | D23: =IFERROR(INDEX(Model!$E$15:$E$85,MATCH(G23,Model!$V$15:$V$85,0)),"") | E23: =IFERROR(INDEX(Model!$R$15:$R$85,MATCH(G23,Model!$V$15:$V$85,0)),"") | F23: =IFERROR(INDEX(Model!$U$15:$U$85,MATCH(G23,Model!$V$15:$V$85,0)),"") | G23: =IFERROR(LARGE(Model!$V$15:$V$85,3),"") | H23: =IFERROR(INDEX(Model!$W$15:$W$85,MATCH(G23,Model!$V$15:$V$85,0)),"") | K23: 3 | L23: =IFERROR(INDEX(Model!$B$15:$B$85,MATCH(P23,Model!$V$15:$V$85,0)),"") | M23: =IFERROR(INDEX(Model!$E$15:$E$85,MATCH(P23,Model!$V$15:$V$85,0)),"") | N23: =IFERROR(INDEX(Model!$R$15:$R$85,MATCH(P23,Model!$V$15:$V$85,0)),"") | O23: =IFERROR(INDEX(Model!$U$15:$U$85,MATCH(P23,Model!$V$15:$V$85,0)),"") | P23: =IFERROR(SMALL(Model!$V$15:$V$85,3),"") | Q23: =IFERROR(INDEX(Model!$W$15:$W$85,MATCH(P23,Model!$V$15:$V$85,0)),"") | V23: 15 | W23: =IFERROR(INDEX(Model!$B$15:$B$85,MATCH(X23,Model!$V$15:$V$85,0)),"") | X23: =IFERROR(LARGE(Model!$V$15:$V$85,15),"")
B24: 4 | C24: =IFERROR(INDEX(Model!$B$15:$B$85,MATCH(G24,Model!$V$15:$V$85,0)),"") | D24: =IFERROR(INDEX(Model!$E$15:$E$85,MATCH(G24,Model!$V$15:$V$85,0)),"") | E24: =IFERROR(INDEX(Model!$R$15:$R$85,MATCH(G24,Model!$V$15:$V$85,0)),"") | F24: =IFERROR(INDEX(Model!$U$15:$U$85,MATCH(G24,Model!$V$15:$V$85,0)),"") | G24: =IFERROR(LARGE(Model!$V$15:$V$85,4),"") | H24: =IFERROR(INDEX(Model!$W$15:$W$85,MATCH(G24,Model!$V$15:$V$85,0)),"") | K24: 4 | L24: =IFERROR(INDEX(Model!$B$15:$B$85,MATCH(P24,Model!$V$15:$V$85,0)),"") | M24: =IFERROR(INDEX(Model!$E$15:$E$85,MATCH(P24,Model!$V$15:$V$85,0)),"") | N24: =IFERROR(INDEX(Model!$R$15:$R$85,MATCH(P24,Model!$V$15:$V$85,0)),"") | O24: =IFERROR(INDEX(Model!$U$15:$U$85,MATCH(P24,Model!$V$15:$V$85,0)),"") | P24: =IFERROR(SMALL(Model!$V$15:$V$85,4),"") | Q24: =IFERROR(INDEX(Model!$W$15:$W$85,MATCH(P24,Model!$V$15:$V$85,0)),"") | V24: 16 | W24: =IFERROR(INDEX(Model!$B$15:$B$85,MATCH(X24,Model!$V$15:$V$85,0)),"") | X24: =IFERROR(LARGE(Model!$V$15:$V$85,16),"")
B25: 5 | C25: =IFERROR(INDEX(Model!$B$15:$B$85,MATCH(G25,Model!$V$15:$V$85,0)),"") | D25: =IFERROR(INDEX(Model!$E$15:$E$85,MATCH(G25,Model!$V$15:$V$85,0)),"") | E25: =IFERROR(INDEX(Model!$R$15:$R$85,MATCH(G25,Model!$V$15:$V$85,0)),"") | F25: =IFERROR(INDEX(Model!$U$15:$U$85,MATCH(G25,Model!$V$15:$V$85,0)),"") | G25: =IFERROR(LARGE(Model!$V$15:$V$85,5),"") | H25: =IFERROR(INDEX(Model!$W$15:$W$85,MATCH(G25,Model!$V$15:$V$85,0)),"") | K25: 5 | L25: =IFERROR(INDEX(Model!$B$15:$B$85,MATCH(P25,Model!$V$15:$V$85,0)),"") | M25: =IFERROR(INDEX(Model!$E$15:$E$85,MATCH(P25,Model!$V$15:$V$85,0)),"") | N25: =IFERROR(INDEX(Model!$R$15:$R$85,MATCH(P25,Model!$V$15:$V$85,0)),"") | O25: =IFERROR(INDEX(Model!$U$15:$U$85,MATCH(P25,Model!$V$15:$V$85,0)),"") | P25: =IFERROR(SMALL(Model!$V$15:$V$85,5),"") | Q25: =IFERROR(INDEX(Model!$W$15:$W$85,MATCH(P25,Model!$V$15:$V$85,0)),"") | V25: 17 | W25: =IFERROR(INDEX(Model!$B$15:$B$85,MATCH(X25,Model!$V$15:$V$85,0)),"") | X25: =IFERROR(LARGE(Model!$V$15:$V$85,17),"")
B26: 6 | C26: =IFERROR(INDEX(Model!$B$15:$B$85,MATCH(G26,Model!$V$15:$V$85,0)),"") | D26: =IFERROR(INDEX(Model!$E$15:$E$85,MATCH(G26,Model!$V$15:$V$85,0)),"") | E26: =IFERROR(INDEX(Model!$R$15:$R$85,MATCH(G26,Model!$V$15:$V$85,0)),"") | F26: =IFERROR(INDEX(Model!$U$15:$U$85,MATCH(G26,Model!$V$15:$V$85,0)),"") | G26: =IFERROR(LARGE(Model!$V$15:$V$85,6),"") | H26: =IFERROR(INDEX(Model!$W$15:$W$85,MATCH(G26,Model!$V$15:$V$85,0)),"") | K26: 6 | L26: =IFERROR(INDEX(Model!$B$15:$B$85,MATCH(P26,Model!$V$15:$V$85,0)),"") | M26: =IFERROR(INDEX(Model!$E$15:$E$85,MATCH(P26,Model!$V$15:$V$85,0)),"") | N26: =IFERROR(INDEX(Model!$R$15:$R$85,MATCH(P26,Model!$V$15:$V$85,0)),"") | O26: =IFERROR(INDEX(Model!$U$15:$U$85,MATCH(P26,Model!$V$15:$V$85,0)),"") | P26: =IFERROR(SMALL(Model!$V$15:$V$85,6),"") | Q26: =IFERROR(INDEX(Model!$W$15:$W$85,MATCH(P26,Model!$V$15:$V$85,0)),"") | V26: 18 | W26: =IFERROR(INDEX(Model!$B$15:$B$85,MATCH(X26,Model!$V$15:$V$85,0)),"") | X26: =IFERROR(LARGE(Model!$V$15:$V$85,18),"")
B27: 7 | C27: =IFERROR(INDEX(Model!$B$15:$B$85,MATCH(G27,Model!$V$15:$V$85,0)),"") | D27: =IFERROR(INDEX(Model!$E$15:$E$85,MATCH(G27,Model!$V$15:$V$85,0)),"") | E27: =IFERROR(INDEX(Model!$R$15:$R$85,MATCH(G27,Model!$V$15:$V$85,0)),"") | F27: =IFERROR(INDEX(Model!$U$15:$U$85,MATCH(G27,Model!$V$15:$V$85,0)),"") | G27: =IFERROR(LARGE(Model!$V$15:$V$85,7),"") | H27: =IFERROR(INDEX(Model!$W$15:$W$85,MATCH(G27,Model!$V$15:$V$85,0)),"") | K27: 7 | L27: =IFERROR(INDEX(Model!$B$15:$B$85,MATCH(P27,Model!$V$15:$V$85,0)),"") | M27: =IFERROR(INDEX(Model!$E$15:$E$85,MATCH(P27,Model!$V$15:$V$85,0)),"") | N27: =IFERROR(INDEX(Model!$R$15:$R$85,MATCH(P27,Model!$V$15:$V$85,0)),"") | O27: =IFERROR(INDEX(Model!$U$15:$U$85,MATCH(P27,Model!$V$15:$V$85,0)),"") | P27: =IFERROR(SMALL(Model!$V$15:$V$85,7),"") | Q27: =IFERROR(INDEX(Model!$W$15:$W$85,MATCH(P27,Model!$V$15:$V$85,0)),"") | V27: 19 | W27: =IFERROR(INDEX(Model!$B$15:$B$85,MATCH(X27,Model!$V$15:$V$85,0)),"") | X27: =IFERROR(LARGE(Model!$V$15:$V$85,19),"")
B28: 8 | C28: =IFERROR(INDEX(Model!$B$15:$B$85,MATCH(G28,Model!$V$15:$V$85,0)),"") | D28: =IFERROR(INDEX(Model!$E$15:$E$85,MATCH(G28,Model!$V$15:$V$85,0)),"") | E28: =IFERROR(INDEX(Model!$R$15:$R$85,MATCH(G28,Model!$V$15:$V$85,0)),"") | F28: =IFERROR(INDEX(Model!$U$15:$U$85,MATCH(G28,Model!$V$15:$V$85,0)),"") | G28: =IFERROR(LARGE(Model!$V$15:$V$85,8),"") | H28: =IFERROR(INDEX(Model!$W$15:$W$85,MATCH(G28,Model!$V$15:$V$85,0)),"") | K28: 8 | L28: =IFERROR(INDEX(Model!$B$15:$B$85,MATCH(P28,Model!$V$15:$V$85,0)),"") | M28: =IFERROR(INDEX(Model!$E$15:$E$85,MATCH(P28,Model!$V$15:$V$85,0)),"") | N28: =IFERROR(INDEX(Model!$R$15:$R$85,MATCH(P28,Model!$V$15:$V$85,0)),"") | O28: =IFERROR(INDEX(Model!$U$15:$U$85,MATCH(P28,Model!$V$15:$V$85,0)),"") | P28: =IFERROR(SMALL(Model!$V$15:$V$85,8),"") | Q28: =IFERROR(INDEX(Model!$W$15:$W$85,MATCH(P28,Model!$V$15:$V$85,0)),"") | V28: 20 | W28: =IFERROR(INDEX(Model!$B$15:$B$85,MATCH(X28,Model!$V$15:$V$85,0)),"") | X28: =IFERROR(LARGE(Model!$V$15:$V$85,20),"")
B29: 9 | C29: =IFERROR(INDEX(Model!$B$15:$B$85,MATCH(G29,Model!$V$15:$V$85,0)),"") | D29: =IFERROR(INDEX(Model!$E$15:$E$85,MATCH(G29,Model!$V$15:$V$85,0)),"") | E29: =IFERROR(INDEX(Model!$R$15:$R$85,MATCH(G29,Model!$V$15:$V$85,0)),"") | F29: =IFERROR(INDEX(Model!$U$15:$U$85,MATCH(G29,Model!$V$15:$V$85,0)),"") | G29: =IFERROR(LARGE(Model!$V$15:$V$85,9),"") | H29: =IFERROR(INDEX(Model!$W$15:$W$85,MATCH(G29,Model!$V$15:$V$85,0)),"") | K29: 9 | L29: =IFERROR(INDEX(Model!$B$15:$B$85,MATCH(P29,Model!$V$15:$V$85,0)),"") | M29: =IFERROR(INDEX(Model!$E$15:$E$85,MATCH(P29,Model!$V$15:$V$85,0)),"") | N29: =IFERROR(INDEX(Model!$R$15:$R$85,MATCH(P29,Model!$V$15:$V$85,0)),"") | O29: =IFERROR(INDEX(Model!$U$15:$U$85,MATCH(P29,Model!$V$15:$V$85,0)),"") | P29: =IFERROR(SMALL(Model!$V$15:$V$85,9),"") | Q29: =IFERROR(INDEX(Model!$W$15:$W$85,MATCH(P29,Model!$V$15:$V$85,0)),"") | V29: 21 | W29: =IFERROR(INDEX(Model!$B$15:$B$85,MATCH(X29,Model!$V$15:$V$85,0)),"") | X29: =IFERROR(LARGE(Model!$V$15:$V$85,21),"")
B30: 10 | C30: =IFERROR(INDEX(Model!$B$15:$B$85,MATCH(G30,Model!$V$15:$V$85,0)),"") | D30: =IFERROR(INDEX(Model!$E$15:$E$85,MATCH(G30,Model!$V$15:$V$85,0)),"") | E30: =IFERROR(INDEX(Model!$R$15:$R$85,MATCH(G30,Model!$V$15:$V$85,0)),"") | F30: =IFERROR(INDEX(Model!$U$15:$U$85,MATCH(G30,Model!$V$15:$V$85,0)),"") | G30: =IFERROR(LARGE(Model!$V$15:$V$85,10),"") | H30: =IFERROR(INDEX(Model!$W$15:$W$85,MATCH(G30,Model!$V$15:$V$85,0)),"") | K30: 10 | L30: =IFERROR(INDEX(Model!$B$15:$B$85,MATCH(P30,Model!$V$15:$V$85,0)),"") | M30: =IFERROR(INDEX(Model!$E$15:$E$85,MATCH(P30,Model!$V$15:$V$85,0)),"") | N30: =IFERROR(INDEX(Model!$R$15:$R$85,MATCH(P30,Model!$V$15:$V$85,0)),"") | O30: =IFERROR(INDEX(Model!$U$15:$U$85,MATCH(P30,Model!$V$15:$V$85,0)),"") | P30: =IFERROR(SMALL(Model!$V$15:$V$85,10),"") | Q30: =IFERROR(INDEX(Model!$W$15:$W$85,MATCH(P30,Model!$V$15:$V$85,0)),"") | V30: 22 | W30: =IFERROR(INDEX(Model!$B$15:$B$85,MATCH(X30,Model!$V$15:$V$85,0)),"") | X30: =IFERROR(LARGE(Model!$V$15:$V$85,22),"")
V31: 23 | W31: =IFERROR(INDEX(Model!$B$15:$B$85,MATCH(X31,Model!$V$15:$V$85,0)),"") | X31: =IFERROR(LARGE(Model!$V$15:$V$85,23),"")
V32: 24 | W32: =IFERROR(INDEX(Model!$B$15:$B$85,MATCH(X32,Model!$V$15:$V$85,0)),"") | X32: =IFERROR(LARGE(Model!$V$15:$V$85,24),"")
V33: 25 | W33: =IFERROR(INDEX(Model!$B$15:$B$85,MATCH(X33,Model!$V$15:$V$85,0)),"") | X33: =IFERROR(LARGE(Model!$V$15:$V$85,25),"")
V34: 26 | W34: =IFERROR(INDEX(Model!$B$15:$B$85,MATCH(X34,Model!$V$15:$V$85,0)),"") | X34: =IFERROR(LARGE(Model!$V$15:$V$85,26),"")
V35: 27 | W35: =IFERROR(INDEX(Model!$B$15:$B$85,MATCH(X35,Model!$V$15:$V$85,0)),"") | X35: =IFERROR(LARGE(Model!$V$15:$V$85,27),"")
V36: 28 | W36: =IFERROR(INDEX(Model!$B$15:$B$85,MATCH(X36,Model!$V$15:$V$85,0)),"") | X36: =IFERROR(LARGE(Model!$V$15:$V$85,28),"")
V37: 29 | W37: =IFERROR(INDEX(Model!$B$15:$B$85,MATCH(X37,Model!$V$15:$V$85,0)),"") | X37: =IFERROR(LARGE(Model!$V$15:$V$85,29),"")
V38: 30 | W38: =IFERROR(INDEX(Model!$B$15:$B$85,MATCH(X38,Model!$V$15:$V$85,0)),"") | X38: =IFERROR(LARGE(Model!$V$15:$V$85,30),"")
V39: 31 | W39: =IFERROR(INDEX(Model!$B$15:$B$85,MATCH(X39,Model!$V$15:$V$85,0)),"") | X39: =IFERROR(LARGE(Model!$V$15:$V$85,31),"")
V40: 32 | W40: =IFERROR(INDEX(Model!$B$15:$B$85,MATCH(X40,Model!$V$15:$V$85,0)),"") | X40: =IFERROR(LARGE(Model!$V$15:$V$85,32),"")
V41: 33 | W41: =IFERROR(INDEX(Model!$B$15:$B$85,MATCH(X41,Model!$V$15:$V$85,0)),"") | X41: =IFERROR(LARGE(Model!$V$15:$V$85,33),"")
V42: 34 | W42: =IFERROR(INDEX(Model!$B$15:$B$85,MATCH(X42,Model!$V$15:$V$85,0)),"") | X42: =IFERROR(LARGE(Model!$V$15:$V$85,34),"")
V43: 35 | W43: =IFERROR(INDEX(Model!$B$15:$B$85,MATCH(X43,Model!$V$15:$V$85,0)),"") | X43: =IFERROR(LARGE(Model!$V$15:$V$85,35),"")
V44: 36 | W44: =IFERROR(INDEX(Model!$B$15:$B$85,MATCH(X44,Model!$V$15:$V$85,0)),"") | X44: =IFERROR(LARGE(Model!$V$15:$V$85,36),"")
V45: 37 | W45: =IFERROR(INDEX(Model!$B$15:$B$85,MATCH(X45,Model!$V$15:$V$85,0)),"") | X45: =IFERROR(LARGE(Model!$V$15:$V$85,37),"")
...

Sheet Country
B2: Country Detail
B4: Pick a sovereign — KPIs and the scatter all update from live Bloomberg data.
B6: Sovereign: | C6: BRAZIL
B8: Spread (bps) | E8: Composite rating | H8: Fund. score | K8: Resid (log) | N8: Z-score signal
B9: =IFERROR(INDEX(Model!$E$15:$E$85,MATCH($C$6,Model!$B$15:$B$85,0)),NA()) | E9: =IFERROR(INDEX(Model!$D$15:$D$85,MATCH($C$6,Model!$B$15:$B$85,0)),NA()) | H9: =IFERROR(INDEX(Model!$R$15:$R$85,MATCH($C$6,Model!$B$15:$B$85,0)),NA()) | K9: =IFERROR(INDEX(Model!$U$15:$U$85,MATCH($C$6,Model!$B$15:$B$85,0)),NA()) | N9: =IFERROR(INDEX(Model!$V$15:$V$85,MATCH($C$6,Model!$B$15:$B$85,0)),NA())
B12: =IFERROR(INDEX(Model!$W$15:$W$85,MATCH($C$6,Model!$B$15:$B$85,0)),"-")
B14: Macro fundamentals · vs. peer-group cross-section
E15: Latest value | H15: Peer median | K15: Cross-section z
B16: GDP growth (%) | E16: =IFERROR(INDEX(Model!$G$15:$G$85,MATCH($C$6,Model!$B$15:$B$85,0)),"") | H16: =IFERROR(MEDIAN(Model!$G$15:$G$85),"") | K16: =IFERROR(INDEX(Model!$Q$15:$Q$85,MATCH($C$6,Model!$B$15:$B$85,0)),"")
B17: Inflation (%) | E17: =IFERROR(INDEX(Model!$H$15:$H$85,MATCH($C$6,Model!$B$15:$B$85,0)),"") | H17: =IFERROR(MEDIAN(Model!$H$15:$H$85),"") | K17: =IFERROR(INDEX(Model!$R$15:$R$85,MATCH($C$6,Model!$B$15:$B$85,0)),"")
B18: Govt debt (%GDP) | E18: =IFERROR(INDEX(Model!$I$15:$I$85,MATCH($C$6,Model!$B$15:$B$85,0)),"") | H18: =IFERROR(MEDIAN(Model!$I$15:$I$85),"") | K18: =IFERROR(INDEX(Model!$M$15:$M$85,MATCH($C$6,Model!$B$15:$B$85,0)),"")
B19: Curr acct (%GDP) | E19: =IFERROR(INDEX(Model!$J$15:$J$85,MATCH($C$6,Model!$B$15:$B$85,0)),"") | H19: =IFERROR(MEDIAN(Model!$J$15:$J$85),"") | K19: =IFERROR(INDEX(Model!$N$15:$N$85,MATCH($C$6,Model!$B$15:$B$85,0)),"")
B20: FX reserves (USD) | E20: =IFERROR(INDEX(Model!$K$15:$K$85,MATCH($C$6,Model!$B$15:$B$85,0)),"") | H20: =IFERROR(MEDIAN(Model!$K$15:$K$85),"") | K20: =IFERROR(INDEX(Model!$O$15:$O$85,MATCH($C$6,Model!$B$15:$B$85,0)),"")
B21: Rating (1=AAA→22=D) | E21: =IFERROR(INDEX(Model!$D$15:$D$85,MATCH($C$6,Model!$B$15:$B$85,0)),"") | H21: =IFERROR(MEDIAN(Model!$D$15:$D$85),"") | K21: =IFERROR(INDEX(Model!$L$15:$L$85,MATCH($C$6,Model!$B$15:$B$85,0)),"")
R200: helper
R201: =IFERROR(INDEX(Model!$R$15:$R$85,MATCH($C$6,Model!$B$15:$B$85,0)),NA()) | S201: =IFERROR(INDEX(Model!$S$15:$S$85,MATCH($C$6,Model!$B$15:$B$85,0)),NA())

Sheet Model
B2: Cross-Section Fair Value Model
B4: log(EMBI spread) = α + β · Composite Fundamental Score · coefficients re-estimated every Bloomberg refresh · no frozen anything
B6: Factor weights (editable, blue cells) | I6: Live regression coefficients
B7: Rating | C7: w_R | D7: 0.35 | I7: Intercept (α) | N7: =IFERROR(INTERCEPT($Z$15:$Z$85,$AA$15:$AA$85),"")
B8: Govt debt | C8: w_D | D8: 0.2 | I8: Slope (β) | N8: =IFERROR(SLOPE($Z$15:$Z$85,$AA$15:$AA$85),"")
B9: Curr acct | C9: w_C | D9: 0.15 | I9: R² | N9: =IFERROR(RSQ($Z$15:$Z$85,$AA$15:$AA$85),"")
B10: FX reserves | C10: w_X | D10: 0.1 | I10: # countries with full data | N10: =COUNT($AA$15:$AA$85)
B11: GDP growth | C11: w_g | D11: 0.12 | I11: Median spread (bps) | N11: =IFERROR(ROUND(MEDIAN($E$15:$E$85),0),"") | P11: Min vars in regression | S11: 4
B12: Inflation | C12: w_p | D12: 0.08 | I12: Snapshot | N12: =TODAY()
B13: Sum | D13: =SUM(D7:D12)
B14: Country | C14: ISO | D14: Rating# | E14: Spread bps | F14: CDS bps | G14: GDP % | H14: CPI % | I14: Debt %GDP | J14: CA %GDP | K14: Reserves | L14: zR | M14: zD | N14: zC | O14: zX | P14: zg | Q14: zp | R14: Fund Score | S14: log(spread) | T14: Fitted log | U14: Resid | V14: Z resid | W14: Signal | X14: Coverage | Y14: Conf | Z14: flt_logS | AA14: flt_F
B15: =Tickers!B7 | C15: =Tickers!C7 | D15: =Tickers!E7 | E15: =IFERROR(Tickers!G7,"") | F15: =IFERROR(Tickers!I7,"") | G15: =IFERROR(IF(ISNUMBER(Tickers!K7),Tickers!K7,IF(ISNUMBER(Haver!E7),Haver!E7,IF(ISNUMBER(Tickers!T7),Tickers!T7,""))),"") | H15: =IFERROR(IF(ISNUMBER(Tickers!M7),Tickers!M7,IF(ISNUMBER(Haver!G7),Haver!G7,IF(ISNUMBER(Tickers!U7),Tickers!U7,""))),"") | I15: =IFERROR(IF(ISNUMBER(Tickers!O7),Tickers!O7,IF(ISNUMBER(Haver!I7),Haver!I7,IF(ISNUMBER(Tickers!V7),Tickers!V7,""))),"") | J15: =IFERROR(IF(ISNUMBER(Tickers!Q7),Tickers!Q7,IF(ISNUMBER(Haver!K7),Haver!K7,IF(ISNUMBER(Tickers!W7),Tickers!W7,""))),"") | K15: =IFERROR(IF(ISNUMBER(Tickers!S7),Tickers!S7,IF(ISNUMBER(Haver!M7),Haver!M7,IF(ISNUMBER(Tickers!X7),Tickers!X7,""))),"") | L15: =IFERROR(($D$15-AVERAGE($D$15:$D$85))/STDEV($D$15:$D$85),"") | M15: =IFERROR(($I$15-AVERAGE($I$15:$I$85))/STDEV($I$15:$I$85),"") | N15: =IFERROR(-($J$15-AVERAGE($J$15:$J$85))/STDEV($J$15:$J$85),"") | O15: =IFERROR(-($K$15-AVERAGE($K$15:$K$85))/STDEV($K$15:$K$85),"") | P15: =IFERROR(-($G$15-AVERAGE($G$15:$G$85))/STDEV($G$15:$G$85),"") | Q15: =IFERROR(($H$15-AVERAGE($H$15:$H$85))/STDEV($H$15:$H$85),"") | R15: =IFERROR((IF(ISNUMBER(L15),$D$7*L15,0)+IF(ISNUMBER(M15),$D$8*M15,0)+IF(ISNUMBER(N15),$D$9*N15,0)+IF(ISNUMBER(O15),$D$10*O15,0)+IF(ISNUMBER(P15),$D$11*P15,0)+IF(ISNUMBER(Q15),$D$12*Q15,0))/(IF(ISNUMBER(L15),$D$7,0)+IF(ISNUMBER(M15),$D$8,0)+IF(ISNUMBER(N15),$D$9,0)+IF(ISNUMBER(O15),$D$10,0)+IF(ISNUMBER(P15),$D$11,0)+IF(ISNUMBER(Q15),$D$12,0)),"") | S15: =IFERROR(LN($E$15),"") | T15: =IFERROR($N$7+$N$8*$R$15,"") | U15: =IFERROR($S$15-$T$15,"") | V15: =IFERROR(($U$15-AVERAGE($U$15:$U$85))/STDEV($U$15:$U$85),"") | W15: =IF(ISNUMBER($V$15),IF($V$15>=1.5,"CHEAP",IF($V$15>=0.5,"slightly cheap",IF($V$15<=-1.5,"RICH",IF($V$15<=-0.5,"slightly rich","fair")))),"") | X15: =SUMPRODUCT(--ISNUMBER((D15,G15,H15,I15,J15,K15))) | Y15: =IF(X15>=5,"HIGH",IF(X15>=3,"MED","LOW")) | Z15: =IF(AND(ISNUMBER(S15),X15>=$S$11),S15,"") | AA15: =IF(AND(ISNUMBER(R15),X15>=$S$11),R15,"")
B16: =Tickers!B8 | C16: =Tickers!C8 | D16: =Tickers!E8 | E16: =IFERROR(Tickers!G8,"") | F16: =IFERROR(Tickers!I8,"") | G16: =IFERROR(IF(ISNUMBER(Tickers!K8),Tickers!K8,IF(ISNUMBER(Haver!E8),Haver!E8,IF(ISNUMBER(Tickers!T8),Tickers!T8,""))),"") | H16: =IFERROR(IF(ISNUMBER(Tickers!M8),Tickers!M8,IF(ISNUMBER(Haver!G8),Haver!G8,IF(ISNUMBER(Tickers!U8),Tickers!U8,""))),"") | I16: =IFERROR(IF(ISNUMBER(Tickers!O8),Tickers!O8,IF(ISNUMBER(Haver!I8),Haver!I8,IF(ISNUMBER(Tickers!V8),Tickers!V8,""))),"") | J16: =IFERROR(IF(ISNUMBER(Tickers!Q8),Tickers!Q8,IF(ISNUMBER(Haver!K8),Haver!K8,IF(ISNUMBER(Tickers!W8),Tickers!W8,""))),"") | K16: =IFERROR(IF(ISNUMBER(Tickers!S8),Tickers!S8,IF(ISNUMBER(Haver!M8),Haver!M8,IF(ISNUMBER(Tickers!X8),Tickers!X8,""))),"") | L16: =IFERROR(($D$16-AVERAGE($D$15:$D$85))/STDEV($D$15:$D$85),"") | M16: =IFERROR(($I$16-AVERAGE($I$15:$I$85))/STDEV($I$15:$I$85),"") | N16: =IFERROR(-($J$16-AVERAGE($J$15:$J$85))/STDEV($J$15:$J$85),"") | O16: =IFERROR(-($K$16-AVERAGE($K$15:$K$85))/STDEV($K$15:$K$85),"") | P16: =IFERROR(-($G$16-AVERAGE($G$15:$G$85))/STDEV($G$15:$G$85),"") | Q16: =IFERROR(($H$16-AVERAGE($H$15:$H$85))/STDEV($H$15:$H$85),"") | R16: =IFERROR((IF(ISNUMBER(L16),$D$7*L16,0)+IF(ISNUMBER(M16),$D$8*M16,0)+IF(ISNUMBER(N16),$D$9*N16,0)+IF(ISNUMBER(O16),$D$10*O16,0)+IF(ISNUMBER(P16),$D$11*P16,0)+IF(ISNUMBER(Q16),$D$12*Q16,0))/(IF(ISNUMBER(L16),$D$7,0)+IF(ISNUMBER(M16),$D$8,0)+IF(ISNUMBER(N16),$D$9,0)+IF(ISNUMBER(O16),$D$10,0)+IF(ISNUMBER(P16),$D$11,0)+IF(ISNUMBER(Q16),$D$12,0)),"") | S16: =IFERROR(LN($E$16),"") | T16: =IFERROR($N$7+$N$8*$R$16,"") | U16: =IFERROR($S$16-$T$16,"") | V16: =IFERROR(($U$16-AVERAGE($U$15:$U$85))/STDEV($U$15:$U$85),"") | W16: =IF(ISNUMBER($V$16),IF($V$16>=1.5,"CHEAP",IF($V$16>=0.5,"slightly cheap",IF($V$16<=-1.5,"RICH",IF($V$16<=-0.5,"slightly rich","fair")))),"") | X16: =SUMPRODUCT(--ISNUMBER((D16,G16,H16,I16,J16,K16))) | Y16: =IF(X16>=5,"HIGH",IF(X16>=3,"MED","LOW")) | Z16: =IF(AND(ISNUMBER(S16),X16>=$S$11),S16,"") | AA16: =IF(AND(ISNUMBER(R16),X16>=$S$11),R16,"")
B17: =Tickers!B9 | C17: =Tickers!C9 | D17: =Tickers!E9 | E17: =IFERROR(Tickers!G9,"") | F17: =IFERROR(Tickers!I9,"") | G17: =IFERROR(IF(ISNUMBER(Tickers!K9),Tickers!K9,IF(ISNUMBER(Haver!E9),Haver!E9,IF(ISNUMBER(Tickers!T9),Tickers!T9,""))),"") | H17: =IFERROR(IF(ISNUMBER(Tickers!M9),Tickers!M9,IF(ISNUMBER(Haver!G9),Haver!G9,IF(ISNUMBER(Tickers!U9),Tickers!U9,""))),"") | I17: =IFERROR(IF(ISNUMBER(Tickers!O9),Tickers!O9,IF(ISNUMBER(Haver!I9),Haver!I9,IF(ISNUMBER(Tickers!V9),Tickers!V9,""))),"") | J17: =IFERROR(IF(ISNUMBER(Tickers!Q9),Tickers!Q9,IF(ISNUMBER(Haver!K9),Haver!K9,IF(ISNUMBER(Tickers!W9),Tickers!W9,""))),"") | K17: =IFERROR(IF(ISNUMBER(Tickers!S9),Tickers!S9,IF(ISNUMBER(Haver!M9),Haver!M9,IF(ISNUMBER(Tickers!X9),Tickers!X9,""))),"") | L17: =IFERROR(($D$17-AVERAGE($D$15:$D$85))/STDEV($D$15:$D$85),"") | M17: =IFERROR(($I$17-AVERAGE($I$15:$I$85))/STDEV($I$15:$I$85),"") | N17: =IFERROR(-($J$17-AVERAGE($J$15:$J$85))/STDEV($J$15:$J$85),"") | O17: =IFERROR(-($K$17-AVERAGE($K$15:$K$85))/STDEV($K$15:$K$85),"") | P17: =IFERROR(-($G$17-AVERAGE($G$15:$G$85))/STDEV($G$15:$G$85),"") | Q17: =IFERROR(($H$17-AVERAGE($H$15:$H$85))/STDEV($H$15:$H$85),"") | R17: =IFERROR((IF(ISNUMBER(L17),$D$7*L17,0)+IF(ISNUMBER(M17),$D$8*M17,0)+IF(ISNUMBER(N17),$D$9*N17,0)+IF(ISNUMBER(O17),$D$10*O17,0)+IF(ISNUMBER(P17),$D$11*P17,0)+IF(ISNUMBER(Q17),$D$12*Q17,0))/(IF(ISNUMBER(L17),$D$7,0)+IF(ISNUMBER(M17),$D$8,0)+IF(ISNUMBER(N17),$D$9,0)+IF(ISNUMBER(O17),$D$10,0)+IF(ISNUMBER(P17),$D$11,0)+IF(ISNUMBER(Q17),$D$12,0)),"") | S17: =IFERROR(LN($E$17),"") | T17: =IFERROR($N$7+$N$8*$R$17,"") | U17: =IFERROR($S$17-$T$17,"") | V17: =IFERROR(($U$17-AVERAGE($U$15:$U$85))/STDEV($U$15:$U$85),"") | W17: =IF(ISNUMBER($V$17),IF($V$17>=1.5,"CHEAP",IF($V$17>=0.5,"slightly cheap",IF($V$17<=-1.5,"RICH",IF($V$17<=-0.5,"slightly rich","fair")))),"") | X17: =SUMPRODUCT(--ISNUMBER((D17,G17,H17,I17,J17,K17))) | Y17: =IF(X17>=5,"HIGH",IF(X17>=3,"MED","LOW")) | Z17: =IF(AND(ISNUMBER(S17),X17>=$S$11),S17,"") | AA17: =IF(AND(ISNUMBER(R17),X17>=$S$11),R17,"")
B18: =Tickers!B10 | C18: =Tickers!C10 | D18: =Tickers!E10 | E18: =IFERROR(Tickers!G10,"") | F18: =IFERROR(Tickers!I10,"") | G18: =IFERROR(IF(ISNUMBER(Tickers!K10),Tickers!K10,IF(ISNUMBER(Haver!E10),Haver!E10,IF(ISNUMBER(Tickers!T10),Tickers!T10,""))),"") | H18: =IFERROR(IF(ISNUMBER(Tickers!M10),Tickers!M10,IF(ISNUMBER(Haver!G10),Haver!G10,IF(ISNUMBER(Tickers!U10),Tickers!U10,""))),"") | I18: =IFERROR(IF(ISNUMBER(Tickers!O10),Tickers!O10,IF(ISNUMBER(Haver!I10),Haver!I10,IF(ISNUMBER(Tickers!V10),Tickers!V10,""))),"") | J18: =IFERROR(IF(ISNUMBER(Tickers!Q10),Tickers!Q10,IF(ISNUMBER(Haver!K10),Haver!K10,IF(ISNUMBER(Tickers!W10),Tickers!W10,""))),"") | K18: =IFERROR(IF(ISNUMBER(Tickers!S10),Tickers!S10,IF(ISNUMBER(Haver!M10),Haver!M10,IF(ISNUMBER(Tickers!X10),Tickers!X10,""))),"") | L18: =IFERROR(($D$18-AVERAGE($D$15:$D$85))/STDEV($D$15:$D$85),"") | M18: =IFERROR(($I$18-AVERAGE($I$15:$I$85))/STDEV($I$15:$I$85),"") | N18: =IFERROR(-($J$18-AVERAGE($J$15:$J$85))/STDEV($J$15:$J$85),"") | O18: =IFERROR(-($K$18-AVERAGE($K$15:$K$85))/STDEV($K$15:$K$85),"") | P18: =IFERROR(-($G$18-AVERAGE($G$15:$G$85))/STDEV($G$15:$G$85),"") | Q18: =IFERROR(($H$18-AVERAGE($H$15:$H$85))/STDEV($H$15:$H$85),"") | R18: =IFERROR((IF(ISNUMBER(L18),$D$7*L18,0)+IF(ISNUMBER(M18),$D$8*M18,0)+IF(ISNUMBER(N18),$D$9*N18,0)+IF(ISNUMBER(O18),$D$10*O18,0)+IF(ISNUMBER(P18),$D$11*P18,0)+IF(ISNUMBER(Q18),$D$12*Q18,0))/(IF(ISNUMBER(L18),$D$7,0)+IF(ISNUMBER(M18),$D$8,0)+IF(ISNUMBER(N18),$D$9,0)+IF(ISNUMBER(O18),$D$10,0)+IF(ISNUMBER(P18),$D$11,0)+IF(ISNUMBER(Q18),$D$12,0)),"") | S18: =IFERROR(LN($E$18),"") | T18: =IFERROR($N$7+$N$8*$R$18,"") | U18: =IFERROR($S$18-$T$18,"") | V18: =IFERROR(($U$18-AVERAGE($U$15:$U$85))/STDEV($U$15:$U$85),"") | W18: =IF(ISNUMBER($V$18),IF($V$18>=1.5,"CHEAP",IF($V$18>=0.5,"slightly cheap",IF($V$18<=-1.5,"RICH",IF($V$18<=-0.5,"slightly rich","fair")))),"") | X18: =SUMPRODUCT(--ISNUMBER((D18,G18,H18,I18,J18,K18))) | Y18: =IF(X18>=5,"HIGH",IF(X18>=3,"MED","LOW")) | Z18: =IF(AND(ISNUMBER(S18),X18>=$S$11),S18,"") | AA18: =IF(AND(ISNUMBER(R18),X18>=$S$11),R18,"")
B19: =Tickers!B11 | C19: =Tickers!C11 | D19: =Tickers!E11 | E19: =IFERROR(Tickers!G11,"") | F19: =IFERROR(Tickers!I11,"") | G19: =IFERROR(IF(ISNUMBER(Tickers!K11),Tickers!K11,IF(ISNUMBER(Haver!E11),Haver!E11,IF(ISNUMBER(Tickers!T11),Tickers!T11,""))),"") | H19: =IFERROR(IF(ISNUMBER(Tickers!M11),Tickers!M11,IF(ISNUMBER(Haver!G11),Haver!G11,IF(ISNUMBER(Tickers!U11),Tickers!U11,""))),"") | I19: =IFERROR(IF(ISNUMBER(Tickers!O11),Tickers!O11,IF(ISNUMBER(Haver!I11),Haver!I11,IF(ISNUMBER(Tickers!V11),Tickers!V11,""))),"") | J19: =IFERROR(IF(ISNUMBER(Tickers!Q11),Tickers!Q11,IF(ISNUMBER(Haver!K11),Haver!K11,IF(ISNUMBER(Tickers!W11),Tickers!W11,""))),"") | K19: =IFERROR(IF(ISNUMBER(Tickers!S11),Tickers!S11,IF(ISNUMBER(Haver!M11),Haver!M11,IF(ISNUMBER(Tickers!X11),Tickers!X11,""))),"") | L19: =IFERROR(($D$19-AVERAGE($D$15:$D$85))/STDEV($D$15:$D$85),"") | M19: =IFERROR(($I$19-AVERAGE($I$15:$I$85))/STDEV($I$15:$I$85),"") | N19: =IFERROR(-($J$19-AVERAGE($J$15:$J$85))/STDEV($J$15:$J$85),"") | O19: =IFERROR(-($K$19-AVERAGE($K$15:$K$85))/STDEV($K$15:$K$85),"") | P19: =IFERROR(-($G$19-AVERAGE($G$15:$G$85))/STDEV($G$15:$G$85),"") | Q19: =IFERROR(($H$19-AVERAGE($H$15:$H$85))/STDEV($H$15:$H$85),"") | R19: =IFERROR((IF(ISNUMBER(L19),$D$7*L19,0)+IF(ISNUMBER(M19),$D$8*M19,0)+IF(ISNUMBER(N19),$D$9*N19,0)+IF(ISNUMBER(O19),$D$10*O19,0)+IF(ISNUMBER(P19),$D$11*P19,0)+IF(ISNUMBER(Q19),$D$12*Q19,0))/(IF(ISNUMBER(L19),$D$7,0)+IF(ISNUMBER(M19),$D$8,0)+IF(ISNUMBER(N19),$D$9,0)+IF(ISNUMBER(O19),$D$10,0)+IF(ISNUMBER(P19),$D$11,0)+IF(ISNUMBER(Q19),$D$12,0)),"") | S19: =IFERROR(LN($E$19),"") | T19: =IFERROR($N$7+$N$8*$R$19,"") | U19: =IFERROR($S$19-$T$19,"") | V19: =IFERROR(($U$19-AVERAGE($U$15:$U$85))/STDEV($U$15:$U$85),"") | W19: =IF(ISNUMBER($V$19),IF($V$19>=1.5,"CHEAP",IF($V$19>=0.5,"slightly cheap",IF($V$19<=-1.5,"RICH",IF($V$19<=-0.5,"slightly rich","fair")))),"") | X19: =SUMPRODUCT(--ISNUMBER((D19,G19,H19,I19,J19,K19))) | Y19: =IF(X19>=5,"HIGH",IF(X19>=3,"MED","LOW")) | Z19: =IF(AND(ISNUMBER(S19),X19>=$S$11),S19,"") | AA19: =IF(AND(ISNUMBER(R19),X19>=$S$11),R19,"")
B20: =Tickers!B12 | C20: =Tickers!C12 | D20: =Tickers!E12 | E20: =IFERROR(Tickers!G12,"") | F20: =IFERROR(Tickers!I12,"") | G20: =IFERROR(IF(ISNUMBER(Tickers!K12),Tickers!K12,IF(ISNUMBER(Haver!E12),Haver!E12,IF(ISNUMBER(Tickers!T12),Tickers!T12,""))),"") | H20: =IFERROR(IF(ISNUMBER(Tickers!M12),Tickers!M12,IF(ISNUMBER(Haver!G12),Haver!G12,IF(ISNUMBER(Tickers!U12),Tickers!U12,""))),"") | I20: =IFERROR(IF(ISNUMBER(Tickers!O12),Tickers!O12,IF(ISNUMBER(Haver!I12),Haver!I12,IF(ISNUMBER(Tickers!V12),Tickers!V12,""))),"") | J20: =IFERROR(IF(ISNUMBER(Tickers!Q12),Tickers!Q12,IF(ISNUMBER(Haver!K12),Haver!K12,IF(ISNUMBER(Tickers!W12),Tickers!W12,""))),"") | K20: =IFERROR(IF(ISNUMBER(Tickers!S12),Tickers!S12,IF(ISNUMBER(Haver!M12),Haver!M12,IF(ISNUMBER(Tickers!X12),Tickers!X12,""))),"") | L20: =IFERROR(($D$20-AVERAGE($D$15:$D$85))/STDEV($D$15:$D$85),"") | M20: =IFERROR(($I$20-AVERAGE($I$15:$I$85))/STDEV($I$15:$I$85),"") | N20: =IFERROR(-($J$20-AVERAGE($J$15:$J$85))/STDEV($J$15:$J$85),"") | O20: =IFERROR(-($K$20-AVERAGE($K$15:$K$85))/STDEV($K$15:$K$85),"") | P20: =IFERROR(-($G$20-AVERAGE($G$15:$G$85))/STDEV($G$15:$G$85),"") | Q20: =IFERROR(($H$20-AVERAGE($H$15:$H$85))/STDEV($H$15:$H$85),"") | R20: =IFERROR((IF(ISNUMBER(L20),$D$7*L20,0)+IF(ISNUMBER(M20),$D$8*M20,0)+IF(ISNUMBER(N20),$D$9*N20,0)+IF(ISNUMBER(O20),$D$10*O20,0)+IF(ISNUMBER(P20),$D$11*P20,0)+IF(ISNUMBER(Q20),$D$12*Q20,0))/(IF(ISNUMBER(L20),$D$7,0)+IF(ISNUMBER(M20),$D$8,0)+IF(ISNUMBER(N20),$D$9,0)+IF(ISNUMBER(O20),$D$10,0)+IF(ISNUMBER(P20),$D$11,0)+IF(ISNUMBER(Q20),$D$12,0)),"") | S20: =IFERROR(LN($E$20),"") | T20: =IFERROR($N$7+$N$8*$R$20,"") | U20: =IFERROR($S$20-$T$20,"") | V20: =IFERROR(($U$20-AVERAGE($U$15:$U$85))/STDEV($U$15:$U$85),"") | W20: =IF(ISNUMBER($V$20),IF($V$20>=1.5,"CHEAP",IF($V$20>=0.5,"slightly cheap",IF($V$20<=-1.5,"RICH",IF($V$20<=-0.5,"slightly rich","fair")))),"") | X20: =SUMPRODUCT(--ISNUMBER((D20,G20,H20,I20,J20,K20))) | Y20: =IF(X20>=5,"HIGH",IF(X20>=3,"MED","LOW")) | Z20: =IF(AND(ISNUMBER(S20),X20>=$S$11),S20,"") | AA20: =IF(AND(ISNUMBER(R20),X20>=$S$11),R20,"")
B21: =Tickers!B13 | C21: =Tickers!C13 | D21: =Tickers!E13 | E21: =IFERROR(Tickers!G13,"") | F21: =IFERROR(Tickers!I13,"") | G21: =IFERROR(IF(ISNUMBER(Tickers!K13),Tickers!K13,IF(ISNUMBER(Haver!E13),Haver!E13,IF(ISNUMBER(Tickers!T13),Tickers!T13,""))),"") | H21: =IFERROR(IF(ISNUMBER(Tickers!M13),Tickers!M13,IF(ISNUMBER(Haver!G13),Haver!G13,IF(ISNUMBER(Tickers!U13),Tickers!U13,""))),"") | I21: =IFERROR(IF(ISNUMBER(Tickers!O13),Tickers!O13,IF(ISNUMBER(Haver!I13),Haver!I13,IF(ISNUMBER(Tickers!V13),Tickers!V13,""))),"") | J21: =IFERROR(IF(ISNUMBER(Tickers!Q13),Tickers!Q13,IF(ISNUMBER(Haver!K13),Haver!K13,IF(ISNUMBER(Tickers!W13),Tickers!W13,""))),"") | K21: =IFERROR(IF(ISNUMBER(Tickers!S13),Tickers!S13,IF(ISNUMBER(Haver!M13),Haver!M13,IF(ISNUMBER(Tickers!X13),Tickers!X13,""))),"") | L21: =IFERROR(($D$21-AVERAGE($D$15:$D$85))/STDEV($D$15:$D$85),"") | M21: =IFERROR(($I$21-AVERAGE($I$15:$I$85))/STDEV($I$15:$I$85),"") | N21: =IFERROR(-($J$21-AVERAGE($J$15:$J$85))/STDEV($J$15:$J$85),"") | O21: =IFERROR(-($K$21-AVERAGE($K$15:$K$85))/STDEV($K$15:$K$85),"") | P21: =IFERROR(-($G$21-AVERAGE($G$15:$G$85))/STDEV($G$15:$G$85),"") | Q21: =IFERROR(($H$21-AVERAGE($H$15:$H$85))/STDEV($H$15:$H$85),"") | R21: =IFERROR((IF(ISNUMBER(L21),$D$7*L21,0)+IF(ISNUMBER(M21),$D$8*M21,0)+IF(ISNUMBER(N21),$D$9*N21,0)+IF(ISNUMBER(O21),$D$10*O21,0)+IF(ISNUMBER(P21),$D$11*P21,0)+IF(ISNUMBER(Q21),$D$12*Q21,0))/(IF(ISNUMBER(L21),$D$7,0)+IF(ISNUMBER(M21),$D$8,0)+IF(ISNUMBER(N21),$D$9,0)+IF(ISNUMBER(O21),$D$10,0)+IF(ISNUMBER(P21),$D$11,0)+IF(ISNUMBER(Q21),$D$12,0)),"") | S21: =IFERROR(LN($E$21),"") | T21: =IFERROR($N$7+$N$8*$R$21,"") | U21: =IFERROR($S$21-$T$21,"") | V21: =IFERROR(($U$21-AVERAGE($U$15:$U$85))/STDEV($U$15:$U$85),"") | W21: =IF(ISNUMBER($V$21),IF($V$21>=1.5,"CHEAP",IF($V$21>=0.5,"slightly cheap",IF($V$21<=-1.5,"RICH",IF($V$21<=-0.5,"slightly rich","fair")))),"") | X21: =SUMPRODUCT(--ISNUMBER((D21,G21,H21,I21,J21,K21))) | Y21: =IF(X21>=5,"HIGH",IF(X21>=3,"MED","LOW")) | Z21: =IF(AND(ISNUMBER(S21),X21>=$S$11),S21,"") | AA21: =IF(AND(ISNUMBER(R21),X21>=$S$11),R21,"")
B22: =Tickers!B14 | C22: =Tickers!C14 | D22: =Tickers!E14 | E22: =IFERROR(Tickers!G14,"") | F22: =IFERROR(Tickers!I14,"") | G22: =IFERROR(IF(ISNUMBER(Tickers!K14),Tickers!K14,IF(ISNUMBER(Haver!E14),Haver!E14,IF(ISNUMBER(Tickers!T14),Tickers!T14,""))),"") | H22: =IFERROR(IF(ISNUMBER(Tickers!M14),Tickers!M14,IF(ISNUMBER(Haver!G14),Haver!G14,IF(ISNUMBER(Tickers!U14),Tickers!U14,""))),"") | I22: =IFERROR(IF(ISNUMBER(Tickers!O14),Tickers!O14,IF(ISNUMBER(Haver!I14),Haver!I14,IF(ISNUMBER(Tickers!V14),Tickers!V14,""))),"") | J22: =IFERROR(IF(ISNUMBER(Tickers!Q14),Tickers!Q14,IF(ISNUMBER(Haver!K14),Haver!K14,IF(ISNUMBER(Tickers!W14),Tickers!W14,""))),"") | K22: =IFERROR(IF(ISNUMBER(Tickers!S14),Tickers!S14,IF(ISNUMBER(Haver!M14),Haver!M14,IF(ISNUMBER(Tickers!X14),Tickers!X14,""))),"") | L22: =IFERROR(($D$22-AVERAGE($D$15:$D$85))/STDEV($D$15:$D$85),"") | M22: =IFERROR(($I$22-AVERAGE($I$15:$I$85))/STDEV($I$15:$I$85),"") | N22: =IFERROR(-($J$22-AVERAGE($J$15:$J$85))/STDEV($J$15:$J$85),"") | O22: =IFERROR(-($K$22-AVERAGE($K$15:$K$85))/STDEV($K$15:$K$85),"") | P22: =IFERROR(-($G$22-AVERAGE($G$15:$G$85))/STDEV($G$15:$G$85),"") | Q22: =IFERROR(($H$22-AVERAGE($H$15:$H$85))/STDEV($H$15:$H$85),"") | R22: =IFERROR((IF(ISNUMBER(L22),$D$7*L22,0)+IF(ISNUMBER(M22),$D$8*M22,0)+IF(ISNUMBER(N22),$D$9*N22,0)+IF(ISNUMBER(O22),$D$10*O22,0)+IF(ISNUMBER(P22),$D$11*P22,0)+IF(ISNUMBER(Q22),$D$12*Q22,0))/(IF(ISNUMBER(L22),$D$7,0)+IF(ISNUMBER(M22),$D$8,0)+IF(ISNUMBER(N22),$D$9,0)+IF(ISNUMBER(O22),$D$10,0)+IF(ISNUMBER(P22),$D$11,0)+IF(ISNUMBER(Q22),$D$12,0)),"") | S22: =IFERROR(LN($E$22),"") | T22: =IFERROR($N$7+$N$8*$R$22,"") | U22: =IFERROR($S$22-$T$22,"") | V22: =IFERROR(($U$22-AVERAGE($U$15:$U$85))/STDEV($U$15:$U$85),"") | W22: =IF(ISNUMBER($V$22),IF($V$22>=1.5,"CHEAP",IF($V$22>=0.5,"slightly cheap",IF($V$22<=-1.5,"RICH",IF($V$22<=-0.5,"slightly rich","fair")))),"") | X22: =SUMPRODUCT(--ISNUMBER((D22,G22,H22,I22,J22,K22))) | Y22: =IF(X22>=5,"HIGH",IF(X22>=3,"MED","LOW")) | Z22: =IF(AND(ISNUMBER(S22),X22>=$S$11),S22,"") | AA22: =IF(AND(ISNUMBER(R22),X22>=$S$11),R22,"")
B23: =Tickers!B15 | C23: =Tickers!C15 | D23: =Tickers!E15 | E23: =IFERROR(Tickers!G15,"") | F23: =IFERROR(Tickers!I15,"") | G23: =IFERROR(IF(ISNUMBER(Tickers!K15),Tickers!K15,IF(ISNUMBER(Haver!E15),Haver!E15,IF(ISNUMBER(Tickers!T15),Tickers!T15,""))),"") | H23: =IFERROR(IF(ISNUMBER(Tickers!M15),Tickers!M15,IF(ISNUMBER(Haver!G15),Haver!G15,IF(ISNUMBER(Tickers!U15),Tickers!U15,""))),"") | I23: =IFERROR(IF(ISNUMBER(Tickers!O15),Tickers!O15,IF(ISNUMBER(Haver!I15),Haver!I15,IF(ISNUMBER(Tickers!V15),Tickers!V15,""))),"") | J23: =IFERROR(IF(ISNUMBER(Tickers!Q15),Tickers!Q15,IF(ISNUMBER(Haver!K15),Haver!K15,IF(ISNUMBER(Tickers!W15),Tickers!W15,""))),"") | K23: =IFERROR(IF(ISNUMBER(Tickers!S15),Tickers!S15,IF(ISNUMBER(Haver!M15),Haver!M15,IF(ISNUMBER(Tickers!X15),Tickers!X15,""))),"") | L23: =IFERROR(($D$23-AVERAGE($D$15:$D$85))/STDEV($D$15:$D$85),"") | M23: =IFERROR(($I$23-AVERAGE($I$15:$I$85))/STDEV($I$15:$I$85),"") | N23: =IFERROR(-($J$23-AVERAGE($J$15:$J$85))/STDEV($J$15:$J$85),"") | O23: =IFERROR(-($K$23-AVERAGE($K$15:$K$85))/STDEV($K$15:$K$85),"") | P23: =IFERROR(-($G$23-AVERAGE($G$15:$G$85))/STDEV($G$15:$G$85),"") | Q23: =IFERROR(($H$23-AVERAGE($H$15:$H$85))/STDEV($H$15:$H$85),"") | R23: =IFERROR((IF(ISNUMBER(L23),$D$7*L23,0)+IF(ISNUMBER(M23),$D$8*M23,0)+IF(ISNUMBER(N23),$D$9*N23,0)+IF(ISNUMBER(O23),$D$10*O23,0)+IF(ISNUMBER(P23),$D$11*P23,0)+IF(ISNUMBER(Q23),$D$12*Q23,0))/(IF(ISNUMBER(L23),$D$7,0)+IF(ISNUMBER(M23),$D$8,0)+IF(ISNUMBER(N23),$D$9,0)+IF(ISNUMBER(O23),$D$10,0)+IF(ISNUMBER(P23),$D$11,0)+IF(ISNUMBER(Q23),$D$12,0)),"") | S23: =IFERROR(LN($E$23),"") | T23: =IFERROR($N$7+$N$8*$R$23,"") | U23: =IFERROR($S$23-$T$23,"") | V23: =IFERROR(($U$23-AVERAGE($U$15:$U$85))/STDEV($U$15:$U$85),"") | W23: =IF(ISNUMBER($V$23),IF($V$23>=1.5,"CHEAP",IF($V$23>=0.5,"slightly cheap",IF($V$23<=-1.5,"RICH",IF($V$23<=-0.5,"slightly rich","fair")))),"") | X23: =SUMPRODUCT(--ISNUMBER((D23,G23,H23,I23,J23,K23))) | Y23: =IF(X23>=5,"HIGH",IF(X23>=3,"MED","LOW")) | Z23: =IF(AND(ISNUMBER(S23),X23>=$S$11),S23,"") | AA23: =IF(AND(ISNUMBER(R23),X23>=$S$11),R23,"")
B24: =Tickers!B16 | C24: =Tickers!C16 | D24: =Tickers!E16 | E24: =IFERROR(Tickers!G16,"") | F24: =IFERROR(Tickers!I16,"") | G24: =IFERROR(IF(ISNUMBER(Tickers!K16),Tickers!K16,IF(ISNUMBER(Haver!E16),Haver!E16,IF(ISNUMBER(Tickers!T16),Tickers!T16,""))),"") | H24: =IFERROR(IF(ISNUMBER(Tickers!M16),Tickers!M16,IF(ISNUMBER(Haver!G16),Haver!G16,IF(ISNUMBER(Tickers!U16),Tickers!U16,""))),"") | I24: =IFERROR(IF(ISNUMBER(Tickers!O16),Tickers!O16,IF(ISNUMBER(Haver!I16),Haver!I16,IF(ISNUMBER(Tickers!V16),Tickers!V16,""))),"") | J24: =IFERROR(IF(ISNUMBER(Tickers!Q16),Tickers!Q16,IF(ISNUMBER(Haver!K16),Haver!K16,IF(ISNUMBER(Tickers!W16),Tickers!W16,""))),"") | K24: =IFERROR(IF(ISNUMBER(Tickers!S16),Tickers!S16,IF(ISNUMBER(Haver!M16),Haver!M16,IF(ISNUMBER(Tickers!X16),Tickers!X16,""))),"") | L24: =IFERROR(($D$24-AVERAGE($D$15:$D$85))/STDEV($D$15:$D$85),"") | M24: =IFERROR(($I$24-AVERAGE($I$15:$I$85))/STDEV($I$15:$I$85),"") | N24: =IFERROR(-($J$24-AVERAGE($J$15:$J$85))/STDEV($J$15:$J$85),"") | O24: =IFERROR(-($K$24-AVERAGE($K$15:$K$85))/STDEV($K$15:$K$85),"") | P24: =IFERROR(-($G$24-AVERAGE($G$15:$G$85))/STDEV($G$15:$G$85),"") | Q24: =IFERROR(($H$24-AVERAGE($H$15:$H$85))/STDEV($H$15:$H$85),"") | R24: =IFERROR((IF(ISNUMBER(L24),$D$7*L24,0)+IF(ISNUMBER(M24),$D$8*M24,0)+IF(ISNUMBER(N24),$D$9*N24,0)+IF(ISNUMBER(O24),$D$10*O24,0)+IF(ISNUMBER(P24),$D$11*P24,0)+IF(ISNUMBER(Q24),$D$12*Q24,0))/(IF(ISNUMBER(L24),$D$7,0)+IF(ISNUMBER(M24),$D$8,0)+IF(ISNUMBER(N24),$D$9,0)+IF(ISNUMBER(O24),$D$10,0)+IF(ISNUMBER(P24),$D$11,0)+IF(ISNUMBER(Q24),$D$12,0)),"") | S24: =IFERROR(LN($E$24),"") | T24: =IFERROR($N$7+$N$8*$R$24,"") | U24: =IFERROR($S$24-$T$24,"") | V24: =IFERROR(($U$24-AVERAGE($U$15:$U$85))/STDEV($U$15:$U$85),"") | W24: =IF(ISNUMBER($V$24),IF($V$24>=1.5,"CHEAP",IF($V$24>=0.5,"slightly cheap",IF($V$24<=-1.5,"RICH",IF($V$24<=-0.5,"slightly rich","fair")))),"") | X24: =SUMPRODUCT(--ISNUMBER((D24,G24,H24,I24,J24,K24))) | Y24: =IF(X24>=5,"HIGH",IF(X24>=3,"MED","LOW")) | Z24: =IF(AND(ISNUMBER(S24),X24>=$S$11),S24,"") | AA24: =IF(AND(ISNUMBER(R24),X24>=$S$11),R24,"")
B25: =Tickers!B17 | C25: =Tickers!C17 | D25: =Tickers!E17 | E25: =IFERROR(Tickers!G17,"") | F25: =IFERROR(Tickers!I17,"") | G25: =IFERROR(IF(ISNUMBER(Tickers!K17),Tickers!K17,IF(ISNUMBER(Haver!E17),Haver!E17,IF(ISNUMBER(Tickers!T17),Tickers!T17,""))),"") | H25: =IFERROR(IF(ISNUMBER(Tickers!M17),Tickers!M17,IF(ISNUMBER(Haver!G17),Haver!G17,IF(ISNUMBER(Tickers!U17),Tickers!U17,""))),"") | I25: =IFERROR(IF(ISNUMBER(Tickers!O17),Tickers!O17,IF(ISNUMBER(Haver!I17),Haver!I17,IF(ISNUMBER(Tickers!V17),Tickers!V17,""))),"") | J25: =IFERROR(IF(ISNUMBER(Tickers!Q17),Tickers!Q17,IF(ISNUMBER(Haver!K17),Haver!K17,IF(ISNUMBER(Tickers!W17),Tickers!W17,""))),"") | K25: =IFERROR(IF(ISNUMBER(Tickers!S17),Tickers!S17,IF(ISNUMBER(Haver!M17),Haver!M17,IF(ISNUMBER(Tickers!X17),Tickers!X17,""))),"") | L25: =IFERROR(($D$25-AVERAGE($D$15:$D$85))/STDEV($D$15:$D$85),"") | M25: =IFERROR(($I$25-AVERAGE($I$15:$I$85))/STDEV($I$15:$I$85),"") | N25: =IFERROR(-($J$25-AVERAGE($J$15:$J$85))/STDEV($J$15:$J$85),"") | O25: =IFERROR(-($K$25-AVERAGE($K$15:$K$85))/STDEV($K$15:$K$85),"") | P25: =IFERROR(-($G$25-AVERAGE($G$15:$G$85))/STDEV($G$15:$G$85),"") | Q25: =IFERROR(($H$25-AVERAGE($H$15:$H$85))/STDEV($H$15:$H$85),"") | R25: =IFERROR((IF(ISNUMBER(L25),$D$7*L25,0)+IF(ISNUMBER(M25),$D$8*M25,0)+IF(ISNUMBER(N25),$D$9*N25,0)+IF(ISNUMBER(O25),$D$10*O25,0)+IF(ISNUMBER(P25),$D$11*P25,0)+IF(ISNUMBER(Q25),$D$12*Q25,0))/(IF(ISNUMBER(L25),$D$7,0)+IF(ISNUMBER(M25),$D$8,0)+IF(ISNUMBER(N25),$D$9,0)+IF(ISNUMBER(O25),$D$10,0)+IF(ISNUMBER(P25),$D$11,0)+IF(ISNUMBER(Q25),$D$12,0)),"") | S25: =IFERROR(LN($E$25),"") | T25: =IFERROR($N$7+$N$8*$R$25,"") | U25: =IFERROR($S$25-$T$25,"") | V25: =IFERROR(($U$25-AVERAGE($U$15:$U$85))/STDEV($U$15:$U$85),"") | W25: =IF(ISNUMBER($V$25),IF($V$25>=1.5,"CHEAP",IF($V$25>=0.5,"slightly cheap",IF($V$25<=-1.5,"RICH",IF($V$25<=-0.5,"slightly rich","fair")))),"") | X25: =SUMPRODUCT(--ISNUMBER((D25,G25,H25,I25,J25,K25))) | Y25: =IF(X25>=5,"HIGH",IF(X25>=3,"MED","LOW")) | Z25: =IF(AND(ISNUMBER(S25),X25>=$S$11),S25,"") | AA25: =IF(AND(ISNUMBER(R25),X25>=$S$11),R25,"")
B26: =Tickers!B18 | C26: =Tickers!C18 | D26: =Tickers!E18 | E26: =IFERROR(Tickers!G18,"") | F26: =IFERROR(Tickers!I18,"") | G26: =IFERROR(IF(ISNUMBER(Tickers!K18),Tickers!K18,IF(ISNUMBER(Haver!E18),Haver!E18,IF(ISNUMBER(Tickers!T18),Tickers!T18,""))),"") | H26: =IFERROR(IF(ISNUMBER(Tickers!M18),Tickers!M18,IF(ISNUMBER(Haver!G18),Haver!G18,IF(ISNUMBER(Tickers!U18),Tickers!U18,""))),"") | I26: =IFERROR(IF(ISNUMBER(Tickers!O18),Tickers!O18,IF(ISNUMBER(Haver!I18),Haver!I18,IF(ISNUMBER(Tickers!V18),Tickers!V18,""))),"") | J26: =IFERROR(IF(ISNUMBER(Tickers!Q18),Tickers!Q18,IF(ISNUMBER(Haver!K18),Haver!K18,IF(ISNUMBER(Tickers!W18),Tickers!W18,""))),"") | K26: =IFERROR(IF(ISNUMBER(Tickers!S18),Tickers!S18,IF(ISNUMBER(Haver!M18),Haver!M18,IF(ISNUMBER(Tickers!X18),Tickers!X18,""))),"") | L26: =IFERROR(($D$26-AVERAGE($D$15:$D$85))/STDEV($D$15:$D$85),"") | M26: =IFERROR(($I$26-AVERAGE($I$15:$I$85))/STDEV($I$15:$I$85),"") | N26: =IFERROR(-($J$26-AVERAGE($J$15:$J$85))/STDEV($J$15:$J$85),"") | O26: =IFERROR(-($K$26-AVERAGE($K$15:$K$85))/STDEV($K$15:$K$85),"") | P26: =IFERROR(-($G$26-AVERAGE($G$15:$G$85))/STDEV($G$15:$G$85),"") | Q26: =IFERROR(($H$26-AVERAGE($H$15:$H$85))/STDEV($H$15:$H$85),"") | R26: =IFERROR((IF(ISNUMBER(L26),$D$7*L26,0)+IF(ISNUMBER(M26),$D$8*M26,0)+IF(ISNUMBER(N26),$D$9*N26,0)+IF(ISNUMBER(O26),$D$10*O26,0)+IF(ISNUMBER(P26),$D$11*P26,0)+IF(ISNUMBER(Q26),$D$12*Q26,0))/(IF(ISNUMBER(L26),$D$7,0)+IF(ISNUMBER(M26),$D$8,0)+IF(ISNUMBER(N26),$D$9,0)+IF(ISNUMBER(O26),$D$10,0)+IF(ISNUMBER(P26),$D$11,0)+IF(ISNUMBER(Q26),$D$12,0)),"") | S26: =IFERROR(LN($E$26),"") | T26: =IFERROR($N$7+$N$8*$R$26,"") | U26: =IFERROR($S$26-$T$26,"") | V26: =IFERROR(($U$26-AVERAGE($U$15:$U$85))/STDEV($U$15:$U$85),"") | W26: =IF(ISNUMBER($V$26),IF($V$26>=1.5,"CHEAP",IF($V$26>=0.5,"slightly cheap",IF($V$26<=-1.5,"RICH",IF($V$26<=-0.5,"slightly rich","fair")))),"") | X26: =SUMPRODUCT(--ISNUMBER((D26,G26,H26,I26,J26,K26))) | Y26: =IF(X26>=5,"HIGH",IF(X26>=3,"MED","LOW")) | Z26: =IF(AND(ISNUMBER(S26),X26>=$S$11),S26,"") | AA26: =IF(AND(ISNUMBER(R26),X26>=$S$11),R26,"")
B27: =Tickers!B19 | C27: =Tickers!C19 | D27: =Tickers!E19 | E27: =IFERROR(Tickers!G19,"") | F27: =IFERROR(Tickers!I19,"") | G27: =IFERROR(IF(ISNUMBER(Tickers!K19),Tickers!K19,IF(ISNUMBER(Haver!E19),Haver!E19,IF(ISNUMBER(Tickers!T19),Tickers!T19,""))),"") | H27: =IFERROR(IF(ISNUMBER(Tickers!M19),Tickers!M19,IF(ISNUMBER(Haver!G19),Haver!G19,IF(ISNUMBER(Tickers!U19),Tickers!U19,""))),"") | I27: =IFERROR(IF(ISNUMBER(Tickers!O19),Tickers!O19,IF(ISNUMBER(Haver!I19),Haver!I19,IF(ISNUMBER(Tickers!V19),Tickers!V19,""))),"") | J27: =IFERROR(IF(ISNUMBER(Tickers!Q19),Tickers!Q19,IF(ISNUMBER(Haver!K19),Haver!K19,IF(ISNUMBER(Tickers!W19),Tickers!W19,""))),"") | K27: =IFERROR(IF(ISNUMBER(Tickers!S19),Tickers!S19,IF(ISNUMBER(Haver!M19),Haver!M19,IF(ISNUMBER(Tickers!X19),Tickers!X19,""))),"") | L27: =IFERROR(($D$27-AVERAGE($D$15:$D$85))/STDEV($D$15:$D$85),"") | M27: =IFERROR(($I$27-AVERAGE($I$15:$I$85))/STDEV($I$15:$I$85),"") | N27: =IFERROR(-($J$27-AVERAGE($J$15:$J$85))/STDEV($J$15:$J$85),"") | O27: =IFERROR(-($K$27-AVERAGE($K$15:$K$85))/STDEV($K$15:$K$85),"") | P27: =IFERROR(-($G$27-AVERAGE($G$15:$G$85))/STDEV($G$15:$G$85),"") | Q27: =IFERROR(($H$27-AVERAGE($H$15:$H$85))/STDEV($H$15:$H$85),"") | R27: =IFERROR((IF(ISNUMBER(L27),$D$7*L27,0)+IF(ISNUMBER(M27),$D$8*M27,0)+IF(ISNUMBER(N27),$D$9*N27,0)+IF(ISNUMBER(O27),$D$10*O27,0)+IF(ISNUMBER(P27),$D$11*P27,0)+IF(ISNUMBER(Q27),$D$12*Q27,0))/(IF(ISNUMBER(L27),$D$7,0)+IF(ISNUMBER(M27),$D$8,0)+IF(ISNUMBER(N27),$D$9,0)+IF(ISNUMBER(O27),$D$10,0)+IF(ISNUMBER(P27),$D$11,0)+IF(ISNUMBER(Q27),$D$12,0)),"") | S27: =IFERROR(LN($E$27),"") | T27: =IFERROR($N$7+$N$8*$R$27,"") | U27: =IFERROR($S$27-$T$27,"") | V27: =IFERROR(($U$27-AVERAGE($U$15:$U$85))/STDEV($U$15:$U$85),"") | W27: =IF(ISNUMBER($V$27),IF($V$27>=1.5,"CHEAP",IF($V$27>=0.5,"slightly cheap",IF($V$27<=-1.5,"RICH",IF($V$27<=-0.5,"slightly rich","fair")))),"") | X27: =SUMPRODUCT(--ISNUMBER((D27,G27,H27,I27,J27,K27))) | Y27: =IF(X27>=5,"HIGH",IF(X27>=3,"MED","LOW")) | Z27: =IF(AND(ISNUMBER(S27),X27>=$S$11),S27,"") | AA27: =IF(AND(ISNUMBER(R27),X27>=$S$11),R27,"")
B28: =Tickers!B20 | C28: =Tickers!C20 | D28: =Tickers!E20 | E28: =IFERROR(Tickers!G20,"") | F28: =IFERROR(Tickers!I20,"") | G28: =IFERROR(IF(ISNUMBER(Tickers!K20),Tickers!K20,IF(ISNUMBER(Haver!E20),Haver!E20,IF(ISNUMBER(Tickers!T20),Tickers!T20,""))),"") | H28: =IFERROR(IF(ISNUMBER(Tickers!M20),Tickers!M20,IF(ISNUMBER(Haver!G20),Haver!G20,IF(ISNUMBER(Tickers!U20),Tickers!U20,""))),"") | I28: =IFERROR(IF(ISNUMBER(Tickers!O20),Tickers!O20,IF(ISNUMBER(Haver!I20),Haver!I20,IF(ISNUMBER(Tickers!V20),Tickers!V20,""))),"") | J28: =IFERROR(IF(ISNUMBER(Tickers!Q20),Tickers!Q20,IF(ISNUMBER(Haver!K20),Haver!K20,IF(ISNUMBER(Tickers!W20),Tickers!W20,""))),"") | K28: =IFERROR(IF(ISNUMBER(Tickers!S20),Tickers!S20,IF(ISNUMBER(Haver!M20),Haver!M20,IF(ISNUMBER(Tickers!X20),Tickers!X20,""))),"") | L28: =IFERROR(($D$28-AVERAGE($D$15:$D$85))/STDEV($D$15:$D$85),"") | M28: =IFERROR(($I$28-AVERAGE($I$15:$I$85))/STDEV($I$15:$I$85),"") | N28: =IFERROR(-($J$28-AVERAGE($J$15:$J$85))/STDEV($J$15:$J$85),"") | O28: =IFERROR(-($K$28-AVERAGE($K$15:$K$85))/STDEV($K$15:$K$85),"") | P28: =IFERROR(-($G$28-AVERAGE($G$15:$G$85))/STDEV($G$15:$G$85),"") | Q28: =IFERROR(($H$28-AVERAGE($H$15:$H$85))/STDEV($H$15:$H$85),"") | R28: =IFERROR((IF(ISNUMBER(L28),$D$7*L28,0)+IF(ISNUMBER(M28),$D$8*M28,0)+IF(ISNUMBER(N28),$D$9*N28,0)+IF(ISNUMBER(O28),$D$10*O28,0)+IF(ISNUMBER(P28),$D$11*P28,0)+IF(ISNUMBER(Q28),$D$12*Q28,0))/(IF(ISNUMBER(L28),$D$7,0)+IF(ISNUMBER(M28),$D$8,0)+IF(ISNUMBER(N28),$D$9,0)+IF(ISNUMBER(O28),$D$10,0)+IF(ISNUMBER(P28),$D$11,0)+IF(ISNUMBER(Q28),$D$12,0)),"") | S28: =IFERROR(LN($E$28),"") | T28: =IFERROR($N$7+$N$8*$R$28,"") | U28: =IFERROR($S$28-$T$28,"") | V28: =IFERROR(($U$28-AVERAGE($U$15:$U$85))/STDEV($U$15:$U$85),"") | W28: =IF(ISNUMBER($V$28),IF($V$28>=1.5,"CHEAP",IF($V$28>=0.5,"slightly cheap",IF($V$28<=-1.5,"RICH",IF($V$28<=-0.5,"slightly rich","fair")))),"") | X28: =SUMPRODUCT(--ISNUMBER((D28,G28,H28,I28,J28,K28))) | Y28: =IF(X28>=5,"HIGH",IF(X28>=3,"MED","LOW")) | Z28: =IF(AND(ISNUMBER(S28),X28>=$S$11),S28,"") | AA28: =IF(AND(ISNUMBER(R28),X28>=$S$11),R28,"")
B29: =Tickers!B21 | C29: =Tickers!C21 | D29: =Tickers!E21 | E29: =IFERROR(Tickers!G21,"") | F29: =IFERROR(Tickers!I21,"") | G29: =IFERROR(IF(ISNUMBER(Tickers!K21),Tickers!K21,IF(ISNUMBER(Haver!E21),Haver!E21,IF(ISNUMBER(Tickers!T21),Tickers!T21,""))),"") | H29: =IFERROR(IF(ISNUMBER(Tickers!M21),Tickers!M21,IF(ISNUMBER(Haver!G21),Haver!G21,IF(ISNUMBER(Tickers!U21),Tickers!U21,""))),"") | I29: =IFERROR(IF(ISNUMBER(Tickers!O21),Tickers!O21,IF(ISNUMBER(Haver!I21),Haver!I21,IF(ISNUMBER(Tickers!V21),Tickers!V21,""))),"") | J29: =IFERROR(IF(ISNUMBER(Tickers!Q21),Tickers!Q21,IF(ISNUMBER(Haver!K21),Haver!K21,IF(ISNUMBER(Tickers!W21),Tickers!W21,""))),"") | K29: =IFERROR(IF(ISNUMBER(Tickers!S21),Tickers!S21,IF(ISNUMBER(Haver!M21),Haver!M21,IF(ISNUMBER(Tickers!X21),Tickers!X21,""))),"") | L29: =IFERROR(($D$29-AVERAGE($D$15:$D$85))/STDEV($D$15:$D$85),"") | M29: =IFERROR(($I$29-AVERAGE($I$15:$I$85))/STDEV($I$15:$I$85),"") | N29: =IFERROR(-($J$29-AVERAGE($J$15:$J$85))/STDEV($J$15:$J$85),"") | O29: =IFERROR(-($K$29-AVERAGE($K$15:$K$85))/STDEV($K$15:$K$85),"") | P29: =IFERROR(-($G$29-AVERAGE($G$15:$G$85))/STDEV($G$15:$G$85),"") | Q29: =IFERROR(($H$29-AVERAGE($H$15:$H$85))/STDEV($H$15:$H$85),"") | R29: =IFERROR((IF(ISNUMBER(L29),$D$7*L29,0)+IF(ISNUMBER(M29),$D$8*M29,0)+IF(ISNUMBER(N29),$D$9*N29,0)+IF(ISNUMBER(O29),$D$10*O29,0)+IF(ISNUMBER(P29),$D$11*P29,0)+IF(ISNUMBER(Q29),$D$12*Q29,0))/(IF(ISNUMBER(L29),$D$7,0)+IF(ISNUMBER(M29),$D$8,0)+IF(ISNUMBER(N29),$D$9,0)+IF(ISNUMBER(O29),$D$10,0)+IF(ISNUMBER(P29),$D$11,0)+IF(ISNUMBER(Q29),$D$12,0)),"") | S29: =IFERROR(LN($E$29),"") | T29: =IFERROR($N$7+$N$8*$R$29,"") | U29: =IFERROR($S$29-$T$29,"") | V29: =IFERROR(($U$29-AVERAGE($U$15:$U$85))/STDEV($U$15:$U$85),"") | W29: =IF(ISNUMBER($V$29),IF($V$29>=1.5,"CHEAP",IF($V$29>=0.5,"slightly cheap",IF($V$29<=-1.5,"RICH",IF($V$29<=-0.5,"slightly rich","fair")))),"") | X29: =SUMPRODUCT(--ISNUMBER((D29,G29,H29,I29,J29,K29))) | Y29: =IF(X29>=5,"HIGH",IF(X29>=3,"MED","LOW")) | Z29: =IF(AND(ISNUMBER(S29),X29>=$S$11),S29,"") | AA29: =IF(AND(ISNUMBER(R29),X29>=$S$11),R29,"")
B30: =Tickers!B22 | C30: =Tickers!C22 | D30: =Tickers!E22 | E30: =IFERROR(Tickers!G22,"") | F30: =IFERROR(Tickers!I22,"") | G30: =IFERROR(IF(ISNUMBER(Tickers!K22),Tickers!K22,IF(ISNUMBER(Haver!E22),Haver!E22,IF(ISNUMBER(Tickers!T22),Tickers!T22,""))),"") | H30: =IFERROR(IF(ISNUMBER(Tickers!M22),Tickers!M22,IF(ISNUMBER(Haver!G22),Haver!G22,IF(ISNUMBER(Tickers!U22),Tickers!U22,""))),"") | I30: =IFERROR(IF(ISNUMBER(Tickers!O22),Tickers!O22,IF(ISNUMBER(Haver!I22),Haver!I22,IF(ISNUMBER(Tickers!V22),Tickers!V22,""))),"") | J30: =IFERROR(IF(ISNUMBER(Tickers!Q22),Tickers!Q22,IF(ISNUMBER(Haver!K22),Haver!K22,IF(ISNUMBER(Tickers!W22),Tickers!W22,""))),"") | K30: =IFERROR(IF(ISNUMBER(Tickers!S22),Tickers!S22,IF(ISNUMBER(Haver!M22),Haver!M22,IF(ISNUMBER(Tickers!X22),Tickers!X22,""))),"") | L30: =IFERROR(($D$30-AVERAGE($D$15:$D$85))/STDEV($D$15:$D$85),"") | M30: =IFERROR(($I$30-AVERAGE($I$15:$I$85))/STDEV($I$15:$I$85),"") | N30: =IFERROR(-($J$30-AVERAGE($J$15:$J$85))/STDEV($J$15:$J$85),"") | O30: =IFERROR(-($K$30-AVERAGE($K$15:$K$85))/STDEV($K$15:$K$85),"") | P30: =IFERROR(-($G$30-AVERAGE($G$15:$G$85))/STDEV($G$15:$G$85),"") | Q30: =IFERROR(($H$30-AVERAGE($H$15:$H$85))/STDEV($H$15:$H$85),"") | R30: =IFERROR((IF(ISNUMBER(L30),$D$7*L30,0)+IF(ISNUMBER(M30),$D$8*M30,0)+IF(ISNUMBER(N30),$D$9*N30,0)+IF(ISNUMBER(O30),$D$10*O30,0)+IF(ISNUMBER(P30),$D$11*P30,0)+IF(ISNUMBER(Q30),$D$12*Q30,0))/(IF(ISNUMBER(L30),$D$7,0)+IF(ISNUMBER(M30),$D$8,0)+IF(ISNUMBER(N30),$D$9,0)+IF(ISNUMBER(O30),$D$10,0)+IF(ISNUMBER(P30),$D$11,0)+IF(ISNUMBER(Q30),$D$12,0)),"") | S30: =IFERROR(LN($E$30),"") | T30: =IFERROR($N$7+$N$8*$R$30,"") | U30: =IFERROR($S$30-$T$30,"") | V30: =IFERROR(($U$30-AVERAGE($U$15:$U$85))/STDEV($U$15:$U$85),"") | W30: =IF(ISNUMBER($V$30),IF($V$30>=1.5,"CHEAP",IF($V$30>=0.5,"slightly cheap",IF($V$30<=-1.5,"RICH",IF($V$30<=-0.5,"slightly rich","fair")))),"") | X30: =SUMPRODUCT(--ISNUMBER((D30,G30,H30,I30,J30,K30))) | Y30: =IF(X30>=5,"HIGH",IF(X30>=3,"MED","LOW")) | Z30: =IF(AND(ISNUMBER(S30),X30>=$S$11),S30,"") | AA30: =IF(AND(ISNUMBER(R30),X30>=$S$11),R30,"")
B31: =Tickers!B23 | C31: =Tickers!C23 | D31: =Tickers!E23 | E31: =IFERROR(Tickers!G23,"") | F31: =IFERROR(Tickers!I23,"") | G31: =IFERROR(IF(ISNUMBER(Tickers!K23),Tickers!K23,IF(ISNUMBER(Haver!E23),Haver!E23,IF(ISNUMBER(Tickers!T23),Tickers!T23,""))),"") | H31: =IFERROR(IF(ISNUMBER(Tickers!M23),Tickers!M23,IF(ISNUMBER(Haver!G23),Haver!G23,IF(ISNUMBER(Tickers!U23),Tickers!U23,""))),"") | I31: =IFERROR(IF(ISNUMBER(Tickers!O23),Tickers!O23,IF(ISNUMBER(Haver!I23),Haver!I23,IF(ISNUMBER(Tickers!V23),Tickers!V23,""))),"") | J31: =IFERROR(IF(ISNUMBER(Tickers!Q23),Tickers!Q23,IF(ISNUMBER(Haver!K23),Haver!K23,IF(ISNUMBER(Tickers!W23),Tickers!W23,""))),"") | K31: =IFERROR(IF(ISNUMBER(Tickers!S23),Tickers!S23,IF(ISNUMBER(Haver!M23),Haver!M23,IF(ISNUMBER(Tickers!X23),Tickers!X23,""))),"") | L31: =IFERROR(($D$31-AVERAGE($D$15:$D$85))/STDEV($D$15:$D$85),"") | M31: =IFERROR(($I$31-AVERAGE($I$15:$I$85))/STDEV($I$15:$I$85),"") | N31: =IFERROR(-($J$31-AVERAGE($J$15:$J$85))/STDEV($J$15:$J$85),"") | O31: =IFERROR(-($K$31-AVERAGE($K$15:$K$85))/STDEV($K$15:$K$85),"") | P31: =IFERROR(-($G$31-AVERAGE($G$15:$G$85))/STDEV($G$15:$G$85),"") | Q31: =IFERROR(($H$31-AVERAGE($H$15:$H$85))/STDEV($H$15:$H$85),"") | R31: =IFERROR((IF(ISNUMBER(L31),$D$7*L31,0)+IF(ISNUMBER(M31),$D$8*M31,0)+IF(ISNUMBER(N31),$D$9*N31,0)+IF(ISNUMBER(O31),$D$10*O31,0)+IF(ISNUMBER(P31),$D$11*P31,0)+IF(ISNUMBER(Q31),$D$12*Q31,0))/(IF(ISNUMBER(L31),$D$7,0)+IF(ISNUMBER(M31),$D$8,0)+IF(ISNUMBER(N31),$D$9,0)+IF(ISNUMBER(O31),$D$10,0)+IF(ISNUMBER(P31),$D$11,0)+IF(ISNUMBER(Q31),$D$12,0)),"") | S31: =IFERROR(LN($E$31),"") | T31: =IFERROR($N$7+$N$8*$R$31,"") | U31: =IFERROR($S$31-$T$31,"") | V31: =IFERROR(($U$31-AVERAGE($U$15:$U$85))/STDEV($U$15:$U$85),"") | W31: =IF(ISNUMBER($V$31),IF($V$31>=1.5,"CHEAP",IF($V$31>=0.5,"slightly cheap",IF($V$31<=-1.5,"RICH",IF($V$31<=-0.5,"slightly rich","fair")))),"") | X31: =SUMPRODUCT(--ISNUMBER((D31,G31,H31,I31,J31,K31))) | Y31: =IF(X31>=5,"HIGH",IF(X31>=3,"MED","LOW")) | Z31: =IF(AND(ISNUMBER(S31),X31>=$S$11),S31,"") | AA31: =IF(AND(ISNUMBER(R31),X31>=$S$11),R31,"")
B32: =Tickers!B24 | C32: =Tickers!C24 | D32: =Tickers!E24 | E32: =IFERROR(Tickers!G24,"") | F32: =IFERROR(Tickers!I24,"") | G32: =IFERROR(IF(ISNUMBER(Tickers!K24),Tickers!K24,IF(ISNUMBER(Haver!E24),Haver!E24,IF(ISNUMBER(Tickers!T24),Tickers!T24,""))),"") | H32: =IFERROR(IF(ISNUMBER(Tickers!M24),Tickers!M24,IF(ISNUMBER(Haver!G24),Haver!G24,IF(ISNUMBER(Tickers!U24),Tickers!U24,""))),"") | I32: =IFERROR(IF(ISNUMBER(Tickers!O24),Tickers!O24,IF(ISNUMBER(Haver!I24),Haver!I24,IF(ISNUMBER(Tickers!V24),Tickers!V24,""))),"") | J32: =IFERROR(IF(ISNUMBER(Tickers!Q24),Tickers!Q24,IF(ISNUMBER(Haver!K24),Haver!K24,IF(ISNUMBER(Tickers!W24),Tickers!W24,""))),"") | K32: =IFERROR(IF(ISNUMBER(Tickers!S24),Tickers!S24,IF(ISNUMBER(Haver!M24),Haver!M24,IF(ISNUMBER(Tickers!X24),Tickers!X24,""))),"") | L32: =IFERROR(($D$32-AVERAGE($D$15:$D$85))/STDEV($D$15:$D$85),"") | M32: =IFERROR(($I$32-AVERAGE($I$15:$I$85))/STDEV($I$15:$I$85),"") | N32: =IFERROR(-($J$32-AVERAGE($J$15:$J$85))/STDEV($J$15:$J$85),"") | O32: =IFERROR(-($K$32-AVERAGE($K$15:$K$85))/STDEV($K$15:$K$85),"") | P32: =IFERROR(-($G$32-AVERAGE($G$15:$G$85))/STDEV($G$15:$G$85),"") | Q32: =IFERROR(($H$32-AVERAGE($H$15:$H$85))/STDEV($H$15:$H$85),"") | R32: =IFERROR((IF(ISNUMBER(L32),$D$7*L32,0)+IF(ISNUMBER(M32),$D$8*M32,0)+IF(ISNUMBER(N32),$D$9*N32,0)+IF(ISNUMBER(O32),$D$10*O32,0)+IF(ISNUMBER(P32),$D$11*P32,0)+IF(ISNUMBER(Q32),$D$12*Q32,0))/(IF(ISNUMBER(L32),$D$7,0)+IF(ISNUMBER(M32),$D$8,0)+IF(ISNUMBER(N32),$D$9,0)+IF(ISNUMBER(O32),$D$10,0)+IF(ISNUMBER(P32),$D$11,0)+IF(ISNUMBER(Q32),$D$12,0)),"") | S32: =IFERROR(LN($E$32),"") | T32: =IFERROR($N$7+$N$8*$R$32,"") | U32: =IFERROR($S$32-$T$32,"") | V32: =IFERROR(($U$32-AVERAGE($U$15:$U$85))/STDEV($U$15:$U$85),"") | W32: =IF(ISNUMBER($V$32),IF($V$32>=1.5,"CHEAP",IF($V$32>=0.5,"slightly cheap",IF($V$32<=-1.5,"RICH",IF($V$32<=-0.5,"slightly rich","fair")))),"") | X32: =SUMPRODUCT(--ISNUMBER((D32,G32,H32,I32,J32,K32))) | Y32: =IF(X32>=5,"HIGH",IF(X32>=3,"MED","LOW")) | Z32: =IF(AND(ISNUMBER(S32),X32>=$S$11),S32,"") | AA32: =IF(AND(ISNUMBER(R32),X32>=$S$11),R32,"")
B33: =Tickers!B25 | C33: =Tickers!C25 | D33: =Tickers!E25 | E33: =IFERROR(Tickers!G25,"") | F33: =IFERROR(Tickers!I25,"") | G33: =IFERROR(IF(ISNUMBER(Tickers!K25),Tickers!K25,IF(ISNUMBER(Haver!E25),Haver!E25,IF(ISNUMBER(Tickers!T25),Tickers!T25,""))),"") | H33: =IFERROR(IF(ISNUMBER(Tickers!M25),Tickers!M25,IF(ISNUMBER(Haver!G25),Haver!G25,IF(ISNUMBER(Tickers!U25),Tickers!U25,""))),"") | I33: =IFERROR(IF(ISNUMBER(Tickers!O25),Tickers!O25,IF(ISNUMBER(Haver!I25),Haver!I25,IF(ISNUMBER(Tickers!V25),Tickers!V25,""))),"") | J33: =IFERROR(IF(ISNUMBER(Tickers!Q25),Tickers!Q25,IF(ISNUMBER(Haver!K25),Haver!K25,IF(ISNUMBER(Tickers!W25),Tickers!W25,""))),"") | K33: =IFERROR(IF(ISNUMBER(Tickers!S25),Tickers!S25,IF(ISNUMBER(Haver!M25),Haver!M25,IF(ISNUMBER(Tickers!X25),Tickers!X25,""))),"") | L33: =IFERROR(($D$33-AVERAGE($D$15:$D$85))/STDEV($D$15:$D$85),"") | M33: =IFERROR(($I$33-AVERAGE($I$15:$I$85))/STDEV($I$15:$I$85),"") | N33: =IFERROR(-($J$33-AVERAGE($J$15:$J$85))/STDEV($J$15:$J$85),"") | O33: =IFERROR(-($K$33-AVERAGE($K$15:$K$85))/STDEV($K$15:$K$85),"") | P33: =IFERROR(-($G$33-AVERAGE($G$15:$G$85))/STDEV($G$15:$G$85),"") | Q33: =IFERROR(($H$33-AVERAGE($H$15:$H$85))/STDEV($H$15:$H$85),"") | R33: =IFERROR((IF(ISNUMBER(L33),$D$7*L33,0)+IF(ISNUMBER(M33),$D$8*M33,0)+IF(ISNUMBER(N33),$D$9*N33,0)+IF(ISNUMBER(O33),$D$10*O33,0)+IF(ISNUMBER(P33),$D$11*P33,0)+IF(ISNUMBER(Q33),$D$12*Q33,0))/(IF(ISNUMBER(L33),$D$7,0)+IF(ISNUMBER(M33),$D$8,0)+IF(ISNUMBER(N33),$D$9,0)+IF(ISNUMBER(O33),$D$10,0)+IF(ISNUMBER(P33),$D$11,0)+IF(ISNUMBER(Q33),$D$12,0)),"") | S33: =IFERROR(LN($E$33),"") | T33: =IFERROR($N$7+$N$8*$R$33,"") | U33: =IFERROR($S$33-$T$33,"") | V33: =IFERROR(($U$33-AVERAGE($U$15:$U$85))/STDEV($U$15:$U$85),"") | W33: =IF(ISNUMBER($V$33),IF($V$33>=1.5,"CHEAP",IF($V$33>=0.5,"slightly cheap",IF($V$33<=-1.5,"RICH",IF($V$33<=-0.5,"slightly rich","fair")))),"") | X33: =SUMPRODUCT(--ISNUMBER((D33,G33,H33,I33,J33,K33))) | Y33: =IF(X33>=5,"HIGH",IF(X33>=3,"MED","LOW")) | Z33: =IF(AND(ISNUMBER(S33),X33>=$S$11),S33,"") | AA33: =IF(AND(ISNUMBER(R33),X33>=$S$11),R33,"")
B34: =Tickers!B26 | C34: =Tickers!C26 | D34: =Tickers!E26 | E34: =IFERROR(Tickers!G26,"") | F34: =IFERROR(Tickers!I26,"") | G34: =IFERROR(IF(ISNUMBER(Tickers!K26),Tickers!K26,IF(ISNUMBER(Haver!E26),Haver!E26,IF(ISNUMBER(Tickers!T26),Tickers!T26,""))),"") | H34: =IFERROR(IF(ISNUMBER(Tickers!M26),Tickers!M26,IF(ISNUMBER(Haver!G26),Haver!G26,IF(ISNUMBER(Tickers!U26),Tickers!U26,""))),"") | I34: =IFERROR(IF(ISNUMBER(Tickers!O26),Tickers!O26,IF(ISNUMBER(Haver!I26),Haver!I26,IF(ISNUMBER(Tickers!V26),Tickers!V26,""))),"") | J34: =IFERROR(IF(ISNUMBER(Tickers!Q26),Tickers!Q26,IF(ISNUMBER(Haver!K26),Haver!K26,IF(ISNUMBER(Tickers!W26),Tickers!W26,""))),"") | K34: =IFERROR(IF(ISNUMBER(Tickers!S26),Tickers!S26,IF(ISNUMBER(Haver!M26),Haver!M26,IF(ISNUMBER(Tickers!X26),Tickers!X26,""))),"") | L34: =IFERROR(($D$34-AVERAGE($D$15:$D$85))/STDEV($D$15:$D$85),"") | M34: =IFERROR(($I$34-AVERAGE($I$15:$I$85))/STDEV($I$15:$I$85),"") | N34: =IFERROR(-($J$34-AVERAGE($J$15:$J$85))/STDEV($J$15:$J$85),"") | O34: =IFERROR(-($K$34-AVERAGE($K$15:$K$85))/STDEV($K$15:$K$85),"") | P34: =IFERROR(-($G$34-AVERAGE($G$15:$G$85))/STDEV($G$15:$G$85),"") | Q34: =IFERROR(($H$34-AVERAGE($H$15:$H$85))/STDEV($H$15:$H$85),"") | R34: =IFERROR((IF(ISNUMBER(L34),$D$7*L34,0)+IF(ISNUMBER(M34),$D$8*M34,0)+IF(ISNUMBER(N34),$D$9*N34,0)+IF(ISNUMBER(O34),$D$10*O34,0)+IF(ISNUMBER(P34),$D$11*P34,0)+IF(ISNUMBER(Q34),$D$12*Q34,0))/(IF(ISNUMBER(L34),$D$7,0)+IF(ISNUMBER(M34),$D$8,0)+IF(ISNUMBER(N34),$D$9,0)+IF(ISNUMBER(O34),$D$10,0)+IF(ISNUMBER(P34),$D$11,0)+IF(ISNUMBER(Q34),$D$12,0)),"") | S34: =IFERROR(LN($E$34),"") | T34: =IFERROR($N$7+$N$8*$R$34,"") | U34: =IFERROR($S$34-$T$34,"") | V34: =IFERROR(($U$34-AVERAGE($U$15:$U$85))/STDEV($U$15:$U$85),"") | W34: =IF(ISNUMBER($V$34),IF($V$34>=1.5,"CHEAP",IF($V$34>=0.5,"slightly cheap",IF($V$34<=-1.5,"RICH",IF($V$34<=-0.5,"slightly rich","fair")))),"") | X34: =SUMPRODUCT(--ISNUMBER((D34,G34,H34,I34,J34,K34))) | Y34: =IF(X34>=5,"HIGH",IF(X34>=3,"MED","LOW")) | Z34: =IF(AND(ISNUMBER(S34),X34>=$S$11),S34,"") | AA34: =IF(AND(ISNUMBER(R34),X34>=$S$11),R34,"")
