Workbook

Sheet Monitor
B2: EM Sovereign Credit · Cheap / Rich Monitor
B3: Cross-section fair value across the EMBI universe. Macro fundamentals are static (IMF WEO / rating agencies, locked once a year). Z-spreads refresh live from Bloomberg — the regression and signal re-fit every refresh.
B5: Snapshot date | D5: N countries | E5: Median spread | F5: Live R² | G5: Live β | H5: Live α | L5: Top 5 CHEAP | N5: Top 5 RICH
B6: =TEXT(TODAY(),"yyyy-mm-dd") -> 2026-05-11 | D6: =COUNT(Model!E15:E120) -> 68 | E6: =IFERROR(ROUND(MEDIAN(Model!E15:E120),0),NA()) -> 290 | F6: =IFERROR(RSQ(Model!AB15:AB120,Model!AC15:AC120),NA()) -> 0.75164838 | G6: =IFERROR(SLOPE(Model!AB15:AB120,Model!AC15:AC120),NA()) -> 1.1144475 | H6: =IFERROR(INTERCEPT(Model!AB15:AB120,Model!AC15:AC120),NA()) -> 5.6626447 | L6: =IFERROR(INDEX(Model!$B$15:$B$120,MATCH(LARGE(Model!$V$15:$V$120,1),Model!$V$15:$V$120,0)),"") -> ETHIOPIA | M6: =IFERROR(LARGE(Model!$V$15:$V$120,1),"") -> 2.0451048 | N6: =IFERROR(INDEX(Model!$B$15:$B$120,MATCH(SMALL(Model!$V$15:$V$120,1),Model!$V$15:$V$120,0)),"") -> KOREA | O6: =IFERROR(SMALL(Model!$V$15:$V$120,1),"") -> -2.0153263
L7: =IFERROR(INDEX(Model!$B$15:$B$120,MATCH(LARGE(Model!$V$15:$V$120,2),Model!$V$15:$V$120,0)),"") -> ECUADOR | M7: =IFERROR(LARGE(Model!$V$15:$V$120,2),"") -> 2.0185839 | N7: =IFERROR(INDEX(Model!$B$15:$B$120,MATCH(SMALL(Model!$V$15:$V$120,2),Model!$V$15:$V$120,0)),"") -> SLOVENIA | O7: =IFERROR(SMALL(Model!$V$15:$V$120,2),"") -> -2.0054289
B8: Signal distribution | L8: =IFERROR(INDEX(Model!$B$15:$B$120,MATCH(LARGE(Model!$V$15:$V$120,3),Model!$V$15:$V$120,0)),"") -> CAMEROON | M8: =IFERROR(LARGE(Model!$V$15:$V$120,3),"") -> 1.870361 | N8: =IFERROR(INDEX(Model!$B$15:$B$120,MATCH(SMALL(Model!$V$15:$V$120,3),Model!$V$15:$V$120,0)),"") -> CHINA | O8: =IFERROR(SMALL(Model!$V$15:$V$120,3),"") -> -1.9215799
B9: CHEAP | D9: slightly cheap | F9: fair | H9: slightly rich | J9: RICH | L9: =IFERROR(INDEX(Model!$B$15:$B$120,MATCH(LARGE(Model!$V$15:$V$120,4),Model!$V$15:$V$120,0)),"") -> BOLIVIA | M9: =IFERROR(LARGE(Model!$V$15:$V$120,4),"") -> 1.6882388 | N9: =IFERROR(INDEX(Model!$B$15:$B$120,MATCH(SMALL(Model!$V$15:$V$120,4),Model!$V$15:$V$120,0)),"") -> URUGUAY | O9: =IFERROR(SMALL(Model!$V$15:$V$120,4),"") -> -1.9172547
B10: =COUNTIF(Model!W15:W120,"CHEAP") -> 5 | D10: =COUNTIF(Model!W15:W120,"slightly cheap") -> 16 | F10: =COUNTIF(Model!W15:W120,"fair") -> 24 | H10: =COUNTIF(Model!W15:W120,"slightly rich") -> 18 | J10: =COUNTIF(Model!W15:W120,"RICH") -> 5 | L10: =IFERROR(INDEX(Model!$B$15:$B$120,MATCH(LARGE(Model!$V$15:$V$120,5),Model!$V$15:$V$120,0)),"") -> COTE D'IVOIRE | M10: =IFERROR(LARGE(Model!$V$15:$V$120,5),"") -> 1.5997137 | N10: =IFERROR(INDEX(Model!$B$15:$B$120,MATCH(SMALL(Model!$V$15:$V$120,5),Model!$V$15:$V$120,0)),"") -> SLOVAKIA | O10: =IFERROR(SMALL(Model!$V$15:$V$120,5),"") -> -1.5357846
B11: Universe · sorted cheap → rich
B12: Rank | C12: Country | D12: ISO | E12: Spread (bps) | F12: Fair Value (bps) | G12: Basis (bps) | H12: Z-resid | I12: Signal | J12: Conf
B13: 1 | C13: =IFERROR(INDEX(Model!$B$15:$B$120,MATCH(LARGE(Model!$V$15:$V$120,1),Model!$V$15:$V$120,0)),"") -> ETHIOPIA | D13: =IFERROR(INDEX(Model!$C$15:$C$120,MATCH(LARGE(Model!$V$15:$V$120,1),Model!$V$15:$V$120,0)),"") -> ETH | E13: =IFERROR(INDEX(Model!$E$15:$E$120,MATCH(LARGE(Model!$V$15:$V$120,1),Model!$V$15:$V$120,0)),"") -> 1200 | F13: =IFERROR(EXP(INDEX(Model!$T$15:$T$120,MATCH(LARGE(Model!$V$15:$V$120,1),Model!$V$15:$V$120,0))),"") -> 526.71916 | G13: =IFERROR(E13-F13,"") -> 673.28084 | H13: =IFERROR(LARGE(Model!$V$15:$V$120,1),"") -> 2.0451048 | I13: =IFERROR(INDEX(Model!$W$15:$W$120,MATCH(LARGE(Model!$V$15:$V$120,1),Model!$V$15:$V$120,0)),"") -> CHEAP | J13: =IFERROR(INDEX(Model!$Y$15:$Y$120,MATCH(LARGE(Model!$V$15:$V$120,1),Model!$V$15:$V$120,0)),"") -> HIGH
B14: 2 | C14: =IFERROR(INDEX(Model!$B$15:$B$120,MATCH(LARGE(Model!$V$15:$V$120,2),Model!$V$15:$V$120,0)),"") -> ECUADOR | D14: =IFERROR(INDEX(Model!$C$15:$C$120,MATCH(LARGE(Model!$V$15:$V$120,2),Model!$V$15:$V$120,0)),"") -> ECU | E14: =IFERROR(INDEX(Model!$E$15:$E$120,MATCH(LARGE(Model!$V$15:$V$120,2),Model!$V$15:$V$120,0)),"") -> 1300 | F14: =IFERROR(EXP(INDEX(Model!$T$15:$T$120,MATCH(LARGE(Model!$V$15:$V$120,2),Model!$V$15:$V$120,0))),"") -> 576.73804 | G14: =IFERROR(E14-F14,"") -> 723.26196 | H14: =IFERROR(LARGE(Model!$V$15:$V$120,2),"") -> 2.0185839 | I14: =IFERROR(INDEX(Model!$W$15:$W$120,MATCH(LARGE(Model!$V$15:$V$120,2),Model!$V$15:$V$120,0)),"") -> CHEAP | J14: =IFERROR(INDEX(Model!$Y$15:$Y$120,MATCH(LARGE(Model!$V$15:$V$120,2),Model!$V$15:$V$120,0)),"") -> HIGH
B15: 3 | C15: =IFERROR(INDEX(Model!$B$15:$B$120,MATCH(LARGE(Model!$V$15:$V$120,3),Model!$V$15:$V$120,0)),"") -> CAMEROON | D15: =IFERROR(INDEX(Model!$C$15:$C$120,MATCH(LARGE(Model!$V$15:$V$120,3),Model!$V$15:$V$120,0)),"") -> CMR | E15: =IFERROR(INDEX(Model!$E$15:$E$120,MATCH(LARGE(Model!$V$15:$V$120,3),Model!$V$15:$V$120,0)),"") -> 760 | F15: =IFERROR(EXP(INDEX(Model!$T$15:$T$120,MATCH(LARGE(Model!$V$15:$V$120,3),Model!$V$15:$V$120,0))),"") -> 357.90415 | G15: =IFERROR(E15-F15,"") -> 402.09585 | H15: =IFERROR(LARGE(Model!$V$15:$V$120,3),"") -> 1.870361 | I15: =IFERROR(INDEX(Model!$W$15:$W$120,MATCH(LARGE(Model!$V$15:$V$120,3),Model!$V$15:$V$120,0)),"") -> CHEAP | J15: =IFERROR(INDEX(Model!$Y$15:$Y$120,MATCH(LARGE(Model!$V$15:$V$120,3),Model!$V$15:$V$120,0)),"") -> HIGH
B16: 4 | C16: =IFERROR(INDEX(Model!$B$15:$B$120,MATCH(LARGE(Model!$V$15:$V$120,4),Model!$V$15:$V$120,0)),"") -> BOLIVIA | D16: =IFERROR(INDEX(Model!$C$15:$C$120,MATCH(LARGE(Model!$V$15:$V$120,4),Model!$V$15:$V$120,0)),"") -> BOL | E16: =IFERROR(INDEX(Model!$E$15:$E$120,MATCH(LARGE(Model!$V$15:$V$120,4),Model!$V$15:$V$120,0)),"") -> 1700 | F16: =IFERROR(EXP(INDEX(Model!$T$15:$T$120,MATCH(LARGE(Model!$V$15:$V$120,4),Model!$V$15:$V$120,0))),"") -> 861.4846 | G16: =IFERROR(E16-F16,"") -> 838.5154 | H16: =IFERROR(LARGE(Model!$V$15:$V$120,4),"") -> 1.6882388 | I16: =IFERROR(INDEX(Model!$W$15:$W$120,MATCH(LARGE(Model!$V$15:$V$120,4),Model!$V$15:$V$120,0)),"") -> CHEAP | J16: =IFERROR(INDEX(Model!$Y$15:$Y$120,MATCH(LARGE(Model!$V$15:$V$120,4),Model!$V$15:$V$120,0)),"") -> HIGH
B17: 5 | C17: =IFERROR(INDEX(Model!$B$15:$B$120,MATCH(LARGE(Model!$V$15:$V$120,5),Model!$V$15:$V$120,0)),"") -> COTE D'IVOIRE | D17: =IFERROR(INDEX(Model!$C$15:$C$120,MATCH(LARGE(Model!$V$15:$V$120,5),Model!$V$15:$V$120,0)),"") -> CIV | E17: =IFERROR(INDEX(Model!$E$15:$E$120,MATCH(LARGE(Model!$V$15:$V$120,5),Model!$V$15:$V$120,0)),"") -> 480 | F17: =IFERROR(EXP(INDEX(Model!$T$15:$T$120,MATCH(LARGE(Model!$V$15:$V$120,5),Model!$V$15:$V$120,0))),"") -> 252.06882 | G17: =IFERROR(E17-F17,"") -> 227.93118 | H17: =IFERROR(LARGE(Model!$V$15:$V$120,5),"") -> 1.5997137 | I17: =IFERROR(INDEX(Model!$W$15:$W$120,MATCH(LARGE(Model!$V$15:$V$120,5),Model!$V$15:$V$120,0)),"") -> CHEAP | J17: =IFERROR(INDEX(Model!$Y$15:$Y$120,MATCH(LARGE(Model!$V$15:$V$120,5),Model!$V$15:$V$120,0)),"") -> HIGH
B18: 6 | C18: =IFERROR(INDEX(Model!$B$15:$B$120,MATCH(LARGE(Model!$V$15:$V$120,6),Model!$V$15:$V$120,0)),"") -> GABON | D18: =IFERROR(INDEX(Model!$C$15:$C$120,MATCH(LARGE(Model!$V$15:$V$120,6),Model!$V$15:$V$120,0)),"") -> GAB | E18: =IFERROR(INDEX(Model!$E$15:$E$120,MATCH(LARGE(Model!$V$15:$V$120,6),Model!$V$15:$V$120,0)),"") -> 1100 | F18: =IFERROR(EXP(INDEX(Model!$T$15:$T$120,MATCH(LARGE(Model!$V$15:$V$120,6),Model!$V$15:$V$120,0))),"") -> 611.71455 | G18: =IFERROR(E18-F18,"") -> 488.28545 | H18: =IFERROR(LARGE(Model!$V$15:$V$120,6),"") -> 1.4574366 | I18: =IFERROR(INDEX(Model!$W$15:$W$120,MATCH(LARGE(Model!$V$15:$V$120,6),Model!$V$15:$V$120,0)),"") -> slightly cheap | J18: =IFERROR(INDEX(Model!$Y$15:$Y$120,MATCH(LARGE(Model!$V$15:$V$120,6),Model!$V$15:$V$120,0)),"") -> HIGH
B19: 7 | C19: =IFERROR(INDEX(Model!$B$15:$B$120,MATCH(LARGE(Model!$V$15:$V$120,7),Model!$V$15:$V$120,0)),"") -> KUWAIT | D19: =IFERROR(INDEX(Model!$C$15:$C$120,MATCH(LARGE(Model!$V$15:$V$120,7),Model!$V$15:$V$120,0)),"") -> KWT | E19: =IFERROR(INDEX(Model!$E$15:$E$120,MATCH(LARGE(Model!$V$15:$V$120,7),Model!$V$15:$V$120,0)),"") -> 70 | F19: =IFERROR(EXP(INDEX(Model!$T$15:$T$120,MATCH(LARGE(Model!$V$15:$V$120,7),Model!$V$15:$V$120,0))),"") -> 41.27256 | G19: =IFERROR(E19-F19,"") -> 28.72744 | H19: =IFERROR(LARGE(Model!$V$15:$V$120,7),"") -> 1.3121341 | I19: =IFERROR(INDEX(Model!$W$15:$W$120,MATCH(LARGE(Model!$V$15:$V$120,7),Model!$V$15:$V$120,0)),"") -> slightly cheap | J19: =IFERROR(INDEX(Model!$Y$15:$Y$120,MATCH(LARGE(Model!$V$15:$V$120,7),Model!$V$15:$V$120,0)),"") -> HIGH
B20: 8 | C20: =IFERROR(INDEX(Model!$B$15:$B$120,MATCH(LARGE(Model!$V$15:$V$120,8),Model!$V$15:$V$120,0)),"") -> AZERBAIJAN | D20: =IFERROR(INDEX(Model!$C$15:$C$120,MATCH(LARGE(Model!$V$15:$V$120,8),Model!$V$15:$V$120,0)),"") -> AZE | E20: =IFERROR(INDEX(Model!$E$15:$E$120,MATCH(LARGE(Model!$V$15:$V$120,8),Model!$V$15:$V$120,0)),"") -> 250 | F20: =IFERROR(EXP(INDEX(Model!$T$15:$T$120,MATCH(LARGE(Model!$V$15:$V$120,8),Model!$V$15:$V$120,0))),"") -> 153.23608 | G20: =IFERROR(E20-F20,"") -> 96.763922 | H20: =IFERROR(LARGE(Model!$V$15:$V$120,8),"") -> 1.2157262 | I20: =IFERROR(INDEX(Model!$W$15:$W$120,MATCH(LARGE(Model!$V$15:$V$120,8),Model!$V$15:$V$120,0)),"") -> slightly cheap | J20: =IFERROR(INDEX(Model!$Y$15:$Y$120,MATCH(LARGE(Model!$V$15:$V$120,8),Model!$V$15:$V$120,0)),"") -> HIGH
B21: 9 | C21: =IFERROR(INDEX(Model!$B$15:$B$120,MATCH(LARGE(Model!$V$15:$V$120,9),Model!$V$15:$V$120,0)),"") -> UZBEKISTAN | D21: =IFERROR(INDEX(Model!$C$15:$C$120,MATCH(LARGE(Model!$V$15:$V$120,9),Model!$V$15:$V$120,0)),"") -> UZB | E21: =IFERROR(INDEX(Model!$E$15:$E$120,MATCH(LARGE(Model!$V$15:$V$120,9),Model!$V$15:$V$120,0)),"") -> 320 | F21: =IFERROR(EXP(INDEX(Model!$T$15:$T$120,MATCH(LARGE(Model!$V$15:$V$120,9),Model!$V$15:$V$120,0))),"") -> 197.29552 | G21: =IFERROR(E21-F21,"") -> 122.70448 | H21: =IFERROR(LARGE(Model!$V$15:$V$120,9),"") -> 1.2011645 | I21: =IFERROR(INDEX(Model!$W$15:$W$120,MATCH(LARGE(Model!$V$15:$V$120,9),Model!$V$15:$V$120,0)),"") -> slightly cheap | J21: =IFERROR(INDEX(Model!$Y$15:$Y$120,MATCH(LARGE(Model!$V$15:$V$120,9),Model!$V$15:$V$120,0)),"") -> HIGH
B22: 10 | C22: =IFERROR(INDEX(Model!$B$15:$B$120,MATCH(LARGE(Model!$V$15:$V$120,10),Model!$V$15:$V$120,0)),"") -> ARMENIA | D22: =IFERROR(INDEX(Model!$C$15:$C$120,MATCH(LARGE(Model!$V$15:$V$120,10),Model!$V$15:$V$120,0)),"") -> ARM | E22: =IFERROR(INDEX(Model!$E$15:$E$120,MATCH(LARGE(Model!$V$15:$V$120,10),Model!$V$15:$V$120,0)),"") -> 380 | F22: =IFERROR(EXP(INDEX(Model!$T$15:$T$120,MATCH(LARGE(Model!$V$15:$V$120,10),Model!$V$15:$V$120,0))),"") -> 244.33334 | G22: =IFERROR(E22-F22,"") -> 135.66666 | H22: =IFERROR(LARGE(Model!$V$15:$V$120,10),"") -> 1.0968974 | I22: =IFERROR(INDEX(Model!$W$15:$W$120,MATCH(LARGE(Model!$V$15:$V$120,10),Model!$V$15:$V$120,0)),"") -> slightly cheap | J22: =IFERROR(INDEX(Model!$Y$15:$Y$120,MATCH(LARGE(Model!$V$15:$V$120,10),Model!$V$15:$V$120,0)),"") -> HIGH
B23: 11 | C23: =IFERROR(INDEX(Model!$B$15:$B$120,MATCH(LARGE(Model!$V$15:$V$120,11),Model!$V$15:$V$120,0)),"") -> GEORGIA | D23: =IFERROR(INDEX(Model!$C$15:$C$120,MATCH(LARGE(Model!$V$15:$V$120,11),Model!$V$15:$V$120,0)),"") -> GEO | E23: =IFERROR(INDEX(Model!$E$15:$E$120,MATCH(LARGE(Model!$V$15:$V$120,11),Model!$V$15:$V$120,0)),"") -> 320 | F23: =IFERROR(EXP(INDEX(Model!$T$15:$T$120,MATCH(LARGE(Model!$V$15:$V$120,11),Model!$V$15:$V$120,0))),"") -> 209.73407 | G23: =IFERROR(E23-F23,"") -> 110.26593 | H23: =IFERROR(LARGE(Model!$V$15:$V$120,11),"") -> 1.0493166 | I23: =IFERROR(INDEX(Model!$W$15:$W$120,MATCH(LARGE(Model!$V$15:$V$120,11),Model!$V$15:$V$120,0)),"") -> slightly cheap | J23: =IFERROR(INDEX(Model!$Y$15:$Y$120,MATCH(LARGE(Model!$V$15:$V$120,11),Model!$V$15:$V$120,0)),"") -> HIGH
B24: 12 | C24: =IFERROR(INDEX(Model!$B$15:$B$120,MATCH(LARGE(Model!$V$15:$V$120,12),Model!$V$15:$V$120,0)),"") -> UNITED ARAB EMIRATES | D24: =IFERROR(INDEX(Model!$C$15:$C$120,MATCH(LARGE(Model!$V$15:$V$120,12),Model!$V$15:$V$120,0)),"") -> ARE | E24: =IFERROR(INDEX(Model!$E$15:$E$120,MATCH(LARGE(Model!$V$15:$V$120,12),Model!$V$15:$V$120,0)),"") -> 80 | F24: =IFERROR(EXP(INDEX(Model!$T$15:$T$120,MATCH(LARGE(Model!$V$15:$V$120,12),Model!$V$15:$V$120,0))),"") -> 53.291525 | G24: =IFERROR(E24-F24,"") -> 26.708475 | H24: =IFERROR(LARGE(Model!$V$15:$V$120,12),"") -> 1.0090029 | I24: =IFERROR(INDEX(Model!$W$15:$W$120,MATCH(LARGE(Model!$V$15:$V$120,12),Model!$V$15:$V$120,0)),"") -> slightly cheap | J24: =IFERROR(INDEX(Model!$Y$15:$Y$120,MATCH(LARGE(Model!$V$15:$V$120,12),Model!$V$15:$V$120,0)),"") -> HIGH
B25: 13 | C25: =IFERROR(INDEX(Model!$B$15:$B$120,MATCH(LARGE(Model!$V$15:$V$120,13),Model!$V$15:$V$120,0)),"") -> ZAMBIA | D25: =IFERROR(INDEX(Model!$C$15:$C$120,MATCH(LARGE(Model!$V$15:$V$120,13),Model!$V$15:$V$120,0)),"") -> ZMB | E25: =IFERROR(INDEX(Model!$E$15:$E$120,MATCH(LARGE(Model!$V$15:$V$120,13),Model!$V$15:$V$120,0)),"") -> 800 | F25: =IFERROR(EXP(INDEX(Model!$T$15:$T$120,MATCH(LARGE(Model!$V$15:$V$120,13),Model!$V$15:$V$120,0))),"") -> 557.55119 | G25: =IFERROR(E25-F25,"") -> 242.44881 | H25: =IFERROR(LARGE(Model!$V$15:$V$120,13),"") -> 0.89675958 | I25: =IFERROR(INDEX(Model!$W$15:$W$120,MATCH(LARGE(Model!$V$15:$V$120,13),Model!$V$15:$V$120,0)),"") -> slightly cheap | J25: =IFERROR(INDEX(Model!$Y$15:$Y$120,MATCH(LARGE(Model!$V$15:$V$120,13),Model!$V$15:$V$120,0)),"") -> HIGH
B26: 14 | C26: =IFERROR(INDEX(Model!$B$15:$B$120,MATCH(LARGE(Model!$V$15:$V$120,14),Model!$V$15:$V$120,0)),"") -> ANGOLA | D26: =IFERROR(INDEX(Model!$C$15:$C$120,MATCH(LARGE(Model!$V$15:$V$120,14),Model!$V$15:$V$120,0)),"") -> AGO | E26: =IFERROR(INDEX(Model!$E$15:$E$120,MATCH(LARGE(Model!$V$15:$V$120,14),Model!$V$15:$V$120,0)),"") -> 700 | F26: =IFERROR(EXP(INDEX(Model!$T$15:$T$120,MATCH(LARGE(Model!$V$15:$V$120,14),Model!$V$15:$V$120,0))),"") -> 488.66686 | G26: =IFERROR(E26-F26,"") -> 211.33314 | H26: =IFERROR(LARGE(Model!$V$15:$V$120,14),"") -> 0.89264146 | I26: =IFERROR(INDEX(Model!$W$15:$W$120,MATCH(LARGE(Model!$V$15:$V$120,14),Model!$V$15:$V$120,0)),"") -> slightly cheap | J26: =IFERROR(INDEX(Model!$Y$15:$Y$120,MATCH(LARGE(Model!$V$15:$V$120,14),Model!$V$15:$V$120,0)),"") -> HIGH
B27: 15 | C27: =IFERROR(INDEX(Model!$B$15:$B$120,MATCH(LARGE(Model!$V$15:$V$120,15),Model!$V$15:$V$120,0)),"") -> GUATEMALA | D27: =IFERROR(INDEX(Model!$C$15:$C$120,MATCH(LARGE(Model!$V$15:$V$120,15),Model!$V$15:$V$120,0)),"") -> GTM | E27: =IFERROR(INDEX(Model!$E$15:$E$120,MATCH(LARGE(Model!$V$15:$V$120,15),Model!$V$15:$V$120,0)),"") -> 230 | F27: =IFERROR(EXP(INDEX(Model!$T$15:$T$120,MATCH(LARGE(Model!$V$15:$V$120,15),Model!$V$15:$V$120,0))),"") -> 161.58694 | G27: =IFERROR(E27-F27,"") -> 68.413061 | H27: =IFERROR(LARGE(Model!$V$15:$V$120,15),"") -> 0.87683676 | I27: =IFERROR(INDEX(Model!$W$15:$W$120,MATCH(LARGE(Model!$V$15:$V$120,15),Model!$V$15:$V$120,0)),"") -> slightly cheap | J27: =IFERROR(INDEX(Model!$Y$15:$Y$120,MATCH(LARGE(Model!$V$15:$V$120,15),Model!$V$15:$V$120,0)),"") -> HIGH
B28: 16 | C28: =IFERROR(INDEX(Model!$B$15:$B$120,MATCH(LARGE(Model!$V$15:$V$120,16),Model!$V$15:$V$120,0)),"") -> PARAGUAY | D28: =IFERROR(INDEX(Model!$C$15:$C$120,MATCH(LARGE(Model!$V$15:$V$120,16),Model!$V$15:$V$120,0)),"") -> PRY | E28: =IFERROR(INDEX(Model!$E$15:$E$120,MATCH(LARGE(Model!$V$15:$V$120,16),Model!$V$15:$V$120,0)),"") -> 220 | F28: =IFERROR(EXP(INDEX(Model!$T$15:$T$120,MATCH(LARGE(Model!$V$15:$V$120,16),Model!$V$15:$V$120,0))),"") -> 160.75304 | G28: =IFERROR(E28-F28,"") -> 59.246964 | H28: =IFERROR(LARGE(Model!$V$15:$V$120,16),"") -> 0.77928263 | I28: =IFERROR(INDEX(Model!$W$15:$W$120,MATCH(LARGE(Model!$V$15:$V$120,16),Model!$V$15:$V$120,0)),"") -> slightly cheap | J28: =IFERROR(INDEX(Model!$Y$15:$Y$120,MATCH(LARGE(Model!$V$15:$V$120,16),Model!$V$15:$V$120,0)),"") -> HIGH
B29: 17 | C29: =IFERROR(INDEX(Model!$B$15:$B$120,MATCH(LARGE(Model!$V$15:$V$120,17),Model!$V$15:$V$120,0)),"") -> SAUDI ARABIA | D29: =IFERROR(INDEX(Model!$C$15:$C$120,MATCH(LARGE(Model!$V$15:$V$120,17),Model!$V$15:$V$120,0)),"") -> SAU | E29: =IFERROR(INDEX(Model!$E$15:$E$120,MATCH(LARGE(Model!$V$15:$V$120,17),Model!$V$15:$V$120,0)),"") -> 100 | F29: =IFERROR(EXP(INDEX(Model!$T$15:$T$120,MATCH(LARGE(Model!$V$15:$V$120,17),Model!$V$15:$V$120,0))),"") -> 76.16217 | G29: =IFERROR(E29-F29,"") -> 23.83783 | H29: =IFERROR(LARGE(Model!$V$15:$V$120,17),"") -> 0.67632566 | I29: =IFERROR(INDEX(Model!$W$15:$W$120,MATCH(LARGE(Model!$V$15:$V$120,17),Model!$V$15:$V$120,0)),"") -> slightly cheap | J29: =IFERROR(INDEX(Model!$Y$15:$Y$120,MATCH(LARGE(Model!$V$15:$V$120,17),Model!$V$15:$V$120,0)),"") -> HIGH
B30: 18 | C30: =IFERROR(INDEX(Model!$B$15:$B$120,MATCH(LARGE(Model!$V$15:$V$120,18),Model!$V$15:$V$120,0)),"") -> UKRAINE | D30: =IFERROR(INDEX(Model!$C$15:$C$120,MATCH(LARGE(Model!$V$15:$V$120,18),Model!$V$15:$V$120,0)),"") -> UKR | E30: =IFERROR(INDEX(Model!$E$15:$E$120,MATCH(LARGE(Model!$V$15:$V$120,18),Model!$V$15:$V$120,0)),"") -> 1100 | F30: =IFERROR(EXP(INDEX(Model!$T$15:$T$120,MATCH(LARGE(Model!$V$15:$V$120,18),Model!$V$15:$V$120,0))),"") -> 841.76153 | G30: =IFERROR(E30-F30,"") -> 258.23847 | H30: =IFERROR(LARGE(Model!$V$15:$V$120,18),"") -> 0.66456137 | I30: =IFERROR(INDEX(Model!$W$15:$W$120,MATCH(LARGE(Model!$V$15:$V$120,18),Model!$V$15:$V$120,0)),"") -> slightly cheap | J30: =IFERROR(INDEX(Model!$Y$15:$Y$120,MATCH(LARGE(Model!$V$15:$V$120,18),Model!$V$15:$V$120,0)),"") -> HIGH
B31: 19 | C31: =IFERROR(INDEX(Model!$B$15:$B$120,MATCH(LARGE(Model!$V$15:$V$120,19),Model!$V$15:$V$120,0)),"") -> NIGERIA | D31: =IFERROR(INDEX(Model!$C$15:$C$120,MATCH(LARGE(Model!$V$15:$V$120,19),Model!$V$15:$V$120,0)),"") -> NGA | E31: =IFERROR(INDEX(Model!$E$15:$E$120,MATCH(LARGE(Model!$V$15:$V$120,19),Model!$V$15:$V$120,0)),"") -> 620 | F31: =IFERROR(EXP(INDEX(Model!$T$15:$T$120,MATCH(LARGE(Model!$V$15:$V$120,19),Model!$V$15:$V$120,0))),"") -> 495.26325 | G31: =IFERROR(E31-F31,"") -> 124.73675 | H31: =IFERROR(LARGE(Model!$V$15:$V$120,19),"") -> 0.55791446 | I31: =IFERROR(INDEX(Model!$W$15:$W$120,MATCH(LARGE(Model!$V$15:$V$120,19),Model!$V$15:$V$120,0)),"") -> slightly cheap | J31: =IFERROR(INDEX(Model!$Y$15:$Y$120,MATCH(LARGE(Model!$V$15:$V$120,19),Model!$V$15:$V$120,0)),"") -> HIGH
B32: 20 | C32: =IFERROR(INDEX(Model!$B$15:$B$120,MATCH(LARGE(Model!$V$15:$V$120,20),Model!$V$15:$V$120,0)),"") -> SERBIA | D32: =IFERROR(INDEX(Model!$C$15:$C$120,MATCH(LARGE(Model!$V$15:$V$120,20),Model!$V$15:$V$120,0)),"") -> SRB | E32: =IFERROR(INDEX(Model!$E$15:$E$120,MATCH(LARGE(Model!$V$15:$V$120,20),Model!$V$15:$V$120,0)),"") -> 260 | F32: =IFERROR(EXP(INDEX(Model!$T$15:$T$120,MATCH(LARGE(Model!$V$15:$V$120,20),Model!$V$15:$V$120,0))),"") -> 207.77598 | G32: =IFERROR(E32-F32,"") -> 52.224017 | H32: =IFERROR(LARGE(Model!$V$15:$V$120,20),"") -> 0.55689886 | I32: =IFERROR(INDEX(Model!$W$15:$W$120,MATCH(LARGE(Model!$V$15:$V$120,20),Model!$V$15:$V$120,0)),"") -> slightly cheap | J32: =IFERROR(INDEX(Model!$Y$15:$Y$120,MATCH(LARGE(Model!$V$15:$V$120,20),Model!$V$15:$V$120,0)),"") -> HIGH
B33: 21 | C33: =IFERROR(INDEX(Model!$B$15:$B$120,MATCH(LARGE(Model!$V$15:$V$120,21),Model!$V$15:$V$120,0)),"") -> KAZAKHSTAN | D33: =IFERROR(INDEX(Model!$C$15:$C$120,MATCH(LARGE(Model!$V$15:$V$120,21),Model!$V$15:$V$120,0)),"") -> KAZ | E33: =IFERROR(INDEX(Model!$E$15:$E$120,MATCH(LARGE(Model!$V$15:$V$120,21),Model!$V$15:$V$120,0)),"") -> 220 | F33: =IFERROR(EXP(INDEX(Model!$T$15:$T$120,MATCH(LARGE(Model!$V$15:$V$120,21),Model!$V$15:$V$120,0))),"") -> 179.30431 | G33: =IFERROR(E33-F33,"") -> 40.695686 | H33: =IFERROR(LARGE(Model!$V$15:$V$120,21),"") -> 0.50802446 | I33: =IFERROR(INDEX(Model!$W$15:$W$120,MATCH(LARGE(Model!$V$15:$V$120,21),Model!$V$15:$V$120,0)),"") -> slightly cheap | J33: =IFERROR(INDEX(Model!$Y$15:$Y$120,MATCH(LARGE(Model!$V$15:$V$120,21),Model!$V$15:$V$120,0)),"") -> HIGH
B34: 22 | C34: =IFERROR(INDEX(Model!$B$15:$B$120,MATCH(LARGE(Model!$V$15:$V$120,22),Model!$V$15:$V$120,0)),"") -> RWANDA | D34: =IFERROR(INDEX(Model!$C$15:$C$120,MATCH(LARGE(Model!$V$15:$V$120,22),Model!$V$15:$V$120,0)),"") -> RWA | E34: =IFERROR(INDEX(Model!$E$15:$E$120,MATCH(LARGE(Model!$V$15:$V$120,22),Model!$V$15:$V$120,0)),"") -> 480 | F34: =IFERROR(EXP(INDEX(Model!$T$15:$T$120,MATCH(LARGE(Model!$V$15:$V$120,22),Model!$V$15:$V$120,0))),"") -> 403.32586 | G34: =IFERROR(E34-F34,"") -> 76.674135 | H34: =IFERROR(LARGE(Model!$V$15:$V$120,22),"") -> 0.43226694 | I34: =IFERROR(INDEX(Model!$W$15:$W$120,MATCH(LARGE(Model!$V$15:$V$120,22),Model!$V$15:$V$120,0)),"") -> fair | J34: =IFERROR(INDEX(Model!$Y$15:$Y$120,MATCH(LARGE(Model!$V$15:$V$120,22),Model!$V$15:$V$120,0)),"") -> HIGH
B35: 23 | C35: =IFERROR(INDEX(Model!$B$15:$B$120,MATCH(LARGE(Model!$V$15:$V$120,23),Model!$V$15:$V$120,0)),"") -> SENEGAL | D35: =IFERROR(INDEX(Model!$C$15:$C$120,MATCH(LARGE(Model!$V$15:$V$120,23),Model!$V$15:$V$120,0)),"") -> SEN | E35: =IFERROR(INDEX(Model!$E$15:$E$120,MATCH(LARGE(Model!$V$15:$V$120,23),Model!$V$15:$V$120,0)),"") -> 520 | F35: =IFERROR(EXP(INDEX(Model!$T$15:$T$120,MATCH(LARGE(Model!$V$15:$V$120,23),Model!$V$15:$V$120,0))),"") -> 437.15789 | G35: =IFERROR(E35-F35,"") -> 82.842111 | H35: =IFERROR(LARGE(Model!$V$15:$V$120,23),"") -> 0.43100797 | I35: =IFERROR(INDEX(Model!$W$15:$W$120,MATCH(LARGE(Model!$V$15:$V$120,23),Model!$V$15:$V$120,0)),"") -> fair | J35: =IFERROR(INDEX(Model!$Y$15:$Y$120,MATCH(LARGE(Model!$V$15:$V$120,23),Model!$V$15:$V$120,0)),"") -> HIGH
B36: 24 | C36: =IFERROR(INDEX(Model!$B$15:$B$120,MATCH(LARGE(Model!$V$15:$V$120,24),Model!$V$15:$V$120,0)),"") -> COLOMBIA | D36: =IFERROR(INDEX(Model!$C$15:$C$120,MATCH(LARGE(Model!$V$15:$V$120,24),Model!$V$15:$V$120,0)),"") -> COL | E36: =IFERROR(INDEX(Model!$E$15:$E$120,MATCH(LARGE(Model!$V$15:$V$120,24),Model!$V$15:$V$120,0)),"") -> 350 | F36: =IFERROR(EXP(INDEX(Model!$T$15:$T$120,MATCH(LARGE(Model!$V$15:$V$120,24),Model!$V$15:$V$120,0))),"") -> 295.96806 | G36: =IFERROR(E36-F36,"") -> 54.031938 | H36: =IFERROR(LARGE(Model!$V$15:$V$120,24),"") -> 0.41647141 | I36: =IFERROR(INDEX(Model!$W$15:$W$120,MATCH(LARGE(Model!$V$15:$V$120,24),Model!$V$15:$V$120,0)),"") -> fair | J36: =IFERROR(INDEX(Model!$Y$15:$Y$120,MATCH(LARGE(Model!$V$15:$V$120,24),Model!$V$15:$V$120,0)),"") -> HIGH
B37: 25 | C37: =IFERROR(INDEX(Model!$B$15:$B$120,MATCH(LARGE(Model!$V$15:$V$120,25),Model!$V$15:$V$120,0)),"") -> PANAMA | D37: =IFERROR(INDEX(Model!$C$15:$C$120,MATCH(LARGE(Model!$V$15:$V$120,25),Model!$V$15:$V$120,0)),"") -> PAN | E37: =IFERROR(INDEX(Model!$E$15:$E$120,MATCH(LARGE(Model!$V$15:$V$120,25),Model!$V$15:$V$120,0)),"") -> 360 | F37: =IFERROR(EXP(INDEX(Model!$T$15:$T$120,MATCH(LARGE(Model!$V$15:$V$120,25),Model!$V$15:$V$120,0))),"") -> 311.48841 | G37: =IFERROR(E37-F37,"") -> 48.511594 | H37: =IFERROR(LARGE(Model!$V$15:$V$120,25),"") -> 0.35949602 | I37: =IFERROR(INDEX(Model!$W$15:$W$120,MATCH(LARGE(Model!$V$15:$V$120,25),Model!$V$15:$V$120,0)),"") -> fair | J37: =IFERROR(INDEX(Model!$Y$15:$Y$120,MATCH(LARGE(Model!$V$15:$V$120,25),Model!$V$15:$V$120,0)),"") -> HIGH
B38: 26 | C38: =IFERROR(INDEX(Model!$B$15:$B$120,MATCH(LARGE(Model!$V$15:$V$120,26),Model!$V$15:$V$120,0)),"") -> IRAQ | D38: =IFERROR(INDEX(Model!$C$15:$C$120,MATCH(LARGE(Model!$V$15:$V$120,26),Model!$V$15:$V$120,0)),"") -> IRQ | E38: =IFERROR(INDEX(Model!$E$15:$E$120,MATCH(LARGE(Model!$V$15:$V$120,26),Model!$V$15:$V$120,0)),"") -> 360 | F38: =IFERROR(EXP(INDEX(Model!$T$15:$T$120,MATCH(LARGE(Model!$V$15:$V$120,26),Model!$V$15:$V$120,0))),"") -> 313.1081 | G38: =IFERROR(E38-F38,"") -> 46.891904 | H38: =IFERROR(LARGE(Model!$V$15:$V$120,26),"") -> 0.34661461 | I38: =IFERROR(INDEX(Model!$W$15:$W$120,MATCH(LARGE(Model!$V$15:$V$120,26),Model!$V$15:$V$120,0)),"") -> fair | J38: =IFERROR(INDEX(Model!$Y$15:$Y$120,MATCH(LARGE(Model!$V$15:$V$120,26),Model!$V$15:$V$120,0)),"") -> HIGH
B39: 27 | C39: =IFERROR(INDEX(Model!$B$15:$B$120,MATCH(LARGE(Model!$V$15:$V$120,27),Model!$V$15:$V$120,0)),"") -> GHANA | D39: =IFERROR(INDEX(Model!$C$15:$C$120,MATCH(LARGE(Model!$V$15:$V$120,27),Model!$V$15:$V$120,0)),"") -> GHA | E39: =IFERROR(INDEX(Model!$E$15:$E$120,MATCH(LARGE(Model!$V$15:$V$120,27),Model!$V$15:$V$120,0)),"") -> 950 | F39: =IFERROR(EXP(INDEX(Model!$T$15:$T$120,MATCH(LARGE(Model!$V$15:$V$120,27),Model!$V$15:$V$120,0))),"") -> 829.3621 | G39: =IFERROR(E39-F39,"") -> 120.6379 | H39: =IFERROR(LARGE(Model!$V$15:$V$120,27),"") -> 0.33729969 | I39: =IFERROR(INDEX(Model!$W$15:$W$120,MATCH(LARGE(Model!$V$15:$V$120,27),Model!$V$15:$V$120,0)),"") -> fair | J39: =IFERROR(INDEX(Model!$Y$15:$Y$120,MATCH(LARGE(Model!$V$15:$V$120,27),Model!$V$15:$V$120,0)),"") -> HIGH
B40: 28 | C40: =IFERROR(INDEX(Model!$B$15:$B$120,MATCH(LARGE(Model!$V$15:$V$120,28),Model!$V$15:$V$120,0)),"") -> QATAR | D40: =IFERROR(INDEX(Model!$C$15:$C$120,MATCH(LARGE(Model!$V$15:$V$120,28),Model!$V$15:$V$120,0)),"") -> QAT | E40: =IFERROR(INDEX(Model!$E$15:$E$120,MATCH(LARGE(Model!$V$15:$V$120,28),Model!$V$15:$V$120,0)),"") -> 70 | F40: =IFERROR(EXP(INDEX(Model!$T$15:$T$120,MATCH(LARGE(Model!$V$15:$V$120,28),Model!$V$15:$V$120,0))),"") -> 63.679358 | G40: =IFERROR(E40-F40,"") -> 6.3206415 | H40: =IFERROR(LARGE(Model!$V$15:$V$120,28),"") -> 0.23504473 | I40: =IFERROR(INDEX(Model!$W$15:$W$120,MATCH(LARGE(Model!$V$15:$V$120,28),Model!$V$15:$V$120,0)),"") -> fair | J40: =IFERROR(INDEX(Model!$Y$15:$Y$120,MATCH(LARGE(Model!$V$15:$V$120,28),Model!$V$15:$V$120,0)),"") -> HIGH
B41: 29 | C41: =IFERROR(INDEX(Model!$B$15:$B$120,MATCH(LARGE(Model!$V$15:$V$120,29),Model!$V$15:$V$120,0)),"") -> VIETNAM | D41: =IFERROR(INDEX(Model!$C$15:$C$120,MATCH(LARGE(Model!$V$15:$V$120,29),Model!$V$15:$V$120,0)),"") -> VNM | E41: =IFERROR(INDEX(Model!$E$15:$E$120,MATCH(LARGE(Model!$V$15:$V$120,29),Model!$V$15:$V$120,0)),"") -> 130 | F41: =IFERROR(EXP(INDEX(Model!$T$15:$T$120,MATCH(LARGE(Model!$V$15:$V$120,29),Model!$V$15:$V$120,0))),"") -> 120.11608 | G41: =IFERROR(E41-F41,"") -> 9.8839208 | H41: =IFERROR(LARGE(Model!$V$15:$V$120,29),"") -> 0.19640097 | I41: =IFERROR(INDEX(Model!$W$15:$W$120,MATCH(LARGE(Model!$V$15:$V$120,29),Model!$V$15:$V$120,0)),"") -> fair | J41: =IFERROR(INDEX(Model!$Y$15:$Y$120,MATCH(LARGE(Model!$V$15:$V$120,29),Model!$V$15:$V$120,0)),"") -> HIGH
B42: 30 | C42: =IFERROR(INDEX(Model!$B$15:$B$120,MATCH(LARGE(Model!$V$15:$V$120,30),Model!$V$15:$V$120,0)),"") -> KENYA | D42: =IFERROR(INDEX(Model!$C$15:$C$120,MATCH(LARGE(Model!$V$15:$V$120,30),Model!$V$15:$V$120,0)),"") -> KEN | E42: =IFERROR(INDEX(Model!$E$15:$E$120,MATCH(LARGE(Model!$V$15:$V$120,30),Model!$V$15:$V$120,0)),"") -> 480 | F42: =IFERROR(EXP(INDEX(Model!$T$15:$T$120,MATCH(LARGE(Model!$V$15:$V$120,30),Model!$V$15:$V$120,0))),"") -> 454.14884 | G42: =IFERROR(E42-F42,"") -> 25.851163 | H42: =IFERROR(LARGE(Model!$V$15:$V$120,30),"") -> 0.13750063 | I42: =IFERROR(INDEX(Model!$W$15:$W$120,MATCH(LARGE(Model!$V$15:$V$120,30),Model!$V$15:$V$120,0)),"") -> fair | J42: =IFERROR(INDEX(Model!$Y$15:$Y$120,MATCH(LARGE(Model!$V$15:$V$120,30),Model!$V$15:$V$120,0)),"") -> HIGH
...

Sheet Model
B2: Model · Cross-section fair value engine
B3: log(EMBI Z-spread) = α + β · Composite Fundamental Score. α and β are re-estimated cross-sectionally every Bloomberg refresh.
B5: Factor weights (editable, yellow cells) | G5: Live regression | M5: Quality gates | T5: Static macro vintage
B6: Rating | C6: w_R | D6: 0.35 | G6: Intercept α | K6: =IFERROR(INTERCEPT($AB$15:$AB$120,$AC$15:$AC$120),"") -> 5.6626447 | M6: Min vars to enter regression | R6: 4 | T6: Macro values (columns F–K) are hardcoded from IMF WEO Apr 2025 + S&P/Moody's/Fitch composite ratings as of Q1 2026. Refresh once a year with Claude.
B7: Govt debt | C7: w_D | D7: 0.2 | G7: Slope β | K7: =IFERROR(SLOPE($AB$15:$AB$120,$AC$15:$AC$120),"") -> 1.1144475 | M7: Cheap threshold (Z-resid ≥) | R7: 1.5
B8: Current acct | C8: w_C | D8: 0.15 | G8: R² | K8: =IFERROR(RSQ($AB$15:$AB$120,$AC$15:$AC$120),"") -> 0.75164838 | M8: Rich threshold (Z-resid ≤) | R8: -1.5
B9: FX reserves | C9: w_X | D9: 0.1 | G9: N (full data) | K9: =COUNT($AC$15:$AC$120) -> 68
B10: GDP growth | C10: w_G | D10: 0.12 | G10: Median spread bps | K10: =IFERROR(ROUND(MEDIAN($E$15:$E$120),0),"") -> 290
B11: Inflation | C11: w_P | D11: 0.08 | G11: Snapshot | K11: =TODAY() -> 46153
B12: Sum | D12: =SUM(D6:D11) -> 1
B14: Country | C14: ISO | D14: EMBI ticker | E14: Z bps | F14: Rating# | G14: GDP % | H14: CPI % | I14: Debt/GDP | J14: CA/GDP | K14: Res/GDP | L14: zR | M14: zD | N14: zC | O14: zX | P14: zG | Q14: zP | R14: F score | S14: log(S) | T14: fitted | U14: resid | V14: Z-resid | W14: Signal | X14: Cov | Y14: Conf | Z14: Refresh | AA14: As-of | AB14: flt_logS | AC14: flt_F
B15: ARGENTINA | C15: ARG | D15: JPSYARZW Index | E15: 600 | F15: 19 | G15: 5 | H15: 35 | I15: 80 | J15: 0.5 | K15: 5 | L15: =IFERROR(($F15-AVERAGE($F$15:$F$120))/STDEV($F$15:$F$120),"") -> 1.4497906 | M15: =IFERROR(($I15-AVERAGE($I$15:$I$120))/STDEV($I$15:$I$120),"") -> 0.90654459 | N15: =IFERROR(-($J15-AVERAGE($J$15:$J$120))/STDEV($J$15:$J$120),"") -> -0.21280465 | O15: =IFERROR(-($K15-AVERAGE($K$15:$K$120))/STDEV($K$15:$K$120),"") -> 1.2762614 | P15: =IFERROR(-($G15-AVERAGE($G$15:$G$120))/STDEV($G$15:$G$120),"") -> -1.0749091 | Q15: =IFERROR(($H15-AVERAGE($H$15:$H$120))/STDEV($H$15:$H$120),"") -> 4.0846562 | R15: =IFERROR(IF(ISNUMBER(L15),$D$6*L15,0)+IF(ISNUMBER(M15),$D$7*M15,0)+IF(ISNUMBER(N15),$D$8*N15,0)+IF(ISNUMBER(O15),$D$9*O15,0)+IF(ISNUMBER(P15),$D$10*P15,0)+IF(ISNUMBER(Q15),$D$11*Q15,0),"") -> 0.98222448 | S15: =IFERROR(LN($E15),"") -> 6.3969297 | T15: =IFERROR($K$6+$K$7*$R15,"") -> 6.7572823 | U15: =IFERROR($S15-$T15,"") -> -0.36035264 | V15: =IFERROR(($U15-AVERAGE($U$15:$U$120))/STDEV($U$15:$U$120),"") -> -0.89500916 | W15: =IF(ISNUMBER($V15),IF($V15>=$R$7,"CHEAP",IF($V15>=0.5,"slightly cheap",IF($V15<=$R$8,"RICH",IF($V15<=-0.5,"slightly rich","fair")))),"") -> slightly rich | X15: =COUNT($F15)+COUNT($G15)+COUNT($H15)+COUNT($I15)+COUNT($J15)+COUNT($K15) -> 6 | Y15: =IF($X15>=5,"HIGH",IF($X15>=3,"MED","LOW")) -> HIGH | AA15: 2025 (IMF WEO Apr 2025) | AB15: =IF(AND(ISNUMBER($S15),$X15>=$R$6),$S15,"") -> 6.3969297 | AC15: =IF(AND(ISNUMBER($R15),$X15>=$R$6),$R15,"") -> 0.98222448
B16: BOLIVIA | C16: BOL | D16: JPSYBVZW Index | E16: 1700 | F16: 17 | G16: 1.5 | H16: 12 | I16: 84 | J16: -3 | K16: 5 | L16: =IFERROR(($F16-AVERAGE($F$15:$F$120))/STDEV($F$15:$F$120),"") -> 1.0154921 | M16: =IFERROR(($I16-AVERAGE($I$15:$I$120))/STDEV($I$15:$I$120),"") -> 1.0825475 | N16: =IFERROR(-($J16-AVERAGE($J$15:$J$120))/STDEV($J$15:$J$120),"") -> 0.34807583 | O16: =IFERROR(-($K16-AVERAGE($K$15:$K$120))/STDEV($K$15:$K$120),"") -> 1.2762614 | P16: =IFERROR(-($G16-AVERAGE($G$15:$G$120))/STDEV($G$15:$G$120),"") -> 1.3873466 | Q16: =IFERROR(($H16-AVERAGE($H$15:$H$120))/STDEV($H$15:$H$120),"") -> 0.81509158 | R16: =IFERROR(IF(ISNUMBER(L16),$D$6*L16,0)+IF(ISNUMBER(M16),$D$7*M16,0)+IF(ISNUMBER(N16),$D$8*N16,0)+IF(ISNUMBER(O16),$D$9*O16,0)+IF(ISNUMBER(P16),$D$10*P16,0)+IF(ISNUMBER(Q16),$D$11*Q16,0),"") -> 0.98345817 | S16: =IFERROR(LN($E16),"") -> 7.4383835 | T16: =IFERROR($K$6+$K$7*$R16,"") -> 6.7586572 | U16: =IFERROR($S16-$T16,"") -> 0.67972635 | V16: =IFERROR(($U16-AVERAGE($U$15:$U$120))/STDEV($U$15:$U$120),"") -> 1.6882388 | W16: =IF(ISNUMBER($V16),IF($V16>=$R$7,"CHEAP",IF($V16>=0.5,"slightly cheap",IF($V16<=$R$8,"RICH",IF($V16<=-0.5,"slightly rich","fair")))),"") -> CHEAP | X16: =COUNT($F16)+COUNT($G16)+COUNT($H16)+COUNT($I16)+COUNT($J16)+COUNT($K16) -> 6 | Y16: =IF($X16>=5,"HIGH",IF($X16>=3,"MED","LOW")) -> HIGH | AA16: 2025 (IMF WEO Apr 2025) | AB16: =IF(AND(ISNUMBER($S16),$X16>=$R$6),$S16,"") -> 7.4383835 | AC16: =IF(AND(ISNUMBER($R16),$X16>=$R$6),$R16,"") -> 0.98345817
B17: BRAZIL | C17: BRA | D17: JPSYBRZW Index | E17: 245 | F17: 12 | G17: 2.1 | H17: 4.5 | I17: 88 | J17: -2 | K17: 17 | L17: =IFERROR(($F17-AVERAGE($F$15:$F$120))/STDEV($F$15:$F$120),"") -> -0.07025417 | M17: =IFERROR(($I17-AVERAGE($I$15:$I$120))/STDEV($I$15:$I$120),"") -> 1.2585505 | N17: =IFERROR(-($J17-AVERAGE($J$15:$J$120))/STDEV($J$15:$J$120),"") -> 0.18782426 | O17: =IFERROR(-($K17-AVERAGE($K$15:$K$120))/STDEV($K$15:$K$120),"") -> 0.079216226 | P17: =IFERROR(-($G17-AVERAGE($G$15:$G$120))/STDEV($G$15:$G$120),"") -> 0.9652456 | Q17: =IFERROR(($H17-AVERAGE($H$15:$H$120))/STDEV($H$15:$H$120),"") -> -0.25107079 | R17: =IFERROR(IF(ISNUMBER(L17),$D$6*L17,0)+IF(ISNUMBER(M17),$D$7*M17,0)+IF(ISNUMBER(N17),$D$8*N17,0)+IF(ISNUMBER(O17),$D$9*O17,0)+IF(ISNUMBER(P17),$D$10*P17,0)+IF(ISNUMBER(Q17),$D$11*Q17,0),"") -> 0.35896021 | S17: =IFERROR(LN($E17),"") -> 5.5012582 | T17: =IFERROR($K$6+$K$7*$R17,"") -> 6.062687 | U17: =IFERROR($S17-$T17,"") -> -0.56142879 | V17: =IFERROR(($U17-AVERAGE($U$15:$U$120))/STDEV($U$15:$U$120),"") -> -1.3944227 | W17: =IF(ISNUMBER($V17),IF($V17>=$R$7,"CHEAP",IF($V17>=0.5,"slightly cheap",IF($V17<=$R$8,"RICH",IF($V17<=-0.5,"slightly rich","fair")))),"") -> slightly rich | X17: =COUNT($F17)+COUNT($G17)+COUNT($H17)+COUNT($I17)+COUNT($J17)+COUNT($K17) -> 6 | Y17: =IF($X17>=5,"HIGH",IF($X17>=3,"MED","LOW")) -> HIGH | AA17: 2025 (IMF WEO Apr 2025) | AB17: =IF(AND(ISNUMBER($S17),$X17>=$R$6),$S17,"") -> 5.5012582 | AC17: =IF(AND(ISNUMBER($R17),$X17>=$R$6),$R17,"") -> 0.35896021
B18: CHILE | C18: CHL | D18: JPSYCHZW Index | E18: 130 | F18: 6 | G18: 2.3 | H18: 3.8 | I18: 42 | J18: -3 | K18: 14 | L18: =IFERROR(($F18-AVERAGE($F$15:$F$120))/STDEV($F$15:$F$120),"") -> -1.3731497 | M18: =IFERROR(($I18-AVERAGE($I$15:$I$120))/STDEV($I$15:$I$120),"") -> -0.7654834 | N18: =IFERROR(-($J18-AVERAGE($J$15:$J$120))/STDEV($J$15:$J$120),"") -> 0.34807583 | O18: =IFERROR(-($K18-AVERAGE($K$15:$K$120))/STDEV($K$15:$K$120),"") -> 0.37847752 | P18: =IFERROR(-($G18-AVERAGE($G$15:$G$120))/STDEV($G$15:$G$120),"") -> 0.82454528 | Q18: =IFERROR(($H18-AVERAGE($H$15:$H$120))/STDEV($H$15:$H$120),"") -> -0.35057927 | R18: =IFERROR(IF(ISNUMBER(L18),$D$6*L18,0)+IF(ISNUMBER(M18),$D$7*M18,0)+IF(ISNUMBER(N18),$D$8*N18,0)+IF(ISNUMBER(O18),$D$9*O18,0)+IF(ISNUMBER(P18),$D$10*P18,0)+IF(ISNUMBER(Q18),$D$11*Q18,0),"") -> -0.47274085 | S18: =IFERROR(LN($E18),"") -> 4.8675345 | T18: =IFERROR($K$6+$K$7*$R18,"") -> 5.1357999 | U18: =IFERROR($S18-$T18,"") -> -0.2682654 | V18: =IFERROR(($U18-AVERAGE($U$15:$U$120))/STDEV($U$15:$U$120),"") -> -0.66629176 | W18: =IF(ISNUMBER($V18),IF($V18>=$R$7,"CHEAP",IF($V18>=0.5,"slightly cheap",IF($V18<=$R$8,"RICH",IF($V18<=-0.5,"slightly rich","fair")))),"") -> slightly rich | X18: =COUNT($F18)+COUNT($G18)+COUNT($H18)+COUNT($I18)+COUNT($J18)+COUNT($K18) -> 6 | Y18: =IF($X18>=5,"HIGH",IF($X18>=3,"MED","LOW")) -> HIGH | AA18: 2025 (IMF WEO Apr 2025) | AB18: =IF(AND(ISNUMBER($S18),$X18>=$R$6),$S18,"") -> 4.8675345 | AC18: =IF(AND(ISNUMBER($R18),$X18>=$R$6),$R18,"") -> -0.47274085
B19: COLOMBIA | C19: COL | D19: JPSYCLZW Index | E19: 350 | F19: 11 | G19: 2.4 | H19: 4 | I19: 60 | J19: -2.8 | K19: 17 | L19: =IFERROR(($F19-AVERAGE($F$15:$F$120))/STDEV($F$15:$F$120),"") -> -0.28740342 | M19: =IFERROR(($I19-AVERAGE($I$15:$I$120))/STDEV($I$15:$I$120),"") -> 0.026529856 | N19: =IFERROR(-($J19-AVERAGE($J$15:$J$120))/STDEV($J$15:$J$120),"") -> 0.31602552 | O19: =IFERROR(-($K19-AVERAGE($K$15:$K$120))/STDEV($K$15:$K$120),"") -> 0.079216226 | P19: =IFERROR(-($G19-AVERAGE($G$15:$G$120))/STDEV($G$15:$G$120),"") -> 0.75419512 | Q19: =IFERROR(($H19-AVERAGE($H$15:$H$120))/STDEV($H$15:$H$120),"") -> -0.32214828 | R19: =IFERROR(IF(ISNUMBER(L19),$D$6*L19,0)+IF(ISNUMBER(M19),$D$7*M19,0)+IF(ISNUMBER(N19),$D$8*N19,0)+IF(ISNUMBER(O19),$D$9*O19,0)+IF(ISNUMBER(P19),$D$10*P19,0)+IF(ISNUMBER(Q19),$D$11*Q19,0),"") -> 0.024771774 | S19: =IFERROR(LN($E19),"") -> 5.8579332 | T19: =IFERROR($K$6+$K$7*$R19,"") -> 5.6902515 | U19: =IFERROR($S19-$T19,"") -> 0.16768161 | V19: =IFERROR(($U19-AVERAGE($U$15:$U$120))/STDEV($U$15:$U$120),"") -> 0.41647141 | W19: =IF(ISNUMBER($V19),IF($V19>=$R$7,"CHEAP",IF($V19>=0.5,"slightly cheap",IF($V19<=$R$8,"RICH",IF($V19<=-0.5,"slightly rich","fair")))),"") -> fair | X19: =COUNT($F19)+COUNT($G19)+COUNT($H19)+COUNT($I19)+COUNT($J19)+COUNT($K19) -> 6 | Y19: =IF($X19>=5,"HIGH",IF($X19>=3,"MED","LOW")) -> HIGH | AA19: 2025 (IMF WEO Apr 2025) | AB19: =IF(AND(ISNUMBER($S19),$X19>=$R$6),$S19,"") -> 5.8579332 | AC19: =IF(AND(ISNUMBER($R19),$X19>=$R$6),$R19,"") -> 0.024771774
B20: COSTA RICA | C20: CRI | D20: JPSYCRZW Index | E20: 280 | F20: 13 | G20: 3.8 | H20: 1.5 | I20: 61 | J20: -2 | K20: 16 | L20: =IFERROR(($F20-AVERAGE($F$15:$F$120))/STDEV($F$15:$F$120),"") -> 0.14689508 | M20: =IFERROR(($I20-AVERAGE($I$15:$I$120))/STDEV($I$15:$I$120),"") -> 0.070530592 | N20: =IFERROR(-($J20-AVERAGE($J$15:$J$120))/STDEV($J$15:$J$120),"") -> 0.18782426 | O20: =IFERROR(-($K20-AVERAGE($K$15:$K$120))/STDEV($K$15:$K$120),"") -> 0.17896999 | P20: =IFERROR(-($G20-AVERAGE($G$15:$G$120))/STDEV($G$15:$G$120),"") -> -0.23070715 | Q20: =IFERROR(($H20-AVERAGE($H$15:$H$120))/STDEV($H$15:$H$120),"") -> -0.67753573 | R20: =IFERROR(IF(ISNUMBER(L20),$D$6*L20,0)+IF(ISNUMBER(M20),$D$7*M20,0)+IF(ISNUMBER(N20),$D$8*N20,0)+IF(ISNUMBER(O20),$D$9*O20,0)+IF(ISNUMBER(P20),$D$10*P20,0)+IF(ISNUMBER(Q20),$D$11*Q20,0),"") -> 0.02970232 | S20: =IFERROR(LN($E20),"") -> 5.6347896 | T20: =IFERROR($K$6+$K$7*$R20,"") -> 5.6957464 | U20: =IFERROR($S20-$T20,"") -> -0.060956779 | V20: =IFERROR(($U20-AVERAGE($U$15:$U$120))/STDEV($U$15:$U$120),"") -> -0.15139857 | W20: =IF(ISNUMBER($V20),IF($V20>=$R$7,"CHEAP",IF($V20>=0.5,"slightly cheap",IF($V20<=$R$8,"RICH",IF($V20<=-0.5,"slightly rich","fair")))),"") -> fair | X20: =COUNT($F20)+COUNT($G20)+COUNT($H20)+COUNT($I20)+COUNT($J20)+COUNT($K20) -> 6 | Y20: =IF($X20>=5,"HIGH",IF($X20>=3,"MED","LOW")) -> HIGH | AA20: 2025 (IMF WEO Apr 2025) | AB20: =IF(AND(ISNUMBER($S20),$X20>=$R$6),$S20,"") -> 5.6347896 | AC20: =IF(AND(ISNUMBER($R20),$X20>=$R$6),$R20,"") -> 0.02970232
B21: DOMINICAN REPUBLIC | C21: DOM | D21: JPSYDRZW Index | E21: 290 | F21: 13 | G21: 4.5 | H21: 4 | I21: 60 | J21: -3 | K21: 13 | L21: =IFERROR(($F21-AVERAGE($F$15:$F$120))/STDEV($F$15:$F$120),"") -> 0.14689508 | M21: =IFERROR(($I21-AVERAGE($I$15:$I$120))/STDEV($I$15:$I$120),"") -> 0.026529856 | N21: =IFERROR(-($J21-AVERAGE($J$15:$J$120))/STDEV($J$15:$J$120),"") -> 0.34807583 | O21: =IFERROR(-($K21-AVERAGE($K$15:$K$120))/STDEV($K$15:$K$120),"") -> 0.47823129 | P21: =IFERROR(-($G21-AVERAGE($G$15:$G$120))/STDEV($G$15:$G$120),"") -> -0.72315828 | Q21: =IFERROR(($H21-AVERAGE($H$15:$H$120))/STDEV($H$15:$H$120),"") -> -0.32214828 | R21: =IFERROR(IF(ISNUMBER(L21),$D$6*L21,0)+IF(ISNUMBER(M21),$D$7*M21,0)+IF(ISNUMBER(N21),$D$8*N21,0)+IF(ISNUMBER(O21),$D$9*O21,0)+IF(ISNUMBER(P21),$D$10*P21,0)+IF(ISNUMBER(Q21),$D$11*Q21,0),"") -> 0.044202898 | S21: =IFERROR(LN($E21),"") -> 5.6698809 | T21: =IFERROR($K$6+$K$7*$R21,"") -> 5.7119065 | U21: =IFERROR($S21-$T21,"") -> -0.042025592 | V21: =IFERROR(($U21-AVERAGE($U$15:$U$120))/STDEV($U$15:$U$120),"") -> -0.10437912 | W21: =IF(ISNUMBER($V21),IF($V21>=$R$7,"CHEAP",IF($V21>=0.5,"slightly cheap",IF($V21<=$R$8,"RICH",IF($V21<=-0.5,"slightly rich","fair")))),"") -> fair | X21: =COUNT($F21)+COUNT($G21)+COUNT($H21)+COUNT($I21)+COUNT($J21)+COUNT($K21) -> 6 | Y21: =IF($X21>=5,"HIGH",IF($X21>=3,"MED","LOW")) -> HIGH | AA21: 2025 (IMF WEO Apr 2025) | AB21: =IF(AND(ISNUMBER($S21),$X21>=$R$6),$S21,"") -> 5.6698809 | AC21: =IF(AND(ISNUMBER($R21),$X21>=$R$6),$R21,"") -> 0.044202898
B22: ECUADOR | C22: ECU | D22: JPSYECZW Index | E22: 1300 | F22: 18 | G22: 1 | H22: 2 | I22: 56 | J22: 1.5 | K22: 6 | L22: =IFERROR(($F22-AVERAGE($F$15:$F$120))/STDEV($F$15:$F$120),"") -> 1.2326414 | M22: =IFERROR(($I22-AVERAGE($I$15:$I$120))/STDEV($I$15:$I$120),"") -> -0.14947309 | N22: =IFERROR(-($J22-AVERAGE($J$15:$J$120))/STDEV($J$15:$J$120),"") -> -0.37305622 | O22: =IFERROR(-($K22-AVERAGE($K$15:$K$120))/STDEV($K$15:$K$120),"") -> 1.1765077 | P22: =IFERROR(-($G22-AVERAGE($G$15:$G$120))/STDEV($G$15:$G$120),"") -> 1.7390974 | Q22: =IFERROR(($H22-AVERAGE($H$15:$H$120))/STDEV($H$15:$H$120),"") -> -0.60645824 | R22: =IFERROR(IF(ISNUMBER(L22),$D$6*L22,0)+IF(ISNUMBER(M22),$D$7*M22,0)+IF(ISNUMBER(N22),$D$8*N22,0)+IF(ISNUMBER(O22),$D$9*O22,0)+IF(ISNUMBER(P22),$D$10*P22,0)+IF(ISNUMBER(Q22),$D$11*Q22,0),"") -> 0.62339721 | S22: =IFERROR(LN($E22),"") -> 7.1701195 | T22: =IFERROR($K$6+$K$7*$R22,"") -> 6.3573882 | U22: =IFERROR($S22-$T22,"") -> 0.81273139 | V22: =IFERROR(($U22-AVERAGE($U$15:$U$120))/STDEV($U$15:$U$120),"") -> 2.0185839 | W22: =IF(ISNUMBER($V22),IF($V22>=$R$7,"CHEAP",IF($V22>=0.5,"slightly cheap",IF($V22<=$R$8,"RICH",IF($V22<=-0.5,"slightly rich","fair")))),"") -> CHEAP | X22: =COUNT($F22)+COUNT($G22)+COUNT($H22)+COUNT($I22)+COUNT($J22)+COUNT($K22) -> 6 | Y22: =IF($X22>=5,"HIGH",IF($X22>=3,"MED","LOW")) -> HIGH | AA22: 2025 (IMF WEO Apr 2025) | AB22: =IF(AND(ISNUMBER($S22),$X22>=$R$6),$S22,"") -> 7.1701195 | AC22: =IF(AND(ISNUMBER($R22),$X22>=$R$6),$R22,"") -> 0.62339721
B23: EL SALVADOR | C23: SLV | D23: JPSYESZW Index | E23: 480 | F23: 18 | G23: 2.5 | H23: 1.5 | I23: 84 | J23: -2.5 | K23: 13 | L23: =IFERROR(($F23-AVERAGE($F$15:$F$120))/STDEV($F$15:$F$120),"") -> 1.2326414 | M23: =IFERROR(($I23-AVERAGE($I$15:$I$120))/STDEV($I$15:$I$120),"") -> 1.0825475 | N23: =IFERROR(-($J23-AVERAGE($J$15:$J$120))/STDEV($J$15:$J$120),"") -> 0.26795005 | O23: =IFERROR(-($K23-AVERAGE($K$15:$K$120))/STDEV($K$15:$K$120),"") -> 0.47823129 | P23: =IFERROR(-($G23-AVERAGE($G$15:$G$120))/STDEV($G$15:$G$120),"") -> 0.68384495 | Q23: =IFERROR(($H23-AVERAGE($H$15:$H$120))/STDEV($H$15:$H$120),"") -> -0.67753573 | R23: =IFERROR(IF(ISNUMBER(L23),$D$6*L23,0)+IF(ISNUMBER(M23),$D$7*M23,0)+IF(ISNUMBER(N23),$D$8*N23,0)+IF(ISNUMBER(O23),$D$9*O23,0)+IF(ISNUMBER(P23),$D$10*P23,0)+IF(ISNUMBER(Q23),$D$11*Q23,0),"") -> 0.76380815 | S23: =IFERROR(LN($E23),"") -> 6.1737861 | T23: =IFERROR($K$6+$K$7*$R23,"") -> 6.5138688 | U23: =IFERROR($S23-$T23,"") -> -0.34008267 | V23: =IFERROR(($U23-AVERAGE($U$15:$U$120))/STDEV($U$15:$U$120),"") -> -0.84466456 | W23: =IF(ISNUMBER($V23),IF($V23>=$R$7,"CHEAP",IF($V23>=0.5,"slightly cheap",IF($V23<=$R$8,"RICH",IF($V23<=-0.5,"slightly rich","fair")))),"") -> slightly rich | X23: =COUNT($F23)+COUNT($G23)+COUNT($H23)+COUNT($I23)+COUNT($J23)+COUNT($K23) -> 6 | Y23: =IF($X23>=5,"HIGH",IF($X23>=3,"MED","LOW")) -> HIGH | AA23: 2025 (IMF WEO Apr 2025) | AB23: =IF(AND(ISNUMBER($S23),$X23>=$R$6),$S23,"") -> 6.1737861 | AC23: =IF(AND(ISNUMBER($R23),$X23>=$R$6),$R23,"") -> 0.76380815
B24: GUATEMALA | C24: GTM | D24: JPSYGTZW Index | E24: 230 | F24: 11 | G24: 3.8 | H24: 4 | I24: 28 | J24: 1.5 | K24: 21 | L24: =IFERROR(($F24-AVERAGE($F$15:$F$120))/STDEV($F$15:$F$120),"") -> -0.28740342 | M24: =IFERROR(($I24-AVERAGE($I$15:$I$120))/STDEV($I$15:$I$120),"") -> -1.3814937 | N24: =IFERROR(-($J24-AVERAGE($J$15:$J$120))/STDEV($J$15:$J$120),"") -> -0.37305622 | O24: =IFERROR(-($K24-AVERAGE($K$15:$K$120))/STDEV($K$15:$K$120),"") -> -0.31979884 | P24: =IFERROR(-($G24-AVERAGE($G$15:$G$120))/STDEV($G$15:$G$120),"") -> -0.23070715 | Q24: =IFERROR(($H24-AVERAGE($H$15:$H$120))/STDEV($H$15:$H$120),"") -> -0.32214828 | R24: =IFERROR(IF(ISNUMBER(L24),$D$6*L24,0)+IF(ISNUMBER(M24),$D$7*M24,0)+IF(ISNUMBER(N24),$D$8*N24,0)+IF(ISNUMBER(O24),$D$9*O24,0)+IF(ISNUMBER(P24),$D$10*P24,0)+IF(ISNUMBER(Q24),$D$11*Q24,0),"") -> -0.51828498 | S24: =IFERROR(LN($E24),"") -> 5.4380793 | T24: =IFERROR($K$6+$K$7*$R24,"") -> 5.0850433 | U24: =IFERROR($S24-$T24,"") -> 0.35303599 | V24: =IFERROR(($U24-AVERAGE($U$15:$U$120))/STDEV($U$15:$U$120),"") -> 0.87683676 | W24: =IF(ISNUMBER($V24),IF($V24>=$R$7,"CHEAP",IF($V24>=0.5,"slightly cheap",IF($V24<=$R$8,"RICH",IF($V24<=-0.5,"slightly rich","fair")))),"") -> slightly cheap | X24: =COUNT($F24)+COUNT($G24)+COUNT($H24)+COUNT($I24)+COUNT($J24)+COUNT($K24) -> 6 | Y24: =IF($X24>=5,"HIGH",IF($X24>=3,"MED","LOW")) -> HIGH | AA24: 2025 (IMF WEO Apr 2025) | AB24: =IF(AND(ISNUMBER($S24),$X24>=$R$6),$S24,"") -> 5.4380793 | AC24: =IF(AND(ISNUMBER($R24),$X24>=$R$6),$R24,"") -> -0.51828498
B25: JAMAICA | C25: JAM | D25: JPSYJMZW Index | E25: 320 | F25: 14 | G25: 2 | H25: 5.5 | I25: 70 | J25: -1.5 | K25: 25 | L25: =IFERROR(($F25-AVERAGE($F$15:$F$120))/STDEV($F$15:$F$120),"") -> 0.36404434 | M25: =IFERROR(($I25-AVERAGE($I$15:$I$120))/STDEV($I$15:$I$120),"") -> 0.46653722 | N25: =IFERROR(-($J25-AVERAGE($J$15:$J$120))/STDEV($J$15:$J$120),"") -> 0.10769848 | O25: =IFERROR(-($K25-AVERAGE($K$15:$K$120))/STDEV($K$15:$K$120),"") -> -0.7188139 | P25: =IFERROR(-($G25-AVERAGE($G$15:$G$120))/STDEV($G$15:$G$120),"") -> 1.0355958 | Q25: =IFERROR(($H25-AVERAGE($H$15:$H$120))/STDEV($H$15:$H$120),"") -> -0.1089158 | R25: =IFERROR(IF(ISNUMBER(L25),$D$6*L25,0)+IF(ISNUMBER(M25),$D$7*M25,0)+IF(ISNUMBER(N25),$D$8*N25,0)+IF(ISNUMBER(O25),$D$9*O25,0)+IF(ISNUMBER(P25),$D$10*P25,0)+IF(ISNUMBER(Q25),$D$11*Q25,0),"") -> 0.28055457 | S25: =IFERROR(LN($E25),"") -> 5.768321 | T25: =IFERROR($K$6+$K$7*$R25,"") -> 5.975308 | U25: =IFERROR($S25-$T25,"") -> -0.20698705 | V25: =IFERROR(($U25-AVERAGE($U$15:$U$120))/STDEV($U$15:$U$120),"") -> -0.51409448 | W25: =IF(ISNUMBER($V25),IF($V25>=$R$7,"CHEAP",IF($V25>=0.5,"slightly cheap",IF($V25<=$R$8,"RICH",IF($V25<=-0.5,"slightly rich","fair")))),"") -> slightly rich | X25: =COUNT($F25)+COUNT($G25)+COUNT($H25)+COUNT($I25)+COUNT($J25)+COUNT($K25) -> 6 | Y25: =IF($X25>=5,"HIGH",IF($X25>=3,"MED","LOW")) -> HIGH | AA25: 2025 (IMF WEO Apr 2025) | AB25: =IF(AND(ISNUMBER($S25),$X25>=$R$6),$S25,"") -> 5.768321 | AC25: =IF(AND(ISNUMBER($R25),$X25>=$R$6),$R25,"") -> 0.28055457
B26: MEXICO | C26: MEX | D26: JPSYMXZW Index | E26: 290 | F26: 10 | G26: 1.5 | H26: 4 | I26: 53 | J26: -1 | K26: 12 | L26: =IFERROR(($F26-AVERAGE($F$15:$F$120))/STDEV($F$15:$F$120),"") -> -0.50455268 | M26: =IFERROR(($I26-AVERAGE($I$15:$I$120))/STDEV($I$15:$I$120),"") -> -0.2814753 | N26: =IFERROR(-($J26-AVERAGE($J$15:$J$120))/STDEV($J$15:$J$120),"") -> 0.027572696 | O26: =IFERROR(-($K26-AVERAGE($K$15:$K$120))/STDEV($K$15:$K$120),"") -> 0.57798506 | P26: =IFERROR(-($G26-AVERAGE($G$15:$G$120))/STDEV($G$15:$G$120),"") -> 1.3873466 | Q26: =IFERROR(($H26-AVERAGE($H$15:$H$120))/STDEV($H$15:$H$120),"") -> -0.32214828 | R26: =IFERROR(IF(ISNUMBER(L26),$D$6*L26,0)+IF(ISNUMBER(M26),$D$7*M26,0)+IF(ISNUMBER(N26),$D$8*N26,0)+IF(ISNUMBER(O26),$D$9*O26,0)+IF(ISNUMBER(P26),$D$10*P26,0)+IF(ISNUMBER(Q26),$D$11*Q26,0),"") -> -0.030244361 | S26: =IFERROR(LN($E26),"") -> 5.6698809 | T26: =IFERROR($K$6+$K$7*$R26,"") -> 5.628939 | U26: =IFERROR($S26-$T26,"") -> 0.040941967 | V26: =IFERROR(($U26-AVERAGE($U$15:$U$120))/STDEV($U$15:$U$120),"") -> 0.10168771 | W26: =IF(ISNUMBER($V26),IF($V26>=$R$7,"CHEAP",IF($V26>=0.5,"slightly cheap",IF($V26<=$R$8,"RICH",IF($V26<=-0.5,"slightly rich","fair")))),"") -> fair | X26: =COUNT($F26)+COUNT($G26)+COUNT($H26)+COUNT($I26)+COUNT($J26)+COUNT($K26) -> 6 | Y26: =IF($X26>=5,"HIGH",IF($X26>=3,"MED","LOW")) -> HIGH | AA26: 2025 (IMF WEO Apr 2025) | AB26: =IF(AND(ISNUMBER($S26),$X26>=$R$6),$S26,"") -> 5.6698809 | AC26: =IF(AND(ISNUMBER($R26),$X26>=$R$6),$R26,"") -> -0.030244361
... B82: VIETNAM | C82: VNM | D82: JPSYVNZW Index | E82: 130 | F82: 11 | G82: 6.5 | H82: 3.5 | I82: 35 | J82: 5 | K82: 22 | L82: =IFERROR(($F82-AVERAGE($F$15:$F$120))/STDEV($F$15:$F$120),"") -> -0.28740342 | M82: =IFERROR(($I82-AVERAGE($I$15:$I$120))/STDEV($I$15:$I$120),"") -> -1.0734886 | N82: =IFERROR(-($J82-AVERAGE($J$15:$J$120))/STDEV($J$15:$J$120),"") -> -0.9339367 | O82: =IFERROR(-($K82-AVERAGE($K$15:$K$120))/STDEV($K$15:$K$120),"") -> -0.4195526 | P82: =IFERROR(-($G82-AVERAGE($G$15:$G$120))/STDEV($G$15:$G$120),"") -> -2.1301615 | Q82: =IFERROR(($H82-AVERAGE($H$15:$H$120))/STDEV($H$15:$H$120),"") -> -0.39322577 | R82: =IFERROR(IF(ISNUMBER(L82),$D$6*L82,0)+IF(ISNUMBER(M82),$D$7*M82,0)+IF(ISNUMBER(N82),$D$8*N82,0)+IF(ISNUMBER(O82),$D$9*O82,0)+IF(ISNUMBER(P82),$D$10*P82,0)+IF(ISNUMBER(Q82),$D$11*Q82,0),"") -> -0.78441212 | S82: =IFERROR(LN($E82),"") -> 4.8675345 | T82: =IFERROR($K$6+$K$7*$R82,"") -> 4.7884586 | U82: =IFERROR($S82-$T82,"") -> 0.079075848 | V82: =IFERROR(($U82-AVERAGE($U$15:$U$120))/STDEV($U$15:$U$120),"") -> 0.19640097 | W82: =IF(ISNUMBER($V82),IF($V82>=$R$7,"CHEAP",IF($V82>=0.5,"slightly cheap",IF($V82<=$R$8,"RICH",IF($V82<=-0.5,"slightly rich","fair")))),"") -> fair | X82: =COUNT($F82)+COUNT($G82)+COUNT($H82)+COUNT($I82)+COUNT($J82)+COUNT($K82) -> 6 | Y82: =IF($X82>=5,"HIGH",IF($X82>=3,"MED","LOW")) -> HIGH | AA82: 2025 (IMF WEO Apr 2025) | AB82: =IF(AND(ISNUMBER($S82),$X82>=$R$6),$S82,"") -> 4.8675345 | AC82: =IF(AND(ISNUMBER($R82),$X82>=$R$6),$R82,"") -> -0.78441212

Sheet Methodology
B2: Methodology
B4: The idea in one paragraph
D5: Every sovereign gets a Fundamental Score F built from six macro variables: rating, government debt, current account, FX reserves, GDP growth, and inflation. F is cross-sectionally z-scored — so it measures each country's macro risk relative to the rest of the EMBI universe. We then regress log(EMBI Z-spread) on F across all countries to get a fair-value spread curve. The residual is the cheap/rich signal.
B7: Why static macro?
D8: Macro fundamentals barely move from week to week. Pulling them live from Bloomberg tickers (some of which Bloomberg cannot resolve for frontier names) was the main source of friction in the old file. We freeze the macro panel and only refresh it once a year. The signal still moves daily because the LIVE input — the Z-spread — is what drives the regression residual.
B10: The math
B11: 1. Inputs (static) | D11: For each country, hardcoded values for rating (numeric 1–22 composite of S&P / Moody's / Fitch), GDP growth %, CPI %, debt %GDP, current account %GDP, FX reserves %GDP.
B12: 2. Cross-section z-scores | D12: For each macro variable v across all N countries: z(vᵢ) = (vᵢ − mean) / stdev. We invert the sign so 'higher z = riskier' for all six variables.
B13: 3. Composite Fundamental Score | D13: Fᵢ = Σ w_k · z_k(i). Weights are editable on the Model tab (default: rating 0.35, debt 0.20, CA 0.15, reserves 0.10, growth 0.12, inflation 0.08). These sum to 1.0.
B14: 4. LIVE cross-sectional regression | D14: log(Sᵢ) = α + β · Fᵢ estimated via Excel INTERCEPT / SLOPE every Bloomberg refresh. β should be positive — riskier macro → wider spread.
B15: 5. Residual | D15: rᵢ = log(Sᵢ) − (α + β · Fᵢ). Z-score the residuals across the universe: Zᵢ = (rᵢ − mean) / stdev. Positive Z = trading wider than fair = CHEAP.
B16: 6. Signal buckets | D16: Z ≥ +1.5 → CHEAP | +0.5 ≤ Z < +1.5 → slightly cheap | −0.5 < Z < +0.5 → fair | −1.5 < Z ≤ −0.5 → slightly rich | Z ≤ −1.5 → RICH. Cut-offs are editable on Model tab (cells R7, R8).
B18: Coverage tiers
B19: HIGH (5–6 vars) | D19: All six macro inputs populated. Treat as full-confidence signal.
B20: MED (3–4 vars) | D20: Some inputs missing. Use signal as supporting evidence only.
B21: LOW (0–2 vars) | D21: Excluded from regression — F score not reliable.
B23: Daily workflow (with Bloomberg)
B24: 1. | D24: Open EM_Sovereign_Credit_v2.xlsx in Excel with the Bloomberg add-in loaded.
B25: 2. | D25: Replace the Z bps column (Model!E15:E84) with =BDP(D15,"PX_LAST") down the column. The build comment on each cell shows the exact formula.
B26: 3. | D26: Press Ctrl+Alt+F9 to refresh. α, β, R², residuals, signals all update.
B27: 4. | D27: The Monitor tab is your read. Top of the list = cheapest. Bottom = richest.
B29: Yearly refresh (with Claude)
D30: Once a year (or after a rating action) the macro panel needs updating. Send Luis's Claude session: 'refresh the EM Sovereign Credit macro inputs to latest IMF WEO + current ratings.' Claude updates the blue cells in Model!F15:K84 and the As-of column. No code or Bloomberg work required.
B32: Caveats
B33: • | D33: Cross-section z-scores are sensitive to the universe. Distressed names (Ukraine, Lebanon, defaulted issuers) can drag the mean — consider excluding them from regression by lowering their Coverage to <4.
B34: • | D34: Single-equation regression on one composite is intentionally simple. A multi-factor regression has slightly better fit but worse interpretability and more overfit.
B35: • | D35: log(spread) breaks down for very tight (<1bp) names. None of the universe should be near zero, but watch out for stale Bloomberg ticks.
B36: • | D36: Composite numerical ratings are MANUAL. Update them on the Model tab after rating actions — they don't pull live.
B38: Literature anchors
B39: Cantor & Packer (1996) | D39: FRBNY Economic Policy Review. 'Determinants and Impact of Sovereign Credit Ratings.'
B40: Eichengreen & Mody (1998) | D40: NBER WP 6408. 'What Explains Changing Spreads on Emerging Market Debt: Fundamentals or Market Sentiment?'
B41: Hilscher & Nosbusch (2010) | D41: Review of Finance 14(2). 'Determinants and Implications of Sovereign Default Risk in the Cross-Section.'
B42: Csonto & Ivaschenko (2013) | D42: IMF WP 13/164. 'Determinants of Sovereign Bond Spreads in Emerging Markets.'
B43: Comelli (2012) | D43: IMF WP 12/212. 'Emerging Market Sovereign Bond Spreads: Estimation and Back-testing.'

Sheet Ratings
B2: Rating → numeric scale (reference)
B4: S&P | C4: score | E4: Moody's | F4: score | H4: Fitch | I4: score
B5: AAA | C5: 1 | E5: Aaa | F5: 1 | H5: AAA | I5: 1
B6: AA+ | C6: 2 | E6: Aa1 | F6: 2 | H6: AA+ | I6: 2
B7: AA | C7: 3 | E7: Aa2 | F7: 3 | H7: AA | I7: 3
B8: AA- | C8: 4 | E8: Aa3 | F8: 4 | H8: AA- | I8: 4
B9: A+ | C9: 5 | E9: A1 | F9: 5 | H9: A+ | I9: 5
B10: A | C10: 6 | E10: A2 | F10: 6 | H10: A | I10: 6
B11: A- | C11: 7 | E11: A3 | F11: 7 | H11: A- | I11: 7
B12: BBB+ | C12: 8 | E12: Baa1 | F12: 8 | H12: BBB+ | I12: 8
B13: BBB | C13: 9 | E13: Baa2 | F13: 9 | H13: BBB | I13: 9
B14: BBB- | C14: 10 | E14: Baa3 | F14: 10 | H14: BBB- | I14: 10
B15: BB+ | C15: 11 | E15: Ba1 | F15: 11 | H15: BB+ | I15: 11
B16: BB | C16: 12 | E16: Ba2 | F16: 12 | H16: BB | I16: 12
... B26: D | C26: 22 | E26: - | F26: 22 | H26: D/RD | I26: 22
B28: Investment grade = score ≤ 10. Speculative = 11+. Distressed/Default = 17+.
