Workbook

Sheet Read me
B2: EMBI Global Diversified — Monitor
B3: Spread monitor + total return analysis. Bloomberg-driven, no Python.
B5: How to refresh
B6: Open with Bloomberg Terminal running. BLP → Refresh Workbook (or F9). All BDP and BDH formulas re-pull. The chart redraws automatically. Optionally enable BLP → Settings → 'Refresh on open' for fully automatic refresh on file open.
B8: Tabs
B9: Read me · Spread Monitor (regional table + 15y EMBI chart) · Total Return (MTD/QTD/YTD/1Y/3Y per country) · Tickers (single source of truth — edit here).
B11: Spread Monitor
B12: Top: KPI strip with current EMBI Global spread plus Δ1d / Δ1m / ΔYTD. Below: the 15-year daily history chart (date axis auto-extends as new data loads). Below that: regional table in your specified order — LatAm, EM Europe & Turkey, GCC, Africa, Asia. Each region has a subtotal showing weight share, weighted-average spread, and total contribution to aggregate EMBI. Final TOTAL row sums across all regions.
B14: Total Return tab
B15: Same regional grouping. Columns: latest TR index level, MTD %, QTD %, YTD %, 1Y %, 3Y %. Per-country TR uses BDH at fixed dates (end of last month, end of last quarter, end of last year, 1y ago, 3y ago) divided into the latest BDP value to compute the period return. Conditional shading: green positive, red negative. Region rows show weight-weighted average return per period.
B17: Editing tickers
B18: All tickers and weights live on the Tickers tab. Edit in one place; both monitor tabs pick up the change automatically because they reference Tickers!E (spread) and Tickers!F (total return) cells. To add a country, insert a row in the right regional band on Tickers, fill in the cells, and the table will pick it up on the next refresh — but you'll need to re-extend the table-row range on the monitor tabs (or just rebuild).
... B21: Tickers are best-guess Bloomberg conventions (JPSSxxxx for spread, JPMExxxx for total return). Use TickerVerifier.xlsx in the same folder to confirm them. JPM index family is browsable via JPGB <GO> or JPMI <GO> in the Terminal. Country weights are approximate Q1 2026 estimates — paste the latest from JPM's monthly index report into the Tickers!D column when you want them precise.

Sheet Spread Monitor
A1: EMBI Global Diversified — Spread Monitor
A2: Live from Bloomberg. Refresh: BLP → Refresh Workbook (or F9). Tickers and weights edited on Tickers tab.
A4: EMBI Global Diversified
A6: Current spread | B6: Δ 1d | C6: Δ 1m | D6: Δ YTD
A7: =BDP(Tickers!E5,"PX_LAST") | B7: =BDP(Tickers!E5,"PX_LAST")-BDP(Tickers!E5,"PX_LAST_DT_PREV_DAY") | C7: =BDP(Tickers!E5,"PX_LAST")-INDEX(BDH(Tickers!E5,"PX_LAST",EDATE(TODAY(),-1),EDATE(TODAY(),-1)+5,"Days","A","fill","P"),1,2) | D7: =BDP(Tickers!E5,"PX_LAST")-INDEX(BDH(Tickers!E5,"PX_LAST",DATE(YEAR(TODAY())-1,12,29),DATE(YEAR(TODAY()),1,5),"Days","A","fill","P"),1,2)
A35: Country | B35: Region | C35: Spread ticker | D35: Weight (%) | E35: Current (bps) | F35: Δ 1d | G35: Δ 1m | H35: Δ YTD | I35: Contribution (bps)
A36: LatAm
A37: =Tickers!B6 | B37: =Tickers!C6 | C37: =Tickers!E6 | D37: =Tickers!D6 | E37: =IFERROR(BDP(Tickers!E6,"PX_LAST"),NA()) | F37: =IFERROR(BDP(Tickers!E6,"PX_LAST")-BDP(Tickers!E6,"PX_LAST_DT_PREV_DAY"),NA()) | G37: =IFERROR(BDP(Tickers!E6,"PX_LAST")-INDEX(BDH(Tickers!E6,"PX_LAST",EDATE(TODAY(),-1),EDATE(TODAY(),-1)+5,"Days","A","fill","P"),1,2),NA()) | H37: =IFERROR(BDP(Tickers!E6,"PX_LAST")-INDEX(BDH(Tickers!E6,"PX_LAST",DATE(YEAR(TODAY())-1,12,29),DATE(YEAR(TODAY()),1,5),"Days","A","fill","P"),1,2),NA()) | I37: =IFERROR(D37*E37/100,NA())
A38: =Tickers!B7 | B38: =Tickers!C7 | C38: =Tickers!E7 | D38: =Tickers!D7 | E38: =IFERROR(BDP(Tickers!E7,"PX_LAST"),NA()) | F38: =IFERROR(BDP(Tickers!E7,"PX_LAST")-BDP(Tickers!E7,"PX_LAST_DT_PREV_DAY"),NA()) | G38: =IFERROR(BDP(Tickers!E7,"PX_LAST")-INDEX(BDH(Tickers!E7,"PX_LAST",EDATE(TODAY(),-1),EDATE(TODAY(),-1)+5,"Days","A","fill","P"),1,2),NA()) | H38: =IFERROR(BDP(Tickers!E7,"PX_LAST")-INDEX(BDH(Tickers!E7,"PX_LAST",DATE(YEAR(TODAY())-1,12,29),DATE(YEAR(TODAY()),1,5),"Days","A","fill","P"),1,2),NA()) | I38: =IFERROR(D38*E38/100,NA())
A39: =Tickers!B8 | B39: =Tickers!C8 | C39: =Tickers!E8 | D39: =Tickers!D8 | E39: =IFERROR(BDP(Tickers!E8,"PX_LAST"),NA()) | F39: =IFERROR(BDP(Tickers!E8,"PX_LAST")-BDP(Tickers!E8,"PX_LAST_DT_PREV_DAY"),NA()) | G39: =IFERROR(BDP(Tickers!E8,"PX_LAST")-INDEX(BDH(Tickers!E8,"PX_LAST",EDATE(TODAY(),-1),EDATE(TODAY(),-1)+5,"Days","A","fill","P"),1,2),NA()) | H39: =IFERROR(BDP(Tickers!E8,"PX_LAST")-INDEX(BDH(Tickers!E8,"PX_LAST",DATE(YEAR(TODAY())-1,12,29),DATE(YEAR(TODAY()),1,5),"Days","A","fill","P"),1,2),NA()) | I39: =IFERROR(D39*E39/100,NA())
A40: =Tickers!B9 | B40: =Tickers!C9 | C40: =Tickers!E9 | D40: =Tickers!D9 | E40: =IFERROR(BDP(Tickers!E9,"PX_LAST"),NA()) | F40: =IFERROR(BDP(Tickers!E9,"PX_LAST")-BDP(Tickers!E9,"PX_LAST_DT_PREV_DAY"),NA()) | G40: =IFERROR(BDP(Tickers!E9,"PX_LAST")-INDEX(BDH(Tickers!E9,"PX_LAST",EDATE(TODAY(),-1),EDATE(TODAY(),-1)+5,"Days","A","fill","P"),1,2),NA()) | H40: =IFERROR(BDP(Tickers!E9,"PX_LAST")-INDEX(BDH(Tickers!E9,"PX_LAST",DATE(YEAR(TODAY())-1,12,29),DATE(YEAR(TODAY()),1,5),"Days","A","fill","P"),1,2),NA()) | I40: =IFERROR(D40*E40/100,NA())
A41: =Tickers!B10 | B41: =Tickers!C10 | C41: =Tickers!E10 | D41: =Tickers!D10 | E41: =IFERROR(BDP(Tickers!E10,"PX_LAST"),NA()) | F41: =IFERROR(BDP(Tickers!E10,"PX_LAST")-BDP(Tickers!E10,"PX_LAST_DT_PREV_DAY"),NA()) | G41: =IFERROR(BDP(Tickers!E10,"PX_LAST")-INDEX(BDH(Tickers!E10,"PX_LAST",EDATE(TODAY(),-1),EDATE(TODAY(),-1)+5,"Days","A","fill","P"),1,2),NA()) | H41: =IFERROR(BDP(Tickers!E10,"PX_LAST")-INDEX(BDH(Tickers!E10,"PX_LAST",DATE(YEAR(TODAY())-1,12,29),DATE(YEAR(TODAY()),1,5),"Days","A","fill","P"),1,2),NA()) | I41: =IFERROR(D41*E41/100,NA())
A42: =Tickers!B11 | B42: =Tickers!C11 | C42: =Tickers!E11 | D42: =Tickers!D11 | E42: =IFERROR(BDP(Tickers!E11,"PX_LAST"),NA()) | F42: =IFERROR(BDP(Tickers!E11,"PX_LAST")-BDP(Tickers!E11,"PX_LAST_DT_PREV_DAY"),NA()) | G42: =IFERROR(BDP(Tickers!E11,"PX_LAST")-INDEX(BDH(Tickers!E11,"PX_LAST",EDATE(TODAY(),-1),EDATE(TODAY(),-1)+5,"Days","A","fill","P"),1,2),NA()) | H42: =IFERROR(BDP(Tickers!E11,"PX_LAST")-INDEX(BDH(Tickers!E11,"PX_LAST",DATE(YEAR(TODAY())-1,12,29),DATE(YEAR(TODAY()),1,5),"Days","A","fill","P"),1,2),NA()) | I42: =IFERROR(D42*E42/100,NA())
A43: =Tickers!B12 | B43: =Tickers!C12 | C43: =Tickers!E12 | D43: =Tickers!D12 | E43: =IFERROR(BDP(Tickers!E12,"PX_LAST"),NA()) | F43: =IFERROR(BDP(Tickers!E12,"PX_LAST")-BDP(Tickers!E12,"PX_LAST_DT_PREV_DAY"),NA()) | G43: =IFERROR(BDP(Tickers!E12,"PX_LAST")-INDEX(BDH(Tickers!E12,"PX_LAST",EDATE(TODAY(),-1),EDATE(TODAY(),-1)+5,"Days","A","fill","P"),1,2),NA()) | H43: =IFERROR(BDP(Tickers!E12,"PX_LAST")-INDEX(BDH(Tickers!E12,"PX_LAST",DATE(YEAR(TODAY())-1,12,29),DATE(YEAR(TODAY()),1,5),"Days","A","fill","P"),1,2),NA()) | I43: =IFERROR(D43*E43/100,NA())
A44: =Tickers!B13 | B44: =Tickers!C13 | C44: =Tickers!E13 | D44: =Tickers!D13 | E44: =IFERROR(BDP(Tickers!E13,"PX_LAST"),NA()) | F44: =IFERROR(BDP(Tickers!E13,"PX_LAST")-BDP(Tickers!E13,"PX_LAST_DT_PREV_DAY"),NA()) | G44: =IFERROR(BDP(Tickers!E13,"PX_LAST")-INDEX(BDH(Tickers!E13,"PX_LAST",EDATE(TODAY(),-1),EDATE(TODAY(),-1)+5,"Days","A","fill","P"),1,2),NA()) | H44: =IFERROR(BDP(Tickers!E13,"PX_LAST")-INDEX(BDH(Tickers!E13,"PX_LAST",DATE(YEAR(TODAY())-1,12,29),DATE(YEAR(TODAY()),1,5),"Days","A","fill","P"),1,2),NA()) | I44: =IFERROR(D44*E44/100,NA())
A45: =Tickers!B14 | B45: =Tickers!C14 | C45: =Tickers!E14 | D45: =Tickers!D14 | E45: =IFERROR(BDP(Tickers!E14,"PX_LAST"),NA()) | F45: =IFERROR(BDP(Tickers!E14,"PX_LAST")-BDP(Tickers!E14,"PX_LAST_DT_PREV_DAY"),NA()) | G45: =IFERROR(BDP(Tickers!E14,"PX_LAST")-INDEX(BDH(Tickers!E14,"PX_LAST",EDATE(TODAY(),-1),EDATE(TODAY(),-1)+5,"Days","A","fill","P"),1,2),NA()) | H45: =IFERROR(BDP(Tickers!E14,"PX_LAST")-INDEX(BDH(Tickers!E14,"PX_LAST",DATE(YEAR(TODAY())-1,12,29),DATE(YEAR(TODAY()),1,5),"Days","A","fill","P"),1,2),NA()) | I45: =IFERROR(D45*E45/100,NA())
A46: =Tickers!B15 | B46: =Tickers!C15 | C46: =Tickers!E15 | D46: =Tickers!D15 | E46: =IFERROR(BDP(Tickers!E15,"PX_LAST"),NA()) | F46: =IFERROR(BDP(Tickers!E15,"PX_LAST")-BDP(Tickers!E15,"PX_LAST_DT_PREV_DAY"),NA()) | G46: =IFERROR(BDP(Tickers!E15,"PX_LAST")-INDEX(BDH(Tickers!E15,"PX_LAST",EDATE(TODAY(),-1),EDATE(TODAY(),-1)+5,"Days","A","fill","P"),1,2),NA()) | H46: =IFERROR(BDP(Tickers!E15,"PX_LAST")-INDEX(BDH(Tickers!E15,"PX_LAST",DATE(YEAR(TODAY())-1,12,29),DATE(YEAR(TODAY()),1,5),"Days","A","fill","P"),1,2),NA()) | I46: =IFERROR(D46*E46/100,NA())
A47: =Tickers!B16 | B47: =Tickers!C16 | C47: =Tickers!E16 | D47: =Tickers!D16 | E47: =IFERROR(BDP(Tickers!E16,"PX_LAST"),NA()) | F47: =IFERROR(BDP(Tickers!E16,"PX_LAST")-BDP(Tickers!E16,"PX_LAST_DT_PREV_DAY"),NA()) | G47: =IFERROR(BDP(Tickers!E16,"PX_LAST")-INDEX(BDH(Tickers!E16,"PX_LAST",EDATE(TODAY(),-1),EDATE(TODAY(),-1)+5,"Days","A","fill","P"),1,2),NA()) | H47: =IFERROR(BDP(Tickers!E16,"PX_LAST")-INDEX(BDH(Tickers!E16,"PX_LAST",DATE(YEAR(TODAY())-1,12,29),DATE(YEAR(TODAY()),1,5),"Days","A","fill","P"),1,2),NA()) | I47: =IFERROR(D47*E47/100,NA())
A48: =Tickers!B17 | B48: =Tickers!C17 | C48: =Tickers!E17 | D48: =Tickers!D17 | E48: =IFERROR(BDP(Tickers!E17,"PX_LAST"),NA()) | F48: =IFERROR(BDP(Tickers!E17,"PX_LAST")-BDP(Tickers!E17,"PX_LAST_DT_PREV_DAY"),NA()) | G48: =IFERROR(BDP(Tickers!E17,"PX_LAST")-INDEX(BDH(Tickers!E17,"PX_LAST",EDATE(TODAY(),-1),EDATE(TODAY(),-1)+5,"Days","A","fill","P"),1,2),NA()) | H48: =IFERROR(BDP(Tickers!E17,"PX_LAST")-INDEX(BDH(Tickers!E17,"PX_LAST",DATE(YEAR(TODAY())-1,12,29),DATE(YEAR(TODAY()),1,5),"Days","A","fill","P"),1,2),NA()) | I48: =IFERROR(D48*E48/100,NA())
... A52: =Tickers!B21 | B52: =Tickers!C21 | C52: =Tickers!E21 | D52: =Tickers!D21 | E52: =IFERROR(BDP(Tickers!E21,"PX_LAST"),NA()) | F52: =IFERROR(BDP(Tickers!E21,"PX_LAST")-BDP(Tickers!E21,"PX_LAST_DT_PREV_DAY"),NA()) | G52: =IFERROR(BDP(Tickers!E21,"PX_LAST")-INDEX(BDH(Tickers!E21,"PX_LAST",EDATE(TODAY(),-1),EDATE(TODAY(),-1)+5,"Days","A","fill","P"),1,2),NA()) | H52: =IFERROR(BDP(Tickers!E21,"PX_LAST")-INDEX(BDH(Tickers!E21,"PX_LAST",DATE(YEAR(TODAY())-1,12,29),DATE(YEAR(TODAY()),1,5),"Days","A","fill","P"),1,2),NA()) | I52: =IFERROR(D52*E52/100,NA())
A53: ="LatAm subtotal" | D53: =SUM(D37:D52) | E53: =SUMPRODUCT(D37:D52,E37:E52)/SUM(D37:D52) | I53: =SUM(I37:I52)
A55: EM Europe & Turkey
A56: =Tickers!B22 | B56: =Tickers!C22 | C56: =Tickers!E22 | D56: =Tickers!D22 | E56: =IFERROR(BDP(Tickers!E22,"PX_LAST"),NA()) | F56: =IFERROR(BDP(Tickers!E22,"PX_LAST")-BDP(Tickers!E22,"PX_LAST_DT_PREV_DAY"),NA()) | G56: =IFERROR(BDP(Tickers!E22,"PX_LAST")-INDEX(BDH(Tickers!E22,"PX_LAST",EDATE(TODAY(),-1),EDATE(TODAY(),-1)+5,"Days","A","fill","P"),1,2),NA()) | H56: =IFERROR(BDP(Tickers!E22,"PX_LAST")-INDEX(BDH(Tickers!E22,"PX_LAST",DATE(YEAR(TODAY())-1,12,29),DATE(YEAR(TODAY()),1,5),"Days","A","fill","P"),1,2),NA()) | I56: =IFERROR(D56*E56/100,NA())
A57: =Tickers!B23 | B57: =Tickers!C23 | C57: =Tickers!E23 | D57: =Tickers!D23 | E57: =IFERROR(BDP(Tickers!E23,"PX_LAST"),NA()) | F57: =IFERROR(BDP(Tickers!E23,"PX_LAST")-BDP(Tickers!E23,"PX_LAST_DT_PREV_DAY"),NA()) | G57: =IFERROR(BDP(Tickers!E23,"PX_LAST")-INDEX(BDH(Tickers!E23,"PX_LAST",EDATE(TODAY(),-1),EDATE(TODAY(),-1)+5,"Days","A","fill","P"),1,2),NA()) | H57: =IFERROR(BDP(Tickers!E23,"PX_LAST")-INDEX(BDH(Tickers!E23,"PX_LAST",DATE(YEAR(TODAY())-1,12,29),DATE(YEAR(TODAY()),1,5),"Days","A","fill","P"),1,2),NA()) | I57: =IFERROR(D57*E57/100,NA())
A58: =Tickers!B24 | B58: =Tickers!C24 | C58: =Tickers!E24 | D58: =Tickers!D24 | E58: =IFERROR(BDP(Tickers!E24,"PX_LAST"),NA()) | F58: =IFERROR(BDP(Tickers!E24,"PX_LAST")-BDP(Tickers!E24,"PX_LAST_DT_PREV_DAY"),NA()) | G58: =IFERROR(BDP(Tickers!E24,"PX_LAST")-INDEX(BDH(Tickers!E24,"PX_LAST",EDATE(TODAY(),-1),EDATE(TODAY(),-1)+5,"Days","A","fill","P"),1,2),NA()) | H58: =IFERROR(BDP(Tickers!E24,"PX_LAST")-INDEX(BDH(Tickers!E24,"PX_LAST",DATE(YEAR(TODAY())-1,12,29),DATE(YEAR(TODAY()),1,5),"Days","A","fill","P"),1,2),NA()) | I58: =IFERROR(D58*E58/100,NA())
A59: =Tickers!B25 | B59: =Tickers!C25 | C59: =Tickers!E25 | D59: =Tickers!D25 | E59: =IFERROR(BDP(Tickers!E25,"PX_LAST"),NA()) | F59: =IFERROR(BDP(Tickers!E25,"PX_LAST")-BDP(Tickers!E25,"PX_LAST_DT_PREV_DAY"),NA()) | G59: =IFERROR(BDP(Tickers!E25,"PX_LAST")-INDEX(BDH(Tickers!E25,"PX_LAST",EDATE(TODAY(),-1),EDATE(TODAY(),-1)+5,"Days","A","fill","P"),1,2),NA()) | H59: =IFERROR(BDP(Tickers!E25,"PX_LAST")-INDEX(BDH(Tickers!E25,"PX_LAST",DATE(YEAR(TODAY())-1,12,29),DATE(YEAR(TODAY()),1,5),"Days","A","fill","P"),1,2),NA()) | I59: =IFERROR(D59*E59/100,NA())
A60: =Tickers!B26 | B60: =Tickers!C26 | C60: =Tickers!E26 | D60: =Tickers!D26 | E60: =IFERROR(BDP(Tickers!E26,"PX_LAST"),NA()) | F60: =IFERROR(BDP(Tickers!E26,"PX_LAST")-BDP(Tickers!E26,"PX_LAST_DT_PREV_DAY"),NA()) | G60: =IFERROR(BDP(Tickers!E26,"PX_LAST")-INDEX(BDH(Tickers!E26,"PX_LAST",EDATE(TODAY(),-1),EDATE(TODAY(),-1)+5,"Days","A","fill","P"),1,2),NA()) | H60: =IFERROR(BDP(Tickers!E26,"PX_LAST")-INDEX(BDH(Tickers!E26,"PX_LAST",DATE(YEAR(TODAY())-1,12,29),DATE(YEAR(TODAY()),1,5),"Days","A","fill","P"),1,2),NA()) | I60: =IFERROR(D60*E60/100,NA())
A61: =Tickers!B27 | B61: =Tickers!C27 | C61: =Tickers!E27 | D61: =Tickers!D27 | E61: =IFERROR(BDP(Tickers!E27,"PX_LAST"),NA()) | F61: =IFERROR(BDP(Tickers!E27,"PX_LAST")-BDP(Tickers!E27,"PX_LAST_DT_PREV_DAY"),NA()) | G61: =IFERROR(BDP(Tickers!E27,"PX_LAST")-INDEX(BDH(Tickers!E27,"PX_LAST",EDATE(TODAY(),-1),EDATE(TODAY(),-1)+5,"Days","A","fill","P"),1,2),NA()) | H61: =IFERROR(BDP(Tickers!E27,"PX_LAST")-INDEX(BDH(Tickers!E27,"PX_LAST",DATE(YEAR(TODAY())-1,12,29),DATE(YEAR(TODAY()),1,5),"Days","A","fill","P"),1,2),NA()) | I61: =IFERROR(D61*E61/100,NA())
A62: =Tickers!B28 | B62: =Tickers!C28 | C62: =Tickers!E28 | D62: =Tickers!D28 | E62: =IFERROR(BDP(Tickers!E28,"PX_LAST"),NA()) | F62: =IFERROR(BDP(Tickers!E28,"PX_LAST")-BDP(Tickers!E28,"PX_LAST_DT_PREV_DAY"),NA()) | G62: =IFERROR(BDP(Tickers!E28,"PX_LAST")-INDEX(BDH(Tickers!E28,"PX_LAST",EDATE(TODAY(),-1),EDATE(TODAY(),-1)+5,"Days","A","fill","P"),1,2),NA()) | H62: =IFERROR(BDP(Tickers!E28,"PX_LAST")-INDEX(BDH(Tickers!E28,"PX_LAST",DATE(YEAR(TODAY())-1,12,29),DATE(YEAR(TODAY()),1,5),"Days","A","fill","P"),1,2),NA()) | I62: =IFERROR(D62*E62/100,NA())
A63: =Tickers!B29 | B63: =Tickers!C29 | C63: =Tickers!E29 | D63: =Tickers!D29 | E63: =IFERROR(BDP(Tickers!E29,"PX_LAST"),NA()) | F63: =IFERROR(BDP(Tickers!E29,"PX_LAST")-BDP(Tickers!E29,"PX_LAST_DT_PREV_DAY"),NA()) | G63: =IFERROR(BDP(Tickers!E29,"PX_LAST")-INDEX(BDH(Tickers!E29,"PX_LAST",EDATE(TODAY(),-1),EDATE(TODAY(),-1)+5,"Days","A","fill","P"),1,2),NA()) | H63: =IFERROR(BDP(Tickers!E29,"PX_LAST")-INDEX(BDH(Tickers!E29,"PX_LAST",DATE(YEAR(TODAY())-1,12,29),DATE(YEAR(TODAY()),1,5),"Days","A","fill","P"),1,2),NA()) | I63: =IFERROR(D63*E63/100,NA())
A64: =Tickers!B30 | B64: =Tickers!C30 | C64: =Tickers!E30 | D64: =Tickers!D30 | E64: =IFERROR(BDP(Tickers!E30,"PX_LAST"),NA()) | F64: =IFERROR(BDP(Tickers!E30,"PX_LAST")-BDP(Tickers!E30,"PX_LAST_DT_PREV_DAY"),NA()) | G64: =IFERROR(BDP(Tickers!E30,"PX_LAST")-INDEX(BDH(Tickers!E30,"PX_LAST",EDATE(TODAY(),-1),EDATE(TODAY(),-1)+5,"Days","A","fill","P"),1,2),NA()) | H64: =IFERROR(BDP(Tickers!E30,"PX_LAST")-INDEX(BDH(Tickers!E30,"PX_LAST",DATE(YEAR(TODAY())-1,12,29),DATE(YEAR(TODAY()),1,5),"Days","A","fill","P"),1,2),NA()) | I64: =IFERROR(D64*E64/100,NA())
A65: =Tickers!B31 | B65: =Tickers!C31 | C65: =Tickers!E31 | D65: =Tickers!D31 | E65: =IFERROR(BDP(Tickers!E31,"PX_LAST"),NA()) | F65: =IFERROR(BDP(Tickers!E31,"PX_LAST")-BDP(Tickers!E31,"PX_LAST_DT_PREV_DAY"),NA()) | G65: =IFERROR(BDP(Tickers!E31,"PX_LAST")-INDEX(BDH(Tickers!E31,"PX_LAST",EDATE(TODAY(),-1),EDATE(TODAY(),-1)+5,"Days","A","fill","P"),1,2),NA()) | H65: =IFERROR(BDP(Tickers!E31,"PX_LAST")-INDEX(BDH(Tickers!E31,"PX_LAST",DATE(YEAR(TODAY())-1,12,29),DATE(YEAR(TODAY()),1,5),"Days","A","fill","P"),1,2),NA()) | I65: =IFERROR(D65*E65/100,NA())
A66: =Tickers!B32 | B66: =Tickers!C32 | C66: =Tickers!E32 | D66: =Tickers!D32 | E66: =IFERROR(BDP(Tickers!E32,"PX_LAST"),NA()) | F66: =IFERROR(BDP(Tickers!E32,"PX_LAST")-BDP(Tickers!E32,"PX_LAST_DT_PREV_DAY"),NA()) | G66: =IFERROR(BDP(Tickers!E32,"PX_LAST")-INDEX(BDH(Tickers!E32,"PX_LAST",EDATE(TODAY(),-1),EDATE(TODAY(),-1)+5,"Days","A","fill","P"),1,2),NA()) | H66: =IFERROR(BDP(Tickers!E32,"PX_LAST")-INDEX(BDH(Tickers!E32,"PX_LAST",DATE(YEAR(TODAY())-1,12,29),DATE(YEAR(TODAY()),1,5),"Days","A","fill","P"),1,2),NA()) | I66: =IFERROR(D66*E66/100,NA())
A67: ="EM Europe & Turkey subtotal" | D67: =SUM(D56:D66) | E67: =SUMPRODUCT(D56:D66,E56:E66)/SUM(D56:D66) | I67: =SUM(I56:I66)
A69: GCC
A70: =Tickers!B33 | B70: =Tickers!C33 | C70: =Tickers!E33 | D70: =Tickers!D33 | E70: =IFERROR(BDP(Tickers!E33,"PX_LAST"),NA()) | F70: =IFERROR(BDP(Tickers!E33,"PX_LAST")-BDP(Tickers!E33,"PX_LAST_DT_PREV_DAY"),NA()) | G70: =IFERROR(BDP(Tickers!E33,"PX_LAST")-INDEX(BDH(Tickers!E33,"PX_LAST",EDATE(TODAY(),-1),EDATE(TODAY(),-1)+5,"Days","A","fill","P"),1,2),NA()) | H70: =IFERROR(BDP(Tickers!E33,"PX_LAST")-INDEX(BDH(Tickers!E33,"PX_LAST",DATE(YEAR(TODAY())-1,12,29),DATE(YEAR(TODAY()),1,5),"Days","A","fill","P"),1,2),NA()) | I70: =IFERROR(D70*E70/100,NA())
A71: =Tickers!B34 | B71: =Tickers!C34 | C71: =Tickers!E34 | D71: =Tickers!D34 | E71: =IFERROR(BDP(Tickers!E34,"PX_LAST"),NA()) | F71: =IFERROR(BDP(Tickers!E34,"PX_LAST")-BDP(Tickers!E34,"PX_LAST_DT_PREV_DAY"),NA()) | G71: =IFERROR(BDP(Tickers!E34,"PX_LAST")-INDEX(BDH(Tickers!E34,"PX_LAST",EDATE(TODAY(),-1),EDATE(TODAY(),-1)+5,"Days","A","fill","P"),1,2),NA()) | H71: =IFERROR(BDP(Tickers!E34,"PX_LAST")-INDEX(BDH(Tickers!E34,"PX_LAST",DATE(YEAR(TODAY())-1,12,29),DATE(YEAR(TODAY()),1,5),"Days","A","fill","P"),1,2),NA()) | I71: =IFERROR(D71*E71/100,NA())
A72: =Tickers!B35 | B72: =Tickers!C35 | C72: =Tickers!E35 | D72: =Tickers!D35 | E72: =IFERROR(BDP(Tickers!E35,"PX_LAST"),NA()) | F72: =IFERROR(BDP(Tickers!E35,"PX_LAST")-BDP(Tickers!E35,"PX_LAST_DT_PREV_DAY"),NA()) | G72: =IFERROR(BDP(Tickers!E35,"PX_LAST")-INDEX(BDH(Tickers!E35,"PX_LAST",EDATE(TODAY(),-1),EDATE(TODAY(),-1)+5,"Days","A","fill","P"),1,2),NA()) | H72: =IFERROR(BDP(Tickers!E35,"PX_LAST")-INDEX(BDH(Tickers!E35,"PX_LAST",DATE(YEAR(TODAY())-1,12,29),DATE(YEAR(TODAY()),1,5),"Days","A","fill","P"),1,2),NA()) | I72: =IFERROR(D72*E72/100,NA())
A73: =Tickers!B36 | B73: =Tickers!C36 | C73: =Tickers!E36 | D73: =Tickers!D36 | E73: =IFERROR(BDP(Tickers!E36,"PX_LAST"),NA()) | F73: =IFERROR(BDP(Tickers!E36,"PX_LAST")-BDP(Tickers!E36,"PX_LAST_DT_PREV_DAY"),NA()) | G73: =IFERROR(BDP(Tickers!E36,"PX_LAST")-INDEX(BDH(Tickers!E36,"PX_LAST",EDATE(TODAY(),-1),EDATE(TODAY(),-1)+5,"Days","A","fill","P"),1,2),NA()) | H73: =IFERROR(BDP(Tickers!E36,"PX_LAST")-INDEX(BDH(Tickers!E36,"PX_LAST",DATE(YEAR(TODAY())-1,12,29),DATE(YEAR(TODAY()),1,5),"Days","A","fill","P"),1,2),NA()) | I73: =IFERROR(D73*E73/100,NA())
A74: =Tickers!B37 | B74: =Tickers!C37 | C74: =Tickers!E37 | D74: =Tickers!D37 | E74: =IFERROR(BDP(Tickers!E37,"PX_LAST"),NA()) | F74: =IFERROR(BDP(Tickers!E37,"PX_LAST")-BDP(Tickers!E37,"PX_LAST_DT_PREV_DAY"),NA()) | G74: =IFERROR(BDP(Tickers!E37,"PX_LAST")-INDEX(BDH(Tickers!E37,"PX_LAST",EDATE(TODAY(),-1),EDATE(TODAY(),-1)+5,"Days","A","fill","P"),1,2),NA()) | H74: =IFERROR(BDP(Tickers!E37,"PX_LAST")-INDEX(BDH(Tickers!E37,"PX_LAST",DATE(YEAR(TODAY())-1,12,29),DATE(YEAR(TODAY()),1,5),"Days","A","fill","P"),1,2),NA()) | I74: =IFERROR(D74*E74/100,NA())
...

Sheet Total Return
A1: EMBI Global Diversified — Total Return Analysis
A2: Total returns from JPM total-return sub-indices. MTD / QTD / YTD / 1Y / 3Y per country and aggregate.
A4: Country | B4: Region | C4: TR ticker | D4: Weight (%) | E4: Latest level | F4: MTD % | G4: QTD % | H4: YTD % | I4: 1Y % | J4: 3Y %
A5: =Tickers!B5 | B5: =Tickers!C5 | C5: =Tickers!F5 | D5: =Tickers!D5 | E5: =IFERROR(BDP(Tickers!F5,"PX_LAST"),NA()) | F5: =IFERROR(BDP(Tickers!F5,"PX_LAST")/INDEX(BDH(Tickers!F5,"PX_LAST",EOMONTH(TODAY(),-1),EOMONTH(TODAY(),-1)+5,"Days","A","fill","P"),1,2)-1,NA()) | G5: =IFERROR(BDP(Tickers!F5,"PX_LAST")/INDEX(BDH(Tickers!F5,"PX_LAST",DATE(YEAR(TODAY()),(INT((MONTH(TODAY())-1)/3))*3+1,1)-1,DATE(YEAR(TODAY()),(INT((MONTH(TODAY())-1)/3))*3+1,1)-1+5,"Days","A","fill","P"),1,2)-1,NA()) | H5: =IFERROR(BDP(Tickers!F5,"PX_LAST")/INDEX(BDH(Tickers!F5,"PX_LAST",DATE(YEAR(TODAY())-1,12,31),DATE(YEAR(TODAY())-1,12,31)+5,"Days","A","fill","P"),1,2)-1,NA()) | I5: =IFERROR(BDP(Tickers!F5,"PX_LAST")/INDEX(BDH(Tickers!F5,"PX_LAST",EDATE(TODAY(),-12),EDATE(TODAY(),-12)+5,"Days","A","fill","P"),1,2)-1,NA()) | J5: =IFERROR(BDP(Tickers!F5,"PX_LAST")/INDEX(BDH(Tickers!F5,"PX_LAST",EDATE(TODAY(),-36),EDATE(TODAY(),-36)+5,"Days","A","fill","P"),1,2)-1,NA())
A7: LatAm
A8: =Tickers!B6 | B8: =Tickers!C6 | C8: =Tickers!F6 | D8: =Tickers!D6 | E8: =IFERROR(BDP(Tickers!F6,"PX_LAST"),NA()) | F8: =IFERROR(BDP(Tickers!F6,"PX_LAST")/INDEX(BDH(Tickers!F6,"PX_LAST",EOMONTH(TODAY(),-1),EOMONTH(TODAY(),-1)+5,"Days","A","fill","P"),1,2)-1,NA()) | G8: =IFERROR(BDP(Tickers!F6,"PX_LAST")/INDEX(BDH(Tickers!F6,"PX_LAST",DATE(YEAR(TODAY()),(INT((MONTH(TODAY())-1)/3))*3+1,1)-1,DATE(YEAR(TODAY()),(INT((MONTH(TODAY())-1)/3))*3+1,1)-1+5,"Days","A","fill","P"),1,2)-1,NA()) | H8: =IFERROR(BDP(Tickers!F6,"PX_LAST")/INDEX(BDH(Tickers!F6,"PX_LAST",DATE(YEAR(TODAY())-1,12,31),DATE(YEAR(TODAY())-1,12,31)+5,"Days","A","fill","P"),1,2)-1,NA()) | I8: =IFERROR(BDP(Tickers!F6,"PX_LAST")/INDEX(BDH(Tickers!F6,"PX_LAST",EDATE(TODAY(),-12),EDATE(TODAY(),-12)+5,"Days","A","fill","P"),1,2)-1,NA()) | J8: =IFERROR(BDP(Tickers!F6,"PX_LAST")/INDEX(BDH(Tickers!F6,"PX_LAST",EDATE(TODAY(),-36),EDATE(TODAY(),-36)+5,"Days","A","fill","P"),1,2)-1,NA())
A9: =Tickers!B7 | B9: =Tickers!C7 | C9: =Tickers!F7 | D9: =Tickers!D7 | E9: =IFERROR(BDP(Tickers!F7,"PX_LAST"),NA()) | F9: =IFERROR(BDP(Tickers!F7,"PX_LAST")/INDEX(BDH(Tickers!F7,"PX_LAST",EOMONTH(TODAY(),-1),EOMONTH(TODAY(),-1)+5,"Days","A","fill","P"),1,2)-1,NA()) | G9: =IFERROR(BDP(Tickers!F7,"PX_LAST")/INDEX(BDH(Tickers!F7,"PX_LAST",DATE(YEAR(TODAY()),(INT((MONTH(TODAY())-1)/3))*3+1,1)-1,DATE(YEAR(TODAY()),(INT((MONTH(TODAY())-1)/3))*3+1,1)-1+5,"Days","A","fill","P"),1,2)-1,NA()) | H9: =IFERROR(BDP(Tickers!F7,"PX_LAST")/INDEX(BDH(Tickers!F7,"PX_LAST",DATE(YEAR(TODAY())-1,12,31),DATE(YEAR(TODAY())-1,12,31)+5,"Days","A","fill","P"),1,2)-1,NA()) | I9: =IFERROR(BDP(Tickers!F7,"PX_LAST")/INDEX(BDH(Tickers!F7,"PX_LAST",EDATE(TODAY(),-12),EDATE(TODAY(),-12)+5,"Days","A","fill","P"),1,2)-1,NA()) | J9: =IFERROR(BDP(Tickers!F7,"PX_LAST")/INDEX(BDH(Tickers!F7,"PX_LAST",EDATE(TODAY(),-36),EDATE(TODAY(),-36)+5,"Days","A","fill","P"),1,2)-1,NA())
A10: =Tickers!B8 | B10: =Tickers!C8 | C10: =Tickers!F8 | D10: =Tickers!D8 | E10: =IFERROR(BDP(Tickers!F8,"PX_LAST"),NA()) | F10: =IFERROR(BDP(Tickers!F8,"PX_LAST")/INDEX(BDH(Tickers!F8,"PX_LAST",EOMONTH(TODAY(),-1),EOMONTH(TODAY(),-1)+5,"Days","A","fill","P"),1,2)-1,NA()) | G10: =IFERROR(BDP(Tickers!F8,"PX_LAST")/INDEX(BDH(Tickers!F8,"PX_LAST",DATE(YEAR(TODAY()),(INT((MONTH(TODAY())-1)/3))*3+1,1)-1,DATE(YEAR(TODAY()),(INT((MONTH(TODAY())-1)/3))*3+1,1)-1+5,"Days","A","fill","P"),1,2)-1,NA()) | H10: =IFERROR(BDP(Tickers!F8,"PX_LAST")/INDEX(BDH(Tickers!F8,"PX_LAST",DATE(YEAR(TODAY())-1,12,31),DATE(YEAR(TODAY())-1,12,31)+5,"Days","A","fill","P"),1,2)-1,NA()) | I10: =IFERROR(BDP(Tickers!F8,"PX_LAST")/INDEX(BDH(Tickers!F8,"PX_LAST",EDATE(TODAY(),-12),EDATE(TODAY(),-12)+5,"Days","A","fill","P"),1,2)-1,NA()) | J10: =IFERROR(BDP(Tickers!F8,"PX_LAST")/INDEX(BDH(Tickers!F8,"PX_LAST",EDATE(TODAY(),-36),EDATE(TODAY(),-36)+5,"Days","A","fill","P"),1,2)-1,NA())
A11: =Tickers!B9 | B11: =Tickers!C9 | C11: =Tickers!F9 | D11: =Tickers!D9 | E11: =IFERROR(BDP(Tickers!F9,"PX_LAST"),NA()) | F11: =IFERROR(BDP(Tickers!F9,"PX_LAST")/INDEX(BDH(Tickers!F9,"PX_LAST",EOMONTH(TODAY(),-1),EOMONTH(TODAY(),-1)+5,"Days","A","fill","P"),1,2)-1,NA()) | G11: =IFERROR(BDP(Tickers!F9,"PX_LAST")/INDEX(BDH(Tickers!F9,"PX_LAST",DATE(YEAR(TODAY()),(INT((MONTH(TODAY())-1)/3))*3+1,1)-1,DATE(YEAR(TODAY()),(INT((MONTH(TODAY())-1)/3))*3+1,1)-1+5,"Days","A","fill","P"),1,2)-1,NA()) | H11: =IFERROR(BDP(Tickers!F9,"PX_LAST")/INDEX(BDH(Tickers!F9,"PX_LAST",DATE(YEAR(TODAY())-1,12,31),DATE(YEAR(TODAY())-1,12,31)+5,"Days","A","fill","P"),1,2)-1,NA()) | I11: =IFERROR(BDP(Tickers!F9,"PX_LAST")/INDEX(BDH(Tickers!F9,"PX_LAST",EDATE(TODAY(),-12),EDATE(TODAY(),-12)+5,"Days","A","fill","P"),1,2)-1,NA()) | J11: =IFERROR(BDP(Tickers!F9,"PX_LAST")/INDEX(BDH(Tickers!F9,"PX_LAST",EDATE(TODAY(),-36),EDATE(TODAY(),-36)+5,"Days","A","fill","P"),1,2)-1,NA())
A12: =Tickers!B10 | B12: =Tickers!C10 | C12: =Tickers!F10 | D12: =Tickers!D10 | E12: =IFERROR(BDP(Tickers!F10,"PX_LAST"),NA()) | F12: =IFERROR(BDP(Tickers!F10,"PX_LAST")/INDEX(BDH(Tickers!F10,"PX_LAST",EOMONTH(TODAY(),-1),EOMONTH(TODAY(),-1)+5,"Days","A","fill","P"),1,2)-1,NA()) | G12: =IFERROR(BDP(Tickers!F10,"PX_LAST")/INDEX(BDH(Tickers!F10,"PX_LAST",DATE(YEAR(TODAY()),(INT((MONTH(TODAY())-1)/3))*3+1,1)-1,DATE(YEAR(TODAY()),(INT((MONTH(TODAY())-1)/3))*3+1,1)-1+5,"Days","A","fill","P"),1,2)-1,NA()) | H12: =IFERROR(BDP(Tickers!F10,"PX_LAST")/INDEX(BDH(Tickers!F10,"PX_LAST",DATE(YEAR(TODAY())-1,12,31),DATE(YEAR(TODAY())-1,12,31)+5,"Days","A","fill","P"),1,2)-1,NA()) | I12: =IFERROR(BDP(Tickers!F10,"PX_LAST")/INDEX(BDH(Tickers!F10,"PX_LAST",EDATE(TODAY(),-12),EDATE(TODAY(),-12)+5,"Days","A","fill","P"),1,2)-1,NA()) | J12: =IFERROR(BDP(Tickers!F10,"PX_LAST")/INDEX(BDH(Tickers!F10,"PX_LAST",EDATE(TODAY(),-36),EDATE(TODAY(),-36)+5,"Days","A","fill","P"),1,2)-1,NA())
A13: =Tickers!B11 | B13: =Tickers!C11 | C13: =Tickers!F11 | D13: =Tickers!D11 | E13: =IFERROR(BDP(Tickers!F11,"PX_LAST"),NA()) | F13: =IFERROR(BDP(Tickers!F11,"PX_LAST")/INDEX(BDH(Tickers!F11,"PX_LAST",EOMONTH(TODAY(),-1),EOMONTH(TODAY(),-1)+5,"Days","A","fill","P"),1,2)-1,NA()) | G13: =IFERROR(BDP(Tickers!F11,"PX_LAST")/INDEX(BDH(Tickers!F11,"PX_LAST",DATE(YEAR(TODAY()),(INT((MONTH(TODAY())-1)/3))*3+1,1)-1,DATE(YEAR(TODAY()),(INT((MONTH(TODAY())-1)/3))*3+1,1)-1+5,"Days","A","fill","P"),1,2)-1,NA()) | H13: =IFERROR(BDP(Tickers!F11,"PX_LAST")/INDEX(BDH(Tickers!F11,"PX_LAST",DATE(YEAR(TODAY())-1,12,31),DATE(YEAR(TODAY())-1,12,31)+5,"Days","A","fill","P"),1,2)-1,NA()) | I13: =IFERROR(BDP(Tickers!F11,"PX_LAST")/INDEX(BDH(Tickers!F11,"PX_LAST",EDATE(TODAY(),-12),EDATE(TODAY(),-12)+5,"Days","A","fill","P"),1,2)-1,NA()) | J13: =IFERROR(BDP(Tickers!F11,"PX_LAST")/INDEX(BDH(Tickers!F11,"PX_LAST",EDATE(TODAY(),-36),EDATE(TODAY(),-36)+5,"Days","A","fill","P"),1,2)-1,NA())
A14: =Tickers!B12 | B14: =Tickers!C12 | C14: =Tickers!F12 | D14: =Tickers!D12 | E14: =IFERROR(BDP(Tickers!F12,"PX_LAST"),NA()) | F14: =IFERROR(BDP(Tickers!F12,"PX_LAST")/INDEX(BDH(Tickers!F12,"PX_LAST",EOMONTH(TODAY(),-1),EOMONTH(TODAY(),-1)+5,"Days","A","fill","P"),1,2)-1,NA()) | G14: =IFERROR(BDP(Tickers!F12,"PX_LAST")/INDEX(BDH(Tickers!F12,"PX_LAST",DATE(YEAR(TODAY()),(INT((MONTH(TODAY())-1)/3))*3+1,1)-1,DATE(YEAR(TODAY()),(INT((MONTH(TODAY())-1)/3))*3+1,1)-1+5,"Days","A","fill","P"),1,2)-1,NA()) | H14: =IFERROR(BDP(Tickers!F12,"PX_LAST")/INDEX(BDH(Tickers!F12,"PX_LAST",DATE(YEAR(TODAY())-1,12,31),DATE(YEAR(TODAY())-1,12,31)+5,"Days","A","fill","P"),1,2)-1,NA()) | I14: =IFERROR(BDP(Tickers!F12,"PX_LAST")/INDEX(BDH(Tickers!F12,"PX_LAST",EDATE(TODAY(),-12),EDATE(TODAY(),-12)+5,"Days","A","fill","P"),1,2)-1,NA()) | J14: =IFERROR(BDP(Tickers!F12,"PX_LAST")/INDEX(BDH(Tickers!F12,"PX_LAST",EDATE(TODAY(),-36),EDATE(TODAY(),-36)+5,"Days","A","fill","P"),1,2)-1,NA())
A15: =Tickers!B13 | B15: =Tickers!C13 | C15: =Tickers!F13 | D15: =Tickers!D13 | E15: =IFERROR(BDP(Tickers!F13,"PX_LAST"),NA()) | F15: =IFERROR(BDP(Tickers!F13,"PX_LAST")/INDEX(BDH(Tickers!F13,"PX_LAST",EOMONTH(TODAY(),-1),EOMONTH(TODAY(),-1)+5,"Days","A","fill","P"),1,2)-1,NA()) | G15: =IFERROR(BDP(Tickers!F13,"PX_LAST")/INDEX(BDH(Tickers!F13,"PX_LAST",DATE(YEAR(TODAY()),(INT((MONTH(TODAY())-1)/3))*3+1,1)-1,DATE(YEAR(TODAY()),(INT((MONTH(TODAY())-1)/3))*3+1,1)-1+5,"Days","A","fill","P"),1,2)-1,NA()) | H15: =IFERROR(BDP(Tickers!F13,"PX_LAST")/INDEX(BDH(Tickers!F13,"PX_LAST",DATE(YEAR(TODAY())-1,12,31),DATE(YEAR(TODAY())-1,12,31)+5,"Days","A","fill","P"),1,2)-1,NA()) | I15: =IFERROR(BDP(Tickers!F13,"PX_LAST")/INDEX(BDH(Tickers!F13,"PX_LAST",EDATE(TODAY(),-12),EDATE(TODAY(),-12)+5,"Days","A","fill","P"),1,2)-1,NA()) | J15: =IFERROR(BDP(Tickers!F13,"PX_LAST")/INDEX(BDH(Tickers!F13,"PX_LAST",EDATE(TODAY(),-36),EDATE(TODAY(),-36)+5,"Days","A","fill","P"),1,2)-1,NA())
A16: =Tickers!B14 | B16: =Tickers!C14 | C16: =Tickers!F14 | D16: =Tickers!D14 | E16: =IFERROR(BDP(Tickers!F14,"PX_LAST"),NA()) | F16: =IFERROR(BDP(Tickers!F14,"PX_LAST")/INDEX(BDH(Tickers!F14,"PX_LAST",EOMONTH(TODAY(),-1),EOMONTH(TODAY(),-1)+5,"Days","A","fill","P"),1,2)-1,NA()) | G16: =IFERROR(BDP(Tickers!F14,"PX_LAST")/INDEX(BDH(Tickers!F14,"PX_LAST",DATE(YEAR(TODAY()),(INT((MONTH(TODAY())-1)/3))*3+1,1)-1,DATE(YEAR(TODAY()),(INT((MONTH(TODAY())-1)/3))*3+1,1)-1+5,"Days","A","fill","P"),1,2)-1,NA()) | H16: =IFERROR(BDP(Tickers!F14,"PX_LAST")/INDEX(BDH(Tickers!F14,"PX_LAST",DATE(YEAR(TODAY())-1,12,31),DATE(YEAR(TODAY())-1,12,31)+5,"Days","A","fill","P"),1,2)-1,NA()) | I16: =IFERROR(BDP(Tickers!F14,"PX_LAST")/INDEX(BDH(Tickers!F14,"PX_LAST",EDATE(TODAY(),-12),EDATE(TODAY(),-12)+5,"Days","A","fill","P"),1,2)-1,NA()) | J16: =IFERROR(BDP(Tickers!F14,"PX_LAST")/INDEX(BDH(Tickers!F14,"PX_LAST",EDATE(TODAY(),-36),EDATE(TODAY(),-36)+5,"Days","A","fill","P"),1,2)-1,NA())
A17: =Tickers!B15 | B17: =Tickers!C15 | C17: =Tickers!F15 | D17: =Tickers!D15 | E17: =IFERROR(BDP(Tickers!F15,"PX_LAST"),NA()) | F17: =IFERROR(BDP(Tickers!F15,"PX_LAST")/INDEX(BDH(Tickers!F15,"PX_LAST",EOMONTH(TODAY(),-1),EOMONTH(TODAY(),-1)+5,"Days","A","fill","P"),1,2)-1,NA()) | G17: =IFERROR(BDP(Tickers!F15,"PX_LAST")/INDEX(BDH(Tickers!F15,"PX_LAST",DATE(YEAR(TODAY()),(INT((MONTH(TODAY())-1)/3))*3+1,1)-1,DATE(YEAR(TODAY()),(INT((MONTH(TODAY())-1)/3))*3+1,1)-1+5,"Days","A","fill","P"),1,2)-1,NA()) | H17: =IFERROR(BDP(Tickers!F15,"PX_LAST")/INDEX(BDH(Tickers!F15,"PX_LAST",DATE(YEAR(TODAY())-1,12,31),DATE(YEAR(TODAY())-1,12,31)+5,"Days","A","fill","P"),1,2)-1,NA()) | I17: =IFERROR(BDP(Tickers!F15,"PX_LAST")/INDEX(BDH(Tickers!F15,"PX_LAST",EDATE(TODAY(),-12),EDATE(TODAY(),-12)+5,"Days","A","fill","P"),1,2)-1,NA()) | J17: =IFERROR(BDP(Tickers!F15,"PX_LAST")/INDEX(BDH(Tickers!F15,"PX_LAST",EDATE(TODAY(),-36),EDATE(TODAY(),-36)+5,"Days","A","fill","P"),1,2)-1,NA())
A18: =Tickers!B16 | B18: =Tickers!C16 | C18: =Tickers!F16 | D18: =Tickers!D16 | E18: =IFERROR(BDP(Tickers!F16,"PX_LAST"),NA()) | F18: =IFERROR(BDP(Tickers!F16,"PX_LAST")/INDEX(BDH(Tickers!F16,"PX_LAST",EOMONTH(TODAY(),-1),EOMONTH(TODAY(),-1)+5,"Days","A","fill","P"),1,2)-1,NA()) | G18: =IFERROR(BDP(Tickers!F16,"PX_LAST")/INDEX(BDH(Tickers!F16,"PX_LAST",DATE(YEAR(TODAY()),(INT((MONTH(TODAY())-1)/3))*3+1,1)-1,DATE(YEAR(TODAY()),(INT((MONTH(TODAY())-1)/3))*3+1,1)-1+5,"Days","A","fill","P"),1,2)-1,NA()) | H18: =IFERROR(BDP(Tickers!F16,"PX_LAST")/INDEX(BDH(Tickers!F16,"PX_LAST",DATE(YEAR(TODAY())-1,12,31),DATE(YEAR(TODAY())-1,12,31)+5,"Days","A","fill","P"),1,2)-1,NA()) | I18: =IFERROR(BDP(Tickers!F16,"PX_LAST")/INDEX(BDH(Tickers!F16,"PX_LAST",EDATE(TODAY(),-12),EDATE(TODAY(),-12)+5,"Days","A","fill","P"),1,2)-1,NA()) | J18: =IFERROR(BDP(Tickers!F16,"PX_LAST")/INDEX(BDH(Tickers!F16,"PX_LAST",EDATE(TODAY(),-36),EDATE(TODAY(),-36)+5,"Days","A","fill","P"),1,2)-1,NA())
A19: =Tickers!B17 | B19: =Tickers!C17 | C19: =Tickers!F17 | D19: =Tickers!D17 | E19: =IFERROR(BDP(Tickers!F17,"PX_LAST"),NA()) | F19: =IFERROR(BDP(Tickers!F17,"PX_LAST")/INDEX(BDH(Tickers!F17,"PX_LAST",EOMONTH(TODAY(),-1),EOMONTH(TODAY(),-1)+5,"Days","A","fill","P"),1,2)-1,NA()) | G19: =IFERROR(BDP(Tickers!F17,"PX_LAST")/INDEX(BDH(Tickers!F17,"PX_LAST",DATE(YEAR(TODAY()),(INT((MONTH(TODAY())-1)/3))*3+1,1)-1,DATE(YEAR(TODAY()),(INT((MONTH(TODAY())-1)/3))*3+1,1)-1+5,"Days","A","fill","P"),1,2)-1,NA()) | H19: =IFERROR(BDP(Tickers!F17,"PX_LAST")/INDEX(BDH(Tickers!F17,"PX_LAST",DATE(YEAR(TODAY())-1,12,31),DATE(YEAR(TODAY())-1,12,31)+5,"Days","A","fill","P"),1,2)-1,NA()) | I19: =IFERROR(BDP(Tickers!F17,"PX_LAST")/INDEX(BDH(Tickers!F17,"PX_LAST",EDATE(TODAY(),-12),EDATE(TODAY(),-12)+5,"Days","A","fill","P"),1,2)-1,NA()) | J19: =IFERROR(BDP(Tickers!F17,"PX_LAST")/INDEX(BDH(Tickers!F17,"PX_LAST",EDATE(TODAY(),-36),EDATE(TODAY(),-36)+5,"Days","A","fill","P"),1,2)-1,NA())
... A23: =Tickers!B21 | B23: =Tickers!C21 | C23: =Tickers!F21 | D23: =Tickers!D21 | E23: =IFERROR(BDP(Tickers!F21,"PX_LAST"),NA()) | F23: =IFERROR(BDP(Tickers!F21,"PX_LAST")/INDEX(BDH(Tickers!F21,"PX_LAST",EOMONTH(TODAY(),-1),EOMONTH(TODAY(),-1)+5,"Days","A","fill","P"),1,2)-1,NA()) | G23: =IFERROR(BDP(Tickers!F21,"PX_LAST")/INDEX(BDH(Tickers!F21,"PX_LAST",DATE(YEAR(TODAY()),(INT((MONTH(TODAY())-1)/3))*3+1,1)-1,DATE(YEAR(TODAY()),(INT((MONTH(TODAY())-1)/3))*3+1,1)-1+5,"Days","A","fill","P"),1,2)-1,NA()) | H23: =IFERROR(BDP(Tickers!F21,"PX_LAST")/INDEX(BDH(Tickers!F21,"PX_LAST",DATE(YEAR(TODAY())-1,12,31),DATE(YEAR(TODAY())-1,12,31)+5,"Days","A","fill","P"),1,2)-1,NA()) | I23: =IFERROR(BDP(Tickers!F21,"PX_LAST")/INDEX(BDH(Tickers!F21,"PX_LAST",EDATE(TODAY(),-12),EDATE(TODAY(),-12)+5,"Days","A","fill","P"),1,2)-1,NA()) | J23: =IFERROR(BDP(Tickers!F21,"PX_LAST")/INDEX(BDH(Tickers!F21,"PX_LAST",EDATE(TODAY(),-36),EDATE(TODAY(),-36)+5,"Days","A","fill","P"),1,2)-1,NA())
A24: ="LatAm weighted avg" | D24: =SUM(D8:D23) | F24: =SUMPRODUCT(D8:D23,F8:F23)/SUM(D8:D23) | G24: =SUMPRODUCT(D8:D23,G8:G23)/SUM(D8:D23) | H24: =SUMPRODUCT(D8:D23,H8:H23)/SUM(D8:D23) | I24: =SUMPRODUCT(D8:D23,I8:I23)/SUM(D8:D23) | J24: =SUMPRODUCT(D8:D23,J8:J23)/SUM(D8:D23)
A26: EM Europe & Turkey
A27: =Tickers!B22 | B27: =Tickers!C22 | C27: =Tickers!F22 | D27: =Tickers!D22 | E27: =IFERROR(BDP(Tickers!F22,"PX_LAST"),NA()) | F27: =IFERROR(BDP(Tickers!F22,"PX_LAST")/INDEX(BDH(Tickers!F22,"PX_LAST",EOMONTH(TODAY(),-1),EOMONTH(TODAY(),-1)+5,"Days","A","fill","P"),1,2)-1,NA()) | G27: =IFERROR(BDP(Tickers!F22,"PX_LAST")/INDEX(BDH(Tickers!F22,"PX_LAST",DATE(YEAR(TODAY()),(INT((MONTH(TODAY())-1)/3))*3+1,1)-1,DATE(YEAR(TODAY()),(INT((MONTH(TODAY())-1)/3))*3+1,1)-1+5,"Days","A","fill","P"),1,2)-1,NA()) | H27: =IFERROR(BDP(Tickers!F22,"PX_LAST")/INDEX(BDH(Tickers!F22,"PX_LAST",DATE(YEAR(TODAY())-1,12,31),DATE(YEAR(TODAY())-1,12,31)+5,"Days","A","fill","P"),1,2)-1,NA()) | I27: =IFERROR(BDP(Tickers!F22,"PX_LAST")/INDEX(BDH(Tickers!F22,"PX_LAST",EDATE(TODAY(),-12),EDATE(TODAY(),-12)+5,"Days","A","fill","P"),1,2)-1,NA()) | J27: =IFERROR(BDP(Tickers!F22,"PX_LAST")/INDEX(BDH(Tickers!F22,"PX_LAST",EDATE(TODAY(),-36),EDATE(TODAY(),-36)+5,"Days","A","fill","P"),1,2)-1,NA())
A28: =Tickers!B23 | B28: =Tickers!C23 | C28: =Tickers!F23 | D28: =Tickers!D23 | E28: =IFERROR(BDP(Tickers!F23,"PX_LAST"),NA()) | F28: =IFERROR(BDP(Tickers!F23,"PX_LAST")/INDEX(BDH(Tickers!F23,"PX_LAST",EOMONTH(TODAY(),-1),EOMONTH(TODAY(),-1)+5,"Days","A","fill","P"),1,2)-1,NA()) | G28: =IFERROR(BDP(Tickers!F23,"PX_LAST")/INDEX(BDH(Tickers!F23,"PX_LAST",DATE(YEAR(TODAY()),(INT((MONTH(TODAY())-1)/3))*3+1,1)-1,DATE(YEAR(TODAY()),(INT((MONTH(TODAY())-1)/3))*3+1,1)-1+5,"Days","A","fill","P"),1,2)-1,NA()) | H28: =IFERROR(BDP(Tickers!F23,"PX_LAST")/INDEX(BDH(Tickers!F23,"PX_LAST",DATE(YEAR(TODAY())-1,12,31),DATE(YEAR(TODAY())-1,12,31)+5,"Days","A","fill","P"),1,2)-1,NA()) | I28: =IFERROR(BDP(Tickers!F23,"PX_LAST")/INDEX(BDH(Tickers!F23,"PX_LAST",EDATE(TODAY(),-12),EDATE(TODAY(),-12)+5,"Days","A","fill","P"),1,2)-1,NA()) | J28: =IFERROR(BDP(Tickers!F23,"PX_LAST")/INDEX(BDH(Tickers!F23,"PX_LAST",EDATE(TODAY(),-36),EDATE(TODAY(),-36)+5,"Days","A","fill","P"),1,2)-1,NA())
A29: =Tickers!B24 | B29: =Tickers!C24 | C29: =Tickers!F24 | D29: =Tickers!D24 | E29: =IFERROR(BDP(Tickers!F24,"PX_LAST"),NA()) | F29: =IFERROR(BDP(Tickers!F24,"PX_LAST")/INDEX(BDH(Tickers!F24,"PX_LAST",EOMONTH(TODAY(),-1),EOMONTH(TODAY(),-1)+5,"Days","A","fill","P"),1,2)-1,NA()) | G29: =IFERROR(BDP(Tickers!F24,"PX_LAST")/INDEX(BDH(Tickers!F24,"PX_LAST",DATE(YEAR(TODAY()),(INT((MONTH(TODAY())-1)/3))*3+1,1)-1,DATE(YEAR(TODAY()),(INT((MONTH(TODAY())-1)/3))*3+1,1)-1+5,"Days","A","fill","P"),1,2)-1,NA()) | H29: =IFERROR(BDP(Tickers!F24,"PX_LAST")/INDEX(BDH(Tickers!F24,"PX_LAST",DATE(YEAR(TODAY())-1,12,31),DATE(YEAR(TODAY())-1,12,31)+5,"Days","A","fill","P"),1,2)-1,NA()) | I29: =IFERROR(BDP(Tickers!F24,"PX_LAST")/INDEX(BDH(Tickers!F24,"PX_LAST",EDATE(TODAY(),-12),EDATE(TODAY(),-12)+5,"Days","A","fill","P"),1,2)-1,NA()) | J29: =IFERROR(BDP(Tickers!F24,"PX_LAST")/INDEX(BDH(Tickers!F24,"PX_LAST",EDATE(TODAY(),-36),EDATE(TODAY(),-36)+5,"Days","A","fill","P"),1,2)-1,NA())
A30: =Tickers!B25 | B30: =Tickers!C25 | C30: =Tickers!F25 | D30: =Tickers!D25 | E30: =IFERROR(BDP(Tickers!F25,"PX_LAST"),NA()) | F30: =IFERROR(BDP(Tickers!F25,"PX_LAST")/INDEX(BDH(Tickers!F25,"PX_LAST",EOMONTH(TODAY(),-1),EOMONTH(TODAY(),-1)+5,"Days","A","fill","P"),1,2)-1,NA()) | G30: =IFERROR(BDP(Tickers!F25,"PX_LAST")/INDEX(BDH(Tickers!F25,"PX_LAST",DATE(YEAR(TODAY()),(INT((MONTH(TODAY())-1)/3))*3+1,1)-1,DATE(YEAR(TODAY()),(INT((MONTH(TODAY())-1)/3))*3+1,1)-1+5,"Days","A","fill","P"),1,2)-1,NA()) | H30: =IFERROR(BDP(Tickers!F25,"PX_LAST")/INDEX(BDH(Tickers!F25,"PX_LAST",DATE(YEAR(TODAY())-1,12,31),DATE(YEAR(TODAY())-1,12,31)+5,"Days","A","fill","P"),1,2)-1,NA()) | I30: =IFERROR(BDP(Tickers!F25,"PX_LAST")/INDEX(BDH(Tickers!F25,"PX_LAST",EDATE(TODAY(),-12),EDATE(TODAY(),-12)+5,"Days","A","fill","P"),1,2)-1,NA()) | J30: =IFERROR(BDP(Tickers!F25,"PX_LAST")/INDEX(BDH(Tickers!F25,"PX_LAST",EDATE(TODAY(),-36),EDATE(TODAY(),-36)+5,"Days","A","fill","P"),1,2)-1,NA())
A31: =Tickers!B26 | B31: =Tickers!C26 | C31: =Tickers!F26 | D31: =Tickers!D26 | E31: =IFERROR(BDP(Tickers!F26,"PX_LAST"),NA()) | F31: =IFERROR(BDP(Tickers!F26,"PX_LAST")/INDEX(BDH(Tickers!F26,"PX_LAST",EOMONTH(TODAY(),-1),EOMONTH(TODAY(),-1)+5,"Days","A","fill","P"),1,2)-1,NA()) | G31: =IFERROR(BDP(Tickers!F26,"PX_LAST")/INDEX(BDH(Tickers!F26,"PX_LAST",DATE(YEAR(TODAY()),(INT((MONTH(TODAY())-1)/3))*3+1,1)-1,DATE(YEAR(TODAY()),(INT((MONTH(TODAY())-1)/3))*3+1,1)-1+5,"Days","A","fill","P"),1,2)-1,NA()) | H31: =IFERROR(BDP(Tickers!F26,"PX_LAST")/INDEX(BDH(Tickers!F26,"PX_LAST",DATE(YEAR(TODAY())-1,12,31),DATE(YEAR(TODAY())-1,12,31)+5,"Days","A","fill","P"),1,2)-1,NA()) | I31: =IFERROR(BDP(Tickers!F26,"PX_LAST")/INDEX(BDH(Tickers!F26,"PX_LAST",EDATE(TODAY(),-12),EDATE(TODAY(),-12)+5,"Days","A","fill","P"),1,2)-1,NA()) | J31: =IFERROR(BDP(Tickers!F26,"PX_LAST")/INDEX(BDH(Tickers!F26,"PX_LAST",EDATE(TODAY(),-36),EDATE(TODAY(),-36)+5,"Days","A","fill","P"),1,2)-1,NA())
A32: =Tickers!B27 | B32: =Tickers!C27 | C32: =Tickers!F27 | D32: =Tickers!D27 | E32: =IFERROR(BDP(Tickers!F27,"PX_LAST"),NA()) | F32: =IFERROR(BDP(Tickers!F27,"PX_LAST")/INDEX(BDH(Tickers!F27,"PX_LAST",EOMONTH(TODAY(),-1),EOMONTH(TODAY(),-1)+5,"Days","A","fill","P"),1,2)-1,NA()) | G32: =IFERROR(BDP(Tickers!F27,"PX_LAST")/INDEX(BDH(Tickers!F27,"PX_LAST",DATE(YEAR(TODAY()),(INT((MONTH(TODAY())-1)/3))*3+1,1)-1,DATE(YEAR(TODAY()),(INT((MONTH(TODAY())-1)/3))*3+1,1)-1+5,"Days","A","fill","P"),1,2)-1,NA()) | H32: =IFERROR(BDP(Tickers!F27,"PX_LAST")/INDEX(BDH(Tickers!F27,"PX_LAST",DATE(YEAR(TODAY())-1,12,31),DATE(YEAR(TODAY())-1,12,31)+5,"Days","A","fill","P"),1,2)-1,NA()) | I32: =IFERROR(BDP(Tickers!F27,"PX_LAST")/INDEX(BDH(Tickers!F27,"PX_LAST",EDATE(TODAY(),-12),EDATE(TODAY(),-12)+5,"Days","A","fill","P"),1,2)-1,NA()) | J32: =IFERROR(BDP(Tickers!F27,"PX_LAST")/INDEX(BDH(Tickers!F27,"PX_LAST",EDATE(TODAY(),-36),EDATE(TODAY(),-36)+5,"Days","A","fill","P"),1,2)-1,NA())
A33: =Tickers!B28 | B33: =Tickers!C28 | C33: =Tickers!F28 | D33: =Tickers!D28 | E33: =IFERROR(BDP(Tickers!F28,"PX_LAST"),NA()) | F33: =IFERROR(BDP(Tickers!F28,"PX_LAST")/INDEX(BDH(Tickers!F28,"PX_LAST",EOMONTH(TODAY(),-1),EOMONTH(TODAY(),-1)+5,"Days","A","fill","P"),1,2)-1,NA()) | G33: =IFERROR(BDP(Tickers!F28,"PX_LAST")/INDEX(BDH(Tickers!F28,"PX_LAST",DATE(YEAR(TODAY()),(INT((MONTH(TODAY())-1)/3))*3+1,1)-1,DATE(YEAR(TODAY()),(INT((MONTH(TODAY())-1)/3))*3+1,1)-1+5,"Days","A","fill","P"),1,2)-1,NA()) | H33: =IFERROR(BDP(Tickers!F28,"PX_LAST")/INDEX(BDH(Tickers!F28,"PX_LAST",DATE(YEAR(TODAY())-1,12,31),DATE(YEAR(TODAY())-1,12,31)+5,"Days","A","fill","P"),1,2)-1,NA()) | I33: =IFERROR(BDP(Tickers!F28,"PX_LAST")/INDEX(BDH(Tickers!F28,"PX_LAST",EDATE(TODAY(),-12),EDATE(TODAY(),-12)+5,"Days","A","fill","P"),1,2)-1,NA()) | J33: =IFERROR(BDP(Tickers!F28,"PX_LAST")/INDEX(BDH(Tickers!F28,"PX_LAST",EDATE(TODAY(),-36),EDATE(TODAY(),-36)+5,"Days","A","fill","P"),1,2)-1,NA())
A34: =Tickers!B29 | B34: =Tickers!C29 | C34: =Tickers!F29 | D34: =Tickers!D29 | E34: =IFERROR(BDP(Tickers!F29,"PX_LAST"),NA()) | F34: =IFERROR(BDP(Tickers!F29,"PX_LAST")/INDEX(BDH(Tickers!F29,"PX_LAST",EOMONTH(TODAY(),-1),EOMONTH(TODAY(),-1)+5,"Days","A","fill","P"),1,2)-1,NA()) | G34: =IFERROR(BDP(Tickers!F29,"PX_LAST")/INDEX(BDH(Tickers!F29,"PX_LAST",DATE(YEAR(TODAY()),(INT((MONTH(TODAY())-1)/3))*3+1,1)-1,DATE(YEAR(TODAY()),(INT((MONTH(TODAY())-1)/3))*3+1,1)-1+5,"Days","A","fill","P"),1,2)-1,NA()) | H34: =IFERROR(BDP(Tickers!F29,"PX_LAST")/INDEX(BDH(Tickers!F29,"PX_LAST",DATE(YEAR(TODAY())-1,12,31),DATE(YEAR(TODAY())-1,12,31)+5,"Days","A","fill","P"),1,2)-1,NA()) | I34: =IFERROR(BDP(Tickers!F29,"PX_LAST")/INDEX(BDH(Tickers!F29,"PX_LAST",EDATE(TODAY(),-12),EDATE(TODAY(),-12)+5,"Days","A","fill","P"),1,2)-1,NA()) | J34: =IFERROR(BDP(Tickers!F29,"PX_LAST")/INDEX(BDH(Tickers!F29,"PX_LAST",EDATE(TODAY(),-36),EDATE(TODAY(),-36)+5,"Days","A","fill","P"),1,2)-1,NA())
A35: =Tickers!B30 | B35: =Tickers!C30 | C35: =Tickers!F30 | D35: =Tickers!D30 | E35: =IFERROR(BDP(Tickers!F30,"PX_LAST"),NA()) | F35: =IFERROR(BDP(Tickers!F30,"PX_LAST")/INDEX(BDH(Tickers!F30,"PX_LAST",EOMONTH(TODAY(),-1),EOMONTH(TODAY(),-1)+5,"Days","A","fill","P"),1,2)-1,NA()) | G35: =IFERROR(BDP(Tickers!F30,"PX_LAST")/INDEX(BDH(Tickers!F30,"PX_LAST",DATE(YEAR(TODAY()),(INT((MONTH(TODAY())-1)/3))*3+1,1)-1,DATE(YEAR(TODAY()),(INT((MONTH(TODAY())-1)/3))*3+1,1)-1+5,"Days","A","fill","P"),1,2)-1,NA()) | H35: =IFERROR(BDP(Tickers!F30,"PX_LAST")/INDEX(BDH(Tickers!F30,"PX_LAST",DATE(YEAR(TODAY())-1,12,31),DATE(YEAR(TODAY())-1,12,31)+5,"Days","A","fill","P"),1,2)-1,NA()) | I35: =IFERROR(BDP(Tickers!F30,"PX_LAST")/INDEX(BDH(Tickers!F30,"PX_LAST",EDATE(TODAY(),-12),EDATE(TODAY(),-12)+5,"Days","A","fill","P"),1,2)-1,NA()) | J35: =IFERROR(BDP(Tickers!F30,"PX_LAST")/INDEX(BDH(Tickers!F30,"PX_LAST",EDATE(TODAY(),-36),EDATE(TODAY(),-36)+5,"Days","A","fill","P"),1,2)-1,NA())
A36: =Tickers!B31 | B36: =Tickers!C31 | C36: =Tickers!F31 | D36: =Tickers!D31 | E36: =IFERROR(BDP(Tickers!F31,"PX_LAST"),NA()) | F36: =IFERROR(BDP(Tickers!F31,"PX_LAST")/INDEX(BDH(Tickers!F31,"PX_LAST",EOMONTH(TODAY(),-1),EOMONTH(TODAY(),-1)+5,"Days","A","fill","P"),1,2)-1,NA()) | G36: =IFERROR(BDP(Tickers!F31,"PX_LAST")/INDEX(BDH(Tickers!F31,"PX_LAST",DATE(YEAR(TODAY()),(INT((MONTH(TODAY())-1)/3))*3+1,1)-1,DATE(YEAR(TODAY()),(INT((MONTH(TODAY())-1)/3))*3+1,1)-1+5,"Days","A","fill","P"),1,2)-1,NA()) | H36: =IFERROR(BDP(Tickers!F31,"PX_LAST")/INDEX(BDH(Tickers!F31,"PX_LAST",DATE(YEAR(TODAY())-1,12,31),DATE(YEAR(TODAY())-1,12,31)+5,"Days","A","fill","P"),1,2)-1,NA()) | I36: =IFERROR(BDP(Tickers!F31,"PX_LAST")/INDEX(BDH(Tickers!F31,"PX_LAST",EDATE(TODAY(),-12),EDATE(TODAY(),-12)+5,"Days","A","fill","P"),1,2)-1,NA()) | J36: =IFERROR(BDP(Tickers!F31,"PX_LAST")/INDEX(BDH(Tickers!F31,"PX_LAST",EDATE(TODAY(),-36),EDATE(TODAY(),-36)+5,"Days","A","fill","P"),1,2)-1,NA())
A37: =Tickers!B32 | B37: =Tickers!C32 | C37: =Tickers!F32 | D37: =Tickers!D32 | E37: =IFERROR(BDP(Tickers!F32,"PX_LAST"),NA()) | F37: =IFERROR(BDP(Tickers!F32,"PX_LAST")/INDEX(BDH(Tickers!F32,"PX_LAST",EOMONTH(TODAY(),-1),EOMONTH(TODAY(),-1)+5,"Days","A","fill","P"),1,2)-1,NA()) | G37: =IFERROR(BDP(Tickers!F32,"PX_LAST")/INDEX(BDH(Tickers!F32,"PX_LAST",DATE(YEAR(TODAY()),(INT((MONTH(TODAY())-1)/3))*3+1,1)-1,DATE(YEAR(TODAY()),(INT((MONTH(TODAY())-1)/3))*3+1,1)-1+5,"Days","A","fill","P"),1,2)-1,NA()) | H37: =IFERROR(BDP(Tickers!F32,"PX_LAST")/INDEX(BDH(Tickers!F32,"PX_LAST",DATE(YEAR(TODAY())-1,12,31),DATE(YEAR(TODAY())-1,12,31)+5,"Days","A","fill","P"),1,2)-1,NA()) | I37: =IFERROR(BDP(Tickers!F32,"PX_LAST")/INDEX(BDH(Tickers!F32,"PX_LAST",EDATE(TODAY(),-12),EDATE(TODAY(),-12)+5,"Days","A","fill","P"),1,2)-1,NA()) | J37: =IFERROR(BDP(Tickers!F32,"PX_LAST")/INDEX(BDH(Tickers!F32,"PX_LAST",EDATE(TODAY(),-36),EDATE(TODAY(),-36)+5,"Days","A","fill","P"),1,2)-1,NA())
A38: ="EM Europe & Turkey weighted avg" | D38: =SUM(D27:D37) | F38: =SUMPRODUCT(D27:D37,F27:F37)/SUM(D27:D37) | G38: =SUMPRODUCT(D27:D37,G27:G37)/SUM(D27:D37) | H38: =SUMPRODUCT(D27:D37,H27:H37)/SUM(D27:D37) | I38: =SUMPRODUCT(D27:D37,I27:I37)/SUM(D27:D37) | J38: =SUMPRODUCT(D27:D37,J27:J37)/SUM(D27:D37)
A40: GCC
A41: =Tickers!B33 | B41: =Tickers!C33 | C41: =Tickers!F33 | D41: =Tickers!D33 | E41: =IFERROR(BDP(Tickers!F33,"PX_LAST"),NA()) | F41: =IFERROR(BDP(Tickers!F33,"PX_LAST")/INDEX(BDH(Tickers!F33,"PX_LAST",EOMONTH(TODAY(),-1),EOMONTH(TODAY(),-1)+5,"Days","A","fill","P"),1,2)-1,NA()) | G41: =IFERROR(BDP(Tickers!F33,"PX_LAST")/INDEX(BDH(Tickers!F33,"PX_LAST",DATE(YEAR(TODAY()),(INT((MONTH(TODAY())-1)/3))*3+1,1)-1,DATE(YEAR(TODAY()),(INT((MONTH(TODAY())-1)/3))*3+1,1)-1+5,"Days","A","fill","P"),1,2)-1,NA()) | H41: =IFERROR(BDP(Tickers!F33,"PX_LAST")/INDEX(BDH(Tickers!F33,"PX_LAST",DATE(YEAR(TODAY())-1,12,31),DATE(YEAR(TODAY())-1,12,31)+5,"Days","A","fill","P"),1,2)-1,NA()) | I41: =IFERROR(BDP(Tickers!F33,"PX_LAST")/INDEX(BDH(Tickers!F33,"PX_LAST",EDATE(TODAY(),-12),EDATE(TODAY(),-12)+5,"Days","A","fill","P"),1,2)-1,NA()) | J41: =IFERROR(BDP(Tickers!F33,"PX_LAST")/INDEX(BDH(Tickers!F33,"PX_LAST",EDATE(TODAY(),-36),EDATE(TODAY(),-36)+5,"Days","A","fill","P"),1,2)-1,NA())
A42: =Tickers!B34 | B42: =Tickers!C34 | C42: =Tickers!F34 | D42: =Tickers!D34 | E42: =IFERROR(BDP(Tickers!F34,"PX_LAST"),NA()) | F42: =IFERROR(BDP(Tickers!F34,"PX_LAST")/INDEX(BDH(Tickers!F34,"PX_LAST",EOMONTH(TODAY(),-1),EOMONTH(TODAY(),-1)+5,"Days","A","fill","P"),1,2)-1,NA()) | G42: =IFERROR(BDP(Tickers!F34,"PX_LAST")/INDEX(BDH(Tickers!F34,"PX_LAST",DATE(YEAR(TODAY()),(INT((MONTH(TODAY())-1)/3))*3+1,1)-1,DATE(YEAR(TODAY()),(INT((MONTH(TODAY())-1)/3))*3+1,1)-1+5,"Days","A","fill","P"),1,2)-1,NA()) | H42: =IFERROR(BDP(Tickers!F34,"PX_LAST")/INDEX(BDH(Tickers!F34,"PX_LAST",DATE(YEAR(TODAY())-1,12,31),DATE(YEAR(TODAY())-1,12,31)+5,"Days","A","fill","P"),1,2)-1,NA()) | I42: =IFERROR(BDP(Tickers!F34,"PX_LAST")/INDEX(BDH(Tickers!F34,"PX_LAST",EDATE(TODAY(),-12),EDATE(TODAY(),-12)+5,"Days","A","fill","P"),1,2)-1,NA()) | J42: =IFERROR(BDP(Tickers!F34,"PX_LAST")/INDEX(BDH(Tickers!F34,"PX_LAST",EDATE(TODAY(),-36),EDATE(TODAY(),-36)+5,"Days","A","fill","P"),1,2)-1,NA())
A43: =Tickers!B35 | B43: =Tickers!C35 | C43: =Tickers!F35 | D43: =Tickers!D35 | E43: =IFERROR(BDP(Tickers!F35,"PX_LAST"),NA()) | F43: =IFERROR(BDP(Tickers!F35,"PX_LAST")/INDEX(BDH(Tickers!F35,"PX_LAST",EOMONTH(TODAY(),-1),EOMONTH(TODAY(),-1)+5,"Days","A","fill","P"),1,2)-1,NA()) | G43: =IFERROR(BDP(Tickers!F35,"PX_LAST")/INDEX(BDH(Tickers!F35,"PX_LAST",DATE(YEAR(TODAY()),(INT((MONTH(TODAY())-1)/3))*3+1,1)-1,DATE(YEAR(TODAY()),(INT((MONTH(TODAY())-1)/3))*3+1,1)-1+5,"Days","A","fill","P"),1,2)-1,NA()) | H43: =IFERROR(BDP(Tickers!F35,"PX_LAST")/INDEX(BDH(Tickers!F35,"PX_LAST",DATE(YEAR(TODAY())-1,12,31),DATE(YEAR(TODAY())-1,12,31)+5,"Days","A","fill","P"),1,2)-1,NA()) | I43: =IFERROR(BDP(Tickers!F35,"PX_LAST")/INDEX(BDH(Tickers!F35,"PX_LAST",EDATE(TODAY(),-12),EDATE(TODAY(),-12)+5,"Days","A","fill","P"),1,2)-1,NA()) | J43: =IFERROR(BDP(Tickers!F35,"PX_LAST")/INDEX(BDH(Tickers!F35,"PX_LAST",EDATE(TODAY(),-36),EDATE(TODAY(),-36)+5,"Days","A","fill","P"),1,2)-1,NA())
A44: =Tickers!B36 | B44: =Tickers!C36 | C44: =Tickers!F36 | D44: =Tickers!D36 | E44: =IFERROR(BDP(Tickers!F36,"PX_LAST"),NA()) | F44: =IFERROR(BDP(Tickers!F36,"PX_LAST")/INDEX(BDH(Tickers!F36,"PX_LAST",EOMONTH(TODAY(),-1),EOMONTH(TODAY(),-1)+5,"Days","A","fill","P"),1,2)-1,NA()) | G44: =IFERROR(BDP(Tickers!F36,"PX_LAST")/INDEX(BDH(Tickers!F36,"PX_LAST",DATE(YEAR(TODAY()),(INT((MONTH(TODAY())-1)/3))*3+1,1)-1,DATE(YEAR(TODAY()),(INT((MONTH(TODAY())-1)/3))*3+1,1)-1+5,"Days","A","fill","P"),1,2)-1,NA()) | H44: =IFERROR(BDP(Tickers!F36,"PX_LAST")/INDEX(BDH(Tickers!F36,"PX_LAST",DATE(YEAR(TODAY())-1,12,31),DATE(YEAR(TODAY())-1,12,31)+5,"Days","A","fill","P"),1,2)-1,NA()) | I44: =IFERROR(BDP(Tickers!F36,"PX_LAST")/INDEX(BDH(Tickers!F36,"PX_LAST",EDATE(TODAY(),-12),EDATE(TODAY(),-12)+5,"Days","A","fill","P"),1,2)-1,NA()) | J44: =IFERROR(BDP(Tickers!F36,"PX_LAST")/INDEX(BDH(Tickers!F36,"PX_LAST",EDATE(TODAY(),-36),EDATE(TODAY(),-36)+5,"Days","A","fill","P"),1,2)-1,NA())
A45: =Tickers!B37 | B45: =Tickers!C37 | C45: =Tickers!F37 | D45: =Tickers!D37 | E45: =IFERROR(BDP(Tickers!F37,"PX_LAST"),NA()) | F45: =IFERROR(BDP(Tickers!F37,"PX_LAST")/INDEX(BDH(Tickers!F37,"PX_LAST",EOMONTH(TODAY(),-1),EOMONTH(TODAY(),-1)+5,"Days","A","fill","P"),1,2)-1,NA()) | G45: =IFERROR(BDP(Tickers!F37,"PX_LAST")/INDEX(BDH(Tickers!F37,"PX_LAST",DATE(YEAR(TODAY()),(INT((MONTH(TODAY())-1)/3))*3+1,1)-1,DATE(YEAR(TODAY()),(INT((MONTH(TODAY())-1)/3))*3+1,1)-1+5,"Days","A","fill","P"),1,2)-1,NA()) | H45: =IFERROR(BDP(Tickers!F37,"PX_LAST")/INDEX(BDH(Tickers!F37,"PX_LAST",DATE(YEAR(TODAY())-1,12,31),DATE(YEAR(TODAY())-1,12,31)+5,"Days","A","fill","P"),1,2)-1,NA()) | I45: =IFERROR(BDP(Tickers!F37,"PX_LAST")/INDEX(BDH(Tickers!F37,"PX_LAST",EDATE(TODAY(),-12),EDATE(TODAY(),-12)+5,"Days","A","fill","P"),1,2)-1,NA()) | J45: =IFERROR(BDP(Tickers!F37,"PX_LAST")/INDEX(BDH(Tickers!F37,"PX_LAST",EDATE(TODAY(),-36),EDATE(TODAY(),-36)+5,"Days","A","fill","P"),1,2)-1,NA())
A46: =Tickers!B38 | B46: =Tickers!C38 | C46: =Tickers!F38 | D46: =Tickers!D38 | E46: =IFERROR(BDP(Tickers!F38,"PX_LAST"),NA()) | F46: =IFERROR(BDP(Tickers!F38,"PX_LAST")/INDEX(BDH(Tickers!F38,"PX_LAST",EOMONTH(TODAY(),-1),EOMONTH(TODAY(),-1)+5,"Days","A","fill","P"),1,2)-1,NA()) | G46: =IFERROR(BDP(Tickers!F38,"PX_LAST")/INDEX(BDH(Tickers!F38,"PX_LAST",DATE(YEAR(TODAY()),(INT((MONTH(TODAY())-1)/3))*3+1,1)-1,DATE(YEAR(TODAY()),(INT((MONTH(TODAY())-1)/3))*3+1,1)-1+5,"Days","A","fill","P"),1,2)-1,NA()) | H46: =IFERROR(BDP(Tickers!F38,"PX_LAST")/INDEX(BDH(Tickers!F38,"PX_LAST",DATE(YEAR(TODAY())-1,12,31),DATE(YEAR(TODAY())-1,12,31)+5,"Days","A","fill","P"),1,2)-1,NA()) | I46: =IFERROR(BDP(Tickers!F38,"PX_LAST")/INDEX(BDH(Tickers!F38,"PX_LAST",EDATE(TODAY(),-12),EDATE(TODAY(),-12)+5,"Days","A","fill","P"),1,2)-1,NA()) | J46: =IFERROR(BDP(Tickers!F38,"PX_LAST")/INDEX(BDH(Tickers!F38,"PX_LAST",EDATE(TODAY(),-36),EDATE(TODAY(),-36)+5,"Days","A","fill","P"),1,2)-1,NA())
A47: ="GCC weighted avg" | D47: =SUM(D41:D46) | F47: =SUMPRODUCT(D41:D46,F41:F46)/SUM(D41:D46) | G47: =SUMPRODUCT(D41:D46,G41:G46)/SUM(D41:D46) | H47: =SUMPRODUCT(D41:D46,H41:H46)/SUM(D41:D46) | I47: =SUMPRODUCT(D41:D46,I41:I46)/SUM(D41:D46) | J47: =SUMPRODUCT(D41:D46,J41:J46)/SUM(D41:D46)
...

Sheet Tickers
A1: Tickers — single source of truth
A2: Edit yellow cells. Spread Monitor and Total Return tabs read from this list.
A4: # | B4: Country | C4: Region | D4: Weight (%) | E4: Spread ticker | F4: TR ticker
A5: 0 | B5: EMBI Global Diversified | C5: Aggregate | D5: 100 | E5: JPEGSOSD Index | F5: JPEIDIVR Index
A6: 1 | B6: Mexico | C6: LatAm | D6: 4.8 | E6: JPSSMEXI Index | F6: JPMEMEXI Index
A7: 2 | B7: Brazil | C7: LatAm | D7: 4.5 | E7: JPSSBRZL Index | F7: JPMEBRZL Index
A8: 3 | B8: Argentina | C8: LatAm | D8: 3.5 | E8: JPSSARGE Index | F8: JPMEARGE Index
A9: 4 | B9: Colombia | C9: LatAm | D9: 3 | E9: JPSSCOLO Index | F9: JPMECOLO Index
A10: 5 | B10: Chile | C10: LatAm | D10: 2.5 | E10: JPSSCHIL Index | F10: JPMECHIL Index
A11: 6 | B11: Peru | C11: LatAm | D11: 2 | E11: JPSSPERU Index | F11: JPMEPERU Index
A12: 7 | B12: Dominican Rep. | C12: LatAm | D12: 1.8 | E12: JPSSDOMI Index | F12: JPMEDOMI Index
A13: 8 | B13: Panama | C13: LatAm | D13: 1.5 | E13: JPSSPANA Index | F13: JPMEPANA Index
A14: 9 | B14: Uruguay | C14: LatAm | D14: 0.8 | E14: JPSSURUG Index | F14: JPMEURUG Index
A15: 10 | B15: Costa Rica | C15: LatAm | D15: 0.7 | E15: JPSSCOSR Index | F15: JPMECOSR Index
A16: 11 | B16: Ecuador | C16: LatAm | D16: 0.6 | E16: JPSSECUA Index | F16: JPMEECUA Index
... A63: 58 | B63: Malaysia | C63: Asia | D63: 0.5 | E63: JPSSMAYL Index | F63: JPMEMAYL Index

Sheet _chart_data
A1: EMBI Global Diversified spread — daily history
A2: Spilled by =BDH(...). Do not edit. The Spread Monitor chart reads rows A3:B5500 (≈22y headroom).
A3: Date | B3: Spread (bps)
A4: =BDH(Tickers!E5,"PX_LAST","1/1/2010",TODAY(),"Days","A","fill","P")
