Workbook
Name SETTINGS_LOOK: '01 SETTINGS'!$C$5
Name SETTINGS_FREQ: '01 SETTINGS'!$C$6
Name SETTINGS_ZC: '01 SETTINGS'!$C$7
Name SETTINGS_ZR: '01 SETTINGS'!$C$8
Name SETTINGS_FXSRC: '01 SETTINGS'!$C$9
Name SETTINGS_CAP: '01 SETTINGS'!$C$10
Name SETTINGS_GROSS: '01 SETTINGS'!$C$11
Name SETTINGS_ZMIN: '01 SETTINGS'!$C$12

Sheet 00 README
A1: GLOBAL MACRO VALUE MONITOR — 100 ASSETS, LIVE FROM BLOOMBERG
A2: Cross-sectional value screen with per-asset-class metrics, z-scores, a 50/50 long-short book and paired trades · built 10 October 2026
A4: HOW THIS WORKS — READ THIS FIRST
A5: Every number in this workbook is EMPTY until you open it on a machine with the Bloomberg Excel add-in. The cells contain live BDP and BDH formulas wrapped in IFERROR, so away from a terminal they show blanks rather than errors. On your terminal they populate and everything downstream — z-scores, rankings, the long-short book, the trade pairs — computes itself. Open it, let the add-in finish pulling (the history calls take a minute or two), then press Ctrl+Alt+F9 to force a full recalculation. Do that again any morning you want a fresh read.
A7: THE FOUR-STEP WORKFLOW
B8: Step | C8: What to do | D8: Why
B9: 1 · Open on Bloomberg | C9: Open the file, wait for the add-in, then Ctrl+Alt+F9. | D9: Two BDH history calls per instrument. 100 instruments. Give it a minute.
B10: 2 · Fix the tickers | C10: Go to tab 02 MONITOR, column G. Any row showing CHECK has a ticker Bloomberg did not recognise — overwrite column D with the right one. | D10: I built this without terminal access, so roughly a third of the tickers are flagged VERIFY — mostly EM govvies, credit indices and a few commodity contracts. Column G turns that into a five-minute job instead of a hidden flaw.
B11: 3 · Set your lookback | C11: Tab 01 SETTINGS. Default is 10 years of weekly data. | D11: A z-score is meaningless without its window. 10y spans a full cycle; 5y is more responsive and more regime-contaminated. Run both.
B12: 4 · Read in this order | C12: 03 RANKINGS first (within asset class), then 04 CROSS-ASSET, then 05 PORTFOLIO, then 06 TRADES. | D12: Within-class ranking is the statistically defensible comparison. Cross-asset is interesting and much weaker — the workbook says so where it matters.
A14: TAB MAP
B15: Tab | C15: What it gives you
B16: 01 SETTINGS | C16: Lookback window, z thresholds, capital, and the one toggle that switches FX value between spot and REER.
B17: 02 MONITOR | C17: The master table. 100 instruments, each with its own valuation metric, mean, standard deviation, z-score, a sign-corrected VALUE SCORE where positive always means cheap, percentile, 1-year momentum, and rank within its asset class.
B18: 03 RANKINGS | C18: Cheapest and most expensive WITHIN each asset class. This is the defensible comparison and the one to trust.
B19: 04 CROSS-ASSET | C19: One global list, cheapest to most expensive, plus the ±2 standard deviation extremes screen you asked for. Read the health warning at the top.
B20: 05 PORTFOLIO | C20: 100 positions — 50 long, 50 short — built mechanically from the value scores, risk-weighted, and neutral within every asset class by construction.
B21: 06 TRADES | C21: Eight paired relative-value trades, one per sub-bucket, auto-populated with the cheapest against the richest and a structure note for each.
B22: 07 RISK DASH | C22: Eight regime indicators — VIX, MOVE, CVIX, DXY and others. Context, not positions, and deliberately outside the book.
B23: 08 METHOD | C23: Why each asset class gets the metric it gets, and the four places this screen will mislead you.
A25: THE SIGN CONVENTION THAT MAKES THIS WORK
A26: The one piece of plumbing worth understanding. Each asset class is measured on its own metric, and 'high' means opposite things across them — a high forward P/E is expensive, a high bond yield is cheap. So every instrument carries a sign (+1 or −1) that converts its raw z-score into a VALUE SCORE on a single convention: VALUE SCORE = raw z-score × sign → POSITIVE ALWAYS MEANS CHEAP Equity forward P/E −1 · Bond yield +1 · Credit spread +1 · Commodity price −1 · FX depends on the quote convention, which is the trap: USDBRL rising means a WEAK real, so high = cheap (+1), while EURUSD rising means a STRONG euro, so high = expensive (−1). Column F on the monitor carries that per currency.
A28: Built without Bloomberg access, so every ticker is my best knowledge rather than a verified pull. Column G is the safety net. Nothing here is a recommendation — it is a screen, and a screen is the beginning of the work.

Sheet 01 SETTINGS
A1: SETTINGS
A2: Change these and the entire workbook re-reads. Blue on yellow = input.
B4: Setting | C4: Value | D4: What it does
B5: Lookback start (Bloomberg relative date) | C5: -10Y | D5: Window for the mean and standard deviation. Use -10Y for a full-cycle read, -5Y for a responsive one. Must be a Bloomberg relative date string.
B6: Data frequency | C6: W | D6: D daily, W weekly, M monthly. Weekly is the right trade-off: 520 points over 10 years, light enough that 200 history calls do not hang the sheet.
B7: Cheap threshold (z) | C7: 2 | D7: Flag an asset CHEAP when its value score is at or above this. 2.0 is the convention; 1.5 gives you a longer list.
B8: Rich threshold (z) | C8: -2 | D8: Flag RICH at or below this.
B9: FX value source | C9: SPOT | D9: SPOT uses the 5y/10y z-score of the exchange rate. REER uses the real effective rate tickers in column T of the monitor, which you must supply. REER is the better value measure; SPOT is the one that works out of the box.
B10: Gross capital (USD) | C10: 100000000 | D10: Used only to turn portfolio weights into notional on tab 05.
B11: Target gross exposure (x capital) | C11: 2 | D11: 2.0 means $100mn long and $100mn short on $100mn of capital.
B12: Minimum |z| to take a position | C12: 0.5 | D12: Positions inside this band are set to zero weight on tab 05 — do not pay spread for noise.
B14: As-of (refreshes on open) | C14: =TODAY()
A16: The lookback and frequency cells feed straight into every BDH call on the monitor, so changing them re-pulls all 200 history series. Expect a pause. If the add-in struggles, switch frequency to M before you switch the window.

Sheet 02 MONITOR
A1: MONITOR — 100 GLOBAL MACRO ASSETS
A2: Each asset on its own valuation metric. VALUE SCORE is sign-corrected so POSITIVE ALWAYS MEANS CHEAP. Column G flags bad tickers.
A4: Blank cells mean no Bloomberg connection. Column G: a name = good ticker; CHECK = Bloomberg did not recognise it, fix column D. Column T is optional — paste a REER ticker there and set FX value source to REER on tab 01 to use it instead of spot.
B6: Class | C6: Instrument | D6: Bloomberg ticker | E6: Metric field | F6: Conf. | G6: Ticker check (BDP NAME) | H6: Current | I6: Mean | J6: Std dev | K6: Z (raw) | L6: Sign | M6: VALUE SCORE (+ = cheap) | N6: Percentile | O6: 1y chg % | P6: Rank in class | Q6: N in class | R6: Flag | S6: Metric note / why | T6: REER ticker (FX only, optional) | U6: Global rank
B7: EQUITY | C7: US S&P 500 | D7: SPX Index | E7: BEST_PE_RATIO | F7: HIGH | G7: =IFERROR(IF(BDP($D7,"NAME")="","CHECK",BDP($D7,"NAME")),"CHECK") | H7: =IFERROR(BDP($D7,$E7),"") | I7: =IFERROR(AVERAGE(BDH($D7,$E7,SETTINGS_LOOK,"0D","Days="&SETTINGS_FREQ,"Fill=P")),"") | J7: =IFERROR(STDEV(BDH($D7,$E7,SETTINGS_LOOK,"0D","Days="&SETTINGS_FREQ,"Fill=P")),"") | K7: =IFERROR(($H7-$I7)/$J7,"") | L7: -1 | M7: =IFERROR($K7*$L7,"") | N7: =IFERROR(NORMSDIST($M7),"") | O7: =IFERROR(BDP($D7,"CHG_PCT_1YR")/100,"") | P7: =IFERROR(SUMPRODUCT(($B$7:$B$106=$B7)*($M$7:$M$106>$M7))+1,"") | Q7: =COUNTIF($B$7:$B$106,$B7) | R7: =IFERROR(IF($M7>=SETTINGS_ZC,"CHEAP",IF($M7<=SETTINGS_ZR,"RICH","-")),"") | S7: Forward P/E. High = expensive. | U7: =IFERROR(SUMPRODUCT(($M$7:$M$106>$M7)*1)+1,"")
B8: EQUITY | C8: US Nasdaq 100 | D8: NDX Index | E8: BEST_PE_RATIO | F8: HIGH | G8: =IFERROR(IF(BDP($D8,"NAME")="","CHECK",BDP($D8,"NAME")),"CHECK") | H8: =IFERROR(BDP($D8,$E8),"") | I8: =IFERROR(AVERAGE(BDH($D8,$E8,SETTINGS_LOOK,"0D","Days="&SETTINGS_FREQ,"Fill=P")),"") | J8: =IFERROR(STDEV(BDH($D8,$E8,SETTINGS_LOOK,"0D","Days="&SETTINGS_FREQ,"Fill=P")),"") | K8: =IFERROR(($H8-$I8)/$J8,"") | L8: -1 | M8: =IFERROR($K8*$L8,"") | N8: =IFERROR(NORMSDIST($M8),"") | O8: =IFERROR(BDP($D8,"CHG_PCT_1YR")/100,"") | P8: =IFERROR(SUMPRODUCT(($B$7:$B$106=$B8)*($M$7:$M$106>$M8))+1,"") | Q8: =COUNTIF($B$7:$B$106,$B8) | R8: =IFERROR(IF($M8>=SETTINGS_ZC,"CHEAP",IF($M8<=SETTINGS_ZR,"RICH","-")),"") | S8: Forward P/E. High = expensive. | U8: =IFERROR(SUMPRODUCT(($M$7:$M$106>$M8)*1)+1,"")
B9: EQUITY | C9: US Russell 2000 | D9: RTY Index | E9: BEST_PE_RATIO | F9: HIGH | G9: =IFERROR(IF(BDP($D9,"NAME")="","CHECK",BDP($D9,"NAME")),"CHECK") | H9: =IFERROR(BDP($D9,$E9),"") | I9: =IFERROR(AVERAGE(BDH($D9,$E9,SETTINGS_LOOK,"0D","Days="&SETTINGS_FREQ,"Fill=P")),"") | J9: =IFERROR(STDEV(BDH($D9,$E9,SETTINGS_LOOK,"0D","Days="&SETTINGS_FREQ,"Fill=P")),"") | K9: =IFERROR(($H9-$I9)/$J9,"") | L9: -1 | M9: =IFERROR($K9*$L9,"") | N9: =IFERROR(NORMSDIST($M9),"") | O9: =IFERROR(BDP($D9,"CHG_PCT_1YR")/100,"") | P9: =IFERROR(SUMPRODUCT(($B$7:$B$106=$B9)*($M$7:$M$106>$M9))+1,"") | Q9: =COUNTIF($B$7:$B$106,$B9) | R9: =IFERROR(IF($M9>=SETTINGS_ZC,"CHEAP",IF($M9<=SETTINGS_ZR,"RICH","-")),"") | S9: Forward P/E. High = expensive. | U9: =IFERROR(SUMPRODUCT(($M$7:$M$106>$M9)*1)+1,"")
B10: EQUITY | C10: Euro Stoxx 50 | D10: SX5E Index | E10: BEST_PE_RATIO | F10: HIGH | G10: =IFERROR(IF(BDP($D10,"NAME")="","CHECK",BDP($D10,"NAME")),"CHECK") | H10: =IFERROR(BDP($D10,$E10),"") | I10: =IFERROR(AVERAGE(BDH($D10,$E10,SETTINGS_LOOK,"0D","Days="&SETTINGS_FREQ,"Fill=P")),"") | J10: =IFERROR(STDEV(BDH($D10,$E10,SETTINGS_LOOK,"0D","Days="&SETTINGS_FREQ,"Fill=P")),"") | K10: =IFERROR(($H10-$I10)/$J10,"") | L10: -1 | M10: =IFERROR($K10*$L10,"") | N10: =IFERROR(NORMSDIST($M10),"") | O10: =IFERROR(BDP($D10,"CHG_PCT_1YR")/100,"") | P10: =IFERROR(SUMPRODUCT(($B$7:$B$106=$B10)*($M$7:$M$106>$M10))+1,"") | Q10: =COUNTIF($B$7:$B$106,$B10) | R10: =IFERROR(IF($M10>=SETTINGS_ZC,"CHEAP",IF($M10<=SETTINGS_ZR,"RICH","-")),"") | S10: Forward P/E. High = expensive. | U10: =IFERROR(SUMPRODUCT(($M$7:$M$106>$M10)*1)+1,"")
B11: EQUITY | C11: Germany DAX | D11: DAX Index | E11: BEST_PE_RATIO | F11: HIGH | G11: =IFERROR(IF(BDP($D11,"NAME")="","CHECK",BDP($D11,"NAME")),"CHECK") | H11: =IFERROR(BDP($D11,$E11),"") | I11: =IFERROR(AVERAGE(BDH($D11,$E11,SETTINGS_LOOK,"0D","Days="&SETTINGS_FREQ,"Fill=P")),"") | J11: =IFERROR(STDEV(BDH($D11,$E11,SETTINGS_LOOK,"0D","Days="&SETTINGS_FREQ,"Fill=P")),"") | K11: =IFERROR(($H11-$I11)/$J11,"") | L11: -1 | M11: =IFERROR($K11*$L11,"") | N11: =IFERROR(NORMSDIST($M11),"") | O11: =IFERROR(BDP($D11,"CHG_PCT_1YR")/100,"") | P11: =IFERROR(SUMPRODUCT(($B$7:$B$106=$B11)*($M$7:$M$106>$M11))+1,"") | Q11: =COUNTIF($B$7:$B$106,$B11) | R11: =IFERROR(IF($M11>=SETTINGS_ZC,"CHEAP",IF($M11<=SETTINGS_ZR,"RICH","-")),"") | S11: Forward P/E. High = expensive. | U11: =IFERROR(SUMPRODUCT(($M$7:$M$106>$M11)*1)+1,"")
B12: EQUITY | C12: UK FTSE 100 | D12: UKX Index | E12: BEST_PE_RATIO | F12: HIGH | G12: =IFERROR(IF(BDP($D12,"NAME")="","CHECK",BDP($D12,"NAME")),"CHECK") | H12: =IFERROR(BDP($D12,$E12),"") | I12: =IFERROR(AVERAGE(BDH($D12,$E12,SETTINGS_LOOK,"0D","Days="&SETTINGS_FREQ,"Fill=P")),"") | J12: =IFERROR(STDEV(BDH($D12,$E12,SETTINGS_LOOK,"0D","Days="&SETTINGS_FREQ,"Fill=P")),"") | K12: =IFERROR(($H12-$I12)/$J12,"") | L12: -1 | M12: =IFERROR($K12*$L12,"") | N12: =IFERROR(NORMSDIST($M12),"") | O12: =IFERROR(BDP($D12,"CHG_PCT_1YR")/100,"") | P12: =IFERROR(SUMPRODUCT(($B$7:$B$106=$B12)*($M$7:$M$106>$M12))+1,"") | Q12: =COUNTIF($B$7:$B$106,$B12) | R12: =IFERROR(IF($M12>=SETTINGS_ZC,"CHEAP",IF($M12<=SETTINGS_ZR,"RICH","-")),"") | S12: Forward P/E. High = expensive. | U12: =IFERROR(SUMPRODUCT(($M$7:$M$106>$M12)*1)+1,"")
B13: EQUITY | C13: Japan TOPIX | D13: TPX Index | E13: BEST_PE_RATIO | F13: HIGH | G13: =IFERROR(IF(BDP($D13,"NAME")="","CHECK",BDP($D13,"NAME")),"CHECK") | H13: =IFERROR(BDP($D13,$E13),"") | I13: =IFERROR(AVERAGE(BDH($D13,$E13,SETTINGS_LOOK,"0D","Days="&SETTINGS_FREQ,"Fill=P")),"") | J13: =IFERROR(STDEV(BDH($D13,$E13,SETTINGS_LOOK,"0D","Days="&SETTINGS_FREQ,"Fill=P")),"") | K13: =IFERROR(($H13-$I13)/$J13,"") | L13: -1 | M13: =IFERROR($K13*$L13,"") | N13: =IFERROR(NORMSDIST($M13),"") | O13: =IFERROR(BDP($D13,"CHG_PCT_1YR")/100,"") | P13: =IFERROR(SUMPRODUCT(($B$7:$B$106=$B13)*($M$7:$M$106>$M13))+1,"") | Q13: =COUNTIF($B$7:$B$106,$B13) | R13: =IFERROR(IF($M13>=SETTINGS_ZC,"CHEAP",IF($M13<=SETTINGS_ZR,"RICH","-")),"") | S13: Forward P/E. High = expensive. | U13: =IFERROR(SUMPRODUCT(($M$7:$M$106>$M13)*1)+1,"")
B14: EQUITY | C14: Switzerland SMI | D14: SMI Index | E14: BEST_PE_RATIO | F14: HIGH | G14: =IFERROR(IF(BDP($D14,"NAME")="","CHECK",BDP($D14,"NAME")),"CHECK") | H14: =IFERROR(BDP($D14,$E14),"") | I14: =IFERROR(AVERAGE(BDH($D14,$E14,SETTINGS_LOOK,"0D","Days="&SETTINGS_FREQ,"Fill=P")),"") | J14: =IFERROR(STDEV(BDH($D14,$E14,SETTINGS_LOOK,"0D","Days="&SETTINGS_FREQ,"Fill=P")),"") | K14: =IFERROR(($H14-$I14)/$J14,"") | L14: -1 | M14: =IFERROR($K14*$L14,"") | N14: =IFERROR(NORMSDIST($M14),"") | O14: =IFERROR(BDP($D14,"CHG_PCT_1YR")/100,"") | P14: =IFERROR(SUMPRODUCT(($B$7:$B$106=$B14)*($M$7:$M$106>$M14))+1,"") | Q14: =COUNTIF($B$7:$B$106,$B14) | R14: =IFERROR(IF($M14>=SETTINGS_ZC,"CHEAP",IF($M14<=SETTINGS_ZR,"RICH","-")),"") | S14: Forward P/E. High = expensive. | U14: =IFERROR(SUMPRODUCT(($M$7:$M$106>$M14)*1)+1,"")
B15: EQUITY | C15: Canada S&P/TSX | D15: SPTSX Index | E15: BEST_PE_RATIO | F15: HIGH | G15: =IFERROR(IF(BDP($D15,"NAME")="","CHECK",BDP($D15,"NAME")),"CHECK") | H15: =IFERROR(BDP($D15,$E15),"") | I15: =IFERROR(AVERAGE(BDH($D15,$E15,SETTINGS_LOOK,"0D","Days="&SETTINGS_FREQ,"Fill=P")),"") | J15: =IFERROR(STDEV(BDH($D15,$E15,SETTINGS_LOOK,"0D","Days="&SETTINGS_FREQ,"Fill=P")),"") | K15: =IFERROR(($H15-$I15)/$J15,"") | L15: -1 | M15: =IFERROR($K15*$L15,"") | N15: =IFERROR(NORMSDIST($M15),"") | O15: =IFERROR(BDP($D15,"CHG_PCT_1YR")/100,"") | P15: =IFERROR(SUMPRODUCT(($B$7:$B$106=$B15)*($M$7:$M$106>$M15))+1,"") | Q15: =COUNTIF($B$7:$B$106,$B15) | R15: =IFERROR(IF($M15>=SETTINGS_ZC,"CHEAP",IF($M15<=SETTINGS_ZR,"RICH","-")),"") | S15: Forward P/E. High = expensive. | U15: =IFERROR(SUMPRODUCT(($M$7:$M$106>$M15)*1)+1,"")
B16: EQUITY | C16: Australia ASX 200 | D16: AS51 Index | E16: BEST_PE_RATIO | F16: HIGH | G16: =IFERROR(IF(BDP($D16,"NAME")="","CHECK",BDP($D16,"NAME")),"CHECK") | H16: =IFERROR(BDP($D16,$E16),"") | I16: =IFERROR(AVERAGE(BDH($D16,$E16,SETTINGS_LOOK,"0D","Days="&SETTINGS_FREQ,"Fill=P")),"") | J16: =IFERROR(STDEV(BDH($D16,$E16,SETTINGS_LOOK,"0D","Days="&SETTINGS_FREQ,"Fill=P")),"") | K16: =IFERROR(($H16-$I16)/$J16,"") | L16: -1 | M16: =IFERROR($K16*$L16,"") | N16: =IFERROR(NORMSDIST($M16),"") | O16: =IFERROR(BDP($D16,"CHG_PCT_1YR")/100,"") | P16: =IFERROR(SUMPRODUCT(($B$7:$B$106=$B16)*($M$7:$M$106>$M16))+1,"") | Q16: =COUNTIF($B$7:$B$106,$B16) | R16: =IFERROR(IF($M16>=SETTINGS_ZC,"CHEAP",IF($M16<=SETTINGS_ZR,"RICH","-")),"") | S16: Forward P/E. High = expensive. | U16: =IFERROR(SUMPRODUCT(($M$7:$M$106>$M16)*1)+1,"")
B17: EQUITY | C17: MSCI EM | D17: MXEF Index | E17: BEST_PE_RATIO | F17: HIGH | G17: =IFERROR(IF(BDP($D17,"NAME")="","CHECK",BDP($D17,"NAME")),"CHECK") | H17: =IFERROR(BDP($D17,$E17),"") | I17: =IFERROR(AVERAGE(BDH($D17,$E17,SETTINGS_LOOK,"0D","Days="&SETTINGS_FREQ,"Fill=P")),"") | J17: =IFERROR(STDEV(BDH($D17,$E17,SETTINGS_LOOK,"0D","Days="&SETTINGS_FREQ,"Fill=P")),"") | K17: =IFERROR(($H17-$I17)/$J17,"") | L17: -1 | M17: =IFERROR($K17*$L17,"") | N17: =IFERROR(NORMSDIST($M17),"") | O17: =IFERROR(BDP($D17,"CHG_PCT_1YR")/100,"") | P17: =IFERROR(SUMPRODUCT(($B$7:$B$106=$B17)*($M$7:$M$106>$M17))+1,"") | Q17: =COUNTIF($B$7:$B$106,$B17) | R17: =IFERROR(IF($M17>=SETTINGS_ZC,"CHEAP",IF($M17<=SETTINGS_ZR,"RICH","-")),"") | S17: Forward P/E. High = expensive. | U17: =IFERROR(SUMPRODUCT(($M$7:$M$106>$M17)*1)+1,"")
B18: EQUITY | C18: China CSI 300 | D18: SHSZ300 Index | E18: BEST_PE_RATIO | F18: HIGH | G18: =IFERROR(IF(BDP($D18,"NAME")="","CHECK",BDP($D18,"NAME")),"CHECK") | H18: =IFERROR(BDP($D18,$E18),"") | I18: =IFERROR(AVERAGE(BDH($D18,$E18,SETTINGS_LOOK,"0D","Days="&SETTINGS_FREQ,"Fill=P")),"") | J18: =IFERROR(STDEV(BDH($D18,$E18,SETTINGS_LOOK,"0D","Days="&SETTINGS_FREQ,"Fill=P")),"") | K18: =IFERROR(($H18-$I18)/$J18,"") | L18: -1 | M18: =IFERROR($K18*$L18,"") | N18: =IFERROR(NORMSDIST($M18),"") | O18: =IFERROR(BDP($D18,"CHG_PCT_1YR")/100,"") | P18: =IFERROR(SUMPRODUCT(($B$7:$B$106=$B18)*($M$7:$M$106>$M18))+1,"") | Q18: =COUNTIF($B$7:$B$106,$B18) | R18: =IFERROR(IF($M18>=SETTINGS_ZC,"CHEAP",IF($M18<=SETTINGS_ZR,"RICH","-")),"") | S18: Forward P/E. High = expensive. | U18: =IFERROR(SUMPRODUCT(($M$7:$M$106>$M18)*1)+1,"")
... B50: RATES | C50: Korea 10y | D50: GVSK10YR Index | E50: PX_LAST | F50: VERIFY | G50: =IFERROR(IF(BDP($D50,"NAME")="","CHECK",BDP($D50,"NAME")),"CHECK") | H50: =IFERROR(BDP($D50,$E50),"") | I50: =IFERROR(AVERAGE(BDH($D50,$E50,SETTINGS_LOOK,"0D","Days="&SETTINGS_FREQ,"Fill=P")),"") | J50: =IFERROR(STDEV(BDH($D50,$E50,SETTINGS_LOOK,"0D","Days="&SETTINGS_FREQ,"Fill=P")),"") | K50: =IFERROR(($H50-$I50)/$J50,"") | L50: 1 | M50: =IFERROR($K50*$L50,"") | N50: =IFERROR(NORMSDIST($M50),"") | O50: =IFERROR(BDP($D50,"CHG_PCT_1YR")/100,"") | P50: =IFERROR(SUMPRODUCT(($B$7:$B$106=$B50)*($M$7:$M$106>$M50))+1,"") | Q50: =COUNTIF($B$7:$B$106,$B50) | R50: =IFERROR(IF($M50>=SETTINGS_ZC,"CHEAP",IF($M50<=SETTINGS_ZR,"RICH","-")),"") | S50: 10y nominal yield, %. High yield = cheap bond. | U50: =IFERROR(SUMPRODUCT(($M$7:$M$106>$M50)*1)+1,"")
B51: FX | C51: Euro | D51: EURUSD Curncy | E51: PX_LAST | F51: HIGH | G51: =IFERROR(IF(BDP($D51,"NAME")="","CHECK",BDP($D51,"NAME")),"CHECK") | H51: =IFERROR(BDP($D51,$E51),"") | I51: =IFERROR(AVERAGE(BDH($D51,$E51,SETTINGS_LOOK,"0D","Days="&SETTINGS_FREQ,"Fill=P")),"") | J51: =IFERROR(STDEV(BDH($D51,$E51,SETTINGS_LOOK,"0D","Days="&SETTINGS_FREQ,"Fill=P")),"") | K51: =IFERROR(($H51-$I51)/$J51,"") | L51: -1 | M51: =IFERROR(IF(AND(SETTINGS_FXSRC="REER",$T51<>""),-1*((BDP($T51,"PX_LAST")-AVERAGE(BDH($T51,"PX_LAST",SETTINGS_LOOK,"0D","Days="&SETTINGS_FREQ,"Fill=P")))/STDEV(BDH($T51,"PX_LAST",SETTINGS_LOOK,"0D","Days="&SETTINGS_FREQ,"Fill=P"))),$K51*$L51),"") | N51: =IFERROR(NORMSDIST($M51),"") | O51: =IFERROR(BDP($D51,"CHG_PCT_1YR")/100,"") | P51: =IFERROR(SUMPRODUCT(($B$7:$B$106=$B51)*($M$7:$M$106>$M51))+1,"") | Q51: =COUNTIF($B$7:$B$106,$B51) | R51: =IFERROR(IF($M51>=SETTINGS_ZC,"CHEAP",IF($M51<=SETTINGS_ZR,"RICH","-")),"") | S51: Spot, USD per unit. High = strong local ccy = expensive. | U51: =IFERROR(SUMPRODUCT(($M$7:$M$106>$M51)*1)+1,"")
B52: FX | C52: Japanese yen | D52: USDJPY Curncy | E52: PX_LAST | F52: HIGH | G52: =IFERROR(IF(BDP($D52,"NAME")="","CHECK",BDP($D52,"NAME")),"CHECK") | H52: =IFERROR(BDP($D52,$E52),"") | I52: =IFERROR(AVERAGE(BDH($D52,$E52,SETTINGS_LOOK,"0D","Days="&SETTINGS_FREQ,"Fill=P")),"") | J52: =IFERROR(STDEV(BDH($D52,$E52,SETTINGS_LOOK,"0D","Days="&SETTINGS_FREQ,"Fill=P")),"") | K52: =IFERROR(($H52-$I52)/$J52,"") | L52: 1 | M52: =IFERROR(IF(AND(SETTINGS_FXSRC="REER",$T52<>""),-1*((BDP($T52,"PX_LAST")-AVERAGE(BDH($T52,"PX_LAST",SETTINGS_LOOK,"0D","Days="&SETTINGS_FREQ,"Fill=P")))/STDEV(BDH($T52,"PX_LAST",SETTINGS_LOOK,"0D","Days="&SETTINGS_FREQ,"Fill=P"))),$K52*$L52),"") | N52: =IFERROR(NORMSDIST($M52),"") | O52: =IFERROR(BDP($D52,"CHG_PCT_1YR")/100,"") | P52: =IFERROR(SUMPRODUCT(($B$7:$B$106=$B52)*($M$7:$M$106>$M52))+1,"") | Q52: =COUNTIF($B$7:$B$106,$B52) | R52: =IFERROR(IF($M52>=SETTINGS_ZC,"CHEAP",IF($M52<=SETTINGS_ZR,"RICH","-")),"") | S52: Spot, units per USD. High = weak local ccy = cheap. | U52: =IFERROR(SUMPRODUCT(($M$7:$M$106>$M52)*1)+1,"")
B53: FX | C53: Sterling | D53: GBPUSD Curncy | E53: PX_LAST | F53: HIGH | G53: =IFERROR(IF(BDP($D53,"NAME")="","CHECK",BDP($D53,"NAME")),"CHECK") | H53: =IFERROR(BDP($D53,$E53),"") | I53: =IFERROR(AVERAGE(BDH($D53,$E53,SETTINGS_LOOK,"0D","Days="&SETTINGS_FREQ,"Fill=P")),"") | J53: =IFERROR(STDEV(BDH($D53,$E53,SETTINGS_LOOK,"0D","Days="&SETTINGS_FREQ,"Fill=P")),"") | K53: =IFERROR(($H53-$I53)/$J53,"") | L53: -1 | M53: =IFERROR(IF(AND(SETTINGS_FXSRC="REER",$T53<>""),-1*((BDP($T53,"PX_LAST")-AVERAGE(BDH($T53,"PX_LAST",SETTINGS_LOOK,"0D","Days="&SETTINGS_FREQ,"Fill=P")))/STDEV(BDH($T53,"PX_LAST",SETTINGS_LOOK,"0D","Days="&SETTINGS_FREQ,"Fill=P"))),$K53*$L53),"") | N53: =IFERROR(NORMSDIST($M53),"") | O53: =IFERROR(BDP($D53,"CHG_PCT_1YR")/100,"") | P53: =IFERROR(SUMPRODUCT(($B$7:$B$106=$B53)*($M$7:$M$106>$M53))+1,"") | Q53: =COUNTIF($B$7:$B$106,$B53) | R53: =IFERROR(IF($M53>=SETTINGS_ZC,"CHEAP",IF($M53<=SETTINGS_ZR,"RICH","-")),"") | S53: Spot, USD per unit. High = strong local ccy = expensive. | U53: =IFERROR(SUMPRODUCT(($M$7:$M$106>$M53)*1)+1,"")
B54: FX | C54: Swiss franc | D54: USDCHF Curncy | E54: PX_LAST | F54: HIGH | G54: =IFERROR(IF(BDP($D54,"NAME")="","CHECK",BDP($D54,"NAME")),"CHECK") | H54: =IFERROR(BDP($D54,$E54),"") | I54: =IFERROR(AVERAGE(BDH($D54,$E54,SETTINGS_LOOK,"0D","Days="&SETTINGS_FREQ,"Fill=P")),"") | J54: =IFERROR(STDEV(BDH($D54,$E54,SETTINGS_LOOK,"0D","Days="&SETTINGS_FREQ,"Fill=P")),"") | K54: =IFERROR(($H54-$I54)/$J54,"") | L54: 1 | M54: =IFERROR(IF(AND(SETTINGS_FXSRC="REER",$T54<>""),-1*((BDP($T54,"PX_LAST")-AVERAGE(BDH($T54,"PX_LAST",SETTINGS_LOOK,"0D","Days="&SETTINGS_FREQ,"Fill=P")))/STDEV(BDH($T54,"PX_LAST",SETTINGS_LOOK,"0D","Days="&SETTINGS_FREQ,"Fill=P"))),$K54*$L54),"") | N54: =IFERROR(NORMSDIST($M54),"") | O54: =IFERROR(BDP($D54,"CHG_PCT_1YR")/100,"") | P54: =IFERROR(SUMPRODUCT(($B$7:$B$106=$B54)*($M$7:$M$106>$M54))+1,"") | Q54: =COUNTIF($B$7:$B$106,$B54) | R54: =IFERROR(IF($M54>=SETTINGS_ZC,"CHEAP",IF($M54<=SETTINGS_ZR,"RICH","-")),"") | S54: Spot, units per USD. High = weak local ccy = cheap. | U54: =IFERROR(SUMPRODUCT(($M$7:$M$106>$M54)*1)+1,"")
B55: FX | C55: Canadian dollar | D55: USDCAD Curncy | E55: PX_LAST | F55: HIGH | G55: =IFERROR(IF(BDP($D55,"NAME")="","CHECK",BDP($D55,"NAME")),"CHECK") | H55: =IFERROR(BDP($D55,$E55),"") | I55: =IFERROR(AVERAGE(BDH($D55,$E55,SETTINGS_LOOK,"0D","Days="&SETTINGS_FREQ,"Fill=P")),"") | J55: =IFERROR(STDEV(BDH($D55,$E55,SETTINGS_LOOK,"0D","Days="&SETTINGS_FREQ,"Fill=P")),"") | K55: =IFERROR(($H55-$I55)/$J55,"") | L55: 1 | M55: =IFERROR(IF(AND(SETTINGS_FXSRC="REER",$T55<>""),-1*((BDP($T55,"PX_LAST")-AVERAGE(BDH($T55,"PX_LAST",SETTINGS_LOOK,"0D","Days="&SETTINGS_FREQ,"Fill=P")))/STDEV(BDH($T55,"PX_LAST",SETTINGS_LOOK,"0D","Days="&SETTINGS_FREQ,"Fill=P"))),$K55*$L55),"") | N55: =IFERROR(NORMSDIST($M55),"") | O55: =IFERROR(BDP($D55,"CHG_PCT_1YR")/100,"") | P55: =IFERROR(SUMPRODUCT(($B$7:$B$106=$B55)*($M$7:$M$106>$M55))+1,"") | Q55: =COUNTIF($B$7:$B$106,$B55) | R55: =IFERROR(IF($M55>=SETTINGS_ZC,"CHEAP",IF($M55<=SETTINGS_ZR,"RICH","-")),"") | S55: Spot, units per USD. High = weak local ccy = cheap. | U55: =IFERROR(SUMPRODUCT(($M$7:$M$106>$M55)*1)+1,"")
B56: FX | C56: Australian dollar | D56: AUDUSD Curncy | E56: PX_LAST | F56: HIGH | G56: =IFERROR(IF(BDP($D56,"NAME")="","CHECK",BDP($D56,"NAME")),"CHECK") | H56: =IFERROR(BDP($D56,$E56),"") | I56: =IFERROR(AVERAGE(BDH($D56,$E56,SETTINGS_LOOK,"0D","Days="&SETTINGS_FREQ,"Fill=P")),"") | J56: =IFERROR(STDEV(BDH($D56,$E56,SETTINGS_LOOK,"0D","Days="&SETTINGS_FREQ,"Fill=P")),"") | K56: =IFERROR(($H56-$I56)/$J56,"") | L56: -1 | M56: =IFERROR(IF(AND(SETTINGS_FXSRC="REER",$T56<>""),-1*((BDP($T56,"PX_LAST")-AVERAGE(BDH($T56,"PX_LAST",SETTINGS_LOOK,"0D","Days="&SETTINGS_FREQ,"Fill=P")))/STDEV(BDH($T56,"PX_LAST",SETTINGS_LOOK,"0D","Days="&SETTINGS_FREQ,"Fill=P"))),$K56*$L56),"") | N56: =IFERROR(NORMSDIST($M56),"") | O56: =IFERROR(BDP($D56,"CHG_PCT_1YR")/100,"") | P56: =IFERROR(SUMPRODUCT(($B$7:$B$106=$B56)*($M$7:$M$106>$M56))+1,"") | Q56: =COUNTIF($B$7:$B$106,$B56) | R56: =IFERROR(IF($M56>=SETTINGS_ZC,"CHEAP",IF($M56<=SETTINGS_ZR,"RICH","-")),"") | S56: Spot, USD per unit. High = strong local ccy = expensive. | U56: =IFERROR(SUMPRODUCT(($M$7:$M$106>$M56)*1)+1,"")
B57: FX | C57: NZ dollar | D57: NZDUSD Curncy | E57: PX_LAST | F57: HIGH | G57: =IFERROR(IF(BDP($D57,"NAME")="","CHECK",BDP($D57,"NAME")),"CHECK") | H57: =IFERROR(BDP($D57,$E57),"") | I57: =IFERROR(AVERAGE(BDH($D57,$E57,SETTINGS_LOOK,"0D","Days="&SETTINGS_FREQ,"Fill=P")),"") | J57: =IFERROR(STDEV(BDH($D57,$E57,SETTINGS_LOOK,"0D","Days="&SETTINGS_FREQ,"Fill=P")),"") | K57: =IFERROR(($H57-$I57)/$J57,"") | L57: -1 | M57: =IFERROR(IF(AND(SETTINGS_FXSRC="REER",$T57<>""),-1*((BDP($T57,"PX_LAST")-AVERAGE(BDH($T57,"PX_LAST",SETTINGS_LOOK,"0D","Days="&SETTINGS_FREQ,"Fill=P")))/STDEV(BDH($T57,"PX_LAST",SETTINGS_LOOK,"0D","Days="&SETTINGS_FREQ,"Fill=P"))),$K57*$L57),"") | N57: =IFERROR(NORMSDIST($M57),"") | O57: =IFERROR(BDP($D57,"CHG_PCT_1YR")/100,"") | P57: =IFERROR(SUMPRODUCT(($B$7:$B$106=$B57)*($M$7:$M$106>$M57))+1,"") | Q57: =COUNTIF($B$7:$B$106,$B57) | R57: =IFERROR(IF($M57>=SETTINGS_ZC,"CHEAP",IF($M57<=SETTINGS_ZR,"RICH","-")),"") | S57: Spot, USD per unit. High = strong local ccy = expensive. | U57: =IFERROR(SUMPRODUCT(($M$7:$M$106>$M57)*1)+1,"")
B58: FX | C58: Norwegian krone | D58: USDNOK Curncy | E58: PX_LAST | F58: HIGH | G58: =IFERROR(IF(BDP($D58,"NAME")="","CHECK",BDP($D58,"NAME")),"CHECK") | H58: =IFERROR(BDP($D58,$E58),"") | I58: =IFERROR(AVERAGE(BDH($D58,$E58,SETTINGS_LOOK,"0D","Days="&SETTINGS_FREQ,"Fill=P")),"") | J58: =IFERROR(STDEV(BDH($D58,$E58,SETTINGS_LOOK,"0D","Days="&SETTINGS_FREQ,"Fill=P")),"") | K58: =IFERROR(($H58-$I58)/$J58,"") | L58: 1 | M58: =IFERROR(IF(AND(SETTINGS_FXSRC="REER",$T58<>""),-1*((BDP($T58,"PX_LAST")-AVERAGE(BDH($T58,"PX_LAST",SETTINGS_LOOK,"0D","Days="&SETTINGS_FREQ,"Fill=P")))/STDEV(BDH($T58,"PX_LAST",SETTINGS_LOOK,"0D","Days="&SETTINGS_FREQ,"Fill=P"))),$K58*$L58),"") | N58: =IFERROR(NORMSDIST($M58),"") | O58: =IFERROR(BDP($D58,"CHG_PCT_1YR")/100,"") | P58: =IFERROR(SUMPRODUCT(($B$7:$B$106=$B58)*($M$7:$M$106>$M58))+1,"") | Q58: =COUNTIF($B$7:$B$106,$B58) | R58: =IFERROR(IF($M58>=SETTINGS_ZC,"CHEAP",IF($M58<=SETTINGS_ZR,"RICH","-")),"") | S58: Spot, units per USD. High = weak local ccy = cheap. | U58: =IFERROR(SUMPRODUCT(($M$7:$M$106>$M58)*1)+1,"")
B59: FX | C59: Swedish krona | D59: USDSEK Curncy | E59: PX_LAST | F59: HIGH | G59: =IFERROR(IF(BDP($D59,"NAME")="","CHECK",BDP($D59,"NAME")),"CHECK") | H59: =IFERROR(BDP($D59,$E59),"") | I59: =IFERROR(AVERAGE(BDH($D59,$E59,SETTINGS_LOOK,"0D","Days="&SETTINGS_FREQ,"Fill=P")),"") | J59: =IFERROR(STDEV(BDH($D59,$E59,SETTINGS_LOOK,"0D","Days="&SETTINGS_FREQ,"Fill=P")),"") | K59: =IFERROR(($H59-$I59)/$J59,"") | L59: 1 | M59: =IFERROR(IF(AND(SETTINGS_FXSRC="REER",$T59<>""),-1*((BDP($T59,"PX_LAST")-AVERAGE(BDH($T59,"PX_LAST",SETTINGS_LOOK,"0D","Days="&SETTINGS_FREQ,"Fill=P")))/STDEV(BDH($T59,"PX_LAST",SETTINGS_LOOK,"0D","Days="&SETTINGS_FREQ,"Fill=P"))),$K59*$L59),"") | N59: =IFERROR(NORMSDIST($M59),"") | O59: =IFERROR(BDP($D59,"CHG_PCT_1YR")/100,"") | P59: =IFERROR(SUMPRODUCT(($B$7:$B$106=$B59)*($M$7:$M$106>$M59))+1,"") | Q59: =COUNTIF($B$7:$B$106,$B59) | R59: =IFERROR(IF($M59>=SETTINGS_ZC,"CHEAP",IF($M59<=SETTINGS_ZR,"RICH","-")),"") | S59: Spot, units per USD. High = weak local ccy = cheap. | U59: =IFERROR(SUMPRODUCT(($M$7:$M$106>$M59)*1)+1,"")
B60: FX | C60: Brazilian real | D60: USDBRL Curncy | E60: PX_LAST | F60: HIGH | G60: =IFERROR(IF(BDP($D60,"NAME")="","CHECK",BDP($D60,"NAME")),"CHECK") | H60: =IFERROR(BDP($D60,$E60),"") | I60: =IFERROR(AVERAGE(BDH($D60,$E60,SETTINGS_LOOK,"0D","Days="&SETTINGS_FREQ,"Fill=P")),"") | J60: =IFERROR(STDEV(BDH($D60,$E60,SETTINGS_LOOK,"0D","Days="&SETTINGS_FREQ,"Fill=P")),"") | K60: =IFERROR(($H60-$I60)/$J60,"") | L60: 1 | M60: =IFERROR(IF(AND(SETTINGS_FXSRC="REER",$T60<>""),-1*((BDP($T60,"PX_LAST")-AVERAGE(BDH($T60,"PX_LAST",SETTINGS_LOOK,"0D","Days="&SETTINGS_FREQ,"Fill=P")))/STDEV(BDH($T60,"PX_LAST",SETTINGS_LOOK,"0D","Days="&SETTINGS_FREQ,"Fill=P"))),$K60*$L60),"") | N60: =IFERROR(NORMSDIST($M60),"") | O60: =IFERROR(BDP($D60,"CHG_PCT_1YR")/100,"") | P60: =IFERROR(SUMPRODUCT(($B$7:$B$106=$B60)*($M$7:$M$106>$M60))+1,"") | Q60: =COUNTIF($B$7:$B$106,$B60) | R60: =IFERROR(IF($M60>=SETTINGS_ZC,"CHEAP",IF($M60<=SETTINGS_ZR,"RICH","-")),"") | S60: Spot, units per USD. High = weak local ccy = cheap. | U60: =IFERROR(SUMPRODUCT(($M$7:$M$106>$M60)*1)+1,"")
B61: FX | C61: Mexican peso | D61: USDMXN Curncy | E61: PX_LAST | F61: HIGH | G61: =IFERROR(IF(BDP($D61,"NAME")="","CHECK",BDP($D61,"NAME")),"CHECK") | H61: =IFERROR(BDP($D61,$E61),"") | I61: =IFERROR(AVERAGE(BDH($D61,$E61,SETTINGS_LOOK,"0D","Days="&SETTINGS_FREQ,"Fill=P")),"") | J61: =IFERROR(STDEV(BDH($D61,$E61,SETTINGS_LOOK,"0D","Days="&SETTINGS_FREQ,"Fill=P")),"") | K61: =IFERROR(($H61-$I61)/$J61,"") | L61: 1 | M61: =IFERROR(IF(AND(SETTINGS_FXSRC="REER",$T61<>""),-1*((BDP($T61,"PX_LAST")-AVERAGE(BDH($T61,"PX_LAST",SETTINGS_LOOK,"0D","Days="&SETTINGS_FREQ,"Fill=P")))/STDEV(BDH($T61,"PX_LAST",SETTINGS_LOOK,"0D","Days="&SETTINGS_FREQ,"Fill=P"))),$K61*$L61),"") | N61: =IFERROR(NORMSDIST($M61),"") | O61: =IFERROR(BDP($D61,"CHG_PCT_1YR")/100,"") | P61: =IFERROR(SUMPRODUCT(($B$7:$B$106=$B61)*($M$7:$M$106>$M61))+1,"") | Q61: =COUNTIF($B$7:$B$106,$B61) | R61: =IFERROR(IF($M61>=SETTINGS_ZC,"CHEAP",IF($M61<=SETTINGS_ZR,"RICH","-")),"") | S61: Spot, units per USD. High = weak local ccy = cheap. | U61: =IFERROR(SUMPRODUCT(($M$7:$M$106>$M61)*1)+1,"")
B62: FX | C62: Colombian peso | D62: USDCOP Curncy | E62: PX_LAST | F62: HIGH | G62: =IFERROR(IF(BDP($D62,"NAME")="","CHECK",BDP($D62,"NAME")),"CHECK") | H62: =IFERROR(BDP($D62,$E62),"") | I62: =IFERROR(AVERAGE(BDH($D62,$E62,SETTINGS_LOOK,"0D","Days="&SETTINGS_FREQ,"Fill=P")),"") | J62: =IFERROR(STDEV(BDH($D62,$E62,SETTINGS_LOOK,"0D","Days="&SETTINGS_FREQ,"Fill=P")),"") | K62: =IFERROR(($H62-$I62)/$J62,"") | L62: 1 | M62: =IFERROR(IF(AND(SETTINGS_FXSRC="REER",$T62<>""),-1*((BDP($T62,"PX_LAST")-AVERAGE(BDH($T62,"PX_LAST",SETTINGS_LOOK,"0D","Days="&SETTINGS_FREQ,"Fill=P")))/STDEV(BDH($T62,"PX_LAST",SETTINGS_LOOK,"0D","Days="&SETTINGS_FREQ,"Fill=P"))),$K62*$L62),"") | N62: =IFERROR(NORMSDIST($M62),"") | O62: =IFERROR(BDP($D62,"CHG_PCT_1YR")/100,"") | P62: =IFERROR(SUMPRODUCT(($B$7:$B$106=$B62)*($M$7:$M$106>$M62))+1,"") | Q62: =COUNTIF($B$7:$B$106,$B62) | R62: =IFERROR(IF($M62>=SETTINGS_ZC,"CHEAP",IF($M62<=SETTINGS_ZR,"RICH","-")),"") | S62: Spot, units per USD. High = weak local ccy = cheap. | U62: =IFERROR(SUMPRODUCT(($M$7:$M$106>$M62)*1)+1,"")
... B76: FX | C76: Offshore renminbi | D76: USDCNH Curncy | E76: PX_LAST | F76: HIGH | G76: =IFERROR(IF(BDP($D76,"NAME")="","CHECK",BDP($D76,"NAME")),"CHECK") | H76: =IFERROR(BDP($D76,$E76),"") | I76: =IFERROR(AVERAGE(BDH($D76,$E76,SETTINGS_LOOK,"0D","Days="&SETTINGS_FREQ,"Fill=P")),"") | J76: =IFERROR(STDEV(BDH($D76,$E76,SETTINGS_LOOK,"0D","Days="&SETTINGS_FREQ,"Fill=P")),"") | K76: =IFERROR(($H76-$I76)/$J76,"") | L76: 1 | M76: =IFERROR(IF(AND(SETTINGS_FXSRC="REER",$T76<>""),-1*((BDP($T76,"PX_LAST")-AVERAGE(BDH($T76,"PX_LAST",SETTINGS_LOOK,"0D","Days="&SETTINGS_FREQ,"Fill=P")))/STDEV(BDH($T76,"PX_LAST",SETTINGS_LOOK,"0D","Days="&SETTINGS_FREQ,"Fill=P"))),$K76*$L76),"") | N76: =IFERROR(NORMSDIST($M76),"") | O76: =IFERROR(BDP($D76,"CHG_PCT_1YR")/100,"") | P76: =IFERROR(SUMPRODUCT(($B$7:$B$106=$B76)*($M$7:$M$106>$M76))+1,"") | Q76: =COUNTIF($B$7:$B$106,$B76) | R76: =IFERROR(IF($M76>=SETTINGS_ZC,"CHEAP",IF($M76<=SETTINGS_ZR,"RICH","-")),"") | S76: Spot, units per USD. High = weak local ccy = cheap. | U76: =IFERROR(SUMPRODUCT(($M$7:$M$106>$M76)*1)+1,"")
B77: CREDIT | C77: US IG OAS | D77: LUACOAS Index | E77: PX_LAST | F77: HIGH | G77: =IFERROR(IF(BDP($D77,"NAME")="","CHECK",BDP($D77,"NAME")),"CHECK") | H77: =IFERROR(BDP($D77,$E77),"") | I77: =IFERROR(AVERAGE(BDH($D77,$E77,SETTINGS_LOOK,"0D","Days="&SETTINGS_FREQ,"Fill=P")),"") | J77: =IFERROR(STDEV(BDH($D77,$E77,SETTINGS_LOOK,"0D","Days="&SETTINGS_FREQ,"Fill=P")),"") | K77: =IFERROR(($H77-$I77)/$J77,"") | L77: 1 | M77: =IFERROR($K77*$L77,"") | N77: =IFERROR(NORMSDIST($M77),"") | O77: =IFERROR(BDP($D77,"CHG_PCT_1YR")/100,"") | P77: =IFERROR(SUMPRODUCT(($B$7:$B$106=$B77)*($M$7:$M$106>$M77))+1,"") | Q77: =COUNTIF($B$7:$B$106,$B77) | R77: =IFERROR(IF($M77>=SETTINGS_ZC,"CHEAP",IF($M77<=SETTINGS_ZR,"RICH","-")),"") | S77: Spread in bp. High spread = cheap credit. | U77: =IFERROR(SUMPRODUCT(($M$7:$M$106>$M77)*1)+1,"")
B78: CREDIT | C78: US HY OAS | D78: LF98OAS Index | E78: PX_LAST | F78: HIGH | G78: =IFERROR(IF(BDP($D78,"NAME")="","CHECK",BDP($D78,"NAME")),"CHECK") | H78: =IFERROR(BDP($D78,$E78),"") | I78: =IFERROR(AVERAGE(BDH($D78,$E78,SETTINGS_LOOK,"0D","Days="&SETTINGS_FREQ,"Fill=P")),"") | J78: =IFERROR(STDEV(BDH($D78,$E78,SETTINGS_LOOK,"0D","Days="&SETTINGS_FREQ,"Fill=P")),"") | K78: =IFERROR(($H78-$I78)/$J78,"") | L78: 1 | M78: =IFERROR($K78*$L78,"") | N78: =IFERROR(NORMSDIST($M78),"") | O78: =IFERROR(BDP($D78,"CHG_PCT_1YR")/100,"") | P78: =IFERROR(SUMPRODUCT(($B$7:$B$106=$B78)*($M$7:$M$106>$M78))+1,"") | Q78: =COUNTIF($B$7:$B$106,$B78) | R78: =IFERROR(IF($M78>=SETTINGS_ZC,"CHEAP",IF($M78<=SETTINGS_ZR,"RICH","-")),"") | S78: Spread in bp. High spread = cheap credit. | U78: =IFERROR(SUMPRODUCT(($M$7:$M$106>$M78)*1)+1,"")
B79: CREDIT | C79: Euro IG OAS | D79: LECPOAS Index | E79: PX_LAST | F79: VERIFY | G79: =IFERROR(IF(BDP($D79,"NAME")="","CHECK",BDP($D79,"NAME")),"CHECK") | H79: =IFERROR(BDP($D79,$E79),"") | I79: =IFERROR(AVERAGE(BDH($D79,$E79,SETTINGS_LOOK,"0D","Days="&SETTINGS_FREQ,"Fill=P")),"") | J79: =IFERROR(STDEV(BDH($D79,$E79,SETTINGS_LOOK,"0D","Days="&SETTINGS_FREQ,"Fill=P")),"") | K79: =IFERROR(($H79-$I79)/$J79,"") | L79: 1 | M79: =IFERROR($K79*$L79,"") | N79: =IFERROR(NORMSDIST($M79),"") | O79: =IFERROR(BDP($D79,"CHG_PCT_1YR")/100,"") | P79: =IFERROR(SUMPRODUCT(($B$7:$B$106=$B79)*($M$7:$M$106>$M79))+1,"") | Q79: =COUNTIF($B$7:$B$106,$B79) | R79: =IFERROR(IF($M79>=SETTINGS_ZC,"CHEAP",IF($M79<=SETTINGS_ZR,"RICH","-")),"") | S79: Spread in bp. High spread = cheap credit. | U79: =IFERROR(SUMPRODUCT(($M$7:$M$106>$M79)*1)+1,"")
B80: CREDIT | C80: Euro HY OAS | D80: LP01OAS Index | E80: PX_LAST | F80: VERIFY | G80: =IFERROR(IF(BDP($D80,"NAME")="","CHECK",BDP($D80,"NAME")),"CHECK") | H80: =IFERROR(BDP($D80,$E80),"") | I80: =IFERROR(AVERAGE(BDH($D80,$E80,SETTINGS_LOOK,"0D","Days="&SETTINGS_FREQ,"Fill=P")),"") | J80: =IFERROR(STDEV(BDH($D80,$E80,SETTINGS_LOOK,"0D","Days="&SETTINGS_FREQ,"Fill=P")),"") | K80: =IFERROR(($H80-$I80)/$J80,"") | L80: 1 | M80: =IFERROR($K80*$L80,"") | N80: =IFERROR(NORMSDIST($M80),"") | O80: =IFERROR(BDP($D80,"CHG_PCT_1YR")/100,"") | P80: =IFERROR(SUMPRODUCT(($B$7:$B$106=$B80)*($M$7:$M$106>$M80))+1,"") | Q80: =COUNTIF($B$7:$B$106,$B80) | R80: =IFERROR(IF($M80>=SETTINGS_ZC,"CHEAP",IF($M80<=SETTINGS_ZR,"RICH","-")),"") | S80: Spread in bp. High spread = cheap credit. | U80: =IFERROR(SUMPRODUCT(($M$7:$M$106>$M80)*1)+1,"")
B81: CREDIT | C81: EM sovereign USD (EMBI GD) spread | D81: JPEGSOSD Index | E81: PX_LAST | F81: VERIFY | G81: =IFERROR(IF(BDP($D81,"NAME")="","CHECK",BDP($D81,"NAME")),"CHECK") | H81: =IFERROR(BDP($D81,$E81),"") | I81: =IFERROR(AVERAGE(BDH($D81,$E81,SETTINGS_LOOK,"0D","Days="&SETTINGS_FREQ,"Fill=P")),"") | J81: =IFERROR(STDEV(BDH($D81,$E81,SETTINGS_LOOK,"0D","Days="&SETTINGS_FREQ,"Fill=P")),"") | K81: =IFERROR(($H81-$I81)/$J81,"") | L81: 1 | M81: =IFERROR($K81*$L81,"") | N81: =IFERROR(NORMSDIST($M81),"") | O81: =IFERROR(BDP($D81,"CHG_PCT_1YR")/100,"") | P81: =IFERROR(SUMPRODUCT(($B$7:$B$106=$B81)*($M$7:$M$106>$M81))+1,"") | Q81: =COUNTIF($B$7:$B$106,$B81) | R81: =IFERROR(IF($M81>=SETTINGS_ZC,"CHEAP",IF($M81<=SETTINGS_ZR,"RICH","-")),"") | S81: Spread in bp. High spread = cheap credit. | U81: =IFERROR(SUMPRODUCT(($M$7:$M$106>$M81)*1)+1,"")
B82: CREDIT | C82: EM corporate (CEMBI) spread | D82: JBCDCOMP Index | E82: PX_LAST | F82: VERIFY | G82: =IFERROR(IF(BDP($D82,"NAME")="","CHECK",BDP($D82,"NAME")),"CHECK") | H82: =IFERROR(BDP($D82,$E82),"") | I82: =IFERROR(AVERAGE(BDH($D82,$E82,SETTINGS_LOOK,"0D","Days="&SETTINGS_FREQ,"Fill=P")),"") | J82: =IFERROR(STDEV(BDH($D82,$E82,SETTINGS_LOOK,"0D","Days="&SETTINGS_FREQ,"Fill=P")),"") | K82: =IFERROR(($H82-$I82)/$J82,"") | L82: 1 | M82: =IFERROR($K82*$L82,"") | N82: =IFERROR(NORMSDIST($M82),"") | O82: =IFERROR(BDP($D82,"CHG_PCT_1YR")/100,"") | P82: =IFERROR(SUMPRODUCT(($B$7:$B$106=$B82)*($M$7:$M$106>$M82))+1,"") | Q82: =COUNTIF($B$7:$B$106,$B82) | R82: =IFERROR(IF($M82>=SETTINGS_ZC,"CHEAP",IF($M82<=SETTINGS_ZR,"RICH","-")),"") | S82: Spread in bp. High spread = cheap credit. | U82: =IFERROR(SUMPRODUCT(($M$7:$M$106>$M82)*1)+1,"")
B83: CREDIT | C83: CDX IG 5y | D83: CDX IG CDSI GEN 5Y Corp | E83: PX_LAST | F83: VERIFY | G83: =IFERROR(IF(BDP($D83,"NAME")="","CHECK",BDP($D83,"NAME")),"CHECK") | H83: =IFERROR(BDP($D83,$E83),"") | I83: =IFERROR(AVERAGE(BDH($D83,$E83,SETTINGS_LOOK,"0D","Days="&SETTINGS_FREQ,"Fill=P")),"") | J83: =IFERROR(STDEV(BDH($D83,$E83,SETTINGS_LOOK,"0D","Days="&SETTINGS_FREQ,"Fill=P")),"") | K83: =IFERROR(($H83-$I83)/$J83,"") | L83: 1 | M83: =IFERROR($K83*$L83,"") | N83: =IFERROR(NORMSDIST($M83),"") | O83: =IFERROR(BDP($D83,"CHG_PCT_1YR")/100,"") | P83: =IFERROR(SUMPRODUCT(($B$7:$B$106=$B83)*($M$7:$M$106>$M83))+1,"") | Q83: =COUNTIF($B$7:$B$106,$B83) | R83: =IFERROR(IF($M83>=SETTINGS_ZC,"CHEAP",IF($M83<=SETTINGS_ZR,"RICH","-")),"") | S83: Spread in bp. High spread = cheap credit. | U83: =IFERROR(SUMPRODUCT(($M$7:$M$106>$M83)*1)+1,"")
B84: CREDIT | C84: CDX HY 5y | D84: CDX HY CDSI GEN 5Y Corp | E84: PX_LAST | F84: VERIFY | G84: =IFERROR(IF(BDP($D84,"NAME")="","CHECK",BDP($D84,"NAME")),"CHECK") | H84: =IFERROR(BDP($D84,$E84),"") | I84: =IFERROR(AVERAGE(BDH($D84,$E84,SETTINGS_LOOK,"0D","Days="&SETTINGS_FREQ,"Fill=P")),"") | J84: =IFERROR(STDEV(BDH($D84,$E84,SETTINGS_LOOK,"0D","Days="&SETTINGS_FREQ,"Fill=P")),"") | K84: =IFERROR(($H84-$I84)/$J84,"") | L84: 1 | M84: =IFERROR($K84*$L84,"") | N84: =IFERROR(NORMSDIST($M84),"") | O84: =IFERROR(BDP($D84,"CHG_PCT_1YR")/100,"") | P84: =IFERROR(SUMPRODUCT(($B$7:$B$106=$B84)*($M$7:$M$106>$M84))+1,"") | Q84: =COUNTIF($B$7:$B$106,$B84) | R84: =IFERROR(IF($M84>=SETTINGS_ZC,"CHEAP",IF($M84<=SETTINGS_ZR,"RICH","-")),"") | S84: Spread in bp. High spread = cheap credit. | U84: =IFERROR(SUMPRODUCT(($M$7:$M$106>$M84)*1)+1,"")
B85: CREDIT | C85: iTraxx Main 5y | D85: ITRX EUR CDSI GEN 5Y Corp | E85: PX_LAST | F85: VERIFY | G85: =IFERROR(IF(BDP($D85,"NAME")="","CHECK",BDP($D85,"NAME")),"CHECK") | H85: =IFERROR(BDP($D85,$E85),"") | I85: =IFERROR(AVERAGE(BDH($D85,$E85,SETTINGS_LOOK,"0D","Days="&SETTINGS_FREQ,"Fill=P")),"") | J85: =IFERROR(STDEV(BDH($D85,$E85,SETTINGS_LOOK,"0D","Days="&SETTINGS_FREQ,"Fill=P")),"") | K85: =IFERROR(($H85-$I85)/$J85,"") | L85: 1 | M85: =IFERROR($K85*$L85,"") | N85: =IFERROR(NORMSDIST($M85),"") | O85: =IFERROR(BDP($D85,"CHG_PCT_1YR")/100,"") | P85: =IFERROR(SUMPRODUCT(($B$7:$B$106=$B85)*($M$7:$M$106>$M85))+1,"") | Q85: =COUNTIF($B$7:$B$106,$B85) | R85: =IFERROR(IF($M85>=SETTINGS_ZC,"CHEAP",IF($M85<=SETTINGS_ZR,"RICH","-")),"") | S85: Spread in bp. High spread = cheap credit. | U85: =IFERROR(SUMPRODUCT(($M$7:$M$106>$M85)*1)+1,"")
B86: CREDIT | C86: iTraxx Crossover 5y | D86: ITRX XOVER CDSI GEN 5Y Corp | E86: PX_LAST | F86: VERIFY | G86: =IFERROR(IF(BDP($D86,"NAME")="","CHECK",BDP($D86,"NAME")),"CHECK") | H86: =IFERROR(BDP($D86,$E86),"") | I86: =IFERROR(AVERAGE(BDH($D86,$E86,SETTINGS_LOOK,"0D","Days="&SETTINGS_FREQ,"Fill=P")),"") | J86: =IFERROR(STDEV(BDH($D86,$E86,SETTINGS_LOOK,"0D","Days="&SETTINGS_FREQ,"Fill=P")),"") | K86: =IFERROR(($H86-$I86)/$J86,"") | L86: 1 | M86: =IFERROR($K86*$L86,"") | N86: =IFERROR(NORMSDIST($M86),"") | O86: =IFERROR(BDP($D86,"CHG_PCT_1YR")/100,"") | P86: =IFERROR(SUMPRODUCT(($B$7:$B$106=$B86)*($M$7:$M$106>$M86))+1,"") | Q86: =COUNTIF($B$7:$B$106,$B86) | R86: =IFERROR(IF($M86>=SETTINGS_ZC,"CHEAP",IF($M86<=SETTINGS_ZR,"RICH","-")),"") | S86: Spread in bp. High spread = cheap credit. | U86: =IFERROR(SUMPRODUCT(($M$7:$M$106>$M86)*1)+1,"")
...

Sheet 03 RANKINGS
A1: CHEAPEST AND MOST EXPENSIVE — WITHIN EACH ASSET CLASS
A2: The statistically defensible comparison. Each instrument is ranked only against others measured the same way.
A4: Left = cheapest in class (highest value score). Right = most expensive. Value score is the sign-corrected z-score, so +2.0 means two standard deviations CHEAP on that asset class's own metric, whatever that metric happens to be.
A6: EQUITY — measured on Forward P/E — 24 instruments
B7: CHEAPEST | C7: Instrument | D7: Ticker | E7: Value score | F7: Z (raw) | G7: Current | H7: 1y chg | J7: MOST EXPENSIVE | K7: Instrument | L7: Ticker | M7: Value score | N7: Z (raw) | O7: Current | P7: 1y chg
B8: 1 | C8: =IFERROR(INDEX('02 MONITOR'!$C$7:$C$106,SUMPRODUCT(('02 MONITOR'!$B$7:$B$106="EQUITY")*('02 MONITOR'!$P$7:$P$106=1)*(ROW('02 MONITOR'!$B$7:$B$106)-6))),"") | D8: =IFERROR(INDEX('02 MONITOR'!$D$7:$D$106,SUMPRODUCT(('02 MONITOR'!$B$7:$B$106="EQUITY")*('02 MONITOR'!$P$7:$P$106=1)*(ROW('02 MONITOR'!$B$7:$B$106)-6))),"") | E8: =IFERROR(INDEX('02 MONITOR'!$M$7:$M$106,SUMPRODUCT(('02 MONITOR'!$B$7:$B$106="EQUITY")*('02 MONITOR'!$P$7:$P$106=1)*(ROW('02 MONITOR'!$B$7:$B$106)-6))),"") | F8: =IFERROR(INDEX('02 MONITOR'!$K$7:$K$106,SUMPRODUCT(('02 MONITOR'!$B$7:$B$106="EQUITY")*('02 MONITOR'!$P$7:$P$106=1)*(ROW('02 MONITOR'!$B$7:$B$106)-6))),"") | G8: =IFERROR(INDEX('02 MONITOR'!$H$7:$H$106,SUMPRODUCT(('02 MONITOR'!$B$7:$B$106="EQUITY")*('02 MONITOR'!$P$7:$P$106=1)*(ROW('02 MONITOR'!$B$7:$B$106)-6))),"") | H8: =IFERROR(INDEX('02 MONITOR'!$O$7:$O$106,SUMPRODUCT(('02 MONITOR'!$B$7:$B$106="EQUITY")*('02 MONITOR'!$P$7:$P$106=1)*(ROW('02 MONITOR'!$B$7:$B$106)-6))),"") | J8: 1 | K8: =IFERROR(INDEX('02 MONITOR'!$C$7:$C$106,SUMPRODUCT(('02 MONITOR'!$B$7:$B$106="EQUITY")*('02 MONITOR'!$P$7:$P$106=24)*(ROW('02 MONITOR'!$B$7:$B$106)-6))),"") | L8: =IFERROR(INDEX('02 MONITOR'!$D$7:$D$106,SUMPRODUCT(('02 MONITOR'!$B$7:$B$106="EQUITY")*('02 MONITOR'!$P$7:$P$106=24)*(ROW('02 MONITOR'!$B$7:$B$106)-6))),"") | M8: =IFERROR(INDEX('02 MONITOR'!$M$7:$M$106,SUMPRODUCT(('02 MONITOR'!$B$7:$B$106="EQUITY")*('02 MONITOR'!$P$7:$P$106=24)*(ROW('02 MONITOR'!$B$7:$B$106)-6))),"") | N8: =IFERROR(INDEX('02 MONITOR'!$K$7:$K$106,SUMPRODUCT(('02 MONITOR'!$B$7:$B$106="EQUITY")*('02 MONITOR'!$P$7:$P$106=24)*(ROW('02 MONITOR'!$B$7:$B$106)-6))),"") | O8: =IFERROR(INDEX('02 MONITOR'!$H$7:$H$106,SUMPRODUCT(('02 MONITOR'!$B$7:$B$106="EQUITY")*('02 MONITOR'!$P$7:$P$106=24)*(ROW('02 MONITOR'!$B$7:$B$106)-6))),"") | P8: =IFERROR(INDEX('02 MONITOR'!$O$7:$O$106,SUMPRODUCT(('02 MONITOR'!$B$7:$B$106="EQUITY")*('02 MONITOR'!$P$7:$P$106=24)*(ROW('02 MONITOR'!$B$7:$B$106)-6))),"")
B9: 2 | C9: =IFERROR(INDEX('02 MONITOR'!$C$7:$C$106,SUMPRODUCT(('02 MONITOR'!$B$7:$B$106="EQUITY")*('02 MONITOR'!$P$7:$P$106=2)*(ROW('02 MONITOR'!$B$7:$B$106)-6))),"") | D9: =IFERROR(INDEX('02 MONITOR'!$D$7:$D$106,SUMPRODUCT(('02 MONITOR'!$B$7:$B$106="EQUITY")*('02 MONITOR'!$P$7:$P$106=2)*(ROW('02 MONITOR'!$B$7:$B$106)-6))),"") | E9: =IFERROR(INDEX('02 MONITOR'!$M$7:$M$106,SUMPRODUCT(('02 MONITOR'!$B$7:$B$106="EQUITY")*('02 MONITOR'!$P$7:$P$106=2)*(ROW('02 MONITOR'!$B$7:$B$106)-6))),"") | F9: =IFERROR(INDEX('02 MONITOR'!$K$7:$K$106,SUMPRODUCT(('02 MONITOR'!$B$7:$B$106="EQUITY")*('02 MONITOR'!$P$7:$P$106=2)*(ROW('02 MONITOR'!$B$7:$B$106)-6))),"") | G9: =IFERROR(INDEX('02 MONITOR'!$H$7:$H$106,SUMPRODUCT(('02 MONITOR'!$B$7:$B$106="EQUITY")*('02 MONITOR'!$P$7:$P$106=2)*(ROW('02 MONITOR'!$B$7:$B$106)-6))),"") | H9: =IFERROR(INDEX('02 MONITOR'!$O$7:$O$106,SUMPRODUCT(('02 MONITOR'!$B$7:$B$106="EQUITY")*('02 MONITOR'!$P$7:$P$106=2)*(ROW('02 MONITOR'!$B$7:$B$106)-6))),"") | J9: 2 | K9: =IFERROR(INDEX('02 MONITOR'!$C$7:$C$106,SUMPRODUCT(('02 MONITOR'!$B$7:$B$106="EQUITY")*('02 MONITOR'!$P$7:$P$106=23)*(ROW('02 MONITOR'!$B$7:$B$106)-6))),"") | L9: =IFERROR(INDEX('02 MONITOR'!$D$7:$D$106,SUMPRODUCT(('02 MONITOR'!$B$7:$B$106="EQUITY")*('02 MONITOR'!$P$7:$P$106=23)*(ROW('02 MONITOR'!$B$7:$B$106)-6))),"") | M9: =IFERROR(INDEX('02 MONITOR'!$M$7:$M$106,SUMPRODUCT(('02 MONITOR'!$B$7:$B$106="EQUITY")*('02 MONITOR'!$P$7:$P$106=23)*(ROW('02 MONITOR'!$B$7:$B$106)-6))),"") | N9: =IFERROR(INDEX('02 MONITOR'!$K$7:$K$106,SUMPRODUCT(('02 MONITOR'!$B$7:$B$106="EQUITY")*('02 MONITOR'!$P$7:$P$106=23)*(ROW('02 MONITOR'!$B$7:$B$106)-6))),"") | O9: =IFERROR(INDEX('02 MONITOR'!$H$7:$H$106,SUMPRODUCT(('02 MONITOR'!$B$7:$B$106="EQUITY")*('02 MONITOR'!$P$7:$P$106=23)*(ROW('02 MONITOR'!$B$7:$B$106)-6))),"") | P9: =IFERROR(INDEX('02 MONITOR'!$O$7:$O$106,SUMPRODUCT(('02 MONITOR'!$B$7:$B$106="EQUITY")*('02 MONITOR'!$P$7:$P$106=23)*(ROW('02 MONITOR'!$B$7:$B$106)-6))),"")
B10: 3 | C10: =IFERROR(INDEX('02 MONITOR'!$C$7:$C$106,SUMPRODUCT(('02 MONITOR'!$B$7:$B$106="EQUITY")*('02 MONITOR'!$P$7:$P$106=3)*(ROW('02 MONITOR'!$B$7:$B$106)-6))),"") | D10: =IFERROR(INDEX('02 MONITOR'!$D$7:$D$106,SUMPRODUCT(('02 MONITOR'!$B$7:$B$106="EQUITY")*('02 MONITOR'!$P$7:$P$106=3)*(ROW('02 MONITOR'!$B$7:$B$106)-6))),"") | E10: =IFERROR(INDEX('02 MONITOR'!$M$7:$M$106,SUMPRODUCT(('02 MONITOR'!$B$7:$B$106="EQUITY")*('02 MONITOR'!$P$7:$P$106=3)*(ROW('02 MONITOR'!$B$7:$B$106)-6))),"") | F10: =IFERROR(INDEX('02 MONITOR'!$K$7:$K$106,SUMPRODUCT(('02 MONITOR'!$B$7:$B$106="EQUITY")*('02 MONITOR'!$P$7:$P$106=3)*(ROW('02 MONITOR'!$B$7:$B$106)-6))),"") | G10: =IFERROR(INDEX('02 MONITOR'!$H$7:$H$106,SUMPRODUCT(('02 MONITOR'!$B$7:$B$106="EQUITY")*('02 MONITOR'!$P$7:$P$106=3)*(ROW('02 MONITOR'!$B$7:$B$106)-6))),"") | H10: =IFERROR(INDEX('02 MONITOR'!$O$7:$O$106,SUMPRODUCT(('02 MONITOR'!$B$7:$B$106="EQUITY")*('02 MONITOR'!$P$7:$P$106=3)*(ROW('02 MONITOR'!$B$7:$B$106)-6))),"") | J10: 3 | K10: =IFERROR(INDEX('02 MONITOR'!$C$7:$C$106,SUMPRODUCT(('02 MONITOR'!$B$7:$B$106="EQUITY")*('02 MONITOR'!$P$7:$P$106=22)*(ROW('02 MONITOR'!$B$7:$B$106)-6))),"") | L10: =IFERROR(INDEX('02 MONITOR'!$D$7:$D$106,SUMPRODUCT(('02 MONITOR'!$B$7:$B$106="EQUITY")*('02 MONITOR'!$P$7:$P$106=22)*(ROW('02 MONITOR'!$B$7:$B$106)-6))),"") | M10: =IFERROR(INDEX('02 MONITOR'!$M$7:$M$106,SUMPRODUCT(('02 MONITOR'!$B$7:$B$106="EQUITY")*('02 MONITOR'!$P$7:$P$106=22)*(ROW('02 MONITOR'!$B$7:$B$106)-6))),"") | N10: =IFERROR(INDEX('02 MONITOR'!$K$7:$K$106,SUMPRODUCT(('02 MONITOR'!$B$7:$B$106="EQUITY")*('02 MONITOR'!$P$7:$P$106=22)*(ROW('02 MONITOR'!$B$7:$B$106)-6))),"") | O10: =IFERROR(INDEX('02 MONITOR'!$H$7:$H$106,SUMPRODUCT(('02 MONITOR'!$B$7:$B$106="EQUITY")*('02 MONITOR'!$P$7:$P$106=22)*(ROW('02 MONITOR'!$B$7:$B$106)-6))),"") | P10: =IFERROR(INDEX('02 MONITOR'!$O$7:$O$106,SUMPRODUCT(('02 MONITOR'!$B$7:$B$106="EQUITY")*('02 MONITOR'!$P$7:$P$106=22)*(ROW('02 MONITOR'!$B$7:$B$106)-6))),"")
B11: 4 | C11: =IFERROR(INDEX('02 MONITOR'!$C$7:$C$106,SUMPRODUCT(('02 MONITOR'!$B$7:$B$106="EQUITY")*('02 MONITOR'!$P$7:$P$106=4)*(ROW('02 MONITOR'!$B$7:$B$106)-6))),"") | D11: =IFERROR(INDEX('02 MONITOR'!$D$7:$D$106,SUMPRODUCT(('02 MONITOR'!$B$7:$B$106="EQUITY")*('02 MONITOR'!$P$7:$P$106=4)*(ROW('02 MONITOR'!$B$7:$B$106)-6))),"") | E11: =IFERROR(INDEX('02 MONITOR'!$M$7:$M$106,SUMPRODUCT(('02 MONITOR'!$B$7:$B$106="EQUITY")*('02 MONITOR'!$P$7:$P$106=4)*(ROW('02 MONITOR'!$B$7:$B$106)-6))),"") | F11: =IFERROR(INDEX('02 MONITOR'!$K$7:$K$106,SUMPRODUCT(('02 MONITOR'!$B$7:$B$106="EQUITY")*('02 MONITOR'!$P$7:$P$106=4)*(ROW('02 MONITOR'!$B$7:$B$106)-6))),"") | G11: =IFERROR(INDEX('02 MONITOR'!$H$7:$H$106,SUMPRODUCT(('02 MONITOR'!$B$7:$B$106="EQUITY")*('02 MONITOR'!$P$7:$P$106=4)*(ROW('02 MONITOR'!$B$7:$B$106)-6))),"") | H11: =IFERROR(INDEX('02 MONITOR'!$O$7:$O$106,SUMPRODUCT(('02 MONITOR'!$B$7:$B$106="EQUITY")*('02 MONITOR'!$P$7:$P$106=4)*(ROW('02 MONITOR'!$B$7:$B$106)-6))),"") | J11: 4 | K11: =IFERROR(INDEX('02 MONITOR'!$C$7:$C$106,SUMPRODUCT(('02 MONITOR'!$B$7:$B$106="EQUITY")*('02 MONITOR'!$P$7:$P$106=21)*(ROW('02 MONITOR'!$B$7:$B$106)-6))),"") | L11: =IFERROR(INDEX('02 MONITOR'!$D$7:$D$106,SUMPRODUCT(('02 MONITOR'!$B$7:$B$106="EQUITY")*('02 MONITOR'!$P$7:$P$106=21)*(ROW('02 MONITOR'!$B$7:$B$106)-6))),"") | M11: =IFERROR(INDEX('02 MONITOR'!$M$7:$M$106,SUMPRODUCT(('02 MONITOR'!$B$7:$B$106="EQUITY")*('02 MONITOR'!$P$7:$P$106=21)*(ROW('02 MONITOR'!$B$7:$B$106)-6))),"") | N11: =IFERROR(INDEX('02 MONITOR'!$K$7:$K$106,SUMPRODUCT(('02 MONITOR'!$B$7:$B$106="EQUITY")*('02 MONITOR'!$P$7:$P$106=21)*(ROW('02 MONITOR'!$B$7:$B$106)-6))),"") | O11: =IFERROR(INDEX('02 MONITOR'!$H$7:$H$106,SUMPRODUCT(('02 MONITOR'!$B$7:$B$106="EQUITY")*('02 MONITOR'!$P$7:$P$106=21)*(ROW('02 MONITOR'!$B$7:$B$106)-6))),"") | P11: =IFERROR(INDEX('02 MONITOR'!$O$7:$O$106,SUMPRODUCT(('02 MONITOR'!$B$7:$B$106="EQUITY")*('02 MONITOR'!$P$7:$P$106=21)*(ROW('02 MONITOR'!$B$7:$B$106)-6))),"")
B12: 5 | C12: =IFERROR(INDEX('02 MONITOR'!$C$7:$C$106,SUMPRODUCT(('02 MONITOR'!$B$7:$B$106="EQUITY")*('02 MONITOR'!$P$7:$P$106=5)*(ROW('02 MONITOR'!$B$7:$B$106)-6))),"") | D12: =IFERROR(INDEX('02 MONITOR'!$D$7:$D$106,SUMPRODUCT(('02 MONITOR'!$B$7:$B$106="EQUITY")*('02 MONITOR'!$P$7:$P$106=5)*(ROW('02 MONITOR'!$B$7:$B$106)-6))),"") | E12: =IFERROR(INDEX('02 MONITOR'!$M$7:$M$106,SUMPRODUCT(('02 MONITOR'!$B$7:$B$106="EQUITY")*('02 MONITOR'!$P$7:$P$106=5)*(ROW('02 MONITOR'!$B$7:$B$106)-6))),"") | F12: =IFERROR(INDEX('02 MONITOR'!$K$7:$K$106,SUMPRODUCT(('02 MONITOR'!$B$7:$B$106="EQUITY")*('02 MONITOR'!$P$7:$P$106=5)*(ROW('02 MONITOR'!$B$7:$B$106)-6))),"") | G12: =IFERROR(INDEX('02 MONITOR'!$H$7:$H$106,SUMPRODUCT(('02 MONITOR'!$B$7:$B$106="EQUITY")*('02 MONITOR'!$P$7:$P$106=5)*(ROW('02 MONITOR'!$B$7:$B$106)-6))),"") | H12: =IFERROR(INDEX('02 MONITOR'!$O$7:$O$106,SUMPRODUCT(('02 MONITOR'!$B$7:$B$106="EQUITY")*('02 MONITOR'!$P$7:$P$106=5)*(ROW('02 MONITOR'!$B$7:$B$106)-6))),"") | J12: 5 | K12: =IFERROR(INDEX('02 MONITOR'!$C$7:$C$106,SUMPRODUCT(('02 MONITOR'!$B$7:$B$106="EQUITY")*('02 MONITOR'!$P$7:$P$106=20)*(ROW('02 MONITOR'!$B$7:$B$106)-6))),"") | L12: =IFERROR(INDEX('02 MONITOR'!$D$7:$D$106,SUMPRODUCT(('02 MONITOR'!$B$7:$B$106="EQUITY")*('02 MONITOR'!$P$7:$P$106=20)*(ROW('02 MONITOR'!$B$7:$B$106)-6))),"") | M12: =IFERROR(INDEX('02 MONITOR'!$M$7:$M$106,SUMPRODUCT(('02 MONITOR'!$B$7:$B$106="EQUITY")*('02 MONITOR'!$P$7:$P$106=20)*(ROW('02 MONITOR'!$B$7:$B$106)-6))),"") | N12: =IFERROR(INDEX('02 MONITOR'!$K$7:$K$106,SUMPRODUCT(('02 MONITOR'!$B$7:$B$106="EQUITY")*('02 MONITOR'!$P$7:$P$106=20)*(ROW('02 MONITOR'!$B$7:$B$106)-6))),"") | O12: =IFERROR(INDEX('02 MONITOR'!$H$7:$H$106,SUMPRODUCT(('02 MONITOR'!$B$7:$B$106="EQUITY")*('02 MONITOR'!$P$7:$P$106=20)*(ROW('02 MONITOR'!$B$7:$B$106)-6))),"") | P12: =IFERROR(INDEX('02 MONITOR'!$O$7:$O$106,SUMPRODUCT(('02 MONITOR'!$B$7:$B$106="EQUITY")*('02 MONITOR'!$P$7:$P$106=20)*(ROW('02 MONITOR'!$B$7:$B$106)-6))),"")
B13: 6 | C13: =IFERROR(INDEX('02 MONITOR'!$C$7:$C$106,SUMPRODUCT(('02 MONITOR'!$B$7:$B$106="EQUITY")*('02 MONITOR'!$P$7:$P$106=6)*(ROW('02 MONITOR'!$B$7:$B$106)-6))),"") | D13: =IFERROR(INDEX('02 MONITOR'!$D$7:$D$106,SUMPRODUCT(('02 MONITOR'!$B$7:$B$106="EQUITY")*('02 MONITOR'!$P$7:$P$106=6)*(ROW('02 MONITOR'!$B$7:$B$106)-6))),"") | E13: =IFERROR(INDEX('02 MONITOR'!$M$7:$M$106,SUMPRODUCT(('02 MONITOR'!$B$7:$B$106="EQUITY")*('02 MONITOR'!$P$7:$P$106=6)*(ROW('02 MONITOR'!$B$7:$B$106)-6))),"") | F13: =IFERROR(INDEX('02 MONITOR'!$K$7:$K$106,SUMPRODUCT(('02 MONITOR'!$B$7:$B$106="EQUITY")*('02 MONITOR'!$P$7:$P$106=6)*(ROW('02 MONITOR'!$B$7:$B$106)-6))),"") | G13: =IFERROR(INDEX('02 MONITOR'!$H$7:$H$106,SUMPRODUCT(('02 MONITOR'!$B$7:$B$106="EQUITY")*('02 MONITOR'!$P$7:$P$106=6)*(ROW('02 MONITOR'!$B$7:$B$106)-6))),"") | H13: =IFERROR(INDEX('02 MONITOR'!$O$7:$O$106,SUMPRODUCT(('02 MONITOR'!$B$7:$B$106="EQUITY")*('02 MONITOR'!$P$7:$P$106=6)*(ROW('02 MONITOR'!$B$7:$B$106)-6))),"") | J13: 6 | K13: =IFERROR(INDEX('02 MONITOR'!$C$7:$C$106,SUMPRODUCT(('02 MONITOR'!$B$7:$B$106="EQUITY")*('02 MONITOR'!$P$7:$P$106=19)*(ROW('02 MONITOR'!$B$7:$B$106)-6))),"") | L13: =IFERROR(INDEX('02 MONITOR'!$D$7:$D$106,SUMPRODUCT(('02 MONITOR'!$B$7:$B$106="EQUITY")*('02 MONITOR'!$P$7:$P$106=19)*(ROW('02 MONITOR'!$B$7:$B$106)-6))),"") | M13: =IFERROR(INDEX('02 MONITOR'!$M$7:$M$106,SUMPRODUCT(('02 MONITOR'!$B$7:$B$106="EQUITY")*('02 MONITOR'!$P$7:$P$106=19)*(ROW('02 MONITOR'!$B$7:$B$106)-6))),"") | N13: =IFERROR(INDEX('02 MONITOR'!$K$7:$K$106,SUMPRODUCT(('02 MONITOR'!$B$7:$B$106="EQUITY")*('02 MONITOR'!$P$7:$P$106=19)*(ROW('02 MONITOR'!$B$7:$B$106)-6))),"") | O13: =IFERROR(INDEX('02 MONITOR'!$H$7:$H$106,SUMPRODUCT(('02 MONITOR'!$B$7:$B$106="EQUITY")*('02 MONITOR'!$P$7:$P$106=19)*(ROW('02 MONITOR'!$B$7:$B$106)-6))),"") | P13: =IFERROR(INDEX('02 MONITOR'!$O$7:$O$106,SUMPRODUCT(('02 MONITOR'!$B$7:$B$106="EQUITY")*('02 MONITOR'!$P$7:$P$106=19)*(ROW('02 MONITOR'!$B$7:$B$106)-6))),"")
A15: RATES — measured on 10y nominal yield — 20 instruments
B16: CHEAPEST | C16: Instrument | D16: Ticker | E16: Value score | F16: Z (raw) | G16: Current | H16: 1y chg | J16: MOST EXPENSIVE | K16: Instrument | L16: Ticker | M16: Value score | N16: Z (raw) | O16: Current | P16: 1y chg
B17: 1 | C17: =IFERROR(INDEX('02 MONITOR'!$C$7:$C$106,SUMPRODUCT(('02 MONITOR'!$B$7:$B$106="RATES")*('02 MONITOR'!$P$7:$P$106=1)*(ROW('02 MONITOR'!$B$7:$B$106)-6))),"") | D17: =IFERROR(INDEX('02 MONITOR'!$D$7:$D$106,SUMPRODUCT(('02 MONITOR'!$B$7:$B$106="RATES")*('02 MONITOR'!$P$7:$P$106=1)*(ROW('02 MONITOR'!$B$7:$B$106)-6))),"") | E17: =IFERROR(INDEX('02 MONITOR'!$M$7:$M$106,SUMPRODUCT(('02 MONITOR'!$B$7:$B$106="RATES")*('02 MONITOR'!$P$7:$P$106=1)*(ROW('02 MONITOR'!$B$7:$B$106)-6))),"") | F17: =IFERROR(INDEX('02 MONITOR'!$K$7:$K$106,SUMPRODUCT(('02 MONITOR'!$B$7:$B$106="RATES")*('02 MONITOR'!$P$7:$P$106=1)*(ROW('02 MONITOR'!$B$7:$B$106)-6))),"") | G17: =IFERROR(INDEX('02 MONITOR'!$H$7:$H$106,SUMPRODUCT(('02 MONITOR'!$B$7:$B$106="RATES")*('02 MONITOR'!$P$7:$P$106=1)*(ROW('02 MONITOR'!$B$7:$B$106)-6))),"") | H17: =IFERROR(INDEX('02 MONITOR'!$O$7:$O$106,SUMPRODUCT(('02 MONITOR'!$B$7:$B$106="RATES")*('02 MONITOR'!$P$7:$P$106=1)*(ROW('02 MONITOR'!$B$7:$B$106)-6))),"") | J17: 1 | K17: =IFERROR(INDEX('02 MONITOR'!$C$7:$C$106,SUMPRODUCT(('02 MONITOR'!$B$7:$B$106="RATES")*('02 MONITOR'!$P$7:$P$106=20)*(ROW('02 MONITOR'!$B$7:$B$106)-6))),"") | L17: =IFERROR(INDEX('02 MONITOR'!$D$7:$D$106,SUMPRODUCT(('02 MONITOR'!$B$7:$B$106="RATES")*('02 MONITOR'!$P$7:$P$106=20)*(ROW('02 MONITOR'!$B$7:$B$106)-6))),"") | M17: =IFERROR(INDEX('02 MONITOR'!$M$7:$M$106,SUMPRODUCT(('02 MONITOR'!$B$7:$B$106="RATES")*('02 MONITOR'!$P$7:$P$106=20)*(ROW('02 MONITOR'!$B$7:$B$106)-6))),"") | N17: =IFERROR(INDEX('02 MONITOR'!$K$7:$K$106,SUMPRODUCT(('02 MONITOR'!$B$7:$B$106="RATES")*('02 MONITOR'!$P$7:$P$106=20)*(ROW('02 MONITOR'!$B$7:$B$106)-6))),"") | O17: =IFERROR(INDEX('02 MONITOR'!$H$7:$H$106,SUMPRODUCT(('02 MONITOR'!$B$7:$B$106="RATES")*('02 MONITOR'!$P$7:$P$106=20)*(ROW('02 MONITOR'!$B$7:$B$106)-6))),"") | P17: =IFERROR(INDEX('02 MONITOR'!$O$7:$O$106,SUMPRODUCT(('02 MONITOR'!$B$7:$B$106="RATES")*('02 MONITOR'!$P$7:$P$106=20)*(ROW('02 MONITOR'!$B$7:$B$106)-6))),"")
B18: 2 | C18: =IFERROR(INDEX('02 MONITOR'!$C$7:$C$106,SUMPRODUCT(('02 MONITOR'!$B$7:$B$106="RATES")*('02 MONITOR'!$P$7:$P$106=2)*(ROW('02 MONITOR'!$B$7:$B$106)-6))),"") | D18: =IFERROR(INDEX('02 MONITOR'!$D$7:$D$106,SUMPRODUCT(('02 MONITOR'!$B$7:$B$106="RATES")*('02 MONITOR'!$P$7:$P$106=2)*(ROW('02 MONITOR'!$B$7:$B$106)-6))),"") | E18: =IFERROR(INDEX('02 MONITOR'!$M$7:$M$106,SUMPRODUCT(('02 MONITOR'!$B$7:$B$106="RATES")*('02 MONITOR'!$P$7:$P$106=2)*(ROW('02 MONITOR'!$B$7:$B$106)-6))),"") | F18: =IFERROR(INDEX('02 MONITOR'!$K$7:$K$106,SUMPRODUCT(('02 MONITOR'!$B$7:$B$106="RATES")*('02 MONITOR'!$P$7:$P$106=2)*(ROW('02 MONITOR'!$B$7:$B$106)-6))),"") | G18: =IFERROR(INDEX('02 MONITOR'!$H$7:$H$106,SUMPRODUCT(('02 MONITOR'!$B$7:$B$106="RATES")*('02 MONITOR'!$P$7:$P$106=2)*(ROW('02 MONITOR'!$B$7:$B$106)-6))),"") | H18: =IFERROR(INDEX('02 MONITOR'!$O$7:$O$106,SUMPRODUCT(('02 MONITOR'!$B$7:$B$106="RATES")*('02 MONITOR'!$P$7:$P$106=2)*(ROW('02 MONITOR'!$B$7:$B$106)-6))),"") | J18: 2 | K18: =IFERROR(INDEX('02 MONITOR'!$C$7:$C$106,SUMPRODUCT(('02 MONITOR'!$B$7:$B$106="RATES")*('02 MONITOR'!$P$7:$P$106=19)*(ROW('02 MONITOR'!$B$7:$B$106)-6))),"") | L18: =IFERROR(INDEX('02 MONITOR'!$D$7:$D$106,SUMPRODUCT(('02 MONITOR'!$B$7:$B$106="RATES")*('02 MONITOR'!$P$7:$P$106=19)*(ROW('02 MONITOR'!$B$7:$B$106)-6))),"") | M18: =IFERROR(INDEX('02 MONITOR'!$M$7:$M$106,SUMPRODUCT(('02 MONITOR'!$B$7:$B$106="RATES")*('02 MONITOR'!$P$7:$P$106=19)*(ROW('02 MONITOR'!$B$7:$B$106)-6))),"") | N18: =IFERROR(INDEX('02 MONITOR'!$K$7:$K$106,SUMPRODUCT(('02 MONITOR'!$B$7:$B$106="RATES")*('02 MONITOR'!$P$7:$P$106=19)*(ROW('02 MONITOR'!$B$7:$B$106)-6))),"") | O18: =IFERROR(INDEX('02 MONITOR'!$H$7:$H$106,SUMPRODUCT(('02 MONITOR'!$B$7:$B$106="RATES")*('02 MONITOR'!$P$7:$P$106=19)*(ROW('02 MONITOR'!$B$7:$B$106)-6))),"") | P18: =IFERROR(INDEX('02 MONITOR'!$O$7:$O$106,SUMPRODUCT(('02 MONITOR'!$B$7:$B$106="RATES")*('02 MONITOR'!$P$7:$P$106=19)*(ROW('02 MONITOR'!$B$7:$B$106)-6))),"")
B19: 3 | C19: =IFERROR(INDEX('02 MONITOR'!$C$7:$C$106,SUMPRODUCT(('02 MONITOR'!$B$7:$B$106="RATES")*('02 MONITOR'!$P$7:$P$106=3)*(ROW('02 MONITOR'!$B$7:$B$106)-6))),"") | D19: =IFERROR(INDEX('02 MONITOR'!$D$7:$D$106,SUMPRODUCT(('02 MONITOR'!$B$7:$B$106="RATES")*('02 MONITOR'!$P$7:$P$106=3)*(ROW('02 MONITOR'!$B$7:$B$106)-6))),"") | E19: =IFERROR(INDEX('02 MONITOR'!$M$7:$M$106,SUMPRODUCT(('02 MONITOR'!$B$7:$B$106="RATES")*('02 MONITOR'!$P$7:$P$106=3)*(ROW('02 MONITOR'!$B$7:$B$106)-6))),"") | F19: =IFERROR(INDEX('02 MONITOR'!$K$7:$K$106,SUMPRODUCT(('02 MONITOR'!$B$7:$B$106="RATES")*('02 MONITOR'!$P$7:$P$106=3)*(ROW('02 MONITOR'!$B$7:$B$106)-6))),"") | G19: =IFERROR(INDEX('02 MONITOR'!$H$7:$H$106,SUMPRODUCT(('02 MONITOR'!$B$7:$B$106="RATES")*('02 MONITOR'!$P$7:$P$106=3)*(ROW('02 MONITOR'!$B$7:$B$106)-6))),"") | H19: =IFERROR(INDEX('02 MONITOR'!$O$7:$O$106,SUMPRODUCT(('02 MONITOR'!$B$7:$B$106="RATES")*('02 MONITOR'!$P$7:$P$106=3)*(ROW('02 MONITOR'!$B$7:$B$106)-6))),"") | J19: 3 | K19: =IFERROR(INDEX('02 MONITOR'!$C$7:$C$106,SUMPRODUCT(('02 MONITOR'!$B$7:$B$106="RATES")*('02 MONITOR'!$P$7:$P$106=18)*(ROW('02 MONITOR'!$B$7:$B$106)-6))),"") | L19: =IFERROR(INDEX('02 MONITOR'!$D$7:$D$106,SUMPRODUCT(('02 MONITOR'!$B$7:$B$106="RATES")*('02 MONITOR'!$P$7:$P$106=18)*(ROW('02 MONITOR'!$B$7:$B$106)-6))),"") | M19: =IFERROR(INDEX('02 MONITOR'!$M$7:$M$106,SUMPRODUCT(('02 MONITOR'!$B$7:$B$106="RATES")*('02 MONITOR'!$P$7:$P$106=18)*(ROW('02 MONITOR'!$B$7:$B$106)-6))),"") | N19: =IFERROR(INDEX('02 MONITOR'!$K$7:$K$106,SUMPRODUCT(('02 MONITOR'!$B$7:$B$106="RATES")*('02 MONITOR'!$P$7:$P$106=18)*(ROW('02 MONITOR'!$B$7:$B$106)-6))),"") | O19: =IFERROR(INDEX('02 MONITOR'!$H$7:$H$106,SUMPRODUCT(('02 MONITOR'!$B$7:$B$106="RATES")*('02 MONITOR'!$P$7:$P$106=18)*(ROW('02 MONITOR'!$B$7:$B$106)-6))),"") | P19: =IFERROR(INDEX('02 MONITOR'!$O$7:$O$106,SUMPRODUCT(('02 MONITOR'!$B$7:$B$106="RATES")*('02 MONITOR'!$P$7:$P$106=18)*(ROW('02 MONITOR'!$B$7:$B$106)-6))),"")
