Workbook

Sheet Data
A1: Global Equities — Total Return and Price Performance
A3: Refresh | B3: =Settings!B4 | D3: Custom date | E3: =Settings!B8
A5: Bloomberg Ticker | B5: Name | C5: Type | D5: Price | E5: TR YTD | F5: TR 1M | G5: TR 3M | H5: TR vs Custom | I5: Px YTD | J5: Px 1M | K5: Px 3M | L5: Px vs Custom
A6: US Broad
A7: SPX Index | B7: S&P 500 | C7: US Broad | D7: =IFERROR(BDP(A7,"PX_LAST"),"") | E7: =IFERROR(BDP(A7,"CUST_TRR_RETURN_HOLDING_PER","CUST_TRR_START_DT",Settings!$C$5,"CUST_TRR_END_DT",Settings!$C$4)/100,"") | F7: =IFERROR(BDP(A7,"CUST_TRR_RETURN_HOLDING_PER","CUST_TRR_START_DT",Settings!$C$6,"CUST_TRR_END_DT",Settings!$C$4)/100,"") | G7: =IFERROR(BDP(A7,"CUST_TRR_RETURN_HOLDING_PER","CUST_TRR_START_DT",Settings!$C$7,"CUST_TRR_END_DT",Settings!$C$4)/100,"") | H7: =IFERROR(BDP(A7,"CUST_TRR_RETURN_HOLDING_PER","CUST_TRR_START_DT",Settings!$C$8,"CUST_TRR_END_DT",Settings!$C$4)/100,"") | I7: =IFERROR(BDP(A7,"PX_LAST")/BDH(A7,"PX_LAST",Settings!$C$5,Settings!$C$5)-1,"") | J7: =IFERROR(BDP(A7,"PX_LAST")/BDH(A7,"PX_LAST",Settings!$C$6,Settings!$C$6)-1,"") | K7: =IFERROR(BDP(A7,"PX_LAST")/BDH(A7,"PX_LAST",Settings!$C$7,Settings!$C$7)-1,"") | L7: =IFERROR(BDP(A7,"PX_LAST")/BDH(A7,"PX_LAST",Settings!$C$8,Settings!$C$8)-1,"")
A8: SPW Index | B8: S&P 500 Equal Weight | C8: US Broad | D8: =IFERROR(BDP(A8,"PX_LAST"),"") | E8: =IFERROR(BDP(A8,"CUST_TRR_RETURN_HOLDING_PER","CUST_TRR_START_DT",Settings!$C$5,"CUST_TRR_END_DT",Settings!$C$4)/100,"") | F8: =IFERROR(BDP(A8,"CUST_TRR_RETURN_HOLDING_PER","CUST_TRR_START_DT",Settings!$C$6,"CUST_TRR_END_DT",Settings!$C$4)/100,"") | G8: =IFERROR(BDP(A8,"CUST_TRR_RETURN_HOLDING_PER","CUST_TRR_START_DT",Settings!$C$7,"CUST_TRR_END_DT",Settings!$C$4)/100,"") | H8: =IFERROR(BDP(A8,"CUST_TRR_RETURN_HOLDING_PER","CUST_TRR_START_DT",Settings!$C$8,"CUST_TRR_END_DT",Settings!$C$4)/100,"") | I8: =IFERROR(BDP(A8,"PX_LAST")/BDH(A8,"PX_LAST",Settings!$C$5,Settings!$C$5)-1,"") | J8: =IFERROR(BDP(A8,"PX_LAST")/BDH(A8,"PX_LAST",Settings!$C$6,Settings!$C$6)-1,"") | K8: =IFERROR(BDP(A8,"PX_LAST")/BDH(A8,"PX_LAST",Settings!$C$7,Settings!$C$7)-1,"") | L8: =IFERROR(BDP(A8,"PX_LAST")/BDH(A8,"PX_LAST",Settings!$C$8,Settings!$C$8)-1,"")
A9: NDX Index | B9: Nasdaq 100 | C9: US Broad | D9: =IFERROR(BDP(A9,"PX_LAST"),"") | E9: =IFERROR(BDP(A9,"CUST_TRR_RETURN_HOLDING_PER","CUST_TRR_START_DT",Settings!$C$5,"CUST_TRR_END_DT",Settings!$C$4)/100,"") | F9: =IFERROR(BDP(A9,"CUST_TRR_RETURN_HOLDING_PER","CUST_TRR_START_DT",Settings!$C$6,"CUST_TRR_END_DT",Settings!$C$4)/100,"") | G9: =IFERROR(BDP(A9,"CUST_TRR_RETURN_HOLDING_PER","CUST_TRR_START_DT",Settings!$C$7,"CUST_TRR_END_DT",Settings!$C$4)/100,"") | H9: =IFERROR(BDP(A9,"CUST_TRR_RETURN_HOLDING_PER","CUST_TRR_START_DT",Settings!$C$8,"CUST_TRR_END_DT",Settings!$C$4)/100,"") | I9: =IFERROR(BDP(A9,"PX_LAST")/BDH(A9,"PX_LAST",Settings!$C$5,Settings!$C$5)-1,"") | J9: =IFERROR(BDP(A9,"PX_LAST")/BDH(A9,"PX_LAST",Settings!$C$6,Settings!$C$6)-1,"") | K9: =IFERROR(BDP(A9,"PX_LAST")/BDH(A9,"PX_LAST",Settings!$C$7,Settings!$C$7)-1,"") | L9: =IFERROR(BDP(A9,"PX_LAST")/BDH(A9,"PX_LAST",Settings!$C$8,Settings!$C$8)-1,"")
A10: INDU Index | B10: Dow Jones Industrial Avg | C10: US Broad | D10: =IFERROR(BDP(A10,"PX_LAST"),"") | E10: =IFERROR(BDP(A10,"CUST_TRR_RETURN_HOLDING_PER","CUST_TRR_START_DT",Settings!$C$5,"CUST_TRR_END_DT",Settings!$C$4)/100,"") | F10: =IFERROR(BDP(A10,"CUST_TRR_RETURN_HOLDING_PER","CUST_TRR_START_DT",Settings!$C$6,"CUST_TRR_END_DT",Settings!$C$4)/100,"") | G10: =IFERROR(BDP(A10,"CUST_TRR_RETURN_HOLDING_PER","CUST_TRR_START_DT",Settings!$C$7,"CUST_TRR_END_DT",Settings!$C$4)/100,"") | H10: =IFERROR(BDP(A10,"CUST_TRR_RETURN_HOLDING_PER","CUST_TRR_START_DT",Settings!$C$8,"CUST_TRR_END_DT",Settings!$C$4)/100,"") | I10: =IFERROR(BDP(A10,"PX_LAST")/BDH(A10,"PX_LAST",Settings!$C$5,Settings!$C$5)-1,"") | J10: =IFERROR(BDP(A10,"PX_LAST")/BDH(A10,"PX_LAST",Settings!$C$6,Settings!$C$6)-1,"") | K10: =IFERROR(BDP(A10,"PX_LAST")/BDH(A10,"PX_LAST",Settings!$C$7,Settings!$C$7)-1,"") | L10: =IFERROR(BDP(A10,"PX_LAST")/BDH(A10,"PX_LAST",Settings!$C$8,Settings!$C$8)-1,"")
A11: RTY Index | B11: Russell 2000 | C11: US Broad | D11: =IFERROR(BDP(A11,"PX_LAST"),"") | E11: =IFERROR(BDP(A11,"CUST_TRR_RETURN_HOLDING_PER","CUST_TRR_START_DT",Settings!$C$5,"CUST_TRR_END_DT",Settings!$C$4)/100,"") | F11: =IFERROR(BDP(A11,"CUST_TRR_RETURN_HOLDING_PER","CUST_TRR_START_DT",Settings!$C$6,"CUST_TRR_END_DT",Settings!$C$4)/100,"") | G11: =IFERROR(BDP(A11,"CUST_TRR_RETURN_HOLDING_PER","CUST_TRR_START_DT",Settings!$C$7,"CUST_TRR_END_DT",Settings!$C$4)/100,"") | H11: =IFERROR(BDP(A11,"CUST_TRR_RETURN_HOLDING_PER","CUST_TRR_START_DT",Settings!$C$8,"CUST_TRR_END_DT",Settings!$C$4)/100,"") | I11: =IFERROR(BDP(A11,"PX_LAST")/BDH(A11,"PX_LAST",Settings!$C$5,Settings!$C$5)-1,"") | J11: =IFERROR(BDP(A11,"PX_LAST")/BDH(A11,"PX_LAST",Settings!$C$6,Settings!$C$6)-1,"") | K11: =IFERROR(BDP(A11,"PX_LAST")/BDH(A11,"PX_LAST",Settings!$C$7,Settings!$C$7)-1,"") | L11: =IFERROR(BDP(A11,"PX_LAST")/BDH(A11,"PX_LAST",Settings!$C$8,Settings!$C$8)-1,"")
A12: RAY Index | B12: Russell 3000 | C12: US Broad | D12: =IFERROR(BDP(A12,"PX_LAST"),"") | E12: =IFERROR(BDP(A12,"CUST_TRR_RETURN_HOLDING_PER","CUST_TRR_START_DT",Settings!$C$5,"CUST_TRR_END_DT",Settings!$C$4)/100,"") | F12: =IFERROR(BDP(A12,"CUST_TRR_RETURN_HOLDING_PER","CUST_TRR_START_DT",Settings!$C$6,"CUST_TRR_END_DT",Settings!$C$4)/100,"") | G12: =IFERROR(BDP(A12,"CUST_TRR_RETURN_HOLDING_PER","CUST_TRR_START_DT",Settings!$C$7,"CUST_TRR_END_DT",Settings!$C$4)/100,"") | H12: =IFERROR(BDP(A12,"CUST_TRR_RETURN_HOLDING_PER","CUST_TRR_START_DT",Settings!$C$8,"CUST_TRR_END_DT",Settings!$C$4)/100,"") | I12: =IFERROR(BDP(A12,"PX_LAST")/BDH(A12,"PX_LAST",Settings!$C$5,Settings!$C$5)-1,"") | J12: =IFERROR(BDP(A12,"PX_LAST")/BDH(A12,"PX_LAST",Settings!$C$6,Settings!$C$6)-1,"") | K12: =IFERROR(BDP(A12,"PX_LAST")/BDH(A12,"PX_LAST",Settings!$C$7,Settings!$C$7)-1,"") | L12: =IFERROR(BDP(A12,"PX_LAST")/BDH(A12,"PX_LAST",Settings!$C$8,Settings!$C$8)-1,"")
A13: MID Index | B13: S&P MidCap 400 | C13: US Broad | D13: =IFERROR(BDP(A13,"PX_LAST"),"") | E13: =IFERROR(BDP(A13,"CUST_TRR_RETURN_HOLDING_PER","CUST_TRR_START_DT",Settings!$C$5,"CUST_TRR_END_DT",Settings!$C$4)/100,"") | F13: =IFERROR(BDP(A13,"CUST_TRR_RETURN_HOLDING_PER","CUST_TRR_START_DT",Settings!$C$6,"CUST_TRR_END_DT",Settings!$C$4)/100,"") | G13: =IFERROR(BDP(A13,"CUST_TRR_RETURN_HOLDING_PER","CUST_TRR_START_DT",Settings!$C$7,"CUST_TRR_END_DT",Settings!$C$4)/100,"") | H13: =IFERROR(BDP(A13,"CUST_TRR_RETURN_HOLDING_PER","CUST_TRR_START_DT",Settings!$C$8,"CUST_TRR_END_DT",Settings!$C$4)/100,"") | I13: =IFERROR(BDP(A13,"PX_LAST")/BDH(A13,"PX_LAST",Settings!$C$5,Settings!$C$5)-1,"") | J13: =IFERROR(BDP(A13,"PX_LAST")/BDH(A13,"PX_LAST",Settings!$C$6,Settings!$C$6)-1,"") | K13: =IFERROR(BDP(A13,"PX_LAST")/BDH(A13,"PX_LAST",Settings!$C$7,Settings!$C$7)-1,"") | L13: =IFERROR(BDP(A13,"PX_LAST")/BDH(A13,"PX_LAST",Settings!$C$8,Settings!$C$8)-1,"")
A14: SML Index | B14: S&P SmallCap 600 | C14: US Broad | D14: =IFERROR(BDP(A14,"PX_LAST"),"") | E14: =IFERROR(BDP(A14,"CUST_TRR_RETURN_HOLDING_PER","CUST_TRR_START_DT",Settings!$C$5,"CUST_TRR_END_DT",Settings!$C$4)/100,"") | F14: =IFERROR(BDP(A14,"CUST_TRR_RETURN_HOLDING_PER","CUST_TRR_START_DT",Settings!$C$6,"CUST_TRR_END_DT",Settings!$C$4)/100,"") | G14: =IFERROR(BDP(A14,"CUST_TRR_RETURN_HOLDING_PER","CUST_TRR_START_DT",Settings!$C$7,"CUST_TRR_END_DT",Settings!$C$4)/100,"") | H14: =IFERROR(BDP(A14,"CUST_TRR_RETURN_HOLDING_PER","CUST_TRR_START_DT",Settings!$C$8,"CUST_TRR_END_DT",Settings!$C$4)/100,"") | I14: =IFERROR(BDP(A14,"PX_LAST")/BDH(A14,"PX_LAST",Settings!$C$5,Settings!$C$5)-1,"") | J14: =IFERROR(BDP(A14,"PX_LAST")/BDH(A14,"PX_LAST",Settings!$C$6,Settings!$C$6)-1,"") | K14: =IFERROR(BDP(A14,"PX_LAST")/BDH(A14,"PX_LAST",Settings!$C$7,Settings!$C$7)-1,"") | L14: =IFERROR(BDP(A14,"PX_LAST")/BDH(A14,"PX_LAST",Settings!$C$8,Settings!$C$8)-1,"")
A15: S&P 500 Sector
A16: S5INFT Index | B16: S&P 500 Information Technology | C16: S&P 500 Sector | D16: =IFERROR(BDP(A16,"PX_LAST"),"") | E16: =IFERROR(BDP(A16,"CUST_TRR_RETURN_HOLDING_PER","CUST_TRR_START_DT",Settings!$C$5,"CUST_TRR_END_DT",Settings!$C$4)/100,"") | F16: =IFERROR(BDP(A16,"CUST_TRR_RETURN_HOLDING_PER","CUST_TRR_START_DT",Settings!$C$6,"CUST_TRR_END_DT",Settings!$C$4)/100,"") | G16: =IFERROR(BDP(A16,"CUST_TRR_RETURN_HOLDING_PER","CUST_TRR_START_DT",Settings!$C$7,"CUST_TRR_END_DT",Settings!$C$4)/100,"") | H16: =IFERROR(BDP(A16,"CUST_TRR_RETURN_HOLDING_PER","CUST_TRR_START_DT",Settings!$C$8,"CUST_TRR_END_DT",Settings!$C$4)/100,"") | I16: =IFERROR(BDP(A16,"PX_LAST")/BDH(A16,"PX_LAST",Settings!$C$5,Settings!$C$5)-1,"") | J16: =IFERROR(BDP(A16,"PX_LAST")/BDH(A16,"PX_LAST",Settings!$C$6,Settings!$C$6)-1,"") | K16: =IFERROR(BDP(A16,"PX_LAST")/BDH(A16,"PX_LAST",Settings!$C$7,Settings!$C$7)-1,"") | L16: =IFERROR(BDP(A16,"PX_LAST")/BDH(A16,"PX_LAST",Settings!$C$8,Settings!$C$8)-1,"")
A17: S5TELS Index | B17: S&P 500 Communication Services | C17: S&P 500 Sector | D17: =IFERROR(BDP(A17,"PX_LAST"),"") | E17: =IFERROR(BDP(A17,"CUST_TRR_RETURN_HOLDING_PER","CUST_TRR_START_DT",Settings!$C$5,"CUST_TRR_END_DT",Settings!$C$4)/100,"") | F17: =IFERROR(BDP(A17,"CUST_TRR_RETURN_HOLDING_PER","CUST_TRR_START_DT",Settings!$C$6,"CUST_TRR_END_DT",Settings!$C$4)/100,"") | G17: =IFERROR(BDP(A17,"CUST_TRR_RETURN_HOLDING_PER","CUST_TRR_START_DT",Settings!$C$7,"CUST_TRR_END_DT",Settings!$C$4)/100,"") | H17: =IFERROR(BDP(A17,"CUST_TRR_RETURN_HOLDING_PER","CUST_TRR_START_DT",Settings!$C$8,"CUST_TRR_END_DT",Settings!$C$4)/100,"") | I17: =IFERROR(BDP(A17,"PX_LAST")/BDH(A17,"PX_LAST",Settings!$C$5,Settings!$C$5)-1,"") | J17: =IFERROR(BDP(A17,"PX_LAST")/BDH(A17,"PX_LAST",Settings!$C$6,Settings!$C$6)-1,"") | K17: =IFERROR(BDP(A17,"PX_LAST")/BDH(A17,"PX_LAST",Settings!$C$7,Settings!$C$7)-1,"") | L17: =IFERROR(BDP(A17,"PX_LAST")/BDH(A17,"PX_LAST",Settings!$C$8,Settings!$C$8)-1,"")
A18: S5COND Index | B18: S&P 500 Consumer Discretionary | C18: S&P 500 Sector | D18: =IFERROR(BDP(A18,"PX_LAST"),"") | E18: =IFERROR(BDP(A18,"CUST_TRR_RETURN_HOLDING_PER","CUST_TRR_START_DT",Settings!$C$5,"CUST_TRR_END_DT",Settings!$C$4)/100,"") | F18: =IFERROR(BDP(A18,"CUST_TRR_RETURN_HOLDING_PER","CUST_TRR_START_DT",Settings!$C$6,"CUST_TRR_END_DT",Settings!$C$4)/100,"") | G18: =IFERROR(BDP(A18,"CUST_TRR_RETURN_HOLDING_PER","CUST_TRR_START_DT",Settings!$C$7,"CUST_TRR_END_DT",Settings!$C$4)/100,"") | H18: =IFERROR(BDP(A18,"CUST_TRR_RETURN_HOLDING_PER","CUST_TRR_START_DT",Settings!$C$8,"CUST_TRR_END_DT",Settings!$C$4)/100,"") | I18: =IFERROR(BDP(A18,"PX_LAST")/BDH(A18,"PX_LAST",Settings!$C$5,Settings!$C$5)-1,"") | J18: =IFERROR(BDP(A18,"PX_LAST")/BDH(A18,"PX_LAST",Settings!$C$6,Settings!$C$6)-1,"") | K18: =IFERROR(BDP(A18,"PX_LAST")/BDH(A18,"PX_LAST",Settings!$C$7,Settings!$C$7)-1,"") | L18: =IFERROR(BDP(A18,"PX_LAST")/BDH(A18,"PX_LAST",Settings!$C$8,Settings!$C$8)-1,"")
A19: S5CONS Index | B19: S&P 500 Consumer Staples | C19: S&P 500 Sector | D19: =IFERROR(BDP(A19,"PX_LAST"),"") | E19: =IFERROR(BDP(A19,"CUST_TRR_RETURN_HOLDING_PER","CUST_TRR_START_DT",Settings!$C$5,"CUST_TRR_END_DT",Settings!$C$4)/100,"") | F19: =IFERROR(BDP(A19,"CUST_TRR_RETURN_HOLDING_PER","CUST_TRR_START_DT",Settings!$C$6,"CUST_TRR_END_DT",Settings!$C$4)/100,"") | G19: =IFERROR(BDP(A19,"CUST_TRR_RETURN_HOLDING_PER","CUST_TRR_START_DT",Settings!$C$7,"CUST_TRR_END_DT",Settings!$C$4)/100,"") | H19: =IFERROR(BDP(A19,"CUST_TRR_RETURN_HOLDING_PER","CUST_TRR_START_DT",Settings!$C$8,"CUST_TRR_END_DT",Settings!$C$4)/100,"") | I19: =IFERROR(BDP(A19,"PX_LAST")/BDH(A19,"PX_LAST",Settings!$C$5,Settings!$C$5)-1,"") | J19: =IFERROR(BDP(A19,"PX_LAST")/BDH(A19,"PX_LAST",Settings!$C$6,Settings!$C$6)-1,"") | K19: =IFERROR(BDP(A19,"PX_LAST")/BDH(A19,"PX_LAST",Settings!$C$7,Settings!$C$7)-1,"") | L19: =IFERROR(BDP(A19,"PX_LAST")/BDH(A19,"PX_LAST",Settings!$C$8,Settings!$C$8)-1,"")
A20: S5ENRS Index | B20: S&P 500 Energy | C20: S&P 500 Sector | D20: =IFERROR(BDP(A20,"PX_LAST"),"") | E20: =IFERROR(BDP(A20,"CUST_TRR_RETURN_HOLDING_PER","CUST_TRR_START_DT",Settings!$C$5,"CUST_TRR_END_DT",Settings!$C$4)/100,"") | F20: =IFERROR(BDP(A20,"CUST_TRR_RETURN_HOLDING_PER","CUST_TRR_START_DT",Settings!$C$6,"CUST_TRR_END_DT",Settings!$C$4)/100,"") | G20: =IFERROR(BDP(A20,"CUST_TRR_RETURN_HOLDING_PER","CUST_TRR_START_DT",Settings!$C$7,"CUST_TRR_END_DT",Settings!$C$4)/100,"") | H20: =IFERROR(BDP(A20,"CUST_TRR_RETURN_HOLDING_PER","CUST_TRR_START_DT",Settings!$C$8,"CUST_TRR_END_DT",Settings!$C$4)/100,"") | I20: =IFERROR(BDP(A20,"PX_LAST")/BDH(A20,"PX_LAST",Settings!$C$5,Settings!$C$5)-1,"") | J20: =IFERROR(BDP(A20,"PX_LAST")/BDH(A20,"PX_LAST",Settings!$C$6,Settings!$C$6)-1,"") | K20: =IFERROR(BDP(A20,"PX_LAST")/BDH(A20,"PX_LAST",Settings!$C$7,Settings!$C$7)-1,"") | L20: =IFERROR(BDP(A20,"PX_LAST")/BDH(A20,"PX_LAST",Settings!$C$8,Settings!$C$8)-1,"")
A21: S5FINL Index | B21: S&P 500 Financials | C21: S&P 500 Sector | D21: =IFERROR(BDP(A21,"PX_LAST"),"") | E21: =IFERROR(BDP(A21,"CUST_TRR_RETURN_HOLDING_PER","CUST_TRR_START_DT",Settings!$C$5,"CUST_TRR_END_DT",Settings!$C$4)/100,"") | F21: =IFERROR(BDP(A21,"CUST_TRR_RETURN_HOLDING_PER","CUST_TRR_START_DT",Settings!$C$6,"CUST_TRR_END_DT",Settings!$C$4)/100,"") | G21: =IFERROR(BDP(A21,"CUST_TRR_RETURN_HOLDING_PER","CUST_TRR_START_DT",Settings!$C$7,"CUST_TRR_END_DT",Settings!$C$4)/100,"") | H21: =IFERROR(BDP(A21,"CUST_TRR_RETURN_HOLDING_PER","CUST_TRR_START_DT",Settings!$C$8,"CUST_TRR_END_DT",Settings!$C$4)/100,"") | I21: =IFERROR(BDP(A21,"PX_LAST")/BDH(A21,"PX_LAST",Settings!$C$5,Settings!$C$5)-1,"") | J21: =IFERROR(BDP(A21,"PX_LAST")/BDH(A21,"PX_LAST",Settings!$C$6,Settings!$C$6)-1,"") | K21: =IFERROR(BDP(A21,"PX_LAST")/BDH(A21,"PX_LAST",Settings!$C$7,Settings!$C$7)-1,"") | L21: =IFERROR(BDP(A21,"PX_LAST")/BDH(A21,"PX_LAST",Settings!$C$8,Settings!$C$8)-1,"")
A22: S5HLTH Index | B22: S&P 500 Health Care | C22: S&P 500 Sector | D22: =IFERROR(BDP(A22,"PX_LAST"),"") | E22: =IFERROR(BDP(A22,"CUST_TRR_RETURN_HOLDING_PER","CUST_TRR_START_DT",Settings!$C$5,"CUST_TRR_END_DT",Settings!$C$4)/100,"") | F22: =IFERROR(BDP(A22,"CUST_TRR_RETURN_HOLDING_PER","CUST_TRR_START_DT",Settings!$C$6,"CUST_TRR_END_DT",Settings!$C$4)/100,"") | G22: =IFERROR(BDP(A22,"CUST_TRR_RETURN_HOLDING_PER","CUST_TRR_START_DT",Settings!$C$7,"CUST_TRR_END_DT",Settings!$C$4)/100,"") | H22: =IFERROR(BDP(A22,"CUST_TRR_RETURN_HOLDING_PER","CUST_TRR_START_DT",Settings!$C$8,"CUST_TRR_END_DT",Settings!$C$4)/100,"") | I22: =IFERROR(BDP(A22,"PX_LAST")/BDH(A22,"PX_LAST",Settings!$C$5,Settings!$C$5)-1,"") | J22: =IFERROR(BDP(A22,"PX_LAST")/BDH(A22,"PX_LAST",Settings!$C$6,Settings!$C$6)-1,"") | K22: =IFERROR(BDP(A22,"PX_LAST")/BDH(A22,"PX_LAST",Settings!$C$7,Settings!$C$7)-1,"") | L22: =IFERROR(BDP(A22,"PX_LAST")/BDH(A22,"PX_LAST",Settings!$C$8,Settings!$C$8)-1,"")
A23: S5INDU Index | B23: S&P 500 Industrials | C23: S&P 500 Sector | D23: =IFERROR(BDP(A23,"PX_LAST"),"") | E23: =IFERROR(BDP(A23,"CUST_TRR_RETURN_HOLDING_PER","CUST_TRR_START_DT",Settings!$C$5,"CUST_TRR_END_DT",Settings!$C$4)/100,"") | F23: =IFERROR(BDP(A23,"CUST_TRR_RETURN_HOLDING_PER","CUST_TRR_START_DT",Settings!$C$6,"CUST_TRR_END_DT",Settings!$C$4)/100,"") | G23: =IFERROR(BDP(A23,"CUST_TRR_RETURN_HOLDING_PER","CUST_TRR_START_DT",Settings!$C$7,"CUST_TRR_END_DT",Settings!$C$4)/100,"") | H23: =IFERROR(BDP(A23,"CUST_TRR_RETURN_HOLDING_PER","CUST_TRR_START_DT",Settings!$C$8,"CUST_TRR_END_DT",Settings!$C$4)/100,"") | I23: =IFERROR(BDP(A23,"PX_LAST")/BDH(A23,"PX_LAST",Settings!$C$5,Settings!$C$5)-1,"") | J23: =IFERROR(BDP(A23,"PX_LAST")/BDH(A23,"PX_LAST",Settings!$C$6,Settings!$C$6)-1,"") | K23: =IFERROR(BDP(A23,"PX_LAST")/BDH(A23,"PX_LAST",Settings!$C$7,Settings!$C$7)-1,"") | L23: =IFERROR(BDP(A23,"PX_LAST")/BDH(A23,"PX_LAST",Settings!$C$8,Settings!$C$8)-1,"")
A24: S5MATR Index | B24: S&P 500 Materials | C24: S&P 500 Sector | D24: =IFERROR(BDP(A24,"PX_LAST"),"") | E24: =IFERROR(BDP(A24,"CUST_TRR_RETURN_HOLDING_PER","CUST_TRR_START_DT",Settings!$C$5,"CUST_TRR_END_DT",Settings!$C$4)/100,"") | F24: =IFERROR(BDP(A24,"CUST_TRR_RETURN_HOLDING_PER","CUST_TRR_START_DT",Settings!$C$6,"CUST_TRR_END_DT",Settings!$C$4)/100,"") | G24: =IFERROR(BDP(A24,"CUST_TRR_RETURN_HOLDING_PER","CUST_TRR_START_DT",Settings!$C$7,"CUST_TRR_END_DT",Settings!$C$4)/100,"") | H24: =IFERROR(BDP(A24,"CUST_TRR_RETURN_HOLDING_PER","CUST_TRR_START_DT",Settings!$C$8,"CUST_TRR_END_DT",Settings!$C$4)/100,"") | I24: =IFERROR(BDP(A24,"PX_LAST")/BDH(A24,"PX_LAST",Settings!$C$5,Settings!$C$5)-1,"") | J24: =IFERROR(BDP(A24,"PX_LAST")/BDH(A24,"PX_LAST",Settings!$C$6,Settings!$C$6)-1,"") | K24: =IFERROR(BDP(A24,"PX_LAST")/BDH(A24,"PX_LAST",Settings!$C$7,Settings!$C$7)-1,"") | L24: =IFERROR(BDP(A24,"PX_LAST")/BDH(A24,"PX_LAST",Settings!$C$8,Settings!$C$8)-1,"")
A25: S5RLST Index | B25: S&P 500 Real Estate | C25: S&P 500 Sector | D25: =IFERROR(BDP(A25,"PX_LAST"),"") | E25: =IFERROR(BDP(A25,"CUST_TRR_RETURN_HOLDING_PER","CUST_TRR_START_DT",Settings!$C$5,"CUST_TRR_END_DT",Settings!$C$4)/100,"") | F25: =IFERROR(BDP(A25,"CUST_TRR_RETURN_HOLDING_PER","CUST_TRR_START_DT",Settings!$C$6,"CUST_TRR_END_DT",Settings!$C$4)/100,"") | G25: =IFERROR(BDP(A25,"CUST_TRR_RETURN_HOLDING_PER","CUST_TRR_START_DT",Settings!$C$7,"CUST_TRR_END_DT",Settings!$C$4)/100,"") | H25: =IFERROR(BDP(A25,"CUST_TRR_RETURN_HOLDING_PER","CUST_TRR_START_DT",Settings!$C$8,"CUST_TRR_END_DT",Settings!$C$4)/100,"") | I25: =IFERROR(BDP(A25,"PX_LAST")/BDH(A25,"PX_LAST",Settings!$C$5,Settings!$C$5)-1,"") | J25: =IFERROR(BDP(A25,"PX_LAST")/BDH(A25,"PX_LAST",Settings!$C$6,Settings!$C$6)-1,"") | K25: =IFERROR(BDP(A25,"PX_LAST")/BDH(A25,"PX_LAST",Settings!$C$7,Settings!$C$7)-1,"") | L25: =IFERROR(BDP(A25,"PX_LAST")/BDH(A25,"PX_LAST",Settings!$C$8,Settings!$C$8)-1,"")
A26: S5UTIL Index | B26: S&P 500 Utilities | C26: S&P 500 Sector | D26: =IFERROR(BDP(A26,"PX_LAST"),"") | E26: =IFERROR(BDP(A26,"CUST_TRR_RETURN_HOLDING_PER","CUST_TRR_START_DT",Settings!$C$5,"CUST_TRR_END_DT",Settings!$C$4)/100,"") | F26: =IFERROR(BDP(A26,"CUST_TRR_RETURN_HOLDING_PER","CUST_TRR_START_DT",Settings!$C$6,"CUST_TRR_END_DT",Settings!$C$4)/100,"") | G26: =IFERROR(BDP(A26,"CUST_TRR_RETURN_HOLDING_PER","CUST_TRR_START_DT",Settings!$C$7,"CUST_TRR_END_DT",Settings!$C$4)/100,"") | H26: =IFERROR(BDP(A26,"CUST_TRR_RETURN_HOLDING_PER","CUST_TRR_START_DT",Settings!$C$8,"CUST_TRR_END_DT",Settings!$C$4)/100,"") | I26: =IFERROR(BDP(A26,"PX_LAST")/BDH(A26,"PX_LAST",Settings!$C$5,Settings!$C$5)-1,"") | J26: =IFERROR(BDP(A26,"PX_LAST")/BDH(A26,"PX_LAST",Settings!$C$6,Settings!$C$6)-1,"") | K26: =IFERROR(BDP(A26,"PX_LAST")/BDH(A26,"PX_LAST",Settings!$C$7,Settings!$C$7)-1,"") | L26: =IFERROR(BDP(A26,"PX_LAST")/BDH(A26,"PX_LAST",Settings!$C$8,Settings!$C$8)-1,"")
A27: MSCI Aggregate
A28: MXWD Index | B28: MSCI ACWI | C28: MSCI Aggregate | D28: =IFERROR(BDP(A28,"PX_LAST"),"") | E28: =IFERROR(BDP(A28,"CUST_TRR_RETURN_HOLDING_PER","CUST_TRR_START_DT",Settings!$C$5,"CUST_TRR_END_DT",Settings!$C$4)/100,"") | F28: =IFERROR(BDP(A28,"CUST_TRR_RETURN_HOLDING_PER","CUST_TRR_START_DT",Settings!$C$6,"CUST_TRR_END_DT",Settings!$C$4)/100,"") | G28: =IFERROR(BDP(A28,"CUST_TRR_RETURN_HOLDING_PER","CUST_TRR_START_DT",Settings!$C$7,"CUST_TRR_END_DT",Settings!$C$4)/100,"") | H28: =IFERROR(BDP(A28,"CUST_TRR_RETURN_HOLDING_PER","CUST_TRR_START_DT",Settings!$C$8,"CUST_TRR_END_DT",Settings!$C$4)/100,"") | I28: =IFERROR(BDP(A28,"PX_LAST")/BDH(A28,"PX_LAST",Settings!$C$5,Settings!$C$5)-1,"") | J28: =IFERROR(BDP(A28,"PX_LAST")/BDH(A28,"PX_LAST",Settings!$C$6,Settings!$C$6)-1,"") | K28: =IFERROR(BDP(A28,"PX_LAST")/BDH(A28,"PX_LAST",Settings!$C$7,Settings!$C$7)-1,"") | L28: =IFERROR(BDP(A28,"PX_LAST")/BDH(A28,"PX_LAST",Settings!$C$8,Settings!$C$8)-1,"")
A29: MXWO Index | B29: MSCI World (DM) | C29: MSCI Aggregate | D29: =IFERROR(BDP(A29,"PX_LAST"),"") | E29: =IFERROR(BDP(A29,"CUST_TRR_RETURN_HOLDING_PER","CUST_TRR_START_DT",Settings!$C$5,"CUST_TRR_END_DT",Settings!$C$4)/100,"") | F29: =IFERROR(BDP(A29,"CUST_TRR_RETURN_HOLDING_PER","CUST_TRR_START_DT",Settings!$C$6,"CUST_TRR_END_DT",Settings!$C$4)/100,"") | G29: =IFERROR(BDP(A29,"CUST_TRR_RETURN_HOLDING_PER","CUST_TRR_START_DT",Settings!$C$7,"CUST_TRR_END_DT",Settings!$C$4)/100,"") | H29: =IFERROR(BDP(A29,"CUST_TRR_RETURN_HOLDING_PER","CUST_TRR_START_DT",Settings!$C$8,"CUST_TRR_END_DT",Settings!$C$4)/100,"") | I29: =IFERROR(BDP(A29,"PX_LAST")/BDH(A29,"PX_LAST",Settings!$C$5,Settings!$C$5)-1,"") | J29: =IFERROR(BDP(A29,"PX_LAST")/BDH(A29,"PX_LAST",Settings!$C$6,Settings!$C$6)-1,"") | K29: =IFERROR(BDP(A29,"PX_LAST")/BDH(A29,"PX_LAST",Settings!$C$7,Settings!$C$7)-1,"") | L29: =IFERROR(BDP(A29,"PX_LAST")/BDH(A29,"PX_LAST",Settings!$C$8,Settings!$C$8)-1,"")
A30: MXEA Index | B30: MSCI EAFE | C30: MSCI Aggregate | D30: =IFERROR(BDP(A30,"PX_LAST"),"") | E30: =IFERROR(BDP(A30,"CUST_TRR_RETURN_HOLDING_PER","CUST_TRR_START_DT",Settings!$C$5,"CUST_TRR_END_DT",Settings!$C$4)/100,"") | F30: =IFERROR(BDP(A30,"CUST_TRR_RETURN_HOLDING_PER","CUST_TRR_START_DT",Settings!$C$6,"CUST_TRR_END_DT",Settings!$C$4)/100,"") | G30: =IFERROR(BDP(A30,"CUST_TRR_RETURN_HOLDING_PER","CUST_TRR_START_DT",Settings!$C$7,"CUST_TRR_END_DT",Settings!$C$4)/100,"") | H30: =IFERROR(BDP(A30,"CUST_TRR_RETURN_HOLDING_PER","CUST_TRR_START_DT",Settings!$C$8,"CUST_TRR_END_DT",Settings!$C$4)/100,"") | I30: =IFERROR(BDP(A30,"PX_LAST")/BDH(A30,"PX_LAST",Settings!$C$5,Settings!$C$5)-1,"") | J30: =IFERROR(BDP(A30,"PX_LAST")/BDH(A30,"PX_LAST",Settings!$C$6,Settings!$C$6)-1,"") | K30: =IFERROR(BDP(A30,"PX_LAST")/BDH(A30,"PX_LAST",Settings!$C$7,Settings!$C$7)-1,"") | L30: =IFERROR(BDP(A30,"PX_LAST")/BDH(A30,"PX_LAST",Settings!$C$8,Settings!$C$8)-1,"")
A31: MXEF Index | B31: MSCI Emerging Markets | C31: MSCI Aggregate | D31: =IFERROR(BDP(A31,"PX_LAST"),"") | E31: =IFERROR(BDP(A31,"CUST_TRR_RETURN_HOLDING_PER","CUST_TRR_START_DT",Settings!$C$5,"CUST_TRR_END_DT",Settings!$C$4)/100,"") | F31: =IFERROR(BDP(A31,"CUST_TRR_RETURN_HOLDING_PER","CUST_TRR_START_DT",Settings!$C$6,"CUST_TRR_END_DT",Settings!$C$4)/100,"") | G31: =IFERROR(BDP(A31,"CUST_TRR_RETURN_HOLDING_PER","CUST_TRR_START_DT",Settings!$C$7,"CUST_TRR_END_DT",Settings!$C$4)/100,"") | H31: =IFERROR(BDP(A31,"CUST_TRR_RETURN_HOLDING_PER","CUST_TRR_START_DT",Settings!$C$8,"CUST_TRR_END_DT",Settings!$C$4)/100,"") | I31: =IFERROR(BDP(A31,"PX_LAST")/BDH(A31,"PX_LAST",Settings!$C$5,Settings!$C$5)-1,"") | J31: =IFERROR(BDP(A31,"PX_LAST")/BDH(A31,"PX_LAST",Settings!$C$6,Settings!$C$6)-1,"") | K31: =IFERROR(BDP(A31,"PX_LAST")/BDH(A31,"PX_LAST",Settings!$C$7,Settings!$C$7)-1,"") | L31: =IFERROR(BDP(A31,"PX_LAST")/BDH(A31,"PX_LAST",Settings!$C$8,Settings!$C$8)-1,"")
A32: MXFM Index | B32: MSCI Frontier Markets | C32: MSCI Aggregate | D32: =IFERROR(BDP(A32,"PX_LAST"),"") | E32: =IFERROR(BDP(A32,"CUST_TRR_RETURN_HOLDING_PER","CUST_TRR_START_DT",Settings!$C$5,"CUST_TRR_END_DT",Settings!$C$4)/100,"") | F32: =IFERROR(BDP(A32,"CUST_TRR_RETURN_HOLDING_PER","CUST_TRR_START_DT",Settings!$C$6,"CUST_TRR_END_DT",Settings!$C$4)/100,"") | G32: =IFERROR(BDP(A32,"CUST_TRR_RETURN_HOLDING_PER","CUST_TRR_START_DT",Settings!$C$7,"CUST_TRR_END_DT",Settings!$C$4)/100,"") | H32: =IFERROR(BDP(A32,"CUST_TRR_RETURN_HOLDING_PER","CUST_TRR_START_DT",Settings!$C$8,"CUST_TRR_END_DT",Settings!$C$4)/100,"") | I32: =IFERROR(BDP(A32,"PX_LAST")/BDH(A32,"PX_LAST",Settings!$C$5,Settings!$C$5)-1,"") | J32: =IFERROR(BDP(A32,"PX_LAST")/BDH(A32,"PX_LAST",Settings!$C$6,Settings!$C$6)-1,"") | K32: =IFERROR(BDP(A32,"PX_LAST")/BDH(A32,"PX_LAST",Settings!$C$7,Settings!$C$7)-1,"") | L32: =IFERROR(BDP(A32,"PX_LAST")/BDH(A32,"PX_LAST",Settings!$C$8,Settings!$C$8)-1,"")
A33: DM Country
A34: SPTSX Index | B34: S&P/TSX Composite (Canada) | C34: DM Country | D34: =IFERROR(BDP(A34,"PX_LAST"),"") | E34: =IFERROR(BDP(A34,"CUST_TRR_RETURN_HOLDING_PER","CUST_TRR_START_DT",Settings!$C$5,"CUST_TRR_END_DT",Settings!$C$4)/100,"") | F34: =IFERROR(BDP(A34,"CUST_TRR_RETURN_HOLDING_PER","CUST_TRR_START_DT",Settings!$C$6,"CUST_TRR_END_DT",Settings!$C$4)/100,"") | G34: =IFERROR(BDP(A34,"CUST_TRR_RETURN_HOLDING_PER","CUST_TRR_START_DT",Settings!$C$7,"CUST_TRR_END_DT",Settings!$C$4)/100,"") | H34: =IFERROR(BDP(A34,"CUST_TRR_RETURN_HOLDING_PER","CUST_TRR_START_DT",Settings!$C$8,"CUST_TRR_END_DT",Settings!$C$4)/100,"") | I34: =IFERROR(BDP(A34,"PX_LAST")/BDH(A34,"PX_LAST",Settings!$C$5,Settings!$C$5)-1,"") | J34: =IFERROR(BDP(A34,"PX_LAST")/BDH(A34,"PX_LAST",Settings!$C$6,Settings!$C$6)-1,"") | K34: =IFERROR(BDP(A34,"PX_LAST")/BDH(A34,"PX_LAST",Settings!$C$7,Settings!$C$7)-1,"") | L34: =IFERROR(BDP(A34,"PX_LAST")/BDH(A34,"PX_LAST",Settings!$C$8,Settings!$C$8)-1,"")
A35: DM Region
A36: SX5E Index | B36: Euro Stoxx 50 | C36: DM Region | D36: =IFERROR(BDP(A36,"PX_LAST"),"") | E36: =IFERROR(BDP(A36,"CUST_TRR_RETURN_HOLDING_PER","CUST_TRR_START_DT",Settings!$C$5,"CUST_TRR_END_DT",Settings!$C$4)/100,"") | F36: =IFERROR(BDP(A36,"CUST_TRR_RETURN_HOLDING_PER","CUST_TRR_START_DT",Settings!$C$6,"CUST_TRR_END_DT",Settings!$C$4)/100,"") | G36: =IFERROR(BDP(A36,"CUST_TRR_RETURN_HOLDING_PER","CUST_TRR_START_DT",Settings!$C$7,"CUST_TRR_END_DT",Settings!$C$4)/100,"") | H36: =IFERROR(BDP(A36,"CUST_TRR_RETURN_HOLDING_PER","CUST_TRR_START_DT",Settings!$C$8,"CUST_TRR_END_DT",Settings!$C$4)/100,"") | I36: =IFERROR(BDP(A36,"PX_LAST")/BDH(A36,"PX_LAST",Settings!$C$5,Settings!$C$5)-1,"") | J36: =IFERROR(BDP(A36,"PX_LAST")/BDH(A36,"PX_LAST",Settings!$C$6,Settings!$C$6)-1,"") | K36: =IFERROR(BDP(A36,"PX_LAST")/BDH(A36,"PX_LAST",Settings!$C$7,Settings!$C$7)-1,"") | L36: =IFERROR(BDP(A36,"PX_LAST")/BDH(A36,"PX_LAST",Settings!$C$8,Settings!$C$8)-1,"")
A37: SXXP Index | B37: Stoxx Europe 600 | C37: DM Region | D37: =IFERROR(BDP(A37,"PX_LAST"),"") | E37: =IFERROR(BDP(A37,"CUST_TRR_RETURN_HOLDING_PER","CUST_TRR_START_DT",Settings!$C$5,"CUST_TRR_END_DT",Settings!$C$4)/100,"") | F37: =IFERROR(BDP(A37,"CUST_TRR_RETURN_HOLDING_PER","CUST_TRR_START_DT",Settings!$C$6,"CUST_TRR_END_DT",Settings!$C$4)/100,"") | G37: =IFERROR(BDP(A37,"CUST_TRR_RETURN_HOLDING_PER","CUST_TRR_START_DT",Settings!$C$7,"CUST_TRR_END_DT",Settings!$C$4)/100,"") | H37: =IFERROR(BDP(A37,"CUST_TRR_RETURN_HOLDING_PER","CUST_TRR_START_DT",Settings!$C$8,"CUST_TRR_END_DT",Settings!$C$4)/100,"") | I37: =IFERROR(BDP(A37,"PX_LAST")/BDH(A37,"PX_LAST",Settings!$C$5,Settings!$C$5)-1,"") | J37: =IFERROR(BDP(A37,"PX_LAST")/BDH(A37,"PX_LAST",Settings!$C$6,Settings!$C$6)-1,"") | K37: =IFERROR(BDP(A37,"PX_LAST")/BDH(A37,"PX_LAST",Settings!$C$7,Settings!$C$7)-1,"") | L37: =IFERROR(BDP(A37,"PX_LAST")/BDH(A37,"PX_LAST",Settings!$C$8,Settings!$C$8)-1,"")
A38: DM Country
A39: DAX Index | B39: DAX (Germany) | C39: DM Country | D39: =IFERROR(BDP(A39,"PX_LAST"),"") | E39: =IFERROR(BDP(A39,"CUST_TRR_RETURN_HOLDING_PER","CUST_TRR_START_DT",Settings!$C$5,"CUST_TRR_END_DT",Settings!$C$4)/100,"") | F39: =IFERROR(BDP(A39,"CUST_TRR_RETURN_HOLDING_PER","CUST_TRR_START_DT",Settings!$C$6,"CUST_TRR_END_DT",Settings!$C$4)/100,"") | G39: =IFERROR(BDP(A39,"CUST_TRR_RETURN_HOLDING_PER","CUST_TRR_START_DT",Settings!$C$7,"CUST_TRR_END_DT",Settings!$C$4)/100,"") | H39: =IFERROR(BDP(A39,"CUST_TRR_RETURN_HOLDING_PER","CUST_TRR_START_DT",Settings!$C$8,"CUST_TRR_END_DT",Settings!$C$4)/100,"") | I39: =IFERROR(BDP(A39,"PX_LAST")/BDH(A39,"PX_LAST",Settings!$C$5,Settings!$C$5)-1,"") | J39: =IFERROR(BDP(A39,"PX_LAST")/BDH(A39,"PX_LAST",Settings!$C$6,Settings!$C$6)-1,"") | K39: =IFERROR(BDP(A39,"PX_LAST")/BDH(A39,"PX_LAST",Settings!$C$7,Settings!$C$7)-1,"") | L39: =IFERROR(BDP(A39,"PX_LAST")/BDH(A39,"PX_LAST",Settings!$C$8,Settings!$C$8)-1,"")
A40: CAC Index | B40: CAC 40 (France) | C40: DM Country | D40: =IFERROR(BDP(A40,"PX_LAST"),"") | E40: =IFERROR(BDP(A40,"CUST_TRR_RETURN_HOLDING_PER","CUST_TRR_START_DT",Settings!$C$5,"CUST_TRR_END_DT",Settings!$C$4)/100,"") | F40: =IFERROR(BDP(A40,"CUST_TRR_RETURN_HOLDING_PER","CUST_TRR_START_DT",Settings!$C$6,"CUST_TRR_END_DT",Settings!$C$4)/100,"") | G40: =IFERROR(BDP(A40,"CUST_TRR_RETURN_HOLDING_PER","CUST_TRR_START_DT",Settings!$C$7,"CUST_TRR_END_DT",Settings!$C$4)/100,"") | H40: =IFERROR(BDP(A40,"CUST_TRR_RETURN_HOLDING_PER","CUST_TRR_START_DT",Settings!$C$8,"CUST_TRR_END_DT",Settings!$C$4)/100,"") | I40: =IFERROR(BDP(A40,"PX_LAST")/BDH(A40,"PX_LAST",Settings!$C$5,Settings!$C$5)-1,"") | J40: =IFERROR(BDP(A40,"PX_LAST")/BDH(A40,"PX_LAST",Settings!$C$6,Settings!$C$6)-1,"") | K40: =IFERROR(BDP(A40,"PX_LAST")/BDH(A40,"PX_LAST",Settings!$C$7,Settings!$C$7)-1,"") | L40: =IFERROR(BDP(A40,"PX_LAST")/BDH(A40,"PX_LAST",Settings!$C$8,Settings!$C$8)-1,"")
A41: UKX Index | B41: FTSE 100 (UK) | C41: DM Country | D41: =IFERROR(BDP(A41,"PX_LAST"),"") | E41: =IFERROR(BDP(A41,"CUST_TRR_RETURN_HOLDING_PER","CUST_TRR_START_DT",Settings!$C$5,"CUST_TRR_END_DT",Settings!$C$4)/100,"") | F41: =IFERROR(BDP(A41,"CUST_TRR_RETURN_HOLDING_PER","CUST_TRR_START_DT",Settings!$C$6,"CUST_TRR_END_DT",Settings!$C$4)/100,"") | G41: =IFERROR(BDP(A41,"CUST_TRR_RETURN_HOLDING_PER","CUST_TRR_START_DT",Settings!$C$7,"CUST_TRR_END_DT",Settings!$C$4)/100,"") | H41: =IFERROR(BDP(A41,"CUST_TRR_RETURN_HOLDING_PER","CUST_TRR_START_DT",Settings!$C$8,"CUST_TRR_END_DT",Settings!$C$4)/100,"") | I41: =IFERROR(BDP(A41,"PX_LAST")/BDH(A41,"PX_LAST",Settings!$C$5,Settings!$C$5)-1,"") | J41: =IFERROR(BDP(A41,"PX_LAST")/BDH(A41,"PX_LAST",Settings!$C$6,Settings!$C$6)-1,"") | K41: =IFERROR(BDP(A41,"PX_LAST")/BDH(A41,"PX_LAST",Settings!$C$7,Settings!$C$7)-1,"") | L41: =IFERROR(BDP(A41,"PX_LAST")/BDH(A41,"PX_LAST",Settings!$C$8,Settings!$C$8)-1,"")
A42: IBEX Index | B42: IBEX 35 (Spain) | C42: DM Country | D42: =IFERROR(BDP(A42,"PX_LAST"),"") | E42: =IFERROR(BDP(A42,"CUST_TRR_RETURN_HOLDING_PER","CUST_TRR_START_DT",Settings!$C$5,"CUST_TRR_END_DT",Settings!$C$4)/100,"") | F42: =IFERROR(BDP(A42,"CUST_TRR_RETURN_HOLDING_PER","CUST_TRR_START_DT",Settings!$C$6,"CUST_TRR_END_DT",Settings!$C$4)/100,"") | G42: =IFERROR(BDP(A42,"CUST_TRR_RETURN_HOLDING_PER","CUST_TRR_START_DT",Settings!$C$7,"CUST_TRR_END_DT",Settings!$C$4)/100,"") | H42: =IFERROR(BDP(A42,"CUST_TRR_RETURN_HOLDING_PER","CUST_TRR_START_DT",Settings!$C$8,"CUST_TRR_END_DT",Settings!$C$4)/100,"") | I42: =IFERROR(BDP(A42,"PX_LAST")/BDH(A42,"PX_LAST",Settings!$C$5,Settings!$C$5)-1,"") | J42: =IFERROR(BDP(A42,"PX_LAST")/BDH(A42,"PX_LAST",Settings!$C$6,Settings!$C$6)-1,"") | K42: =IFERROR(BDP(A42,"PX_LAST")/BDH(A42,"PX_LAST",Settings!$C$7,Settings!$C$7)-1,"") | L42: =IFERROR(BDP(A42,"PX_LAST")/BDH(A42,"PX_LAST",Settings!$C$8,Settings!$C$8)-1,"")
...

Sheet Settings
A1: Performance — Date Settings
A3: Label | B3: Date | C3: YYYYMMDD (Bloomberg) | D3: Used for
A4: Today | B4: =TODAY() | C4: =TEXT(B4,"yyyymmdd") | D4: End date for all windows
A5: YTD baseline | B5: =DATE(YEAR(TODAY())-1,12,31) | C5: =TEXT(B5,"yyyymmdd") | D5: Prior year-end close
A6: 1M ago | B6: =EDATE(TODAY(),-1) | C6: =TEXT(B6,"yyyymmdd") | D6: One month trailing
A7: 3M ago | B7: =EDATE(TODAY(),-3) | C7: =TEXT(B7,"yyyymmdd") | D7: Three months trailing
A8: Custom date | B8: =EDATE(TODAY(),-6) | C8: =TEXT(B8,"yyyymmdd") | D8: EDIT ME — any date you want to compare today against
A10: Notes
A11: All performance numbers on the Data sheet anchor to these cells. Change B8 to compare today vs any date.
A12: Total return uses Bloomberg's CUST_TRR_RETURN_HOLDING_PER with date overrides — captures dividends.
A13: Price return uses PX_LAST today divided by PX_LAST on the start date — no dividends.
A14: Bloomberg CUST_TRR_RETURN_HOLDING_PER typically returns a percentage value (e.g. 5.2 = 5.2%) — formulas /100 to give a decimal,
A15: then the cell is formatted as %. If your Bloomberg returns it as decimal already, remove the /100.
