Workbook

Sheet README
A1: BBG OPTIONS MONITOR — 24 per-ticker tabs + BestNow ranking
A3: HOW TO USE — 30-second version
A4: 1. Open on a Bloomberg workstation. Press F9 to refresh.
A5: 2. Go to the BestNow tab. See the top 3 across the entire universe — even when nothing is perfect, it shows the 3 best-conditioned trades available right now, with sizing and exit prices.
A6: 3. For details on any individual ticker, click its tab (SPY, XLK, GDX, etc.). Each tab analyses both Bull-Put spreads (upper block) and Bear-Call spreads (lower block) at the Front and Back expirations from Calendar.
A7: 4. To analyse a DIFFERENT expiration or strike on any ticker — type the override on that ticker's tab in the PARAMETER OVERRIDES block. Blank = use default from Calendar. Everything recalculates.
A9: TABS
A10: README — This page.
A11: Settings — All tunables (account size, risk caps, gates, expiration offsets).
A12: Calendar — Rolling third-Friday dates. Front_Exp/Back_Exp update automatically each month.
A13: BestNow — TOP 3 trades across all 24 tickers. Decision cards with sizing + GO/WAIT signals.
A14: [Ticker tabs] — 24 per-ticker analysis tabs (SPY, IWM, QQQ, XL_, GLD, GDX, TLT, XOP, EEM, FXI, EWZ, ...).
... A38: BestNow always shows '3 best amid current conditions' — even when none have ✓ GO. Read the Signal column. ✓ GO means all gates pass. ✗ WAIT - <reason> means at least one gate is failing — DO NOT TRADE those. The credit-spread max loss IS realized when it happens. This is a screener, not investment advice.

Sheet Settings
A1: SETTINGS — edit blue cells
A3: Account equity ($) | B3: 50000 | C3: Used by ¼-Kelly sizing.
A4: Trades per month target | B4: 3 | C4: 2–4 short-premium spreads + 1 hedge.
A5: Book risk cap ($) | B5: 5500 | C5: Total max loss across all open spreads.
A6: Max book as % of account | B6: 0.12 | C6: Hard cap on book vs equity.
A7: Kelly fraction | B7: 0.25 | C7: ¼ Kelly. Don't go above 0.50.
A8: Min IV Rank to enter | B8: 30 | C8: Don't sell premium when IV is cheap.
A9: Min credit/width ratio | B9: 0.1 | C9: Skip thin trades.
A10: Min credit ($) | B10: 0.3 | C10: Skip if mid credit below this.
A11: Max bid-ask % of mid | B11: 0.1 | C11: Liquidity gate.
A12: Short-strike |delta| min | B12: 0.15 | C12: If short delta outside this band, WAIT.
A13: Short-strike |delta| max | B13: 0.25
A14: Entry DTE — minimum | B14: 60 | C14: Don't open inside this floor.
A15: Entry DTE — maximum | B15: 120 | C15: Don't open beyond this cap.
A16: Mandatory exit DTE | B16: 60 | C16: Hard close (UBS 30-day hold rule).
A17: Take-profit (% of credit) | B17: 0.5 | C17: Close at 50% of credit.
A18: Stop-loss × credit | B18: 2 | C18: Cut when spread value reaches this × credit.
A19: Min strike buffer (% of spot) | B19: 0.03 | C19: Skip if short strike within X% of spot.
A20: Hedge budget — % of book risk | B20: 0.08 | C20: Cash for UVXY long calls.
A21: UVXY OTM % | B21: 0.3 | C21: UVXY hedge call strike = spot × (1+this).
A22: Front expiration offset (months) | B22: 2 | C22: Months from today to the FRONT 3rd-Friday.
A23: Back expiration offset (months) | B23: 3 | C23: Months from today to the BACK 3rd-Friday.

Sheet Calendar
A1: CALENDAR — third Fridays roll forward automatically from TODAY()
A3: Label | B3: Third_Friday | C3: DTE | D3: Note
A4: Today + 1 months → 3rd Fri | B4: =DATE(YEAR(EDATE(TODAY(),1)),MONTH(EDATE(TODAY(),1)),1)+MOD(5-WEEKDAY(DATE(YEAR(EDATE(TODAY(),1)),MONTH(EDATE(TODAY(),1)),1),2)+7,7)+14 -> 46192 | C4: =B4-TODAY() -> 39 | D4: =IF(AND(C4>=Settings!$B$14,C4<=Settings!$B$15),"in 60-120 window","outside window") -> outside window
A5: Today + 2 months → 3rd Fri | B5: =DATE(YEAR(EDATE(TODAY(),2)),MONTH(EDATE(TODAY(),2)),1)+MOD(5-WEEKDAY(DATE(YEAR(EDATE(TODAY(),2)),MONTH(EDATE(TODAY(),2)),1),2)+7,7)+14 -> 46220 | C5: =B5-TODAY() -> 67 | D5: =IF(AND(C5>=Settings!$B$14,C5<=Settings!$B$15),"in 60-120 window","outside window") -> in 60-120 window
A6: Today + 3 months → 3rd Fri | B6: =DATE(YEAR(EDATE(TODAY(),3)),MONTH(EDATE(TODAY(),3)),1)+MOD(5-WEEKDAY(DATE(YEAR(EDATE(TODAY(),3)),MONTH(EDATE(TODAY(),3)),1),2)+7,7)+14 -> 46255 | C6: =B6-TODAY() -> 102 | D6: =IF(AND(C6>=Settings!$B$14,C6<=Settings!$B$15),"in 60-120 window","outside window") -> in 60-120 window
A7: Today + 4 months → 3rd Fri | B7: =DATE(YEAR(EDATE(TODAY(),4)),MONTH(EDATE(TODAY(),4)),1)+MOD(5-WEEKDAY(DATE(YEAR(EDATE(TODAY(),4)),MONTH(EDATE(TODAY(),4)),1),2)+7,7)+14 -> 46283 | C7: =B7-TODAY() -> 130 | D7: =IF(AND(C7>=Settings!$B$14,C7<=Settings!$B$15),"in 60-120 window","outside window") -> outside window
A8: Today + 5 months → 3rd Fri | B8: =DATE(YEAR(EDATE(TODAY(),5)),MONTH(EDATE(TODAY(),5)),1)+MOD(5-WEEKDAY(DATE(YEAR(EDATE(TODAY(),5)),MONTH(EDATE(TODAY(),5)),1),2)+7,7)+14 -> 46311 | C8: =B8-TODAY() -> 158 | D8: =IF(AND(C8>=Settings!$B$14,C8<=Settings!$B$15),"in 60-120 window","outside window") -> outside window
A10: SELECTED EXPIRATIONS (default for every ticker tab; can be overridden per ticker)
A11: Front_Exp (3rd Fri at +Front_Offset months) | B11: =DATE(YEAR(EDATE(TODAY(),Settings!$B$22)),MONTH(EDATE(TODAY(),Settings!$B$22)),1)+MOD(5-WEEKDAY(DATE(YEAR(EDATE(TODAY(),Settings!$B$22)),MONTH(EDATE(TODAY(),Settings!$B$22)),1),2)+7,7)+14 -> 46220 | C11: =B11-TODAY() -> 67
A12: Back_Exp (3rd Fri at +Back_Offset months) | B12: =DATE(YEAR(EDATE(TODAY(),Settings!$B$23)),MONTH(EDATE(TODAY(),Settings!$B$23)),1)+MOD(5-WEEKDAY(DATE(YEAR(EDATE(TODAY(),Settings!$B$23)),MONTH(EDATE(TODAY(),Settings!$B$23)),1),2)+7,7)+14 -> 46255 | C12: =B12-TODAY() -> 102

Sheet BestNow
A1: BEST NOW — top 3 spreads + 1 UVXY hedge
A2: As of: | B2: =TODAY() -> 46153
A4: Rank | B4: Ticker | C4: Strategy | D4: Exp | E4: Strikes (Short/Long) | F4: Credit | G4: MaxLoss | H4: Contracts | I4: Signal | J4: Action
A5: =IF((LARGE($M$22:$M$37,1)>-100000000),1,"") | B5: =IF((LARGE($M$22:$M$37,1)>-100000000),INDEX($A$22:$A$37,MATCH(LARGE($M$22:$M$37,1),$M$22:$M$37,0)),"") | C5: =IF((LARGE($M$22:$M$37,1)>-100000000),INDEX($B$22:$B$37,MATCH(LARGE($M$22:$M$37,1),$M$22:$M$37,0)),"") | D5: =IF((LARGE($M$22:$M$37,1)>-100000000),INDEX($D$22:$D$37,MATCH(LARGE($M$22:$M$37,1),$M$22:$M$37,0)),"") | E5: =IF((LARGE($M$22:$M$37,1)>-100000000),TEXT(INDEX($F$22:$F$37,MATCH(LARGE($M$22:$M$37,1),$M$22:$M$37,0)),"$0")&" / "&TEXT(INDEX($G$22:$G$37,MATCH(LARGE($M$22:$M$37,1),$M$22:$M$37,0)),"$0"),"") | F5: =IF((LARGE($M$22:$M$37,1)>-100000000),INDEX($H$22:$H$37,MATCH(LARGE($M$22:$M$37,1),$M$22:$M$37,0)),"") | G5: =IF((LARGE($M$22:$M$37,1)>-100000000),INDEX($I$22:$I$37,MATCH(LARGE($M$22:$M$37,1),$M$22:$M$37,0)),"") | H5: =IF((LARGE($M$22:$M$37,1)>-100000000),IFERROR(IF(INDEX($I$22:$I$37,MATCH(LARGE($M$22:$M$37,1),$M$22:$M$37,0))>0,FLOOR(MIN(MIN(Settings!$B$5,Settings!$B$6*Settings!$B$3)/Settings!$B$4,IFERROR(MAX(0, INDEX($J$22:$J$37,MATCH(LARGE($M$22:$M$37,1),$M$22:$M$37,0)) - (1-INDEX($J$22:$J$37,MATCH(LARGE($M$22:$M$37,1),$M$22:$M$37,0))) / (INDEX($H$22:$H$37,MATCH(LARGE($M$22:$M$37,1),$M$22:$M$37,0))/INDEX($I$22:$I$37,MATCH(LARGE($M$22:$M$37,1),$M$22:$M$37,0))))*Settings!$B$7*Settings!$B$3,0))/(INDEX($I$22:$I$37,MATCH(LARGE($M$22:$M$37,1),$M$22:$M$37,0))*100),1),0),0),"") | I5: =IF((LARGE($M$22:$M$37,1)>-100000000),INDEX($L$22:$L$37,MATCH(LARGE($M$22:$M$37,1),$M$22:$M$37,0)),"") | J5: =IF((LARGE($M$22:$M$37,1)>-100000000),IF(INDEX($L$22:$L$37,MATCH(LARGE($M$22:$M$37,1),$M$22:$M$37,0))="GO","SELL "&TEXT(IFERROR(IF(INDEX($I$22:$I$37,MATCH(LARGE($M$22:$M$37,1),$M$22:$M$37,0))>0,FLOOR(MIN(MIN(Settings!$B$5,Settings!$B$6*Settings!$B$3)/Settings!$B$4,IFERROR(MAX(0, INDEX($J$22:$J$37,MATCH(LARGE($M$22:$M$37,1),$M$22:$M$37,0)) - (1-INDEX($J$22:$J$37,MATCH(LARGE($M$22:$M$37,1),$M$22:$M$37,0))) / (INDEX($H$22:$H$37,MATCH(LARGE($M$22:$M$37,1),$M$22:$M$37,0))/INDEX($I$22:$I$37,MATCH(LARGE($M$22:$M$37,1),$M$22:$M$37,0))))*Settings!$B$7*Settings!$B$3,0))/(INDEX($I$22:$I$37,MATCH(LARGE($M$22:$M$37,1),$M$22:$M$37,0))*100),1),0),0),"0")&" "&INDEX($A$22:$A$37,MATCH(LARGE($M$22:$M$37,1),$M$22:$M$37,0))&" "&INDEX($B$22:$B$37,MATCH(LARGE($M$22:$M$37,1),$M$22:$M$37,0))&" "&TEXT(INDEX($F$22:$F$37,MATCH(LARGE($M$22:$M$37,1),$M$22:$M$37,0)),"$0")&"/"&TEXT(INDEX($G$22:$G$37,MATCH(LARGE($M$22:$M$37,1),$M$22:$M$37,0)),"$0")&" exp "&TEXT(INDEX($D$22:$D$37,MATCH(LARGE($M$22:$M$37,1),$M$22:$M$37,0)),"m/d")&". Collect "&TEXT(IFERROR(IF(INDEX($I$22:$I$37,MATCH(LARGE($M$22:$M$37,1),$M$22:$M$37,0))>0,FLOOR(MIN(MIN(Settings!$B$5,Settings!$B$6*Settings!$B$3)/Settings!$B$4,IFERROR(MAX(0, INDEX($J$22:$J$37,MATCH(LARGE($M$22:$M$37,1),$M$22:$M$37,0)) - (1-INDEX($J$22:$J$37,MATCH(LARGE($M$22:$M$37,1),$M$22:$M$37,0))) / (INDEX($H$22:$H$37,MATCH(LARGE($M$22:$M$37,1),$M$22:$M$37,0))/INDEX($I$22:$I$37,MATCH(LARGE($M$22:$M$37,1),$M$22:$M$37,0))))*Settings!$B$7*Settings!$B$3,0))/(INDEX($I$22:$I$37,MATCH(LARGE($M$22:$M$37,1),$M$22:$M$37,0))*100),1),0),0)*INDEX($H$22:$H$37,MATCH(LARGE($M$22:$M$37,1),$M$22:$M$37,0))*100,"$#,##0")&" upfront. Max loss "&TEXT(IFERROR(IF(INDEX($I$22:$I$37,MATCH(LARGE($M$22:$M$37,1),$M$22:$M$37,0))>0,FLOOR(MIN(MIN(Settings!$B$5,Settings!$B$6*Settings!$B$3)/Settings!$B$4,IFERROR(MAX(0, INDEX($J$22:$J$37,MATCH(LARGE($M$22:$M$37,1),$M$22:$M$37,0)) - (1-INDEX($J$22:$J$37,MATCH(LARGE($M$22:$M$37,1),$M$22:$M$37,0))) / (INDEX($H$22:$H$37,MATCH(LARGE($M$22:$M$37,1),$M$22:$M$37,0))/INDEX($I$22:$I$37,MATCH(LARGE($M$22:$M$37,1),$M$22:$M$37,0))))*Settings!$B$7*Settings!$B$3,0))/(INDEX($I$22:$I$37,MATCH(LARGE($M$22:$M$37,1),$M$22:$M$37,0))*100),1),0),0)*INDEX($I$22:$I$37,MATCH(LARGE($M$22:$M$37,1),$M$22:$M$37,0))*100,"$#,##0")&".","Best of universe, but "&INDEX($L$22:$L$37,MATCH(LARGE($M$22:$M$37,1),$M$22:$M$37,0))&". Wait for the gate to clear — see the "&INDEX($A$22:$A$37,MATCH(LARGE($M$22:$M$37,1),$M$22:$M$37,0))&" tab for details."),"")
A6: =IF((LARGE($M$22:$M$37,2)>-100000000),2,"") | B6: =IF((LARGE($M$22:$M$37,2)>-100000000),INDEX($A$22:$A$37,MATCH(LARGE($M$22:$M$37,2),$M$22:$M$37,0)),"") | C6: =IF((LARGE($M$22:$M$37,2)>-100000000),INDEX($B$22:$B$37,MATCH(LARGE($M$22:$M$37,2),$M$22:$M$37,0)),"") | D6: =IF((LARGE($M$22:$M$37,2)>-100000000),INDEX($D$22:$D$37,MATCH(LARGE($M$22:$M$37,2),$M$22:$M$37,0)),"") | E6: =IF((LARGE($M$22:$M$37,2)>-100000000),TEXT(INDEX($F$22:$F$37,MATCH(LARGE($M$22:$M$37,2),$M$22:$M$37,0)),"$0")&" / "&TEXT(INDEX($G$22:$G$37,MATCH(LARGE($M$22:$M$37,2),$M$22:$M$37,0)),"$0"),"") | F6: =IF((LARGE($M$22:$M$37,2)>-100000000),INDEX($H$22:$H$37,MATCH(LARGE($M$22:$M$37,2),$M$22:$M$37,0)),"") | G6: =IF((LARGE($M$22:$M$37,2)>-100000000),INDEX($I$22:$I$37,MATCH(LARGE($M$22:$M$37,2),$M$22:$M$37,0)),"") | H6: =IF((LARGE($M$22:$M$37,2)>-100000000),IFERROR(IF(INDEX($I$22:$I$37,MATCH(LARGE($M$22:$M$37,2),$M$22:$M$37,0))>0,FLOOR(MIN(MIN(Settings!$B$5,Settings!$B$6*Settings!$B$3)/Settings!$B$4,IFERROR(MAX(0, INDEX($J$22:$J$37,MATCH(LARGE($M$22:$M$37,2),$M$22:$M$37,0)) - (1-INDEX($J$22:$J$37,MATCH(LARGE($M$22:$M$37,2),$M$22:$M$37,0))) / (INDEX($H$22:$H$37,MATCH(LARGE($M$22:$M$37,2),$M$22:$M$37,0))/INDEX($I$22:$I$37,MATCH(LARGE($M$22:$M$37,2),$M$22:$M$37,0))))*Settings!$B$7*Settings!$B$3,0))/(INDEX($I$22:$I$37,MATCH(LARGE($M$22:$M$37,2),$M$22:$M$37,0))*100),1),0),0),"") | I6: =IF((LARGE($M$22:$M$37,2)>-100000000),INDEX($L$22:$L$37,MATCH(LARGE($M$22:$M$37,2),$M$22:$M$37,0)),"") | J6: =IF((LARGE($M$22:$M$37,2)>-100000000),IF(INDEX($L$22:$L$37,MATCH(LARGE($M$22:$M$37,2),$M$22:$M$37,0))="GO","SELL "&TEXT(IFERROR(IF(INDEX($I$22:$I$37,MATCH(LARGE($M$22:$M$37,2),$M$22:$M$37,0))>0,FLOOR(MIN(MIN(Settings!$B$5,Settings!$B$6*Settings!$B$3)/Settings!$B$4,IFERROR(MAX(0, INDEX($J$22:$J$37,MATCH(LARGE($M$22:$M$37,2),$M$22:$M$37,0)) - (1-INDEX($J$22:$J$37,MATCH(LARGE($M$22:$M$37,2),$M$22:$M$37,0))) / (INDEX($H$22:$H$37,MATCH(LARGE($M$22:$M$37,2),$M$22:$M$37,0))/INDEX($I$22:$I$37,MATCH(LARGE($M$22:$M$37,2),$M$22:$M$37,0))))*Settings!$B$7*Settings!$B$3,0))/(INDEX($I$22:$I$37,MATCH(LARGE($M$22:$M$37,2),$M$22:$M$37,0))*100),1),0),0),"0")&" "&INDEX($A$22:$A$37,MATCH(LARGE($M$22:$M$37,2),$M$22:$M$37,0))&" "&INDEX($B$22:$B$37,MATCH(LARGE($M$22:$M$37,2),$M$22:$M$37,0))&" "&TEXT(INDEX($F$22:$F$37,MATCH(LARGE($M$22:$M$37,2),$M$22:$M$37,0)),"$0")&"/"&TEXT(INDEX($G$22:$G$37,MATCH(LARGE($M$22:$M$37,2),$M$22:$M$37,0)),"$0")&" exp "&TEXT(INDEX($D$22:$D$37,MATCH(LARGE($M$22:$M$37,2),$M$22:$M$37,0)),"m/d")&". Collect "&TEXT(IFERROR(IF(INDEX($I$22:$I$37,MATCH(LARGE($M$22:$M$37,2),$M$22:$M$37,0))>0,FLOOR(MIN(MIN(Settings!$B$5,Settings!$B$6*Settings!$B$3)/Settings!$B$4,IFERROR(MAX(0, INDEX($J$22:$J$37,MATCH(LARGE($M$22:$M$37,2),$M$22:$M$37,0)) - (1-INDEX($J$22:$J$37,MATCH(LARGE($M$22:$M$37,2),$M$22:$M$37,0))) / (INDEX($H$22:$H$37,MATCH(LARGE($M$22:$M$37,2),$M$22:$M$37,0))/INDEX($I$22:$I$37,MATCH(LARGE($M$22:$M$37,2),$M$22:$M$37,0))))*Settings!$B$7*Settings!$B$3,0))/(INDEX($I$22:$I$37,MATCH(LARGE($M$22:$M$37,2),$M$22:$M$37,0))*100),1),0),0)*INDEX($H$22:$H$37,MATCH(LARGE($M$22:$M$37,2),$M$22:$M$37,0))*100,"$#,##0")&" upfront. Max loss "&TEXT(IFERROR(IF(INDEX($I$22:$I$37,MATCH(LARGE($M$22:$M$37,2),$M$22:$M$37,0))>0,FLOOR(MIN(MIN(Settings!$B$5,Settings!$B$6*Settings!$B$3)/Settings!$B$4,IFERROR(MAX(0, INDEX($J$22:$J$37,MATCH(LARGE($M$22:$M$37,2),$M$22:$M$37,0)) - (1-INDEX($J$22:$J$37,MATCH(LARGE($M$22:$M$37,2),$M$22:$M$37,0))) / (INDEX($H$22:$H$37,MATCH(LARGE($M$22:$M$37,2),$M$22:$M$37,0))/INDEX($I$22:$I$37,MATCH(LARGE($M$22:$M$37,2),$M$22:$M$37,0))))*Settings!$B$7*Settings!$B$3,0))/(INDEX($I$22:$I$37,MATCH(LARGE($M$22:$M$37,2),$M$22:$M$37,0))*100),1),0),0)*INDEX($I$22:$I$37,MATCH(LARGE($M$22:$M$37,2),$M$22:$M$37,0))*100,"$#,##0")&".","Best of universe, but "&INDEX($L$22:$L$37,MATCH(LARGE($M$22:$M$37,2),$M$22:$M$37,0))&". Wait for the gate to clear — see the "&INDEX($A$22:$A$37,MATCH(LARGE($M$22:$M$37,2),$M$22:$M$37,0))&" tab for details."),"")
A7: =IF((LARGE($M$22:$M$37,3)>-100000000),3,"") | B7: =IF((LARGE($M$22:$M$37,3)>-100000000),INDEX($A$22:$A$37,MATCH(LARGE($M$22:$M$37,3),$M$22:$M$37,0)),"") | C7: =IF((LARGE($M$22:$M$37,3)>-100000000),INDEX($B$22:$B$37,MATCH(LARGE($M$22:$M$37,3),$M$22:$M$37,0)),"") | D7: =IF((LARGE($M$22:$M$37,3)>-100000000),INDEX($D$22:$D$37,MATCH(LARGE($M$22:$M$37,3),$M$22:$M$37,0)),"") | E7: =IF((LARGE($M$22:$M$37,3)>-100000000),TEXT(INDEX($F$22:$F$37,MATCH(LARGE($M$22:$M$37,3),$M$22:$M$37,0)),"$0")&" / "&TEXT(INDEX($G$22:$G$37,MATCH(LARGE($M$22:$M$37,3),$M$22:$M$37,0)),"$0"),"") | F7: =IF((LARGE($M$22:$M$37,3)>-100000000),INDEX($H$22:$H$37,MATCH(LARGE($M$22:$M$37,3),$M$22:$M$37,0)),"") | G7: =IF((LARGE($M$22:$M$37,3)>-100000000),INDEX($I$22:$I$37,MATCH(LARGE($M$22:$M$37,3),$M$22:$M$37,0)),"") | H7: =IF((LARGE($M$22:$M$37,3)>-100000000),IFERROR(IF(INDEX($I$22:$I$37,MATCH(LARGE($M$22:$M$37,3),$M$22:$M$37,0))>0,FLOOR(MIN(MIN(Settings!$B$5,Settings!$B$6*Settings!$B$3)/Settings!$B$4,IFERROR(MAX(0, INDEX($J$22:$J$37,MATCH(LARGE($M$22:$M$37,3),$M$22:$M$37,0)) - (1-INDEX($J$22:$J$37,MATCH(LARGE($M$22:$M$37,3),$M$22:$M$37,0))) / (INDEX($H$22:$H$37,MATCH(LARGE($M$22:$M$37,3),$M$22:$M$37,0))/INDEX($I$22:$I$37,MATCH(LARGE($M$22:$M$37,3),$M$22:$M$37,0))))*Settings!$B$7*Settings!$B$3,0))/(INDEX($I$22:$I$37,MATCH(LARGE($M$22:$M$37,3),$M$22:$M$37,0))*100),1),0),0),"") | I7: =IF((LARGE($M$22:$M$37,3)>-100000000),INDEX($L$22:$L$37,MATCH(LARGE($M$22:$M$37,3),$M$22:$M$37,0)),"") | J7: =IF((LARGE($M$22:$M$37,3)>-100000000),IF(INDEX($L$22:$L$37,MATCH(LARGE($M$22:$M$37,3),$M$22:$M$37,0))="GO","SELL "&TEXT(IFERROR(IF(INDEX($I$22:$I$37,MATCH(LARGE($M$22:$M$37,3),$M$22:$M$37,0))>0,FLOOR(MIN(MIN(Settings!$B$5,Settings!$B$6*Settings!$B$3)/Settings!$B$4,IFERROR(MAX(0, INDEX($J$22:$J$37,MATCH(LARGE($M$22:$M$37,3),$M$22:$M$37,0)) - (1-INDEX($J$22:$J$37,MATCH(LARGE($M$22:$M$37,3),$M$22:$M$37,0))) / (INDEX($H$22:$H$37,MATCH(LARGE($M$22:$M$37,3),$M$22:$M$37,0))/INDEX($I$22:$I$37,MATCH(LARGE($M$22:$M$37,3),$M$22:$M$37,0))))*Settings!$B$7*Settings!$B$3,0))/(INDEX($I$22:$I$37,MATCH(LARGE($M$22:$M$37,3),$M$22:$M$37,0))*100),1),0),0),"0")&" "&INDEX($A$22:$A$37,MATCH(LARGE($M$22:$M$37,3),$M$22:$M$37,0))&" "&INDEX($B$22:$B$37,MATCH(LARGE($M$22:$M$37,3),$M$22:$M$37,0))&" "&TEXT(INDEX($F$22:$F$37,MATCH(LARGE($M$22:$M$37,3),$M$22:$M$37,0)),"$0")&"/"&TEXT(INDEX($G$22:$G$37,MATCH(LARGE($M$22:$M$37,3),$M$22:$M$37,0)),"$0")&" exp "&TEXT(INDEX($D$22:$D$37,MATCH(LARGE($M$22:$M$37,3),$M$22:$M$37,0)),"m/d")&". Collect "&TEXT(IFERROR(IF(INDEX($I$22:$I$37,MATCH(LARGE($M$22:$M$37,3),$M$22:$M$37,0))>0,FLOOR(MIN(MIN(Settings!$B$5,Settings!$B$6*Settings!$B$3)/Settings!$B$4,IFERROR(MAX(0, INDEX($J$22:$J$37,MATCH(LARGE($M$22:$M$37,3),$M$22:$M$37,0)) - (1-INDEX($J$22:$J$37,MATCH(LARGE($M$22:$M$37,3),$M$22:$M$37,0))) / (INDEX($H$22:$H$37,MATCH(LARGE($M$22:$M$37,3),$M$22:$M$37,0))/INDEX($I$22:$I$37,MATCH(LARGE($M$22:$M$37,3),$M$22:$M$37,0))))*Settings!$B$7*Settings!$B$3,0))/(INDEX($I$22:$I$37,MATCH(LARGE($M$22:$M$37,3),$M$22:$M$37,0))*100),1),0),0)*INDEX($H$22:$H$37,MATCH(LARGE($M$22:$M$37,3),$M$22:$M$37,0))*100,"$#,##0")&" upfront. Max loss "&TEXT(IFERROR(IF(INDEX($I$22:$I$37,MATCH(LARGE($M$22:$M$37,3),$M$22:$M$37,0))>0,FLOOR(MIN(MIN(Settings!$B$5,Settings!$B$6*Settings!$B$3)/Settings!$B$4,IFERROR(MAX(0, INDEX($J$22:$J$37,MATCH(LARGE($M$22:$M$37,3),$M$22:$M$37,0)) - (1-INDEX($J$22:$J$37,MATCH(LARGE($M$22:$M$37,3),$M$22:$M$37,0))) / (INDEX($H$22:$H$37,MATCH(LARGE($M$22:$M$37,3),$M$22:$M$37,0))/INDEX($I$22:$I$37,MATCH(LARGE($M$22:$M$37,3),$M$22:$M$37,0))))*Settings!$B$7*Settings!$B$3,0))/(INDEX($I$22:$I$37,MATCH(LARGE($M$22:$M$37,3),$M$22:$M$37,0))*100),1),0),0)*INDEX($I$22:$I$37,MATCH(LARGE($M$22:$M$37,3),$M$22:$M$37,0))*100,"$#,##0")&".","Best of universe, but "&INDEX($L$22:$L$37,MATCH(LARGE($M$22:$M$37,3),$M$22:$M$37,0))&". Wait for the gate to clear — see the "&INDEX($A$22:$A$37,MATCH(LARGE($M$22:$M$37,3),$M$22:$M$37,0))&" tab for details."),"")
A8: H | B8: UVXY | C8: Hedge | D8: =UVXY!$D$8 -> 46220 | E8: =TEXT(UVXY!$D$10,"$0")&" call (long)" -> $0 call (long) | F8: — | G8: =UVXY!$L$14 -> 0 | H8: =UVXY!$B$18 -> 0 | I8: =IF(UVXY!$L$14>0,"BUY","WAIT") -> WAIT | J8: =IF(UVXY!$L$14>0,"BUY "&TEXT(UVXY!$B$18,"0")&" UVXY "&TEXT(UVXY!$D$10,"$0")&" calls exp "&TEXT(UVXY!$D$8,"m/d")&". Total cost "&TEXT(UVXY!$B$19,"$#,##0")&".","Wait — no UVXY quote.") -> Wait — no UVXY quote.
A10: BOOK SUMMARY (top 3 spreads + hedge)
A11: Total credit if all 3 opened ($) | F11: =IFERROR(SUMPRODUCT(F5:F7,H5:H7)*100,0) -> 0
A12: Total max loss across 3 spreads ($) | F12: =IFERROR(SUMPRODUCT(G5:G7,H5:H7)*100,0) -> 0
A13: Hedge cost (UVXY) | F13: =IFERROR(UVXY!$B$19,0) -> 0
A14: Net target this month (50% TP − hedge) | F14: =IFERROR(SUMPRODUCT(F5:F7,H5:H7)*100*0.5 - UVXY!$B$19,0) -> 0
A15: % of account at risk (top 3) | F15: =IFERROR(SUMPRODUCT(G5:G7,H5:H7)*100/Settings!$B$3,0) -> 0
A20: AGGREGATION TABLE — each ticker's best of 4 (row 38 on its tab)
A21: Ticker | B21: Strategy | C21: ExpLabel | D21: Exp | E21: DTE | F21: Short_K | G21: Long_K | H21: Credit | I21: MaxLoss | J21: POP | K21: EV/Max | L21: Signal | M21: Score
A22: SPY | B22: =SPY!$A$38 -> BullPut | C22: =SPY!$B$38 -> Front | D22: =SPY!$C$38 -> 46220 | E22: =SPY!$D$38 -> 67 | F22: =SPY!$E$38 -> 0 | G22: =SPY!$F$38 -> -5 | H22: =SPY!$G$38 -> 0 | I22: =SPY!$H$38 -> 5 | J22: =SPY!$I$38 -> 1 | K22: =SPY!$J$38 -> 0 | L22: =SPY!$K$38 -> WAIT - DELTA | M22: =SPY!$L$38 -> -1000000000
A23: XLB | B23: =XLB!$A$38 -> BullPut | C23: =XLB!$B$38 -> Front | D23: =XLB!$C$38 -> 46220 | E23: =XLB!$D$38 -> 67 | F23: =XLB!$E$38 -> 0 | G23: =XLB!$F$38 -> -2 | H23: =XLB!$G$38 -> 0 | I23: =XLB!$H$38 -> 2 | J23: =XLB!$I$38 -> 1 | K23: =XLB!$J$38 -> 0 | L23: =XLB!$K$38 -> WAIT - DELTA | M23: =XLB!$L$38 -> -1000000000
A24: XLC | B24: =XLC!$A$38 -> BullPut | C24: =XLC!$B$38 -> Front | D24: =XLC!$C$38 -> 46220 | E24: =XLC!$D$38 -> 67 | F24: =XLC!$E$38 -> 0 | G24: =XLC!$F$38 -> -2 | H24: =XLC!$G$38 -> 0 | I24: =XLC!$H$38 -> 2 | J24: =XLC!$I$38 -> 1 | K24: =XLC!$J$38 -> 0 | L24: =XLC!$K$38 -> WAIT - DELTA | M24: =XLC!$L$38 -> -1000000000
A25: XLE | B25: =XLE!$A$38 -> BullPut | C25: =XLE!$B$38 -> Front | D25: =XLE!$C$38 -> 46220 | E25: =XLE!$D$38 -> 67 | F25: =XLE!$E$38 -> 0 | G25: =XLE!$F$38 -> -2 | H25: =XLE!$G$38 -> 0 | I25: =XLE!$H$38 -> 2 | J25: =XLE!$I$38 -> 1 | K25: =XLE!$J$38 -> 0 | L25: =XLE!$K$38 -> WAIT - DELTA | M25: =XLE!$L$38 -> -1000000000
A26: XLF | B26: =XLF!$A$38 -> BullPut | C26: =XLF!$B$38 -> Front | D26: =XLF!$C$38 -> 46220 | E26: =XLF!$D$38 -> 67 | F26: =XLF!$E$38 -> 0 | G26: =XLF!$F$38 -> -2 | H26: =XLF!$G$38 -> 0 | I26: =XLF!$H$38 -> 2 | J26: =XLF!$I$38 -> 1 | K26: =XLF!$J$38 -> 0 | L26: =XLF!$K$38 -> WAIT - DELTA | M26: =XLF!$L$38 -> -1000000000
A27: XLI | B27: =XLI!$A$38 -> BullPut | C27: =XLI!$B$38 -> Front | D27: =XLI!$C$38 -> 46220 | E27: =XLI!$D$38 -> 67 | F27: =XLI!$E$38 -> 0 | G27: =XLI!$F$38 -> -2 | H27: =XLI!$G$38 -> 0 | I27: =XLI!$H$38 -> 2 | J27: =XLI!$I$38 -> 1 | K27: =XLI!$J$38 -> 0 | L27: =XLI!$K$38 -> WAIT - DELTA | M27: =XLI!$L$38 -> -1000000000
A28: XLK | B28: =XLK!$A$38 -> BullPut | C28: =XLK!$B$38 -> Front | D28: =XLK!$C$38 -> 46220 | E28: =XLK!$D$38 -> 67 | F28: =XLK!$E$38 -> 0 | G28: =XLK!$F$38 -> -5 | H28: =XLK!$G$38 -> 0 | I28: =XLK!$H$38 -> 5 | J28: =XLK!$I$38 -> 1 | K28: =XLK!$J$38 -> 0 | L28: =XLK!$K$38 -> WAIT - DELTA | M28: =XLK!$L$38 -> -1000000000
A29: XLP | B29: =XLP!$A$38 -> BullPut | C29: =XLP!$B$38 -> Front | D29: =XLP!$C$38 -> 46220 | E29: =XLP!$D$38 -> 67 | F29: =XLP!$E$38 -> 0 | G29: =XLP!$F$38 -> -1 | H29: =XLP!$G$38 -> 0 | I29: =XLP!$H$38 -> 1 | J29: =XLP!$I$38 -> 1 | K29: =XLP!$J$38 -> 0 | L29: =XLP!$K$38 -> WAIT - DELTA | M29: =XLP!$L$38 -> -1000000000
A30: XLRE | B30: =XLRE!$A$38 -> BullPut | C30: =XLRE!$B$38 -> Front | D30: =XLRE!$C$38 -> 46220 | E30: =XLRE!$D$38 -> 67 | F30: =XLRE!$E$38 -> 0 | G30: =XLRE!$F$38 -> -1 | H30: =XLRE!$G$38 -> 0 | I30: =XLRE!$H$38 -> 1 | J30: =XLRE!$I$38 -> 1 | K30: =XLRE!$J$38 -> 0 | L30: =XLRE!$K$38 -> WAIT - DELTA | M30: =XLRE!$L$38 -> -1000000000
A31: XLU | B31: =XLU!$A$38 -> BullPut | C31: =XLU!$B$38 -> Front | D31: =XLU!$C$38 -> 46220 | E31: =XLU!$D$38 -> 67 | F31: =XLU!$E$38 -> 0 | G31: =XLU!$F$38 -> -1 | H31: =XLU!$G$38 -> 0 | I31: =XLU!$H$38 -> 1 | J31: =XLU!$I$38 -> 1 | K31: =XLU!$J$38 -> 0 | L31: =XLU!$K$38 -> WAIT - DELTA | M31: =XLU!$L$38 -> -1000000000
A32: XLV | B32: =XLV!$A$38 -> BullPut | C32: =XLV!$B$38 -> Front | D32: =XLV!$C$38 -> 46220 | E32: =XLV!$D$38 -> 67 | F32: =XLV!$E$38 -> 0 | G32: =XLV!$F$38 -> -2 | H32: =XLV!$G$38 -> 0 | I32: =XLV!$H$38 -> 2 | J32: =XLV!$I$38 -> 1 | K32: =XLV!$J$38 -> 0 | L32: =XLV!$K$38 -> WAIT - DELTA | M32: =XLV!$L$38 -> -1000000000
A33: XLY | B33: =XLY!$A$38 -> BullPut | C33: =XLY!$B$38 -> Front | D33: =XLY!$C$38 -> 46220 | E33: =XLY!$D$38 -> 67 | F33: =XLY!$E$38 -> 0 | G33: =XLY!$F$38 -> -5 | H33: =XLY!$G$38 -> 0 | I33: =XLY!$H$38 -> 5 | J33: =XLY!$I$38 -> 1 | K33: =XLY!$J$38 -> 0 | L33: =XLY!$K$38 -> WAIT - DELTA | M33: =XLY!$L$38 -> -1000000000
A34: XOP | B34: =XOP!$A$38 -> BullPut | C34: =XOP!$B$38 -> Front | D34: =XOP!$C$38 -> 46220 | E34: =XOP!$D$38 -> 67 | F34: =XOP!$E$38 -> 0 | G34: =XOP!$F$38 -> -2 | H34: =XOP!$G$38 -> 0 | I34: =XOP!$H$38 -> 2 | J34: =XOP!$I$38 -> 1 | K34: =XOP!$J$38 -> 0 | L34: =XOP!$K$38 -> WAIT - DELTA | M34: =XOP!$L$38 -> -1000000000
A35: GLD | B35: =GLD!$A$38 -> BullPut | C35: =GLD!$B$38 -> Front | D35: =GLD!$C$38 -> 46220 | E35: =GLD!$D$38 -> 67 | F35: =GLD!$E$38 -> 0 | G35: =GLD!$F$38 -> -5 | H35: =GLD!$G$38 -> 0 | I35: =GLD!$H$38 -> 5 | J35: =GLD!$I$38 -> 1 | K35: =GLD!$J$38 -> 0 | L35: =GLD!$K$38 -> WAIT - DELTA | M35: =GLD!$L$38 -> -1000000000
A36: GDX | B36: =GDX!$A$38 -> BullPut | C36: =GDX!$B$38 -> Front | D36: =GDX!$C$38 -> 46220 | E36: =GDX!$D$38 -> 67 | F36: =GDX!$E$38 -> 0 | G36: =GDX!$F$38 -> -1 | H36: =GDX!$G$38 -> 0 | I36: =GDX!$H$38 -> 1 | J36: =GDX!$I$38 -> 1 | K36: =GDX!$J$38 -> 0 | L36: =GDX!$K$38 -> WAIT - DELTA | M36: =GDX!$L$38 -> -1000000000
A37: EEM | B37: =EEM!$A$38 -> BullPut | C37: =EEM!$B$38 -> Front | D37: =EEM!$C$38 -> 46220 | E37: =EEM!$D$38 -> 67 | F37: =EEM!$E$38 -> 0 | G37: =EEM!$F$38 -> -1 | H37: =EEM!$G$38 -> 0 | I37: =EEM!$H$38 -> 1 | J37: =EEM!$I$38 -> 1 | K37: =EEM!$J$38 -> 0 | L37: =EEM!$K$38 -> WAIT - DELTA | M37: =EEM!$L$38 -> -1000000000

Sheet SPY
A1: SPY — SPDR S&P 500 (Broad US)
A3: Underlying | B3: BBG_Ticker | C3: PX_LAST | D3: IVOL_RANK | E3: Spot | F3: IVR
A4: SPY | B4: SPY US Equity | C4: =C$3 -> PX_LAST | D4: =D$3 -> IVOL_RANK | E4: =IFERROR(bdp(B4,C4),0) -> 0 | F4: =IFERROR(bdp(B4,D4),0) -> 0
A6: PARAMETER OVERRIDES — blank Override = use Default
A7: Parameter | B7: Default | C7: Override | D7: Effective
A8: Width ($) | B8: 5 | D8: =IF(C8="",B8,C8) -> 5
A9: Front Expiration | B9: =Calendar!$B$11 -> 46220 | D9: =IF(C9="",B9,C9) -> 46220
A10: Back Expiration | B10: =Calendar!$B$12 -> 46255 | D10: =IF(C10="",B10,C10) -> 46255
A11: BP Short Strike ($) | B11: =IF($E$4=0,0,FLOOR($E$4*(1-0.05)/$D$8,1)*$D$8) -> 0 | D11: =IF(C11="",B11,C11) -> 0
A12: BC Short Strike ($) | B12: =IF($E$4=0,0,CEILING($E$4*(1+0.05)/$D$8,1)*$D$8) -> 0 | D12: =IF(C12="",B12,C12) -> 0
A14: BULL PUT ANALYSIS — short put + long lower put
A15: Strategy | B15: Leg | C15: Type | D15: Strike | E15: Expiration | F15: BBG_Ticker | G15: PX_LAST | H15: BID | I15: ASK | J15: VOL_MEAN | K15: DELTA_MID_RT | L15: Mid
A16: BullPut | B16: Front Short | C16: P | D16: =$D$11 -> 0 | E16: =$D$9 -> 46220 | F16: ="SPY"&" US "&TEXT(E16,"mm/dd/yy")&" "&"P"&IF(D16=INT(D16),INT(D16),D16)&" Equity" -> SPY US 07/17/26 P0 Equity | G16: =IFERROR(bdp($F16, G$15), 0) -> 0 | H16: =IFERROR(bdp($F16, H$15), 0) -> 0 | I16: =IFERROR(bdp($F16, I$15), 0) -> 0 | J16: =IFERROR(bdp($F16, J$15), 0) -> 0 | K16: =IFERROR(bdp($F16, K$15), 0) -> 0 | L16: =IFERROR((H16+I16)/2, 0) -> 0
A17: BullPut | B17: Front Long | C17: P | D17: =$D$11-$D$8 -> -5 | E17: =$D$9 -> 46220 | F17: ="SPY"&" US "&TEXT(E17,"mm/dd/yy")&" "&"P"&IF(D17=INT(D17),INT(D17),D17)&" Equity" -> SPY US 07/17/26 P-5 Equity | G17: =IFERROR(bdp($F17, G$15), 0) -> 0 | H17: =IFERROR(bdp($F17, H$15), 0) -> 0 | I17: =IFERROR(bdp($F17, I$15), 0) -> 0 | J17: =IFERROR(bdp($F17, J$15), 0) -> 0 | K17: =IFERROR(bdp($F17, K$15), 0) -> 0 | L17: =IFERROR((H17+I17)/2, 0) -> 0
A18: BullPut | B18: Back Short | C18: P | D18: =$D$11 -> 0 | E18: =$D$10 -> 46255 | F18: ="SPY"&" US "&TEXT(E18,"mm/dd/yy")&" "&"P"&IF(D18=INT(D18),INT(D18),D18)&" Equity" -> SPY US 08/21/26 P0 Equity | G18: =IFERROR(bdp($F18, G$15), 0) -> 0 | H18: =IFERROR(bdp($F18, H$15), 0) -> 0 | I18: =IFERROR(bdp($F18, I$15), 0) -> 0 | J18: =IFERROR(bdp($F18, J$15), 0) -> 0 | K18: =IFERROR(bdp($F18, K$15), 0) -> 0 | L18: =IFERROR((H18+I18)/2, 0) -> 0
A19: BullPut | B19: Back Long | C19: P | D19: =$D$11-$D$8 -> -5 | E19: =$D$10 -> 46255 | F19: ="SPY"&" US "&TEXT(E19,"mm/dd/yy")&" "&"P"&IF(D19=INT(D19),INT(D19),D19)&" Equity" -> SPY US 08/21/26 P-5 Equity | G19: =IFERROR(bdp($F19, G$15), 0) -> 0 | H19: =IFERROR(bdp($F19, H$15), 0) -> 0 | I19: =IFERROR(bdp($F19, I$15), 0) -> 0 | J19: =IFERROR(bdp($F19, J$15), 0) -> 0 | K19: =IFERROR(bdp($F19, K$15), 0) -> 0 | L19: =IFERROR((H19+I19)/2, 0) -> 0
A21: Strategy | B21: Exp_Label | C21: DTE | D21: Short_K | E21: Long_K | F21: Width | G21: Credit | H21: MaxLoss | I21: C/W | J21: BidAsk% | K21: Buffer% | L21: POP | M21: EV | N21: EV/Max | O21: Signal | P21: Score
A22: BullPut | B22: Front | C22: =$D$9-TODAY() -> 67 | D22: =$D$11 -> 0 | E22: =$D$11-$D$8 -> -5 | F22: =$D$8 -> 5 | G22: =IFERROR(L16-L17,0) -> 0 | H22: =IFERROR(F22-G22,0) -> 5 | I22: =IFERROR(G22/F22,0) -> 0 | J22: =IFERROR((I16-H16)/L16,1) -> 1 | K22: =IFERROR(($E$4-D22)/$E$4,0) -> 0 | L22: =IFERROR(1-ABS(K16),0) -> 1 | M22: =L22*G22-(1-L22)*H22 -> 0 | N22: =IFERROR(M22/H22,0) -> 0 | O22: =IF(NOT(AND(C22>=Settings!$B$14,C22<=Settings!$B$15)),"WAIT - DTE",IF(NOT(AND(ABS(K16)>=Settings!$B$12,ABS(K16)<=Settings!$B$13)),"WAIT - DELTA",IF(NOT($F$4>=Settings!$B$8),"WAIT - IVR",IF(NOT(G22>=Settings!$B$10),"WAIT - CREDIT",IF(NOT(I22>=Settings!$B$9),"WAIT - C/W",IF(NOT(AND(J22<=Settings!$B$11,H16>0,I16>0,H17>0,I17>0)),"WAIT - LIQ",IF(NOT(K22>=Settings!$B$19),"WAIT - BUFFER","GO"))))))) -> WAIT - DELTA | P22: =IF(O22="GO",N22,-1000000000) -> -1000000000
A23: BullPut | B23: Back | C23: =$D$10-TODAY() -> 102 | D23: =$D$11 -> 0 | E23: =$D$11-$D$8 -> -5 | F23: =$D$8 -> 5 | G23: =IFERROR(L18-L19,0) -> 0 | H23: =IFERROR(F23-G23,0) -> 5 | I23: =IFERROR(G23/F23,0) -> 0 | J23: =IFERROR((I18-H18)/L18,1) -> 1 | K23: =IFERROR(($E$4-D23)/$E$4,0) -> 0 | L23: =IFERROR(1-ABS(K18),0) -> 1 | M23: =L23*G23-(1-L23)*H23 -> 0 | N23: =IFERROR(M23/H23,0) -> 0 | O23: =IF(NOT(AND(C23>=Settings!$B$14,C23<=Settings!$B$15)),"WAIT - DTE",IF(NOT(AND(ABS(K18)>=Settings!$B$12,ABS(K18)<=Settings!$B$13)),"WAIT - DELTA",IF(NOT($F$4>=Settings!$B$8),"WAIT - IVR",IF(NOT(G23>=Settings!$B$10),"WAIT - CREDIT",IF(NOT(I23>=Settings!$B$9),"WAIT - C/W",IF(NOT(AND(J23<=Settings!$B$11,H18>0,I18>0,H19>0,I19>0)),"WAIT - LIQ",IF(NOT(K23>=Settings!$B$19),"WAIT - BUFFER","GO"))))))) -> WAIT - DELTA | P23: =IF(O23="GO",N23,-1000000000) -> -1000000000
A25: BEAR CALL ANALYSIS — short call + long higher call
A26: Strategy | B26: Leg | C26: Type | D26: Strike | E26: Expiration | F26: BBG_Ticker | G26: PX_LAST | H26: BID | I26: ASK | J26: VOL_MEAN | K26: DELTA_MID_RT | L26: Mid
A27: BearCall | B27: Front Short | C27: C | D27: =$D$12 -> 0 | E27: =$D$9 -> 46220 | F27: ="SPY"&" US "&TEXT(E27,"mm/dd/yy")&" "&"C"&IF(D27=INT(D27),INT(D27),D27)&" Equity" -> SPY US 07/17/26 C0 Equity | G27: =IFERROR(bdp($F27, G$26), 0) -> 0 | H27: =IFERROR(bdp($F27, H$26), 0) -> 0 | I27: =IFERROR(bdp($F27, I$26), 0) -> 0 | J27: =IFERROR(bdp($F27, J$26), 0) -> 0 | K27: =IFERROR(bdp($F27, K$26), 0) -> 0 | L27: =IFERROR((H27+I27)/2, 0) -> 0
A28: BearCall | B28: Front Long | C28: C | D28: =$D$12+$D$8 -> 5 | E28: =$D$9 -> 46220 | F28: ="SPY"&" US "&TEXT(E28,"mm/dd/yy")&" "&"C"&IF(D28=INT(D28),INT(D28),D28)&" Equity" -> SPY US 07/17/26 C5 Equity | G28: =IFERROR(bdp($F28, G$26), 0) -> 0 | H28: =IFERROR(bdp($F28, H$26), 0) -> 0 | I28: =IFERROR(bdp($F28, I$26), 0) -> 0 | J28: =IFERROR(bdp($F28, J$26), 0) -> 0 | K28: =IFERROR(bdp($F28, K$26), 0) -> 0 | L28: =IFERROR((H28+I28)/2, 0) -> 0
A29: BearCall | B29: Back Short | C29: C | D29: =$D$12 -> 0 | E29: =$D$10 -> 46255 | F29: ="SPY"&" US "&TEXT(E29,"mm/dd/yy")&" "&"C"&IF(D29=INT(D29),INT(D29),D29)&" Equity" -> SPY US 08/21/26 C0 Equity | G29: =IFERROR(bdp($F29, G$26), 0) -> 0 | H29: =IFERROR(bdp($F29, H$26), 0) -> 0 | I29: =IFERROR(bdp($F29, I$26), 0) -> 0 | J29: =IFERROR(bdp($F29, J$26), 0) -> 0 | K29: =IFERROR(bdp($F29, K$26), 0) -> 0 | L29: =IFERROR((H29+I29)/2, 0) -> 0
A30: BearCall | B30: Back Long | C30: C | D30: =$D$12+$D$8 -> 5 | E30: =$D$10 -> 46255 | F30: ="SPY"&" US "&TEXT(E30,"mm/dd/yy")&" "&"C"&IF(D30=INT(D30),INT(D30),D30)&" Equity" -> SPY US 08/21/26 C5 Equity | G30: =IFERROR(bdp($F30, G$26), 0) -> 0 | H30: =IFERROR(bdp($F30, H$26), 0) -> 0 | I30: =IFERROR(bdp($F30, I$26), 0) -> 0 | J30: =IFERROR(bdp($F30, J$26), 0) -> 0 | K30: =IFERROR(bdp($F30, K$26), 0) -> 0 | L30: =IFERROR((H30+I30)/2, 0) -> 0
A32: Strategy | B32: Exp_Label | C32: DTE | D32: Short_K | E32: Long_K | F32: Width | G32: Credit | H32: MaxLoss | I32: C/W | J32: BidAsk% | K32: Buffer% | L32: POP | M32: EV | N32: EV/Max | O32: Signal | P32: Score
A33: BearCall | B33: Front | C33: =$D$9-TODAY() -> 67 | D33: =$D$12 -> 0 | E33: =$D$12+$D$8 -> 5 | F33: =$D$8 -> 5 | G33: =IFERROR(L27-L28,0) -> 0 | H33: =IFERROR(F33-G33,0) -> 5 | I33: =IFERROR(G33/F33,0) -> 0 | J33: =IFERROR((I27-H27)/L27,1) -> 1 | K33: =IFERROR((D33-$E$4)/$E$4,0) -> 0 | L33: =IFERROR(1-ABS(K27),0) -> 1 | M33: =L33*G33-(1-L33)*H33 -> 0 | N33: =IFERROR(M33/H33,0) -> 0 | O33: =IF(NOT(AND(C33>=Settings!$B$14,C33<=Settings!$B$15)),"WAIT - DTE",IF(NOT(AND(ABS(K27)>=Settings!$B$12,ABS(K27)<=Settings!$B$13)),"WAIT - DELTA",IF(NOT($F$4>=Settings!$B$8),"WAIT - IVR",IF(NOT(G33>=Settings!$B$10),"WAIT - CREDIT",IF(NOT(I33>=Settings!$B$9),"WAIT - C/W",IF(NOT(AND(J33<=Settings!$B$11,H27>0,I27>0,H28>0,I28>0)),"WAIT - LIQ",IF(NOT(K33>=Settings!$B$19),"WAIT - BUFFER","GO"))))))) -> WAIT - DELTA | P33: =IF(O33="GO",N33,-1000000000) -> -1000000000
A34: BearCall | B34: Back | C34: =$D$10-TODAY() -> 102 | D34: =$D$12 -> 0 | E34: =$D$12+$D$8 -> 5 | F34: =$D$8 -> 5 | G34: =IFERROR(L29-L30,0) -> 0 | H34: =IFERROR(F34-G34,0) -> 5 | I34: =IFERROR(G34/F34,0) -> 0 | J34: =IFERROR((I29-H29)/L29,1) -> 1 | K34: =IFERROR((D34-$E$4)/$E$4,0) -> 0 | L34: =IFERROR(1-ABS(K29),0) -> 1 | M34: =L34*G34-(1-L34)*H34 -> 0 | N34: =IFERROR(M34/H34,0) -> 0 | O34: =IF(NOT(AND(C34>=Settings!$B$14,C34<=Settings!$B$15)),"WAIT - DTE",IF(NOT(AND(ABS(K29)>=Settings!$B$12,ABS(K29)<=Settings!$B$13)),"WAIT - DELTA",IF(NOT($F$4>=Settings!$B$8),"WAIT - IVR",IF(NOT(G34>=Settings!$B$10),"WAIT - CREDIT",IF(NOT(I34>=Settings!$B$9),"WAIT - C/W",IF(NOT(AND(J34<=Settings!$B$11,H29>0,I29>0,H30>0,I30>0)),"WAIT - LIQ",IF(NOT(K34>=Settings!$B$19),"WAIT - BUFFER","GO"))))))) -> WAIT - DELTA | P34: =IF(O34="GO",N34,-1000000000) -> -1000000000
A36: TICKER SUMMARY — best spread on this tab
A37: BestStrategy | B37: BestExpLabel | C37: BestExp | D37: DTE | E37: Short_K | F37: Long_K | G37: Credit | H37: MaxLoss | I37: POP | J37: EV/Max | K37: Signal | L37: Score
A38: =INDEX($A$22:$P$34, IF(P22=MAX(P22,P23,P33,P34),22,IF(P23=MAX(P22,P23,P33,P34),23,IF(P33=MAX(P22,P23,P33,P34),33,34)))-21, 1) -> BullPut | B38: =INDEX($A$22:$P$34, IF(P22=MAX(P22,P23,P33,P34),22,IF(P23=MAX(P22,P23,P33,P34),23,IF(P33=MAX(P22,P23,P33,P34),33,34)))-21, 2) -> Front | C38: =IF(INDEX($A$22:$P$34, IF(P22=MAX(P22,P23,P33,P34),22,IF(P23=MAX(P22,P23,P33,P34),23,IF(P33=MAX(P22,P23,P33,P34),33,34)))-21, 2)="Front",$D$9,$D$10) -> 46220 | D38: =INDEX($A$22:$P$34, IF(P22=MAX(P22,P23,P33,P34),22,IF(P23=MAX(P22,P23,P33,P34),23,IF(P33=MAX(P22,P23,P33,P34),33,34)))-21, 3) -> 67 | E38: =INDEX($A$22:$P$34, IF(P22=MAX(P22,P23,P33,P34),22,IF(P23=MAX(P22,P23,P33,P34),23,IF(P33=MAX(P22,P23,P33,P34),33,34)))-21, 4) -> 0 | F38: =INDEX($A$22:$P$34, IF(P22=MAX(P22,P23,P33,P34),22,IF(P23=MAX(P22,P23,P33,P34),23,IF(P33=MAX(P22,P23,P33,P34),33,34)))-21, 5) -> -5 | G38: =INDEX($A$22:$P$34, IF(P22=MAX(P22,P23,P33,P34),22,IF(P23=MAX(P22,P23,P33,P34),23,IF(P33=MAX(P22,P23,P33,P34),33,34)))-21, 7) -> 0 | H38: =INDEX($A$22:$P$34, IF(P22=MAX(P22,P23,P33,P34),22,IF(P23=MAX(P22,P23,P33,P34),23,IF(P33=MAX(P22,P23,P33,P34),33,34)))-21, 8) -> 5 | I38: =INDEX($A$22:$P$34, IF(P22=MAX(P22,P23,P33,P34),22,IF(P23=MAX(P22,P23,P33,P34),23,IF(P33=MAX(P22,P23,P33,P34),33,34)))-21, 12) -> 1 | J38: =INDEX($A$22:$P$34, IF(P22=MAX(P22,P23,P33,P34),22,IF(P23=MAX(P22,P23,P33,P34),23,IF(P33=MAX(P22,P23,P33,P34),33,34)))-21, 14) -> 0 | K38: =INDEX($A$22:$P$34, IF(P22=MAX(P22,P23,P33,P34),22,IF(P23=MAX(P22,P23,P33,P34),23,IF(P33=MAX(P22,P23,P33,P34),33,34)))-21, 15) -> WAIT - DELTA | L38: =MAX(P22,P23,P33,P34) -> -1000000000

Sheet XLB
A1: XLB — Materials (S&P Sector)
A3: Underlying | B3: BBG_Ticker | C3: PX_LAST | D3: IVOL_RANK | E3: Spot | F3: IVR
A4: XLB | B4: XLB US Equity | C4: =C$3 -> PX_LAST | D4: =D$3 -> IVOL_RANK | E4: =IFERROR(bdp(B4,C4),0) -> 0 | F4: =IFERROR(bdp(B4,D4),0) -> 0
A6: PARAMETER OVERRIDES — blank Override = use Default
A7: Parameter | B7: Default | C7: Override | D7: Effective
A8: Width ($) | B8: 2 | D8: =IF(C8="",B8,C8) -> 2
A9: Front Expiration | B9: =Calendar!$B$11 -> 46220 | D9: =IF(C9="",B9,C9) -> 46220
A10: Back Expiration | B10: =Calendar!$B$12 -> 46255 | D10: =IF(C10="",B10,C10) -> 46255
A11: BP Short Strike ($) | B11: =IF($E$4=0,0,FLOOR($E$4*(1-0.05)/$D$8,1)*$D$8) -> 0 | D11: =IF(C11="",B11,C11) -> 0
A12: BC Short Strike ($) | B12: =IF($E$4=0,0,CEILING($E$4*(1+0.05)/$D$8,1)*$D$8) -> 0 | D12: =IF(C12="",B12,C12) -> 0
A14: BULL PUT ANALYSIS — short put + long lower put
A15: Strategy | B15: Leg | C15: Type | D15: Strike | E15: Expiration | F15: BBG_Ticker | G15: PX_LAST | H15: BID | I15: ASK | J15: VOL_MEAN | K15: DELTA_MID_RT | L15: Mid
A16: BullPut | B16: Front Short | C16: P | D16: =$D$11 -> 0 | E16: =$D$9 -> 46220 | F16: ="XLB"&" US "&TEXT(E16,"mm/dd/yy")&" "&"P"&IF(D16=INT(D16),INT(D16),D16)&" Equity" -> XLB US 07/17/26 P0 Equity | G16: =IFERROR(bdp($F16, G$15), 0) -> 0 | H16: =IFERROR(bdp($F16, H$15), 0) -> 0 | I16: =IFERROR(bdp($F16, I$15), 0) -> 0 | J16: =IFERROR(bdp($F16, J$15), 0) -> 0 | K16: =IFERROR(bdp($F16, K$15), 0) -> 0 | L16: =IFERROR((H16+I16)/2, 0) -> 0
A17: BullPut | B17: Front Long | C17: P | D17: =$D$11-$D$8 -> -2 | E17: =$D$9 -> 46220 | F17: ="XLB"&" US "&TEXT(E17,"mm/dd/yy")&" "&"P"&IF(D17=INT(D17),INT(D17),D17)&" Equity" -> XLB US 07/17/26 P-2 Equity | G17: =IFERROR(bdp($F17, G$15), 0) -> 0 | H17: =IFERROR(bdp($F17, H$15), 0) -> 0 | I17: =IFERROR(bdp($F17, I$15), 0) -> 0 | J17: =IFERROR(bdp($F17, J$15), 0) -> 0 | K17: =IFERROR(bdp($F17, K$15), 0) -> 0 | L17: =IFERROR((H17+I17)/2, 0) -> 0
A18: BullPut | B18: Back Short | C18: P | D18: =$D$11 -> 0 | E18: =$D$10 -> 46255 | F18: ="XLB"&" US "&TEXT(E18,"mm/dd/yy")&" "&"P"&IF(D18=INT(D18),INT(D18),D18)&" Equity" -> XLB US 08/21/26 P0 Equity | G18: =IFERROR(bdp($F18, G$15), 0) -> 0 | H18: =IFERROR(bdp($F18, H$15), 0) -> 0 | I18: =IFERROR(bdp($F18, I$15), 0) -> 0 | J18: =IFERROR(bdp($F18, J$15), 0) -> 0 | K18: =IFERROR(bdp($F18, K$15), 0) -> 0 | L18: =IFERROR((H18+I18)/2, 0) -> 0
A19: BullPut | B19: Back Long | C19: P | D19: =$D$11-$D$8 -> -2 | E19: =$D$10 -> 46255 | F19: ="XLB"&" US "&TEXT(E19,"mm/dd/yy")&" "&"P"&IF(D19=INT(D19),INT(D19),D19)&" Equity" -> XLB US 08/21/26 P-2 Equity | G19: =IFERROR(bdp($F19, G$15), 0) -> 0 | H19: =IFERROR(bdp($F19, H$15), 0) -> 0 | I19: =IFERROR(bdp($F19, I$15), 0) -> 0 | J19: =IFERROR(bdp($F19, J$15), 0) -> 0 | K19: =IFERROR(bdp($F19, K$15), 0) -> 0 | L19: =IFERROR((H19+I19)/2, 0) -> 0
A21: Strategy | B21: Exp_Label | C21: DTE | D21: Short_K | E21: Long_K | F21: Width | G21: Credit | H21: MaxLoss | I21: C/W | J21: BidAsk% | K21: Buffer% | L21: POP | M21: EV | N21: EV/Max | O21: Signal | P21: Score
A22: BullPut | B22: Front | C22: =$D$9-TODAY() -> 67 | D22: =$D$11 -> 0 | E22: =$D$11-$D$8 -> -2 | F22: =$D$8 -> 2 | G22: =IFERROR(L16-L17,0) -> 0 | H22: =IFERROR(F22-G22,0) -> 2 | I22: =IFERROR(G22/F22,0) -> 0 | J22: =IFERROR((I16-H16)/L16,1) -> 1 | K22: =IFERROR(($E$4-D22)/$E$4,0) -> 0 | L22: =IFERROR(1-ABS(K16),0) -> 1 | M22: =L22*G22-(1-L22)*H22 -> 0 | N22: =IFERROR(M22/H22,0) -> 0 | O22: =IF(NOT(AND(C22>=Settings!$B$14,C22<=Settings!$B$15)),"WAIT - DTE",IF(NOT(AND(ABS(K16)>=Settings!$B$12,ABS(K16)<=Settings!$B$13)),"WAIT - DELTA",IF(NOT($F$4>=Settings!$B$8),"WAIT - IVR",IF(NOT(G22>=Settings!$B$10),"WAIT - CREDIT",IF(NOT(I22>=Settings!$B$9),"WAIT - C/W",IF(NOT(AND(J22<=Settings!$B$11,H16>0,I16>0,H17>0,I17>0)),"WAIT - LIQ",IF(NOT(K22>=Settings!$B$19),"WAIT - BUFFER","GO"))))))) -> WAIT - DELTA | P22: =IF(O22="GO",N22,-1000000000) -> -1000000000
A23: BullPut | B23: Back | C23: =$D$10-TODAY() -> 102 | D23: =$D$11 -> 0 | E23: =$D$11-$D$8 -> -2 | F23: =$D$8 -> 2 | G23: =IFERROR(L18-L19,0) -> 0 | H23: =IFERROR(F23-G23,0) -> 2 | I23: =IFERROR(G23/F23,0) -> 0 | J23: =IFERROR((I18-H18)/L18,1) -> 1 | K23: =IFERROR(($E$4-D23)/$E$4,0) -> 0 | L23: =IFERROR(1-ABS(K18),0) -> 1 | M23: =L23*G23-(1-L23)*H23 -> 0 | N23: =IFERROR(M23/H23,0) -> 0 | O23: =IF(NOT(AND(C23>=Settings!$B$14,C23<=Settings!$B$15)),"WAIT - DTE",IF(NOT(AND(ABS(K18)>=Settings!$B$12,ABS(K18)<=Settings!$B$13)),"WAIT - DELTA",IF(NOT($F$4>=Settings!$B$8),"WAIT - IVR",IF(NOT(G23>=Settings!$B$10),"WAIT - CREDIT",IF(NOT(I23>=Settings!$B$9),"WAIT - C/W",IF(NOT(AND(J23<=Settings!$B$11,H18>0,I18>0,H19>0,I19>0)),"WAIT - LIQ",IF(NOT(K23>=Settings!$B$19),"WAIT - BUFFER","GO"))))))) -> WAIT - DELTA | P23: =IF(O23="GO",N23,-1000000000) -> -1000000000
A25: BEAR CALL ANALYSIS — short call + long higher call
A26: Strategy | B26: Leg | C26: Type | D26: Strike | E26: Expiration | F26: BBG_Ticker | G26: PX_LAST | H26: BID | I26: ASK | J26: VOL_MEAN | K26: DELTA_MID_RT | L26: Mid
A27: BearCall | B27: Front Short | C27: C | D27: =$D$12 -> 0 | E27: =$D$9 -> 46220 | F27: ="XLB"&" US "&TEXT(E27,"mm/dd/yy")&" "&"C"&IF(D27=INT(D27),INT(D27),D27)&" Equity" -> XLB US 07/17/26 C0 Equity | G27: =IFERROR(bdp($F27, G$26), 0) -> 0 | H27: =IFERROR(bdp($F27, H$26), 0) -> 0 | I27: =IFERROR(bdp($F27, I$26), 0) -> 0 | J27: =IFERROR(bdp($F27, J$26), 0) -> 0 | K27: =IFERROR(bdp($F27, K$26), 0) -> 0 | L27: =IFERROR((H27+I27)/2, 0) -> 0
A28: BearCall | B28: Front Long | C28: C | D28: =$D$12+$D$8 -> 2 | E28: =$D$9 -> 46220 | F28: ="XLB"&" US "&TEXT(E28,"mm/dd/yy")&" "&"C"&IF(D28=INT(D28),INT(D28),D28)&" Equity" -> XLB US 07/17/26 C2 Equity | G28: =IFERROR(bdp($F28, G$26), 0) -> 0 | H28: =IFERROR(bdp($F28, H$26), 0) -> 0 | I28: =IFERROR(bdp($F28, I$26), 0) -> 0 | J28: =IFERROR(bdp($F28, J$26), 0) -> 0 | K28: =IFERROR(bdp($F28, K$26), 0) -> 0 | L28: =IFERROR((H28+I28)/2, 0) -> 0
A29: BearCall | B29: Back Short | C29: C | D29: =$D$12 -> 0 | E29: =$D$10 -> 46255 | F29: ="XLB"&" US "&TEXT(E29,"mm/dd/yy")&" "&"C"&IF(D29=INT(D29),INT(D29),D29)&" Equity" -> XLB US 08/21/26 C0 Equity | G29: =IFERROR(bdp($F29, G$26), 0) -> 0 | H29: =IFERROR(bdp($F29, H$26), 0) -> 0 | I29: =IFERROR(bdp($F29, I$26), 0) -> 0 | J29: =IFERROR(bdp($F29, J$26), 0) -> 0 | K29: =IFERROR(bdp($F29, K$26), 0) -> 0 | L29: =IFERROR((H29+I29)/2, 0) -> 0
A30: BearCall | B30: Back Long | C30: C | D30: =$D$12+$D$8 -> 2 | E30: =$D$10 -> 46255 | F30: ="XLB"&" US "&TEXT(E30,"mm/dd/yy")&" "&"C"&IF(D30=INT(D30),INT(D30),D30)&" Equity" -> XLB US 08/21/26 C2 Equity | G30: =IFERROR(bdp($F30, G$26), 0) -> 0 | H30: =IFERROR(bdp($F30, H$26), 0) -> 0 | I30: =IFERROR(bdp($F30, I$26), 0) -> 0 | J30: =IFERROR(bdp($F30, J$26), 0) -> 0 | K30: =IFERROR(bdp($F30, K$26), 0) -> 0 | L30: =IFERROR((H30+I30)/2, 0) -> 0
A32: Strategy | B32: Exp_Label | C32: DTE | D32: Short_K | E32: Long_K | F32: Width | G32: Credit | H32: MaxLoss | I32: C/W | J32: BidAsk% | K32: Buffer% | L32: POP | M32: EV | N32: EV/Max | O32: Signal | P32: Score
A33: BearCall | B33: Front | C33: =$D$9-TODAY() -> 67 | D33: =$D$12 -> 0 | E33: =$D$12+$D$8 -> 2 | F33: =$D$8 -> 2 | G33: =IFERROR(L27-L28,0) -> 0 | H33: =IFERROR(F33-G33,0) -> 2 | I33: =IFERROR(G33/F33,0) -> 0 | J33: =IFERROR((I27-H27)/L27,1) -> 1 | K33: =IFERROR((D33-$E$4)/$E$4,0) -> 0 | L33: =IFERROR(1-ABS(K27),0) -> 1 | M33: =L33*G33-(1-L33)*H33 -> 0 | N33: =IFERROR(M33/H33,0) -> 0 | O33: =IF(NOT(AND(C33>=Settings!$B$14,C33<=Settings!$B$15)),"WAIT - DTE",IF(NOT(AND(ABS(K27)>=Settings!$B$12,ABS(K27)<=Settings!$B$13)),"WAIT - DELTA",IF(NOT($F$4>=Settings!$B$8),"WAIT - IVR",IF(NOT(G33>=Settings!$B$10),"WAIT - CREDIT",IF(NOT(I33>=Settings!$B$9),"WAIT - C/W",IF(NOT(AND(J33<=Settings!$B$11,H27>0,I27>0,H28>0,I28>0)),"WAIT - LIQ",IF(NOT(K33>=Settings!$B$19),"WAIT - BUFFER","GO"))))))) -> WAIT - DELTA | P33: =IF(O33="GO",N33,-1000000000) -> -1000000000
A34: BearCall | B34: Back | C34: =$D$10-TODAY() -> 102 | D34: =$D$12 -> 0 | E34: =$D$12+$D$8 -> 2 | F34: =$D$8 -> 2 | G34: =IFERROR(L29-L30,0) -> 0 | H34: =IFERROR(F34-G34,0) -> 2 | I34: =IFERROR(G34/F34,0) -> 0 | J34: =IFERROR((I29-H29)/L29,1) -> 1 | K34: =IFERROR((D34-$E$4)/$E$4,0) -> 0 | L34: =IFERROR(1-ABS(K29),0) -> 1 | M34: =L34*G34-(1-L34)*H34 -> 0 | N34: =IFERROR(M34/H34,0) -> 0 | O34: =IF(NOT(AND(C34>=Settings!$B$14,C34<=Settings!$B$15)),"WAIT - DTE",IF(NOT(AND(ABS(K29)>=Settings!$B$12,ABS(K29)<=Settings!$B$13)),"WAIT - DELTA",IF(NOT($F$4>=Settings!$B$8),"WAIT - IVR",IF(NOT(G34>=Settings!$B$10),"WAIT - CREDIT",IF(NOT(I34>=Settings!$B$9),"WAIT - C/W",IF(NOT(AND(J34<=Settings!$B$11,H29>0,I29>0,H30>0,I30>0)),"WAIT - LIQ",IF(NOT(K34>=Settings!$B$19),"WAIT - BUFFER","GO"))))))) -> WAIT - DELTA | P34: =IF(O34="GO",N34,-1000000000) -> -1000000000
A36: TICKER SUMMARY — best spread on this tab
A37: BestStrategy | B37: BestExpLabel | C37: BestExp | D37: DTE | E37: Short_K | F37: Long_K | G37: Credit | H37: MaxLoss | I37: POP | J37: EV/Max | K37: Signal | L37: Score
A38: =INDEX($A$22:$P$34, IF(P22=MAX(P22,P23,P33,P34),22,IF(P23=MAX(P22,P23,P33,P34),23,IF(P33=MAX(P22,P23,P33,P34),33,34)))-21, 1) -> BullPut | B38: =INDEX($A$22:$P$34, IF(P22=MAX(P22,P23,P33,P34),22,IF(P23=MAX(P22,P23,P33,P34),23,IF(P33=MAX(P22,P23,P33,P34),33,34)))-21, 2) -> Front | C38: =IF(INDEX($A$22:$P$34, IF(P22=MAX(P22,P23,P33,P34),22,IF(P23=MAX(P22,P23,P33,P34),23,IF(P33=MAX(P22,P23,P33,P34),33,34)))-21, 2)="Front",$D$9,$D$10) -> 46220 | D38: =INDEX($A$22:$P$34, IF(P22=MAX(P22,P23,P33,P34),22,IF(P23=MAX(P22,P23,P33,P34),23,IF(P33=MAX(P22,P23,P33,P34),33,34)))-21, 3) -> 67 | E38: =INDEX($A$22:$P$34, IF(P22=MAX(P22,P23,P33,P34),22,IF(P23=MAX(P22,P23,P33,P34),23,IF(P33=MAX(P22,P23,P33,P34),33,34)))-21, 4) -> 0 | F38: =INDEX($A$22:$P$34, IF(P22=MAX(P22,P23,P33,P34),22,IF(P23=MAX(P22,P23,P33,P34),23,IF(P33=MAX(P22,P23,P33,P34),33,34)))-21, 5) -> -2 | G38: =INDEX($A$22:$P$34, IF(P22=MAX(P22,P23,P33,P34),22,IF(P23=MAX(P22,P23,P33,P34),23,IF(P33=MAX(P22,P23,P33,P34),33,34)))-21, 7) -> 0 | H38: =INDEX($A$22:$P$34, IF(P22=MAX(P22,P23,P33,P34),22,IF(P23=MAX(P22,P23,P33,P34),23,IF(P33=MAX(P22,P23,P33,P34),33,34)))-21, 8) -> 2 | I38: =INDEX($A$22:$P$34, IF(P22=MAX(P22,P23,P33,P34),22,IF(P23=MAX(P22,P23,P33,P34),23,IF(P33=MAX(P22,P23,P33,P34),33,34)))-21, 12) -> 1 | J38: =INDEX($A$22:$P$34, IF(P22=MAX(P22,P23,P33,P34),22,IF(P23=MAX(P22,P23,P33,P34),23,IF(P33=MAX(P22,P23,P33,P34),33,34)))-21, 14) -> 0 | K38: =INDEX($A$22:$P$34, IF(P22=MAX(P22,P23,P33,P34),22,IF(P23=MAX(P22,P23,P33,P34),23,IF(P33=MAX(P22,P23,P33,P34),33,34)))-21, 15) -> WAIT - DELTA | L38: =MAX(P22,P23,P33,P34) -> -1000000000

Sheet XLC
A1: XLC — Communications (S&P Sector)
A3: Underlying | B3: BBG_Ticker | C3: PX_LAST | D3: IVOL_RANK | E3: Spot | F3: IVR
A4: XLC | B4: XLC US Equity | C4: =C$3 -> PX_LAST | D4: =D$3 -> IVOL_RANK | E4: =IFERROR(bdp(B4,C4),0) -> 0 | F4: =IFERROR(bdp(B4,D4),0) -> 0
A6: PARAMETER OVERRIDES — blank Override = use Default
A7: Parameter | B7: Default | C7: Override | D7: Effective
A8: Width ($) | B8: 2 | D8: =IF(C8="",B8,C8) -> 2
A9: Front Expiration | B9: =Calendar!$B$11 -> 46220 | D9: =IF(C9="",B9,C9) -> 46220
A10: Back Expiration | B10: =Calendar!$B$12 -> 46255 | D10: =IF(C10="",B10,C10) -> 46255
A11: BP Short Strike ($) | B11: =IF($E$4=0,0,FLOOR($E$4*(1-0.05)/$D$8,1)*$D$8) -> 0 | D11: =IF(C11="",B11,C11) -> 0
A12: BC Short Strike ($) | B12: =IF($E$4=0,0,CEILING($E$4*(1+0.05)/$D$8,1)*$D$8) -> 0 | D12: =IF(C12="",B12,C12) -> 0
A14: BULL PUT ANALYSIS — short put + long lower put
A15: Strategy | B15: Leg | C15: Type | D15: Strike | E15: Expiration | F15: BBG_Ticker | G15: PX_LAST | H15: BID | I15: ASK | J15: VOL_MEAN | K15: DELTA_MID_RT | L15: Mid
A16: BullPut | B16: Front Short | C16: P | D16: =$D$11 -> 0 | E16: =$D$9 -> 46220 | F16: ="XLC"&" US "&TEXT(E16,"mm/dd/yy")&" "&"P"&IF(D16=INT(D16),INT(D16),D16)&" Equity" -> XLC US 07/17/26 P0 Equity | G16: =IFERROR(bdp($F16, G$15), 0) -> 0 | H16: =IFERROR(bdp($F16, H$15), 0) -> 0 | I16: =IFERROR(bdp($F16, I$15), 0) -> 0 | J16: =IFERROR(bdp($F16, J$15), 0) -> 0 | K16: =IFERROR(bdp($F16, K$15), 0) -> 0 | L16: =IFERROR((H16+I16)/2, 0) -> 0
A17: BullPut | B17: Front Long | C17: P | D17: =$D$11-$D$8 -> -2 | E17: =$D$9 -> 46220 | F17: ="XLC"&" US "&TEXT(E17,"mm/dd/yy")&" "&"P"&IF(D17=INT(D17),INT(D17),D17)&" Equity" -> XLC US 07/17/26 P-2 Equity | G17: =IFERROR(bdp($F17, G$15), 0) -> 0 | H17: =IFERROR(bdp($F17, H$15), 0) -> 0 | I17: =IFERROR(bdp($F17, I$15), 0) -> 0 | J17: =IFERROR(bdp($F17, J$15), 0) -> 0 | K17: =IFERROR(bdp($F17, K$15), 0) -> 0 | L17: =IFERROR((H17+I17)/2, 0) -> 0
A18: BullPut | B18: Back Short | C18: P | D18: =$D$11 -> 0 | E18: =$D$10 -> 46255 | F18: ="XLC"&" US "&TEXT(E18,"mm/dd/yy")&" "&"P"&IF(D18=INT(D18),INT(D18),D18)&" Equity" -> XLC US 08/21/26 P0 Equity | G18: =IFERROR(bdp($F18, G$15), 0) -> 0 | H18: =IFERROR(bdp($F18, H$15), 0) -> 0 | I18: =IFERROR(bdp($F18, I$15), 0) -> 0 | J18: =IFERROR(bdp($F18, J$15), 0) -> 0 | K18: =IFERROR(bdp($F18, K$15), 0) -> 0 | L18: =IFERROR((H18+I18)/2, 0) -> 0
A19: BullPut | B19: Back Long | C19: P | D19: =$D$11-$D$8 -> -2 | E19: =$D$10 -> 46255 | F19: ="XLC"&" US "&TEXT(E19,"mm/dd/yy")&" "&"P"&IF(D19=INT(D19),INT(D19),D19)&" Equity" -> XLC US 08/21/26 P-2 Equity | G19: =IFERROR(bdp($F19, G$15), 0) -> 0 | H19: =IFERROR(bdp($F19, H$15), 0) -> 0 | I19: =IFERROR(bdp($F19, I$15), 0) -> 0 | J19: =IFERROR(bdp($F19, J$15), 0) -> 0 | K19: =IFERROR(bdp($F19, K$15), 0) -> 0 | L19: =IFERROR((H19+I19)/2, 0) -> 0
A21: Strategy | B21: Exp_Label | C21: DTE | D21: Short_K | E21: Long_K | F21: Width | G21: Credit | H21: MaxLoss | I21: C/W | J21: BidAsk% | K21: Buffer% | L21: POP | M21: EV | N21: EV/Max | O21: Signal | P21: Score
A22: BullPut | B22: Front | C22: =$D$9-TODAY() -> 67 | D22: =$D$11 -> 0 | E22: =$D$11-$D$8 -> -2 | F22: =$D$8 -> 2 | G22: =IFERROR(L16-L17,0) -> 0 | H22: =IFERROR(F22-G22,0) -> 2 | I22: =IFERROR(G22/F22,0) -> 0 | J22: =IFERROR((I16-H16)/L16,1) -> 1 | K22: =IFERROR(($E$4-D22)/$E$4,0) -> 0 | L22: =IFERROR(1-ABS(K16),0) -> 1 | M22: =L22*G22-(1-L22)*H22 -> 0 | N22: =IFERROR(M22/H22,0) -> 0 | O22: =IF(NOT(AND(C22>=Settings!$B$14,C22<=Settings!$B$15)),"WAIT - DTE",IF(NOT(AND(ABS(K16)>=Settings!$B$12,ABS(K16)<=Settings!$B$13)),"WAIT - DELTA",IF(NOT($F$4>=Settings!$B$8),"WAIT - IVR",IF(NOT(G22>=Settings!$B$10),"WAIT - CREDIT",IF(NOT(I22>=Settings!$B$9),"WAIT - C/W",IF(NOT(AND(J22<=Settings!$B$11,H16>0,I16>0,H17>0,I17>0)),"WAIT - LIQ",IF(NOT(K22>=Settings!$B$19),"WAIT - BUFFER","GO"))))))) -> WAIT - DELTA | P22: =IF(O22="GO",N22,-1000000000) -> -1000000000
A23: BullPut | B23: Back | C23: =$D$10-TODAY() -> 102 | D23: =$D$11 -> 0 | E23: =$D$11-$D$8 -> -2 | F23: =$D$8 -> 2 | G23: =IFERROR(L18-L19,0) -> 0 | H23: =IFERROR(F23-G23,0) -> 2 | I23: =IFERROR(G23/F23,0) -> 0 | J23: =IFERROR((I18-H18)/L18,1) -> 1 | K23: =IFERROR(($E$4-D23)/$E$4,0) -> 0 | L23: =IFERROR(1-ABS(K18),0) -> 1 | M23: =L23*G23-(1-L23)*H23 -> 0 | N23: =IFERROR(M23/H23,0) -> 0 | O23: =IF(NOT(AND(C23>=Settings!$B$14,C23<=Settings!$B$15)),"WAIT - DTE",IF(NOT(AND(ABS(K18)>=Settings!$B$12,ABS(K18)<=Settings!$B$13)),"WAIT - DELTA",IF(NOT($F$4>=Settings!$B$8),"WAIT - IVR",IF(NOT(G23>=Settings!$B$10),"WAIT - CREDIT",IF(NOT(I23>=Settings!$B$9),"WAIT - C/W",IF(NOT(AND(J23<=Settings!$B$11,H18>0,I18>0,H19>0,I19>0)),"WAIT - LIQ",IF(NOT(K23>=Settings!$B$19),"WAIT - BUFFER","GO"))))))) -> WAIT - DELTA | P23: =IF(O23="GO",N23,-1000000000) -> -1000000000
A25: BEAR CALL ANALYSIS — short call + long higher call
A26: Strategy | B26: Leg | C26: Type | D26: Strike | E26: Expiration | F26: BBG_Ticker | G26: PX_LAST | H26: BID | I26: ASK | J26: VOL_MEAN | K26: DELTA_MID_RT | L26: Mid
A27: BearCall | B27: Front Short | C27: C | D27: =$D$12 -> 0 | E27: =$D$9 -> 46220 | F27: ="XLC"&" US "&TEXT(E27,"mm/dd/yy")&" "&"C"&IF(D27=INT(D27),INT(D27),D27)&" Equity" -> XLC US 07/17/26 C0 Equity | G27: =IFERROR(bdp($F27, G$26), 0) -> 0 | H27: =IFERROR(bdp($F27, H$26), 0) -> 0 | I27: =IFERROR(bdp($F27, I$26), 0) -> 0 | J27: =IFERROR(bdp($F27, J$26), 0) -> 0 | K27: =IFERROR(bdp($F27, K$26), 0) -> 0 | L27: =IFERROR((H27+I27)/2, 0) -> 0
A28: BearCall | B28: Front Long | C28: C | D28: =$D$12+$D$8 -> 2 | E28: =$D$9 -> 46220 | F28: ="XLC"&" US "&TEXT(E28,"mm/dd/yy")&" "&"C"&IF(D28=INT(D28),INT(D28),D28)&" Equity" -> XLC US 07/17/26 C2 Equity | G28: =IFERROR(bdp($F28, G$26), 0) -> 0 | H28: =IFERROR(bdp($F28, H$26), 0) -> 0 | I28: =IFERROR(bdp($F28, I$26), 0) -> 0 | J28: =IFERROR(bdp($F28, J$26), 0) -> 0 | K28: =IFERROR(bdp($F28, K$26), 0) -> 0 | L28: =IFERROR((H28+I28)/2, 0) -> 0
A29: BearCall | B29: Back Short | C29: C | D29: =$D$12 -> 0 | E29: =$D$10 -> 46255 | F29: ="XLC"&" US "&TEXT(E29,"mm/dd/yy")&" "&"C"&IF(D29=INT(D29),INT(D29),D29)&" Equity" -> XLC US 08/21/26 C0 Equity | G29: =IFERROR(bdp($F29, G$26), 0) -> 0 | H29: =IFERROR(bdp($F29, H$26), 0) -> 0 | I29: =IFERROR(bdp($F29, I$26), 0) -> 0 | J29: =IFERROR(bdp($F29, J$26), 0) -> 0 | K29: =IFERROR(bdp($F29, K$26), 0) -> 0 | L29: =IFERROR((H29+I29)/2, 0) -> 0
A30: BearCall | B30: Back Long | C30: C | D30: =$D$12+$D$8 -> 2 | E30: =$D$10 -> 46255 | F30: ="XLC"&" US "&TEXT(E30,"mm/dd/yy")&" "&"C"&IF(D30=INT(D30),INT(D30),D30)&" Equity" -> XLC US 08/21/26 C2 Equity | G30: =IFERROR(bdp($F30, G$26), 0) -> 0 | H30: =IFERROR(bdp($F30, H$26), 0) -> 0 | I30: =IFERROR(bdp($F30, I$26), 0) -> 0 | J30: =IFERROR(bdp($F30, J$26), 0) -> 0 | K30: =IFERROR(bdp($F30, K$26), 0) -> 0 | L30: =IFERROR((H30+I30)/2, 0) -> 0
A32: Strategy | B32: Exp_Label | C32: DTE | D32: Short_K | E32: Long_K | F32: Width | G32: Credit | H32: MaxLoss | I32: C/W | J32: BidAsk% | K32: Buffer% | L32: POP | M32: EV | N32: EV/Max | O32: Signal | P32: Score
A33: BearCall | B33: Front | C33: =$D$9-TODAY() -> 67 | D33: =$D$12 -> 0 | E33: =$D$12+$D$8 -> 2 | F33: =$D$8 -> 2 | G33: =IFERROR(L27-L28,0) -> 0 | H33: =IFERROR(F33-G33,0) -> 2 | I33: =IFERROR(G33/F33,0) -> 0 | J33: =IFERROR((I27-H27)/L27,1) -> 1 | K33: =IFERROR((D33-$E$4)/$E$4,0) -> 0 | L33: =IFERROR(1-ABS(K27),0) -> 1 | M33: =L33*G33-(1-L33)*H33 -> 0 | N33: =IFERROR(M33/H33,0) -> 0 | O33: =IF(NOT(AND(C33>=Settings!$B$14,C33<=Settings!$B$15)),"WAIT - DTE",IF(NOT(AND(ABS(K27)>=Settings!$B$12,ABS(K27)<=Settings!$B$13)),"WAIT - DELTA",IF(NOT($F$4>=Settings!$B$8),"WAIT - IVR",IF(NOT(G33>=Settings!$B$10),"WAIT - CREDIT",IF(NOT(I33>=Settings!$B$9),"WAIT - C/W",IF(NOT(AND(J33<=Settings!$B$11,H27>0,I27>0,H28>0,I28>0)),"WAIT - LIQ",IF(NOT(K33>=Settings!$B$19),"WAIT - BUFFER","GO"))))))) -> WAIT - DELTA | P33: =IF(O33="GO",N33,-1000000000) -> -1000000000
A34: BearCall | B34: Back | C34: =$D$10-TODAY() -> 102 | D34: =$D$12 -> 0 | E34: =$D$12+$D$8 -> 2 | F34: =$D$8 -> 2 | G34: =IFERROR(L29-L30,0) -> 0 | H34: =IFERROR(F34-G34,0) -> 2 | I34: =IFERROR(G34/F34,0) -> 0 | J34: =IFERROR((I29-H29)/L29,1) -> 1 | K34: =IFERROR((D34-$E$4)/$E$4,0) -> 0 | L34: =IFERROR(1-ABS(K29),0) -> 1 | M34: =L34*G34-(1-L34)*H34 -> 0 | N34: =IFERROR(M34/H34,0) -> 0 | O34: =IF(NOT(AND(C34>=Settings!$B$14,C34<=Settings!$B$15)),"WAIT - DTE",IF(NOT(AND(ABS(K29)>=Settings!$B$12,ABS(K29)<=Settings!$B$13)),"WAIT - DELTA",IF(NOT($F$4>=Settings!$B$8),"WAIT - IVR",IF(NOT(G34>=Settings!$B$10),"WAIT - CREDIT",IF(NOT(I34>=Settings!$B$9),"WAIT - C/W",IF(NOT(AND(J34<=Settings!$B$11,H29>0,I29>0,H30>0,I30>0)),"WAIT - LIQ",IF(NOT(K34>=Settings!$B$19),"WAIT - BUFFER","GO"))))))) -> WAIT - DELTA | P34: =IF(O34="GO",N34,-1000000000) -> -1000000000
A36: TICKER SUMMARY — best spread on this tab
A37: BestStrategy | B37: BestExpLabel | C37: BestExp | D37: DTE | E37: Short_K | F37: Long_K | G37: Credit | H37: MaxLoss | I37: POP | J37: EV/Max | K37: Signal | L37: Score
A38: =INDEX($A$22:$P$34, IF(P22=MAX(P22,P23,P33,P34),22,IF(P23=MAX(P22,P23,P33,P34),23,IF(P33=MAX(P22,P23,P33,P34),33,34)))-21, 1) -> BullPut | B38: =INDEX($A$22:$P$34, IF(P22=MAX(P22,P23,P33,P34),22,IF(P23=MAX(P22,P23,P33,P34),23,IF(P33=MAX(P22,P23,P33,P34),33,34)))-21, 2) -> Front | C38: =IF(INDEX($A$22:$P$34, IF(P22=MAX(P22,P23,P33,P34),22,IF(P23=MAX(P22,P23,P33,P34),23,IF(P33=MAX(P22,P23,P33,P34),33,34)))-21, 2)="Front",$D$9,$D$10) -> 46220 | D38: =INDEX($A$22:$P$34, IF(P22=MAX(P22,P23,P33,P34),22,IF(P23=MAX(P22,P23,P33,P34),23,IF(P33=MAX(P22,P23,P33,P34),33,34)))-21, 3) -> 67 | E38: =INDEX($A$22:$P$34, IF(P22=MAX(P22,P23,P33,P34),22,IF(P23=MAX(P22,P23,P33,P34),23,IF(P33=MAX(P22,P23,P33,P34),33,34)))-21, 4) -> 0 | F38: =INDEX($A$22:$P$34, IF(P22=MAX(P22,P23,P33,P34),22,IF(P23=MAX(P22,P23,P33,P34),23,IF(P33=MAX(P22,P23,P33,P34),33,34)))-21, 5) -> -2 | G38: =INDEX($A$22:$P$34, IF(P22=MAX(P22,P23,P33,P34),22,IF(P23=MAX(P22,P23,P33,P34),23,IF(P33=MAX(P22,P23,P33,P34),33,34)))-21, 7) -> 0 | H38: =INDEX($A$22:$P$34, IF(P22=MAX(P22,P23,P33,P34),22,IF(P23=MAX(P22,P23,P33,P34),23,IF(P33=MAX(P22,P23,P33,P34),33,34)))-21, 8) -> 2 | I38: =INDEX($A$22:$P$34, IF(P22=MAX(P22,P23,P33,P34),22,IF(P23=MAX(P22,P23,P33,P34),23,IF(P33=MAX(P22,P23,P33,P34),33,34)))-21, 12) -> 1 | J38: =INDEX($A$22:$P$34, IF(P22=MAX(P22,P23,P33,P34),22,IF(P23=MAX(P22,P23,P33,P34),23,IF(P33=MAX(P22,P23,P33,P34),33,34)))-21, 14) -> 0 | K38: =INDEX($A$22:$P$34, IF(P22=MAX(P22,P23,P33,P34),22,IF(P23=MAX(P22,P23,P33,P34),23,IF(P33=MAX(P22,P23,P33,P34),33,34)))-21, 15) -> WAIT - DELTA | L38: =MAX(P22,P23,P33,P34) -> -1000000000

Sheet XLE
A1: XLE — Energy (S&P Sector)
A3: Underlying | B3: BBG_Ticker | C3: PX_LAST | D3: IVOL_RANK | E3: Spot | F3: IVR
A4: XLE | B4: XLE US Equity | C4: =C$3 -> PX_LAST | D4: =D$3 -> IVOL_RANK | E4: =IFERROR(bdp(B4,C4),0) -> 0 | F4: =IFERROR(bdp(B4,D4),0) -> 0
A6: PARAMETER OVERRIDES — blank Override = use Default
A7: Parameter | B7: Default | C7: Override | D7: Effective
A8: Width ($) | B8: 2 | D8: =IF(C8="",B8,C8) -> 2
A9: Front Expiration | B9: =Calendar!$B$11 -> 46220 | D9: =IF(C9="",B9,C9) -> 46220
A10: Back Expiration | B10: =Calendar!$B$12 -> 46255 | D10: =IF(C10="",B10,C10) -> 46255
A11: BP Short Strike ($) | B11: =IF($E$4=0,0,FLOOR($E$4*(1-0.06)/$D$8,1)*$D$8) -> 0 | D11: =IF(C11="",B11,C11) -> 0
A12: BC Short Strike ($) | B12: =IF($E$4=0,0,CEILING($E$4*(1+0.06)/$D$8,1)*$D$8) -> 0 | D12: =IF(C12="",B12,C12) -> 0
A14: BULL PUT ANALYSIS — short put + long lower put
A15: Strategy | B15: Leg | C15: Type | D15: Strike | E15: Expiration | F15: BBG_Ticker | G15: PX_LAST | H15: BID | I15: ASK | J15: VOL_MEAN | K15: DELTA_MID_RT | L15: Mid
A16: BullPut | B16: Front Short | C16: P | D16: =$D$11 -> 0 | E16: =$D$9 -> 46220 | F16: ="XLE"&" US "&TEXT(E16,"mm/dd/yy")&" "&"P"&IF(D16=INT(D16),INT(D16),D16)&" Equity" -> XLE US 07/17/26 P0 Equity | G16: =IFERROR(bdp($F16, G$15), 0) -> 0 | H16: =IFERROR(bdp($F16, H$15), 0) -> 0 | I16: =IFERROR(bdp($F16, I$15), 0) -> 0 | J16: =IFERROR(bdp($F16, J$15), 0) -> 0 | K16: =IFERROR(bdp($F16, K$15), 0) -> 0 | L16: =IFERROR((H16+I16)/2, 0) -> 0
A17: BullPut | B17: Front Long | C17: P | D17: =$D$11-$D$8 -> -2 | E17: =$D$9 -> 46220 | F17: ="XLE"&" US "&TEXT(E17,"mm/dd/yy")&" "&"P"&IF(D17=INT(D17),INT(D17),D17)&" Equity" -> XLE US 07/17/26 P-2 Equity | G17: =IFERROR(bdp($F17, G$15), 0) -> 0 | H17: =IFERROR(bdp($F17, H$15), 0) -> 0 | I17: =IFERROR(bdp($F17, I$15), 0) -> 0 | J17: =IFERROR(bdp($F17, J$15), 0) -> 0 | K17: =IFERROR(bdp($F17, K$15), 0) -> 0 | L17: =IFERROR((H17+I17)/2, 0) -> 0
A18: BullPut | B18: Back Short | C18: P | D18: =$D$11 -> 0 | E18: =$D$10 -> 46255 | F18: ="XLE"&" US "&TEXT(E18,"mm/dd/yy")&" "&"P"&IF(D18=INT(D18),INT(D18),D18)&" Equity" -> XLE US 08/21/26 P0 Equity | G18: =IFERROR(bdp($F18, G$15), 0) -> 0 | H18: =IFERROR(bdp($F18, H$15), 0) -> 0 | I18: =IFERROR(bdp($F18, I$15), 0) -> 0 | J18: =IFERROR(bdp($F18, J$15), 0) -> 0 | K18: =IFERROR(bdp($F18, K$15), 0) -> 0 | L18: =IFERROR((H18+I18)/2, 0) -> 0
A19: BullPut | B19: Back Long | C19: P | D19: =$D$11-$D$8 -> -2 | E19: =$D$10 -> 46255 | F19: ="XLE"&" US "&TEXT(E19,"mm/dd/yy")&" "&"P"&IF(D19=INT(D19),INT(D19),D19)&" Equity" -> XLE US 08/21/26 P-2 Equity | G19: =IFERROR(bdp($F19, G$15), 0) -> 0 | H19: =IFERROR(bdp($F19, H$15), 0) -> 0 | I19: =IFERROR(bdp($F19, I$15), 0) -> 0 | J19: =IFERROR(bdp($F19, J$15), 0) -> 0 | K19: =IFERROR(bdp($F19, K$15), 0) -> 0 | L19: =IFERROR((H19+I19)/2, 0) -> 0
A21: Strategy | B21: Exp_Label | C21: DTE | D21: Short_K | E21: Long_K | F21: Width | G21: Credit | H21: MaxLoss | I21: C/W | J21: BidAsk% | K21: Buffer% | L21: POP | M21: EV | N21: EV/Max | O21: Signal | P21: Score
A22: BullPut | B22: Front | C22: =$D$9-TODAY() -> 67 | D22: =$D$11 -> 0 | E22: =$D$11-$D$8 -> -2 | F22: =$D$8 -> 2 | G22: =IFERROR(L16-L17,0) -> 0 | H22: =IFERROR(F22-G22,0) -> 2 | I22: =IFERROR(G22/F22,0) -> 0 | J22: =IFERROR((I16-H16)/L16,1) -> 1 | K22: =IFERROR(($E$4-D22)/$E$4,0) -> 0 | L22: =IFERROR(1-ABS(K16),0) -> 1 | M22: =L22*G22-(1-L22)*H22 -> 0 | N22: =IFERROR(M22/H22,0) -> 0 | O22: =IF(NOT(AND(C22>=Settings!$B$14,C22<=Settings!$B$15)),"WAIT - DTE",IF(NOT(AND(ABS(K16)>=Settings!$B$12,ABS(K16)<=Settings!$B$13)),"WAIT - DELTA",IF(NOT($F$4>=Settings!$B$8),"WAIT - IVR",IF(NOT(G22>=Settings!$B$10),"WAIT - CREDIT",IF(NOT(I22>=Settings!$B$9),"WAIT - C/W",IF(NOT(AND(J22<=Settings!$B$11,H16>0,I16>0,H17>0,I17>0)),"WAIT - LIQ",IF(NOT(K22>=Settings!$B$19),"WAIT - BUFFER","GO"))))))) -> WAIT - DELTA | P22: =IF(O22="GO",N22,-1000000000) -> -1000000000
