Workbook

Sheet Summary
A1: Book Summary — eight trades, one hedge, one risk budget
A2: Risk at stop is what you lose if every stop fills at once. Sizes live on each trade tab; the scale column tells you how much to cut if the budget is breached.
A4: The book
A5: Trade | B5: Structure | C5: Size | D5: Carry+roll / yr ($) | E5: Risk at stop ($) | F5: Carry / risk | G5: Scaled risk ($) | H5: Scale factor
A6: 1. FX COP-CLP | B6: Long COP / short CLP, 3m NDF | C6: ='FX COP-CLP'!B29 -> 10000000 | D6: ='FX COP-CLP'!B35 -> 743787.68 | E6: ='FX COP-CLP'!B33 -> 838669.19 | F6: =IF(E6=0,0,D6/E6) -> 0.88686658 | G6: =E6*B18 -> 716721.18 | H6: =B18 -> 0.85459344
A7: 2. FX BRL-MXN | B7: Long BRL / short MXN, 3m NDF | C7: ='FX BRL-MXN'!B29 -> 10000000 | D7: ='FX BRL-MXN'!B35 -> 414185.62 | E7: ='FX BRL-MXN'!B33 -> 786722 | F7: =IF(E7=0,0,D7/E7) -> 0.52647011 | G7: =E7*B18 -> 672327.46 | H7: =B18 -> 0.85459344
A8: 3. MX 1y1y | B8: Receive MXN 1y1y TIIE | C8: ='MX 1y1y'!B25 -> 15000 | D8: ='MX 1y1y'!B29 -> 1344111.9 | E8: ='MX 1y1y'!B28 -> 375000 | F8: =IF(E8=0,0,D8/E8) -> 3.5842985 | G8: =E8*B18 -> 320472.54 | H8: =B18 -> 0.85459344
A9: 4. MX-US 2y2y | B9: Receive MX 2y2y / pay US 2y2y, DV01-matched | C9: ='MX-US 2y2y'!B33 -> 10000 | D9: ='MX-US 2y2y'!B37 -> 228440.01 | E9: ='MX-US 2y2y'!B36 -> 250000 | F9: =IF(E9=0,0,D9/E9) -> 0.91376003 | G9: =E9*B18 -> 213648.36 | H9: =B18 -> 0.85459344
A10: 5. BR DI | B10: Receive DI belly + long end (A) or Jan-33/Jan-28 flattener (B) | C10: ='BR DI'!B48 -> 10000 | D10: ='BR DI'!B45 -> -1317571.7 | E10: ='BR DI'!B44 -> 400000 | F10: =IF(E10=0,0,D10/E10) -> -3.2939293 | G10: =E10*B18 -> 341837.37 | H10: =B18 -> 0.85459344
A11: 6. US Rates | B11: Receive 10y SOFR, part-funded paying 2y | C11: ='US Rates'!B29 -> 10000 | D11: ='US Rates'!B28 -> 1253000 | E11: ='US Rates'!B32 -> 250000 | F11: =IF(E11=0,0,D11/E11) -> 5.012 | G11: =E11*B18 -> 213648.36 | H11: =B18 -> 0.85459344
A12: 7. Credit CL-CO | B12: Sell Chile 5y CDS / buy Colombia 5y CDS | C12: ='Credit CL-CO'!B23 -> 10000 | D12: ='Credit CL-CO'!B30 -> -353219.71 | E12: ='Credit CL-CO'!B36 -> 250000 | F12: =IF(E12=0,0,D12/E12) -> -1.4128789 | G12: =E12*B18 -> 213648.36 | H12: =B18 -> 0.85459344
A13: 8. Credit PE-MX | B13: Sell Peru 5y CDS / buy Mexico 5y CDS | C13: ='Credit PE-MX'!B23 -> 10000 | D13: ='Credit PE-MX'!B30 -> -71840.075 | E13: ='Credit PE-MX'!B36 -> 250000 | F13: =IF(E13=0,0,D13/E13) -> -0.2873603 | G13: =E13*B18 -> 213648.36 | H13: =B18 -> 0.85459344
A14: 9. Oil Hedge | B14: Brent 3m put spread, 90/75, rolled with the NDFs | C14: ='Oil Hedge'!B33 -> 71 | D14: =-'Oil Hedge'!B35 -> -440200 | E14: ='Oil Hedge'!B34 -> 110050 | F14: =IF(E14=0,0,D14/E14) -> -4 | G14: =E14*B18 -> 94048.008 | H14: =B18 -> 0.85459344
A15: TOTAL | D15: =SUM(D6:D14) -> 1800693.7 | E15: =SUM(E6:E14) -> 3510441.2 | G15: =SUM(G6:G14) -> 3000000
A16: Risk budget ($) | B16: =Inputs!$F$93 -> 3000000
A17: Over / (under) budget ($) | B17: =E15-B16 -> 510441.19
A18: Scale factor to fit budget | B18: =IF(E15=0,1,MIN(1,B16/E15)) -> 0.85459344 | C18: Multiply every size by this and the book fits. Or trim the weakest carry/risk line first — BRL/MXN.
A20: Size column: FX = notional per leg; rates = DV01 ($/bp); credit = spread DV01 ($/bp); oil = contracts. Hedge carry = premium paid per year.
A22: Where the book is concentrated — say these before they find them
A23: Theme | B23: Positions that share it
A24: Mexico slows / Banxico stays lower than priced | B24: Short MXN (2) · Receive 1y1y (3) · Receive 2y2y vs US (4) · Short Mexico CDS (8). Four legs, one view. Deliberate, and each is small.
A25: Brazil fiscal improvement — runoff 25 Oct | B25: Long BRL (2) · Receive DI (5). One dated catalyst for two positions; size is cut through the event.
A26: Oil | B26: Long COP (1) and long BRL (2) are long oil. Short Colombia CDS (7) is short oil. Net long — hedged by the Brent put spread (9), sized to the 20% crash on the Oil Hedge tab.
A27: US duration | B27: Receive 10y (6) is long. Pay US 2y2y (4) and pay 2y (6, hedge leg) are short the front end. Net: long the long end, short the front — a flattening bias.
A28: Colombia | B28: Long COP (1) vs short Colombia CDS (7). Opposing on purpose: the credit short is the tail hedge for the FX carry.
A29: Copper / Andean growth | B29: COP-CLP nets most of it. Long Peru CDS (8) adds copper beta. In a demand shock Peru widens.
A31: Out of the book, and why
A32: • Argentina — no edge over the technicals; revisit nearer the elections.
A33: • Chile/Peru IG as an oil hedge — only works in a supply-driven crash; they are now in the book as credit pairs, not as hedges. The oil hedge is the Brent put spread.
A34: • Venezuela — present as evidence of edge, not as a fund position.
A35: • Brazil equities — doubled the oil tilt via the Petrobras weight.
A36: • Panama — favourite credit, but with Chile and Peru as the longs the book already has two IG-quality long legs; keep Panama as the answer to 'what would you add'.

Sheet Monitor
A1: Trade Monitor — one row per trade, everything you need to say out loud
A2: Live level comes from the trade tabs. Entry level is yellow: type your actual entry when you put the trade on (it defaults to the 13-Oct snapshot). P&L and room-to-stop update from there. The last three columns are the words.
A4: Trade | B4: Position | C4: Live level | D4: Entry level | E4: Move | F4: P&L ($) | G4: Carry+roll / yr ($) | H4: Stop level | I4: Room to stop | J4: Catalyst / date | K4: Thesis in one sentence | L4: What kills it | M4: If they ask 'why not…'
A5: 1. FX COP-CLP | B5: Long COP / short CLP, $10mm per leg, 3m NDF | C5: ='FX COP-CLP'!B13 -> 0.30852731 | D5: 0.3085 | E5: =C5/D5-1 -> 8.8515523e-05 | F5: ='FX COP-CLP'!B29*(C5/D5-1) -> 885.15523 | G5: ='FX COP-CLP'!B35 -> 743787.68 | H5: ='FX COP-CLP'!B32 -> 0.28265207 | I5: =C5/H5-1 -> 0.091544472 | J5: Quarterly roll 19-Jan. BanRep meetings. Oil. | K5: Colombia pays me 7% to own its currency, Chile charges nothing to short its, and the two move together against the dollar — I keep the carry, lose most of the beta. | L5: A Colombia-specific shock or an oil collapse. The Colombia CDS short is the tail hedge. | M5: …BRL/MXN as the core? Same idea, about half the carry per unit of vol.
A6: 2. FX BRL-MXN | B6: Long BRL / short MXN, $10mm per leg, 3m NDF | C6: ='FX BRL-MXN'!B13 -> 3.6547677 | D6: 3.6548 | E6: =C6/D6-1 -> -8.8358579e-06 | F6: ='FX BRL-MXN'!B29*(C6/D6-1) -> -88.358579 | G6: ='FX BRL-MXN'!B35 -> 414185.62 | H6: ='FX BRL-MXN'!B32 -> 3.3672391 | I6: =C6/H6-1 -> 0.085390021 | J6: Brazil runoff 25-Oct. Size cut through it. | K6: Paid 4% to be long the country whose fiscal story is improving and short the one whose growth is stalling. | L6: Runoff surprise; a USMCA relief rally in MXN. The BRL risk reversal says the market already fears BRL downside. | M6: …7-8% carry? No — the BRL NDF prices off the cupom cambial. It's 4.1%. First trade to trim if the budget is over.
A7: 3. MX 1y1y | B7: Receive MXN 1y1y TIIE, 15k DV01 | C7: ='MX 1y1y'!B9 -> 7.5295746 | D7: 7.53 | E7: =C7-D7 -> -0.00042536951 | F7: =(D7-C7)*100*'MX 1y1y'!B25 -> 638.05427 | G7: ='MX 1y1y'!B29 -> 1344111.9 | H7: ='MX 1y1y'!B27 -> 7.7795746 | I7: =H7-C7 -> 0.25 | J7: Banxico decisions; CPI prints; USD/MXN. | K7: The market prices ~100bp of Banxico hikes over the next year; I think they deliver none, and the curve pays me ~90bp a year to wait. | L7: Inflation re-accelerating, or a peso sell-off Banxico defends with rates. | M7: …the 6m? Sits below policy — nothing to receive. …the Fed? Pay the US 1y1y against it; net roll is on the tab.
A8: 4. MX-US 2y2y | B8: Receive MX 2y2y / pay US 2y2y, 10k DV01 each | C8: ='MX-US 2y2y'!B23 -> 320.49018 | D8: 320.49 | E8: =C8-D8 -> 0.00017534275 | F8: =(D8-C8)*'MX-US 2y2y'!B33 -> -1.7534275 | G8: ='MX-US 2y2y'!B37 -> 228440.01 | H8: ='MX-US 2y2y'!B35 -> 345.49018 | I8: =H8-C8 -> 25 | J8: Banxico vs Fed path; USMCA review. | K8: Mexico's rate premium over the US compresses as its growth gap widens — receive Mexico, pay the US, two years out, DV01 for DV01. | L8: The Fed cutting into a US slowdown while Banxico is stuck with sticky inflation. | M8: …the spot 2y? Already inside the policy differential — partly priced. The forward sector isn't.
A9: 5. BR DI | B9: Receive DI Jan-29 + Jan-33 (A), 10k DV01 total — or Jan-33/Jan-28 flattener (B) | C9: ='BR DI'!B46 -> 12.44625 | D9: 12.4463 | E9: =C9-D9 -> -5e-05 | F9: =(D9-C9)*IF('BR DI'!B43="A",100,1)*'BR DI'!B48 -> 50 | G9: ='BR DI'!B45 -> -1317571.7 | H9: ='BR DI'!B47 -> 12.84625 | I9: =H9-C9 -> 0.4 | J9: Runoff 25-Oct. Fiscal plan. Copom. | K9: Brazil's long end carries a fiscal risk premium a credible plan can remove — I want to own the belly and long end for that. The curve is inverted, so I pay to hold it: quote the break-even. | L9: Runoff surprise; Copom turning hawkish on a weaker BRL. Two Brazil positions, one catalyst. | M9: …the negative carry? Option B pays the front against it and turns the inversion into income. Level shown is blended rate (A) or spread in bp (B).
A10: 6. US Rates | B10: Receive 10y SOFR 20k DV01, pay 2y at the hedge ratio | C10: ='US Rates'!B11 -> 5 | D10: 5 | E10: =C10-D10 -> 0 | F10: =(D10-C10)*100*'US Rates'!B16+('US Rates'!B8-4.6635)*100*'US Rates'!B22 -> 0 | G10: ='US Rates'!B28 -> 1253000 | H10: ='US Rates'!B31 -> 5.25 | I10: =H10-C10 -> 0.25 | J10: FOMC; CPI; Treasury refunding. | K10: Most of the US sell-off is behind us; I want to be long from the 10y out, and because the curve slopes up I'm paid to be. | L10: A bear-steepening on fiscal or term-premium news — the 2y hedge does nothing for that. | M10: …a butterfly? Curvature trade, no duration — wrong tool for a level view. …zero cost? A receiver/payer collar; cells on the tab.
A11: 7. Credit CL-CO | B11: Sell Chile 5y CDS / buy Colombia 5y CDS, 10k CS01 each | C11: ='Credit CL-CO'!B10 -> 145 | D11: 145 | E11: =C11-D11 -> 0 | F11: =(C11-D11)*'Credit CL-CO'!B23 -> 0 | G11: ='Credit CL-CO'!B30 -> -353219.71 | H11: ='Credit CL-CO'!B35 -> 120 | I11: =C11-H11 -> 25 | J11: Colombia fiscal rule / budget; oil. | K11: The market prices Colombia as a credit fixing itself; I think it's being graded on a curve. Chile is what a fixed balance sheet looks like. | L11: Genuine consolidation in Colombia, or a global spread rally that compresses the wide credit hardest. | M11: …the negative carry? It hedges the COP carry trade — if Colombia blows up, FX loses and this pays. Quote the break-even in bp/yr.
A12: 8. Credit PE-MX | B12: Sell Peru 5y CDS / buy Mexico 5y CDS, 10k CS01 each | C12: ='Credit PE-MX'!B10 -> 30 | D12: 30 | E12: =C12-D12 -> 0 | F12: =(C12-D12)*'Credit PE-MX'!B23 -> 0 | G12: ='Credit PE-MX'!B30 -> -71840.075 | H12: ='Credit PE-MX'!B35 -> 5 | I12: =C12-H12 -> 25 | J12: USMCA review; Pemex; Peru politics. | K12: Mexico's spread doesn't reflect Pemex, a growth stall and a trade overhang; Peru's doesn't reflect how clean its balance sheet is. Nearly flat carry — the cheapest view in the book. | L12: Peru political noise; a USMCA outcome that re-rates Mexico. | M12: …four Mexico legs? Yes — deliberate concentration, each sized small. Say it before they do.
A13: 9. Oil Hedge | B13: Brent 3m 90/75 put spread, contracts on the tab | C13: ='Oil Hedge'!B17 -> 70 | D13: 70 | E13: =C13-D13 -> 0 | F13: =-'Oil Hedge'!B34 -> -110050 | G13: =-'Oil Hedge'!B35 -> -440200 | H13: ='Oil Hedge'!B21 -> 63 | I13: =C13-H13 -> 7 | J13: Rolls with the NDFs, 19-Jan. OPEC+. | K13: Two carry trades are long oil by construction; I cap the tail with a put spread and spend a slice of the carry to do it. 'Stop level' here = the long strike, where protection starts. | L13: A slow grind lower that never reaches the strike — premium gone, FX bleeds anyway. | M13: …just cut the COP? The carry is the point. The hedge lets me keep the 7%. P&L shows premium at risk until you mark it.
A15: Book totals
A16: Total P&L ($) | B16: =SUM(F4:F12) -> 1483.0975
A17: Total carry + roll per year ($) | B17: =Summary!D15 -> 1800693.7
A18: Total risk at stop ($) | B18: =Summary!E15 -> 3510441.2
A19: Over / (under) budget ($) | B19: =Summary!B17 -> 510441.19
A21: Opening line if asked for the book in thirty seconds
A22: Eight trades plus an oil hedge, every one a pair with a natural hedge, three themes: Andean carry with the beta stripped out, a Mexico slowdown expressed in FX, rates and credit, and a long-end duration view in Brazil on fiscal and in the US on the sell-off being mostly done. Total risk if every stop fills is on the Summary tab against a $3mm budget. The two things I'd say before you ask: the Mexico concentration is deliberate, and the Brazil DI receiver pays carry to hold — I quote the break-even.

Sheet Track Record
A1: Track Record — the trades to talk about, with the codes to prove them
A2: Yellow = dates and remembered levels you fix. Blue = tickers (edit if one fails). BDH pulls the level on each date once Bloomberg is open; until then the row uses the remembered level. 'Want' = +1 if the call needed the level to RISE, −1 if to FALL. Outcome is computed from the move, not typed.
A4: # | B4: Trade | C4: Years | D4: Ticker A | E4: Ticker B (subtract, optional) | F4: Field | G4: Entry date | H4: Exit date | I4: Entry (BDH) | J4: Exit (BDH) | K4: Entry (remembered) | L4: Exit (remembered) | M4: Entry USED | N4: Exit USED | O4: Want | P4: Outcome | Q4: One line
A5: 1 | B5: Colombia 5s10s IBR steepener (receive 5y / pay 10y, $5k DV01 per leg) | C5: 2016 | D5: CLSWIB10 Curncy | E5: CLSWIB5 Curncy | F5: PX_LAST | G5: 42598 | H5: 42717 | I5: =IFERROR(bdh($D5,$F5,TEXT($G5,"yyyymmdd"),TEXT($G5,"yyyymmdd"),"Dates=H")-IF($E5="",0,bdh($E5,$F5,TEXT($G5,"yyyymmdd"),TEXT($G5,"yyyymmdd"),"Dates=H")),"") | J5: =IFERROR(bdh($D5,$F5,TEXT($H5,"yyyymmdd"),TEXT($H5,"yyyymmdd"),"Dates=H")-IF($E5="",0,bdh($E5,$F5,TEXT($H5,"yyyymmdd"),TEXT($H5,"yyyymmdd"),"Dates=H")),"") | K5: 0.23 | L5: 0.65 | M5: =IF(AND(Inputs!$B$3=1,ISNUMBER(I5)),I5,K5) -> 0.23 | N5: =IF(AND(Inputs!$B$3=1,ISNUMBER(J5)),J5,L5) -> 0.65 | O5: 1 | P5: =IF((N5-M5)*O5>0,"WIN",IF((N5-M5)*O5<0,"LOSS","FLAT")) -> WIN | Q5: Entered at 23bp, target 60bp, stop at flat. Closed at 65bp, printed +$139k. Level = 10y − 5y in %.
A6: 2 | B6: Long Colombia USD sovereign credit — the Petro years | C6: 2022-24 | D6: COLOM CDS USD SR 5Y D14 Corp | F6: PX_LAST | G6: 44941 | H6: 45473 | I6: =IFERROR(bdh($D6,$F6,TEXT($G6,"yyyymmdd"),TEXT($G6,"yyyymmdd"),"Dates=H")-IF($E6="",0,bdh($E6,$F6,TEXT($G6,"yyyymmdd"),TEXT($G6,"yyyymmdd"),"Dates=H")),"") | J6: =IFERROR(bdh($D6,$F6,TEXT($H6,"yyyymmdd"),TEXT($H6,"yyyymmdd"),"Dates=H")-IF($E6="",0,bdh($E6,$F6,TEXT($H6,"yyyymmdd"),TEXT($H6,"yyyymmdd"),"Dates=H")),"") | K6: 250 | L6: 290 | M6: =IF(AND(Inputs!$B$3=1,ISNUMBER(I6)),I6,K6) -> 250 | N6: =IF(AND(Inputs!$B$3=1,ISNUMBER(J6)),J6,L6) -> 290 | O6: -1 | P6: =IF((N6-M6)*O6>0,"WIN",IF((N6-M6)*O6<0,"LOSS","FLAT")) -> LOSS | Q6: FIX DATES AND LEVELS. Spread never tightened the way the fundamentals said it should. The loss.
A7: 3 | B7: Short MXN vs USD into the Texcoco airport cancellation | C7: 2018 | D7: USDMXN Curncy | F7: PX_LAST | G7: 43399 | H7: 43434 | I7: =IFERROR(bdh($D7,$F7,TEXT($G7,"yyyymmdd"),TEXT($G7,"yyyymmdd"),"Dates=H")-IF($E7="",0,bdh($E7,$F7,TEXT($G7,"yyyymmdd"),TEXT($G7,"yyyymmdd"),"Dates=H")),"") | J7: =IFERROR(bdh($D7,$F7,TEXT($H7,"yyyymmdd"),TEXT($H7,"yyyymmdd"),"Dates=H")-IF($E7="",0,bdh($E7,$F7,TEXT($H7,"yyyymmdd"),TEXT($H7,"yyyymmdd"),"Dates=H")),"") | K7: 19.3 | L7: 20.4 | M7: =IF(AND(Inputs!$B$3=1,ISNUMBER(I7)),I7,K7) -> 19.3 | N7: =IF(AND(Inputs!$B$3=1,ISNUMBER(J7)),J7,L7) -> 20.4 | O7: 1 | P7: =IF((N7-M7)*O7>0,"WIN",IF((N7-M7)*O7<0,"LOSS","FLAT")) -> WIN | Q7: Referendum result 28-Oct-2018, AMLO confirmed the cancellation 29-Oct. FIX entry/exit dates to the desk call.
A8: 4 | B8: Venezuela to market weight after the Maduro removal (DCF of recovery value) | C8: 2026 | D8: VENZ 9 1/4 09/15/27 Corp | F8: PX_LAST | G8: 46037 | H8: 46309 | I8: =IFERROR(bdh($D8,$F8,TEXT($G8,"yyyymmdd"),TEXT($G8,"yyyymmdd"),"Dates=H")-IF($E8="",0,bdh($E8,$F8,TEXT($G8,"yyyymmdd"),TEXT($G8,"yyyymmdd"),"Dates=H")),"") | J8: =IFERROR(bdh($D8,$F8,TEXT($H8,"yyyymmdd"),TEXT($H8,"yyyymmdd"),"Dates=H")-IF($E8="",0,bdh($E8,$F8,TEXT($H8,"yyyymmdd"),TEXT($H8,"yyyymmdd"),"Dates=H")),"") | K8: 20 | L8: 40 | M8: =IF(AND(Inputs!$B$3=1,ISNUMBER(I8)),I8,K8) -> 20 | N8: =IF(AND(Inputs!$B$3=1,ISNUMBER(J8)),J8,L8) -> 40 | O8: 1 | P8: =IF((N8-M8)*O8>0,"WIN",IF((N8-M8)*O8<0,"LOSS","FLAT")) -> WIN | Q8: FIX DATE AND BOND. Price in cents. Moved to market weight before it got expensive; DCF said present value of claims was above price.
A9: 5 | B9: Long Panama USD credit — two notches below its rating | C9: 2024-25 | D9: PANAMA CDS USD SR 5Y D14 Corp | F9: PX_LAST | G9: 45611 | H9: 46022 | I9: =IFERROR(bdh($D9,$F9,TEXT($G9,"yyyymmdd"),TEXT($G9,"yyyymmdd"),"Dates=H")-IF($E9="",0,bdh($E9,$F9,TEXT($G9,"yyyymmdd"),TEXT($G9,"yyyymmdd"),"Dates=H")),"") | J9: =IFERROR(bdh($D9,$F9,TEXT($H9,"yyyymmdd"),TEXT($H9,"yyyymmdd"),"Dates=H")-IF($E9="",0,bdh($E9,$F9,TEXT($H9,"yyyymmdd"),TEXT($H9,"yyyymmdd"),"Dates=H")),"") | K9: 140 | L9: 90 | M9: =IF(AND(Inputs!$B$3=1,ISNUMBER(I9)),I9,K9) -> 140 | N9: =IF(AND(Inputs!$B$3=1,ISNUMBER(J9)),J9,L9) -> 90 | O9: -1 | P9: =IF((N9-M9)*O9>0,"WIN",IF((N9-M9)*O9<0,"LOSS","FLAT")) -> WIN | Q9: FIX DATES AND LEVELS. Evidence things improve; if not, it was in the price. Best performer in 2025.
A10: 6 | B10: Short ARS via NDF through the Fernández administration (calling for faster depreciation) | C10: 2020-23 | D10: USDARS Curncy | F10: PX_LAST | G10: 44377 | H10: 44561 | I10: =IFERROR(bdh($D10,$F10,TEXT($G10,"yyyymmdd"),TEXT($G10,"yyyymmdd"),"Dates=H")-IF($E10="",0,bdh($E10,$F10,TEXT($G10,"yyyymmdd"),TEXT($G10,"yyyymmdd"),"Dates=H")),"") | J10: =IFERROR(bdh($D10,$F10,TEXT($H10,"yyyymmdd"),TEXT($H10,"yyyymmdd"),"Dates=H")-IF($E10="",0,bdh($E10,$F10,TEXT($H10,"yyyymmdd"),TEXT($H10,"yyyymmdd"),"Dates=H")),"") | K10: 110 | L10: 102.5 | M10: =IF(AND(Inputs!$B$3=1,ISNUMBER(I10)),I10,K10) -> 110 | N10: =IF(AND(Inputs!$B$3=1,ISNUMBER(J10)),J10,L10) -> 102.5 | O10: 1 | P10: =IF((N10-M10)*O10>0,"WIN",IF((N10-M10)*O10<0,"LOSS","FLAT")) -> LOSS | Q10: FIX DATES. Entry = the NDF outright you traded (type it in 'remembered' and set Use live = 0 for entry). Exit = spot at expiry. Spot never caught the NDF: the carry ate the view.
A12: Reading the row
A13: Move = Exit USED − Entry USED. Want +1 means the call needed the number to rise (a steepener, short MXN = USDMXN up, a bond price). Want −1 means it needed to fall (a CDS spread for a long-credit call). BDH on the IBR row subtracts Ticker B from Ticker A, so the level is the 5s10s spread. If a BDH cell stays blank with Bloomberg open, the ticker is wrong: fix it in the blue cell. The Argentina row is the one where live data misleads: the entry you want is the NDF outright, not spot, so leave that cell on the remembered value.

Sheet Track Record Notes
A1: Track Record — what to say about each one
A2: Setup, the call, what happened, the lesson, and the line to say first. In your words where you gave them; fix anything that isn't how you'd say it.
A4: BEST — 5. Panama USD credit, late 2024 (your favourite)
A5: Setup | B5: Late 2024 Panama was trading roughly two notches below its rating — the market priced a downgrade to high yield that had not happened, on the back of the copper-mine closure, the pension-fund hole and the fiscal numbers.
A6: The call | B6: Long Panama credit. We had evidence things were going to get better — the fiscal adjustment and the mine negotiation were moving. And if they did not get better, the downgrade was already in the price. Limited downside, open upside.
A7: What happened | B7: Best-performing credit in the index in 2025.
A8: Why it's the best | B8: It is the cleanest example of the thing I look for: a defined asymmetry. Two outcomes, one priced, one not. I did not need to be right about Panama — I needed the market to have priced the bad case, and it had.
A9: The line | B9: 'I didn't need to be right. I needed the bad case to be in the price, and it was.'
A10: If they push | B10: On sizing: it was an overweight, not a bet-the-book. On the risk: a second downgrade would have taken it to HY and forced selling by IG-only holders — that was the stop condition, and we watched the rating agencies' review dates for it.
A12: BEST — 4. Venezuela to market weight after the Maduro removal
A13: Setup | B13: After the removal the bonds were still at distressed prices. The question was not whether there would be a restructuring but what the claims were worth when it came. FIX THE DATE on the Track Record tab.
A14: The call | B14: A DCF on the present value of the debt — claims, past-due interest, recovery timeline — said the price was below any reasonable restructuring value. Moved Venezuela from underweight to market weight before it got expensive.
A15: What happened | B15: It did exactly what the DCF said. The move to market weight was early, and that is the point.
A16: The edge | B16: Years of covering the credit. Knowing which bonds carried past-due interest, how the claims rank, what PDVSA paper was worth relative to the Republic. A generalist could not have sized the recovery value with confidence; I could.
A17: The line | B17: 'This was a valuation call, not a political call. The politics gave me the catalyst; the DCF gave me the number.'
A18: Caution | B18: Present it as evidence of edge, not as a current fund position — a macro fund will not hold single-name Venezuela. If asked, PDVSA paper is better value than the Republic's on claim-per-dollar; the earlier study notes have the arithmetic.
A20: GOOD — 3. Short MXN into the Texcoco airport cancellation, October 2018
A21: Setup | B21: AMLO ran a 'public consultation' on the half-built Mexico City airport in late October 2018. We were sitting on the desk and it was obvious: the consultation was theatre and the cancellation was coming. The market still gave him the benefit of the doubt.
A22: The call | B22: Short the peso outright against the dollar. Not a pair, not a hedge — a directional call on a dated event.
A23: What happened | B23: He confirmed the cancellation on 29 October; USD/MXN gapped higher and kept going through November. The call was right on the event and right on the market's reaction to it.
A24: The lesson | B24: Some trades do not come from a model. This one came from reading the man and the sequence of events. That is a real source of edge in EM — but it is not repeatable on demand, so I size it as an event trade, not a core position.
A25: The line | B25: 'We knew before the market did because we were watching the politics, not the price.'
A26: If they push | B26: Why outright rather than a pair? Because the shock was Mexico-specific and the dollar was not the driver. Against the dollar was the cleanest expression; a BRL leg would only have added noise.
A28: GOOD — 1. Colombia 5s10s IBR steepener, August 2016 (the analyst-era trade)
A29: Setup | B29: Credit Suisse note, 16 August 2016, Chodos / Maldonado / Rojas. BanRep was at the end of its hiking cycle and the curve was flat: 5s10s IBR at 23bp. The front end would rally once cuts came into view; the long end would not follow all the way.
A30: The call | B30: Receive 5y IBR, pay 10y IBR, DV01-neutral, $5k per leg. Entry 23bp, target 60bp, stop at flat. Chosen over 2s10s because the 5s10s carry bleed was a fraction of the 2s10s bleed for a similar move.
A31: What happened | B31: Ran through the target to 65bp. Closed 13 December 2016. Printed P&L +$139k on $210k of gross spread P&L — the gap was carry, roll and bid-ask, which is the honest number to quote.
A32: Detail worth owning | B32: Mid-trade we switched to 'net received' on 8 September — added outright duration on top of the curve view — and back to DV01-neutral on 16 November. That was a second bet layered on the first. It worked, but it is the kind of thing a risk manager asks about.
A33: The line | B33: 'The trade was picking the steepener with the least bleed for the same view, and then not falling in love with it: we took it off five bp through target.'
A34: If they push | B34: It is ten years old and I was the third name on it. I bring it up because it is the one with the full ticket — entry, target, stop, carry grid, printed P&L — not because it is my best. The best are Panama and Venezuela.
A36: WORST — 6. Short ARS via NDF through the Fernández administration
A37: Setup | B37: 2020 to 2023. The peso was obviously overvalued at the official rate, the gap to the parallel rate was enormous, reserves were falling. Every model said depreciation.
A38: The call | B38: Buy USD/ARS NDFs — position for the official rate to depreciate faster than the forward implied. Repeated across the period.
A39: What happened | B39: Spot never caught up with the NDF. The government kept the crawl slower than the forward, and the NDF already priced a lot of depreciation. The carry — the implied depreciation we paid to be short — ate the view. We lost.
A40: What I got wrong | B40: We underestimated their willingness to live with the distortion. We modelled the economics correctly and modelled the policymaker wrong: they did not care about the imbalance, so the imbalance did not have to resolve on our horizon. And the forward already embedded most of what we believed — being right on direction paid nothing.
A41: The lesson | B41: Two lessons I apply to everything in the current book. One: a view the forward already prices has no edge — that is why every trade on the Monitor shows what is priced first. Two: when a government controls the price, your horizon is their horizon, not yours. Argentina sits on the sidelines now for exactly that reason.
A42: The line | B42: 'We were right about the economy and wrong about the people running it. The forward made us pay for the privilege.'
A43: Contrast if useful | B43: The same instrument worked in 2017 under Macri — a two-month USDARS NDF that printed +$117k. Same direction, opposite result. The difference was who controlled the crawl and whether the forward already priced it.
A45: WORST — 2. Long Colombia USD sovereign credit in the Petro years
A46: Setup | B46: Colombia widened hard on Petro's election. The fundamentals — reserves, the fiscal rule, the central bank's independence — looked better than the spread implied. FIX THE DATES on the Track Record tab.
...

Sheet Inputs
A1: Inputs — every number in the book comes from this tab
A2: Column D pulls Bloomberg via BDP(). Column E is the 13-Oct-2026 BGN snapshot. Column F is what the book uses: live when Bloomberg returns a number and the switch in B3 is 1, otherwise the snapshot. Orange cells are PLACEHOLDERS that never came off a screen — overwrite them before you quote anything.
A3: Data mode: 1 = use Bloomberg where it returns a number, 0 = force snapshot | B3: 1
A5: Field | B5: Ticker (edit here if a ticker is wrong) | C5: BDP field | D5: Live (Bloomberg) | E5: Snapshot 13-Oct | F5: ACTIVE (used) | G5: Status | H5: Note
A6: Dates
A7: Valuation date | E7: 46309 | F7: =E7 -> 46309 | G7: Input | H7: Change to today when you open it at work.
A8: FX spot date (T+2) | E8: 46311 | F8: =E8 -> 46311 | G8: Input
A9: 3m forward settlement date | E9: 46406 | F9: =E9 -> 46406 | G9: Input | H9: Matches the fund's quarterly IMM roll. Carry annualises x365/days, not x4.
A10: Days in the 3m window | F10: =$F$9-$F$8 -> 95 | G10: Calculated | H10: 95 days in the 13-Oct snapshot.
A11: FX — spots, forward points, vols (FRD <GO> for points, OVDV <GO> for vols)
A12: USDCOP spot | B12: USDCOP Curncy | C12: PX_LAST | D12: =IFERROR(bdp($B12,$C12),"") | E12: 3184.71 | F12: =IF(AND(Inputs!$B$3=1,ISNUMBER(D12)),D12,E12) -> 3184.71 | G12: Screen 13-Oct
A13: USDCOP 3m forward points | B13: COP3M Curncy | C13: PX_LAST | D13: =IFERROR(bdp($B13,$C13),"") | E13: 58.83 | F13: =IF(AND(Inputs!$B$3=1,ISNUMBER(D13)),D13,E13) -> 58.83 | G13: Screen (derived) | H13: Snapshot = outright 3243.54 minus spot. If the live outright below looks wrong, fix the scale row, not the formula.
A14: COP points scale (divide points by) | E14: 1 | F14: =E14 -> 1 | G14: Input | H14: COP points quote in pesos. Check on FRD <GO>.
A15: USDCOP 3m outright | F15: =$F$12+$F$13/$F$14 -> 3243.54 | G15: Calculated | H15: Snapshot outright 3243.54
A16: USDCLP spot | B16: USDCLP Curncy | C16: PX_LAST | D16: =IFERROR(bdp($B16,$C16),"") | E16: 982.57 | F16: =IF(AND(Inputs!$B$3=1,ISNUMBER(D16)),D16,E16) -> 982.57 | G16: Screen 13-Oct
A17: USDCLP 3m forward points | B17: CLP3M Curncy | C17: PX_LAST | D17: =IFERROR(bdp($B17,$C17),"") | E17: -0.87 | F17: =IF(AND(Inputs!$B$3=1,ISNUMBER(D17)),D17,E17) -> -0.87 | G17: Screen (derived) | H17: Snapshot = outright 981.70 minus spot. Chilean points are near zero — that is the whole reason the short CLP leg is free.
A18: CLP points scale (divide points by) | E18: 1 | F18: =E18 -> 1 | G18: Input | H18: Check on FRD <GO>.
A19: USDCLP 3m outright | F19: =$F$16+$F$17/$F$18 -> 981.7 | G19: Calculated | H19: Snapshot outright 981.70
A20: USDBRL spot | B20: USDBRL Curncy | C20: PX_LAST | D20: =IFERROR(bdp($B20,$C20),"") | E20: 5.02705 | F20: =IF(AND(Inputs!$B$3=1,ISNUMBER(D20)),D20,E20) -> 5.02705 | G20: Screen 13-Oct
A21: USDBRL 3m forward points (pips) | B21: BRL3M Curncy | C21: PX_LAST | D21: =IFERROR(bdp($B21,$C21),"") | E21: 867.26 | F21: =IF(AND(Inputs!$B$3=1,ISNUMBER(D21)),D21,E21) -> 867.26 | G21: Screen (derived) | H21: Snapshot = (5.113776 − 5.02705) x 10,000. The NDF prices off the cupom cambial, not Selic minus SOFR — which is why BRL carry is 6.6%, not 9-10%.
A22: BRL points scale (divide points by) | E22: 10000 | F22: =E22 -> 10000 | G22: Input
A23: USDBRL 3m outright | F23: =$F$20+$F$21/$F$22 -> 5.113776 | G23: Calculated | H23: Snapshot outright 5.113776
A24: USDMXN spot | B24: USDMXN Curncy | C24: PX_LAST | D24: =IFERROR(bdp($B24,$C24),"") | E24: 18.3727 | F24: =IF(AND(Inputs!$B$3=1,ISNUMBER(D24)),D24,E24) -> 18.3727 | G24: Screen 13-Oct
A25: USDMXN 3m forward points (pips) | B25: MXN3M Curncy | C25: PX_LAST | D25: =IFERROR(bdp($B25,$C25),"") | E25: 1196.77 | F25: =IF(AND(Inputs!$B$3=1,ISNUMBER(D25)),D25,E25) -> 1196.77 | G25: Screen (derived) | H25: Snapshot = (18.492377 − 18.3727) x 10,000.
A26: MXN points scale (divide points by) | E26: 10000 | F26: =E26 -> 10000 | G26: Input
A27: USDMXN 3m outright | F27: =$F$24+$F$25/$F$26 -> 18.492377 | G27: Calculated | H27: Snapshot outright 18.492377
A28: USDCOP 3m implied vol (%) | B28: USDCOPV3M Curncy | C28: PX_LAST | D28: =IFERROR(bdp($B28,$C28),"") | E28: 14.7 | F28: =IF(AND(Inputs!$B$3=1,ISNUMBER(D28)),D28,E28) -> 14.7 | G28: Screen 13-Oct
A29: USDCLP 3m implied vol (%) | B29: USDCLPV3M Curncy | C29: PX_LAST | D29: =IFERROR(bdp($B29,$C29),"") | E29: 12.8 | F29: =IF(AND(Inputs!$B$3=1,ISNUMBER(D29)),D29,E29) -> 12.8 | G29: Screen 13-Oct
A30: USDBRL 3m implied vol (%) | B30: USDBRLV3M Curncy | C30: PX_LAST | D30: =IFERROR(bdp($B30,$C30),"") | E30: 15.2 | F30: =IF(AND(Inputs!$B$3=1,ISNUMBER(D30)),D30,E30) -> 15.2 | G30: Screen 13-Oct
A31: USDMXN 3m implied vol (%) | B31: USDMXNV3M Curncy | C31: PX_LAST | D31: =IFERROR(bdp($B31,$C31),"") | E31: 11.2 | F31: =IF(AND(Inputs!$B$3=1,ISNUMBER(D31)),D31,E31) -> 11.2 | G31: Screen 13-Oct
A32: USDBRL 3m 25d risk reversal (vol pts) | B32: USDBRL25R3M Curncy | C32: PX_LAST | D32: =IFERROR(bdp($B32,$C32),"") | E32: 4.51 | F32: =IF(AND(Inputs!$B$3=1,ISNUMBER(D32)),D32,E32) -> 4.51 | G32: Screen 13-Oct | H32: USD calls over puts. The market pays up for BRL weakness.
A33: Correlation USDCOP vs USDCLP (3m daily returns) | E33: 0.55 | F33: =IF(AND(Inputs!$B$3=1,ISNUMBER(D33)),D33,E33) -> 0.55 | G33: PLACEHOLDER | H33: Pull from CORR <GO>: USDCOP Curncy vs USDCLP Curncy, 3m daily. No ticker — paste the number into E.
A34: Correlation USDBRL vs USDMXN (3m daily returns) | E34: 0.6 | F34: =IF(AND(Inputs!$B$3=1,ISNUMBER(D34)),D34,E34) -> 0.6 | G34: PLACEHOLDER | H34: Pull from CORR <GO>.
A35: Policy rates
A36: Colombia policy rate (%) | B36: CORRRMIN Index | C36: PX_LAST | D36: =IFERROR(bdp($B36,$C36),"") | E36: 9.25 | F36: =IF(AND(Inputs!$B$3=1,ISNUMBER(D36)),D36,E36) -> 9.25 | G36: PLACEHOLDER | H36: Verify. Not in the 13-Oct pull.
A37: Chile policy rate (%) | B37: CHOVCHOV Index | C37: PX_LAST | D37: =IFERROR(bdp($B37,$C37),"") | E37: 4.75 | F37: =IF(AND(Inputs!$B$3=1,ISNUMBER(D37)),D37,E37) -> 4.75 | G37: PLACEHOLDER | H37: Verify. Not in the 13-Oct pull.
A38: Brazil Selic target (%) | B38: BZSTSETA Index | C38: PX_LAST | D38: =IFERROR(bdp($B38,$C38),"") | E38: 13.75 | F38: =IF(AND(Inputs!$B$3=1,ISNUMBER(D38)),D38,E38) -> 13.75 | G38: Screen (implied) | H38: CDI cash printed 13.65 on 13-Oct; Selic sits ~10bp above CDI.
A39: Mexico overnight target (%) | B39: MXONBR Index | C39: PX_LAST | D39: =IFERROR(bdp($B39,$C39),"") | E39: 6.5 | F39: =IF(AND(Inputs!$B$3=1,ISNUMBER(D39)),D39,E39) -> 6.5 | G39: Screen 13-Oct
A40: SOFR fixing (%) | B40: SOFRRATE Index | C40: PX_LAST | D40: =IFERROR(bdp($B40,$C40),"") | E40: 3.87 | F40: =IF(AND(Inputs!$B$3=1,ISNUMBER(D40)),D40,E40) -> 3.87 | G40: Screen 13-Oct | H40: Cash point of ICVS 490.
A41: Brazil DI curve — offshore Pre x DI, ICVS 388 (tickers below are the DI futures; verify on ODA <GO> if a cell fails to load)
...

Sheet FX COP-CLP
A1: Trade: Long COP / Short CLP — 3m NDF carry pair
A2: The best carry trade in the book. COP earns ~7% from a 9%-plus policy rate and the CLP short costs nothing because Chilean forward points are flat. Both are copper/oil-adjacent Andean currencies, so the dollar beta and the commodity beta largely cancel. What is left is the rate differential.
A4: Structure
A5: Buy COP 3m forward (sell USD/COP NDF) and sell CLP 3m forward (buy USD/CLP NDF), equal USD notional on each leg, both settling on the quarterly roll date. Net USD exposure is zero — the trade is COP vs CLP, not COP vs the dollar.
A7: Levels (green = linked to Inputs)
A8: USDCOP spot | B8: =Inputs!$F$12 -> 3184.71
A9: USDCOP 3m outright | B9: =Inputs!$F$15 -> 3243.54
A10: USDCLP spot | B10: =Inputs!$F$16 -> 982.57
A11: USDCLP 3m outright | B11: =Inputs!$F$19 -> 981.7
A12: Days spot to settlement | B12: =Inputs!$F$10 -> 95
A13: Cross: CLP per 1 COP | B13: =B10/B8 -> 0.30852731 | C13: Equals USDCLP / USDCOP. Long COP wants this number to RISE.
A15: Carry — what you earn just for holding it
A16: COP leg carry, annualised | B16: =(B9/B8-1)*365/B12 -> 0.070973826 | C16: You buy COP at the forward, which is cheaper than spot (more COP per dollar). If spot does not move, that gap is your gain. Annualised x365/days.
A17: CLP leg carry, annualised | B17: =(B10/B11-1)*365/B12 -> 0.003404942 | C17: Chilean forward points are flat, so shorting CLP costs almost nothing. In the 13-Oct snapshot the forward is slightly BELOW spot, so the short leg actually ADDS carry.
A18: NET carry, annualised | B18: =B16+B17 -> 0.074378768 | C18: Positive = you are paid to wait.
A20: Volatility — how much it can move against you
A21: USDCOP 3m vol (%) | B21: =Inputs!$F$28 -> 14.7
A22: USDCLP 3m vol (%) | B22: =Inputs!$F$29 -> 12.8
A23: Correlation of the two legs | B23: =Inputs!$F$33 -> 0.55 | C23: Higher correlation = the dollar moves cancel out = lower pair vol.
A24: Pair vol, annualised | B24: =SQRT(B21^2+B22^2-2*B23*B21*B22)/100 -> 0.13151198 | C24: sqrt(v1² + v2² − 2·ρ·v1·v2). This is the vol of the cross, which is what you actually own.
A25: 1 standard deviation over the 3m window | B25: =B24*SQRT(B12/365) -> 0.067093535 | C25: Vol scales with the square root of time: annual vol x sqrt(days/365).
A26: Carry / vol (annual) | B26: =IF(B24=0,0,B18/B24) -> 0.5655665 | C26: The number that ranks the two FX trades. Above 0.5 is a good carry trade.
A28: Sizing and risk (yellow = you choose)
A29: Notional per leg ($) | B29: 10000000
A30: Stop distance in 3m standard deviations | B30: 1.25 | C30: 1.25σ = a move you'd expect roughly once every 5 quarters.
A31: Stop distance (%) | B31: =B30*B25 -> 0.083866919
A32: Stop level on the cross | B32: =B13*(1-B31) -> 0.28265207 | C32: Close the trade if the cross falls to here.
A33: Risk at stop ($) | B33: =B29*B31 -> 838669.19
A34: Carry over the 3m window ($) | B34: =B29*B18*B12/365 -> 193588.57
A35: Carry per year ($) | B35: =B29*B18 -> 743787.68
A36: Break-even: spot move the carry absorbs over 3m | B36: =B18*B12/365 -> 0.019358857 | C36: The cross can fall this much over the quarter and you still make zero.
A38: What I'd say
A39: Thesis in one line: Colombia pays me 7% to own its currency, Chile charges me nothing to short its currency, and the two move together against the dollar — so I keep the carry and lose most of the beta. What kills it: a Colombia-specific shock — fiscal rule abandonment, a BanRep cut cycle faster than priced, or an oil collapse (Colombia exports oil, Chile imports it, so oil down hurts both legs). That is why the Colombia CDS short on the credit tab is a natural tail hedge for this trade. Why not BRL/MXN as the core: same idea, half the carry-to-vol.

Sheet FX BRL-MXN
A1: Trade: Long BRL / Short MXN — 3m NDF carry pair
A2: The satellite carry trade. BRL carries ~6.6% (the NDF prices off the cupom cambial, not Selic minus SOFR), the MXN short costs ~2.5%, net ~4.1%. Weaker than COP/CLP on carry-to-vol but it expresses two views at once: Brazil fiscal improvement after the 25-Oct runoff and a Mexico growth slowdown.
A4: Structure
A5: Buy BRL 3m forward (sell USD/BRL NDF) and sell MXN 3m forward (buy USD/MXN NDF), equal USD notional on each leg, both settling on the quarterly roll date. Net USD exposure is zero — the trade is BRL vs MXN, not BRL vs the dollar.
A7: Levels (green = linked to Inputs)
A8: USDBRL spot | B8: =Inputs!$F$20 -> 5.02705
A9: USDBRL 3m outright | B9: =Inputs!$F$23 -> 5.113776
A10: USDMXN spot | B10: =Inputs!$F$24 -> 18.3727
A11: USDMXN 3m outright | B11: =Inputs!$F$27 -> 18.492377
A12: Days spot to settlement | B12: =Inputs!$F$10 -> 95
A13: Cross: MXN per 1 BRL | B13: =B10/B8 -> 3.6547677 | C13: Equals USDMXN / USDBRL. Long BRL wants this number to RISE.
A15: Carry — what you earn just for holding it
A16: BRL leg carry, annualised | B16: =(B9/B8-1)*365/B12 -> 0.066283491 | C16: You buy BRL at the forward, which is cheaper than spot (more BRL per dollar). If spot does not move, that gap is your gain. Annualised x365/days.
A17: MXN leg carry, annualised | B17: =(B10/B11-1)*365/B12 -> -0.024864928 | C17: MXN forward points are large and positive, so shorting MXN COSTS carry — you buy USD/MXN forward above spot. This leg is a drag; the BRL leg pays for it.
A18: NET carry, annualised | B18: =B16+B17 -> 0.041418562 | C18: Positive = you are paid to wait.
A20: Volatility — how much it can move against you
A21: USDBRL 3m vol (%) | B21: =Inputs!$F$30 -> 15.2
A22: USDMXN 3m vol (%) | B22: =Inputs!$F$31 -> 11.2
A23: Correlation of the two legs | B23: =Inputs!$F$34 -> 0.6 | C23: Higher correlation = the dollar moves cancel out = lower pair vol.
A24: Pair vol, annualised | B24: =SQRT(B21^2+B22^2-2*B23*B21*B22)/100 -> 0.12336612 | C24: sqrt(v1² + v2² − 2·ρ·v1·v2). This is the vol of the cross, which is what you actually own.
A25: 1 standard deviation over the 3m window | B25: =B24*SQRT(B12/365) -> 0.06293776 | C25: Vol scales with the square root of time: annual vol x sqrt(days/365).
A26: Carry / vol (annual) | B26: =IF(B24=0,0,B18/B24) -> 0.33573692 | C26: The number that ranks the two FX trades. Above 0.5 is a good carry trade.
A28: Sizing and risk (yellow = you choose)
A29: Notional per leg ($) | B29: 10000000
A30: Stop distance in 3m standard deviations | B30: 1.25 | C30: 1.25σ = a move you'd expect roughly once every 5 quarters.
A31: Stop distance (%) | B31: =B30*B25 -> 0.0786722
A32: Stop level on the cross | B32: =B13*(1-B31) -> 3.3672391 | C32: Close the trade if the cross falls to here.
A33: Risk at stop ($) | B33: =B29*B31 -> 786722
A34: Carry over the 3m window ($) | B34: =B29*B18*B12/365 -> 107801.74
A35: Carry per year ($) | B35: =B29*B18 -> 414185.62
A36: Break-even: spot move the carry absorbs over 3m | B36: =B18*B12/365 -> 0.010780174 | C36: The cross can fall this much over the quarter and you still make zero.
A38: What I'd say
A39: Thesis in one line: I'm paid 4% to be long the country whose fiscal story is improving and short the one whose growth is stalling. Say 4.1%, not 7-8% — the naive Selic-minus-Banxico differential overstates it because the BRL NDF is priced off the cupom cambial. What kills it: the 25-Oct Brazil runoff going the wrong way, or a USMCA/tariff relief rally in MXN. The BRL risk reversal at 4.5 vol says the market already pays up for BRL downside, so size is cut through the event and this is the first trade to trim if the risk budget is over. Note the Mexico overlap: this is one of four positions in the book that pay off if Mexico slows.

Sheet MX 1y1y
A1: Trade: Receive Mexico 1y1y TIIE — 'Banxico does not hike'
A2: The hikes are priced in the 1y1y sector, not the 6m. The 6m swap sits below the policy rate (nothing to sell), the 1y1y sits ~100bp above it. If Banxico holds for the next twelve months, the 1y1y has to fall toward the spot 1y — and you collect the roll while you wait.
A4: Levels
A5: Banxico policy rate (%) | B5: =Inputs!$F$39 -> 6.5
A6: TIIE 6m (%) | B6: =Inputs!$F$54 -> 6.4647 | C6: Below policy: the 6m sector prices no hikes. Nothing to receive there.
A7: TIIE 1y spot (%) | B7: =Inputs!$F$55 -> 6.6335
A8: TIIE 2y spot (%) | B8: =Inputs!$F$56 -> 7.0806
A9: Mexico 1y1y forward (%) | B9: =((1+B8/100)^2/(1+B7/100)-1)*100 -> 7.5295746 | C9: The 1y rate the curve implies starting one year from now: (1+2y)² / (1+1y) − 1. Market convention reads this as 'where policy will be in a year'.
A10: Hikes priced over the next year (bp) | B10: =(B9-B5)*100 -> 102.95746 | C10: 1y1y minus today's policy rate.
A12: The same number for the Fed — for the comparison
A13: SOFR 1y (%) | B13: =Inputs!$F$62 -> 4.5
A14: SOFR 2y (%) | B14: =Inputs!$F$63 -> 4.6635
A15: SOFR cash (%) | B15: =Inputs!$F$40 -> 3.87
A16: US 1y1y forward (%) | B16: =((1+B14/100)^2/(1+B13/100)-1)*100 -> 4.8272558
A17: Fed hikes priced over the next year (bp) | B17: =(B16-B15)*100 -> 95.725581 | C17: Both curves price roughly the same hiking cycle. My view is asymmetric: Banxico holds, the Fed delivers.
A19: Carry and roll
A20: A forward-starting receiver has no spot carry — you are not paying floating yet. What it has is roll: in a year, today's 1y1y becomes the spot 1y. If the curve does not move, the rate you receive is worth the gap between the two.
A21: Roll-down over one year (bp) | B21: =(B9-B7)*100 -> 89.607463 | C21: 1y1y minus spot 1y. Positive = the trade pays you to wait.
A22: Roll-down per quarter (bp, approx.) | B22: =B21/4 -> 22.401866 | C22: Straight-line quarter of the annual roll — a fair approximation on a curve this smooth.
A24: Sizing and risk
A25: DV01 ($ per bp) | B25: 15000
A26: Stop: 1y1y rises by (bp) | B26: 25
A27: Stop level on the 1y1y (%) | B27: =B9+B26/100 -> 7.7795746
A28: Risk at stop ($) | B28: =B25*B26 -> 375000
A29: Roll per year ($) | B29: =B25*B21 -> 1344111.9
A30: Roll per quarter ($) | B30: =B25*B22 -> 336027.99
A31: Roll per year / risk at stop | B31: =IF(B28=0,0,B29/B28) -> 3.5842985 | C31: How many times the carry pays for a stop-out in a year.
A33: Hedged version — if they ask 'what about the Fed?'
A34: An outright MX receiver is also a bet that global rates do not sell off. To strip that out, pay the US 1y1y against it, DV01-matched. The net roll is below. That version is self-funding and holds no global duration — it is the purer expression of 'Banxico holds, the Fed hikes'. I run the outright here because the US 10y receiver on the US tab already carries the global-duration view, and I don't want to pay it away twice.
A35: US 1y1y roll if you PAY it (bp/yr) | B35: =-(B16-B13)*100 -> -32.725581 | C35: Paying a forward that rolls down costs you.
A36: Net roll of the hedged pair (bp/yr) | B36: =B21+B35 -> 56.881882
A38: What I'd say
A39: Thesis in one line: the market has about 100bp of Banxico hikes priced over the next year; I think they deliver none, and the curve pays me roughly 90bp a year to wait for it. What kills it: an inflation re-acceleration that forces Banxico to follow the Fed, or a peso sell-off that makes them defend the currency with rates. Note the stop is 25bp — a quarter of what is priced — so I am not betting the whole move, I'm betting the direction. Overlap warning: this and the 2y2y spread are both long Mexican duration. Together they are one view sized twice; say that before they do.

Sheet MX-US 2y2y
A1: Trade: Receive Mexico 2y2y TIIE / Pay US 2y2y SOFR — the cross-market spread
A2: Two years out, both curves price their hiking cycles as done. The differential between them is the market's view of where Mexico's premium over the US settles. My view: Mexico's growth gap to the US widens, Banxico ends up lower than priced relative to the Fed, and the spread compresses. DV01-matched, so no outright duration.
A4: Mexico leg
A5: TIIE 1y (%) | B5: =Inputs!$F$55 -> 6.6335
A6: TIIE 2y (%) | B6: =Inputs!$F$56 -> 7.0806
A7: TIIE 3y (%) | B7: =Inputs!$F$57 -> 7.4
A8: TIIE 4y (%) | B8: =Inputs!$F$58 -> 7.55 | C8: PLACEHOLDER on Inputs until you pull 52x1.
A9: Mexico 2y2y (%) | B9: =(((1+B8/100)^4/(1+B6/100)^2)^(1/2)-1)*100 -> 8.0214577 | C9: The 2y rate implied two years from now: [(1+4y)⁴ / (1+2y)²]^½ − 1.
A10: Mexico 1y2y (%) | B10: =(((1+B7/100)^3/(1+B5/100))^(1/2)-1)*100 -> 7.7853137 | C10: What the 2y2y becomes after one year passes. Needed for roll.
A12: US leg
A13: SOFR 1y (%) | B13: =Inputs!$F$62 -> 4.5
A14: SOFR 2y (%) | B14: =Inputs!$F$63 -> 4.6635
A15: SOFR 3y (%) | B15: =Inputs!$F$64 -> 4.7058
A16: SOFR 4y (%) | B16: =Inputs!$F$65 -> 4.74 | C16: PLACEHOLDER on Inputs until you pull USOSFR4.
A17: US 2y2y (%) | B17: =(((1+B16/100)^4/(1+B14/100)^2)^(1/2)-1)*100 -> 4.8165559
A18: US 1y2y (%) | B18: =(((1+B15/100)^3/(1+B13/100))^(1/2)-1)*100 -> 4.8088519
A20: The spread — and what is already priced
A21: Policy differential today (bp) | B21: =(Inputs!$F$39-Inputs!$F$40)*100 -> 263 | C21: Banxico minus SOFR cash.
A22: 2y spot differential (bp) | B22: =(B6-B14)*100 -> 241.71 | C22: Already INSIDE the policy differential: the market prices some compression in the first two years.
A23: 2y2y differential (bp) — THE TRADE | B23: =(B9-B17)*100 -> 320.49018 | C23: Receive this. You win if it falls.
A25: Carry and roll
A26: Forward-starting on both legs, so no spot carry on either. Roll: each 2y2y drifts toward its own 1y2y as a year passes. You gain the Mexico roll (receiver) and pay the US roll (payer).
A27: Mexico leg roll, 1 year (bp) | B27: =(B9-B10)*100 -> 23.614399
A28: US leg roll, 1 year (bp) — you pay this | B28: =-(B17-B18)*100 -> -0.7703978
A29: NET roll per year (bp) | B29: =B27+B28 -> 22.844001
A30: NET roll per quarter (bp) | B30: =B29/4 -> 5.7110002
A32: Sizing and risk
A33: DV01 per leg ($ per bp) | B33: 10000 | C33: Equal DV01 on both legs = no net duration.
A34: Stop: spread WIDENS by (bp) | B34: 25
A35: Stop level on the 2y2y differential (bp) | B35: =B23+B34 -> 345.49018
A36: Risk at stop ($) | B36: =B33*B34 -> 250000
A37: Net roll per year ($) | B37: =B33*B29 -> 228440.01
A39: What I'd say
A40: Thesis in one line: the market thinks Mexico's rate premium over the US settles around the current 2y2y differential; I think a weaker Mexican economy pulls Banxico lower relative to the Fed, so I receive Mexico and pay the US two years out, DV01 for DV01. Why 2y2y and not 2y: the spot 2y differential already sits inside the policy differential — the first two years are partly priced. The forward sector is where the compression is not. What kills it: the Fed cutting into a US slowdown while Banxico is stuck with sticky inflation — that widens the spread. Honest caveat: with the 1y1y receiver this is two long-Mexico-duration positions. If they push, drop the 1y1y and keep this one — it is self-funded.

Sheet BR DI
A1: Trade: Receive Brazil DI — belly (Jan-29) and long end (Jan-33) — the fiscal-improvement trade
A2: The view is fiscal, not monetary: a credible fiscal plan under a business-friendly government compresses Brazil's term premium, and the long end rallies more than the front. Be straight about the cost: on an inverted curve, receiving the belly outright is NEGATIVE carry. The tab shows exactly how much, and a flattener version that removes most of the drag.
A4: Curve
A5: CDI overnight (%) | B5: =Inputs!$F$42 -> 13.65 | C5: What you PAY on a receiver. Above every DI node — that is the inversion.
A6: DI Jan-28 (%) | B6: =Inputs!$F$43 -> 12.7225
A7: DI Jan-29 (%) | B7: =Inputs!$F$44 -> 12.4425
A8: DI Jan-31 (%) | B8: =Inputs!$F$46 -> 12.345
A9: DI Jan-33 (%) | B9: =Inputs!$F$47 -> 12.45 | C9: PLACEHOLDER on Inputs until pulled.
A10: Valuation date | B10: =Inputs!$F$7 -> 46309
A11: Years to Jan-28 | B11: =(Inputs!$F$49-B10)/365 -> 1.2219178
A12: Years to Jan-29 | B12: =(Inputs!$F$50-B10)/365 -> 2.2219178
A13: Years to Jan-31 | B13: =(Inputs!$F$51-B10)/365 -> 4.2219178
A14: Years to Jan-33 | B14: =(Inputs!$F$52-B10)/365 -> 6.2273973
A16: Option A — what you asked for: receive Jan-29 and Jan-33 outright
A17: Carry: you receive the fixed DI rate and pay CDI overnight. With CDI above every node, that is a cost every day. Roll: as time passes the Jan-29 becomes a shorter swap and reprices to the (higher) shorter rate — on an inverted front end a receiver rolls UP the curve, which also costs. The long end is close to flat, so the Jan-33 leg rolls roughly neutral.
A18: DV01 on Jan-29 leg ($/bp) | B18: 5000
A19: DV01 on Jan-33 leg ($/bp) | B19: 5000
A20: Jan-29 carry per quarter (bp) | B20: =(B7-B5)*100/4 -> -30.1875 | C20: (DI rate − CDI) / 4. Negative = costs you.
A21: Jan-29 roll per quarter (bp) | B21: =-((B6-B7)/(B12-B11))*100/4 -> -7 | C21: Slope toward the next shorter node (Jan-28), one quarter of it. Negative when the shorter rate is higher.
A22: Jan-33 carry per quarter (bp) | B22: =(B9-B5)*100/4 -> -30
A23: Jan-33 roll per quarter (bp) | B23: =-((B8-B9)/(B14-B13))*100/4 -> 1.3089139 | C23: Slope toward Jan-31.
A24: Option A total carry + roll per quarter ($) | B24: =B18*(B20+B21)+B19*(B22+B23) -> -329392.93 | C24: This is what being early costs you per quarter.
A25: Option A total per year ($) | B25: =B24*4 -> -1317571.7
A26: Break-even: rates must FALL by (bp per quarter) | B26: =IF((B18+B19)=0,0,-B24/(B18+B19)) -> 32.939293 | C26: The rally you need each quarter just to cover the carry. Say this number before they ask for it.
A27: Stop: blended rate rises by (bp) | B27: 40 | C27: Wider than the other rates stops — DI moves more, and the runoff is a dated catalyst.
A28: Option A risk at stop ($) | B28: =(B18+B19)*B27 -> 400000
A29: Blended entry rate, DV01-weighted (%) | B29: =IF((B18+B19)=0,0,(B18*B7+B19*B9)/(B18+B19)) -> 12.44625 | C29: For the Monitor.
A31: Option B — the same view with the carry drag removed: receive Jan-33 / pay Jan-28, DV01-matched
A32: Paying the Jan-28 earns you the inversion: you receive CDI (high) and pay the Jan-28 rate (lower), and the pay leg rolls up the steep front end in your favour. That funds the long-end receiver. You give up the outright rally but keep the term-premium compression — which is the fiscal story anyway. Monetary policy largely nets out.
A33: DV01 per leg ($/bp) | B33: 10000
A34: Pay Jan-28 carry per quarter (bp) | B34: =(B5-B6)*100/4 -> 23.1875 | C34: (CDI − DI rate) / 4. Positive: you receive the higher overnight.
A35: Pay Jan-28 roll per quarter (bp) | B35: =((B5-B6)/B11)*100/4 -> 18.976317 | C35: Slope from the Jan-28 back to overnight, one quarter of it. A payer rolling up the curve gains.
A36: Option B total carry + roll per quarter ($) | B36: =B33*(B34+B35+B22+B23) -> 134727.31
A37: Option B total per year ($) | B37: =B36*4 -> 538909.25
A38: Stop: Jan-28/Jan-33 spread STEEPENS by (bp) | B38: 30
A39: Option B risk at stop ($) | B39: =B33*B38 -> 300000
A40: Entry spread Jan-33 minus Jan-28 (bp) | B40: =(B9-B6)*100 -> -27.25 | C40: You win if this falls (flattens).
A42: Which one goes in the book
A43: Selected option (A or B) | B43: A | C43: Summary and Monitor read this cell.
A44: Selected risk at stop ($) | B44: =IF(B43="A",B28,B39) -> 400000
...

Sheet US Rates
A1: Trade: Receive US 10y SOFR, partly funded by paying 2y — 'the sell-off is nearly done'
A2: You asked for a 10y-plus receiver that costs nothing. Good news: with the front end below the 10y, a 10y receiver is ALREADY positive carry — you receive the 10y fixed and pay SOFR floating. The hedge ratio cell lets you dial between an outright receiver (ratio 0) and a pure 2s10s flattener (ratio 1). The butterfly is shown below so you can explain why it is not the trade.
A4: Curve
A5: SOFR cash (%) | B5: =Inputs!$F$40 -> 3.87
A6: SOFR 3m (%) | B6: =Inputs!$F$61 -> 4 | C6: Your funding cost for the quarter. PLACEHOLDER until pulled.
A7: SOFR 1y (%) | B7: =Inputs!$F$62 -> 4.5
A8: SOFR 2y (%) | B8: =Inputs!$F$63 -> 4.6635
A9: SOFR 5y (%) | B9: =Inputs!$F$66 -> 4.78
A10: SOFR 7y (%) | B10: =Inputs!$F$67 -> 4.88
A11: SOFR 10y (%) | B11: =Inputs!$F$68 -> 5 | C11: PLACEHOLDER — pull this first.
A12: SOFR 30y (%) | B12: =Inputs!$F$70 -> 5.15
A13: 2s10s slope (bp) | B13: =(B11-B8)*100 -> 33.65
A15: Leg 1 — receive 10y
A16: Receive DV01 ($/bp) | B16: 20000
A17: 10y carry per quarter (bp) | B17: =(B11-B6)*100/4 -> 25 | C17: (10y fixed − 3m funding) / 4. Positive: you receive more than you pay. This is why a receiver 'costs nothing' when the curve slopes up.
A18: 10y roll per quarter (bp) | B18: =((B11-B10)/3)*100/4 -> 1 | C18: In three months your 10y is a 9.75y. Slope between the 7y and 10y, one quarter of it. Positive on an upward-sloping curve.
A20: Leg 2 — pay 2y (the hedge against 'the Fed hikes more than priced')
A21: Hedge ratio (pay-2y DV01 as a fraction of receive DV01) | B21: 0.5 | C21: 0 = outright 10y receiver. 1 = DV01-neutral 2s10s flattener. 0.5 = half the duration hedged. Your call; I'd argue 0.5.
A22: Pay DV01 ($/bp) | B22: =B21*B16 -> 10000
A23: 2y payer carry per quarter (bp) | B23: =-(B8-B6)*100/4 -> -16.5875 | C23: You pay the 2y fixed and receive 3m floating. Negative when 2y > 3m.
A24: 2y payer roll per quarter (bp) | B24: =-((B8-B7)/1)*100/4 -> -4.0875 | C24: A payer rolling down toward the 1y loses.
A26: Net
A27: Net carry + roll per quarter ($) | B27: =B16*(B17+B18)+B22*(B23+B24) -> 313250
A28: Net carry + roll per year ($) | B28: =B27*4 -> 1253000
A29: Net DV01 ($/bp) — how long duration you really are | B29: =B16-B22 -> 10000
A30: Stop: 10y rises by (bp) | B30: 25
A31: Stop level on 10y (%) | B31: =B11+B30/100 -> 5.25
A32: Risk at stop ($) | B32: =B29*B30 -> 250000 | C32: On net duration. The 2y leg cushions a parallel sell-off; it does not cushion a bear-steepening.
A33: Break-even: 10y can rise by (bp per quarter) and you still break even | B33: =IF(B29=0,0,B27/B29) -> 31.325
A35: Why not the butterfly — 5s10s30s, receive the belly
A36: A butterfly (receive 2× 10y, pay 5y and 30y, DV01 50/50 on the wings) is a bet on curvature, not on the level of rates. Its net DV01 is zero, so it does not express 'the sell-off is nearly done' at all. It is shown here so you can say why you looked at it and put it down. Its carry/roll:
A37: Belly DV01 ($/bp) | B37: 20000
A38: Pay 5y carry+roll per quarter (bp) | B38: =-(B9-B6)*100/4-((B9-B8)/3)*100/4 -> -20.470833
A39: Pay 30y carry+roll per quarter (bp) | B39: =-(B12-B6)*100/4-((B12-B11)/20)*100/4 -> -28.9375
A40: Butterfly net carry + roll per quarter ($) | B40: =B37*(B17+B18)+B37/2*B38+B37/2*B39 -> 25916.667 | C40: Usually near zero — and zero duration. Not this trade.
A42: Zero-premium option version — if they want 'no cost' literally
A43: Buy a 3m-into-10y receiver swaption and sell a 3m-into-10y payer swaption, strikes chosen so the premiums match. Zero cost upfront, long duration below the receiver strike, short above the payer strike — a collar on the 10y. Fill the four yellow cells from VCUB <GO> / SWPM <GO> and the net premium computes. Skew will usually let you set the receiver strike closer to ATM than the payer strike.
A44: 3m10y ATM forward (%) | B44: =B11 -> 5 | C44: Use the true forward from SWPM; the spot 10y is a stand-in.
A45: Receiver strike (%) | B45: 4.9
A46: Receiver premium paid (bp of notional) | B46: 35
...

Sheet Credit CL-CO
A1: Trade: Long Chile / Short Colombia — USD sovereign credit, via 5y CDS
A2: Colombia is treated too kindly by the market for a sovereign whose fiscal rule has been bent, whose deficit is structurally wide and whose oil revenue is fading. Chile is the cleanest balance sheet in the region. Long the quality, short the complacency — and the Colombia short is the tail hedge for the COP carry trade on the FX tab.
A4: Structure
A5: SELL 5y CDS protection on Chile (you receive its spread = long credit) and BUY 5y CDS protection on Colombia (you pay its spread = short credit), notionals set so both legs have the same spread DV01. Both legs carry the standard 100bp running coupon with upfront settlement; the economics below are in running-spread terms, which is how the trade is quoted and talked about.
A7: Levels
A8: Chile 5y CDS (bp) | B8: =Inputs!$F$72 -> 55 | C8: PLACEHOLDER on Inputs until WCDS is pulled.
A9: Colombia 5y CDS (bp) | B9: =Inputs!$F$73 -> 200
A10: Spread differential Colombia − Chile (bp) — THE TRADE | B10: =B9-B8 -> 145 | C10: You win if this WIDENS.
A11: Chile 10y CDS (bp) | B11: =Inputs!$F$76 -> 95
A12: Colombia 10y CDS (bp) | B12: =Inputs!$F$77 -> 280
A13: Chile 5s10s curve (bp) | B13: =B11-B8 -> 40 | C13: A positive slope is a healthy credit. A flat or inverted curve is a credit in stress.
A14: Colombia 5s10s curve (bp) | B14: =B12-B9 -> 80
A16: Spread DV01 and notionals
A17: Recovery rate | B17: =Inputs!$F$80 -> 0.25
A18: 5y SOFR (%) — discount rate | B18: =Inputs!$F$66 -> 4.78
A19: Chile hazard rate | B19: =B8/10000/(1-B17) -> 0.0073333333 | C19: spread / (1 − recovery): the market's annual default probability.
A20: Colombia hazard rate | B20: =B9/10000/(1-B17) -> 0.026666667
A21: Chile risky annuity (years) | B21: =(1-EXP(-(B18/100+B19)*5))/(B18/100+B19) -> 4.3700258 | C21: Value of 1bp a year for 5 years, survival- and discount-adjusted. Spread DV01 per $1mm = annuity × $100.
A22: Colombia risky annuity (years) | B22: =(1-EXP(-(B18/100+B20)*5))/(B18/100+B20) -> 4.1746934 | C22: Lower for the wider credit — it is more likely to default before paying you.
A23: Target spread DV01 per leg ($/bp) | B23: 10000
A24: Chile notional ($) — protection SOLD | B24: =B23/(B21/10000) -> 22883160
A25: Colombia notional ($) — protection BOUGHT | B25: =B23/(B22/10000) -> 23953855
A27: Carry — honest version
A28: Received on Chile ($/yr) | B28: =B24*B8/10000 -> 125857.38
A29: Paid on Colombia ($/yr) | B29: =-B25*B9/10000 -> -479077.1
A30: NET carry ($/yr) | B30: =B28+B29 -> -353219.71 | C30: Negative whenever the short is the wider credit. You pay to hold this view.
A31: Break-even: differential must WIDEN by (bp per year) | B31: =IF(B23=0,0,-B30/B23) -> 35.321971 | C31: Quote this. 'I need Colombia to underperform Chile by X bp a year just to cover the carry' is the question they will ask.
A33: Sizing and risk
A34: Stop: differential TIGHTENS by (bp) | B34: 25
A35: Stop level on the differential (bp) | B35: =B10-B34 -> 120
A36: Risk at stop ($) | B36: =B23*B34 -> 250000
A38: Cash-bond alternative
A39: Same view in bonds: buy the long credit's 2035-area USD benchmark, short the short credit's. Carry is still negative (the wider credit yields more) but you pick up the Chile/Peru bonds' richer repo. CDS is cleaner for the conversation: no funding, no bond-specific basis, and the notionals above are what a PM would actually ask for. Pull YAS <GO> on the two bonds if they want the cash version.
A41: Portfolio logic
