Workbook

Sheet Control
A1: US RATES & CREDIT MONITOR
A2: Bloomberg-linked. Every cell is a formula; nothing is pasted as a value. Built for A. Rojas, UBS CIO Americas.
A4: SETTINGS — every data pull and every calculation on every tab points at these cells
E5: Horizon | F5: Obs back (rows)
A6: History start — daily block | B6: =EDATE(TODAY(),-126) | E6: 1D | F6: 2 | H6: 10.5y buffer so the 10y window is always full
A7: History end | B7: =TODAY() | E7: 1W | F7: 6 | H7: BDH end date
A8: History start — monthly block | B8: =EDATE(TODAY(),-301) | E8: 1M | F8: 23 | H8: 25y of month-ends for deep percentiles
A9: Daily observations pulled | B9: 2610 | E9: 3M | F9: 66 | H9: weekdays; block is HIST_D rows 8:2617
A10: Monthly observations pulled | B10: 301 | E10: 6M | F10: 131 | H10: month-ends; block is HIST_M rows 8:308
A11: bp per 1% | B11: 100 | E11: 1Y | F11: 262 | H11: scaling constant used by every change column
A12: Total-return horizon (years) | B12: 1 | E12: 2Y | F12: 523 | H12: used on Credit_TR and the rates TR grid
A13: Cash hurdle (%) | B13: 4.5 | E13: 3Y | F13: 784 | H13: your stated hurdle for 'EM still attractive vs cash'
A14: Coupon frequency (per year) | B14: 2 | E14: 5Y | F14: 1305 | H14: semi-annual UST convention
A15: Point-in-time: 1W ago date | B15: =WORKDAY(TODAY(),-5) | E15: 10Y | F15: 2610 | H15: used by single-point BDH pulls (futures strip)
A16: Point-in-time: 1M ago date | B16: =WORKDAY(TODAY(),-22) | E16: YTD — row of last obs of prior year | F16: =MATCH(DATE(YEAR(TODAY()),1,1),HIST_D!$A$8:$A$2617,-1)+1 | H16: same
A17: Point-in-time: prior year-end | B17: =DATE(YEAR(TODAY())-1,12,31) | E17: Row 1 = today. Row n = n-1 weekdays ago (Days=W, Fill=P holds the calendar even on holidays). | H17: same
A19: HOW TO REFRESH
A20: 1. Open on a Bloomberg terminal with the Excel add-in loaded. Everything recalculates on open (fullCalcOnLoad is set).
A21: 2. If a history column shows only one number instead of a full column, you are on pre-dynamic-array Excel: select the block and re-enter the BDH with Ctrl+Shift+Enter.
A22: 3. To change any ticker, edit it ONCE on the Tickers tab. Every pull and every downstream calculation reads the ticker from there.
A23: 4. To change a lookback window, edit the 'Obs back' table above. Nothing else needs touching.
A24: 5. Yellow cells are the only ones you should ever type in.
A27: COLOUR LEGEND
A28: Yellow fill, blue text | E28: Hardcoded input or scenario lever — yours to change
A29: Purple text | E29: Live Bloomberg pull (BDH / BDP)
A30: Green text | E30: Link to another tab in this workbook
A31: Black text | E31: Calculation from cells in this workbook
A32: Grey italic | E32: Note, source, or method caveat
A34: HOW THE NUMBERS ARE BUILT — so you can audit any cell in one step
A35: History | E35: HIST_D holds a 10y weekday block, newest first (Sort=D). HIST_M holds 25y of month-ends. Every level, change, percentile and z-score on every other tab is INDEX() into those two blocks — no duplicate pulls.
A36: Changes | E36: Change over horizon h = (row 1 − row h) × 100, where h comes from the 'Obs back' table. Yields and OAS therefore always change in bp.
A37: Percentiles | E37: PERCENTRANK over the first N rows of the block, N from the same table. 0% = tightest/lowest ever in that window, 100% = widest/highest.
A38: 4y and 15y UST | E38: There is no clean cash-Treasury generic at 4y or 15y. Both are built as: linear interpolation of the neighbouring UST nodes PLUS the curvature the SOFR OIS curve actually shows at that tenor (OIS4 minus the linear interp of OIS3/OIS5). That is a real market-observed shape, not a straight line. The components are shown so you can see the adjustment.
A39: Forwards | E39: Bootstrapped from spot par yields as compounded ratios, e.g. 5y5y = ((1+y10)^10 / (1+y5)^5)^(1/5) − 1. Par-yield approximation; fine for monitoring, not for pricing.
A40: Duration / DV01 | E40: Exact par-bond algebra, semi-annual: Dmod = (1 − (1+y/2)^(−2n)) / (y/2) / 2. No table lookups, no hardcoded durations.
A41: Rates total return | E41: Full repricing, not a duration approximation. The bond is priced off the annuity formula at the horizon yield with (n − horizon) years left, plus coupons received. Convexity is therefore captured exactly.
A42: Credit total return | E42: Carry (yield-to-worst × horizon) + roll + (−OAD × Δrate) + (−spread duration × Δspread) − credit loss. Each leg is its own visible cell.
A43: Why the legs stay separate | E43: The EM USD case rests on the Treasury leg providing ballast. Rate and spread P&L are never merged into one number anywhere in this workbook.
A45: TICKER CONFIDENCE — read this before you trust a number
A46: Tickers on the Tickers tab are flagged High or Verify. High = standard Bloomberg security I would defend. Verify = the concept is right but the exact ticker or field should be confirmed in SECF / FLDS before you quote the number to anyone.
...

Sheet Dashboard
A1: US RATES & CREDIT — THE BOARD
A2: =("As of "&TEXT(TODAY(),"dd mmm yyyy")&" · every figure below is a link; nothing here is typed in")
A4: RATES
B5: Level | C5: 1D | D5: 1W | E5: 1M | F5: YTD | G5: 1Y | H5: %ile 1y | I5: %ile 5y | J5: %ile 25y | K5: z (5y) | L5: Note
A6: UST 2Y | B6: =INDEX(HIST_D!$F$8:$F$2617,1) | C6: =IFERROR((INDEX(HIST_D!$F$8:$F$2617,1)-INDEX(HIST_D!$F$8:$F$2617,Control!$F$6))*Control!$B$11,"") | D6: =IFERROR((INDEX(HIST_D!$F$8:$F$2617,1)-INDEX(HIST_D!$F$8:$F$2617,Control!$F$7))*Control!$B$11,"") | E6: =IFERROR((INDEX(HIST_D!$F$8:$F$2617,1)-INDEX(HIST_D!$F$8:$F$2617,Control!$F$8))*Control!$B$11,"") | F6: =IFERROR((INDEX(HIST_D!$F$8:$F$2617,1)-INDEX(HIST_D!$F$8:$F$2617,Control!$F$16))*Control!$B$11,"") | G6: =IFERROR((INDEX(HIST_D!$F$8:$F$2617,1)-INDEX(HIST_D!$F$8:$F$2617,Control!$F$11))*Control!$B$11,"") | H6: =IFERROR(PERCENTRANK(HIST_D!$F$8:INDEX(HIST_D!$F$8:$F$2617,Control!$F$11),INDEX(HIST_D!$F$8:$F$2617,1)),"") | I6: =IFERROR(PERCENTRANK(HIST_D!$F$8:INDEX(HIST_D!$F$8:$F$2617,Control!$F$14),INDEX(HIST_D!$F$8:$F$2617,1)),"") | J6: =IFERROR(PERCENTRANK(HIST_M!$B$8:$B$308,INDEX(HIST_D!$F$8:$F$2617,1)),"") | K6: =IFERROR((INDEX(HIST_D!$F$8:$F$2617,1)-AVERAGE(HIST_D!$F$8:INDEX(HIST_D!$F$8:$F$2617,Control!$F$14)))/STDEV(HIST_D!$F$8:INDEX(HIST_D!$F$8:$F$2617,Control!$F$14)),"")
A7: UST 5Y | B7: =INDEX(HIST_D!$H$8:$H$2617,1) | C7: =IFERROR((INDEX(HIST_D!$H$8:$H$2617,1)-INDEX(HIST_D!$H$8:$H$2617,Control!$F$6))*Control!$B$11,"") | D7: =IFERROR((INDEX(HIST_D!$H$8:$H$2617,1)-INDEX(HIST_D!$H$8:$H$2617,Control!$F$7))*Control!$B$11,"") | E7: =IFERROR((INDEX(HIST_D!$H$8:$H$2617,1)-INDEX(HIST_D!$H$8:$H$2617,Control!$F$8))*Control!$B$11,"") | F7: =IFERROR((INDEX(HIST_D!$H$8:$H$2617,1)-INDEX(HIST_D!$H$8:$H$2617,Control!$F$16))*Control!$B$11,"") | G7: =IFERROR((INDEX(HIST_D!$H$8:$H$2617,1)-INDEX(HIST_D!$H$8:$H$2617,Control!$F$11))*Control!$B$11,"") | H7: =IFERROR(PERCENTRANK(HIST_D!$H$8:INDEX(HIST_D!$H$8:$H$2617,Control!$F$11),INDEX(HIST_D!$H$8:$H$2617,1)),"") | I7: =IFERROR(PERCENTRANK(HIST_D!$H$8:INDEX(HIST_D!$H$8:$H$2617,Control!$F$14),INDEX(HIST_D!$H$8:$H$2617,1)),"") | J7: =IFERROR(PERCENTRANK(HIST_M!$C$8:$C$308,INDEX(HIST_D!$H$8:$H$2617,1)),"") | K7: =IFERROR((INDEX(HIST_D!$H$8:$H$2617,1)-AVERAGE(HIST_D!$H$8:INDEX(HIST_D!$H$8:$H$2617,Control!$F$14)))/STDEV(HIST_D!$H$8:INDEX(HIST_D!$H$8:$H$2617,Control!$F$14)),"")
A8: UST 10Y | B8: =INDEX(HIST_D!$J$8:$J$2617,1) | C8: =IFERROR((INDEX(HIST_D!$J$8:$J$2617,1)-INDEX(HIST_D!$J$8:$J$2617,Control!$F$6))*Control!$B$11,"") | D8: =IFERROR((INDEX(HIST_D!$J$8:$J$2617,1)-INDEX(HIST_D!$J$8:$J$2617,Control!$F$7))*Control!$B$11,"") | E8: =IFERROR((INDEX(HIST_D!$J$8:$J$2617,1)-INDEX(HIST_D!$J$8:$J$2617,Control!$F$8))*Control!$B$11,"") | F8: =IFERROR((INDEX(HIST_D!$J$8:$J$2617,1)-INDEX(HIST_D!$J$8:$J$2617,Control!$F$16))*Control!$B$11,"") | G8: =IFERROR((INDEX(HIST_D!$J$8:$J$2617,1)-INDEX(HIST_D!$J$8:$J$2617,Control!$F$11))*Control!$B$11,"") | H8: =IFERROR(PERCENTRANK(HIST_D!$J$8:INDEX(HIST_D!$J$8:$J$2617,Control!$F$11),INDEX(HIST_D!$J$8:$J$2617,1)),"") | I8: =IFERROR(PERCENTRANK(HIST_D!$J$8:INDEX(HIST_D!$J$8:$J$2617,Control!$F$14),INDEX(HIST_D!$J$8:$J$2617,1)),"") | J8: =IFERROR(PERCENTRANK(HIST_M!$D$8:$D$308,INDEX(HIST_D!$J$8:$J$2617,1)),"") | K8: =IFERROR((INDEX(HIST_D!$J$8:$J$2617,1)-AVERAGE(HIST_D!$J$8:INDEX(HIST_D!$J$8:$J$2617,Control!$F$14)))/STDEV(HIST_D!$J$8:INDEX(HIST_D!$J$8:$J$2617,Control!$F$14)),"")
A9: UST 30Y | B9: =INDEX(HIST_D!$L$8:$L$2617,1) | C9: =IFERROR((INDEX(HIST_D!$L$8:$L$2617,1)-INDEX(HIST_D!$L$8:$L$2617,Control!$F$6))*Control!$B$11,"") | D9: =IFERROR((INDEX(HIST_D!$L$8:$L$2617,1)-INDEX(HIST_D!$L$8:$L$2617,Control!$F$7))*Control!$B$11,"") | E9: =IFERROR((INDEX(HIST_D!$L$8:$L$2617,1)-INDEX(HIST_D!$L$8:$L$2617,Control!$F$8))*Control!$B$11,"") | F9: =IFERROR((INDEX(HIST_D!$L$8:$L$2617,1)-INDEX(HIST_D!$L$8:$L$2617,Control!$F$16))*Control!$B$11,"") | G9: =IFERROR((INDEX(HIST_D!$L$8:$L$2617,1)-INDEX(HIST_D!$L$8:$L$2617,Control!$F$11))*Control!$B$11,"") | H9: =IFERROR(PERCENTRANK(HIST_D!$L$8:INDEX(HIST_D!$L$8:$L$2617,Control!$F$11),INDEX(HIST_D!$L$8:$L$2617,1)),"") | I9: =IFERROR(PERCENTRANK(HIST_D!$L$8:INDEX(HIST_D!$L$8:$L$2617,Control!$F$14),INDEX(HIST_D!$L$8:$L$2617,1)),"") | J9: =IFERROR(PERCENTRANK(HIST_M!$E$8:$E$308,INDEX(HIST_D!$L$8:$L$2617,1)),"") | K9: =IFERROR((INDEX(HIST_D!$L$8:$L$2617,1)-AVERAGE(HIST_D!$L$8:INDEX(HIST_D!$L$8:$L$2617,Control!$F$14)))/STDEV(HIST_D!$L$8:INDEX(HIST_D!$L$8:$L$2617,Control!$F$14)),"")
A10: 2s10s | B10: =INDEX(HIST_D!$AV$8:$AV$2617,1) | C10: =IFERROR((INDEX(HIST_D!$AV$8:$AV$2617,1)-INDEX(HIST_D!$AV$8:$AV$2617,Control!$F$6))*1,"") | D10: =IFERROR((INDEX(HIST_D!$AV$8:$AV$2617,1)-INDEX(HIST_D!$AV$8:$AV$2617,Control!$F$7))*1,"") | E10: =IFERROR((INDEX(HIST_D!$AV$8:$AV$2617,1)-INDEX(HIST_D!$AV$8:$AV$2617,Control!$F$8))*1,"") | F10: =IFERROR((INDEX(HIST_D!$AV$8:$AV$2617,1)-INDEX(HIST_D!$AV$8:$AV$2617,Control!$F$16))*1,"") | G10: =IFERROR((INDEX(HIST_D!$AV$8:$AV$2617,1)-INDEX(HIST_D!$AV$8:$AV$2617,Control!$F$11))*1,"") | H10: =IFERROR(PERCENTRANK(HIST_D!$AV$8:INDEX(HIST_D!$AV$8:$AV$2617,Control!$F$11),INDEX(HIST_D!$AV$8:$AV$2617,1)),"") | I10: =IFERROR(PERCENTRANK(HIST_D!$AV$8:INDEX(HIST_D!$AV$8:$AV$2617,Control!$F$14),INDEX(HIST_D!$AV$8:$AV$2617,1)),"") | J10: =IFERROR(PERCENTRANK(HIST_M!$J$8:$J$308,INDEX(HIST_D!$AV$8:$AV$2617,1)),"") | K10: =IFERROR((INDEX(HIST_D!$AV$8:$AV$2617,1)-AVERAGE(HIST_D!$AV$8:INDEX(HIST_D!$AV$8:$AV$2617,Control!$F$14)))/STDEV(HIST_D!$AV$8:INDEX(HIST_D!$AV$8:$AV$2617,Control!$F$14)),"")
A11: 5s30s | B11: =INDEX(HIST_D!$AY$8:$AY$2617,1) | C11: =IFERROR((INDEX(HIST_D!$AY$8:$AY$2617,1)-INDEX(HIST_D!$AY$8:$AY$2617,Control!$F$6))*1,"") | D11: =IFERROR((INDEX(HIST_D!$AY$8:$AY$2617,1)-INDEX(HIST_D!$AY$8:$AY$2617,Control!$F$7))*1,"") | E11: =IFERROR((INDEX(HIST_D!$AY$8:$AY$2617,1)-INDEX(HIST_D!$AY$8:$AY$2617,Control!$F$8))*1,"") | F11: =IFERROR((INDEX(HIST_D!$AY$8:$AY$2617,1)-INDEX(HIST_D!$AY$8:$AY$2617,Control!$F$16))*1,"") | G11: =IFERROR((INDEX(HIST_D!$AY$8:$AY$2617,1)-INDEX(HIST_D!$AY$8:$AY$2617,Control!$F$11))*1,"") | H11: =IFERROR(PERCENTRANK(HIST_D!$AY$8:INDEX(HIST_D!$AY$8:$AY$2617,Control!$F$11),INDEX(HIST_D!$AY$8:$AY$2617,1)),"") | I11: =IFERROR(PERCENTRANK(HIST_D!$AY$8:INDEX(HIST_D!$AY$8:$AY$2617,Control!$F$14),INDEX(HIST_D!$AY$8:$AY$2617,1)),"") | J11: =IFERROR(PERCENTRANK(HIST_M!$L$8:$L$308,INDEX(HIST_D!$AY$8:$AY$2617,1)),"") | K11: =IFERROR((INDEX(HIST_D!$AY$8:$AY$2617,1)-AVERAGE(HIST_D!$AY$8:INDEX(HIST_D!$AY$8:$AY$2617,Control!$F$14)))/STDEV(HIST_D!$AY$8:INDEX(HIST_D!$AY$8:$AY$2617,Control!$F$14)),"")
A12: 10Y real yield | B12: =INDEX(HIST_D!$X$8:$X$2617,1) | C12: =IFERROR((INDEX(HIST_D!$X$8:$X$2617,1)-INDEX(HIST_D!$X$8:$X$2617,Control!$F$6))*Control!$B$11,"") | D12: =IFERROR((INDEX(HIST_D!$X$8:$X$2617,1)-INDEX(HIST_D!$X$8:$X$2617,Control!$F$7))*Control!$B$11,"") | E12: =IFERROR((INDEX(HIST_D!$X$8:$X$2617,1)-INDEX(HIST_D!$X$8:$X$2617,Control!$F$8))*Control!$B$11,"") | F12: =IFERROR((INDEX(HIST_D!$X$8:$X$2617,1)-INDEX(HIST_D!$X$8:$X$2617,Control!$F$16))*Control!$B$11,"") | G12: =IFERROR((INDEX(HIST_D!$X$8:$X$2617,1)-INDEX(HIST_D!$X$8:$X$2617,Control!$F$11))*Control!$B$11,"") | H12: =IFERROR(PERCENTRANK(HIST_D!$X$8:INDEX(HIST_D!$X$8:$X$2617,Control!$F$11),INDEX(HIST_D!$X$8:$X$2617,1)),"") | I12: =IFERROR(PERCENTRANK(HIST_D!$X$8:INDEX(HIST_D!$X$8:$X$2617,Control!$F$14),INDEX(HIST_D!$X$8:$X$2617,1)),"") | K12: =IFERROR((INDEX(HIST_D!$X$8:$X$2617,1)-AVERAGE(HIST_D!$X$8:INDEX(HIST_D!$X$8:$X$2617,Control!$F$14)))/STDEV(HIST_D!$X$8:INDEX(HIST_D!$X$8:$X$2617,Control!$F$14)),"")
A13: 10Y breakeven | B13: =INDEX(HIST_D!$Z$8:$Z$2617,1) | C13: =IFERROR((INDEX(HIST_D!$Z$8:$Z$2617,1)-INDEX(HIST_D!$Z$8:$Z$2617,Control!$F$6))*Control!$B$11,"") | D13: =IFERROR((INDEX(HIST_D!$Z$8:$Z$2617,1)-INDEX(HIST_D!$Z$8:$Z$2617,Control!$F$7))*Control!$B$11,"") | E13: =IFERROR((INDEX(HIST_D!$Z$8:$Z$2617,1)-INDEX(HIST_D!$Z$8:$Z$2617,Control!$F$8))*Control!$B$11,"") | F13: =IFERROR((INDEX(HIST_D!$Z$8:$Z$2617,1)-INDEX(HIST_D!$Z$8:$Z$2617,Control!$F$16))*Control!$B$11,"") | G13: =IFERROR((INDEX(HIST_D!$Z$8:$Z$2617,1)-INDEX(HIST_D!$Z$8:$Z$2617,Control!$F$11))*Control!$B$11,"") | H13: =IFERROR(PERCENTRANK(HIST_D!$Z$8:INDEX(HIST_D!$Z$8:$Z$2617,Control!$F$11),INDEX(HIST_D!$Z$8:$Z$2617,1)),"") | I13: =IFERROR(PERCENTRANK(HIST_D!$Z$8:INDEX(HIST_D!$Z$8:$Z$2617,Control!$F$14),INDEX(HIST_D!$Z$8:$Z$2617,1)),"") | K13: =IFERROR((INDEX(HIST_D!$Z$8:$Z$2617,1)-AVERAGE(HIST_D!$Z$8:INDEX(HIST_D!$Z$8:$Z$2617,Control!$F$14)))/STDEV(HIST_D!$Z$8:INDEX(HIST_D!$Z$8:$Z$2617,Control!$F$14)),"")
A14: MOVE | B14: =INDEX(HIST_D!$AB$8:$AB$2617,1) | C14: =IFERROR((INDEX(HIST_D!$AB$8:$AB$2617,1)-INDEX(HIST_D!$AB$8:$AB$2617,Control!$F$6))*1,"") | D14: =IFERROR((INDEX(HIST_D!$AB$8:$AB$2617,1)-INDEX(HIST_D!$AB$8:$AB$2617,Control!$F$7))*1,"") | E14: =IFERROR((INDEX(HIST_D!$AB$8:$AB$2617,1)-INDEX(HIST_D!$AB$8:$AB$2617,Control!$F$8))*1,"") | F14: =IFERROR((INDEX(HIST_D!$AB$8:$AB$2617,1)-INDEX(HIST_D!$AB$8:$AB$2617,Control!$F$16))*1,"") | G14: =IFERROR((INDEX(HIST_D!$AB$8:$AB$2617,1)-INDEX(HIST_D!$AB$8:$AB$2617,Control!$F$11))*1,"") | H14: =IFERROR(PERCENTRANK(HIST_D!$AB$8:INDEX(HIST_D!$AB$8:$AB$2617,Control!$F$11),INDEX(HIST_D!$AB$8:$AB$2617,1)),"") | I14: =IFERROR(PERCENTRANK(HIST_D!$AB$8:INDEX(HIST_D!$AB$8:$AB$2617,Control!$F$14),INDEX(HIST_D!$AB$8:$AB$2617,1)),"") | J14: =IFERROR(PERCENTRANK(HIST_M!$I$8:$I$308,INDEX(HIST_D!$AB$8:$AB$2617,1)),"") | K14: =IFERROR((INDEX(HIST_D!$AB$8:$AB$2617,1)-AVERAGE(HIST_D!$AB$8:INDEX(HIST_D!$AB$8:$AB$2617,Control!$F$14)))/STDEV(HIST_D!$AB$8:INDEX(HIST_D!$AB$8:$AB$2617,Control!$F$14)),"")
A16: POLICY
B17: Value | C17: Unit | D17: Note
A18: Spot EFFR | B18: =Policy!$F$9 | C18: % | D18: live
A19: Market terminal (strip trough) | B19: =Policy!$E$36 | C19: % | D19: lowest implied month-average on the FF strip
A20: Cuts priced to the trough | B20: =Policy!$G$36 | C20: # of 25bp
A21: Cuts priced 12m out | B21: =Policy!$G$28 | C21: # of 25bp | D21: FF12 contract vs spot EFFR
A22: OIS 1y1y | B22: =IFERROR(((1+INDEX(HIST_D!$N$8:$N$2617,1)/100)^2/(1+INDEX(HIST_D!$M$8:$M$2617,1)/100))*100-100,"") | C22: % | D22: policy 12–24m out
A23: OIS 5y5y | B23: =IFERROR(((1+INDEX(HIST_D!$S$8:$S$2617,1)/100)^10/(1+INDEX(HIST_D!$Q$8:$Q$2617,1)/100)^5)^(1/5)*100-100,"") | C23: % | D23: long-run anchor
A25: FUNDING & LIQUIDITY
B26: Value | C26: Unit | D26: Status | E26: Note
A27: SOFR − IORB | B27: =Liquidity!$B$44 | C27: bp | D27: =IF($B27>5,"TIGHT","OK") | E27: the scarcity tell
A28: ON RRP volume | B28: =INDEX(HIST_D!$AP$8:$AP$2617,1) | C28: $bn | D28: =IF($B28<50,"BUFFER GONE","OK") | E28: below ~$50bn every drain hits reserves
A29: MOVE percentile (3y) | B29: =IFERROR(PERCENTRANK(HIST_D!$AB$8:INDEX(HIST_D!$AB$8:$AB$2617,Control!$F$13),INDEX(HIST_D!$AB$8:$AB$2617,1)),"") | C29: %ile | D29: =IF($B29>0.8,"STRESSED","OK") | E29: the transmission channel into EM
A30: Swap spread 10Y | B30: =INDEX(HIST_D!$BE$8:$BE$2617,1) | C30: bp | D30: =IF(IFERROR((INDEX(HIST_D!$BE$8:$BE$2617,1)-AVERAGE(HIST_D!$BE$8:INDEX(HIST_D!$BE$8:$BE$2617,Control!$F$14)))/STDEV(HIST_D!$BE$8:INDEX(HIST_D!$BE$8:$BE$2617,Control!$F$14)),"")<-1.5,"BALANCE SHEET SCARCE","OK") | E30: dealer capacity
A32: CREDIT
B33: Level | C33: 1D | D33: 1W | E33: 1M | F33: YTD | G33: 1Y | H33: %ile 1y | I33: %ile 5y | J33: %ile 25y | K33: z (5y) | L33: Note
A34: US IG OAS | B34: =INDEX(HIST_D!$AF$8:$AF$2617,1) | C34: =IFERROR((INDEX(HIST_D!$AF$8:$AF$2617,1)-INDEX(HIST_D!$AF$8:$AF$2617,Control!$F$6))*1,"") | D34: =IFERROR((INDEX(HIST_D!$AF$8:$AF$2617,1)-INDEX(HIST_D!$AF$8:$AF$2617,Control!$F$7))*1,"") | E34: =IFERROR((INDEX(HIST_D!$AF$8:$AF$2617,1)-INDEX(HIST_D!$AF$8:$AF$2617,Control!$F$8))*1,"") | F34: =IFERROR((INDEX(HIST_D!$AF$8:$AF$2617,1)-INDEX(HIST_D!$AF$8:$AF$2617,Control!$F$16))*1,"") | G34: =IFERROR((INDEX(HIST_D!$AF$8:$AF$2617,1)-INDEX(HIST_D!$AF$8:$AF$2617,Control!$F$11))*1,"") | H34: =IFERROR(PERCENTRANK(HIST_D!$AF$8:INDEX(HIST_D!$AF$8:$AF$2617,Control!$F$11),INDEX(HIST_D!$AF$8:$AF$2617,1)),"") | I34: =IFERROR(PERCENTRANK(HIST_D!$AF$8:INDEX(HIST_D!$AF$8:$AF$2617,Control!$F$14),INDEX(HIST_D!$AF$8:$AF$2617,1)),"") | J34: =IFERROR(PERCENTRANK(HIST_M!$F$8:$F$308,INDEX(HIST_D!$AF$8:$AF$2617,1)),"") | K34: =IFERROR((INDEX(HIST_D!$AF$8:$AF$2617,1)-AVERAGE(HIST_D!$AF$8:INDEX(HIST_D!$AF$8:$AF$2617,Control!$F$14)))/STDEV(HIST_D!$AF$8:INDEX(HIST_D!$AF$8:$AF$2617,Control!$F$14)),"")
A35: US HY OAS | B35: =INDEX(HIST_D!$AG$8:$AG$2617,1) | C35: =IFERROR((INDEX(HIST_D!$AG$8:$AG$2617,1)-INDEX(HIST_D!$AG$8:$AG$2617,Control!$F$6))*1,"") | D35: =IFERROR((INDEX(HIST_D!$AG$8:$AG$2617,1)-INDEX(HIST_D!$AG$8:$AG$2617,Control!$F$7))*1,"") | E35: =IFERROR((INDEX(HIST_D!$AG$8:$AG$2617,1)-INDEX(HIST_D!$AG$8:$AG$2617,Control!$F$8))*1,"") | F35: =IFERROR((INDEX(HIST_D!$AG$8:$AG$2617,1)-INDEX(HIST_D!$AG$8:$AG$2617,Control!$F$16))*1,"") | G35: =IFERROR((INDEX(HIST_D!$AG$8:$AG$2617,1)-INDEX(HIST_D!$AG$8:$AG$2617,Control!$F$11))*1,"") | H35: =IFERROR(PERCENTRANK(HIST_D!$AG$8:INDEX(HIST_D!$AG$8:$AG$2617,Control!$F$11),INDEX(HIST_D!$AG$8:$AG$2617,1)),"") | I35: =IFERROR(PERCENTRANK(HIST_D!$AG$8:INDEX(HIST_D!$AG$8:$AG$2617,Control!$F$14),INDEX(HIST_D!$AG$8:$AG$2617,1)),"") | J35: =IFERROR(PERCENTRANK(HIST_M!$G$8:$G$308,INDEX(HIST_D!$AG$8:$AG$2617,1)),"") | K35: =IFERROR((INDEX(HIST_D!$AG$8:$AG$2617,1)-AVERAGE(HIST_D!$AG$8:INDEX(HIST_D!$AG$8:$AG$2617,Control!$F$14)))/STDEV(HIST_D!$AG$8:INDEX(HIST_D!$AG$8:$AG$2617,Control!$F$14)),"")
A36: HY − IG | B36: =INDEX(HIST_D!$BG$8:$BG$2617,1) | C36: =IFERROR((INDEX(HIST_D!$BG$8:$BG$2617,1)-INDEX(HIST_D!$BG$8:$BG$2617,Control!$F$6))*1,"") | D36: =IFERROR((INDEX(HIST_D!$BG$8:$BG$2617,1)-INDEX(HIST_D!$BG$8:$BG$2617,Control!$F$7))*1,"") | E36: =IFERROR((INDEX(HIST_D!$BG$8:$BG$2617,1)-INDEX(HIST_D!$BG$8:$BG$2617,Control!$F$8))*1,"") | F36: =IFERROR((INDEX(HIST_D!$BG$8:$BG$2617,1)-INDEX(HIST_D!$BG$8:$BG$2617,Control!$F$16))*1,"") | G36: =IFERROR((INDEX(HIST_D!$BG$8:$BG$2617,1)-INDEX(HIST_D!$BG$8:$BG$2617,Control!$F$11))*1,"") | H36: =IFERROR(PERCENTRANK(HIST_D!$BG$8:INDEX(HIST_D!$BG$8:$BG$2617,Control!$F$11),INDEX(HIST_D!$BG$8:$BG$2617,1)),"") | I36: =IFERROR(PERCENTRANK(HIST_D!$BG$8:INDEX(HIST_D!$BG$8:$BG$2617,Control!$F$14),INDEX(HIST_D!$BG$8:$BG$2617,1)),"") | J36: =IFERROR(PERCENTRANK(HIST_M!$N$8:$N$308,INDEX(HIST_D!$BG$8:$BG$2617,1)),"") | K36: =IFERROR((INDEX(HIST_D!$BG$8:$BG$2617,1)-AVERAGE(HIST_D!$BG$8:INDEX(HIST_D!$BG$8:$BG$2617,Control!$F$14)))/STDEV(HIST_D!$BG$8:INDEX(HIST_D!$BG$8:$BG$2617,Control!$F$14)),"")
A37: HY / IG | B37: =INDEX(HIST_D!$BH$8:$BH$2617,1) | C37: =IFERROR((INDEX(HIST_D!$BH$8:$BH$2617,1)-INDEX(HIST_D!$BH$8:$BH$2617,Control!$F$6))*1,"") | D37: =IFERROR((INDEX(HIST_D!$BH$8:$BH$2617,1)-INDEX(HIST_D!$BH$8:$BH$2617,Control!$F$7))*1,"") | E37: =IFERROR((INDEX(HIST_D!$BH$8:$BH$2617,1)-INDEX(HIST_D!$BH$8:$BH$2617,Control!$F$8))*1,"") | F37: =IFERROR((INDEX(HIST_D!$BH$8:$BH$2617,1)-INDEX(HIST_D!$BH$8:$BH$2617,Control!$F$16))*1,"") | G37: =IFERROR((INDEX(HIST_D!$BH$8:$BH$2617,1)-INDEX(HIST_D!$BH$8:$BH$2617,Control!$F$11))*1,"") | H37: =IFERROR(PERCENTRANK(HIST_D!$BH$8:INDEX(HIST_D!$BH$8:$BH$2617,Control!$F$11),INDEX(HIST_D!$BH$8:$BH$2617,1)),"") | I37: =IFERROR(PERCENTRANK(HIST_D!$BH$8:INDEX(HIST_D!$BH$8:$BH$2617,Control!$F$14),INDEX(HIST_D!$BH$8:$BH$2617,1)),"") | J37: =IFERROR(PERCENTRANK(HIST_M!$O$8:$O$308,INDEX(HIST_D!$BH$8:$BH$2617,1)),"") | K37: =IFERROR((INDEX(HIST_D!$BH$8:$BH$2617,1)-AVERAGE(HIST_D!$BH$8:INDEX(HIST_D!$BH$8:$BH$2617,Control!$F$14)))/STDEV(HIST_D!$BH$8:INDEX(HIST_D!$BH$8:$BH$2617,Control!$F$14)),"")
B39: 12m TR, ceteris paribus | C39: vs cash hurdle | D39: bp widening to break even | E39: bp to the 5y median
A40: US IG | B40: =Credit_TR!$B$19 | C40: =Credit_TR!$B$19-Control!$B$13/100 | D40: =Credit_TR!$B$21 | E40: =IFERROR(PERCENTILE(HIST_D!$AF$8:INDEX(HIST_D!$AF$8:$AF$2617,Control!$F$14),0.5)-INDEX(HIST_D!$AF$8:$AF$2617,1),"")
A41: US HY | B41: =Credit_TR!$C$19 | C41: =Credit_TR!$C$19-Control!$B$13/100 | D41: =Credit_TR!$C$21 | E41: =IFERROR(PERCENTILE(HIST_D!$AG$8:INDEX(HIST_D!$AG$8:$AG$2617,Control!$F$14),0.5)-INDEX(HIST_D!$AG$8:$AG$2617,1),"")
A42: EM USD Agg | B42: =Credit_TR!$D$19 | C42: =Credit_TR!$D$19-Control!$B$13/100 | D42: =Credit_TR!$D$21 | E42: =IFERROR(PERCENTILE(HIST_D!$AJ$8:INDEX(HIST_D!$AJ$8:$AJ$2617,Control!$F$14),0.5)-INDEX(HIST_D!$AJ$8:$AJ$2617,1),"")
A43: Breakeven column is on Credit_TR; the widening-to-median column says how far a normalisation would actually be.
A45: EM READ-THROUGH
B46: Value | C46: Unit | D46: Note
...

Sheet Curve
A1: US TREASURY CURVE — every node
A2: Levels, changes, distribution and carry/roll economics for each node. Changes in bp. Percentiles: 0% = lowest yield in the window, 100% = highest.
A4: US TREASURY PAR YIELDS
A5: Instrument | B5: Source | C5: Unit | D5: Level | E5: 1D | F5: 1W | G5: 1M | H5: 3M | I5: 6M | J5: YTD | K5: 1Y | L5: 1y min | M5: 1y max | N5: %ile 1y | O5: %ile 3y | P5: %ile 5y | Q5: %ile 10y | R5: %ile 25y | S5: z (5y) | T5: Yrs | U5: y at n−1yr | V5: Roll-down | W5: Mod dur | X5: DV01 $/1mm | Y5: 12m TR @ unch curve | Z5: B/E yield rise
A6: UST 1M | B6: =Tickers!$C$6 | C6: % | D6: =INDEX(HIST_D!$B$8:$B$2617,1) | E6: =IFERROR((INDEX(HIST_D!$B$8:$B$2617,1)-INDEX(HIST_D!$B$8:$B$2617,Control!$F$6))*Control!$B$11,"") | F6: =IFERROR((INDEX(HIST_D!$B$8:$B$2617,1)-INDEX(HIST_D!$B$8:$B$2617,Control!$F$7))*Control!$B$11,"") | G6: =IFERROR((INDEX(HIST_D!$B$8:$B$2617,1)-INDEX(HIST_D!$B$8:$B$2617,Control!$F$8))*Control!$B$11,"") | H6: =IFERROR((INDEX(HIST_D!$B$8:$B$2617,1)-INDEX(HIST_D!$B$8:$B$2617,Control!$F$9))*Control!$B$11,"") | I6: =IFERROR((INDEX(HIST_D!$B$8:$B$2617,1)-INDEX(HIST_D!$B$8:$B$2617,Control!$F$10))*Control!$B$11,"") | J6: =IFERROR((INDEX(HIST_D!$B$8:$B$2617,1)-INDEX(HIST_D!$B$8:$B$2617,Control!$F$16))*Control!$B$11,"") | K6: =IFERROR((INDEX(HIST_D!$B$8:$B$2617,1)-INDEX(HIST_D!$B$8:$B$2617,Control!$F$11))*Control!$B$11,"") | L6: =IFERROR(MIN(HIST_D!$B$8:INDEX(HIST_D!$B$8:$B$2617,Control!$F$11)),"") | M6: =IFERROR(MAX(HIST_D!$B$8:INDEX(HIST_D!$B$8:$B$2617,Control!$F$11)),"") | N6: =IFERROR(PERCENTRANK(HIST_D!$B$8:INDEX(HIST_D!$B$8:$B$2617,Control!$F$11),INDEX(HIST_D!$B$8:$B$2617,1)),"") | O6: =IFERROR(PERCENTRANK(HIST_D!$B$8:INDEX(HIST_D!$B$8:$B$2617,Control!$F$13),INDEX(HIST_D!$B$8:$B$2617,1)),"") | P6: =IFERROR(PERCENTRANK(HIST_D!$B$8:INDEX(HIST_D!$B$8:$B$2617,Control!$F$14),INDEX(HIST_D!$B$8:$B$2617,1)),"") | Q6: =IFERROR(PERCENTRANK(HIST_D!$B$8:INDEX(HIST_D!$B$8:$B$2617,Control!$F$15),INDEX(HIST_D!$B$8:$B$2617,1)),"") | S6: =IFERROR((INDEX(HIST_D!$B$8:$B$2617,1)-AVERAGE(HIST_D!$B$8:INDEX(HIST_D!$B$8:$B$2617,Control!$F$14)))/STDEV(HIST_D!$B$8:INDEX(HIST_D!$B$8:$B$2617,Control!$F$14)),"") | T6: 0.083333333 | U6: =IF(MAX($T6-Control!$B$12,0.0833)<=INDEX($T$6:$T$18,1),INDEX($D$6:$D$18,1),IF(MAX($T6-Control!$B$12,0.0833)>=INDEX($T$6:$T$18,COUNT($T$6:$T$18)),INDEX($D$6:$D$18,COUNT($T$6:$T$18)),INDEX($D$6:$D$18,MATCH(MAX($T6-Control!$B$12,0.0833),$T$6:$T$18,1))+(MAX($T6-Control!$B$12,0.0833)-INDEX($T$6:$T$18,MATCH(MAX($T6-Control!$B$12,0.0833),$T$6:$T$18,1)))/(INDEX($T$6:$T$18,MATCH(MAX($T6-Control!$B$12,0.0833),$T$6:$T$18,1)+1)-INDEX($T$6:$T$18,MATCH(MAX($T6-Control!$B$12,0.0833),$T$6:$T$18,1)))*(INDEX($D$6:$D$18,MATCH(MAX($T6-Control!$B$12,0.0833),$T$6:$T$18,1)+1)-INDEX($D$6:$D$18,MATCH(MAX($T6-Control!$B$12,0.0833),$T$6:$T$18,1))))) | V6: =IF($T6<=Control!$B$12,"",($D6-$U6)*Control!$B$11) | W6: =IFERROR((1-(1+$D6/100/Control!$B$14)^(-Control!$B$14*($T6)))/($D6/100/Control!$B$14)/Control!$B$14,"") | X6: =IFERROR($W6*100*1000000/10000,"") | Y6: =IF($T6<=Control!$B$12,$D6*Control!$B$12/100,IFERROR((IFERROR(($D6/Control!$B$14)*(1-(1+$U6/100/Control!$B$14)^(-Control!$B$14*($T6-Control!$B$12)))/($U6/100/Control!$B$14)+100*(1+$U6/100/Control!$B$14)^(-Control!$B$14*($T6-Control!$B$12)),"")+$D6*Control!$B$12-100)/100,"")) | Z6: =IF($T6<=Control!$B$12,"n/a",IFERROR($Y6*100/IFERROR((1-(1+$U6/100/Control!$B$14)^(-Control!$B$14*($T6-Control!$B$12)))/($U6/100/Control!$B$14)/Control!$B$14,"")*Control!$B$11,""))
A7: UST 3M | B7: =Tickers!$C$7 | C7: % | D7: =INDEX(HIST_D!$C$8:$C$2617,1) | E7: =IFERROR((INDEX(HIST_D!$C$8:$C$2617,1)-INDEX(HIST_D!$C$8:$C$2617,Control!$F$6))*Control!$B$11,"") | F7: =IFERROR((INDEX(HIST_D!$C$8:$C$2617,1)-INDEX(HIST_D!$C$8:$C$2617,Control!$F$7))*Control!$B$11,"") | G7: =IFERROR((INDEX(HIST_D!$C$8:$C$2617,1)-INDEX(HIST_D!$C$8:$C$2617,Control!$F$8))*Control!$B$11,"") | H7: =IFERROR((INDEX(HIST_D!$C$8:$C$2617,1)-INDEX(HIST_D!$C$8:$C$2617,Control!$F$9))*Control!$B$11,"") | I7: =IFERROR((INDEX(HIST_D!$C$8:$C$2617,1)-INDEX(HIST_D!$C$8:$C$2617,Control!$F$10))*Control!$B$11,"") | J7: =IFERROR((INDEX(HIST_D!$C$8:$C$2617,1)-INDEX(HIST_D!$C$8:$C$2617,Control!$F$16))*Control!$B$11,"") | K7: =IFERROR((INDEX(HIST_D!$C$8:$C$2617,1)-INDEX(HIST_D!$C$8:$C$2617,Control!$F$11))*Control!$B$11,"") | L7: =IFERROR(MIN(HIST_D!$C$8:INDEX(HIST_D!$C$8:$C$2617,Control!$F$11)),"") | M7: =IFERROR(MAX(HIST_D!$C$8:INDEX(HIST_D!$C$8:$C$2617,Control!$F$11)),"") | N7: =IFERROR(PERCENTRANK(HIST_D!$C$8:INDEX(HIST_D!$C$8:$C$2617,Control!$F$11),INDEX(HIST_D!$C$8:$C$2617,1)),"") | O7: =IFERROR(PERCENTRANK(HIST_D!$C$8:INDEX(HIST_D!$C$8:$C$2617,Control!$F$13),INDEX(HIST_D!$C$8:$C$2617,1)),"") | P7: =IFERROR(PERCENTRANK(HIST_D!$C$8:INDEX(HIST_D!$C$8:$C$2617,Control!$F$14),INDEX(HIST_D!$C$8:$C$2617,1)),"") | Q7: =IFERROR(PERCENTRANK(HIST_D!$C$8:INDEX(HIST_D!$C$8:$C$2617,Control!$F$15),INDEX(HIST_D!$C$8:$C$2617,1)),"") | S7: =IFERROR((INDEX(HIST_D!$C$8:$C$2617,1)-AVERAGE(HIST_D!$C$8:INDEX(HIST_D!$C$8:$C$2617,Control!$F$14)))/STDEV(HIST_D!$C$8:INDEX(HIST_D!$C$8:$C$2617,Control!$F$14)),"") | T7: 0.25 | U7: =IF(MAX($T7-Control!$B$12,0.0833)<=INDEX($T$6:$T$18,1),INDEX($D$6:$D$18,1),IF(MAX($T7-Control!$B$12,0.0833)>=INDEX($T$6:$T$18,COUNT($T$6:$T$18)),INDEX($D$6:$D$18,COUNT($T$6:$T$18)),INDEX($D$6:$D$18,MATCH(MAX($T7-Control!$B$12,0.0833),$T$6:$T$18,1))+(MAX($T7-Control!$B$12,0.0833)-INDEX($T$6:$T$18,MATCH(MAX($T7-Control!$B$12,0.0833),$T$6:$T$18,1)))/(INDEX($T$6:$T$18,MATCH(MAX($T7-Control!$B$12,0.0833),$T$6:$T$18,1)+1)-INDEX($T$6:$T$18,MATCH(MAX($T7-Control!$B$12,0.0833),$T$6:$T$18,1)))*(INDEX($D$6:$D$18,MATCH(MAX($T7-Control!$B$12,0.0833),$T$6:$T$18,1)+1)-INDEX($D$6:$D$18,MATCH(MAX($T7-Control!$B$12,0.0833),$T$6:$T$18,1))))) | V7: =IF($T7<=Control!$B$12,"",($D7-$U7)*Control!$B$11) | W7: =IFERROR((1-(1+$D7/100/Control!$B$14)^(-Control!$B$14*($T7)))/($D7/100/Control!$B$14)/Control!$B$14,"") | X7: =IFERROR($W7*100*1000000/10000,"") | Y7: =IF($T7<=Control!$B$12,$D7*Control!$B$12/100,IFERROR((IFERROR(($D7/Control!$B$14)*(1-(1+$U7/100/Control!$B$14)^(-Control!$B$14*($T7-Control!$B$12)))/($U7/100/Control!$B$14)+100*(1+$U7/100/Control!$B$14)^(-Control!$B$14*($T7-Control!$B$12)),"")+$D7*Control!$B$12-100)/100,"")) | Z7: =IF($T7<=Control!$B$12,"n/a",IFERROR($Y7*100/IFERROR((1-(1+$U7/100/Control!$B$14)^(-Control!$B$14*($T7-Control!$B$12)))/($U7/100/Control!$B$14)/Control!$B$14,"")*Control!$B$11,""))
A8: UST 6M | B8: =Tickers!$C$8 | C8: % | D8: =INDEX(HIST_D!$D$8:$D$2617,1) | E8: =IFERROR((INDEX(HIST_D!$D$8:$D$2617,1)-INDEX(HIST_D!$D$8:$D$2617,Control!$F$6))*Control!$B$11,"") | F8: =IFERROR((INDEX(HIST_D!$D$8:$D$2617,1)-INDEX(HIST_D!$D$8:$D$2617,Control!$F$7))*Control!$B$11,"") | G8: =IFERROR((INDEX(HIST_D!$D$8:$D$2617,1)-INDEX(HIST_D!$D$8:$D$2617,Control!$F$8))*Control!$B$11,"") | H8: =IFERROR((INDEX(HIST_D!$D$8:$D$2617,1)-INDEX(HIST_D!$D$8:$D$2617,Control!$F$9))*Control!$B$11,"") | I8: =IFERROR((INDEX(HIST_D!$D$8:$D$2617,1)-INDEX(HIST_D!$D$8:$D$2617,Control!$F$10))*Control!$B$11,"") | J8: =IFERROR((INDEX(HIST_D!$D$8:$D$2617,1)-INDEX(HIST_D!$D$8:$D$2617,Control!$F$16))*Control!$B$11,"") | K8: =IFERROR((INDEX(HIST_D!$D$8:$D$2617,1)-INDEX(HIST_D!$D$8:$D$2617,Control!$F$11))*Control!$B$11,"") | L8: =IFERROR(MIN(HIST_D!$D$8:INDEX(HIST_D!$D$8:$D$2617,Control!$F$11)),"") | M8: =IFERROR(MAX(HIST_D!$D$8:INDEX(HIST_D!$D$8:$D$2617,Control!$F$11)),"") | N8: =IFERROR(PERCENTRANK(HIST_D!$D$8:INDEX(HIST_D!$D$8:$D$2617,Control!$F$11),INDEX(HIST_D!$D$8:$D$2617,1)),"") | O8: =IFERROR(PERCENTRANK(HIST_D!$D$8:INDEX(HIST_D!$D$8:$D$2617,Control!$F$13),INDEX(HIST_D!$D$8:$D$2617,1)),"") | P8: =IFERROR(PERCENTRANK(HIST_D!$D$8:INDEX(HIST_D!$D$8:$D$2617,Control!$F$14),INDEX(HIST_D!$D$8:$D$2617,1)),"") | Q8: =IFERROR(PERCENTRANK(HIST_D!$D$8:INDEX(HIST_D!$D$8:$D$2617,Control!$F$15),INDEX(HIST_D!$D$8:$D$2617,1)),"") | S8: =IFERROR((INDEX(HIST_D!$D$8:$D$2617,1)-AVERAGE(HIST_D!$D$8:INDEX(HIST_D!$D$8:$D$2617,Control!$F$14)))/STDEV(HIST_D!$D$8:INDEX(HIST_D!$D$8:$D$2617,Control!$F$14)),"") | T8: 0.5 | U8: =IF(MAX($T8-Control!$B$12,0.0833)<=INDEX($T$6:$T$18,1),INDEX($D$6:$D$18,1),IF(MAX($T8-Control!$B$12,0.0833)>=INDEX($T$6:$T$18,COUNT($T$6:$T$18)),INDEX($D$6:$D$18,COUNT($T$6:$T$18)),INDEX($D$6:$D$18,MATCH(MAX($T8-Control!$B$12,0.0833),$T$6:$T$18,1))+(MAX($T8-Control!$B$12,0.0833)-INDEX($T$6:$T$18,MATCH(MAX($T8-Control!$B$12,0.0833),$T$6:$T$18,1)))/(INDEX($T$6:$T$18,MATCH(MAX($T8-Control!$B$12,0.0833),$T$6:$T$18,1)+1)-INDEX($T$6:$T$18,MATCH(MAX($T8-Control!$B$12,0.0833),$T$6:$T$18,1)))*(INDEX($D$6:$D$18,MATCH(MAX($T8-Control!$B$12,0.0833),$T$6:$T$18,1)+1)-INDEX($D$6:$D$18,MATCH(MAX($T8-Control!$B$12,0.0833),$T$6:$T$18,1))))) | V8: =IF($T8<=Control!$B$12,"",($D8-$U8)*Control!$B$11) | W8: =IFERROR((1-(1+$D8/100/Control!$B$14)^(-Control!$B$14*($T8)))/($D8/100/Control!$B$14)/Control!$B$14,"") | X8: =IFERROR($W8*100*1000000/10000,"") | Y8: =IF($T8<=Control!$B$12,$D8*Control!$B$12/100,IFERROR((IFERROR(($D8/Control!$B$14)*(1-(1+$U8/100/Control!$B$14)^(-Control!$B$14*($T8-Control!$B$12)))/($U8/100/Control!$B$14)+100*(1+$U8/100/Control!$B$14)^(-Control!$B$14*($T8-Control!$B$12)),"")+$D8*Control!$B$12-100)/100,"")) | Z8: =IF($T8<=Control!$B$12,"n/a",IFERROR($Y8*100/IFERROR((1-(1+$U8/100/Control!$B$14)^(-Control!$B$14*($T8-Control!$B$12)))/($U8/100/Control!$B$14)/Control!$B$14,"")*Control!$B$11,""))
A9: UST 1Y | B9: =Tickers!$C$9 | C9: % | D9: =INDEX(HIST_D!$E$8:$E$2617,1) | E9: =IFERROR((INDEX(HIST_D!$E$8:$E$2617,1)-INDEX(HIST_D!$E$8:$E$2617,Control!$F$6))*Control!$B$11,"") | F9: =IFERROR((INDEX(HIST_D!$E$8:$E$2617,1)-INDEX(HIST_D!$E$8:$E$2617,Control!$F$7))*Control!$B$11,"") | G9: =IFERROR((INDEX(HIST_D!$E$8:$E$2617,1)-INDEX(HIST_D!$E$8:$E$2617,Control!$F$8))*Control!$B$11,"") | H9: =IFERROR((INDEX(HIST_D!$E$8:$E$2617,1)-INDEX(HIST_D!$E$8:$E$2617,Control!$F$9))*Control!$B$11,"") | I9: =IFERROR((INDEX(HIST_D!$E$8:$E$2617,1)-INDEX(HIST_D!$E$8:$E$2617,Control!$F$10))*Control!$B$11,"") | J9: =IFERROR((INDEX(HIST_D!$E$8:$E$2617,1)-INDEX(HIST_D!$E$8:$E$2617,Control!$F$16))*Control!$B$11,"") | K9: =IFERROR((INDEX(HIST_D!$E$8:$E$2617,1)-INDEX(HIST_D!$E$8:$E$2617,Control!$F$11))*Control!$B$11,"") | L9: =IFERROR(MIN(HIST_D!$E$8:INDEX(HIST_D!$E$8:$E$2617,Control!$F$11)),"") | M9: =IFERROR(MAX(HIST_D!$E$8:INDEX(HIST_D!$E$8:$E$2617,Control!$F$11)),"") | N9: =IFERROR(PERCENTRANK(HIST_D!$E$8:INDEX(HIST_D!$E$8:$E$2617,Control!$F$11),INDEX(HIST_D!$E$8:$E$2617,1)),"") | O9: =IFERROR(PERCENTRANK(HIST_D!$E$8:INDEX(HIST_D!$E$8:$E$2617,Control!$F$13),INDEX(HIST_D!$E$8:$E$2617,1)),"") | P9: =IFERROR(PERCENTRANK(HIST_D!$E$8:INDEX(HIST_D!$E$8:$E$2617,Control!$F$14),INDEX(HIST_D!$E$8:$E$2617,1)),"") | Q9: =IFERROR(PERCENTRANK(HIST_D!$E$8:INDEX(HIST_D!$E$8:$E$2617,Control!$F$15),INDEX(HIST_D!$E$8:$E$2617,1)),"") | S9: =IFERROR((INDEX(HIST_D!$E$8:$E$2617,1)-AVERAGE(HIST_D!$E$8:INDEX(HIST_D!$E$8:$E$2617,Control!$F$14)))/STDEV(HIST_D!$E$8:INDEX(HIST_D!$E$8:$E$2617,Control!$F$14)),"") | T9: 1 | U9: =IF(MAX($T9-Control!$B$12,0.0833)<=INDEX($T$6:$T$18,1),INDEX($D$6:$D$18,1),IF(MAX($T9-Control!$B$12,0.0833)>=INDEX($T$6:$T$18,COUNT($T$6:$T$18)),INDEX($D$6:$D$18,COUNT($T$6:$T$18)),INDEX($D$6:$D$18,MATCH(MAX($T9-Control!$B$12,0.0833),$T$6:$T$18,1))+(MAX($T9-Control!$B$12,0.0833)-INDEX($T$6:$T$18,MATCH(MAX($T9-Control!$B$12,0.0833),$T$6:$T$18,1)))/(INDEX($T$6:$T$18,MATCH(MAX($T9-Control!$B$12,0.0833),$T$6:$T$18,1)+1)-INDEX($T$6:$T$18,MATCH(MAX($T9-Control!$B$12,0.0833),$T$6:$T$18,1)))*(INDEX($D$6:$D$18,MATCH(MAX($T9-Control!$B$12,0.0833),$T$6:$T$18,1)+1)-INDEX($D$6:$D$18,MATCH(MAX($T9-Control!$B$12,0.0833),$T$6:$T$18,1))))) | V9: =IF($T9<=Control!$B$12,"",($D9-$U9)*Control!$B$11) | W9: =IFERROR((1-(1+$D9/100/Control!$B$14)^(-Control!$B$14*($T9)))/($D9/100/Control!$B$14)/Control!$B$14,"") | X9: =IFERROR($W9*100*1000000/10000,"") | Y9: =IF($T9<=Control!$B$12,$D9*Control!$B$12/100,IFERROR((IFERROR(($D9/Control!$B$14)*(1-(1+$U9/100/Control!$B$14)^(-Control!$B$14*($T9-Control!$B$12)))/($U9/100/Control!$B$14)+100*(1+$U9/100/Control!$B$14)^(-Control!$B$14*($T9-Control!$B$12)),"")+$D9*Control!$B$12-100)/100,"")) | Z9: =IF($T9<=Control!$B$12,"n/a",IFERROR($Y9*100/IFERROR((1-(1+$U9/100/Control!$B$14)^(-Control!$B$14*($T9-Control!$B$12)))/($U9/100/Control!$B$14)/Control!$B$14,"")*Control!$B$11,""))
A10: UST 2Y | B10: =Tickers!$C$10 | C10: % | D10: =INDEX(HIST_D!$F$8:$F$2617,1) | E10: =IFERROR((INDEX(HIST_D!$F$8:$F$2617,1)-INDEX(HIST_D!$F$8:$F$2617,Control!$F$6))*Control!$B$11,"") | F10: =IFERROR((INDEX(HIST_D!$F$8:$F$2617,1)-INDEX(HIST_D!$F$8:$F$2617,Control!$F$7))*Control!$B$11,"") | G10: =IFERROR((INDEX(HIST_D!$F$8:$F$2617,1)-INDEX(HIST_D!$F$8:$F$2617,Control!$F$8))*Control!$B$11,"") | H10: =IFERROR((INDEX(HIST_D!$F$8:$F$2617,1)-INDEX(HIST_D!$F$8:$F$2617,Control!$F$9))*Control!$B$11,"") | I10: =IFERROR((INDEX(HIST_D!$F$8:$F$2617,1)-INDEX(HIST_D!$F$8:$F$2617,Control!$F$10))*Control!$B$11,"") | J10: =IFERROR((INDEX(HIST_D!$F$8:$F$2617,1)-INDEX(HIST_D!$F$8:$F$2617,Control!$F$16))*Control!$B$11,"") | K10: =IFERROR((INDEX(HIST_D!$F$8:$F$2617,1)-INDEX(HIST_D!$F$8:$F$2617,Control!$F$11))*Control!$B$11,"") | L10: =IFERROR(MIN(HIST_D!$F$8:INDEX(HIST_D!$F$8:$F$2617,Control!$F$11)),"") | M10: =IFERROR(MAX(HIST_D!$F$8:INDEX(HIST_D!$F$8:$F$2617,Control!$F$11)),"") | N10: =IFERROR(PERCENTRANK(HIST_D!$F$8:INDEX(HIST_D!$F$8:$F$2617,Control!$F$11),INDEX(HIST_D!$F$8:$F$2617,1)),"") | O10: =IFERROR(PERCENTRANK(HIST_D!$F$8:INDEX(HIST_D!$F$8:$F$2617,Control!$F$13),INDEX(HIST_D!$F$8:$F$2617,1)),"") | P10: =IFERROR(PERCENTRANK(HIST_D!$F$8:INDEX(HIST_D!$F$8:$F$2617,Control!$F$14),INDEX(HIST_D!$F$8:$F$2617,1)),"") | Q10: =IFERROR(PERCENTRANK(HIST_D!$F$8:INDEX(HIST_D!$F$8:$F$2617,Control!$F$15),INDEX(HIST_D!$F$8:$F$2617,1)),"") | R10: =IFERROR(PERCENTRANK(HIST_M!$B$8:$B$308,INDEX(HIST_D!$F$8:$F$2617,1)),"") | S10: =IFERROR((INDEX(HIST_D!$F$8:$F$2617,1)-AVERAGE(HIST_D!$F$8:INDEX(HIST_D!$F$8:$F$2617,Control!$F$14)))/STDEV(HIST_D!$F$8:INDEX(HIST_D!$F$8:$F$2617,Control!$F$14)),"") | T10: 2 | U10: =IF(MAX($T10-Control!$B$12,0.0833)<=INDEX($T$6:$T$18,1),INDEX($D$6:$D$18,1),IF(MAX($T10-Control!$B$12,0.0833)>=INDEX($T$6:$T$18,COUNT($T$6:$T$18)),INDEX($D$6:$D$18,COUNT($T$6:$T$18)),INDEX($D$6:$D$18,MATCH(MAX($T10-Control!$B$12,0.0833),$T$6:$T$18,1))+(MAX($T10-Control!$B$12,0.0833)-INDEX($T$6:$T$18,MATCH(MAX($T10-Control!$B$12,0.0833),$T$6:$T$18,1)))/(INDEX($T$6:$T$18,MATCH(MAX($T10-Control!$B$12,0.0833),$T$6:$T$18,1)+1)-INDEX($T$6:$T$18,MATCH(MAX($T10-Control!$B$12,0.0833),$T$6:$T$18,1)))*(INDEX($D$6:$D$18,MATCH(MAX($T10-Control!$B$12,0.0833),$T$6:$T$18,1)+1)-INDEX($D$6:$D$18,MATCH(MAX($T10-Control!$B$12,0.0833),$T$6:$T$18,1))))) | V10: =IF($T10<=Control!$B$12,"",($D10-$U10)*Control!$B$11) | W10: =IFERROR((1-(1+$D10/100/Control!$B$14)^(-Control!$B$14*($T10)))/($D10/100/Control!$B$14)/Control!$B$14,"") | X10: =IFERROR($W10*100*1000000/10000,"") | Y10: =IF($T10<=Control!$B$12,$D10*Control!$B$12/100,IFERROR((IFERROR(($D10/Control!$B$14)*(1-(1+$U10/100/Control!$B$14)^(-Control!$B$14*($T10-Control!$B$12)))/($U10/100/Control!$B$14)+100*(1+$U10/100/Control!$B$14)^(-Control!$B$14*($T10-Control!$B$12)),"")+$D10*Control!$B$12-100)/100,"")) | Z10: =IF($T10<=Control!$B$12,"n/a",IFERROR($Y10*100/IFERROR((1-(1+$U10/100/Control!$B$14)^(-Control!$B$14*($T10-Control!$B$12)))/($U10/100/Control!$B$14)/Control!$B$14,"")*Control!$B$11,""))
A11: UST 3Y | B11: =Tickers!$C$11 | C11: % | D11: =INDEX(HIST_D!$G$8:$G$2617,1) | E11: =IFERROR((INDEX(HIST_D!$G$8:$G$2617,1)-INDEX(HIST_D!$G$8:$G$2617,Control!$F$6))*Control!$B$11,"") | F11: =IFERROR((INDEX(HIST_D!$G$8:$G$2617,1)-INDEX(HIST_D!$G$8:$G$2617,Control!$F$7))*Control!$B$11,"") | G11: =IFERROR((INDEX(HIST_D!$G$8:$G$2617,1)-INDEX(HIST_D!$G$8:$G$2617,Control!$F$8))*Control!$B$11,"") | H11: =IFERROR((INDEX(HIST_D!$G$8:$G$2617,1)-INDEX(HIST_D!$G$8:$G$2617,Control!$F$9))*Control!$B$11,"") | I11: =IFERROR((INDEX(HIST_D!$G$8:$G$2617,1)-INDEX(HIST_D!$G$8:$G$2617,Control!$F$10))*Control!$B$11,"") | J11: =IFERROR((INDEX(HIST_D!$G$8:$G$2617,1)-INDEX(HIST_D!$G$8:$G$2617,Control!$F$16))*Control!$B$11,"") | K11: =IFERROR((INDEX(HIST_D!$G$8:$G$2617,1)-INDEX(HIST_D!$G$8:$G$2617,Control!$F$11))*Control!$B$11,"") | L11: =IFERROR(MIN(HIST_D!$G$8:INDEX(HIST_D!$G$8:$G$2617,Control!$F$11)),"") | M11: =IFERROR(MAX(HIST_D!$G$8:INDEX(HIST_D!$G$8:$G$2617,Control!$F$11)),"") | N11: =IFERROR(PERCENTRANK(HIST_D!$G$8:INDEX(HIST_D!$G$8:$G$2617,Control!$F$11),INDEX(HIST_D!$G$8:$G$2617,1)),"") | O11: =IFERROR(PERCENTRANK(HIST_D!$G$8:INDEX(HIST_D!$G$8:$G$2617,Control!$F$13),INDEX(HIST_D!$G$8:$G$2617,1)),"") | P11: =IFERROR(PERCENTRANK(HIST_D!$G$8:INDEX(HIST_D!$G$8:$G$2617,Control!$F$14),INDEX(HIST_D!$G$8:$G$2617,1)),"") | Q11: =IFERROR(PERCENTRANK(HIST_D!$G$8:INDEX(HIST_D!$G$8:$G$2617,Control!$F$15),INDEX(HIST_D!$G$8:$G$2617,1)),"") | S11: =IFERROR((INDEX(HIST_D!$G$8:$G$2617,1)-AVERAGE(HIST_D!$G$8:INDEX(HIST_D!$G$8:$G$2617,Control!$F$14)))/STDEV(HIST_D!$G$8:INDEX(HIST_D!$G$8:$G$2617,Control!$F$14)),"") | T11: 3 | U11: =IF(MAX($T11-Control!$B$12,0.0833)<=INDEX($T$6:$T$18,1),INDEX($D$6:$D$18,1),IF(MAX($T11-Control!$B$12,0.0833)>=INDEX($T$6:$T$18,COUNT($T$6:$T$18)),INDEX($D$6:$D$18,COUNT($T$6:$T$18)),INDEX($D$6:$D$18,MATCH(MAX($T11-Control!$B$12,0.0833),$T$6:$T$18,1))+(MAX($T11-Control!$B$12,0.0833)-INDEX($T$6:$T$18,MATCH(MAX($T11-Control!$B$12,0.0833),$T$6:$T$18,1)))/(INDEX($T$6:$T$18,MATCH(MAX($T11-Control!$B$12,0.0833),$T$6:$T$18,1)+1)-INDEX($T$6:$T$18,MATCH(MAX($T11-Control!$B$12,0.0833),$T$6:$T$18,1)))*(INDEX($D$6:$D$18,MATCH(MAX($T11-Control!$B$12,0.0833),$T$6:$T$18,1)+1)-INDEX($D$6:$D$18,MATCH(MAX($T11-Control!$B$12,0.0833),$T$6:$T$18,1))))) | V11: =IF($T11<=Control!$B$12,"",($D11-$U11)*Control!$B$11) | W11: =IFERROR((1-(1+$D11/100/Control!$B$14)^(-Control!$B$14*($T11)))/($D11/100/Control!$B$14)/Control!$B$14,"") | X11: =IFERROR($W11*100*1000000/10000,"") | Y11: =IF($T11<=Control!$B$12,$D11*Control!$B$12/100,IFERROR((IFERROR(($D11/Control!$B$14)*(1-(1+$U11/100/Control!$B$14)^(-Control!$B$14*($T11-Control!$B$12)))/($U11/100/Control!$B$14)+100*(1+$U11/100/Control!$B$14)^(-Control!$B$14*($T11-Control!$B$12)),"")+$D11*Control!$B$12-100)/100,"")) | Z11: =IF($T11<=Control!$B$12,"n/a",IFERROR($Y11*100/IFERROR((1-(1+$U11/100/Control!$B$14)^(-Control!$B$14*($T11-Control!$B$12)))/($U11/100/Control!$B$14)/Control!$B$14,"")*Control!$B$11,""))
A12: UST 4Y | B12: derived on HIST_D | C12: % | D12: =INDEX(HIST_D!$AR$8:$AR$2617,1) | E12: =IFERROR((INDEX(HIST_D!$AR$8:$AR$2617,1)-INDEX(HIST_D!$AR$8:$AR$2617,Control!$F$6))*Control!$B$11,"") | F12: =IFERROR((INDEX(HIST_D!$AR$8:$AR$2617,1)-INDEX(HIST_D!$AR$8:$AR$2617,Control!$F$7))*Control!$B$11,"") | G12: =IFERROR((INDEX(HIST_D!$AR$8:$AR$2617,1)-INDEX(HIST_D!$AR$8:$AR$2617,Control!$F$8))*Control!$B$11,"") | H12: =IFERROR((INDEX(HIST_D!$AR$8:$AR$2617,1)-INDEX(HIST_D!$AR$8:$AR$2617,Control!$F$9))*Control!$B$11,"") | I12: =IFERROR((INDEX(HIST_D!$AR$8:$AR$2617,1)-INDEX(HIST_D!$AR$8:$AR$2617,Control!$F$10))*Control!$B$11,"") | J12: =IFERROR((INDEX(HIST_D!$AR$8:$AR$2617,1)-INDEX(HIST_D!$AR$8:$AR$2617,Control!$F$16))*Control!$B$11,"") | K12: =IFERROR((INDEX(HIST_D!$AR$8:$AR$2617,1)-INDEX(HIST_D!$AR$8:$AR$2617,Control!$F$11))*Control!$B$11,"") | L12: =IFERROR(MIN(HIST_D!$AR$8:INDEX(HIST_D!$AR$8:$AR$2617,Control!$F$11)),"") | M12: =IFERROR(MAX(HIST_D!$AR$8:INDEX(HIST_D!$AR$8:$AR$2617,Control!$F$11)),"") | N12: =IFERROR(PERCENTRANK(HIST_D!$AR$8:INDEX(HIST_D!$AR$8:$AR$2617,Control!$F$11),INDEX(HIST_D!$AR$8:$AR$2617,1)),"") | O12: =IFERROR(PERCENTRANK(HIST_D!$AR$8:INDEX(HIST_D!$AR$8:$AR$2617,Control!$F$13),INDEX(HIST_D!$AR$8:$AR$2617,1)),"") | P12: =IFERROR(PERCENTRANK(HIST_D!$AR$8:INDEX(HIST_D!$AR$8:$AR$2617,Control!$F$14),INDEX(HIST_D!$AR$8:$AR$2617,1)),"") | Q12: =IFERROR(PERCENTRANK(HIST_D!$AR$8:INDEX(HIST_D!$AR$8:$AR$2617,Control!$F$15),INDEX(HIST_D!$AR$8:$AR$2617,1)),"") | S12: =IFERROR((INDEX(HIST_D!$AR$8:$AR$2617,1)-AVERAGE(HIST_D!$AR$8:INDEX(HIST_D!$AR$8:$AR$2617,Control!$F$14)))/STDEV(HIST_D!$AR$8:INDEX(HIST_D!$AR$8:$AR$2617,Control!$F$14)),"") | T12: 4 | U12: =IF(MAX($T12-Control!$B$12,0.0833)<=INDEX($T$6:$T$18,1),INDEX($D$6:$D$18,1),IF(MAX($T12-Control!$B$12,0.0833)>=INDEX($T$6:$T$18,COUNT($T$6:$T$18)),INDEX($D$6:$D$18,COUNT($T$6:$T$18)),INDEX($D$6:$D$18,MATCH(MAX($T12-Control!$B$12,0.0833),$T$6:$T$18,1))+(MAX($T12-Control!$B$12,0.0833)-INDEX($T$6:$T$18,MATCH(MAX($T12-Control!$B$12,0.0833),$T$6:$T$18,1)))/(INDEX($T$6:$T$18,MATCH(MAX($T12-Control!$B$12,0.0833),$T$6:$T$18,1)+1)-INDEX($T$6:$T$18,MATCH(MAX($T12-Control!$B$12,0.0833),$T$6:$T$18,1)))*(INDEX($D$6:$D$18,MATCH(MAX($T12-Control!$B$12,0.0833),$T$6:$T$18,1)+1)-INDEX($D$6:$D$18,MATCH(MAX($T12-Control!$B$12,0.0833),$T$6:$T$18,1))))) | V12: =IF($T12<=Control!$B$12,"",($D12-$U12)*Control!$B$11) | W12: =IFERROR((1-(1+$D12/100/Control!$B$14)^(-Control!$B$14*($T12)))/($D12/100/Control!$B$14)/Control!$B$14,"") | X12: =IFERROR($W12*100*1000000/10000,"") | Y12: =IF($T12<=Control!$B$12,$D12*Control!$B$12/100,IFERROR((IFERROR(($D12/Control!$B$14)*(1-(1+$U12/100/Control!$B$14)^(-Control!$B$14*($T12-Control!$B$12)))/($U12/100/Control!$B$14)+100*(1+$U12/100/Control!$B$14)^(-Control!$B$14*($T12-Control!$B$12)),"")+$D12*Control!$B$12-100)/100,"")) | Z12: =IF($T12<=Control!$B$12,"n/a",IFERROR($Y12*100/IFERROR((1-(1+$U12/100/Control!$B$14)^(-Control!$B$14*($T12-Control!$B$12)))/($U12/100/Control!$B$14)/Control!$B$14,"")*Control!$B$11,""))
A13: UST 5Y | B13: =Tickers!$C$12 | C13: % | D13: =INDEX(HIST_D!$H$8:$H$2617,1) | E13: =IFERROR((INDEX(HIST_D!$H$8:$H$2617,1)-INDEX(HIST_D!$H$8:$H$2617,Control!$F$6))*Control!$B$11,"") | F13: =IFERROR((INDEX(HIST_D!$H$8:$H$2617,1)-INDEX(HIST_D!$H$8:$H$2617,Control!$F$7))*Control!$B$11,"") | G13: =IFERROR((INDEX(HIST_D!$H$8:$H$2617,1)-INDEX(HIST_D!$H$8:$H$2617,Control!$F$8))*Control!$B$11,"") | H13: =IFERROR((INDEX(HIST_D!$H$8:$H$2617,1)-INDEX(HIST_D!$H$8:$H$2617,Control!$F$9))*Control!$B$11,"") | I13: =IFERROR((INDEX(HIST_D!$H$8:$H$2617,1)-INDEX(HIST_D!$H$8:$H$2617,Control!$F$10))*Control!$B$11,"") | J13: =IFERROR((INDEX(HIST_D!$H$8:$H$2617,1)-INDEX(HIST_D!$H$8:$H$2617,Control!$F$16))*Control!$B$11,"") | K13: =IFERROR((INDEX(HIST_D!$H$8:$H$2617,1)-INDEX(HIST_D!$H$8:$H$2617,Control!$F$11))*Control!$B$11,"") | L13: =IFERROR(MIN(HIST_D!$H$8:INDEX(HIST_D!$H$8:$H$2617,Control!$F$11)),"") | M13: =IFERROR(MAX(HIST_D!$H$8:INDEX(HIST_D!$H$8:$H$2617,Control!$F$11)),"") | N13: =IFERROR(PERCENTRANK(HIST_D!$H$8:INDEX(HIST_D!$H$8:$H$2617,Control!$F$11),INDEX(HIST_D!$H$8:$H$2617,1)),"") | O13: =IFERROR(PERCENTRANK(HIST_D!$H$8:INDEX(HIST_D!$H$8:$H$2617,Control!$F$13),INDEX(HIST_D!$H$8:$H$2617,1)),"") | P13: =IFERROR(PERCENTRANK(HIST_D!$H$8:INDEX(HIST_D!$H$8:$H$2617,Control!$F$14),INDEX(HIST_D!$H$8:$H$2617,1)),"") | Q13: =IFERROR(PERCENTRANK(HIST_D!$H$8:INDEX(HIST_D!$H$8:$H$2617,Control!$F$15),INDEX(HIST_D!$H$8:$H$2617,1)),"") | R13: =IFERROR(PERCENTRANK(HIST_M!$C$8:$C$308,INDEX(HIST_D!$H$8:$H$2617,1)),"") | S13: =IFERROR((INDEX(HIST_D!$H$8:$H$2617,1)-AVERAGE(HIST_D!$H$8:INDEX(HIST_D!$H$8:$H$2617,Control!$F$14)))/STDEV(HIST_D!$H$8:INDEX(HIST_D!$H$8:$H$2617,Control!$F$14)),"") | T13: 5 | U13: =IF(MAX($T13-Control!$B$12,0.0833)<=INDEX($T$6:$T$18,1),INDEX($D$6:$D$18,1),IF(MAX($T13-Control!$B$12,0.0833)>=INDEX($T$6:$T$18,COUNT($T$6:$T$18)),INDEX($D$6:$D$18,COUNT($T$6:$T$18)),INDEX($D$6:$D$18,MATCH(MAX($T13-Control!$B$12,0.0833),$T$6:$T$18,1))+(MAX($T13-Control!$B$12,0.0833)-INDEX($T$6:$T$18,MATCH(MAX($T13-Control!$B$12,0.0833),$T$6:$T$18,1)))/(INDEX($T$6:$T$18,MATCH(MAX($T13-Control!$B$12,0.0833),$T$6:$T$18,1)+1)-INDEX($T$6:$T$18,MATCH(MAX($T13-Control!$B$12,0.0833),$T$6:$T$18,1)))*(INDEX($D$6:$D$18,MATCH(MAX($T13-Control!$B$12,0.0833),$T$6:$T$18,1)+1)-INDEX($D$6:$D$18,MATCH(MAX($T13-Control!$B$12,0.0833),$T$6:$T$18,1))))) | V13: =IF($T13<=Control!$B$12,"",($D13-$U13)*Control!$B$11) | W13: =IFERROR((1-(1+$D13/100/Control!$B$14)^(-Control!$B$14*($T13)))/($D13/100/Control!$B$14)/Control!$B$14,"") | X13: =IFERROR($W13*100*1000000/10000,"") | Y13: =IF($T13<=Control!$B$12,$D13*Control!$B$12/100,IFERROR((IFERROR(($D13/Control!$B$14)*(1-(1+$U13/100/Control!$B$14)^(-Control!$B$14*($T13-Control!$B$12)))/($U13/100/Control!$B$14)+100*(1+$U13/100/Control!$B$14)^(-Control!$B$14*($T13-Control!$B$12)),"")+$D13*Control!$B$12-100)/100,"")) | Z13: =IF($T13<=Control!$B$12,"n/a",IFERROR($Y13*100/IFERROR((1-(1+$U13/100/Control!$B$14)^(-Control!$B$14*($T13-Control!$B$12)))/($U13/100/Control!$B$14)/Control!$B$14,"")*Control!$B$11,""))
A14: UST 7Y | B14: =Tickers!$C$13 | C14: % | D14: =INDEX(HIST_D!$I$8:$I$2617,1) | E14: =IFERROR((INDEX(HIST_D!$I$8:$I$2617,1)-INDEX(HIST_D!$I$8:$I$2617,Control!$F$6))*Control!$B$11,"") | F14: =IFERROR((INDEX(HIST_D!$I$8:$I$2617,1)-INDEX(HIST_D!$I$8:$I$2617,Control!$F$7))*Control!$B$11,"") | G14: =IFERROR((INDEX(HIST_D!$I$8:$I$2617,1)-INDEX(HIST_D!$I$8:$I$2617,Control!$F$8))*Control!$B$11,"") | H14: =IFERROR((INDEX(HIST_D!$I$8:$I$2617,1)-INDEX(HIST_D!$I$8:$I$2617,Control!$F$9))*Control!$B$11,"") | I14: =IFERROR((INDEX(HIST_D!$I$8:$I$2617,1)-INDEX(HIST_D!$I$8:$I$2617,Control!$F$10))*Control!$B$11,"") | J14: =IFERROR((INDEX(HIST_D!$I$8:$I$2617,1)-INDEX(HIST_D!$I$8:$I$2617,Control!$F$16))*Control!$B$11,"") | K14: =IFERROR((INDEX(HIST_D!$I$8:$I$2617,1)-INDEX(HIST_D!$I$8:$I$2617,Control!$F$11))*Control!$B$11,"") | L14: =IFERROR(MIN(HIST_D!$I$8:INDEX(HIST_D!$I$8:$I$2617,Control!$F$11)),"") | M14: =IFERROR(MAX(HIST_D!$I$8:INDEX(HIST_D!$I$8:$I$2617,Control!$F$11)),"") | N14: =IFERROR(PERCENTRANK(HIST_D!$I$8:INDEX(HIST_D!$I$8:$I$2617,Control!$F$11),INDEX(HIST_D!$I$8:$I$2617,1)),"") | O14: =IFERROR(PERCENTRANK(HIST_D!$I$8:INDEX(HIST_D!$I$8:$I$2617,Control!$F$13),INDEX(HIST_D!$I$8:$I$2617,1)),"") | P14: =IFERROR(PERCENTRANK(HIST_D!$I$8:INDEX(HIST_D!$I$8:$I$2617,Control!$F$14),INDEX(HIST_D!$I$8:$I$2617,1)),"") | Q14: =IFERROR(PERCENTRANK(HIST_D!$I$8:INDEX(HIST_D!$I$8:$I$2617,Control!$F$15),INDEX(HIST_D!$I$8:$I$2617,1)),"") | S14: =IFERROR((INDEX(HIST_D!$I$8:$I$2617,1)-AVERAGE(HIST_D!$I$8:INDEX(HIST_D!$I$8:$I$2617,Control!$F$14)))/STDEV(HIST_D!$I$8:INDEX(HIST_D!$I$8:$I$2617,Control!$F$14)),"") | T14: 7 | U14: =IF(MAX($T14-Control!$B$12,0.0833)<=INDEX($T$6:$T$18,1),INDEX($D$6:$D$18,1),IF(MAX($T14-Control!$B$12,0.0833)>=INDEX($T$6:$T$18,COUNT($T$6:$T$18)),INDEX($D$6:$D$18,COUNT($T$6:$T$18)),INDEX($D$6:$D$18,MATCH(MAX($T14-Control!$B$12,0.0833),$T$6:$T$18,1))+(MAX($T14-Control!$B$12,0.0833)-INDEX($T$6:$T$18,MATCH(MAX($T14-Control!$B$12,0.0833),$T$6:$T$18,1)))/(INDEX($T$6:$T$18,MATCH(MAX($T14-Control!$B$12,0.0833),$T$6:$T$18,1)+1)-INDEX($T$6:$T$18,MATCH(MAX($T14-Control!$B$12,0.0833),$T$6:$T$18,1)))*(INDEX($D$6:$D$18,MATCH(MAX($T14-Control!$B$12,0.0833),$T$6:$T$18,1)+1)-INDEX($D$6:$D$18,MATCH(MAX($T14-Control!$B$12,0.0833),$T$6:$T$18,1))))) | V14: =IF($T14<=Control!$B$12,"",($D14-$U14)*Control!$B$11) | W14: =IFERROR((1-(1+$D14/100/Control!$B$14)^(-Control!$B$14*($T14)))/($D14/100/Control!$B$14)/Control!$B$14,"") | X14: =IFERROR($W14*100*1000000/10000,"") | Y14: =IF($T14<=Control!$B$12,$D14*Control!$B$12/100,IFERROR((IFERROR(($D14/Control!$B$14)*(1-(1+$U14/100/Control!$B$14)^(-Control!$B$14*($T14-Control!$B$12)))/($U14/100/Control!$B$14)+100*(1+$U14/100/Control!$B$14)^(-Control!$B$14*($T14-Control!$B$12)),"")+$D14*Control!$B$12-100)/100,"")) | Z14: =IF($T14<=Control!$B$12,"n/a",IFERROR($Y14*100/IFERROR((1-(1+$U14/100/Control!$B$14)^(-Control!$B$14*($T14-Control!$B$12)))/($U14/100/Control!$B$14)/Control!$B$14,"")*Control!$B$11,""))
A15: UST 10Y | B15: =Tickers!$C$14 | C15: % | D15: =INDEX(HIST_D!$J$8:$J$2617,1) | E15: =IFERROR((INDEX(HIST_D!$J$8:$J$2617,1)-INDEX(HIST_D!$J$8:$J$2617,Control!$F$6))*Control!$B$11,"") | F15: =IFERROR((INDEX(HIST_D!$J$8:$J$2617,1)-INDEX(HIST_D!$J$8:$J$2617,Control!$F$7))*Control!$B$11,"") | G15: =IFERROR((INDEX(HIST_D!$J$8:$J$2617,1)-INDEX(HIST_D!$J$8:$J$2617,Control!$F$8))*Control!$B$11,"") | H15: =IFERROR((INDEX(HIST_D!$J$8:$J$2617,1)-INDEX(HIST_D!$J$8:$J$2617,Control!$F$9))*Control!$B$11,"") | I15: =IFERROR((INDEX(HIST_D!$J$8:$J$2617,1)-INDEX(HIST_D!$J$8:$J$2617,Control!$F$10))*Control!$B$11,"") | J15: =IFERROR((INDEX(HIST_D!$J$8:$J$2617,1)-INDEX(HIST_D!$J$8:$J$2617,Control!$F$16))*Control!$B$11,"") | K15: =IFERROR((INDEX(HIST_D!$J$8:$J$2617,1)-INDEX(HIST_D!$J$8:$J$2617,Control!$F$11))*Control!$B$11,"") | L15: =IFERROR(MIN(HIST_D!$J$8:INDEX(HIST_D!$J$8:$J$2617,Control!$F$11)),"") | M15: =IFERROR(MAX(HIST_D!$J$8:INDEX(HIST_D!$J$8:$J$2617,Control!$F$11)),"") | N15: =IFERROR(PERCENTRANK(HIST_D!$J$8:INDEX(HIST_D!$J$8:$J$2617,Control!$F$11),INDEX(HIST_D!$J$8:$J$2617,1)),"") | O15: =IFERROR(PERCENTRANK(HIST_D!$J$8:INDEX(HIST_D!$J$8:$J$2617,Control!$F$13),INDEX(HIST_D!$J$8:$J$2617,1)),"") | P15: =IFERROR(PERCENTRANK(HIST_D!$J$8:INDEX(HIST_D!$J$8:$J$2617,Control!$F$14),INDEX(HIST_D!$J$8:$J$2617,1)),"") | Q15: =IFERROR(PERCENTRANK(HIST_D!$J$8:INDEX(HIST_D!$J$8:$J$2617,Control!$F$15),INDEX(HIST_D!$J$8:$J$2617,1)),"") | R15: =IFERROR(PERCENTRANK(HIST_M!$D$8:$D$308,INDEX(HIST_D!$J$8:$J$2617,1)),"") | S15: =IFERROR((INDEX(HIST_D!$J$8:$J$2617,1)-AVERAGE(HIST_D!$J$8:INDEX(HIST_D!$J$8:$J$2617,Control!$F$14)))/STDEV(HIST_D!$J$8:INDEX(HIST_D!$J$8:$J$2617,Control!$F$14)),"") | T15: 10 | U15: =IF(MAX($T15-Control!$B$12,0.0833)<=INDEX($T$6:$T$18,1),INDEX($D$6:$D$18,1),IF(MAX($T15-Control!$B$12,0.0833)>=INDEX($T$6:$T$18,COUNT($T$6:$T$18)),INDEX($D$6:$D$18,COUNT($T$6:$T$18)),INDEX($D$6:$D$18,MATCH(MAX($T15-Control!$B$12,0.0833),$T$6:$T$18,1))+(MAX($T15-Control!$B$12,0.0833)-INDEX($T$6:$T$18,MATCH(MAX($T15-Control!$B$12,0.0833),$T$6:$T$18,1)))/(INDEX($T$6:$T$18,MATCH(MAX($T15-Control!$B$12,0.0833),$T$6:$T$18,1)+1)-INDEX($T$6:$T$18,MATCH(MAX($T15-Control!$B$12,0.0833),$T$6:$T$18,1)))*(INDEX($D$6:$D$18,MATCH(MAX($T15-Control!$B$12,0.0833),$T$6:$T$18,1)+1)-INDEX($D$6:$D$18,MATCH(MAX($T15-Control!$B$12,0.0833),$T$6:$T$18,1))))) | V15: =IF($T15<=Control!$B$12,"",($D15-$U15)*Control!$B$11) | W15: =IFERROR((1-(1+$D15/100/Control!$B$14)^(-Control!$B$14*($T15)))/($D15/100/Control!$B$14)/Control!$B$14,"") | X15: =IFERROR($W15*100*1000000/10000,"") | Y15: =IF($T15<=Control!$B$12,$D15*Control!$B$12/100,IFERROR((IFERROR(($D15/Control!$B$14)*(1-(1+$U15/100/Control!$B$14)^(-Control!$B$14*($T15-Control!$B$12)))/($U15/100/Control!$B$14)+100*(1+$U15/100/Control!$B$14)^(-Control!$B$14*($T15-Control!$B$12)),"")+$D15*Control!$B$12-100)/100,"")) | Z15: =IF($T15<=Control!$B$12,"n/a",IFERROR($Y15*100/IFERROR((1-(1+$U15/100/Control!$B$14)^(-Control!$B$14*($T15-Control!$B$12)))/($U15/100/Control!$B$14)/Control!$B$14,"")*Control!$B$11,""))
A16: UST 15Y | B16: derived on HIST_D | C16: % | D16: =INDEX(HIST_D!$AS$8:$AS$2617,1) | E16: =IFERROR((INDEX(HIST_D!$AS$8:$AS$2617,1)-INDEX(HIST_D!$AS$8:$AS$2617,Control!$F$6))*Control!$B$11,"") | F16: =IFERROR((INDEX(HIST_D!$AS$8:$AS$2617,1)-INDEX(HIST_D!$AS$8:$AS$2617,Control!$F$7))*Control!$B$11,"") | G16: =IFERROR((INDEX(HIST_D!$AS$8:$AS$2617,1)-INDEX(HIST_D!$AS$8:$AS$2617,Control!$F$8))*Control!$B$11,"") | H16: =IFERROR((INDEX(HIST_D!$AS$8:$AS$2617,1)-INDEX(HIST_D!$AS$8:$AS$2617,Control!$F$9))*Control!$B$11,"") | I16: =IFERROR((INDEX(HIST_D!$AS$8:$AS$2617,1)-INDEX(HIST_D!$AS$8:$AS$2617,Control!$F$10))*Control!$B$11,"") | J16: =IFERROR((INDEX(HIST_D!$AS$8:$AS$2617,1)-INDEX(HIST_D!$AS$8:$AS$2617,Control!$F$16))*Control!$B$11,"") | K16: =IFERROR((INDEX(HIST_D!$AS$8:$AS$2617,1)-INDEX(HIST_D!$AS$8:$AS$2617,Control!$F$11))*Control!$B$11,"") | L16: =IFERROR(MIN(HIST_D!$AS$8:INDEX(HIST_D!$AS$8:$AS$2617,Control!$F$11)),"") | M16: =IFERROR(MAX(HIST_D!$AS$8:INDEX(HIST_D!$AS$8:$AS$2617,Control!$F$11)),"") | N16: =IFERROR(PERCENTRANK(HIST_D!$AS$8:INDEX(HIST_D!$AS$8:$AS$2617,Control!$F$11),INDEX(HIST_D!$AS$8:$AS$2617,1)),"") | O16: =IFERROR(PERCENTRANK(HIST_D!$AS$8:INDEX(HIST_D!$AS$8:$AS$2617,Control!$F$13),INDEX(HIST_D!$AS$8:$AS$2617,1)),"") | P16: =IFERROR(PERCENTRANK(HIST_D!$AS$8:INDEX(HIST_D!$AS$8:$AS$2617,Control!$F$14),INDEX(HIST_D!$AS$8:$AS$2617,1)),"") | Q16: =IFERROR(PERCENTRANK(HIST_D!$AS$8:INDEX(HIST_D!$AS$8:$AS$2617,Control!$F$15),INDEX(HIST_D!$AS$8:$AS$2617,1)),"") | S16: =IFERROR((INDEX(HIST_D!$AS$8:$AS$2617,1)-AVERAGE(HIST_D!$AS$8:INDEX(HIST_D!$AS$8:$AS$2617,Control!$F$14)))/STDEV(HIST_D!$AS$8:INDEX(HIST_D!$AS$8:$AS$2617,Control!$F$14)),"") | T16: 15 | U16: =IF(MAX($T16-Control!$B$12,0.0833)<=INDEX($T$6:$T$18,1),INDEX($D$6:$D$18,1),IF(MAX($T16-Control!$B$12,0.0833)>=INDEX($T$6:$T$18,COUNT($T$6:$T$18)),INDEX($D$6:$D$18,COUNT($T$6:$T$18)),INDEX($D$6:$D$18,MATCH(MAX($T16-Control!$B$12,0.0833),$T$6:$T$18,1))+(MAX($T16-Control!$B$12,0.0833)-INDEX($T$6:$T$18,MATCH(MAX($T16-Control!$B$12,0.0833),$T$6:$T$18,1)))/(INDEX($T$6:$T$18,MATCH(MAX($T16-Control!$B$12,0.0833),$T$6:$T$18,1)+1)-INDEX($T$6:$T$18,MATCH(MAX($T16-Control!$B$12,0.0833),$T$6:$T$18,1)))*(INDEX($D$6:$D$18,MATCH(MAX($T16-Control!$B$12,0.0833),$T$6:$T$18,1)+1)-INDEX($D$6:$D$18,MATCH(MAX($T16-Control!$B$12,0.0833),$T$6:$T$18,1))))) | V16: =IF($T16<=Control!$B$12,"",($D16-$U16)*Control!$B$11) | W16: =IFERROR((1-(1+$D16/100/Control!$B$14)^(-Control!$B$14*($T16)))/($D16/100/Control!$B$14)/Control!$B$14,"") | X16: =IFERROR($W16*100*1000000/10000,"") | Y16: =IF($T16<=Control!$B$12,$D16*Control!$B$12/100,IFERROR((IFERROR(($D16/Control!$B$14)*(1-(1+$U16/100/Control!$B$14)^(-Control!$B$14*($T16-Control!$B$12)))/($U16/100/Control!$B$14)+100*(1+$U16/100/Control!$B$14)^(-Control!$B$14*($T16-Control!$B$12)),"")+$D16*Control!$B$12-100)/100,"")) | Z16: =IF($T16<=Control!$B$12,"n/a",IFERROR($Y16*100/IFERROR((1-(1+$U16/100/Control!$B$14)^(-Control!$B$14*($T16-Control!$B$12)))/($U16/100/Control!$B$14)/Control!$B$14,"")*Control!$B$11,""))
A17: UST 20Y | B17: =Tickers!$C$15 | C17: % | D17: =INDEX(HIST_D!$K$8:$K$2617,1) | E17: =IFERROR((INDEX(HIST_D!$K$8:$K$2617,1)-INDEX(HIST_D!$K$8:$K$2617,Control!$F$6))*Control!$B$11,"") | F17: =IFERROR((INDEX(HIST_D!$K$8:$K$2617,1)-INDEX(HIST_D!$K$8:$K$2617,Control!$F$7))*Control!$B$11,"") | G17: =IFERROR((INDEX(HIST_D!$K$8:$K$2617,1)-INDEX(HIST_D!$K$8:$K$2617,Control!$F$8))*Control!$B$11,"") | H17: =IFERROR((INDEX(HIST_D!$K$8:$K$2617,1)-INDEX(HIST_D!$K$8:$K$2617,Control!$F$9))*Control!$B$11,"") | I17: =IFERROR((INDEX(HIST_D!$K$8:$K$2617,1)-INDEX(HIST_D!$K$8:$K$2617,Control!$F$10))*Control!$B$11,"") | J17: =IFERROR((INDEX(HIST_D!$K$8:$K$2617,1)-INDEX(HIST_D!$K$8:$K$2617,Control!$F$16))*Control!$B$11,"") | K17: =IFERROR((INDEX(HIST_D!$K$8:$K$2617,1)-INDEX(HIST_D!$K$8:$K$2617,Control!$F$11))*Control!$B$11,"") | L17: =IFERROR(MIN(HIST_D!$K$8:INDEX(HIST_D!$K$8:$K$2617,Control!$F$11)),"") | M17: =IFERROR(MAX(HIST_D!$K$8:INDEX(HIST_D!$K$8:$K$2617,Control!$F$11)),"") | N17: =IFERROR(PERCENTRANK(HIST_D!$K$8:INDEX(HIST_D!$K$8:$K$2617,Control!$F$11),INDEX(HIST_D!$K$8:$K$2617,1)),"") | O17: =IFERROR(PERCENTRANK(HIST_D!$K$8:INDEX(HIST_D!$K$8:$K$2617,Control!$F$13),INDEX(HIST_D!$K$8:$K$2617,1)),"") | P17: =IFERROR(PERCENTRANK(HIST_D!$K$8:INDEX(HIST_D!$K$8:$K$2617,Control!$F$14),INDEX(HIST_D!$K$8:$K$2617,1)),"") | Q17: =IFERROR(PERCENTRANK(HIST_D!$K$8:INDEX(HIST_D!$K$8:$K$2617,Control!$F$15),INDEX(HIST_D!$K$8:$K$2617,1)),"") | S17: =IFERROR((INDEX(HIST_D!$K$8:$K$2617,1)-AVERAGE(HIST_D!$K$8:INDEX(HIST_D!$K$8:$K$2617,Control!$F$14)))/STDEV(HIST_D!$K$8:INDEX(HIST_D!$K$8:$K$2617,Control!$F$14)),"") | T17: 20 | U17: =IF(MAX($T17-Control!$B$12,0.0833)<=INDEX($T$6:$T$18,1),INDEX($D$6:$D$18,1),IF(MAX($T17-Control!$B$12,0.0833)>=INDEX($T$6:$T$18,COUNT($T$6:$T$18)),INDEX($D$6:$D$18,COUNT($T$6:$T$18)),INDEX($D$6:$D$18,MATCH(MAX($T17-Control!$B$12,0.0833),$T$6:$T$18,1))+(MAX($T17-Control!$B$12,0.0833)-INDEX($T$6:$T$18,MATCH(MAX($T17-Control!$B$12,0.0833),$T$6:$T$18,1)))/(INDEX($T$6:$T$18,MATCH(MAX($T17-Control!$B$12,0.0833),$T$6:$T$18,1)+1)-INDEX($T$6:$T$18,MATCH(MAX($T17-Control!$B$12,0.0833),$T$6:$T$18,1)))*(INDEX($D$6:$D$18,MATCH(MAX($T17-Control!$B$12,0.0833),$T$6:$T$18,1)+1)-INDEX($D$6:$D$18,MATCH(MAX($T17-Control!$B$12,0.0833),$T$6:$T$18,1))))) | V17: =IF($T17<=Control!$B$12,"",($D17-$U17)*Control!$B$11) | W17: =IFERROR((1-(1+$D17/100/Control!$B$14)^(-Control!$B$14*($T17)))/($D17/100/Control!$B$14)/Control!$B$14,"") | X17: =IFERROR($W17*100*1000000/10000,"") | Y17: =IF($T17<=Control!$B$12,$D17*Control!$B$12/100,IFERROR((IFERROR(($D17/Control!$B$14)*(1-(1+$U17/100/Control!$B$14)^(-Control!$B$14*($T17-Control!$B$12)))/($U17/100/Control!$B$14)+100*(1+$U17/100/Control!$B$14)^(-Control!$B$14*($T17-Control!$B$12)),"")+$D17*Control!$B$12-100)/100,"")) | Z17: =IF($T17<=Control!$B$12,"n/a",IFERROR($Y17*100/IFERROR((1-(1+$U17/100/Control!$B$14)^(-Control!$B$14*($T17-Control!$B$12)))/($U17/100/Control!$B$14)/Control!$B$14,"")*Control!$B$11,""))
